Workbook
Name income: Calculations!$B$10
Name Range_EV: Calculations!$B$9
Name range_ICE: Calculations!$B$8

Sheet About
A1: BRAaCTSC BAU Range Anxiety and Charging Time Shadow Cost
A3: Source: | B3: Median US Income
B4: United States Census Bureau
B5: 2020
B6: Income and Poverty in the United States: 2019
B7: https://www.census.gov/library/publications/2020/demo/p60-270.html
B8: First bullet of "Highlights"
B10: Range and Fueling Availability 'Costs'
B11: US Department of Energy
B12: 2013
B13: https://www.nrel.gov/docs/fy13osti/55639.pdf
B15: Number of Gas pumps
B16: CleanTechnica
B17: 2018
B18: Stop Comparing the Number of Gas Stations to EV Charging Stations
B19: https://cleantechnica.com/2018/03/07/stop-comparing-number-gas-stations-ev-charging-stations/
B21: Number of EVSE Ports
B22: Alternative Fuels Data Center
B23: 2021
B24: Electric Vehicle Charging Station Locations
B25: https://afdc.energy.gov/fuels/electricity_locations.html#/analyze?fuel=ELEC
B27: Gasoline vehicle range
B28: US Department of Energy
B29: 2016
B30: All-Electric Vehicle Ranges Can Exceed Those of Some Gasoline Vehicles
B31: https://www.energy.gov/eere/vehicles/fact-939-august-22-2016-all-electric-vehicle-ranges-can-exceed-those-some-gasoline
B32: First Figure
B34: EV range
B35: Inside Evs
B36: 2021
B37: The Median Range of Fully Electric Vehicles Exceeded 250 Miles in 2020
B38: https://insideevs.com/news/464449/median-range-evs-2020-exceeded-250-miles/
A40: Notes
A41: This variable represents the perceived cost of range anxiety - the fear (or inconvenience around) that
A42: the vehicle has insufficient range to reach its destination.
A44: In the US, we use a DOE study to calculate a Range Compensating Value and a Fuel Availability Value.
A45: The Range Compensating Value uses parameters from the DOE study, the median household income,
A46: and the median ranges of ICE and EV vehicles. For EV vehicles, the current median range has already surpassed
A47: 250 miles and is forecated to continue improving. Therefore, we start with today's median range, and assume
A48: the range will reach 300 miles by 2050.
...

Sheet Calculations
A1: Range Compensating Value
A2: b1 | B2: -0.361
A3: b2
A4: b3 | B4: 1.268
A5: b4 | B5: -0.116
B7: 2020 | C7: 2030 | D7: 2050
A8: median range ice (hundred miles) | B8: 4.12 | C8: 4.12 | D8: =B8 -> 4.12
A9: range ev (hundred miles) | B9: 2.59 | C9: 3 | D9: 4.12
A10: income (thousand USD) | B10: 68.703 | C10: =income -> 68.703 | D10: =B10 -> 68.703
A11: *2020 median range taken from historical data. 2030 and 2050 are estimated, with the 2050
A12: range roughly corresponding to today's maximum range
A14: cv (thousand USD) | B14: =($B$4/$B$2*B9*(1-B8/B9)+$B$5/$B$2*B9^2*(1-B8^2/B9^2))*LN(income)*About!$B$53 -> 7.8828464 | C14: =($B$4/$B$2*C9*(1-C8/C9)+$B$5/$B$2*C9^2*(1-C8^2/C9^2))*LN(income)*About!$B$53 -> 5.209951 | D14: =($B$4/$B$2*D9*(1-D8/D9)+$B$5/$B$2*D9^2*(1-D8^2/D9^2))*LN(income)*About!$B$53 -> 0
A16: Fueling Availability
A17: 1e-05 | B17: 7500
A18: 0.05 | B18: 1750
A19: 0.1 | B19: 1000
A20: 1 | B20: 0
A22: y = 220.9751 + 7258.141*e^(-28.95171*x)
A24: 2020 EVSE ports: | B24: 120045
A25: Number of gas pumps | B25: 1200000
B27: 2020 | C27: 2027 | D27: 2030 | E27: 2050
A28: Ratio of EVSE ports:Gas pumps | B28: =B24/B25 -> 0.1000375 | C28: =(B24+'EV charger assumptions'!B9)/Calculations!B25 -> 0.41965866 | D28: =(E28-C28)/(E27-C27)*3+C28 -> 0.49535536 | E28: 1
A29: Corresponding Fueling Availbility Shadow Cost | B29: =B19*About!$B$53 -> 898.05482 | C29: =-667.1*LN(C28)-241.23 -> 338.02201 | D29: =-667.1*LN(D28)-241.23 -> 227.39433 | E29: 0
A31: Fueling time
A32: Ignored, because vast majority of charging can be done overnight and other concerns
A33: addressed by fueling availability and range value
A35: Calculations
A36: 2020 | B36: =B14*1000+B29 -> 8780.9012
A37: 2027 | B37: {=TREND(B14:C14,B7:C7,C27)*1000+C29} -> 6349.8416
A38: 2030 | B38: =C14*1000+D29 -> 5437.3453
A39: 2050 | B39: =D14*1000+E29 -> 0

Sheet EV charger assumptions
A1: We assume EV charger additions based on investments in the Infrastructure Investment and Jobs Act
A2: ($7.5 billion between 2022 and 2026), assuming 80% of the costs are paid for by the government.
A4: Total government funding: | B4: 7500000000
A5: Total government + private funding: | B5: =B4/0.8 -> 9375000000
A7: Average weighted charger cost (see trans/EVCC): | B7: 24443
A9: Chargers added by 2026: | B9: =B5/B7 -> 383545.39

Sheet BRAaCTSC
A1: Cost ($/vehicle) | B1: 2020 | C1: 2021 | D1: 2022 | E1: 2023 | F1: 2024 | G1: 2025 | H1: 2026 | I1: 2027 | J1: 2028 | K1: 2029 | L1: 2030 | M1: 2031 | N1: 2032 | O1: 2033 | P1: 2034 | Q1: 2035 | R1: 2036 | S1: 2037 | T1: 2038 | U1: 2039 | V1: 2040 | W1: 2041 | X1: 2042 | Y1: 2043 | Z1: 2044 | AA1: 2045 | AB1: 2046 | AC1: 2047 | AD1: 2048 | AE1: 2049 | AF1: 2050 | AG1: 2051 | AH1: 2052 | AI1: 2053 | AJ1: 2054 | AK1: 2055 | AL1: 2056 | AM1: 2057 | AN1: 2058 | AO1: 2059 | AP1: 2060 | AQ1: 2061 | AR1: 2062 | AS1: 2063 | AT1: 2064 | AU1: 2065 | AV1: 2066 | AW1: 2067 | AX1: 2068 | AY1: 2069 | AZ1: 2070
A2: Shadow cost | B2: {=TREND(Calculations!$B$36:$B$37,Calculations!$A$36:$A$37,BRAaCTSC!B1)} -> 8780.9012 | C2: {=TREND(Calculations!$B$36:$B$37,Calculations!$A$36:$A$37,BRAaCTSC!C1)} -> 8433.607 | D2: {=TREND(Calculations!$B$36:$B$37,Calculations!$A$36:$A$37,BRAaCTSC!D1)} -> 8086.3128 | E2: {=TREND(Calculations!$B$36:$B$37,Calculations!$A$36:$A$37,BRAaCTSC!E1)} -> 7739.0185 | F2: {=TREND(Calculations!$B$36:$B$37,Calculations!$A$36:$A$37,BRAaCTSC!F1)} -> 7391.7243 | G2: {=TREND(Calculations!$B$36:$B$37,Calculations!$A$36:$A$37,BRAaCTSC!G1)} -> 7044.4301 | H2: {=TREND(Calculations!$B$36:$B$37,Calculations!$A$36:$A$37,BRAaCTSC!H1)} -> 6697.1358 | I2: {=TREND(Calculations!$B$36:$B$37,Calculations!$A$36:$A$37,BRAaCTSC!I1)} -> 6349.8416 | J2: {=TREND(Calculations!$B$37:$B$38,Calculations!$A$37:$A$38,BRAaCTSC!J1)} -> 6045.6762 | K2: {=TREND(Calculations!$B$37:$B$38,Calculations!$A$37:$A$38,BRAaCTSC!K1)} -> 5741.5107 | L2: {=TREND(Calculations!$B$37:$B$38,Calculations!$A$37:$A$38,BRAaCTSC!L1)} -> 5437.3453 | M2: {=TREND(Calculations!$B$38:$B$39,Calculations!$A$38:$A$39,BRAaCTSC!M1)} -> 5165.478 | N2: {=TREND(Calculations!$B$38:$B$39,Calculations!$A$38:$A$39,BRAaCTSC!N1)} -> 4893.6108 | O2: {=TREND(Calculations!$B$38:$B$39,Calculations!$A$38:$A$39,BRAaCTSC!O1)} -> 4621.7435 | P2: {=TREND(Calculations!$B$38:$B$39,Calculations!$A$38:$A$39,BRAaCTSC!P1)} -> 4349.8762 | Q2: {=TREND(Calculations!$B$38:$B$39,Calculations!$A$38:$A$39,BRAaCTSC!Q1)} -> 4078.009 | R2: {=TREND(Calculations!$B$38:$B$39,Calculations!$A$38:$A$39,BRAaCTSC!R1)} -> 3806.1417 | S2: {=TREND(Calculations!$B$38:$B$39,Calculations!$A$38:$A$39,BRAaCTSC!S1)} -> 3534.2744 | T2: {=TREND(Calculations!$B$38:$B$39,Calculations!$A$38:$A$39,BRAaCTSC!T1)} -> 3262.4072 | ... AF2: {=TREND(Calculations!$B$38:$B$39,Calculations!$A$38:$A$39,BRAaCTSC!AF1)} -> 0 | AG2: =AF2 -> 0 | AH2: =AG2 -> 0 | AI2: =AH2 -> 0 | AJ2: =AI2 -> 0 | AK2: =AJ2 -> 0 | AL2: =AK2 -> 0 | AM2: =AL2 -> 0 | AN2: =AM2 -> 0 | ... AZ2: =AY2 -> 0
