Workbook
Name Eno_TM: #REF!
Name Eno_Tons: #REF!
Name Sum_T2: #REF!
Name Sum_TTM: #REF!
Name ti_tbl_50: #REF!
Name ti_tbl_69: #REF!

Sheet About
A1: BAADTbVT BAU Average Annual Dist Traveled by Vehicle Type
A3: Source: | B3: Average Vehicle Loading
B4: EPS Indonesia 1.0 (used the same data)
B6: Annual Distance Traveled (p-km and t-km)
B7: IESR
B8: 2021
B9: Deep decarbonization of Indonesia’s energy system: A Pathway to zero emissions by 2050
B10: https://iesr.or.id/en/pustaka/deep-decarbonization-of-indonesias-energy-system-a-pathway-to-zero-emissions-by-2050
B11: Data from IESR (not published in the study)
B13: SYVbT
B14: See updated SYVbT
A16: Notes:
A17: This is a time-series variable to support countries or regions where average distance traveled per year changes over the model run. Even though the annual distance traveled data has different values projected in the following year, the only value used is the one in 2019, since the SYVbT data is for year 2019. It is assumed that the projected value of annual distance traveled data is because of vehicle volume increase, and not due to average distance increase. Road (p-km) data is divided for LDV, HDV, motorbikes based on the number of vehicles. The value of average annual distance traveled in this model is constant until 2050. Adjusted the number of miles traveled on the road for LDV and HDV from the 'Deep Decarbonization' tab by allocating 93% for LDV and 7% and HDV based on the values of the EPS Indonesia 1.0, which used the US data as proxy (source: IEA Annual Energy Outlook 2020 Tables 7, 46, 47, 49).
A24: Start Year | B24: 2019

Sheet Sheet1
B1: Source: Erahman (2019) Modeling Future Energy Demand and CO2 Emissions of Passenger Cars in Indonesia at the Provincial Level https://www.mdpi.com/1996-1073/12/16/3168#
B3: Vehicle Kilometers Traveled in Provinces, 2012–2015 (km/car/year).
B4: No. | C4: Province | D4: 2012 | E4: 2013 | F4: 2014 | G4: 2015 | H4: Elasticity
C5: Total | D5: =SUM(D6:D38) -> 417180 | E5: =SUM(E6:E38) -> 384145 | F5: =SUM(F6:F38) -> 359461 | G5: =SUM(G6:G38) -> 343869
B6: 1 | C6: Aceh | D6: 8902 | E6: 7867 | F6: 7113 | G6: 6647 | H6: −0.646
B7: 2 | C7: North Sumatra | D7: 11962 | E7: 11319 | F7: 10822 | G7: 10499 | H7: −0.288
B8: 3 | C8: West Sumatra | D8: 15432 | E8: 13916 | F8: 12791 | G8: 12085 | H8: −0.541
B9: 4 | C9: Riau | D9: 9623 | E9: 9142 | F9: 8768 | G9: 8525 | H9: −0.268
B10: 5 | C10: Jambi | D10: 5827 | E10: 5182 | F10: 4710 | G10: 4416 | H10: −0.613
B11: 6 | C11: South Sumatra | D11: 6799 | E11: 6110 | F11: 5600 | G11: 5281 | H11: −0.559
B12: 7 | C12: Bengkulu | D12: 10242 | E12: 9574 | F12: 9062 | G12: 8733 | H12: −0.352
B13: 8 | C13: Lampung | D13: 16858 | E13: 15591 | F13: 14629 | G13: 14014 | H13: −0.409
B14: 9 | C14: Bangka Belitung Islands | D14: 17743 | E14: 15363 | F14: 13660 | G14: 12621 | H14: −0.753
B15: 10 | C15: Riau Islands | D15: 10563 | E15: 9909 | F15: 9406 | G15: 9082 | H15: −0.334
B16: 11 | C16: DKI Jakarta | D16: 4762 | E16: 4334 | F16: 4013 | G16: 3811 | H16: −0.492
B17: 12 | C17: West Java | D17: 33674 | E17: 31320 | F17: 29523 | G17: 28371 | H17: −0.379
... B38: 33 | C38: Papua | D38: 17289 | E38: 15564 | F38: 14286 | G38: 13484 | H38: −0.550

Sheet Deep Decarbonization
B1: million kms
B2: Road [p-km] | M2: Road [t-km]
B3: Region | C3: 2019 | D3: 2020 | E3: 2025 | F3: 2030 | G3: 2035 | H3: 2040 | I3: 2045 | J3: 2050 | M3: Region | N3: 2019 | O3: 2020 | P3: 2025 | Q3: 2030 | R3: 2035 | S3: 2040 | T3: 2045 | U3: 2050
B4: Sumatra | D4: 680447 | E4: 885287 | F4: 1081261 | G4: 1354511 | H4: 1627762 | I4: 1901012 | J4: 2174263 | M4: Sumatra | O4: 179963 | P4: 180574 | Q4: 206307 | R4: 237385 | S4: 268462 | T4: 299539 | U4: 330616
B5: Java - West | D5: 846264 | E5: 1101021 | F5: 1344750 | G5: 1684589 | H5: 2024427 | I5: 2364266 | J5: 2704104 | M5: Java - West | O5: 223818 | P5: 224578 | Q5: 256582 | R5: 295232 | S5: 333883 | T5: 372533 | U5: 411183
B6: Java - Central | D6: 451087 | E6: 586881 | F6: 716798 | G6: 897943 | H6: 1079089 | I6: 1260234 | J6: 1441380 | M6: Java - Central | O6: 119303 | P6: 119708 | Q6: 136767 | R6: 157369 | S6: 177971 | T6: 198573 | U6: 219175
B7: Java - East | D7: 515868 | E7: 671164 | F7: 819738 | G7: 1026898 | H7: 1234058 | I7: 1441218 | J7: 1648378 | M7: Java - East | O7: 136436 | P7: 136899 | Q7: 156408 | R7: 179969 | S7: 203529 | T7: 227090 | U7: 250651
B8: Nusa Tenggara | D8: 122334 | E8: 159161 | F8: 194395 | G8: 243521 | H8: 292647 | I8: 341774 | J8: 390900 | M8: Nusa Tenggara | O8: 32355 | P8: 32465 | Q8: 37091 | R8: 42678 | S8: 48265 | T8: 53853 | U8: 59440
B9: Kalimantan | D9: 190946 | E9: 248428 | F9: 303422 | G9: 380101 | H9: 456780 | I9: 533460 | J9: 610139 | M9: Kalimantan | O9: 50501 | P9: 50672 | Q9: 57894 | R9: 66615 | S9: 75335 | T9: 84056 | U9: 92777
B10: Sulawesi | D10: 229251 | E10: 298265 | F10: 364291 | G10: 456352 | H10: 548414 | I10: 640475 | J10: 732537 | M10: Sulawesi | O10: 60632 | P10: 60838 | Q10: 69508 | R10: 79978 | S10: 90448 | T10: 100919 | U10: 111389
B11: Maluku and Papua | D11: 85596 | E11: 111363 | F11: 136016 | G11: 170389 | H11: 204762 | I11: 239135 | J11: 273508 | M11: Maluku and Papua | O11: 22638 | P11: 22715 | Q11: 25952 | R11: 29861 | S11: 33771 | T11: 37680 | U11: 41589
B12: Total | C12: {=TREND(D12:J12,D3:J3,C3)} -> 2659005.8 | D12: =SUM(D4:D11) -> 3121793 | E12: =SUM(E4:E11) -> 4061570 | F12: =SUM(F4:F11) -> 4960671 | G12: =SUM(G4:G11) -> 6214304 | H12: =SUM(H4:H11) -> 7467939 | I12: =SUM(I4:I11) -> 8721574 | J12: =SUM(J4:J11) -> 9975209 | M12: Total | N12: =391.1722725*N3^2 - 1567426.393*N3 + 1570857258 -> 782766.43 | O12: =SUM(O4:O11) -> 825646 | P12: =SUM(P4:P11) -> 828449 | Q12: =SUM(Q4:Q11) -> 946509 | R12: =SUM(R4:R11) -> 1089087 | S12: =SUM(S4:S11) -> 1231664 | T12: =SUM(T4:T11) -> 1374243 | U12: =SUM(U4:U11) -> 1516820
B14: Rail [p-km] | M14: Rail [t-km]
B15: Region | C15: 2019 | D15: 2020 | E15: 2025 | F15: 2030 | G15: 2035 | H15: 2040 | I15: 2045 | J15: 2050 | M15: Region | N15: 2019 | O15: 2020 | P15: 2025 | Q15: 2030 | R15: 2035 | S15: 2040 | T15: 2045 | U15: 2050
B16: Sumatra | D16: 957 | E16: 1040 | F16: 1141 | G16: 1265 | H16: 1414 | I16: 1593 | J16: 1802 | M16: Sumatra | O16: 10179 | P16: 10845 | Q16: 11637 | R16: 12594 | S16: 13765 | T16: 15217 | U16: 17047
B17: Java - West | D17: 12622 | E17: 13715 | F17: 15053 | G17: 16685 | H17: 18656 | I17: 21006 | J17: 23768 | M17: Java - West | O17: 2296 | P17: 2446 | Q17: 2625 | R17: 2840 | S17: 3105 | T17: 3432 | U17: 3845
B18: Java - Central | D18: 6728 | E18: 7310 | F18: 8024 | G18: 8894 | H18: 9944 | I18: 11197 | J18: 12669 | M18: Java - Central | O18: 1224 | P18: 1304 | Q18: 1399 | R18: 1514 | S18: 1655 | T18: 1829 | U18: 2049
B19: Java - East | D19: 7694 | E19: 8360 | F19: 9176 | G19: 10171 | H19: 11372 | I19: 12805 | J19: 14488 | M19: Java - East | O19: 1399 | P19: 1491 | Q19: 1600 | R19: 1731 | S19: 1892 | T19: 2092 | U19: 2344
B20: Nusa Tenggara | D20: 0 | E20: 0 | F20: 0 | G20: 0 | H20: 0 | I20: 0 | J20: 0 | M20: Nusa Tenggara | O20: 0 | P20: 0 | Q20: 0 | R20: 0 | S20: 0 | T20: 0 | U20: 0
B21: Kalimantan | D21: 0 | E21: 0 | F21: 0 | G21: 0 | H21: 0 | I21: 0 | J21: 0 | M21: Kalimantan | O21: 0 | P21: 0 | Q21: 0 | R21: 0 | S21: 0 | T21: 0 | U21: 0
B22: Sulawesi | D22: 0 | E22: 0 | F22: 0 | G22: 0 | H22: 0 | I22: 0 | J22: 0 | M22: Sulawesi | O22: 0 | P22: 0 | Q22: 0 | R22: 0 | S22: 0 | T22: 0 | U22: 0
B23: Maluku and Papua | D23: 0 | E23: 0 | F23: 0 | G23: 0 | H23: 0 | I23: 0 | J23: 0 | M23: Maluku and Papua | O23: 0 | P23: 0 | Q23: 0 | R23: 0 | S23: 0 | T23: 0 | U23: 0
B24: Total | C24: =14.88114858*C15^2 - 59748.26699*C15 + 59998557.62 -> 27740.274 | D24: =SUM(D16:D23) -> 28001 | E24: =SUM(E16:E23) -> 30425 | F24: =SUM(F16:F23) -> 33394 | G24: =SUM(G16:G23) -> 37015 | H24: =SUM(H16:H23) -> 41386 | I24: =SUM(I16:I23) -> 46601 | J24: =SUM(J16:J23) -> 52727 | M24: Total | N24: =6.745793647*N15^2 - 27121.90459*N15 + 27275894.02 -> 15058.789 | O24: =SUM(O16:O23) -> 15098 | P24: =SUM(P16:P23) -> 16086 | Q24: =SUM(Q16:Q23) -> 17261 | R24: =SUM(R16:R23) -> 18679 | S24: =SUM(S16:S23) -> 20417 | T24: =SUM(T16:T23) -> 22570 | U24: =SUM(U16:U23) -> 25285
B26: Marine [p-km] | M26: Marine [t-km]
B27: Region | C27: 2019 | D27: 2020 | E27: 2025 | F27: 2030 | G27: 2035 | H27: 2040 | I27: 2045 | J27: 2050 | M27: Region | N27: 2019 | O27: 2020 | P27: 2025 | Q27: 2030 | R27: 2035 | S27: 2040 | T27: 2045 | U27: 2050
B28: Sumatra | D28: 1472 | E28: 1914 | F28: 2455 | G28: 3108 | H28: 3879 | I28: 4778 | J28: 5816 | M28: Sumatra | O28: 591265 | P28: 735901 | Q28: 911880 | R28: 1125248 | S28: 1381363 | T28: 1687622 | U28: 2055332
B29: Java - West | D29: 1831 | E29: 2380 | F29: 3054 | G29: 3865 | H29: 4825 | I29: 5942 | J29: 7233 | M29: Java - West | O29: 735349 | P29: 915231 | Q29: 1134094 | R29: 1399457 | S29: 1717984 | T29: 2098875 | U29: 2556192
B30: Java - Central | D30: 976 | E30: 1269 | F30: 1628 | G30: 2060 | H30: 2572 | I30: 3168 | J30: 3855 | M30: Java - Central | O30: 391966 | P30: 487849 | Q30: 604510 | R30: 745958 | S30: 915744 | T30: 1118772 | U30: 1362537
B31: Java - East | D31: 1116 | E31: 1451 | F31: 1862 | G31: 2356 | H31: 2941 | I31: 3622 | J31: 4409 | M31: Java - East | O31: 448257 | P31: 557910 | Q31: 691325 | R31: 853086 | S31: 1047255 | T31: 1279440 | U31: 1558213
B32: Nusa Tenggara | D32: 265 | E32: 344 | F32: 441 | G32: 559 | H32: 697 | I32: 859 | J32: 1046 | M32: Nusa Tenggara | O32: 106301 | P32: 132304 | Q32: 163942 | R32: 202303 | S32: 248349 | T32: 303409 | U32: 369518
B33: Kalimantan | D33: 413 | E33: 537 | F33: 689 | G33: 872 | H33: 1089 | I33: 1341 | J33: 1632 | M33: Kalimantan | O33: 165920 | P33: 206508 | Q33: 255891 | R33: 315766 | S33: 387636 | T33: 473578 | U33: 576765
B34: Sulawesi | D34: 496 | E34: 645 | F34: 827 | G34: 1047 | H34: 1307 | I34: 1610 | J34: 1959 | M34: Sulawesi | O34: 199205 | P34: 247935 | Q34: 307224 | R34: 379110 | S34: 465399 | T34: 568582 | U34: 692468
B35: Maluku and Papua | D35: 185 | E35: 241 | F35: 309 | G35: 391 | H35: 488 | I35: 601 | J35: 732 | M35: Maluku and Papua | O35: 74377 | P35: 92572 | Q35: 114709 | R35: 141549 | S35: 173766 | T35: 212292 | U35: 258547
B36: Total | C36: =4.82813*10^-37*EXP(0.045778497*C27) -> 6671.4748 | D36: =SUM(D28:D35) -> 6754 | E36: =SUM(E28:E35) -> 8781 | F36: =SUM(F28:F35) -> 11265 | G36: =SUM(G28:G35) -> 14258 | H36: =SUM(H28:H35) -> 17798 | I36: =SUM(I28:I35) -> 21921 | J36: =SUM(J28:J35) -> 26682 | M36: Total | N36: =1.02847*10^-30*EXP(0.041521884*N27) -> 2631865 | O36: =SUM(O28:O35) -> 2712640 | P36: =SUM(P28:P35) -> 3376210 | Q36: =SUM(Q28:Q35) -> 4183575 | R36: =SUM(R28:R35) -> 5162477 | S36: =SUM(S28:S35) -> 6337496 | T36: =SUM(T28:T35) -> 7742570 | U36: =SUM(U28:U35) -> 9429572
B38: Aviation[p-km] | M38: Aviation [t-km]
B39: Region | C39: 2019 | D39: 2020 | E39: 2025 | F39: 2030 | G39: 2035 | H39: 2040 | I39: 2045 | J39: 2050 | M39: Region | N39: 2019 | O39: 2020 | P39: 2025 | Q39: 2030 | R39: 2035 | S39: 2040 | T39: 2045 | U39: 2050
B40: Sumatra | D40: 27159 | E40: 34542 | F40: 44869 | G40: 55067 | H40: 71858 | I40: 89365 | J40: 105946 | M40: Sumatra | N40: {=TREND(O40:U40,O39:U39,N39)} -> 469.22857 | O40: 2336 | P40: 3300 | Q40: 4627 | R40: 6428 | S40: 8983 | T40: 12211 | U40: 16046
B41: Java - West | D41: 33777 | E41: 42959 | F41: 55803 | G41: 68486 | H41: 89368 | I41: 111141 | J41: 131763 | M41: Java - West | O41: 2906 | P41: 4105 | Q41: 5756 | R41: 7996 | S41: 11174 | T41: 15189 | U41: 19959
B42: Java - Central | D42: 18004 | E42: 22898 | F42: 29744 | G42: 36504 | H42: 47635 | I42: 59240 | J42: 70232 | M42: Java - Central | O42: 1549 | P42: 2188 | Q42: 3068 | R42: 4262 | S42: 5956 | T42: 8096 | U42: 10639
B43: Java - East | D43: 20590 | E43: 26187 | F43: 34016 | G43: 41747 | H43: 54476 | I43: 67748 | J43: 80318 | M43: Java - East | O43: 1771 | P43: 2502 | Q43: 3508 | R43: 4873 | S43: 6810 | T43: 9257 | U43: 12164
...

Sheet SYVbT-passenger
A1: Number of Vehicles | B1: battery electric vehicle | C1: natural gas vehicle | D1: gasoline vehicle | E1: diesel vehicle | F1: plugin hybrid vehicle | G1: LPG vehicle | H1: hydrogen vehicle
A2: LDVs | B2: 0 | C2: 0 | D2: 17592419 | E2: 0 | F2: 0 | G2: 0 | H2: 0
A3: HDVs | B3: 0 | C3: 0 | D3: 0 | E3: 331569 | F3: 0 | G3: 0 | H3: 0
A4: aircraft | B4: 0 | C4: 0 | D4: 1197 | E4: 0 | F4: 0 | G4: 0 | H4: 0
A5: rail | B5: 97 | C5: 0 | D5: 0 | E5: 667 | F5: 0 | G5: 0 | H5: 0
A6: ships | B6: 0 | C6: 0 | D6: 0 | E6: 2222 | F6: 0 | G6: 0 | H6: 0
A7: motorbikes | B7: 0 | C7: 0 | D7: 112771136 | E7: 0 | F7: 0 | G7: 0 | H7: 0
A10: *As of 2019

Sheet SYVbT-freight
A1: Number of Vehicles | B1: battery electric vehicle | C1: natural gas vehicle | D1: gasoline vehicle | E1: diesel vehicle | F1: plugin hybrid vehicle | G1: LPG vehicle | H1: hydrogen vehicle
A2: LDVs | B2: 0 | C2: 0 | D2: 0 | E2: 0 | F2: 0 | G2: 0 | H2: 0
A3: HDVs | B3: 0 | C3: 0 | D3: 0 | E3: 5021888 | F3: 0 | G3: 0 | H3: 0
A4: aircraft | B4: 0 | C4: 0 | D4: 0 | E4: 0 | F4: 0 | G4: 0 | H4: 0
A5: rail | B5: 0 | C5: 0 | D5: 0 | E5: 0 | F5: 0 | G5: 0 | H5: 0
A6: ships | B6: 0 | C6: 0 | D6: 0 | E6: 27818 | F6: 0 | G6: 0 | H6: 0
A7: motorbikes | B7: 0 | C7: 0 | D7: 0 | E7: 0 | F7: 0 | G7: 0 | H7: 0
A11: *As of 2019

Sheet AVLo-passengers
B1: 2015 | C1: 2016 | D1: 2017 | E1: 2018 | F1: 2019 | G1: 2020 | H1: 2021 | I1: 2022 | J1: 2023 | K1: 2024 | L1: 2025 | M1: 2026 | N1: 2027 | O1: 2028 | P1: 2029 | Q1: 2030 | R1: 2031 | S1: 2032 | T1: 2033 | U1: 2034 | V1: 2035 | W1: 2036 | X1: 2037 | Y1: 2038 | Z1: 2039 | AA1: 2040 | AB1: 2041 | AC1: 2042 | AD1: 2043 | AE1: 2044 | AF1: 2045 | AG1: 2046 | AH1: 2047 | AI1: 2048 | AJ1: 2049 | AK1: 2050
A2: LDVs | B2: 1.67 | C2: 1.67 | D2: 1.67 | E2: 1.67 | F2: 1.67 | G2: 1.67 | H2: 1.67 | I2: 1.67 | J2: 1.67 | K2: 1.67 | L2: 1.67 | M2: 1.67 | N2: 1.67 | O2: 1.67 | P2: 1.67 | Q2: 1.67 | R2: 1.67 | S2: 1.67 | T2: 1.67 | U2: 1.67 | V2: 1.67 | W2: 1.67 | X2: 1.67 | Y2: 1.67 | Z2: 1.67 | AA2: 1.67 | AB2: 1.67 | AC2: 1.67 | AD2: 1.67 | AE2: 1.67 | AF2: 1.67 | AG2: 1.67 | AH2: 1.67 | AI2: 1.67 | AJ2: 1.67 | AK2: 1.67
A3: HDVs | B3: 17.62 | C3: 17.62 | D3: 17.62 | E3: 17.62 | F3: 17.62 | G3: 17.62 | H3: 17.62 | I3: 17.62 | J3: 17.62 | K3: 17.62 | L3: 17.62 | M3: 17.62 | N3: 17.62 | O3: 17.62 | P3: 17.62 | Q3: 17.62 | R3: 17.62 | S3: 17.62 | T3: 17.62 | U3: 17.62 | V3: 17.62 | W3: 17.62 | X3: 17.62 | Y3: 17.62 | Z3: 17.62 | AA3: 17.62 | AB3: 17.62 | AC3: 17.62 | AD3: 17.62 | AE3: 17.62 | AF3: 17.62 | AG3: 17.62 | AH3: 17.62 | AI3: 17.62 | AJ3: 17.62 | AK3: 17.62
A4: aircraft | B4: 137.17018 | C4: 137.17018 | D4: 137.17018 | E4: 137.17018 | F4: 137.17018 | G4: 137.17018 | H4: 137.17018 | I4: 137.17018 | J4: 137.17018 | K4: 137.17018 | L4: 137.17018 | M4: 137.17018 | N4: 137.17018 | O4: 137.17018 | P4: 137.17018 | Q4: 137.17018 | R4: 137.17018 | S4: 137.17018 | T4: 137.17018 | U4: 137.17018 | V4: 137.17018 | W4: 137.17018 | X4: 137.17018 | Y4: 137.17018 | Z4: 137.17018 | AA4: 137.17018 | AB4: 137.17018 | AC4: 137.17018 | AD4: 137.17018 | AE4: 137.17018 | AF4: 137.17018 | AG4: 137.17018 | AH4: 137.17018 | AI4: 137.17018 | AJ4: 137.17018 | AK4: 137.17018
A5: rail | B5: 1301.2821 | C5: 1314.1026 | D5: 1326.9231 | E5: 1339.7436 | F5: 1352.5641 | G5: 1365.3846 | H5: 1378.2051 | I5: 1391.0256 | J5: 1403.8462 | K5: 1416.6667 | L5: 1429.4872 | M5: 1442.3077 | N5: 1455.1282 | O5: 1467.9487 | P5: 1480.7692 | Q5: 1493.5897 | R5: 1506.4103 | S5: 1519.2308 | T5: 1532.0513 | U5: 1544.8718 | V5: 1557.6923 | W5: 1570.5128 | X5: 1583.3333 | Y5: 1596.1538 | Z5: 1608.9744 | AA5: 1621.7949 | AB5: 1634.6154 | AC5: 1647.4359 | AD5: 1660.2564 | AE5: 1673.0769 | AF5: 1685.8974 | AG5: 1698.7179 | AH5: 1711.5385 | AI5: 1724.359 | AJ5: 1737.1795 | AK5: 1750
A6: ships | B6: 625 | C6: 625 | D6: 625 | E6: 625 | F6: 625 | G6: 625 | H6: 625 | I6: 625 | J6: 625 | K6: 625 | L6: 625 | M6: 625 | N6: 625 | O6: 625 | P6: 625 | Q6: 625 | R6: 625 | S6: 625 | T6: 625 | U6: 625 | V6: 625 | W6: 625 | X6: 625 | Y6: 625 | Z6: 625 | AA6: 625 | AB6: 625 | AC6: 625 | AD6: 625 | AE6: 625 | AF6: 625 | AG6: 625 | AH6: 625 | AI6: 625 | AJ6: 625 | AK6: 625
A7: motorbikes | B7: 1.1076936 | C7: 1.1075287 | D7: 1.1073639 | E7: 1.107199 | F7: 1.1070342 | G7: 1.1068693 | H7: 1.1068262 | I7: 1.106783 | J7: 1.1067398 | K7: 1.1066966 | L7: 1.1066534 | M7: 1.1066229 | N7: 1.1065923 | O7: 1.1065618 | P7: 1.1065313 | Q7: 1.1065007 | R7: 1.1064726 | S7: 1.1064445 | T7: 1.1064164 | U7: 1.1063883 | V7: 1.1063601 | W7: 1.106401 | X7: 1.1064419 | Y7: 1.1064828 | Z7: 1.1065236 | AA7: 1.1065645 | AB7: 1.1065255 | AC7: 1.1064865 | AD7: 1.1064475 | AE7: 1.1064085 | AF7: 1.1063695 | AG7: 1.1060004 | AH7: 1.1056312 | AI7: 1.105262 | AJ7: 1.1048928 | AK7: 1.1045236

Sheet AVLo-freight
B1: 2016 | C1: 2017 | D1: 2018 | E1: 2019 | F1: 2020 | G1: 2021 | H1: 2022 | I1: 2023 | J1: 2024 | K1: 2025 | L1: 2026 | M1: 2027 | N1: 2028 | O1: 2029 | P1: 2030 | Q1: 2031 | R1: 2032 | S1: 2033 | T1: 2034 | U1: 2035 | V1: 2036 | W1: 2037 | X1: 2038 | Y1: 2039 | Z1: 2040 | AA1: 2041 | AB1: 2042 | AC1: 2043 | AD1: 2044 | AE1: 2045 | AF1: 2046 | AG1: 2047 | AH1: 2048 | AI1: 2049 | AJ1: 2050
A2: LDVs | B2: 0 | C2: 0 | D2: 0 | E2: 0 | F2: 0 | G2: 0 | H2: 0 | I2: 0 | J2: 0 | K2: 0 | L2: 0 | M2: 0 | N2: 0 | O2: 0 | P2: 0 | Q2: 0 | R2: 0 | S2: 0 | T2: 0 | U2: 0 | V2: 0 | W2: 0 | X2: 0 | Y2: 0 | Z2: 0 | AA2: 0 | AB2: 0 | AC2: 0 | AD2: 0 | AE2: 0 | AF2: 0 | AG2: 0 | AH2: 0 | AI2: 0 | AJ2: 0
A3: HDVs | B3: 16 | C3: 16 | D3: 16 | E3: 16 | F3: 16 | G3: 16 | H3: 16 | I3: 16 | J3: 16 | K3: 16 | L3: 16 | M3: 16 | N3: 16 | O3: 16 | P3: 16 | Q3: 16 | R3: 16 | S3: 16 | T3: 16 | U3: 16 | V3: 16 | W3: 16 | X3: 16 | Y3: 16 | Z3: 16 | AA3: 16 | AB3: 16 | AC3: 16 | AD3: 16 | AE3: 16 | AF3: 16 | AG3: 16 | AH3: 16 | AI3: 16 | AJ3: 16
A4: aircraft | B4: 41.989116 | C4: 41.989116 | D4: 41.989116 | E4: 41.989116 | F4: 41.989116 | G4: 41.989116 | H4: 41.989116 | I4: 41.989116 | J4: 41.989116 | K4: 41.989116 | L4: 41.989116 | M4: 41.989116 | N4: 41.989116 | O4: 41.989116 | P4: 41.989116 | Q4: 41.989116 | R4: 41.989116 | S4: 41.989116 | T4: 41.989116 | U4: 41.989116 | V4: 41.989116 | W4: 41.989116 | X4: 41.989116 | Y4: 41.989116 | Z4: 41.989116 | AA4: 41.989116 | AB4: 41.989116 | AC4: 41.989116 | AD4: 41.989116 | AE4: 41.989116 | AF4: 41.989116 | AG4: 41.989116 | AH4: 41.989116 | AI4: 41.989116 | AJ4: 41.989116
A5: rail | B5: 3512.3592 | C5: 3512.3592 | D5: 3512.3592 | E5: 3512.3592 | F5: 3512.3592 | G5: 3512.3592 | H5: 3512.3592 | I5: 3512.3592 | J5: 3512.3592 | K5: 3512.3592 | L5: 3512.3592 | M5: 3512.3592 | N5: 3512.3592 | O5: 3512.3592 | P5: 3512.3592 | Q5: 3512.3592 | R5: 3512.3592 | S5: 3512.3592 | T5: 3512.3592 | U5: 3512.3592 | V5: 3512.3592 | W5: 3512.3592 | X5: 3512.3592 | Y5: 3512.3592 | Z5: 3512.3592 | AA5: 3512.3592 | AB5: 3512.3592 | AC5: 3512.3592 | AD5: 3512.3592 | AE5: 3512.3592 | AF5: 3512.3592 | AG5: 3512.3592 | AH5: 3512.3592 | AI5: 3512.3592 | AJ5: 3512.3592
A6: ships | B6: 1363.3854 | C6: 1363.3854 | D6: 1363.3854 | E6: 1363.3854 | F6: 1363.3854 | G6: 1363.3854 | H6: 1363.3854 | I6: 1363.3854 | J6: 1363.3854 | K6: 1363.3854 | L6: 1363.3854 | M6: 1363.3854 | N6: 1363.3854 | O6: 1363.3854 | P6: 1363.3854 | Q6: 1363.3854 | R6: 1363.3854 | S6: 1363.3854 | T6: 1363.3854 | U6: 1363.3854 | V6: 1363.3854 | W6: 1363.3854 | X6: 1363.3854 | Y6: 1363.3854 | Z6: 1363.3854 | AA6: 1363.3854 | AB6: 1363.3854 | AC6: 1363.3854 | AD6: 1363.3854 | AE6: 1363.3854 | AF6: 1363.3854 | AG6: 1363.3854 | AH6: 1363.3854 | AI6: 1363.3854 | AJ6: 1363.3854
A7: motorbikes | B7: 0 | C7: 0 | D7: 0 | E7: 0 | F7: 0 | G7: 0 | H7: 0 | I7: 0 | J7: 0 | K7: 0 | L7: 0 | M7: 0 | N7: 0 | O7: 0 | P7: 0 | Q7: 0 | R7: 0 | S7: 0 | T7: 0 | U7: 0 | V7: 0 | W7: 0 | X7: 0 | Y7: 0 | Z7: 0 | AA7: 0 | AB7: 0 | AC7: 0 | AD7: 0 | AE7: 0 | AF7: 0 | AG7: 0 | AH7: 0 | AI7: 0 | AJ7: 0

Sheet BAADTbVT-passengers
A1: Annual Distance (miles/vehicle) | B1: 2019 | C1: 2020 | D1: 2021 | E1: 2022 | F1: 2023 | G1: 2024 | H1: 2025 | I1: 2026 | J1: 2027 | K1: 2028 | L1: 2029 | M1: 2030 | N1: 2031 | O1: 2032 | P1: 2033 | Q1: 2034 | R1: 2035 | S1: 2036 | T1: 2037 | U1: 2038 | V1: 2039 | W1: 2040 | X1: 2041 | Y1: 2042 | Z1: 2043 | AA1: 2044 | AB1: 2045 | AC1: 2046 | AD1: 2047 | AE1: 2048 | AF1: 2049 | AG1: 2050 | AH1: 2051 | AI1: 2052 | AJ1: 2053 | AK1: 2054 | AL1: 2055 | AM1: 2056 | AN1: 2057 | AO1: 2058 | AP1: 2059 | AQ1: 2060 | AR1: 2061 | AS1: 2062 | AT1: 2063 | AU1: 2064 | AV1: 2065 | AW1: 2066 | AX1: 2067 | AY1: 2068 | AZ1: 2069 | BA1: 2070
A2: LDVs | B2: ='Deep Decarbonization'!C12*0.93*0.621371*10^6/('SYVbT-passenger'!D2+'SYVbT-passenger'!E3+'SYVbT-passenger'!D7)/'AVLo-passengers'!F2 -> 7040.0762 | C2: =$B$2 -> 7040.0762 | D2: =$B$2 -> 7040.0762 | E2: =$B$2 -> 7040.0762 | F2: =$B$2 -> 7040.0762 | G2: =$B$2 -> 7040.0762 | H2: =$B$2 -> 7040.0762 | I2: =$B$2 -> 7040.0762 | J2: =$B$2 -> 7040.0762 | ... AG2: =$B$2 -> 7040.0762 | AH2: =AG2 -> 7040.0762 | AI2: =AH2 -> 7040.0762 | AJ2: =AI2 -> 7040.0762 | AK2: =AJ2 -> 7040.0762 | AL2: =AK2 -> 7040.0762 | AM2: =AL2 -> 7040.0762 | AN2: =AM2 -> 7040.0762 | AO2: =AN2 -> 7040.0762 | ... BA2: =AZ2 -> 7040.0762
A3: HDVs | B3: ='Deep Decarbonization'!C12*0.07*0.621371*10^6/('SYVbT-passenger'!D2+'SYVbT-passenger'!E3+'SYVbT-passenger'!D7)/'AVLo-passengers'!F3 -> 50.223043 | C3: =$B$3 -> 50.223043 | D3: =$B$3 -> 50.223043 | E3: =$B$3 -> 50.223043 | F3: =$B$3 -> 50.223043 | G3: =$B$3 -> 50.223043 | H3: =$B$3 -> 50.223043 | I3: =$B$3 -> 50.223043 | J3: =$B$3 -> 50.223043 | ... AG3: =$B$3 -> 50.223043 | AH3: =AG3 -> 50.223043 | AI3: =AH3 -> 50.223043 | AJ3: =AI3 -> 50.223043 | AK3: =AJ3 -> 50.223043 | AL3: =AK3 -> 50.223043 | AM3: =AL3 -> 50.223043 | AN3: =AM3 -> 50.223043 | AO3: =AN3 -> 50.223043 | ... BA3: =AZ3 -> 50.223043
A4: aircraft | B4: ='Deep Decarbonization'!C48*0.621371*10^6/'SYVbT-passenger'!D4/'AVLo-passengers'!F4 -> 446078.08 | C4: =$B$4 -> 446078.08 | D4: =$B$4 -> 446078.08 | E4: =$B$4 -> 446078.08 | F4: =$B$4 -> 446078.08 | G4: =$B$4 -> 446078.08 | H4: =$B$4 -> 446078.08 | I4: =$B$4 -> 446078.08 | J4: =$B$4 -> 446078.08 | ... AG4: =$B$4 -> 446078.08 | AH4: =AG4 -> 446078.08 | AI4: =AH4 -> 446078.08 | AJ4: =AI4 -> 446078.08 | AK4: =AJ4 -> 446078.08 | AL4: =AK4 -> 446078.08 | AM4: =AL4 -> 446078.08 | AN4: =AM4 -> 446078.08 | AO4: =AN4 -> 446078.08 | ... BA4: =AZ4 -> 446078.08
A5: rail | B5: ='Deep Decarbonization'!C24*0.621371*10^6/'SYVbT-passenger'!B5/'AVLo-passengers'!B5 -> 136558.44 | C5: =$B$5 -> 136558.44 | D5: =$B$5 -> 136558.44 | E5: =$B$5 -> 136558.44 | F5: =$B$5 -> 136558.44 | G5: =$B$5 -> 136558.44 | H5: =$B$5 -> 136558.44 | I5: =$B$5 -> 136558.44 | J5: =$B$5 -> 136558.44 | ... AG5: =$B$5 -> 136558.44 | AH5: =AG5 -> 136558.44 | AI5: =AH5 -> 136558.44 | AJ5: =AI5 -> 136558.44 | AK5: =AJ5 -> 136558.44 | AL5: =AK5 -> 136558.44 | AM5: =AL5 -> 136558.44 | AN5: =AM5 -> 136558.44 | AO5: =AN5 -> 136558.44 | ... BA5: =AZ5 -> 136558.44
A6: ships | B6: 0 | C6: 0 | D6: 1 | E6: 2 | F6: 3 | G6: 4 | H6: 5 | I6: 6 | J6: 7 | K6: 8 | L6: 9 | M6: 10 | N6: 11 | O6: 12 | P6: 13 | Q6: 14 | R6: 15 | S6: 16 | T6: 17 | U6: 18 | V6: 19 | W6: 20 | X6: 21 | Y6: 22 | Z6: 23 | AA6: 24 | AB6: 25 | AC6: 26 | AD6: 27 | AE6: 28 | AF6: 29 | AG6: 30 | AH6: =AG6 -> 30 | AI6: =AH6 -> 30 | AJ6: =AI6 -> 30 | AK6: =AJ6 -> 30 | AL6: =AK6 -> 30 | AM6: =AL6 -> 30 | AN6: =AM6 -> 30 | AO6: =AN6 -> 30 | ... BA6: =AZ6 -> 30
A7: motorbikes | B7: ='Deep Decarbonization'!C12/('SYVbT-passenger'!D2+'SYVbT-passenger'!E3+'SYVbT-passenger'!D7)/'AVLo-passengers'!F7*0.621371*10^6 -> 11419.573 | C7: =$B$7 -> 11419.573 | D7: =$B$7 -> 11419.573 | E7: =$B$7 -> 11419.573 | F7: =$B$7 -> 11419.573 | G7: =$B$7 -> 11419.573 | H7: =$B$7 -> 11419.573 | I7: =$B$7 -> 11419.573 | J7: =$B$7 -> 11419.573 | ... AG7: =$B$7 -> 11419.573 | AH7: =AG7 -> 11419.573 | AI7: =AH7 -> 11419.573 | AJ7: =AI7 -> 11419.573 | AK7: =AJ7 -> 11419.573 | AL7: =AK7 -> 11419.573 | AM7: =AL7 -> 11419.573 | AN7: =AM7 -> 11419.573 | AO7: =AN7 -> 11419.573 | ... BA7: =AZ7 -> 11419.573

Sheet BAADTbVT-freight
A1: Annual Distance (miles/vehicle) | B1: 2019 | C1: 2020 | D1: 2021 | E1: 2022 | F1: 2023 | G1: 2024 | H1: 2025 | I1: 2026 | J1: 2027 | K1: 2028 | L1: 2029 | M1: 2030 | N1: 2031 | O1: 2032 | P1: 2033 | Q1: 2034 | R1: 2035 | S1: 2036 | T1: 2037 | U1: 2038 | V1: 2039 | W1: 2040 | X1: 2041 | Y1: 2042 | Z1: 2043 | AA1: 2044 | AB1: 2045 | AC1: 2046 | AD1: 2047 | AE1: 2048 | AF1: 2049 | AG1: 2050 | AH1: 2051 | AI1: 2052 | AJ1: 2053 | AK1: 2054 | AL1: 2055 | AM1: 2056 | AN1: 2057 | AO1: 2058 | AP1: 2059 | AQ1: 2060 | AR1: 2061 | AS1: 2062 | AT1: 2063 | AU1: 2064 | AV1: 2065 | AW1: 2066 | AX1: 2067 | AY1: 2068 | AZ1: 2069 | BA1: 2070
A2: LDVs | B2: 0 | C2: =B2 -> 0 | D2: =C2 -> 0 | E2: =D2 -> 0 | F2: =E2 -> 0 | G2: =F2 -> 0 | H2: =G2 -> 0 | I2: =H2 -> 0 | J2: =I2 -> 0 | ... BA2: =AZ2 -> 0
A3: HDVs | B3: =('Deep Decarbonization'!N12*0.621371*10^6)/'SYVbT-freight'!E3/'AVLo-freight'!B3 -> 6053.3554 | C3: =B3 -> 6053.3554 | D3: =C3 -> 6053.3554 | E3: =D3 -> 6053.3554 | F3: =E3 -> 6053.3554 | G3: =F3 -> 6053.3554 | H3: =G3 -> 6053.3554 | I3: =H3 -> 6053.3554 | J3: =I3 -> 6053.3554 | ... BA3: =AZ3 -> 6053.3554
A4: aircraft | B4: 0 | C4: =B4 -> 0 | D4: =C4 -> 0 | E4: =D4 -> 0 | F4: =E4 -> 0 | G4: =F4 -> 0 | H4: =G4 -> 0 | I4: =H4 -> 0 | J4: =I4 -> 0 | ... BA4: =AZ4 -> 0
A5: rail | B5: 0 | C5: =B5 -> 0 | D5: =C5 -> 0 | E5: =D5 -> 0 | F5: =E5 -> 0 | G5: =F5 -> 0 | H5: =G5 -> 0 | I5: =H5 -> 0 | J5: =I5 -> 0 | ... BA5: =AZ5 -> 0
A6: ships | B6: ='Deep Decarbonization'!N36/'SYVbT-freight'!E6/'AVLo-freight'!E6*0.621371*10^6 -> 43119.137 | C6: =B6 -> 43119.137 | D6: =C6 -> 43119.137 | E6: =D6 -> 43119.137 | F6: =E6 -> 43119.137 | G6: =F6 -> 43119.137 | H6: =G6 -> 43119.137 | I6: =H6 -> 43119.137 | J6: =I6 -> 43119.137 | ... BA6: =AZ6 -> 43119.137
A7: motorbikes | B7: 0 | C7: =B7 -> 0 | D7: =C7 -> 0 | E7: =D7 -> 0 | F7: =E7 -> 0 | G7: =F7 -> 0 | H7: =G7 -> 0 | I7: =H7 -> 0 | J7: =I7 -> 0 | ... BA7: =AZ7 -> 0
