Workbook

Sheet About
A1: CpUDSC Cost per Unit Distributed Solar Capacity
A3: Sources: | B3: Price Trajectory
B4: NREL
B5: 2020, 2022
B6: Annual Technology Baseline 2020, Annual Technology Baseline 2022
B7: https://atb.nrel.gov/
B8: "Solar - PV Dist. Res" tab
B9: "Solar - PV Dist. Comm" tab
B11: Solar DC to AC Derate Value
B12: Jens Schoene, EnerNex
B13: 2015
B14: Production Levels of Utility-Scale and Residential-Scale PV Systems
B15: http://brattle.com/system/publications/pdfs/000/005/188/original/Comparative_Generation_Costs_of_Utility-Scale_and_Residential-Scale_PV_in_Xcel_Energy_Colorado's_Service_Area.pdf?1436797265
B16: This document is included as Appendix B of a report by Brattle Group. It is on Page 10 of the EnerNex report, which is Page 70 of the PDF
B18: Share of Costs that are Soft Costs
B19: NREL
B20: 2018
B21: U.S. Solar Photovoltaic System Cost Benchmark: Q1 2018
B22: https://www.nrel.gov/docs/fy17osti/68925.pdf
B23: Page viii, Figure ES-2
A25: Notes
A26: We use the ATB "Moderate" case
A28: "Soft costs" (non-hardware costs, such as the cost of installation)
A29: are a subset of the total costs. Soft costs are not subject to
A30: reductions from endogenous learning.
A32: 2019 to 2012 | B32: 0.89805482
A33: 2020 to 2012 | B33: 0.88711067

Sheet DC to AC
A1: Watts DC are lower than Watts AC, but AC is needed to either sell to the grid or to power devices in homes.
A2: Therefore, we convert to the cost per Watt AC using a derate factor:
A3: 0.859 | B3: DC to AC derate factor

Sheet Solar - PV Dist. Comm 2021
A1: TEST | L1: https://atb.nrel.gov/electricity/2021/commercial_pv
T3: Inputs
J4: Take me to: | T4: Calculated
B7: X | G7: Assumptions
H9: Technology | J9: Basis Year: | L9: 2019
J10: All values are given in 2019 U.S. dollars, using the Consumer Price Index (BLS, 2020) for dollar year conversions. Projections use an inflation assumption of 2.5% per year.
J11: Commercial Solar Photovoltaic
J14: Representative Dist. Commercial system is fixed-tilt roof mounted with capacity of 300 kW
J15: Overnight Capital Cost, Capacity Factor, Fixed O&M, and Variable O&M costs
J16: represent $/kW DC; however LCOE reflects $/MWh AC.
J17: Capacity factors chosen here to reflect range across the continental U.S. using NREL PVWATTS
N20: Available | O20: Available
N21: Capacity | O21: Generation
N22: (GW) | O22: (GWh)
N23: 386 | O23: 506000
L26: ATB values reflect annual average capacity factor over life of plant including estimated degradation, starting at 0.7% per year, reducing to 0.2%, 0.5%, and 0.5% annual degradation by 2050 for the advanced, moderate, and conservative scenarios, respectively. Capacity factors also assume an energy yield gain at the module of 10%, 5%, and 2.5% for advanced, moderate, and conservatives scenarios.
H32: Finance | J32: Financial Assumptions:
J33: Inflation Rate | N33: =L63 -> 0.025
J34: Capital Recovery Period (Years) | N34: =S34 -> 30 | S34: 30
J35: Interest Rate Nominal - Moderate | N35: =L65 -> 0.04
J36: Calculated Interest Rate Real - Moderate | N36: =L68 -> 0.014634146
J37: Interest During Construction - Nominal | N37: =L70 -> 0.035
J38: Rate of Return on Equity Nominal - Moderate | N38: =L72 -> 0.088
J39: Calculated Rate of Return on Equity Real - Moderate | N39: =L75 -> 0.061463415
J40: Debt Fraction - Moderate | N40: =L78 -> 0.759
J41: Tax Rate (Federal and State) | N41: =L80 -> 0.2574
J42: WACC Nominal - Moderate | N42: =L82 -> 0.043753336
J43: WACC Real - Moderate | N43: =L85 -> 0.018295938
J44: Depreciation Period | N44: 5
J45: Construction Finance Factor | N45: =SUMPRODUCT(K57:K59,L57:L59,M57:M59)+SUMPRODUCT(K57:K59,O57:O59,N57:N59) -> 1.0244028
J46: Present Value of Depreciation | N46: =SUMPRODUCT(R56:W56,R58:W58) -> 0.88881179
J47: Project Finance Factor | N47: =(1 - N41 * N46) / (1 - N41) -> 1.0385401
J48: Capital Recovery Factor (CRF) Nominal - Moderate | N48: =L88 -> 0.060494177
J49: Capital Recovery Factor (CRF) Real - Moderate | N49: =L91 -> 0.043610542
J50: Equity Premium During Construction | N50: 0.02
J51: Cost of equity during construction | N51: =N38+N50 -> 0.108
J52: Construction Duration yrs | L52: 1
J53: Year | K53: Capital | L53: Accumulated | M53: Percent of Leverage During Construction | N53: Percent of Equity During Construction | O53: Accumulated Equity Cost
J54: Index | K54: Fraction | L54: Interest
Q55: MACRS yr | R55: 1 | S55: 2 | T55: 3 | U55: 4 | V55: 5 | W55: 6
...

Sheet Solar - PV Dist. Comm 2022
A1: Solar Distributed Commercial PV | M1: https://atb.nrel.gov/electricity/2022/commercial_pv
U2: Inputs
U3: Calculated
U4: Input from other tab
B7: X | G7: Assumptions
H9: Technology | J9: Base Year: | M9: 2020
J10: All values are given in 2020 U.S. dollars, using the Consumer Price Index (BLS, 2021) for dollar year conversions where source dollar years don't match 2020.
J11: Commercial Solar Photovoltaic
J14: Representative Dist. Commercial system is fixed-tilt roof mounted with capacity of 200 kW
J15: Overnight Capital Cost, Capacity Factor, Fixed O&M, and Variable O&M costs
J16: represent $/kW DC; however LCOE reflects $/MWh AC.
J17: Capacity factors chosen here to reflect range across the continental U.S. using NREL PVWATTS.
O20: Available | P20: Available
O21: Capacity | P21: Generation
O22: (GW) | P22: (GWh)
O23: 386 | P23: 506000
M26: ATB values reflect annual average capacity factor over life of plant including estimated degradation, starting at 0.7% per year, reducing to 0.2%, 0.5%, and 0.5% annual degradation by 2050 for the advanced, moderate, and conservative scenarios, respectively. Capacity factors also assume an energy yield gain at the module of 10%, 5%, and 2.5% for advanced, moderate, and conservatives scenarios.
H32: Finance | J32: Financial Assumptions:
J33: Capital Recovery Period (Years) | O33: =S34 -> 30 | Q33: Financial Case | S33: ='[2]Financial and CRP Inputs'!$B$5 -> Market
J34: Depreciation Period | O34: 5 | Q34: Capital Recovery Period | S34: =IF('[2]Financial and CRP Inputs'!$E$5="Custom",'[2]Financial and CRP Inputs'!$J$9,IF('[2]Financial and CRP Inputs'!$E$5="TechLife",'[2]Financial and CRP Inputs'!$I$9,'[2]Financial and CRP Inputs'!$E$5)) -> 30
J35: Equity Premium During Construction | O35: 0.02
J36: Construction Duration yrs | O36: 1
J37: Year | K37: Capital | L37: Percent of Leverage During Construction | M37: Percent of Equity During Construction
J38: Index | K38: Fraction
J41: 0 | K41: 1 | L41: 0.8 | M41: =1-L41 -> 0.2
J42: 1 | K42: 0 | L42: 0.8 | M42: =1-L42 -> 0.2
J43: 2 | K43: 0 | L43: 0.8 | M43: =1-L43 -> 0.2
M45: Base Year
M46: 2020 | N46: 2021 | O46: 2022 | P46: 2023 | Q46: 2024 | R46: 2025 | S46: 2026 | T46: 2027 | U46: 2028 | V46: 2029 | W46: 2030 | X46: 2031 | Y46: 2032 | Z46: 2033 | AA46: 2034 | AB46: 2035 | AC46: 2036 | AD46: 2037 | AE46: 2038 | AF46: 2039 | AG46: 2040 | AH46: 2041 | AI46: 2042 | AJ46: 2043 | AK46: 2044 | AL46: 2045 | AM46: 2046 | AN46: 2047 | AO46: 2048 | AP46: 2049 | AQ46: 2050
J47: Assumptions | K47: Inflation Rate | L47: * | M47: =IF($S$33="Market",'[2]WACC Calc'!F159,'[2]WACC Calc'!F524) -> 0.025 | N47: =IF($S$33="Market",'[2]WACC Calc'!G159,'[2]WACC Calc'!G524) -> 0.025 | O47: =IF($S$33="Market",'[2]WACC Calc'!H159,'[2]WACC Calc'!H524) -> 0.025 | P47: =IF($S$33="Market",'[2]WACC Calc'!I159,'[2]WACC Calc'!I524) -> 0.025 | Q47: =IF($S$33="Market",'[2]WACC Calc'!J159,'[2]WACC Calc'!J524) -> 0.025 | R47: =IF($S$33="Market",'[2]WACC Calc'!K159,'[2]WACC Calc'!K524) -> 0.025 | S47: =IF($S$33="Market",'[2]WACC Calc'!L159,'[2]WACC Calc'!L524) -> 0.025 | T47: =IF($S$33="Market",'[2]WACC Calc'!M159,'[2]WACC Calc'!M524) -> 0.025 | ... AQ47: =IF($S$33="Market",'[2]WACC Calc'!AJ159,'[2]WACC Calc'!AJ524) -> 0.025
K48: Interest Rate Nominal | L48: Advanced | M48: =IF($S$33="Market",'[2]WACC Calc'!F160,'[2]WACC Calc'!F525) -> 0.04 | N48: =IF($S$33="Market",'[2]WACC Calc'!G160,'[2]WACC Calc'!G525) -> 0.04 | O48: =IF($S$33="Market",'[2]WACC Calc'!H160,'[2]WACC Calc'!H525) -> 0.04 | P48: =IF($S$33="Market",'[2]WACC Calc'!I160,'[2]WACC Calc'!I525) -> 0.04 | Q48: =IF($S$33="Market",'[2]WACC Calc'!J160,'[2]WACC Calc'!J525) -> 0.04 | R48: =IF($S$33="Market",'[2]WACC Calc'!K160,'[2]WACC Calc'!K525) -> 0.04 | S48: =IF($S$33="Market",'[2]WACC Calc'!L160,'[2]WACC Calc'!L525) -> 0.042 | T48: =IF($S$33="Market",'[2]WACC Calc'!M160,'[2]WACC Calc'!M525) -> 0.044 | ... AQ48: =IF($S$33="Market",'[2]WACC Calc'!AJ160,'[2]WACC Calc'!AJ525) -> 0.05
K49: Interest Rate Nominal | L49: Moderate | M49: =IF($S$33="Market",'[2]WACC Calc'!F161,'[2]WACC Calc'!F526) -> 0.04 | N49: =IF($S$33="Market",'[2]WACC Calc'!G161,'[2]WACC Calc'!G526) -> 0.04 | O49: =IF($S$33="Market",'[2]WACC Calc'!H161,'[2]WACC Calc'!H526) -> 0.04 | P49: =IF($S$33="Market",'[2]WACC Calc'!I161,'[2]WACC Calc'!I526) -> 0.04 | Q49: =IF($S$33="Market",'[2]WACC Calc'!J161,'[2]WACC Calc'!J526) -> 0.04 | R49: =IF($S$33="Market",'[2]WACC Calc'!K161,'[2]WACC Calc'!K526) -> 0.04 | S49: =IF($S$33="Market",'[2]WACC Calc'!L161,'[2]WACC Calc'!L526) -> 0.042 | T49: =IF($S$33="Market",'[2]WACC Calc'!M161,'[2]WACC Calc'!M526) -> 0.044 | ... AQ49: =IF($S$33="Market",'[2]WACC Calc'!AJ161,'[2]WACC Calc'!AJ526) -> 0.05
K50: Interest Rate Nominal | L50: Conservative | M50: =IF($S$33="Market",'[2]WACC Calc'!F162,'[2]WACC Calc'!F527) -> 0.04 | N50: =IF($S$33="Market",'[2]WACC Calc'!G162,'[2]WACC Calc'!G527) -> 0.04 | O50: =IF($S$33="Market",'[2]WACC Calc'!H162,'[2]WACC Calc'!H527) -> 0.04 | P50: =IF($S$33="Market",'[2]WACC Calc'!I162,'[2]WACC Calc'!I527) -> 0.04 | Q50: =IF($S$33="Market",'[2]WACC Calc'!J162,'[2]WACC Calc'!J527) -> 0.04 | R50: =IF($S$33="Market",'[2]WACC Calc'!K162,'[2]WACC Calc'!K527) -> 0.04 | S50: =IF($S$33="Market",'[2]WACC Calc'!L162,'[2]WACC Calc'!L527) -> 0.042 | T50: =IF($S$33="Market",'[2]WACC Calc'!M162,'[2]WACC Calc'!M527) -> 0.044 | ... AQ50: =IF($S$33="Market",'[2]WACC Calc'!AJ162,'[2]WACC Calc'!AJ527) -> 0.05
K51: Calculated Interest Rate Real | L51: Advanced | M51: =(1+M48)/(1+M$47) - 1 -> 0.014634146 | N51: =(1+N48)/(1+N$47) - 1 -> 0.014634146 | O51: =(1+O48)/(1+O$47) - 1 -> 0.014634146 | P51: =(1+P48)/(1+P$47) - 1 -> 0.014634146 | Q51: =(1+Q48)/(1+Q$47) - 1 -> 0.014634146 | R51: =(1+R48)/(1+R$47) - 1 -> 0.014634146 | S51: =(1+S48)/(1+S$47) - 1 -> 0.016585366 | T51: =(1+T48)/(1+T$47) - 1 -> 0.018536585 | ... AQ51: =(1+AQ48)/(1+AQ$47) - 1 -> 0.024390244
K52: Calculated Interest Rate Real | L52: Moderate | M52: =(1+M49)/(1+M$47) - 1 -> 0.014634146 | N52: =(1+N49)/(1+N$47) - 1 -> 0.014634146 | O52: =(1+O49)/(1+O$47) - 1 -> 0.014634146 | P52: =(1+P49)/(1+P$47) - 1 -> 0.014634146 | Q52: =(1+Q49)/(1+Q$47) - 1 -> 0.014634146 | R52: =(1+R49)/(1+R$47) - 1 -> 0.014634146 | S52: =(1+S49)/(1+S$47) - 1 -> 0.016585366 | T52: =(1+T49)/(1+T$47) - 1 -> 0.018536585 | ... AQ52: =(1+AQ49)/(1+AQ$47) - 1 -> 0.024390244
K53: Calculated Interest Rate Real | L53: Conservative | M53: =(1+M50)/(1+M$47) - 1 -> 0.014634146 | N53: =(1+N50)/(1+N$47) - 1 -> 0.014634146 | O53: =(1+O50)/(1+O$47) - 1 -> 0.014634146 | P53: =(1+P50)/(1+P$47) - 1 -> 0.014634146 | Q53: =(1+Q50)/(1+Q$47) - 1 -> 0.014634146 | R53: =(1+R50)/(1+R$47) - 1 -> 0.014634146 | S53: =(1+S50)/(1+S$47) - 1 -> 0.016585366 | T53: =(1+T50)/(1+T$47) - 1 -> 0.018536585 | ... AQ53: =(1+AQ50)/(1+AQ$47) - 1 -> 0.024390244
K54: Interest During Construction - Nominal | L54: * | M54: =IF($S$33="Market",'[2]WACC Calc'!F166,'[2]WACC Calc'!F531) -> 0.035 | N54: =IF($S$33="Market",'[2]WACC Calc'!G166,'[2]WACC Calc'!G531) -> 0.035 | O54: =IF($S$33="Market",'[2]WACC Calc'!H166,'[2]WACC Calc'!H531) -> 0.035 | P54: =IF($S$33="Market",'[2]WACC Calc'!I166,'[2]WACC Calc'!I531) -> 0.035 | Q54: =IF($S$33="Market",'[2]WACC Calc'!J166,'[2]WACC Calc'!J531) -> 0.035 | R54: =IF($S$33="Market",'[2]WACC Calc'!K166,'[2]WACC Calc'!K531) -> 0.035 | S54: =IF($S$33="Market",'[2]WACC Calc'!L166,'[2]WACC Calc'!L531) -> 0.037 | T54: =IF($S$33="Market",'[2]WACC Calc'!M166,'[2]WACC Calc'!M531) -> 0.039 | ... AQ54: =IF($S$33="Market",'[2]WACC Calc'!AJ166,'[2]WACC Calc'!AJ531) -> 0.045
K55: Rate of Return on Equity Nominal | L55: Advanced | M55: =IF($S$33="Market",'[2]WACC Calc'!F167,'[2]WACC Calc'!F532) -> 0.0875 | N55: =IF($S$33="Market",'[2]WACC Calc'!G167,'[2]WACC Calc'!G532) -> 0.0875 | O55: =IF($S$33="Market",'[2]WACC Calc'!H167,'[2]WACC Calc'!H532) -> 0.0875 | P55: =IF($S$33="Market",'[2]WACC Calc'!I167,'[2]WACC Calc'!I532) -> 0.0875 | Q55: =IF($S$33="Market",'[2]WACC Calc'!J167,'[2]WACC Calc'!J532) -> 0.0875 | R55: =IF($S$33="Market",'[2]WACC Calc'!K167,'[2]WACC Calc'!K532) -> 0.0875 | S55: =IF($S$33="Market",'[2]WACC Calc'!L167,'[2]WACC Calc'!L532) -> 0.0875 | T55: =IF($S$33="Market",'[2]WACC Calc'!M167,'[2]WACC Calc'!M532) -> 0.0875 | ... AQ55: =IF($S$33="Market",'[2]WACC Calc'!AJ167,'[2]WACC Calc'!AJ532) -> 0.0875
K56: Rate of Return on Equity Nominal | L56: Moderate | M56: =IF($S$33="Market",'[2]WACC Calc'!F168,'[2]WACC Calc'!F533) -> 0.0875 | N56: =IF($S$33="Market",'[2]WACC Calc'!G168,'[2]WACC Calc'!G533) -> 0.0875 | O56: =IF($S$33="Market",'[2]WACC Calc'!H168,'[2]WACC Calc'!H533) -> 0.0875 | P56: =IF($S$33="Market",'[2]WACC Calc'!I168,'[2]WACC Calc'!I533) -> 0.0875 | Q56: =IF($S$33="Market",'[2]WACC Calc'!J168,'[2]WACC Calc'!J533) -> 0.0875 | R56: =IF($S$33="Market",'[2]WACC Calc'!K168,'[2]WACC Calc'!K533) -> 0.0875 | S56: =IF($S$33="Market",'[2]WACC Calc'!L168,'[2]WACC Calc'!L533) -> 0.0875 | T56: =IF($S$33="Market",'[2]WACC Calc'!M168,'[2]WACC Calc'!M533) -> 0.0875 | ... AQ56: =IF($S$33="Market",'[2]WACC Calc'!AJ168,'[2]WACC Calc'!AJ533) -> 0.0875
K57: Rate of Return on Equity Nominal | L57: Conservative | M57: =IF($S$33="Market",'[2]WACC Calc'!F169,'[2]WACC Calc'!F534) -> 0.0875 | N57: =IF($S$33="Market",'[2]WACC Calc'!G169,'[2]WACC Calc'!G534) -> 0.0875 | O57: =IF($S$33="Market",'[2]WACC Calc'!H169,'[2]WACC Calc'!H534) -> 0.0875 | P57: =IF($S$33="Market",'[2]WACC Calc'!I169,'[2]WACC Calc'!I534) -> 0.0875 | Q57: =IF($S$33="Market",'[2]WACC Calc'!J169,'[2]WACC Calc'!J534) -> 0.0875 | R57: =IF($S$33="Market",'[2]WACC Calc'!K169,'[2]WACC Calc'!K534) -> 0.0875 | S57: =IF($S$33="Market",'[2]WACC Calc'!L169,'[2]WACC Calc'!L534) -> 0.0875 | T57: =IF($S$33="Market",'[2]WACC Calc'!M169,'[2]WACC Calc'!M534) -> 0.0875 | ... AQ57: =IF($S$33="Market",'[2]WACC Calc'!AJ169,'[2]WACC Calc'!AJ534) -> 0.0875
...

Sheet NREL calcs
C1: Commercial PV - Class 10 - Moderate
C2: 2019$/kw | D2: 2012$/kw
B3: 2019 | C3: =INDEX('Solar - PV Dist. Comm 2021'!$L$165:$BK$165,MATCH('NREL calcs'!$B3,'Solar - PV Dist. Comm 2021'!$L$163:$BK$163,0)) -> 1806.4626 | D3: =C3*About!$B$32 -> 1622.3025
B4: 2020 | C4: =INDEX('Solar - PV Dist. Comm 2022'!$M$149:$BK$149,MATCH('NREL calcs'!$B4,'Solar - PV Dist. Comm 2022'!$M$147:$BK$147,0)) -> 1783.5623 | D4: =C4*About!$B$33 -> 1582.2171
B5: 2021 | C5: =INDEX('Solar - PV Dist. Comm 2022'!$M$149:$BK$149,MATCH('NREL calcs'!$B5,'Solar - PV Dist. Comm 2022'!$M$147:$BK$147,0)) -> 1597.9942 | D5: =C5*About!$B$33 -> 1417.5977
B6: 2022 | C6: =INDEX('Solar - PV Dist. Comm 2022'!$M$149:$BK$149,MATCH('NREL calcs'!$B6,'Solar - PV Dist. Comm 2022'!$M$147:$BK$147,0)) -> 1523.0419 | D6: =C6*About!$B$33 -> 1351.1067
B7: 2023 | C7: =INDEX('Solar - PV Dist. Comm 2022'!$M$149:$BK$149,MATCH('NREL calcs'!$B7,'Solar - PV Dist. Comm 2022'!$M$147:$BK$147,0)) -> 1448.0895 | D7: =C7*About!$B$33 -> 1284.6157
B8: 2024 | C8: =INDEX('Solar - PV Dist. Comm 2022'!$M$149:$BK$149,MATCH('NREL calcs'!$B8,'Solar - PV Dist. Comm 2022'!$M$147:$BK$147,0)) -> 1373.1372 | D8: =C8*About!$B$33 -> 1218.1247
B9: 2025 | C9: =INDEX('Solar - PV Dist. Comm 2022'!$M$149:$BK$149,MATCH('NREL calcs'!$B9,'Solar - PV Dist. Comm 2022'!$M$147:$BK$147,0)) -> 1298.1849 | D9: =C9*About!$B$33 -> 1151.6337
B10: 2026 | C10: =INDEX('Solar - PV Dist. Comm 2022'!$M$149:$BK$149,MATCH('NREL calcs'!$B10,'Solar - PV Dist. Comm 2022'!$M$147:$BK$147,0)) -> 1224.1711 | D10: =C10*About!$B$33 -> 1085.9753
B11: 2027 | C11: =INDEX('Solar - PV Dist. Comm 2022'!$M$149:$BK$149,MATCH('NREL calcs'!$B11,'Solar - PV Dist. Comm 2022'!$M$147:$BK$147,0)) -> 1150.0415 | D11: =C11*About!$B$33 -> 1020.2141
B12: 2028 | C12: =INDEX('Solar - PV Dist. Comm 2022'!$M$149:$BK$149,MATCH('NREL calcs'!$B12,'Solar - PV Dist. Comm 2022'!$M$147:$BK$147,0)) -> 1075.7962 | D12: =C12*About!$B$33 -> 954.35029
B13: 2029 | C13: =INDEX('Solar - PV Dist. Comm 2022'!$M$149:$BK$149,MATCH('NREL calcs'!$B13,'Solar - PV Dist. Comm 2022'!$M$147:$BK$147,0)) -> 1001.4353 | D13: =C13*About!$B$33 -> 888.38398
B14: 2030 | C14: =INDEX('Solar - PV Dist. Comm 2022'!$M$149:$BK$149,MATCH('NREL calcs'!$B14,'Solar - PV Dist. Comm 2022'!$M$147:$BK$147,0)) -> 926.95913 | D14: =C14*About!$B$33 -> 822.31534
B15: 2031 | C15: =INDEX('Solar - PV Dist. Comm 2022'!$M$149:$BK$149,MATCH('NREL calcs'!$B15,'Solar - PV Dist. Comm 2022'!$M$147:$BK$147,0)) -> 916.1923 | D15: =C15*About!$B$33 -> 812.76396
... B54: 2070 | C54: =INDEX('Solar - PV Dist. Comm 2022'!$M$149:$BK$149,MATCH('NREL calcs'!$B54,'Solar - PV Dist. Comm 2022'!$M$147:$BK$147,0)) -> 527.00722 | D54: =C54*About!$B$33 -> 467.51373

Sheet NREL ATB
A1: Tab Solar - PV Dist. Res
C3: 2018 | D3: 2019 | E3: 2020 | F3: 2021 | G3: 2022 | H3: 2023 | I3: 2024 | J3: 2025 | K3: 2026 | L3: 2027 | M3: 2028 | N3: 2029 | O3: 2030 | P3: 2031 | Q3: 2032 | R3: 2033 | S3: 2034 | T3: 2035 | U3: 2036 | V3: 2037 | W3: 2038 | X3: 2039 | Y3: 2040 | Z3: 2041 | AA3: 2042 | AB3: 2043 | AC3: 2044 | AD3: 2045 | AE3: 2046 | AF3: 2047 | AG3: 2048 | AH3: 2049 | AI3: 2050
A4: Overnight Capital Cost ($/kW) | B4: Res PV - Seattle - Advanced | C4: 3054.3182 | D4: 2796.2451 | E4: 2620.0098 | F4: 2443.7745 | G4: 2267.5393 | H4: 2091.304 | I4: 1915.0687 | J4: 1738.8334 | K4: 1562.5982 | L4: 1386.3629 | M4: 1210.1276 | N4: 1033.8924 | O4: 857.65708 | P4: 844.89528 | Q4: 832.13347 | R4: 819.37166 | S4: 806.60985 | T4: 793.84804 | U4: 781.08623 | V4: 768.32443 | W4: 755.56262 | X4: 742.80081 | Y4: 730.039 | Z4: 717.27719 | AA4: 704.51539 | AB4: 691.75358 | AC4: 678.99177 | AD4: 666.22996 | AE4: 653.46815 | AF4: 640.70635 | AG4: 627.94454 | AH4: 615.18273 | AI4: 602.42092
B5: Res PV - Seattle - Moderate | C5: 3054.3182 | D5: 2796.2451 | E5: 2644.2787 | F5: 2492.3123 | G5: 2340.3458 | H5: 2188.3794 | I5: 2036.413 | J5: 1884.4466 | K5: 1732.4802 | L5: 1580.5138 | M5: 1428.5474 | N5: 1276.581 | O5: 1124.6146 | P5: 1111.2667 | Q5: 1097.9188 | R5: 1084.571 | S5: 1071.2231 | T5: 1057.8752 | U5: 1044.5273 | V5: 1031.1795 | W5: 1017.8316 | X5: 1004.4837 | Y5: 991.13583 | Z5: 977.78796 | AA5: 964.44008 | AB5: 951.09221 | AC5: 937.74433 | AD5: 924.39646 | AE5: 911.04858 | AF5: 897.70071 | AG5: 884.35283 | AH5: 871.00496 | AI5: 857.65708
B6: Res PV - Seattle - Conservative | C6: 3054.3182 | D6: 2796.2451 | E6: 2762.9654 | F6: 2729.6857 | G6: 2696.406 | H6: 2663.1263 | I6: 2629.8467 | J6: 2596.567 | K6: 2563.2873 | L6: 2530.0076 | M6: 2496.7279 | N6: 2463.4482 | O6: 2430.1685 | P6: 2364.8909 | Q6: 2299.6132 | R6: 2234.3355 | S6: 2169.0578 | T6: 2103.7801 | U6: 2038.5024 | V6: 1973.2247 | W6: 1907.947 | X6: 1842.6693 | Y6: 1777.3916 | Z6: 1712.1139 | AA6: 1646.8362 | AB6: 1581.5585 | AC6: 1516.2808 | AD6: 1451.0031 | AE6: 1385.7254 | AF6: 1320.4477 | AG6: 1255.17 | AH6: 1189.8923 | AI6: 1124.6146
B7: Res PV - Chicago - Advanced | C7: 3054.3182 | D7: 2796.2451 | E7: 2620.0098 | F7: 2443.7745 | G7: 2267.5393 | H7: 2091.304 | I7: 1915.0687 | J7: 1738.8334 | K7: 1562.5982 | L7: 1386.3629 | M7: 1210.1276 | N7: 1033.8924 | O7: 857.65708 | P7: 844.89528 | Q7: 832.13347 | R7: 819.37166 | S7: 806.60985 | T7: 793.84804 | U7: 781.08623 | V7: 768.32443 | W7: 755.56262 | X7: 742.80081 | Y7: 730.039 | Z7: 717.27719 | AA7: 704.51539 | AB7: 691.75358 | AC7: 678.99177 | AD7: 666.22996 | AE7: 653.46815 | AF7: 640.70635 | AG7: 627.94454 | AH7: 615.18273 | AI7: 602.42092
B8: Res PV - Chicago - Moderate | C8: 3054.3182 | D8: 2796.2451 | E8: 2644.2787 | F8: 2492.3123 | G8: 2340.3458 | H8: 2188.3794 | I8: 2036.413 | J8: 1884.4466 | K8: 1732.4802 | L8: 1580.5138 | M8: 1428.5474 | N8: 1276.581 | O8: 1124.6146 | P8: 1111.2667 | Q8: 1097.9188 | R8: 1084.571 | S8: 1071.2231 | T8: 1057.8752 | U8: 1044.5273 | V8: 1031.1795 | W8: 1017.8316 | X8: 1004.4837 | Y8: 991.13583 | Z8: 977.78796 | AA8: 964.44008 | AB8: 951.09221 | AC8: 937.74433 | AD8: 924.39646 | AE8: 911.04858 | AF8: 897.70071 | AG8: 884.35283 | AH8: 871.00496 | AI8: 857.65708
B9: Res PV - Chicago - Conservative | C9: 3054.3182 | D9: 2796.2451 | E9: 2762.9654 | F9: 2729.6857 | G9: 2696.406 | H9: 2663.1263 | I9: 2629.8467 | J9: 2596.567 | K9: 2563.2873 | L9: 2530.0076 | M9: 2496.7279 | N9: 2463.4482 | O9: 2430.1685 | P9: 2364.8909 | Q9: 2299.6132 | R9: 2234.3355 | S9: 2169.0578 | T9: 2103.7801 | U9: 2038.5024 | V9: 1973.2247 | W9: 1907.947 | X9: 1842.6693 | Y9: 1777.3916 | Z9: 1712.1139 | AA9: 1646.8362 | AB9: 1581.5585 | AC9: 1516.2808 | AD9: 1451.0031 | AE9: 1385.7254 | AF9: 1320.4477 | AG9: 1255.17 | AH9: 1189.8923 | AI9: 1124.6146
B10: Res PV - Kansas City - Advanced | C10: 3054.3182 | D10: 2796.2451 | E10: 2620.0098 | F10: 2443.7745 | G10: 2267.5393 | H10: 2091.304 | I10: 1915.0687 | J10: 1738.8334 | K10: 1562.5982 | L10: 1386.3629 | M10: 1210.1276 | N10: 1033.8924 | O10: 857.65708 | P10: 844.89528 | Q10: 832.13347 | R10: 819.37166 | S10: 806.60985 | T10: 793.84804 | U10: 781.08623 | V10: 768.32443 | W10: 755.56262 | X10: 742.80081 | Y10: 730.039 | Z10: 717.27719 | AA10: 704.51539 | AB10: 691.75358 | AC10: 678.99177 | AD10: 666.22996 | AE10: 653.46815 | AF10: 640.70635 | AG10: 627.94454 | AH10: 615.18273 | AI10: 602.42092
B11: Res PV - Kansas City - Moderate | C11: 3054.3182 | D11: 2796.2451 | E11: 2644.2787 | F11: 2492.3123 | G11: 2340.3458 | H11: 2188.3794 | I11: 2036.413 | J11: 1884.4466 | K11: 1732.4802 | L11: 1580.5138 | M11: 1428.5474 | N11: 1276.581 | O11: 1124.6146 | P11: 1111.2667 | Q11: 1097.9188 | R11: 1084.571 | S11: 1071.2231 | T11: 1057.8752 | U11: 1044.5273 | V11: 1031.1795 | W11: 1017.8316 | X11: 1004.4837 | Y11: 991.13583 | Z11: 977.78796 | AA11: 964.44008 | AB11: 951.09221 | AC11: 937.74433 | AD11: 924.39646 | AE11: 911.04858 | AF11: 897.70071 | AG11: 884.35283 | AH11: 871.00496 | AI11: 857.65708
B12: Res PV - Kansas City - Conservative | C12: 3054.3182 | D12: 2796.2451 | E12: 2762.9654 | F12: 2729.6857 | G12: 2696.406 | H12: 2663.1263 | I12: 2629.8467 | J12: 2596.567 | K12: 2563.2873 | L12: 2530.0076 | M12: 2496.7279 | N12: 2463.4482 | O12: 2430.1685 | P12: 2364.8909 | Q12: 2299.6132 | R12: 2234.3355 | S12: 2169.0578 | T12: 2103.7801 | U12: 2038.5024 | V12: 1973.2247 | W12: 1907.947 | X12: 1842.6693 | Y12: 1777.3916 | Z12: 1712.1139 | AA12: 1646.8362 | AB12: 1581.5585 | AC12: 1516.2808 | AD12: 1451.0031 | AE12: 1385.7254 | AF12: 1320.4477 | AG12: 1255.17 | AH12: 1189.8923 | AI12: 1124.6146
B13: Res PV - Los Angeles - Advanced | C13: 3054.3182 | D13: 2796.2451 | E13: 2620.0098 | F13: 2443.7745 | G13: 2267.5393 | H13: 2091.304 | I13: 1915.0687 | J13: 1738.8334 | K13: 1562.5982 | L13: 1386.3629 | M13: 1210.1276 | N13: 1033.8924 | O13: 857.65708 | P13: 844.89528 | Q13: 832.13347 | R13: 819.37166 | S13: 806.60985 | T13: 793.84804 | U13: 781.08623 | V13: 768.32443 | W13: 755.56262 | X13: 742.80081 | Y13: 730.039 | Z13: 717.27719 | AA13: 704.51539 | AB13: 691.75358 | AC13: 678.99177 | AD13: 666.22996 | AE13: 653.46815 | AF13: 640.70635 | AG13: 627.94454 | AH13: 615.18273 | AI13: 602.42092
B14: Res PV - Los Angeles - Moderate | C14: 3054.3182 | D14: 2796.2451 | E14: 2644.2787 | F14: 2492.3123 | G14: 2340.3458 | H14: 2188.3794 | I14: 2036.413 | J14: 1884.4466 | K14: 1732.4802 | L14: 1580.5138 | M14: 1428.5474 | N14: 1276.581 | O14: 1124.6146 | P14: 1111.2667 | Q14: 1097.9188 | R14: 1084.571 | S14: 1071.2231 | T14: 1057.8752 | U14: 1044.5273 | V14: 1031.1795 | W14: 1017.8316 | X14: 1004.4837 | Y14: 991.13583 | Z14: 977.78796 | AA14: 964.44008 | AB14: 951.09221 | AC14: 937.74433 | AD14: 924.39646 | AE14: 911.04858 | AF14: 897.70071 | AG14: 884.35283 | AH14: 871.00496 | AI14: 857.65708
B15: Res PV - Los Angeles - Conservative | C15: 3054.3182 | D15: 2796.2451 | E15: 2762.9654 | F15: 2729.6857 | G15: 2696.406 | H15: 2663.1263 | I15: 2629.8467 | J15: 2596.567 | K15: 2563.2873 | L15: 2530.0076 | M15: 2496.7279 | N15: 2463.4482 | O15: 2430.1685 | P15: 2364.8909 | Q15: 2299.6132 | R15: 2234.3355 | S15: 2169.0578 | T15: 2103.7801 | U15: 2038.5024 | V15: 1973.2247 | W15: 1907.947 | X15: 1842.6693 | Y15: 1777.3916 | Z15: 1712.1139 | AA15: 1646.8362 | AB15: 1581.5585 | AC15: 1516.2808 | AD15: 1451.0031 | AE15: 1385.7254 | AF15: 1320.4477 | AG15: 1255.17 | AH15: 1189.8923 | AI15: 1124.6146
B16: Res PV - Daggett, CA - Advanced | C16: 3054.3182 | D16: 2796.2451 | E16: 2620.0098 | F16: 2443.7745 | G16: 2267.5393 | H16: 2091.304 | I16: 1915.0687 | J16: 1738.8334 | K16: 1562.5982 | L16: 1386.3629 | M16: 1210.1276 | N16: 1033.8924 | O16: 857.65708 | P16: 844.89528 | Q16: 832.13347 | R16: 819.37166 | S16: 806.60985 | T16: 793.84804 | U16: 781.08623 | V16: 768.32443 | W16: 755.56262 | X16: 742.80081 | Y16: 730.039 | Z16: 717.27719 | AA16: 704.51539 | AB16: 691.75358 | AC16: 678.99177 | AD16: 666.22996 | AE16: 653.46815 | AF16: 640.70635 | AG16: 627.94454 | AH16: 615.18273 | AI16: 602.42092
... B18: Res PV - Daggett, CA - Conservative | C18: 3054.3182 | D18: 2796.2451 | E18: 2762.9654 | F18: 2729.6857 | G18: 2696.406 | H18: 2663.1263 | I18: 2629.8467 | J18: 2596.567 | K18: 2563.2873 | L18: 2530.0076 | M18: 2496.7279 | N18: 2463.4482 | O18: 2430.1685 | P18: 2364.8909 | Q18: 2299.6132 | R18: 2234.3355 | S18: 2169.0578 | T18: 2103.7801 | U18: 2038.5024 | V18: 1973.2247 | W18: 1907.947 | X18: 1842.6693 | Y18: 1777.3916 | Z18: 1712.1139 | AA18: 1646.8362 | AB18: 1581.5585 | AC18: 1516.2808 | AD18: 1451.0031 | AE18: 1385.7254 | AF18: 1320.4477 | AG18: 1255.17 | AH18: 1189.8923 | AI18: 1124.6146
A20: Representative Dist. Res system is fixed-tilt roof mounted with capacity of 5 kW
A21: Overnight Capital Cost, Capacity Factor, Fixed O&M, and Variable O&M costs
A22: represent $/kW DC; however LCOE reflects $/MWh AC.
A23: Capacity factors chosen here to reflect range of across the continental U.S. using NREL PVWATTS

Sheet Soft Cost Data
A1: Solar PV
A3: Solar PV Type | B3: Non-Hardware Cost %
A4: Residential | B4: 0.63
A5: Commercial | B5: 0.56
A6: Utility-Scale | B6: 0.35
A8: For distributed PV on buildings, we use the average
A9: of residential and commercial soft cost shares.
A10: Buildings | B10: =AVERAGE(B4:B5) -> 0.595

Sheet CpUDSC-totalcost
A1: Unit: $/MW | B1: Distributed Solar Total Cap Cost
A2: 2019 | B2: =(INDEX('NREL calcs'!$D$3:$D$54,MATCH('CpUDSC-totalcost'!$A2,'NREL calcs'!$B$3:$B$54,0))*1000)/'DC to AC'!$A$3 -> 1888594.2
A3: 2020 | B3: =(INDEX('NREL calcs'!$D$3:$D$54,MATCH('CpUDSC-totalcost'!$A3,'NREL calcs'!$B$3:$B$54,0))*1000)/'DC to AC'!$A$3 -> 1841929.2
A4: 2021 | B4: =(INDEX('NREL calcs'!$D$3:$D$54,MATCH('CpUDSC-totalcost'!$A4,'NREL calcs'!$B$3:$B$54,0))*1000)/'DC to AC'!$A$3 -> 1650288.4
A5: 2022 | B5: =(INDEX('NREL calcs'!$D$3:$D$54,MATCH('CpUDSC-totalcost'!$A5,'NREL calcs'!$B$3:$B$54,0))*1000)/'DC to AC'!$A$3 -> 1572883.2
A6: 2023 | B6: =(INDEX('NREL calcs'!$D$3:$D$54,MATCH('CpUDSC-totalcost'!$A6,'NREL calcs'!$B$3:$B$54,0))*1000)/'DC to AC'!$A$3 -> 1495478.1
A7: 2024 | B7: =(INDEX('NREL calcs'!$D$3:$D$54,MATCH('CpUDSC-totalcost'!$A7,'NREL calcs'!$B$3:$B$54,0))*1000)/'DC to AC'!$A$3 -> 1418073
A8: 2025 | B8: =(INDEX('NREL calcs'!$D$3:$D$54,MATCH('CpUDSC-totalcost'!$A8,'NREL calcs'!$B$3:$B$54,0))*1000)/'DC to AC'!$A$3 -> 1340667.8
A9: 2026 | B9: =(INDEX('NREL calcs'!$D$3:$D$54,MATCH('CpUDSC-totalcost'!$A9,'NREL calcs'!$B$3:$B$54,0))*1000)/'DC to AC'!$A$3 -> 1264232
A10: 2027 | B10: =(INDEX('NREL calcs'!$D$3:$D$54,MATCH('CpUDSC-totalcost'!$A10,'NREL calcs'!$B$3:$B$54,0))*1000)/'DC to AC'!$A$3 -> 1187676.5
A11: 2028 | B11: =(INDEX('NREL calcs'!$D$3:$D$54,MATCH('CpUDSC-totalcost'!$A11,'NREL calcs'!$B$3:$B$54,0))*1000)/'DC to AC'!$A$3 -> 1111001.5
A12: 2029 | B12: =(INDEX('NREL calcs'!$D$3:$D$54,MATCH('CpUDSC-totalcost'!$A12,'NREL calcs'!$B$3:$B$54,0))*1000)/'DC to AC'!$A$3 -> 1034207.2
A13: 2030 | B13: =(INDEX('NREL calcs'!$D$3:$D$54,MATCH('CpUDSC-totalcost'!$A13,'NREL calcs'!$B$3:$B$54,0))*1000)/'DC to AC'!$A$3 -> 957293.76
... A53: 2070 | B53: =(INDEX('NREL calcs'!$D$3:$D$54,MATCH('CpUDSC-totalcost'!$A53,'NREL calcs'!$B$3:$B$54,0))*1000)/'DC to AC'!$A$3 -> 544253.47

Sheet CpUDSC-softcosts
A1: Unit: $/MW | B1: Distributed Solar Soft Costs
A2: 2019 | B2: ='Soft Cost Data'!$B$10*'CpUDSC-totalcost'!B2 -> 1123713.6
A3: 2020 | B3: ='Soft Cost Data'!$B$10*'CpUDSC-totalcost'!B3 -> 1095947.8
A4: 2021 | B4: ='Soft Cost Data'!$B$10*'CpUDSC-totalcost'!B4 -> 981921.57
A5: 2022 | B5: ='Soft Cost Data'!$B$10*'CpUDSC-totalcost'!B5 -> 935865.52
A6: 2023 | B6: ='Soft Cost Data'!$B$10*'CpUDSC-totalcost'!B6 -> 889809.47
A7: 2024 | B7: ='Soft Cost Data'!$B$10*'CpUDSC-totalcost'!B7 -> 843753.42
A8: 2025 | B8: ='Soft Cost Data'!$B$10*'CpUDSC-totalcost'!B8 -> 797697.36
A9: 2026 | B9: ='Soft Cost Data'!$B$10*'CpUDSC-totalcost'!B9 -> 752218.04
A10: 2027 | B10: ='Soft Cost Data'!$B$10*'CpUDSC-totalcost'!B10 -> 706667.51
A11: 2028 | B11: ='Soft Cost Data'!$B$10*'CpUDSC-totalcost'!B11 -> 661045.89
A12: 2029 | B12: ='Soft Cost Data'!$B$10*'CpUDSC-totalcost'!B12 -> 615353.28
A13: 2030 | B13: ='Soft Cost Data'!$B$10*'CpUDSC-totalcost'!B13 -> 569589.78
... A53: 2070 | B53: ='Soft Cost Data'!$B$10*'CpUDSC-totalcost'!B53 -> 323830.82
