Workbook

Sheet About
A1: BDbDT BAU Deaths by Demographic Trait
A3: Source: | B3: U.S. Census Bureau
B4: 2017
B5: Projections for the United States: 2017-2060
B6: https://www.census.gov/data/datasets/2017/demo/popproj/2017-popproj.html
B7: Datasets, Table 3, Main Series
B8: Age columns have been removed to reduce filesize
A10: Notes
A11: Key information for the U.S. census file is:
A12: RACE_HISP column
A13: 0 | B13: total population
A14: 1 | B14: white alone
A15: 2 | B15: black alone
A16: 3 | B16: American Indian and Alaska Native alone
A17: 4 | B17: Asian alone
A18: 5 | B18: Native Hawaiian and Pacific Islander alone
A19: 6 | B19: Two or more races
A20: 7 | B20: Not Hispanic
A21: 8 | B21: Hispanic
A22: 9 | B22: Non-Hispanic White Alone
A24: SEX column
A25: 0 | B25: both sexes
A26: 1 | B26: male
A27: 2 | B27: female

Sheet Census T3
A1: RACE_HISP | B1: SEX | C1: YEAR | D1: TOTAL_DEATHS
A2: 0 | B2: 0 | C2: 2017 | D2: 2667093
A3: 0 | B3: 0 | C3: 2018 | D3: 2696006
A4: 0 | B4: 0 | C4: 2019 | D4: 2723837
A5: 0 | B5: 0 | C5: 2020 | D5: 2751811
A6: 0 | B6: 0 | C6: 2021 | D6: 2780803
A7: 0 | B7: 0 | C7: 2022 | D7: 2811336
A8: 0 | B8: 0 | C8: 2023 | D8: 2843763
A9: 0 | B9: 0 | C9: 2024 | D9: 2878325
A10: 0 | B10: 0 | C10: 2025 | D10: 2915138
A11: 0 | B11: 0 | C11: 2026 | D11: 2954248
A12: 0 | B12: 0 | C12: 2027 | D12: 2995840
A13: 0 | B13: 0 | C13: 2028 | D13: 3039790
... A45: 0 | B45: 0 | C45: 2060 | D45: 3905835
A46: 0 | B46: 0 | C46: 2061 | D46: =_xlfn.FORECAST.LINEAR(C46,D2:D45,C2:C45) -> 4212891.7
A47: 0 | B47: 0 | C47: 2062 | D47: =_xlfn.FORECAST.LINEAR(C47,D3:D46,C3:C46) -> 4244264.7
A48: 0 | B48: 0 | C48: 2063 | D48: =_xlfn.FORECAST.LINEAR(C48,D4:D47,C4:C47) -> 4274993.7
A49: 0 | B49: 0 | C49: 2064 | D49: =_xlfn.FORECAST.LINEAR(C49,D5:D48,C5:C48) -> 4304959.6
A50: 0 | B50: 0 | C50: 2065 | D50: =_xlfn.FORECAST.LINEAR(C50,D6:D49,C6:C49) -> 4334090.8
A51: 0 | B51: 0 | C51: 2066 | D51: =_xlfn.FORECAST.LINEAR(C51,D7:D50,C7:C50) -> 4362354.7
A52: 0 | B52: 0 | C52: 2067 | D52: =_xlfn.FORECAST.LINEAR(C52,D8:D51,C8:C51) -> 4389746.8
A53: 0 | B53: 0 | C53: 2068 | D53: =_xlfn.FORECAST.LINEAR(C53,D9:D52,C9:C52) -> 4416287.3
A54: 0 | B54: 0 | C54: 2069 | D54: =_xlfn.FORECAST.LINEAR(C54,D10:D53,C10:C53) -> 4442018.4
A55: 0 | B55: 0 | C55: 2070 | D55: =_xlfn.FORECAST.LINEAR(C55,D11:D54,C11:C54) -> 4467001.6
A56: 0 | B56: 1 | C56: 2017 | D56: 1349944
A57: 0 | B57: 1 | C57: 2018 | D57: 1366331
A58: 0 | B58: 1 | C58: 2019 | D58: 1382584
A59: 0 | B59: 1 | C59: 2020 | D59: 1399014
A60: 0 | B60: 1 | C60: 2021 | D60: 1415904
A61: 0 | B61: 1 | C61: 2022 | D61: 1433335
A62: 0 | B62: 1 | C62: 2023 | D62: 1451474
A63: 0 | B63: 1 | C63: 2024 | D63: 1470351
A64: 0 | B64: 1 | C64: 2025 | D64: 1490023
A65: 0 | B65: 1 | C65: 2026 | D65: 1510466
A66: 0 | B66: 1 | C66: 2027 | D66: 1531731
A67: 0 | B67: 1 | C67: 2028 | D67: 1553790
... A99: 0 | B99: 1 | C99: 2060 | D99: 1914265
A100: 0 | B100: 1 | C100: 2061 | D100: =_xlfn.FORECAST.LINEAR(C100,D56:D99,C56:C99) -> 2056961.4
A101: 0 | B101: 1 | C101: 2062 | D101: =_xlfn.FORECAST.LINEAR(C101,D57:D100,C57:C100) -> 2069116.6
A102: 0 | B102: 1 | C102: 2063 | D102: =_xlfn.FORECAST.LINEAR(C102,D58:D101,C58:C101) -> 2080931.6
...

Sheet BDbDT
B1: 2020 | C1: 2021 | D1: 2022 | E1: 2023 | F1: 2024 | G1: 2025 | H1: 2026 | I1: 2027 | J1: 2028 | K1: 2029 | L1: 2030 | M1: 2031 | N1: 2032 | O1: 2033 | P1: 2034 | Q1: 2035 | R1: 2036 | S1: 2037 | T1: 2038 | U1: 2039 | V1: 2040 | W1: 2041 | X1: 2042 | Y1: 2043 | Z1: 2044 | AA1: 2045 | AB1: 2046 | AC1: 2047 | AD1: 2048 | AE1: 2049 | AF1: 2050 | AG1: 2051 | AH1: 2052 | AI1: 2053 | AJ1: 2054 | AK1: 2055 | AL1: 2056 | AM1: 2057 | AN1: 2058 | AO1: 2059 | AP1: 2060 | AQ1: 2061 | AR1: 2062 | AS1: 2063 | AT1: 2064 | AU1: 2065 | AV1: 2066 | AW1: 2067 | AX1: 2068 | AY1: 2069 | AZ1: 2070
A2: male | B2: =SUMIFS('Census T3'!$D:$D,'Census T3'!$A:$A,0,'Census T3'!$B:$B,1,'Census T3'!$C:$C,B$1) -> 1399014 | C2: =SUMIFS('Census T3'!$D:$D,'Census T3'!$A:$A,0,'Census T3'!$B:$B,1,'Census T3'!$C:$C,C$1) -> 1415904 | D2: =SUMIFS('Census T3'!$D:$D,'Census T3'!$A:$A,0,'Census T3'!$B:$B,1,'Census T3'!$C:$C,D$1) -> 1433335 | E2: =SUMIFS('Census T3'!$D:$D,'Census T3'!$A:$A,0,'Census T3'!$B:$B,1,'Census T3'!$C:$C,E$1) -> 1451474 | F2: =SUMIFS('Census T3'!$D:$D,'Census T3'!$A:$A,0,'Census T3'!$B:$B,1,'Census T3'!$C:$C,F$1) -> 1470351 | G2: =SUMIFS('Census T3'!$D:$D,'Census T3'!$A:$A,0,'Census T3'!$B:$B,1,'Census T3'!$C:$C,G$1) -> 1490023 | H2: =SUMIFS('Census T3'!$D:$D,'Census T3'!$A:$A,0,'Census T3'!$B:$B,1,'Census T3'!$C:$C,H$1) -> 1510466 | I2: =SUMIFS('Census T3'!$D:$D,'Census T3'!$A:$A,0,'Census T3'!$B:$B,1,'Census T3'!$C:$C,I$1) -> 1531731 | ... AZ2: =SUMIFS('Census T3'!$D:$D,'Census T3'!$A:$A,0,'Census T3'!$B:$B,1,'Census T3'!$C:$C,AZ$1) -> 2153656
A3: female | B3: =SUMIFS('Census T3'!$D:$D,'Census T3'!$A:$A,0,'Census T3'!$B:$B,2,'Census T3'!$C:$C,B$1) -> 1352797 | C3: =SUMIFS('Census T3'!$D:$D,'Census T3'!$A:$A,0,'Census T3'!$B:$B,2,'Census T3'!$C:$C,C$1) -> 1364899 | D3: =SUMIFS('Census T3'!$D:$D,'Census T3'!$A:$A,0,'Census T3'!$B:$B,2,'Census T3'!$C:$C,D$1) -> 1378001 | E3: =SUMIFS('Census T3'!$D:$D,'Census T3'!$A:$A,0,'Census T3'!$B:$B,2,'Census T3'!$C:$C,E$1) -> 1392289 | F3: =SUMIFS('Census T3'!$D:$D,'Census T3'!$A:$A,0,'Census T3'!$B:$B,2,'Census T3'!$C:$C,F$1) -> 1407974 | G3: =SUMIFS('Census T3'!$D:$D,'Census T3'!$A:$A,0,'Census T3'!$B:$B,2,'Census T3'!$C:$C,G$1) -> 1425115 | H3: =SUMIFS('Census T3'!$D:$D,'Census T3'!$A:$A,0,'Census T3'!$B:$B,2,'Census T3'!$C:$C,H$1) -> 1443782 | I3: =SUMIFS('Census T3'!$D:$D,'Census T3'!$A:$A,0,'Census T3'!$B:$B,2,'Census T3'!$C:$C,I$1) -> 1464109 | ... AZ3: =SUMIFS('Census T3'!$D:$D,'Census T3'!$A:$A,0,'Census T3'!$B:$B,2,'Census T3'!$C:$C,AZ$1) -> 2313345.6
A4: white | B4: =SUMIFS('Census T3'!$D:$D,'Census T3'!$A:$A,1,'Census T3'!$B:$B,0,'Census T3'!$C:$C,B$1) -> 2266508 | C4: =SUMIFS('Census T3'!$D:$D,'Census T3'!$A:$A,1,'Census T3'!$B:$B,0,'Census T3'!$C:$C,C$1) -> 2288372 | D4: =SUMIFS('Census T3'!$D:$D,'Census T3'!$A:$A,1,'Census T3'!$B:$B,0,'Census T3'!$C:$C,D$1) -> 2311305 | E4: =SUMIFS('Census T3'!$D:$D,'Census T3'!$A:$A,1,'Census T3'!$B:$B,0,'Census T3'!$C:$C,E$1) -> 2335658 | F4: =SUMIFS('Census T3'!$D:$D,'Census T3'!$A:$A,1,'Census T3'!$B:$B,0,'Census T3'!$C:$C,F$1) -> 2361634 | G4: =SUMIFS('Census T3'!$D:$D,'Census T3'!$A:$A,1,'Census T3'!$B:$B,0,'Census T3'!$C:$C,G$1) -> 2389358 | H4: =SUMIFS('Census T3'!$D:$D,'Census T3'!$A:$A,1,'Census T3'!$B:$B,0,'Census T3'!$C:$C,H$1) -> 2418894 | I4: =SUMIFS('Census T3'!$D:$D,'Census T3'!$A:$A,1,'Census T3'!$B:$B,0,'Census T3'!$C:$C,I$1) -> 2450373 | ... AZ4: =SUMIFS('Census T3'!$D:$D,'Census T3'!$A:$A,1,'Census T3'!$B:$B,0,'Census T3'!$C:$C,AZ$1) -> 3397338.9
A5: black | B5: =SUMIFS('Census T3'!$D:$D,'Census T3'!$A:$A,2,'Census T3'!$B:$B,0,'Census T3'!$C:$C,B$1) -> 332414 | C5: =SUMIFS('Census T3'!$D:$D,'Census T3'!$A:$A,2,'Census T3'!$B:$B,0,'Census T3'!$C:$C,C$1) -> 335694 | D5: =SUMIFS('Census T3'!$D:$D,'Census T3'!$A:$A,2,'Census T3'!$B:$B,0,'Census T3'!$C:$C,D$1) -> 339204 | E5: =SUMIFS('Census T3'!$D:$D,'Census T3'!$A:$A,2,'Census T3'!$B:$B,0,'Census T3'!$C:$C,E$1) -> 342968 | F5: =SUMIFS('Census T3'!$D:$D,'Census T3'!$A:$A,2,'Census T3'!$B:$B,0,'Census T3'!$C:$C,F$1) -> 346991 | G5: =SUMIFS('Census T3'!$D:$D,'Census T3'!$A:$A,2,'Census T3'!$B:$B,0,'Census T3'!$C:$C,G$1) -> 351241 | H5: =SUMIFS('Census T3'!$D:$D,'Census T3'!$A:$A,2,'Census T3'!$B:$B,0,'Census T3'!$C:$C,H$1) -> 355775 | I5: =SUMIFS('Census T3'!$D:$D,'Census T3'!$A:$A,2,'Census T3'!$B:$B,0,'Census T3'!$C:$C,I$1) -> 360569 | ... AZ5: =SUMIFS('Census T3'!$D:$D,'Census T3'!$A:$A,2,'Census T3'!$B:$B,0,'Census T3'!$C:$C,AZ$1) -> 593382.14
A6: asian | B6: =SUMIFS('Census T3'!$D:$D,'Census T3'!$A:$A,4,'Census T3'!$B:$B,0,'Census T3'!$C:$C,B$1) -> 97716 | C6: =SUMIFS('Census T3'!$D:$D,'Census T3'!$A:$A,4,'Census T3'!$B:$B,0,'Census T3'!$C:$C,C$1) -> 100313 | D6: =SUMIFS('Census T3'!$D:$D,'Census T3'!$A:$A,4,'Census T3'!$B:$B,0,'Census T3'!$C:$C,D$1) -> 103074 | E6: =SUMIFS('Census T3'!$D:$D,'Census T3'!$A:$A,4,'Census T3'!$B:$B,0,'Census T3'!$C:$C,E$1) -> 106023 | F6: =SUMIFS('Census T3'!$D:$D,'Census T3'!$A:$A,4,'Census T3'!$B:$B,0,'Census T3'!$C:$C,F$1) -> 109158 | G6: =SUMIFS('Census T3'!$D:$D,'Census T3'!$A:$A,4,'Census T3'!$B:$B,0,'Census T3'!$C:$C,G$1) -> 112427 | H6: =SUMIFS('Census T3'!$D:$D,'Census T3'!$A:$A,4,'Census T3'!$B:$B,0,'Census T3'!$C:$C,H$1) -> 115918 | I6: =SUMIFS('Census T3'!$D:$D,'Census T3'!$A:$A,4,'Census T3'!$B:$B,0,'Census T3'!$C:$C,I$1) -> 119579 | ... AZ6: =SUMIFS('Census T3'!$D:$D,'Census T3'!$A:$A,4,'Census T3'!$B:$B,0,'Census T3'!$C:$C,AZ$1) -> 317317.78
A7: other race | B7: =SUMIFS('Census T3'!$D:$D,'Census T3'!$A:$A,0,'Census T3'!$B:$B,0,'Census T3'!$C:$C,B$1)-SUM(B4:B6) -> 55173 | C7: =SUMIFS('Census T3'!$D:$D,'Census T3'!$A:$A,0,'Census T3'!$B:$B,0,'Census T3'!$C:$C,C$1)-SUM(C4:C6) -> 56424 | D7: =SUMIFS('Census T3'!$D:$D,'Census T3'!$A:$A,0,'Census T3'!$B:$B,0,'Census T3'!$C:$C,D$1)-SUM(D4:D6) -> 57753 | E7: =SUMIFS('Census T3'!$D:$D,'Census T3'!$A:$A,0,'Census T3'!$B:$B,0,'Census T3'!$C:$C,E$1)-SUM(E4:E6) -> 59114 | F7: =SUMIFS('Census T3'!$D:$D,'Census T3'!$A:$A,0,'Census T3'!$B:$B,0,'Census T3'!$C:$C,F$1)-SUM(F4:F6) -> 60542 | G7: =SUMIFS('Census T3'!$D:$D,'Census T3'!$A:$A,0,'Census T3'!$B:$B,0,'Census T3'!$C:$C,G$1)-SUM(G4:G6) -> 62112 | H7: =SUMIFS('Census T3'!$D:$D,'Census T3'!$A:$A,0,'Census T3'!$B:$B,0,'Census T3'!$C:$C,H$1)-SUM(H4:H6) -> 63661 | I7: =SUMIFS('Census T3'!$D:$D,'Census T3'!$A:$A,0,'Census T3'!$B:$B,0,'Census T3'!$C:$C,I$1)-SUM(I4:I6) -> 65319 | ... AZ7: =SUMIFS('Census T3'!$D:$D,'Census T3'!$A:$A,0,'Census T3'!$B:$B,0,'Census T3'!$C:$C,AZ$1)-SUM(AZ4:AZ6) -> 158962.69
A8: hispanic | B8: =SUMIFS('Census T3'!$D:$D,'Census T3'!$A:$A,8,'Census T3'!$B:$B,0,'Census T3'!$C:$C,B$1) -> 218889 | C8: =SUMIFS('Census T3'!$D:$D,'Census T3'!$A:$A,8,'Census T3'!$B:$B,0,'Census T3'!$C:$C,C$1) -> 225675 | D8: =SUMIFS('Census T3'!$D:$D,'Census T3'!$A:$A,8,'Census T3'!$B:$B,0,'Census T3'!$C:$C,D$1) -> 232814 | E8: =SUMIFS('Census T3'!$D:$D,'Census T3'!$A:$A,8,'Census T3'!$B:$B,0,'Census T3'!$C:$C,E$1) -> 240210 | F8: =SUMIFS('Census T3'!$D:$D,'Census T3'!$A:$A,8,'Census T3'!$B:$B,0,'Census T3'!$C:$C,F$1) -> 247965 | G8: =SUMIFS('Census T3'!$D:$D,'Census T3'!$A:$A,8,'Census T3'!$B:$B,0,'Census T3'!$C:$C,G$1) -> 256017 | H8: =SUMIFS('Census T3'!$D:$D,'Census T3'!$A:$A,8,'Census T3'!$B:$B,0,'Census T3'!$C:$C,H$1) -> 264411 | I8: =SUMIFS('Census T3'!$D:$D,'Census T3'!$A:$A,8,'Census T3'!$B:$B,0,'Census T3'!$C:$C,I$1) -> 273169 | ... AZ8: =SUMIFS('Census T3'!$D:$D,'Census T3'!$A:$A,8,'Census T3'!$B:$B,0,'Census T3'!$C:$C,AZ$1) -> 819549.84
A9: nonhispanic | B9: =SUMIFS('Census T3'!$D:$D,'Census T3'!$A:$A,0,'Census T3'!$B:$B,0,'Census T3'!$C:$C,B$1)-B8 -> 2532922 | C9: =SUMIFS('Census T3'!$D:$D,'Census T3'!$A:$A,0,'Census T3'!$B:$B,0,'Census T3'!$C:$C,C$1)-C8 -> 2555128 | D9: =SUMIFS('Census T3'!$D:$D,'Census T3'!$A:$A,0,'Census T3'!$B:$B,0,'Census T3'!$C:$C,D$1)-D8 -> 2578522 | E9: =SUMIFS('Census T3'!$D:$D,'Census T3'!$A:$A,0,'Census T3'!$B:$B,0,'Census T3'!$C:$C,E$1)-E8 -> 2603553 | F9: =SUMIFS('Census T3'!$D:$D,'Census T3'!$A:$A,0,'Census T3'!$B:$B,0,'Census T3'!$C:$C,F$1)-F8 -> 2630360 | G9: =SUMIFS('Census T3'!$D:$D,'Census T3'!$A:$A,0,'Census T3'!$B:$B,0,'Census T3'!$C:$C,G$1)-G8 -> 2659121 | H9: =SUMIFS('Census T3'!$D:$D,'Census T3'!$A:$A,0,'Census T3'!$B:$B,0,'Census T3'!$C:$C,H$1)-H8 -> 2689837 | I9: =SUMIFS('Census T3'!$D:$D,'Census T3'!$A:$A,0,'Census T3'!$B:$B,0,'Census T3'!$C:$C,I$1)-I8 -> 2722671 | ... AZ9: =SUMIFS('Census T3'!$D:$D,'Census T3'!$A:$A,0,'Census T3'!$B:$B,0,'Census T3'!$C:$C,AZ$1)-AZ8 -> 3647451.7
