Workbook
Name asdf: About!#REF!
Name cpi_2010to2012: About!#REF!
Name cpi_2013to2012: About!#REF!
Name cpi_2014to2012: About!#REF!
Name cpi_2016to2012: About!#REF!
Name cpi_2017to2012: About!#REF!
Name cpi_2018to2012: About!#REF!
Name cpi_2019to2012: About!#REF!
Name cpi_2020to2012: About!#REF!
Name cpi_2021to2012: About!#REF!
Name H2_kg_to_MMBtu: [1]Constants!$D$7
Name kWh_to_Btu: [1]Constants!$D$4
Name US_salestax: About!#REF!

Sheet About
A1: BNVP BAU New Vehicle Price
A4: Source: | B4: Exchange Rates
B5: 2019
B6: https://www.exchangerates.org.uk/USD-IDR-spot-exchange-rates-history-2019.html
B8: Indonesia - Investments
B9: Import tariff (CBU vehicles)
B10: 2016
B11: https://www.indonesia-investments.com/news/todays-headlines/indonesian-demand-for-imported-cbu-cars-still-strong/item6501?
B13: Global Fleet
B14: VAT (PPN)
B15: 2025
B16: https://www.globalfleet.com/en/taxation-and-legislation/asia-pacific/analysis/tax-turbulence-guiding-fleets-through-indonesias-vat-storm?a=YHE11&t%5B0%5D=Indonesia&t%5B1%5D=Taxation&curl=1
B18: Global Fleet
B19: Luxury goods tax (PPnBM)
B20: 2025
B21: https://www.globalfleet.com/en/taxation-and-legislation/asia-pacific/analysis/tax-turbulence-guiding-fleets-through-indonesias-vat-storm?a=YHE11&t%5B0%5D=Indonesia&t%5B1%5D=Taxation&curl=1
B23: Mordor Intellligence
B24: Dealer margin & logistics
B25: 2024
B26: https://www.mordorintelligence.com/industry-reports/indonesia-freight-logistics-market
B28: World Bank
B29: Final Consumption Expenditure
B30: 2010-2023
B31: https://databank.worldbank.org/reports.aspx?source=2&series=NE.CON.TOTL.CD&country=
B33: Channel News Asia
B34: Prices of electric motorcycles
B35: 2025
B36: https://www.channelnewsasia.com/asia/indonesia-electric-motorcycle-subsidy-vehicle-assistance-program-3734736
A41: Currency Year
A42: The figures from the Center for Automotive Research come from a 2010 Automotive Yearbook
A43: and therefore are likely in 2010 dollars.
A44: The figures from TruckerToTrucker were collected in early 2015 and therefore use 2015 | B44: 2014 to 2012, for TruckerToTrucker
A45: dollars, but because we don't have a 2015 annual CPI-U figure available yet, we use 2014. | B45: 2013 to 2012, for American Public Transit Association
A46: 0.987 | B46: 2013 to 2012
A47: 0.953 | B47: 2016 to 2012
A48: 0.9366596 | B48: 2017 to 2012
A49: 0.914 | B49: 2018 to 2012
A50: 0.89805482 | B50: 2019 to 2012
A51: 0.88711067 | B51: 2020 to 2012
A52: 0.84730413 | B52: 2021 to 2012
...

Sheet NVP-Indonesia
A1: Year | B1: 2011 | C1: 2012 | D1: 2013 | E1: 2014 | F1: 2015 | G1: 2016 | H1: 2017 | I1: 2018 | J1: 2019 | K1: 2020 | L1: 2021 | M1: 2022 | N1: 2023
A2: Average new car price (million Rupiah) | B2: 193 | C2: =ROUNDUP(($B$2+(($N$2-$B$2)/($N$1-$B$1))*(C1-$B$1)),0) -> 206 | D2: =ROUNDUP(($B$2+(($N$2-$B$2)/($N$1-$B$1))*(D1-$B$1)),0) -> 219 | E2: =ROUNDUP(($B$2+(($N$2-$B$2)/($N$1-$B$1))*(E1-$B$1)),0) -> 232 | F2: =ROUNDUP(($B$2+(($N$2-$B$2)/($N$1-$B$1))*(F1-$B$1)),0) -> 245 | G2: =ROUNDUP(($B$2+(($N$2-$B$2)/($N$1-$B$1))*(G1-$B$1)),0) -> 258 | H2: =ROUNDUP(($B$2+(($N$2-$B$2)/($N$1-$B$1))*(H1-$B$1)),0) -> 270 | I2: =ROUNDUP(($B$2+(($N$2-$B$2)/($N$1-$B$1))*(I1-$B$1)),0) -> 283 | J2: =ROUNDUP(($B$2+(($N$2-$B$2)/($N$1-$B$1))*(J1-$B$1)),0) -> 296 | ... M2: =ROUNDUP(($B$2+(($N$2-$B$2)/($N$1-$B$1))*(M1-$B$1)),0) -> 335 | N2: 347
A3: Million Rupiah to Rupiah | B3: 1000000
A4: 1 USD to Rupiah (2019) | B4: 14135.41
A5: 1 Rupiah to USD (2019) | B5: =1/B4 -> 7.0744322e-05
A6: Average new car price (USD) | B6: =ROUNDUP(B2*$B$3*$B$5,0) -> 13654 | C6: =ROUNDUP(C2*$B$3*$B$5,0) -> 14574 | D6: =ROUNDUP(D2*$B$3*$B$5,0) -> 15494 | E6: =ROUNDUP(E2*$B$3*$B$5,0) -> 16413 | F6: =ROUNDUP(F2*$B$3*$B$5,0) -> 17333 | G6: =ROUNDUP(G2*$B$3*$B$5,0) -> 18253 | H6: =ROUNDUP(H2*$B$3*$B$5,0) -> 19101 | I6: =ROUNDUP(I2*$B$3*$B$5,0) -> 20021 | ... N6: =ROUNDUP(N2*$B$3*$B$5,0) -> 24549
A8: Percentage increase overtime | B8: 0.05
A10: Year | B10: 2020 | C10: 2021 | D10: 2022 | E10: 2023 | F10: 2024 | G10: 2025 | H10: 2026 | I10: 2027 | J10: 2028 | K10: 2029 | L10: 2030 | M10: 2031 | N10: 2032 | O10: 2033 | P10: 2034 | Q10: 2035 | R10: 2036 | S10: 2037 | T10: 2038 | U10: 2039 | V10: 2040 | W10: 2041 | X10: 2042 | Y10: 2043 | Z10: 2044 | AA10: 2045 | AB10: 2046 | AC10: 2047 | AD10: 2048 | AE10: 2049 | AF10: 2050 | AG10: 2051 | AH10: 2052 | AI10: 2053 | AJ10: 2054 | AK10: 2055 | AL10: 2056 | AM10: 2057 | AN10: 2058 | AO10: 2059 | AP10: 2060 | AQ10: 2061 | AR10: 2062 | AS10: 2063 | AT10: 2064 | AU10: 2065 | AV10: 2066 | AW10: 2067 | AX10: 2068 | AY10: 2069 | AZ10: 2070
A11: Average new car price (2012 USD) - Percentage Increase | B11: =K6 -> 21860 | C11: =L6 -> 22780 | D11: =M6 -> 23700 | E11: =N6 -> 24549 | F11: =ROUNDUP(E11+E11*$B$8, 0) -> 25777 | G11: =ROUNDUP(F11+F11*$B$8, 0) -> 27066 | H11: =ROUNDUP(G11+G11*$B$8, 0) -> 28420 | I11: =ROUNDUP(H11+H11*$B$8, 0) -> 29841 | J11: =ROUNDUP(I11+I11*$B$8, 0) -> 31334 | K11: =ROUNDUP(J11+J11*$B$8, 0) -> 32901 | L11: =ROUNDUP(K11+K11*$B$8, 0) -> 34547 | M11: =ROUNDUP(L11+L11*$B$8, 0) -> 36275 | ... AZ11: =ROUNDUP(AY11+AY11*$B$8, 0) -> 243261
A12: Average new car price (2012 USD) - Linear Forecast | B12: =B11 -> 21860 | C12: =C11 -> 22780 | D12: =D11 -> 23700 | E12: =E11 -> 24549 | F12: =ROUNDUP(_xlfn.FORECAST.LINEAR(F10,$B$12:$E$12,$B$10:$E$10), 0) -> 25469 | G12: =ROUNDUP(_xlfn.FORECAST.LINEAR(G10,$B$12:$E$12,$B$10:$E$10), 0) -> 26368 | H12: =ROUNDUP(_xlfn.FORECAST.LINEAR(H10,$B$12:$E$12,$B$10:$E$10), 0) -> 27267 | I12: =ROUNDUP(_xlfn.FORECAST.LINEAR(I10,$B$12:$E$12,$B$10:$E$10), 0) -> 28166 | J12: =ROUNDUP(_xlfn.FORECAST.LINEAR(J10,$B$12:$E$12,$B$10:$E$10), 0) -> 29064 | K12: =ROUNDUP(_xlfn.FORECAST.LINEAR(K10,$B$12:$E$12,$B$10:$E$10), 0) -> 29963 | L12: =ROUNDUP(_xlfn.FORECAST.LINEAR(L10,$B$12:$E$12,$B$10:$E$10), 0) -> 30862 | M12: =ROUNDUP(_xlfn.FORECAST.LINEAR(M10,$B$12:$E$12,$B$10:$E$10), 0) -> 31760 | ... AZ12: =ROUNDUP(_xlfn.FORECAST.LINEAR(AZ10,$B$12:$E$12,$B$10:$E$10), 0) -> 66810
A14: Indonesia New Vehicle Price
A16: BNVP-motorbikes-psgr | W16: >> Projections by SO (fitting the curve and put the constant values after 2045)
A17: Price ($/vehicle) | B17: 2020 | C17: 2021 | D17: 2022 | E17: 2023 | F17: 2024 | G17: 2025 | H17: 2026 | I17: 2027 | J17: 2028 | K17: 2029 | L17: 2030 | M17: 2031 | N17: 2032 | O17: 2033 | P17: 2034 | Q17: 2035 | R17: 2036 | S17: 2037 | T17: 2038 | U17: 2039 | V17: 2040 | W17: 2041 | X17: 2042 | Y17: 2043 | Z17: 2044 | AA17: 2045 | AB17: 2046 | AC17: 2047 | AD17: 2048 | AE17: 2049 | AF17: 2050 | AG17: 2051 | AH17: 2052 | AI17: 2053 | AJ17: 2054 | AK17: 2055 | AL17: 2056 | AM17: 2057 | AN17: 2058 | AO17: 2059 | AP17: 2060 | AQ17: 2061 | AR17: 2062 | AS17: 2063 | AT17: 2064 | AU17: 2065 | AV17: 2066 | AW17: 2067 | AX17: 2068 | AY17: 2069 | AZ17: 2070
A18: battery electric vehicle | B18: ='Indonesia - Motorcycles'!M12*About!A52 -> 1957.5015 | C18: =B18-(($B$18-$L$18)/COUNT($C$17:$L$17)) -> 1844.9131 | D18: =C18-(($B$18-$L$18)/COUNT($C$17:$L$17)) -> 1732.3247 | E18: =D18-(($B$18-$L$18)/COUNT($C$17:$L$17)) -> 1619.7363 | F18: =E18-(($B$18-$L$18)/COUNT($C$17:$L$17)) -> 1507.1479 | G18: =F18-(($B$18-$L$18)/COUNT($C$17:$L$17)) -> 1394.5595 | H18: =G18-(($B$18-$L$18)/COUNT($C$17:$L$17)) -> 1281.9711 | I18: =H18-(($B$18-$L$18)/COUNT($C$17:$L$17)) -> 1169.3827 | J18: =I18-(($B$18-$L$18)/COUNT($C$17:$L$17)) -> 1056.7944 | K18: =J18-(($B$18-$L$18)/COUNT($C$17:$L$17)) -> 944.20595 | L18: ='Indonesia - Motorcycles'!M22*About!A52 -> 831.61755 | M18: =L18-(($L$18-$V$18)/COUNT($M$17:$V$17)) -> 782.80597 | N18: =M18-(($L$18-$V$18)/COUNT($M$17:$V$17)) -> 733.99438 | O18: =N18-(($L$18-$V$18)/COUNT($M$17:$V$17)) -> 685.18279 | P18: =O18-(($L$18-$V$18)/COUNT($M$17:$V$17)) -> 636.3712 | Q18: =P18-(($L$18-$V$18)/COUNT($M$17:$V$17)) -> 587.55961 | R18: =Q18-(($L$18-$V$18)/COUNT($M$17:$V$17)) -> 538.74803 | S18: =R18-(($L$18-$V$18)/COUNT($M$17:$V$17)) -> 489.93644 | T18: =S18-(($L$18-$V$18)/COUNT($M$17:$V$17)) -> 441.12485 | U18: =T18-(($L$18-$V$18)/COUNT($M$17:$V$17)) -> 392.31326 | V18: ='Indonesia - Motorcycles'!M28*About!A52 -> 343.50167 | W18: =V18*(1-0.14) -> 295.41144 | X18: =W18*(1-0.14) -> 254.05384 | Y18: =X18*(1-0.14) -> 218.4863 | Z18: =Y18*(1-0.14) -> 187.89822 | AA18: =Z18*(1-0.14) -> 161.59247 | AB18: =AA18*About!A52 -> 136.91797 | AC18: =$AB$18 -> 136.91797 | AD18: =$AB$18 -> 136.91797 | AE18: =$AB$18 -> 136.91797 | AF18: =$AB$18 -> 136.91797 | AG18: =$AB$18 -> 136.91797 | AH18: =$AB$18 -> 136.91797 | AI18: =$AB$18 -> 136.91797 | AJ18: =$AB$18 -> 136.91797 | ... AZ18: =$AB$18 -> 136.91797
A19: natural gas vehicle | B19: 0 | C19: 0 | D19: 0 | E19: 0 | F19: 0 | G19: 0 | H19: 0 | I19: 0 | J19: 0 | K19: 0 | L19: 0 | M19: 0 | N19: 0 | O19: 0 | P19: 0 | Q19: 0 | R19: 0 | S19: 0 | T19: 0 | U19: 0 | V19: 0 | W19: 0 | X19: 0 | Y19: 0 | Z19: 0 | AA19: 0 | AB19: 0 | AC19: 0 | AD19: 0 | AE19: 0 | AF19: 0 | AG19: 0 | AH19: 0 | AI19: 0 | AJ19: 0 | AK19: 0 | AL19: 0 | AM19: 0 | AN19: 0 | AO19: 0 | AP19: 0 | AQ19: 0 | AR19: 0 | AS19: 0 | AT19: 0 | AU19: 0 | AV19: 0 | AW19: 0 | AX19: 0 | AY19: 0 | AZ19: 0
A20: gasoline vehicle | B20: ='Indonesia - Motorcycles'!M10*About!A52 -> 539.84723 | C20: =B20-(($B$20-$L$20)/COUNT($C$17:$L$17)) -> 543.89483 | D20: =C20-(($B$20-$L$20)/COUNT($C$17:$L$17)) -> 547.94242 | E20: =D20-(($B$20-$L$20)/COUNT($C$17:$L$17)) -> 551.99002 | F20: =E20-(($B$20-$L$20)/COUNT($C$17:$L$17)) -> 556.03761 | G20: =F20-(($B$20-$L$20)/COUNT($C$17:$L$17)) -> 560.0852 | H20: =G20-(($B$20-$L$20)/COUNT($C$17:$L$17)) -> 564.1328 | I20: =H20-(($B$20-$L$20)/COUNT($C$17:$L$17)) -> 568.18039 | J20: =I20-(($B$20-$L$20)/COUNT($C$17:$L$17)) -> 572.22799 | K20: =J20-(($B$20-$L$20)/COUNT($C$17:$L$17)) -> 576.27558 | L20: ='Indonesia - Motorcycles'!M20*About!A52 -> 580.32318 | M20: =$L$20 -> 580.32318 | N20: =$L$20 -> 580.32318 | O20: =$L$20 -> 580.32318 | P20: =$L$20 -> 580.32318 | Q20: =$L$20 -> 580.32318 | R20: =$L$20 -> 580.32318 | S20: =$L$20 -> 580.32318 | T20: =$L$20 -> 580.32318 | U20: =$L$20 -> 580.32318 | V20: =$L$20*About!A52 -> 491.71023 | W20: =$L$20 -> 580.32318 | X20: =$L$20 -> 580.32318 | Y20: =$L$20 -> 580.32318 | Z20: =$L$20 -> 580.32318 | AA20: =$L$20 -> 580.32318 | AB20: =$L$20 -> 580.32318 | AC20: =$L$20 -> 580.32318 | AD20: =$L$20 -> 580.32318 | ... AZ20: =$L$20 -> 580.32318
A21: diesel vehicle | B21: 0 | C21: 0 | D21: 0 | E21: 0 | F21: 0 | G21: 0 | H21: 0 | I21: 0 | J21: 0 | K21: 0 | L21: 0 | M21: 0 | N21: 0 | O21: 0 | P21: 0 | Q21: 0 | R21: 0 | S21: 0 | T21: 0 | U21: 0 | V21: 0 | W21: 0 | X21: 0 | Y21: 0 | Z21: 0 | AA21: 0 | AB21: 0 | AC21: 0 | AD21: 0 | AE21: 0 | AF21: 0 | AG21: 0 | AH21: 0 | AI21: 0 | AJ21: 0 | AK21: 0 | AL21: 0 | AM21: 0 | AN21: 0 | AO21: 0 | AP21: 0 | AQ21: 0 | AR21: 0 | AS21: 0 | AT21: 0 | AU21: 0 | AV21: 0 | AW21: 0 | AX21: 0 | AY21: 0 | AZ21: 0
A22: plugin hybrid vehicle | B22: 0 | C22: 0 | D22: 0 | E22: 0 | F22: 0 | G22: 0 | H22: 0 | I22: 0 | J22: 0 | K22: 0 | L22: 0 | M22: 0 | N22: 0 | O22: 0 | P22: 0 | Q22: 0 | R22: 0 | S22: 0 | T22: 0 | U22: 0 | V22: 0 | W22: 0 | X22: 0 | Y22: 0 | Z22: 0 | AA22: 0 | AB22: 0 | AC22: 0 | AD22: 0 | AE22: 0 | AF22: 0 | AG22: 0 | AH22: 0 | AI22: 0 | AJ22: 0 | AK22: 0 | AL22: 0 | AM22: 0 | AN22: 0 | AO22: 0 | AP22: 0 | AQ22: 0 | AR22: 0 | AS22: 0 | AT22: 0 | AU22: 0 | AV22: 0 | AW22: 0 | AX22: 0 | AY22: 0 | AZ22: 0
A23: LPG vehicle | B23: 0 | C23: 0 | D23: 0 | E23: 0 | F23: 0 | G23: 0 | H23: 0 | I23: 0 | J23: 0 | K23: 0 | L23: 0 | M23: 0 | N23: 0 | O23: 0 | P23: 0 | Q23: 0 | R23: 0 | S23: 0 | T23: 0 | U23: 0 | V23: 0 | W23: 0 | X23: 0 | Y23: 0 | Z23: 0 | AA23: 0 | AB23: 0 | AC23: 0 | AD23: 0 | AE23: 0 | AF23: 0 | AG23: 0 | AH23: 0 | AI23: 0 | AJ23: 0 | AK23: 0 | AL23: 0 | AM23: 0 | AN23: 0 | AO23: 0 | AP23: 0 | AQ23: 0 | AR23: 0 | AS23: 0 | AT23: 0 | AU23: 0 | AV23: 0 | AW23: 0 | AX23: 0 | AY23: 0 | AZ23: 0
A24: hydrogen vehicle | B24: 0 | C24: 0 | D24: 0 | E24: 0 | F24: 0 | G24: 0 | H24: 0 | I24: 0 | J24: 0 | K24: 0 | L24: 0 | M24: 0 | N24: 0 | O24: 0 | P24: 0 | Q24: 0 | R24: 0 | S24: 0 | T24: 0 | U24: 0 | V24: 0 | W24: 0 | X24: 0 | Y24: 0 | Z24: 0 | AA24: 0 | AB24: 0 | AC24: 0 | AD24: 0 | AE24: 0 | AF24: 0 | AG24: 0 | AH24: 0 | AI24: 0 | AJ24: 0 | AK24: 0 | AL24: 0 | AM24: 0 | AN24: 0 | AO24: 0 | AP24: 0 | AQ24: 0 | AR24: 0 | AS24: 0 | AT24: 0 | AU24: 0 | AV24: 0 | AW24: 0 | AX24: 0 | AY24: 0 | AZ24: 0
A26: Source: 1) ChannelAsiaNews (See 'About' - https://www.channelnewsasia.com/asia/indonesia-electric-motorcycle-subsidy-vehicle-assistance-program-3734736)
A27: Prices for these electric motorcycles range from 4.8 million rupiah to 37.75 million rupiah.
A28: Source: 2) ICCT (See 'Motorcycles - 2030' tab)
A29: Updated with the 2012 USD from 2021
A43: NOT UPDATED BELOW - PROJECTIONS TO BE CALIBRATED
A44: BNVP-HDVs-psgr
A45: Price ($/vehicle) | B45: 2020 | C45: 2021 | D45: 2022 | E45: 2023 | F45: 2024 | G45: 2025 | H45: 2026 | I45: 2027 | J45: 2028 | K45: 2029 | L45: 2030 | M45: 2031 | N45: 2032 | O45: 2033 | P45: 2034 | Q45: 2035 | R45: 2036 | S45: 2037 | T45: 2038 | U45: 2039 | V45: 2040 | W45: 2041 | X45: 2042 | Y45: 2043 | Z45: 2044 | AA45: 2045 | AB45: 2046 | AC45: 2047 | AD45: 2048 | AE45: 2049 | AF45: 2050 | AG45: 2051 | AH45: 2052 | AI45: 2053 | AJ45: 2054 | AK45: 2055 | AL45: 2056 | AM45: 2057 | AN45: 2058 | AO45: 2059 | AP45: 2060 | AQ45: 2061 | AR45: 2062 | AS45: 2063 | AT45: 2064 | AU45: 2065 | AV45: 2066 | AW45: 2067 | AX45: 2068 | AY45: 2069 | AZ45: 2070
A46: battery electric vehicle | B46: =$D$46 -> 371621.62 | C46: =$D$46 -> 371621.62 | D46: ='Indonesia - HDV '!D21 -> 371621.62 | E46: =$D$46 -> 371621.62 | F46: =$D$46 -> 371621.62 | G46: =$D$46 -> 371621.62 | H46: =$D$46 -> 371621.62 | I46: =$D$46 -> 371621.62 | J46: =$D$46 -> 371621.62 | K46: =$D$46 -> 371621.62 | L46: =$D$46 -> 371621.62 | ... AZ46: =$D$46 -> 371621.62
A47: natural gas vehicle | B47: =$D$47 -> 135608.11 | C47: =$D$47 -> 135608.11 | D47: ='Indonesia - HDV '!D22 -> 135608.11 | E47: =$D$47 -> 135608.11 | F47: =$D$47 -> 135608.11 | G47: =$D$47 -> 135608.11 | H47: =$D$47 -> 135608.11 | I47: =$D$47 -> 135608.11 | J47: =$D$47 -> 135608.11 | K47: =$D$47 -> 135608.11 | L47: =$D$47 -> 135608.11 | ... AZ47: =$D$47 -> 135608.11
A48: gasoline vehicle | B48: =$D$48 -> 84353.201 | C48: =$D$48 -> 84353.201 | D48: ='Indonesia - HDV '!D23 -> 84353.201 | E48: =$D$48 -> 84353.201 | F48: =$D$48 -> 84353.201 | G48: =$D$48 -> 84353.201 | H48: =$D$48 -> 84353.201 | I48: =$D$48 -> 84353.201 | J48: =$D$48 -> 84353.201 | K48: =$D$48 -> 84353.201 | L48: =$D$48 -> 84353.201 | ... AZ48: =$D$48 -> 84353.201
A49: diesel vehicle | B49: =$D$49 -> 84353.201 | C49: =$D$49 -> 84353.201 | D49: ='Indonesia - HDV '!D24 -> 84353.201 | E49: =$D$49 -> 84353.201 | F49: =$D$49 -> 84353.201 | G49: =$D$49 -> 84353.201 | H49: =$D$49 -> 84353.201 | I49: =$D$49 -> 84353.201 | J49: =$D$49 -> 84353.201 | K49: =$D$49 -> 84353.201 | L49: =$D$49 -> 84353.201 | ... AZ49: =$D$49 -> 84353.201
A50: plugin hybrid vehicle | B50: =$D$50 -> 371621.62 | C50: =$D$50 -> 371621.62 | D50: ='Indonesia - HDV '!D25 -> 371621.62 | E50: =$D$50 -> 371621.62 | F50: =$D$50 -> 371621.62 | G50: =$D$50 -> 371621.62 | H50: =$D$50 -> 371621.62 | I50: =$D$50 -> 371621.62 | J50: =$D$50 -> 371621.62 | K50: =$D$50 -> 371621.62 | L50: =$D$50 -> 371621.62 | ... AZ50: =$D$50 -> 371621.62
A51: LPG vehicle | B51: =$D$51 -> 109980.65 | C51: =$D$51 -> 109980.65 | D51: ='Indonesia - HDV '!D26 -> 109980.65 | E51: =$D$51 -> 109980.65 | F51: =$D$51 -> 109980.65 | G51: =$D$51 -> 109980.65 | H51: =$D$51 -> 109980.65 | I51: =$D$51 -> 109980.65 | J51: =$D$51 -> 109980.65 | K51: =$D$51 -> 109980.65 | L51: =$D$51 -> 109980.65 | ... AZ51: =$D$51 -> 109980.65
A52: hydrogen vehicle | B52: =$D$52 -> 1420000 | C52: =$D$52 -> 1420000 | D52: ='Indonesia - HDV '!D27 -> 1420000 | E52: =$D$52 -> 1420000 | F52: =$D$52 -> 1420000 | G52: =$D$52 -> 1420000 | H52: =$D$52 -> 1420000 | I52: =$D$52 -> 1420000 | J52: =$D$52 -> 1420000 | K52: =$D$52 -> 1420000 | L52: =$D$52 -> 1420000 | ... AZ52: =$D$52 -> 1420000
A54: BNVP-HDVs-frgt
A55: Price ($/vehicle) | B55: 2020 | C55: 2021 | D55: 2022 | E55: 2023 | F55: 2024 | G55: 2025 | H55: 2026 | I55: 2027 | J55: 2028 | K55: 2029 | L55: 2030 | M55: 2031 | N55: 2032 | O55: 2033 | P55: 2034 | Q55: 2035 | R55: 2036 | S55: 2037 | T55: 2038 | U55: 2039 | V55: 2040 | W55: 2041 | X55: 2042 | Y55: 2043 | Z55: 2044 | AA55: 2045 | AB55: 2046 | AC55: 2047 | AD55: 2048 | AE55: 2049 | AF55: 2050 | AG55: 2051 | AH55: 2052 | AI55: 2053 | AJ55: 2054 | AK55: 2055 | AL55: 2056 | AM55: 2057 | AN55: 2058 | AO55: 2059 | AP55: 2060 | AQ55: 2061 | AR55: 2062 | AS55: 2063 | AT55: 2064 | AU55: 2065 | AV55: 2066 | AW55: 2067 | AX55: 2068 | AY55: 2069 | AZ55: 2070
A56: battery electric vehicle | B56: 212323.26 | C56: 212323.26 | D56: 212323.26 | E56: 212323.26 | F56: 212323.26 | G56: 212323.26 | H56: 212323.26 | I56: 212323.26 | J56: 212323.26 | K56: 212323.26 | L56: 212323.26 | M56: 212323.26 | N56: 212323.26 | O56: 212323.26 | P56: 212323.26 | Q56: 212323.26 | R56: 212323.26 | S56: 212323.26 | T56: 212323.26 | U56: 212323.26 | V56: 212323.26 | W56: 212323.26 | X56: 212323.26 | Y56: 212323.26 | Z56: 212323.26 | AA56: 212323.26 | AB56: 212323.26 | AC56: 212323.26 | AD56: 212323.26 | AE56: 212323.26 | AF56: 212323.26 | AG56: 212323.26 | AH56: 212323.26 | AI56: 212323.26 | AJ56: 212323.26 | AK56: 212323.26 | AL56: 212323.26 | AM56: 212323.26 | AN56: 212323.26 | AO56: 212323.26 | AP56: 212323.26 | AQ56: 212323.26 | AR56: 212323.26 | AS56: 212323.26 | AT56: 212323.26 | AU56: 212323.26 | AV56: 212323.26 | AW56: 212323.26 | AX56: 212323.26 | AY56: 212323.26 | AZ56: 212323.26
A57: natural gas vehicle | B57: 169081.01 | C57: 167864.65 | D57: 168589.54 | E57: 169720.85 | F57: 170592.77 | G57: 171447.35 | H57: 172235.77 | I57: 172949.86 | J57: 173710.9 | K57: 174435.56 | L57: 175106.83 | M57: 175831.33 | N57: 176390.34 | O57: 177133.8 | P57: 177567.08 | Q57: 177918.6 | R57: 178228.46 | S57: 178533.03 | T57: 178816.19 | U57: 179106.91 | V57: 179311.24 | W57: 179543.09 | X57: 179737.16 | Y57: 179898.98 | Z57: 180064.57 | AA57: 180221.06 | AB57: 180365 | AC57: 180516.08 | AD57: 180668.22 | AE57: 180802.25 | AF57: 180937.41 | AG57: 183362.21 | AH57: 183799.51 | AI57: 184236.81 | AJ57: 184674.12 | AK57: 185111.42 | AL57: 185548.72 | AM57: 185986.03 | AN57: 186423.33 | AO57: 186860.63 | AP57: 187297.94 | AQ57: 187735.24 | AR57: 188172.54 | AS57: 188609.85 | AT57: 189047.15 | AU57: 189484.45 | AV57: 189921.76 | AW57: 190359.06 | AX57: 190796.36 | AY57: 191233.67 | AZ57: 191670.97
A58: gasoline vehicle | B58: 116533.08 | C58: 116533.08 | D58: 116533.08 | E58: 116533.08 | F58: 116533.08 | G58: 116533.08 | H58: 116533.08 | I58: 116533.08 | J58: 116533.08 | K58: 116533.08 | L58: 116533.08 | M58: 116533.08 | N58: 116533.08 | O58: 116533.08 | P58: 116533.08 | Q58: 116533.08 | R58: 116533.08 | S58: 116533.08 | T58: 116533.08 | U58: 116533.08 | V58: 116533.08 | W58: 116533.08 | X58: 116533.08 | Y58: 116533.08 | Z58: 116533.08 | AA58: 116533.08 | AB58: 116533.08 | AC58: 116533.08 | AD58: 116533.08 | AE58: 116533.08 | AF58: 116533.08 | AG58: 116533.08 | AH58: 116533.08 | AI58: 116533.08 | AJ58: 116533.08 | AK58: 116533.08 | AL58: 116533.08 | AM58: 116533.08 | AN58: 116533.08 | AO58: 116533.08 | AP58: 116533.08 | AQ58: 116533.08 | AR58: 116533.08 | AS58: 116533.08 | AT58: 116533.08 | AU58: 116533.08 | AV58: 116533.08 | AW58: 116533.08 | AX58: 116533.08 | AY58: 116533.08 | AZ58: 116533.08
A59: diesel vehicle | B59: 116533.08 | C59: 116533.08 | D59: 116533.08 | E59: 116533.08 | F59: 116533.08 | G59: 116533.08 | H59: 116533.08 | I59: 116533.08 | J59: 116533.08 | K59: 116533.08 | L59: 116533.08 | M59: 116533.08 | N59: 116533.08 | O59: 116533.08 | P59: 116533.08 | Q59: 116533.08 | R59: 116533.08 | S59: 116533.08 | T59: 116533.08 | U59: 116533.08 | V59: 116533.08 | W59: 116533.08 | X59: 116533.08 | Y59: 116533.08 | Z59: 116533.08 | AA59: 116533.08 | AB59: 116533.08 | AC59: 116533.08 | AD59: 116533.08 | AE59: 116533.08 | AF59: 116533.08 | AG59: 116533.08 | AH59: 116533.08 | AI59: 116533.08 | AJ59: 116533.08 | AK59: 116533.08 | AL59: 116533.08 | AM59: 116533.08 | AN59: 116533.08 | AO59: 116533.08 | AP59: 116533.08 | AQ59: 116533.08 | AR59: 116533.08 | AS59: 116533.08 | AT59: 116533.08 | AU59: 116533.08 | AV59: 116533.08 | AW59: 116533.08 | AX59: 116533.08 | AY59: 116533.08 | AZ59: 116533.08
...

Sheet Indonesia - Motorcycles
B3: India's projection
L5: US$1 = INR 74
L9: 2020
K10: Conventional | L10: 47148 | M10: =L10/74 -> 637.13514
K11: BEV100 | L11: 141905 | M11: =L11/74 -> 1917.6351
K12: BEV150 | L12: 170960 | M12: =L12/74 -> 2310.2703 | N12: < used
K13: BEV250 | L13: 229069 | M13: =L13/74 -> 3095.527
L19: 2030
K20: Conventional | L20: 50683 | M20: =L20/74 -> 684.90541
K21: BEV100 | L21: 59007 | M21: =L21/74 -> 797.39189
K22: BEV150 | L22: 72630 | M22: =L22/74 -> 981.48649 | N22: < used
K23: BEV250 | L23: 99877 | M23: =L23/74 -> 1349.6892
L25: 2040
K26: Conventional | L26: 70000 | M26: =L26/74 -> 945.94595
K27: BEV100 | L27: 28000 | M27: =L27/74 -> 378.37838
K28: BEV150 | L28: 30000 | M28: =L28/74 -> 405.40541 | N28: < used
B32: Source: ICCT (2021) https://theicct.org/sites/default/files/publications/E2W-cost-2030-India-jul2021.pdf

Sheet Indonesia - HDV 
B4: Indonesia's HDV passenger
B15: Source: ICCT (2023) | G15: Source: ITDP (2023)
G16: IDR/USD: 15,200, based on exchange rate on October 4, 2022
B17: Exchange rate: 1 USD=14,800 IDR (the average rate in August 2022). | L17: Used the weighted average
G18: Next steps | H18: if possible using the weighted average for HDVs prices | L18: Diesel | O18: ITDP (2023) | P18: ICCT (2023) | Q18: Average
B19: BNVP-HDVs-psgr | C19: Initial EPS prices | D19: ICCT prices | H19: otherwise using unweighted average | L19: Single Bus | M19: ='Number of Vehicles'!C3 -> 0.26664825 | N19: 2341 | O19: =N19*1000000/15200 -> 154013.16 | P19: =2594715750/14800 -> 175318.63 | Q19: =AVERAGE(O19:P19) -> 164665.89
B20: Price ($/vehicle) | C20: 2022 | D20: 2022 | E20: Source | L20: Articulated Bus | M20: ='Number of Vehicles'!C4 -> 0.071014092 | N20: 4800 | O20: =N20*1000000/15200 -> 315789.47 | Q20: =O20 -> 315789.47
B21: battery electric vehicle | C21: 787140.4 | D21: =5500000000/14800 -> 371621.62 | E21: ICCT (2023) | L21: Medium Bus | M21: ='Number of Vehicles'!C5 -> 0.074053606 | N21: 958 | O21: =N21*1000000/15200 -> 63026.316 | Q21: =O21 -> 63026.316
B22: natural gas vehicle | C22: 541991.42 | D22: =2007000000/14800 -> 135608.11 | E22: ICCT (2023) | L22: Microbus | M22: ='Number of Vehicles'!C6 -> 0.58828406 | N22: 345 | O22: =N22*1000000/15200 -> 22697.368 | Q22: =O22 -> 22697.368
B23: gasoline vehicle | C23: 425813.12 | D23: =Q23 -> 84353.201 | E23: Weighted average of ICCT (2023)'s Mercedes Benz Diesel Single Bus and ITDP (2023)'s prices | Q23: =SUMPRODUCT(Q19:Q22,M19:M22)/SUM(M19:M22) -> 84353.201
B24: diesel vehicle | C24: 425813.12 | D24: =Q23 -> 84353.201 | E24: Weighted average of ICCT (2023)'s Mercedes Benz Diesel Single Bus and ITDP (2023)'s prices
B25: plugin hybrid vehicle | C25: 624243.15 | D25: =D21 -> 371621.62 | E25: Same as EV
B26: LPG vehicle | C26: 564719.73 | D26: =AVERAGE(D22:D23) -> 109980.65 | E26: Average of NG, gasoline/diesel
B27: hydrogen vehicle | C27: 838135.09 | D27: 1420000 | E27: French 12-metre hydrogen fuel-cell bus (non-Indonesia source)
B30: Indonesia's HDV freight
B32: BNVP-HDVs-frgt | C32: Initial EPS prices | D32: Same as HDV-pasgr
B33: Price ($/vehicle) | C33: 2022 | D33: 2022
B34: battery electric vehicle | C34: 212323.26 | D34: =D21 -> 371621.62
B35: natural gas vehicle | C35: 168589.54 | D35: =D22 -> 135608.11
B36: gasoline vehicle | C36: 116533.08 | D36: =D23 -> 84353.201
B37: diesel vehicle | C37: 116533.08 | D37: =D24 -> 84353.201 | H37: Next steps | I37: The price provided is low for HDVs freight. If we can't find better data, it is recommended using the weighted average data for HDVs passengers
B38: plugin hybrid vehicle | C38: 296290.7 | D38: =D25 -> 371621.62 | I38: Since we couldn't find a better data, I copied and pasted from HDVs-psgr as suggested
B39: LPG vehicle | C39: 167812.53 | D39: =D26 -> 109980.65
B40: hydrogen vehicle | C40: 348292.91 | D40: =D27 -> 1420000
B42: Source:
B43: New trucks can range from around Rp 125 million (Daihatsu Gran Max PU or Tata Super Ace) to over Rp 800 million (Ford Ranger or Isuzu D Max).
B59: Source: https://changing-transport.org/wp-content/uploads/2021_IDN_Truck-Modernisation.pdf
B63: Source: Wangsa et al. (2023) https://doi.org/10.1016/j.cstp.2023.100966
B64: "The optimal tax incentive and subsidy to promote electric trucks in Indonesia: Insight for government and industry"
J68: Electric trucks | K68: =(60800+62900+61200)/3 -> 61633.333
J69: Disel trucks | K69: =(34190+34210+34200)/3 -> 34200
B75: Global Fuel Economy, Indonesia (https://www.globalfueleconomy.org/media/461034/asia_indonesia.pdf)
B76: ICCT Working Paper (https://theicct.org/wp-content/uploads/2023/01/asia-pacific-evs-cco-evs-indonesia-jan23.pdf)
B77: Mitsubishi (https://www.oto.com/en/truk-baru/mitsubishi/colt-fe-shdx)— Rp579 Juta = $36k

Sheet Number of Vehicles
A1: Number of vehicles by HDV category (i.e., Single Bus, Articulated Bus, Medium Bus, and Microbus)
A2: Category | B2: Count | C2: % | D2: Note | E2: Souce Link
A3: Single Bus | B3: 965 | C3: =B3/$B$7 -> 0.26664825 | D3: Jakarta | E3: https://itdp-indonesia.org/wp-content/uploads/2023/05/3.2.-_-3.3.-Transjakarta-E-Bus-Integrated-Long-Term-Implementation-Phase.pdf
A4: Articulated Bus | B4: 257 | C4: =B4/$B$7 -> 0.071014092 | D4: Jakarta | E4: https://itdp-indonesia.org/wp-content/uploads/2023/05/3.2.-_-3.3.-Transjakarta-E-Bus-Integrated-Long-Term-Implementation-Phase.pdf
A5: Medium Bus | B5: 268 | C5: =B5/$B$7 -> 0.074053606 | D5: Jakarta | E5: https://itdp-indonesia.org/wp-content/uploads/2023/05/3.2.-_-3.3.-Transjakarta-E-Bus-Integrated-Long-Term-Implementation-Phase.pdf
A6: Microbus | B6: 2129 | C6: =B6/$B$7 -> 0.58828406 | D6: Jakarta | E6: https://itdp-indonesia.org/wp-content/uploads/2023/05/3.2.-_-3.3.-Transjakarta-E-Bus-Integrated-Long-Term-Implementation-Phase.pdf
A7: Total | B7: =SUM(B3:B6) -> 3619 | C7: =B7/$B$7 -> 1
A9: All buses | B9: 241000 | D9: In 2022, the number of buses in use was roughly 241 thousand units in Indonesia, indicating a steady increase over the last years. Starting in April 2019, old buses in Jakarta, Indonesia, were not allowed to operate anymore as an attempt to reduce the air pollution in Indonesia. | E9: https://www.statista.com/statistics/978937/indonesia-number-of-buses-use/#:~:text=In%202022%2C%20the%20number%20of,increase%20over%20the%20last%20years.
A10: All buses | B10: 271500 | D10: Market forecast | E10: https://www.researchandmarkets.com/reports/5806834/indonesia-bus-industry-research-report?srsltid=AfmBOooC7WdPcPYG8Fzm8pMPRLZvYSE_UKLWn64ooBzzkwRnleggi0Z8
A11: Electric buses | B11: 124 | D11: Only 124 electric buses are being used in urban public transport systems across three cities currently, accounting for just 0.80% of the target the Ministry of Transportation has set for 2030 just a few years from now. | E11: https://itdp.org/2024/07/15/building-momentum-for-transport-electrification-in-indonesia/

Sheet BNVP-LDVs-psgr
A1: Price ($/vehicle) | B1: 2020 | C1: 2021 | D1: 2022 | E1: 2023 | F1: 2024 | G1: 2025 | H1: 2026 | I1: 2027 | J1: 2028 | K1: 2029 | L1: 2030 | M1: 2031 | N1: 2032 | O1: 2033 | P1: 2034 | Q1: 2035 | R1: 2036 | S1: 2037 | T1: 2038 | U1: 2039 | V1: 2040 | W1: 2041 | X1: 2042 | Y1: 2043 | Z1: 2044 | AA1: 2045 | AB1: 2046 | AC1: 2047 | AD1: 2048 | AE1: 2049 | AF1: 2050 | AG1: 2051 | AH1: 2052 | AI1: 2053 | AJ1: 2054 | AK1: 2055 | AL1: 2056 | AM1: 2057 | AN1: 2058 | AO1: 2059 | AP1: 2060 | AQ1: 2061 | AR1: 2062 | AS1: 2063 | AT1: 2064 | AU1: 2065 | AV1: 2066 | AW1: 2067 | AX1: 2068 | AY1: 2069 | AZ1: 2070
A2: battery electric vehicle | B2: =('NVP-Indonesia'!$B$12+'NVP-Indonesia'!$B$12*'NVP-Indonesia'!$B191) -> 21521.202 | C2: =(B2+B2*'NVP-Indonesia'!$B191) -> 21187.654 | D2: =(C2+C2*'NVP-Indonesia'!$B191) -> 20859.276 | E2: =(D2+D2*'NVP-Indonesia'!$B191) -> 20535.987 | F2: =(E2+E2*'NVP-Indonesia'!$B191) -> 20217.709 | G2: =(F2+F2*'NVP-Indonesia'!$B191) -> 19904.364 | H2: =(G2+G2*'NVP-Indonesia'!$B191) -> 19595.875 | I2: =(H2+H2*'NVP-Indonesia'!$B191) -> 19292.167 | J2: =(I2+I2*'NVP-Indonesia'!$B191) -> 18993.166 | ... AZ2: =(AY2+AY2*'NVP-Indonesia'!$B191) -> 9855.6297
A3: natural gas vehicle | B3: =('NVP-Indonesia'!$B$12+'NVP-Indonesia'!$B$12*'NVP-Indonesia'!$B192) -> 21914.895 | C3: =(B3+B3*'NVP-Indonesia'!$B192) -> 21969.927 | D3: =(C3+C3*'NVP-Indonesia'!$B192) -> 22025.098 | E3: =(D3+D3*'NVP-Indonesia'!$B192) -> 22080.407 | F3: =(E3+E3*'NVP-Indonesia'!$B192) -> 22135.855 | G3: =(F3+F3*'NVP-Indonesia'!$B192) -> 22191.443 | H3: =(G3+G3*'NVP-Indonesia'!$B192) -> 22247.17 | I3: =(H3+H3*'NVP-Indonesia'!$B192) -> 22303.037 | J3: =(I3+I3*'NVP-Indonesia'!$B192) -> 22359.044 | ... AZ3: =(AY3+AY3*'NVP-Indonesia'!$B192) -> 24842.82
A4: gasoline vehicle | B4: =('NVP-Indonesia'!$B$12+'NVP-Indonesia'!$B$12*'NVP-Indonesia'!$B193) -> 21864.419 | C4: =(B4+B4*'NVP-Indonesia'!$B193) -> 21868.839 | D4: =(C4+C4*'NVP-Indonesia'!$B193) -> 21873.26 | E4: =(D4+D4*'NVP-Indonesia'!$B193) -> 21877.682 | F4: =(E4+E4*'NVP-Indonesia'!$B193) -> 21882.104 | G4: =(F4+F4*'NVP-Indonesia'!$B193) -> 21886.528 | H4: =(G4+G4*'NVP-Indonesia'!$B193) -> 21890.952 | I4: =(H4+H4*'NVP-Indonesia'!$B193) -> 21895.378 | J4: =(I4+I4*'NVP-Indonesia'!$B193) -> 21899.804 | ... AZ4: =(AY4+AY4*'NVP-Indonesia'!$B193) -> 22086.516
A5: diesel vehicle | B5: =('NVP-Indonesia'!$B$12+'NVP-Indonesia'!$B$12*'NVP-Indonesia'!$B194) -> 21850.328 | C5: =(B5+B5*'NVP-Indonesia'!$B194) -> 21840.66 | D5: =(C5+C5*'NVP-Indonesia'!$B194) -> 21830.996 | E5: =(D5+D5*'NVP-Indonesia'!$B194) -> 21821.337 | F5: =(E5+E5*'NVP-Indonesia'!$B194) -> 21811.682 | G5: =(F5+F5*'NVP-Indonesia'!$B194) -> 21802.031 | H5: =(G5+G5*'NVP-Indonesia'!$B194) -> 21792.384 | I5: =(H5+H5*'NVP-Indonesia'!$B194) -> 21782.742 | J5: =(I5+I5*'NVP-Indonesia'!$B194) -> 21773.104 | ... AZ5: =(AY5+AY5*'NVP-Indonesia'!$B194) -> 21372.133
A6: plugin hybrid vehicle | B6: =('NVP-Indonesia'!$B$12+'NVP-Indonesia'!$B$12*'NVP-Indonesia'!$B195) -> 21890.968 | C6: =(B6+B6*'NVP-Indonesia'!$B195) -> 21921.981 | D6: =(C6+C6*'NVP-Indonesia'!$B195) -> 21953.037 | E6: =(D6+D6*'NVP-Indonesia'!$B195) -> 21984.137 | F6: =(E6+E6*'NVP-Indonesia'!$B195) -> 22015.282 | G6: =(F6+F6*'NVP-Indonesia'!$B195) -> 22046.47 | H6: =(G6+G6*'NVP-Indonesia'!$B195) -> 22077.703 | I6: =(H6+H6*'NVP-Indonesia'!$B195) -> 22108.98 | J6: =(I6+I6*'NVP-Indonesia'!$B195) -> 22140.301 | ... AZ6: =(AY6+AY6*'NVP-Indonesia'!$B195) -> 23496.647
A7: LPG vehicle | B7: =('NVP-Indonesia'!$B$12+'NVP-Indonesia'!$B$12*'NVP-Indonesia'!$B196) -> 21898.341 | C7: =(B7+B7*'NVP-Indonesia'!$B196) -> 21936.748 | D7: =(C7+C7*'NVP-Indonesia'!$B196) -> 21975.224 | E7: =(D7+D7*'NVP-Indonesia'!$B196) -> 22013.766 | F7: =(E7+E7*'NVP-Indonesia'!$B196) -> 22052.376 | G7: =(F7+F7*'NVP-Indonesia'!$B196) -> 22091.054 | H7: =(G7+G7*'NVP-Indonesia'!$B196) -> 22129.8 | I7: =(H7+H7*'NVP-Indonesia'!$B196) -> 22168.614 | J7: =(I7+I7*'NVP-Indonesia'!$B196) -> 22207.496 | ... AZ7: =(AY7+AY7*'NVP-Indonesia'!$B196) -> 23903.615
A8: hydrogen vehicle | B8: =('NVP-Indonesia'!$B$12+'NVP-Indonesia'!$B$12*'NVP-Indonesia'!$B197) -> 21464.221 | C8: =(B8+B8*'NVP-Indonesia'!$B197) -> 21075.607 | D8: =(C8+C8*'NVP-Indonesia'!$B197) -> 20694.029 | E8: =(D8+D8*'NVP-Indonesia'!$B197) -> 20319.36 | F8: =(E8+E8*'NVP-Indonesia'!$B197) -> 19951.474 | G8: =(F8+F8*'NVP-Indonesia'!$B197) -> 19590.249 | H8: =(G8+G8*'NVP-Indonesia'!$B197) -> 19235.563 | I8: =(H8+H8*'NVP-Indonesia'!$B197) -> 18887.3 | J8: =(I8+I8*'NVP-Indonesia'!$B197) -> 18545.342 | ... AZ8: =(AY8+AY8*'NVP-Indonesia'!$B197) -> 8609.2113

Sheet BNVP-LDVs-frgt
A1: Price ($/vehicle) | B1: 2020 | C1: 2021 | D1: 2022 | E1: 2023 | F1: 2024 | G1: 2025 | H1: 2026 | I1: 2027 | J1: 2028 | K1: 2029 | L1: 2030 | M1: 2031 | N1: 2032 | O1: 2033 | P1: 2034 | Q1: 2035 | R1: 2036 | S1: 2037 | T1: 2038 | U1: 2039 | V1: 2040 | W1: 2041 | X1: 2042 | Y1: 2043 | Z1: 2044 | AA1: 2045 | AB1: 2046 | AC1: 2047 | AD1: 2048 | AE1: 2049 | AF1: 2050 | AG1: 2051 | AH1: 2052 | AI1: 2053 | AJ1: 2054 | AK1: 2055 | AL1: 2056 | AM1: 2057 | AN1: 2058 | AO1: 2059 | AP1: 2060 | AQ1: 2061 | AR1: 2062 | AS1: 2063 | AT1: 2064 | AU1: 2065 | AV1: 2066 | AW1: 2067 | AX1: 2068 | AY1: 2069 | AZ1: 2070
A2: battery electric vehicle | B2: ='NVP-Indonesia'!B78*'NVP-Indonesia'!$B$227 -> 58095.337 | C2: 0 | D2: 0 | E2: 0 | F2: 0 | G2: 0 | H2: 0 | I2: 0 | J2: 0 | K2: 0 | L2: 0 | M2: 0 | N2: 0 | O2: 0 | P2: 0 | Q2: 0 | R2: 0 | S2: 0 | T2: 0 | U2: 0 | V2: 0 | W2: 0 | X2: 0 | Y2: 0 | Z2: 0 | AA2: 0 | AB2: 0 | AC2: 0 | AD2: 0 | AE2: 0 | AF2: 0 | AG2: 0 | AH2: 0 | AI2: 0 | AJ2: 0 | AK2: 0 | AL2: 0 | AM2: 0 | AN2: 0 | AO2: 0 | AP2: 0 | AQ2: 0 | AR2: 0 | AS2: 0 | AT2: 0 | AU2: 0 | AV2: 0 | AW2: 0 | AX2: 0 | AY2: 0 | AZ2: 0
A3: natural gas vehicle | B3: ='NVP-Indonesia'!B79*'NVP-Indonesia'!$B$227 -> 40546.809 | C3: ='NVP-Indonesia'!C79*'NVP-Indonesia'!$B$227 -> 40255.116 | D3: ='NVP-Indonesia'!D79*'NVP-Indonesia'!$B$227 -> 40428.95 | E3: ='NVP-Indonesia'!E79*'NVP-Indonesia'!$B$227 -> 40700.245 | F3: ='NVP-Indonesia'!F79*'NVP-Indonesia'!$B$227 -> 40909.339 | G3: ='NVP-Indonesia'!G79*'NVP-Indonesia'!$B$227 -> 41114.274 | H3: ='NVP-Indonesia'!H79*'NVP-Indonesia'!$B$227 -> 41303.342 | I3: ='NVP-Indonesia'!I79*'NVP-Indonesia'!$B$227 -> 41474.586 | ... AZ3: ='NVP-Indonesia'!AZ79*'NVP-Indonesia'!$B$227 -> 45964.038
A4: gasoline vehicle | B4: ='NVP-Indonesia'!B80*'NVP-Indonesia'!$B$227 -> 35674.636 | C4: ='NVP-Indonesia'!C80*'NVP-Indonesia'!$B$227 -> 35674.636 | D4: ='NVP-Indonesia'!D80*'NVP-Indonesia'!$B$227 -> 35674.636 | E4: ='NVP-Indonesia'!E80*'NVP-Indonesia'!$B$227 -> 35674.636 | F4: ='NVP-Indonesia'!F80*'NVP-Indonesia'!$B$227 -> 35674.636 | G4: ='NVP-Indonesia'!G80*'NVP-Indonesia'!$B$227 -> 35674.636 | H4: ='NVP-Indonesia'!H80*'NVP-Indonesia'!$B$227 -> 35674.636 | I4: ='NVP-Indonesia'!I80*'NVP-Indonesia'!$B$227 -> 35674.636 | ... AZ4: ='NVP-Indonesia'!AZ80*'NVP-Indonesia'!$B$227 -> 35674.636
A5: diesel vehicle | B5: ='NVP-Indonesia'!B81*'NVP-Indonesia'!$B$227 -> 39638.484 | C5: ='NVP-Indonesia'!C81*'NVP-Indonesia'!$B$227 -> 39638.484 | D5: ='NVP-Indonesia'!D81*'NVP-Indonesia'!$B$227 -> 39638.484 | E5: ='NVP-Indonesia'!E81*'NVP-Indonesia'!$B$227 -> 39638.484 | F5: ='NVP-Indonesia'!F81*'NVP-Indonesia'!$B$227 -> 39638.484 | G5: ='NVP-Indonesia'!G81*'NVP-Indonesia'!$B$227 -> 39638.484 | H5: ='NVP-Indonesia'!H81*'NVP-Indonesia'!$B$227 -> 39638.484 | I5: ='NVP-Indonesia'!I81*'NVP-Indonesia'!$B$227 -> 39638.484 | ... AZ5: ='NVP-Indonesia'!AZ81*'NVP-Indonesia'!$B$227 -> 39638.484
A6: plugin hybrid vehicle | B6: ='NVP-Indonesia'!B82*'NVP-Indonesia'!$B$227 -> 40685.859 | C6: ='NVP-Indonesia'!C82*'NVP-Indonesia'!$B$227 -> 41242.058 | D6: ='NVP-Indonesia'!D82*'NVP-Indonesia'!$B$227 -> 41182.553 | E6: ='NVP-Indonesia'!E82*'NVP-Indonesia'!$B$227 -> 41385.132 | F6: ='NVP-Indonesia'!F82*'NVP-Indonesia'!$B$227 -> 41430.439 | G6: ='NVP-Indonesia'!G82*'NVP-Indonesia'!$B$227 -> 41553.938 | H6: ='NVP-Indonesia'!H82*'NVP-Indonesia'!$B$227 -> 41604.402 | I6: ='NVP-Indonesia'!I82*'NVP-Indonesia'!$B$227 -> 41633.147 | ... AZ6: ='NVP-Indonesia'!AZ82*'NVP-Indonesia'!$B$227 -> 43670.122
A7: LPG vehicle | B7: ='NVP-Indonesia'!B83*'NVP-Indonesia'!$B$227 -> 39630.84 | C7: ='NVP-Indonesia'!C83*'NVP-Indonesia'!$B$227 -> 40279.913 | D7: ='NVP-Indonesia'!D83*'NVP-Indonesia'!$B$227 -> 40242.618 | E7: ='NVP-Indonesia'!E83*'NVP-Indonesia'!$B$227 -> 40312.727 | F7: ='NVP-Indonesia'!F83*'NVP-Indonesia'!$B$227 -> 40407.796 | G7: ='NVP-Indonesia'!G83*'NVP-Indonesia'!$B$227 -> 40584.919 | H7: ='NVP-Indonesia'!H83*'NVP-Indonesia'!$B$227 -> 40732.9 | I7: ='NVP-Indonesia'!I83*'NVP-Indonesia'!$B$227 -> 40808.85 | ... AZ7: ='NVP-Indonesia'!AZ83*'NVP-Indonesia'!$B$227 -> 43259.916
A8: hydrogen vehicle | B8: ='NVP-Indonesia'!B84*'NVP-Indonesia'!$B$227 -> 72784.944 | C8: ='NVP-Indonesia'!C84*'NVP-Indonesia'!$B$227 -> 72769.113 | D8: ='NVP-Indonesia'!D84*'NVP-Indonesia'!$B$227 -> 71195.128 | E8: ='NVP-Indonesia'!E84*'NVP-Indonesia'!$B$227 -> 69809.534 | F8: ='NVP-Indonesia'!F84*'NVP-Indonesia'!$B$227 -> 68409.935 | G8: ='NVP-Indonesia'!G84*'NVP-Indonesia'!$B$227 -> 66961.263 | H8: ='NVP-Indonesia'!H84*'NVP-Indonesia'!$B$227 -> 65688.591 | I8: ='NVP-Indonesia'!I84*'NVP-Indonesia'!$B$227 -> 64517.35 | ... AZ8: ='NVP-Indonesia'!AZ84*'NVP-Indonesia'!$B$227 -> 29193.744

Sheet BNVP-HDVs-psgr
A1: Price ($/vehicle) | B1: 2020 | C1: 2021 | D1: 2022 | E1: 2023 | F1: 2024 | G1: 2025 | H1: 2026 | I1: 2027 | J1: 2028 | K1: 2029 | L1: 2030 | M1: 2031 | N1: 2032 | O1: 2033 | P1: 2034 | Q1: 2035 | R1: 2036 | S1: 2037 | T1: 2038 | U1: 2039 | V1: 2040 | W1: 2041 | X1: 2042 | Y1: 2043 | Z1: 2044 | AA1: 2045 | AB1: 2046 | AC1: 2047 | AD1: 2048 | AE1: 2049 | AF1: 2050 | AG1: 2051 | AH1: 2052 | AI1: 2053 | AJ1: 2054 | AK1: 2055 | AL1: 2056 | AM1: 2057 | AN1: 2058 | AO1: 2059 | AP1: 2060 | AQ1: 2061 | AR1: 2062 | AS1: 2063 | AT1: 2064 | AU1: 2065 | AV1: 2066 | AW1: 2067 | AX1: 2068 | AY1: 2069 | AZ1: 2070
A2: battery electric vehicle | B2: ='Indonesia - HDV '!D34 -> 371621.62 | C2: =0 -> 0 | D2: =C2+C2*'NVP-Indonesia'!C202 -> 0 | E2: =D2+D2*'NVP-Indonesia'!D202 -> 0 | F2: =E2+E2*'NVP-Indonesia'!E202 -> 0 | G2: =F2+F2*'NVP-Indonesia'!F202 -> 0 | H2: =G2+G2*'NVP-Indonesia'!G202 -> 0 | I2: =H2+H2*'NVP-Indonesia'!H202 -> 0 | J2: =I2+I2*'NVP-Indonesia'!I202 -> 0 | K2: =J2+J2*'NVP-Indonesia'!J202 -> 0 | ... AZ2: =AY2+AY2*'NVP-Indonesia'!AY202 -> 0
A3: natural gas vehicle | B3: ='Indonesia - HDV '!D35 -> 135608.11 | C3: =B3+B3*'NVP-Indonesia'!B203 -> 135948.65 | D3: =C3+C3*'NVP-Indonesia'!C203 -> 135948.65 | E3: =D3+D3*'NVP-Indonesia'!D203 -> 135948.65 | F3: =E3+E3*'NVP-Indonesia'!E203 -> 135948.65 | G3: =F3+F3*'NVP-Indonesia'!F203 -> 135948.65 | H3: =G3+G3*'NVP-Indonesia'!G203 -> 135948.65 | I3: =H3+H3*'NVP-Indonesia'!H203 -> 135948.65 | J3: =I3+I3*'NVP-Indonesia'!I203 -> 135948.65 | ... AZ3: =AY3+AY3*'NVP-Indonesia'!AY203 -> 135948.65
A4: gasoline vehicle | B4: ='Indonesia - HDV '!D36 -> 84353.201 | C4: =B4+B4*'NVP-Indonesia'!B204 -> 84353.201 | D4: =C4+C4*'NVP-Indonesia'!C204 -> 84353.201 | E4: =D4+D4*'NVP-Indonesia'!D204 -> 84353.201 | F4: =E4+E4*'NVP-Indonesia'!E204 -> 84353.201 | G4: =F4+F4*'NVP-Indonesia'!F204 -> 84353.201 | H4: =G4+G4*'NVP-Indonesia'!G204 -> 84353.201 | I4: =H4+H4*'NVP-Indonesia'!H204 -> 84353.201 | J4: =I4+I4*'NVP-Indonesia'!I204 -> 84353.201 | ... AZ4: =AY4+AY4*'NVP-Indonesia'!AY204 -> 84353.201
A5: diesel vehicle | B5: ='Indonesia - HDV '!D37 -> 84353.201 | C5: =B5+B5*'NVP-Indonesia'!B205 -> 84353.201 | D5: =C5+C5*'NVP-Indonesia'!C205 -> 84353.201 | E5: =D5+D5*'NVP-Indonesia'!D205 -> 84353.201 | F5: =E5+E5*'NVP-Indonesia'!E205 -> 84353.201 | G5: =F5+F5*'NVP-Indonesia'!F205 -> 84353.201 | H5: =G5+G5*'NVP-Indonesia'!G205 -> 84353.201 | I5: =H5+H5*'NVP-Indonesia'!H205 -> 84353.201 | J5: =I5+I5*'NVP-Indonesia'!I205 -> 84353.201 | ... AZ5: =AY5+AY5*'NVP-Indonesia'!AY205 -> 84353.201
A6: plugin hybrid vehicle | B6: ='Indonesia - HDV '!D38 -> 371621.62 | C6: =B6+B6*'NVP-Indonesia'!B206 -> 372148.09 | D6: =C6+C6*'NVP-Indonesia'!C206 -> 372148.09 | E6: =D6+D6*'NVP-Indonesia'!D206 -> 372148.09 | F6: =E6+E6*'NVP-Indonesia'!E206 -> 372148.09 | G6: =F6+F6*'NVP-Indonesia'!F206 -> 372148.09 | H6: =G6+G6*'NVP-Indonesia'!G206 -> 372148.09 | I6: =H6+H6*'NVP-Indonesia'!H206 -> 372148.09 | J6: =I6+I6*'NVP-Indonesia'!I206 -> 372148.09 | ... AZ6: =AY6+AY6*'NVP-Indonesia'!AY206 -> 372148.09
A7: LPG vehicle | B7: ='Indonesia - HDV '!D39 -> 109980.65 | C7: =B7+B7*'NVP-Indonesia'!B207 -> 110173.55 | D7: =C7+C7*'NVP-Indonesia'!C207 -> 110173.55 | E7: =D7+D7*'NVP-Indonesia'!D207 -> 110173.55 | F7: =E7+E7*'NVP-Indonesia'!E207 -> 110173.55 | G7: =F7+F7*'NVP-Indonesia'!F207 -> 110173.55 | H7: =G7+G7*'NVP-Indonesia'!G207 -> 110173.55 | I7: =H7+H7*'NVP-Indonesia'!H207 -> 110173.55 | J7: =I7+I7*'NVP-Indonesia'!I207 -> 110173.55 | ... AZ7: =AY7+AY7*'NVP-Indonesia'!AY207 -> 110173.55
A8: hydrogen vehicle | B8: ='Indonesia - HDV '!D40 -> 1420000 | C8: =B8+B8*'NVP-Indonesia'!B208 -> 1394290.6 | D8: =C8+C8*'NVP-Indonesia'!C208 -> 1394290.6 | E8: =D8+D8*'NVP-Indonesia'!D208 -> 1394290.6 | F8: =E8+E8*'NVP-Indonesia'!E208 -> 1394290.6 | G8: =F8+F8*'NVP-Indonesia'!F208 -> 1394290.6 | H8: =G8+G8*'NVP-Indonesia'!G208 -> 1394290.6 | I8: =H8+H8*'NVP-Indonesia'!H208 -> 1394290.6 | J8: =I8+I8*'NVP-Indonesia'!I208 -> 1394290.6 | ... AZ8: =AY8+AY8*'NVP-Indonesia'!AY208 -> 1394290.6

Sheet BNVP-HDVs-frgt
A1: Price ($/vehicle) | B1: 2020 | C1: 2021 | D1: 2022 | E1: 2023 | F1: 2024 | G1: 2025 | H1: 2026 | I1: 2027 | J1: 2028 | K1: 2029 | L1: 2030 | M1: 2031 | N1: 2032 | O1: 2033 | P1: 2034 | Q1: 2035 | R1: 2036 | S1: 2037 | T1: 2038 | U1: 2039 | V1: 2040 | W1: 2041 | X1: 2042 | Y1: 2043 | Z1: 2044 | AA1: 2045 | AB1: 2046 | AC1: 2047 | AD1: 2048 | AE1: 2049 | AF1: 2050 | AG1: 2051 | AH1: 2052 | AI1: 2053 | AJ1: 2054 | AK1: 2055 | AL1: 2056 | AM1: 2057 | AN1: 2058 | AO1: 2059 | AP1: 2060 | AQ1: 2061 | AR1: 2062 | AS1: 2063 | AT1: 2064 | AU1: 2065 | AV1: 2066 | AW1: 2067 | AX1: 2068 | AY1: 2069 | AZ1: 2070
A2: battery electric vehicle | B2: ='Indonesia - HDV '!D34 -> 371621.62 | C2: 0 | D2: 0 | E2: 0 | F2: 0 | G2: 0 | H2: 0 | I2: 0 | J2: 0 | K2: 0 | L2: 0 | M2: 0 | N2: 0 | O2: 0 | P2: 0 | Q2: 0 | R2: 0 | S2: 0 | T2: 0 | U2: 0 | V2: 0 | W2: 0 | X2: 0 | Y2: 0 | Z2: 0 | AA2: 0 | AB2: 0 | AC2: 0 | AD2: 0 | AE2: 0 | AF2: 0 | AG2: 0 | AH2: 0 | AI2: 0 | AJ2: 0 | AK2: 0 | AL2: 0 | AM2: 0 | AN2: 0 | AO2: 0 | AP2: 0 | AQ2: 0 | AR2: 0 | AS2: 0 | AT2: 0 | AU2: 0 | AV2: 0 | AW2: 0 | AX2: 0 | AY2: 0 | AZ2: 0
A3: natural gas vehicle | B3: ='Indonesia - HDV '!D35 -> 135608.11 | C3: =B3 -> 135608.11 | D3: =C3 -> 135608.11 | E3: =D3 -> 135608.11 | F3: =E3 -> 135608.11 | G3: =F3 -> 135608.11 | H3: =G3 -> 135608.11 | I3: =H3 -> 135608.11 | J3: =I3 -> 135608.11 | ... AZ3: =AY3 -> 135608.11
A4: gasoline vehicle | B4: ='NVP-Indonesia'!B100*'NVP-Indonesia'!$B$227 -> 90895.799 | C4: ='NVP-Indonesia'!C100*'NVP-Indonesia'!$B$227 -> 90895.799 | D4: ='NVP-Indonesia'!D100*'NVP-Indonesia'!$B$227 -> 90895.799 | E4: ='NVP-Indonesia'!E100*'NVP-Indonesia'!$B$227 -> 90895.799 | F4: ='NVP-Indonesia'!F100*'NVP-Indonesia'!$B$227 -> 90895.799 | G4: ='NVP-Indonesia'!G100*'NVP-Indonesia'!$B$227 -> 90895.799 | H4: ='NVP-Indonesia'!H100*'NVP-Indonesia'!$B$227 -> 90895.799 | I4: ='NVP-Indonesia'!I100*'NVP-Indonesia'!$B$227 -> 90895.799 | ... AZ4: ='NVP-Indonesia'!AZ100*'NVP-Indonesia'!$B$227 -> 90895.799
A5: diesel vehicle | B5: ='NVP-Indonesia'!B101*'NVP-Indonesia'!$B$227 -> 90895.799 | C5: ='NVP-Indonesia'!C101*'NVP-Indonesia'!$B$227 -> 90895.799 | D5: ='NVP-Indonesia'!D101*'NVP-Indonesia'!$B$227 -> 90895.799 | E5: ='NVP-Indonesia'!E101*'NVP-Indonesia'!$B$227 -> 90895.799 | F5: ='NVP-Indonesia'!F101*'NVP-Indonesia'!$B$227 -> 90895.799 | G5: ='NVP-Indonesia'!G101*'NVP-Indonesia'!$B$227 -> 90895.799 | H5: ='NVP-Indonesia'!H101*'NVP-Indonesia'!$B$227 -> 90895.799 | I5: ='NVP-Indonesia'!I101*'NVP-Indonesia'!$B$227 -> 90895.799 | ... AZ5: ='NVP-Indonesia'!AZ101*'NVP-Indonesia'!$B$227 -> 90895.799
A6: plugin hybrid vehicle | B6: ='Indonesia - HDV '!D38 -> 371621.62 | C6: =B6 -> 371621.62 | D6: =C6 -> 371621.62 | E6: =D6 -> 371621.62 | F6: =E6 -> 371621.62 | G6: =F6 -> 371621.62 | H6: =G6 -> 371621.62 | I6: =H6 -> 371621.62 | J6: =I6 -> 371621.62 | ... AZ6: =AY6 -> 371621.62
A7: LPG vehicle | B7: ='NVP-Indonesia'!B103*'NVP-Indonesia'!$B$227 -> 128903.9 | C7: =B7 -> 128903.9 | D7: =C7 -> 128903.9 | E7: =D7 -> 128903.9 | F7: =E7 -> 128903.9 | G7: =F7 -> 128903.9 | H7: =G7 -> 128903.9 | I7: =H7 -> 128903.9 | J7: =I7 -> 128903.9 | ... AZ7: =AY7 -> 128903.9
A8: hydrogen vehicle | B8: ='Indonesia - HDV '!D40 -> 1420000 | C8: =B8 -> 1420000 | D8: =C8 -> 1420000 | E8: =D8 -> 1420000 | F8: =E8 -> 1420000 | G8: =F8 -> 1420000 | H8: =G8 -> 1420000 | I8: =H8 -> 1420000 | J8: =I8 -> 1420000 | ... AZ8: =AY8 -> 1420000

Sheet BNVP-aircraft-psgr
A1: Price ($/vehicle) | B1: 2020 | C1: 2021 | D1: 2022 | E1: 2023 | F1: 2024 | G1: 2025 | H1: 2026 | I1: 2027 | J1: 2028 | K1: 2029 | L1: 2030 | M1: 2031 | N1: 2032 | O1: 2033 | P1: 2034 | Q1: 2035 | R1: 2036 | S1: 2037 | T1: 2038 | U1: 2039 | V1: 2040 | W1: 2041 | X1: 2042 | Y1: 2043 | Z1: 2044 | AA1: 2045 | AB1: 2046 | AC1: 2047 | AD1: 2048 | AE1: 2049 | AF1: 2050 | AG1: 2051 | AH1: 2052 | AI1: 2053 | AJ1: 2054 | AK1: 2055 | AL1: 2056 | AM1: 2057 | AN1: 2058 | AO1: 2059 | AP1: 2060 | AQ1: 2061 | AR1: 2062 | AS1: 2063 | AT1: 2064 | AU1: 2065 | AV1: 2066 | AW1: 2067 | AX1: 2068 | AY1: 2069 | AZ1: 2070
A2: battery electric vehicle | B2: ='NVP-Indonesia'!B108*'NVP-Indonesia'!$B$227 -> 93481595 | C2: 0 | D2: =C2 -> 0 | E2: =D2 -> 0 | F2: =E2 -> 0 | G2: =F2 -> 0 | H2: =G2 -> 0 | I2: =H2 -> 0 | J2: =I2 -> 0 | K2: =J2 -> 0 | ... AZ2: =AY2 -> 0
A3: natural gas vehicle | B3: 999999999 | C3: 999999999 | D3: 999999999 | E3: 999999999 | F3: 999999999 | G3: 999999999 | H3: 999999999 | I3: 999999999 | J3: 999999999 | K3: 999999999 | L3: 999999999 | M3: 999999999 | N3: 999999999 | O3: 999999999 | P3: 999999999 | Q3: 999999999 | R3: 999999999 | S3: 999999999 | T3: 999999999 | U3: 999999999 | V3: 999999999 | W3: 999999999 | X3: 999999999 | Y3: 999999999 | Z3: 999999999 | AA3: 999999999 | AB3: 999999999 | AC3: 999999999 | AD3: 999999999 | AE3: 999999999 | AF3: 999999999 | AG3: 999999999 | AH3: 999999999 | AI3: 999999999 | AJ3: 999999999 | AK3: 999999999 | AL3: 999999999 | AM3: 999999999 | AN3: 999999999 | AO3: 999999999 | AP3: 999999999 | AQ3: 999999999 | AR3: 999999999 | AS3: 999999999 | AT3: 999999999 | AU3: 999999999 | AV3: 999999999 | AW3: 999999999 | AX3: 999999999 | AY3: 999999999 | AZ3: 999999999
A4: gasoline vehicle | B4: 999999999 | C4: 999999999 | D4: 999999999 | E4: 999999999 | F4: 999999999 | G4: 999999999 | H4: 999999999 | I4: 999999999 | J4: 999999999 | K4: 999999999 | L4: 999999999 | M4: 999999999 | N4: 999999999 | O4: 999999999 | P4: 999999999 | Q4: 999999999 | R4: 999999999 | S4: 999999999 | T4: 999999999 | U4: 999999999 | V4: 999999999 | W4: 999999999 | X4: 999999999 | Y4: 999999999 | Z4: 999999999 | AA4: 999999999 | AB4: 999999999 | AC4: 999999999 | AD4: 999999999 | AE4: 999999999 | AF4: 999999999 | AG4: 999999999 | AH4: 999999999 | AI4: 999999999 | AJ4: 999999999 | AK4: 999999999 | AL4: 999999999 | AM4: 999999999 | AN4: 999999999 | AO4: 999999999 | AP4: 999999999 | AQ4: 999999999 | AR4: 999999999 | AS4: 999999999 | AT4: 999999999 | AU4: 999999999 | AV4: 999999999 | AW4: 999999999 | AX4: 999999999 | AY4: 999999999 | AZ4: 999999999
A5: diesel vehicle | B5: ='NVP-Indonesia'!B111*'NVP-Indonesia'!$B$227 -> 50570000 | C5: =$B5 -> 50570000 | D5: =$B5 -> 50570000 | E5: =$B5 -> 50570000 | F5: =$B5 -> 50570000 | G5: =$B5 -> 50570000 | H5: =$B5 -> 50570000 | I5: =$B5 -> 50570000 | J5: =$B5 -> 50570000 | ... AF5: =$B5 -> 50570000 | AG5: =_xlfn.FORECAST.LINEAR(AG$1,$B5:$AF5,$B$1:$AF$1) -> 50570000 | AH5: =_xlfn.FORECAST.LINEAR(AH$1,$B5:$AF5,$B$1:$AF$1) -> 50570000 | AI5: =_xlfn.FORECAST.LINEAR(AI$1,$B5:$AF5,$B$1:$AF$1) -> 50570000 | AJ5: =_xlfn.FORECAST.LINEAR(AJ$1,$B5:$AF5,$B$1:$AF$1) -> 50570000 | AK5: =_xlfn.FORECAST.LINEAR(AK$1,$B5:$AF5,$B$1:$AF$1) -> 50570000 | AL5: =_xlfn.FORECAST.LINEAR(AL$1,$B5:$AF5,$B$1:$AF$1) -> 50570000 | AM5: =_xlfn.FORECAST.LINEAR(AM$1,$B5:$AF5,$B$1:$AF$1) -> 50570000 | AN5: =_xlfn.FORECAST.LINEAR(AN$1,$B5:$AF5,$B$1:$AF$1) -> 50570000 | ... AZ5: =_xlfn.FORECAST.LINEAR(AZ$1,$B5:$AF5,$B$1:$AF$1) -> 50570000
A6: plugin hybrid vehicle | B6: 999999999 | C6: 999999999 | D6: 999999999 | E6: 999999999 | F6: 999999999 | G6: 999999999 | H6: 999999999 | I6: 999999999 | J6: 999999999 | K6: 999999999 | L6: 999999999 | M6: 999999999 | N6: 999999999 | O6: 999999999 | P6: 999999999 | Q6: 999999999 | R6: 999999999 | S6: 999999999 | T6: 999999999 | U6: 999999999 | V6: 999999999 | W6: 999999999 | X6: 999999999 | Y6: 999999999 | Z6: 999999999 | AA6: 999999999 | AB6: 999999999 | AC6: 999999999 | AD6: 999999999 | AE6: 999999999 | AF6: 999999999 | AG6: 999999999 | AH6: 999999999 | AI6: 999999999 | AJ6: 999999999 | AK6: 999999999 | AL6: 999999999 | AM6: 999999999 | AN6: 999999999 | AO6: 999999999 | AP6: 999999999 | AQ6: 999999999 | AR6: 999999999 | AS6: 999999999 | AT6: 999999999 | AU6: 999999999 | AV6: 999999999 | AW6: 999999999 | AX6: 999999999 | AY6: 999999999 | AZ6: 999999999
A7: LPG vehicle | B7: 999999999 | C7: 999999999 | D7: 999999999 | E7: 999999999 | F7: 999999999 | G7: 999999999 | H7: 999999999 | I7: 999999999 | J7: 999999999 | K7: 999999999 | L7: 999999999 | M7: 999999999 | N7: 999999999 | O7: 999999999 | P7: 999999999 | Q7: 999999999 | R7: 999999999 | S7: 999999999 | T7: 999999999 | U7: 999999999 | V7: 999999999 | W7: 999999999 | X7: 999999999 | Y7: 999999999 | Z7: 999999999 | AA7: 999999999 | AB7: 999999999 | AC7: 999999999 | AD7: 999999999 | AE7: 999999999 | AF7: 999999999 | AG7: 999999999 | AH7: 999999999 | AI7: 999999999 | AJ7: 999999999 | AK7: 999999999 | AL7: 999999999 | AM7: 999999999 | AN7: 999999999 | AO7: 999999999 | AP7: 999999999 | AQ7: 999999999 | AR7: 999999999 | AS7: 999999999 | AT7: 999999999 | AU7: 999999999 | AV7: 999999999 | AW7: 999999999 | AX7: 999999999 | AY7: 999999999 | AZ7: 999999999
A8: hydrogen vehicle | B8: ='NVP-Indonesia'!B114*'NVP-Indonesia'!$B$227 -> 1.017605e+08 | C8: =B8 -> 1.017605e+08 | D8: =C8 -> 1.017605e+08 | E8: =D8 -> 1.017605e+08 | F8: =E8 -> 1.017605e+08 | G8: =F8 -> 1.017605e+08 | H8: =G8 -> 1.017605e+08 | I8: =H8 -> 1.017605e+08 | J8: =I8 -> 1.017605e+08 | ... AZ8: =AY8 -> 1.017605e+08

Sheet BNVP-rail-psgr
A1: Price ($/vehicle) | B1: 2020 | C1: 2021 | D1: 2022 | E1: 2023 | F1: 2024 | G1: 2025 | H1: 2026 | I1: 2027 | J1: 2028 | K1: 2029 | L1: 2030 | M1: 2031 | N1: 2032 | O1: 2033 | P1: 2034 | Q1: 2035 | R1: 2036 | S1: 2037 | T1: 2038 | U1: 2039 | V1: 2040 | W1: 2041 | X1: 2042 | Y1: 2043 | Z1: 2044 | AA1: 2045 | AB1: 2046 | AC1: 2047 | AD1: 2048 | AE1: 2049 | AF1: 2050 | AG1: 2051 | AH1: 2052 | AI1: 2053 | AJ1: 2054 | AK1: 2055 | AL1: 2056 | AM1: 2057 | AN1: 2058 | AO1: 2059 | AP1: 2060 | AQ1: 2061 | AR1: 2062 | AS1: 2063 | AT1: 2064 | AU1: 2065 | AV1: 2066 | AW1: 2067 | AX1: 2068 | AY1: 2069 | AZ1: 2070
A2: battery electric vehicle | B2: ='NVP-Indonesia'!B118*'NVP-Indonesia'!$B$227 -> 3250000 | C2: 0 | D2: =C2 -> 0 | E2: =D2 -> 0 | F2: =E2 -> 0 | G2: =F2 -> 0 | H2: =G2 -> 0 | I2: =H2 -> 0 | J2: =I2 -> 0 | K2: =J2 -> 0 | ... AZ2: =AY2 -> 0
A3: natural gas vehicle | B3: 999999999 | C3: 999999999 | D3: 999999999 | E3: 999999999 | F3: 999999999 | G3: 999999999 | H3: 999999999 | I3: 999999999 | J3: 999999999 | K3: 999999999 | L3: 999999999 | M3: 999999999 | N3: 999999999 | O3: 999999999 | P3: 999999999 | Q3: 999999999 | R3: 999999999 | S3: 999999999 | T3: 999999999 | U3: 999999999 | V3: 999999999 | W3: 999999999 | X3: 999999999 | Y3: 999999999 | Z3: 999999999 | AA3: 999999999 | AB3: 999999999 | AC3: 999999999 | AD3: 999999999 | AE3: 999999999 | AF3: 999999999 | AG3: 999999999 | AH3: 999999999 | AI3: 999999999 | AJ3: 999999999 | AK3: 999999999 | AL3: 999999999 | AM3: 999999999 | AN3: 999999999 | AO3: 999999999 | AP3: 999999999 | AQ3: 999999999 | AR3: 999999999 | AS3: 999999999 | AT3: 999999999 | AU3: 999999999 | AV3: 999999999 | AW3: 999999999 | AX3: 999999999 | AY3: 999999999 | AZ3: 999999999
A4: gasoline vehicle | B4: 999999999 | C4: 999999999 | D4: 999999999 | E4: 999999999 | F4: 999999999 | G4: 999999999 | H4: 999999999 | I4: 999999999 | J4: 999999999 | K4: 999999999 | L4: 999999999 | M4: 999999999 | N4: 999999999 | O4: 999999999 | P4: 999999999 | Q4: 999999999 | R4: 999999999 | S4: 999999999 | T4: 999999999 | U4: 999999999 | V4: 999999999 | W4: 999999999 | X4: 999999999 | Y4: 999999999 | Z4: 999999999 | AA4: 999999999 | AB4: 999999999 | AC4: 999999999 | AD4: 999999999 | AE4: 999999999 | AF4: 999999999 | AG4: 999999999 | AH4: 999999999 | AI4: 999999999 | AJ4: 999999999 | AK4: 999999999 | AL4: 999999999 | AM4: 999999999 | AN4: 999999999 | AO4: 999999999 | AP4: 999999999 | AQ4: 999999999 | AR4: 999999999 | AS4: 999999999 | AT4: 999999999 | AU4: 999999999 | AV4: 999999999 | AW4: 999999999 | AX4: 999999999 | AY4: 999999999 | AZ4: 999999999
A5: diesel vehicle | B5: ='NVP-Indonesia'!B121*'NVP-Indonesia'!$B$227 -> 1751206.9 | C5: =$B5 -> 1751206.9 | D5: =$B5 -> 1751206.9 | E5: =$B5 -> 1751206.9 | F5: =$B5 -> 1751206.9 | G5: =$B5 -> 1751206.9 | H5: =$B5 -> 1751206.9 | I5: =$B5 -> 1751206.9 | J5: =$B5 -> 1751206.9 | ... AF5: =$B5 -> 1751206.9 | AG5: =_xlfn.FORECAST.LINEAR(AG$1,$B5:$AF5,$B$1:$AF$1) -> 1751206.9 | AH5: =_xlfn.FORECAST.LINEAR(AH$1,$B5:$AF5,$B$1:$AF$1) -> 1751206.9 | AI5: =_xlfn.FORECAST.LINEAR(AI$1,$B5:$AF5,$B$1:$AF$1) -> 1751206.9 | AJ5: =_xlfn.FORECAST.LINEAR(AJ$1,$B5:$AF5,$B$1:$AF$1) -> 1751206.9 | AK5: =_xlfn.FORECAST.LINEAR(AK$1,$B5:$AF5,$B$1:$AF$1) -> 1751206.9 | AL5: =_xlfn.FORECAST.LINEAR(AL$1,$B5:$AF5,$B$1:$AF$1) -> 1751206.9 | AM5: =_xlfn.FORECAST.LINEAR(AM$1,$B5:$AF5,$B$1:$AF$1) -> 1751206.9 | AN5: =_xlfn.FORECAST.LINEAR(AN$1,$B5:$AF5,$B$1:$AF$1) -> 1751206.9 | ... AZ5: =_xlfn.FORECAST.LINEAR(AZ$1,$B5:$AF5,$B$1:$AF$1) -> 1751206.9
A6: plugin hybrid vehicle | B6: 999999999 | C6: 999999999 | D6: 999999999 | E6: 999999999 | F6: 999999999 | G6: 999999999 | H6: 999999999 | I6: 999999999 | J6: 999999999 | K6: 999999999 | L6: 999999999 | M6: 999999999 | N6: 999999999 | O6: 999999999 | P6: 999999999 | Q6: 999999999 | R6: 999999999 | S6: 999999999 | T6: 999999999 | U6: 999999999 | V6: 999999999 | W6: 999999999 | X6: 999999999 | Y6: 999999999 | Z6: 999999999 | AA6: 999999999 | AB6: 999999999 | AC6: 999999999 | AD6: 999999999 | AE6: 999999999 | AF6: 999999999 | AG6: 999999999 | AH6: 999999999 | AI6: 999999999 | AJ6: 999999999 | AK6: 999999999 | AL6: 999999999 | AM6: 999999999 | AN6: 999999999 | AO6: 999999999 | AP6: 999999999 | AQ6: 999999999 | AR6: 999999999 | AS6: 999999999 | AT6: 999999999 | AU6: 999999999 | AV6: 999999999 | AW6: 999999999 | AX6: 999999999 | AY6: 999999999 | AZ6: 999999999
A7: LPG vehicle | B7: 999999999 | C7: 999999999 | D7: 999999999 | E7: 999999999 | F7: 999999999 | G7: 999999999 | H7: 999999999 | I7: 999999999 | J7: 999999999 | K7: 999999999 | L7: 999999999 | M7: 999999999 | N7: 999999999 | O7: 999999999 | P7: 999999999 | Q7: 999999999 | R7: 999999999 | S7: 999999999 | T7: 999999999 | U7: 999999999 | V7: 999999999 | W7: 999999999 | X7: 999999999 | Y7: 999999999 | Z7: 999999999 | AA7: 999999999 | AB7: 999999999 | AC7: 999999999 | AD7: 999999999 | AE7: 999999999 | AF7: 999999999 | AG7: 999999999 | AH7: 999999999 | AI7: 999999999 | AJ7: 999999999 | AK7: 999999999 | AL7: 999999999 | AM7: 999999999 | AN7: 999999999 | AO7: 999999999 | AP7: 999999999 | AQ7: 999999999 | AR7: 999999999 | AS7: 999999999 | AT7: 999999999 | AU7: 999999999 | AV7: 999999999 | AW7: 999999999 | AX7: 999999999 | AY7: 999999999 | AZ7: 999999999
A8: hydrogen vehicle | B8: ='NVP-Indonesia'!B124*'NVP-Indonesia'!$B$227 -> 2311593.1 | C8: =$B$8*'BNVP-HDVs-frgt'!C8/'BNVP-HDVs-frgt'!$B$8 -> 2311593.1 | D8: =$B$8*'BNVP-HDVs-frgt'!D8/'BNVP-HDVs-frgt'!$B$8 -> 2311593.1 | E8: =$B$8*'BNVP-HDVs-frgt'!E8/'BNVP-HDVs-frgt'!$B$8 -> 2311593.1 | F8: =$B$8*'BNVP-HDVs-frgt'!F8/'BNVP-HDVs-frgt'!$B$8 -> 2311593.1 | G8: =$B$8*'BNVP-HDVs-frgt'!G8/'BNVP-HDVs-frgt'!$B$8 -> 2311593.1 | H8: =$B$8*'BNVP-HDVs-frgt'!H8/'BNVP-HDVs-frgt'!$B$8 -> 2311593.1 | I8: =$B$8*'BNVP-HDVs-frgt'!I8/'BNVP-HDVs-frgt'!$B$8 -> 2311593.1 | J8: =$B$8*'BNVP-HDVs-frgt'!J8/'BNVP-HDVs-frgt'!$B$8 -> 2311593.1 | ... AF8: =$B$8*'BNVP-HDVs-frgt'!AF8/'BNVP-HDVs-frgt'!$B$8 -> 2311593.1 | AG8: =_xlfn.FORECAST.LINEAR(AG$1,$B8:$AF8,$B$1:$AF$1) -> 2311593.1 | AH8: =_xlfn.FORECAST.LINEAR(AH$1,$B8:$AF8,$B$1:$AF$1) -> 2311593.1 | AI8: =_xlfn.FORECAST.LINEAR(AI$1,$B8:$AF8,$B$1:$AF$1) -> 2311593.1 | AJ8: =_xlfn.FORECAST.LINEAR(AJ$1,$B8:$AF8,$B$1:$AF$1) -> 2311593.1 | AK8: =_xlfn.FORECAST.LINEAR(AK$1,$B8:$AF8,$B$1:$AF$1) -> 2311593.1 | AL8: =_xlfn.FORECAST.LINEAR(AL$1,$B8:$AF8,$B$1:$AF$1) -> 2311593.1 | AM8: =_xlfn.FORECAST.LINEAR(AM$1,$B8:$AF8,$B$1:$AF$1) -> 2311593.1 | AN8: =_xlfn.FORECAST.LINEAR(AN$1,$B8:$AF8,$B$1:$AF$1) -> 2311593.1 | ... AZ8: =_xlfn.FORECAST.LINEAR(AZ$1,$B8:$AF8,$B$1:$AF$1) -> 2311593.1

Sheet BNVP-aircraft-frgt
A1: Price ($/vehicle) | B1: 2020 | C1: 2021 | D1: 2022 | E1: 2023 | F1: 2024 | G1: 2025 | H1: 2026 | I1: 2027 | J1: 2028 | K1: 2029 | L1: 2030 | M1: 2031 | N1: 2032 | O1: 2033 | P1: 2034 | Q1: 2035 | R1: 2036 | S1: 2037 | T1: 2038 | U1: 2039 | V1: 2040 | W1: 2041 | X1: 2042 | Y1: 2043 | Z1: 2044 | AA1: 2045 | AB1: 2046 | AC1: 2047 | AD1: 2048 | AE1: 2049 | AF1: 2050 | AG1: 2051 | AH1: 2052 | AI1: 2053 | AJ1: 2054 | AK1: 2055 | AL1: 2056 | AM1: 2057 | AN1: 2058 | AO1: 2059 | AP1: 2060 | AQ1: 2061 | AR1: 2062 | AS1: 2063 | AT1: 2064 | AU1: 2065 | AV1: 2066 | AW1: 2067 | AX1: 2068 | AY1: 2069 | AZ1: 2070
A2: battery electric vehicle | B2: ='NVP-Indonesia'!B128*'NVP-Indonesia'!$B$227 -> 93481595 | C2: 0 | D2: =C2 -> 0 | E2: =D2 -> 0 | F2: =E2 -> 0 | G2: =F2 -> 0 | H2: =G2 -> 0 | I2: =H2 -> 0 | J2: =I2 -> 0 | K2: =J2 -> 0 | ... AZ2: =AY2 -> 0
A3: natural gas vehicle | B3: 999999999 | C3: 999999999 | D3: 999999999 | E3: 999999999 | F3: 999999999 | G3: 999999999 | H3: 999999999 | I3: 999999999 | J3: 999999999 | K3: 999999999 | L3: 999999999 | M3: 999999999 | N3: 999999999 | O3: 999999999 | P3: 999999999 | Q3: 999999999 | R3: 999999999 | S3: 999999999 | T3: 999999999 | U3: 999999999 | V3: 999999999 | W3: 999999999 | X3: 999999999 | Y3: 999999999 | Z3: 999999999 | AA3: 999999999 | AB3: 999999999 | AC3: 999999999 | AD3: 999999999 | AE3: 999999999 | AF3: 999999999 | AG3: 999999999 | AH3: 999999999 | AI3: 999999999 | AJ3: 999999999 | AK3: 999999999 | AL3: 999999999 | AM3: 999999999 | AN3: 999999999 | AO3: 999999999 | AP3: 999999999 | AQ3: 999999999 | AR3: 999999999 | AS3: 999999999 | AT3: 999999999 | AU3: 999999999 | AV3: 999999999 | AW3: 999999999 | AX3: 999999999 | AY3: 999999999 | AZ3: 999999999
A4: gasoline vehicle | B4: 999999999 | C4: 999999999 | D4: 999999999 | E4: 999999999 | F4: 999999999 | G4: 999999999 | H4: 999999999 | I4: 999999999 | J4: 999999999 | K4: 999999999 | L4: 999999999 | M4: 999999999 | N4: 999999999 | O4: 999999999 | P4: 999999999 | Q4: 999999999 | R4: 999999999 | S4: 999999999 | T4: 999999999 | U4: 999999999 | V4: 999999999 | W4: 999999999 | X4: 999999999 | Y4: 999999999 | Z4: 999999999 | AA4: 999999999 | AB4: 999999999 | AC4: 999999999 | AD4: 999999999 | AE4: 999999999 | AF4: 999999999 | AG4: 999999999 | AH4: 999999999 | AI4: 999999999 | AJ4: 999999999 | AK4: 999999999 | AL4: 999999999 | AM4: 999999999 | AN4: 999999999 | AO4: 999999999 | AP4: 999999999 | AQ4: 999999999 | AR4: 999999999 | AS4: 999999999 | AT4: 999999999 | AU4: 999999999 | AV4: 999999999 | AW4: 999999999 | AX4: 999999999 | AY4: 999999999 | AZ4: 999999999
A5: diesel vehicle | B5: ='NVP-Indonesia'!B131*'NVP-Indonesia'!$B$227 -> 50570000 | C5: =$B5 -> 50570000 | D5: =$B5 -> 50570000 | E5: =$B5 -> 50570000 | F5: =$B5 -> 50570000 | G5: =$B5 -> 50570000 | H5: =$B5 -> 50570000 | I5: =$B5 -> 50570000 | J5: =$B5 -> 50570000 | ... AF5: =$B5 -> 50570000 | AG5: =_xlfn.FORECAST.LINEAR(AG$1,$B5:$AF5,$B$1:$AF$1) -> 50570000 | AH5: =_xlfn.FORECAST.LINEAR(AH$1,$B5:$AF5,$B$1:$AF$1) -> 50570000 | AI5: =_xlfn.FORECAST.LINEAR(AI$1,$B5:$AF5,$B$1:$AF$1) -> 50570000 | AJ5: =_xlfn.FORECAST.LINEAR(AJ$1,$B5:$AF5,$B$1:$AF$1) -> 50570000 | AK5: =_xlfn.FORECAST.LINEAR(AK$1,$B5:$AF5,$B$1:$AF$1) -> 50570000 | AL5: =_xlfn.FORECAST.LINEAR(AL$1,$B5:$AF5,$B$1:$AF$1) -> 50570000 | AM5: =_xlfn.FORECAST.LINEAR(AM$1,$B5:$AF5,$B$1:$AF$1) -> 50570000 | AN5: =_xlfn.FORECAST.LINEAR(AN$1,$B5:$AF5,$B$1:$AF$1) -> 50570000 | ... AZ5: =_xlfn.FORECAST.LINEAR(AZ$1,$B5:$AF5,$B$1:$AF$1) -> 50570000
