Workbook
Name billion: About!$A$84
Name Eno_TM: '[1]1997 Table 1a Modified'!#REF!
Name Eno_Tons: '[1]1997 Table 1a Modified'!#REF!
Name NTS_YR: About!$B$149
Name Sum_T2: '[1]1997 Table 1a Modified'!#REF!
Name Sum_TTM: '[1]1997 Table 1a Modified'!#REF!
Name ti_tbl_50: #REF!
Name ti_tbl_50: #REF!
Name ti_tbl_69: #REF!
Name ti_tbl_69: #REF!
Name trillion: About!$A$85

Sheet About
A1: SYFAFE Start Year Fleet Avg Fuel Economy
A3: Source | B3: IESR (2024)
B4: https://iesr.or.id/en/
A10: Comments | B10: These data come from the LEAP (Long-range Energy Alternatives Planning) Indonesia model and represent BAU (Business As Usual) scenarios projected for the country. The BAU scenarios assume no significant changes to current energy policies or interventions, providing a baseline for analyzing future energy consumption, emissions, and sectoral growth under existing conditions. This model helps evaluate long-term trends in Indonesia's energy use and environmental impacts, serving as a foundation for comparing potential outcomes from alternative policy scenarios aimed at sustainable development and climate goals.

Sheet Level of Activity (LA) - psgr
A1: Variable: Car: Total Activity (Billion Passenger-km)
A2: Scenario: Business as Usual
A3: Branch: Demand\Transportation\Passenger\Road Transport\Car\Gasoline Car
A4: Region: Indonesia
A5: Billion Passenger-km to Passenger*miles | B5: 621371000
A6: Branch | B6: 2022 | C6: 2023 | D6: 2024 | E6: 2025 | F6: 2026 | G6: 2027 | H6: 2028 | I6: 2029 | J6: 2030 | K6: 2031 | L6: 2032 | M6: 2033 | N6: 2034 | O6: 2035 | P6: 2036 | Q6: 2037 | R6: 2038 | S6: 2039 | T6: 2040 | U6: 2041 | V6: 2042 | W6: 2043 | X6: 2044 | Y6: 2045 | Z6: 2046 | AA6: 2047 | AB6: 2048 | AC6: 2049 | AD6: 2050 | AE6: 2051 | AF6: 2052 | AG6: 2053 | AH6: 2054 | AI6: 2055 | AJ6: 2056 | AK6: 2057 | AL6: 2058 | AM6: 2059 | AN6: 2060
A7: Gasoline Car | B7: 323.83387 | C7: 332.93373 | D7: 342.2893 | E7: 351.90776 | F7: 361.7965 | G7: 371.96312 | H7: 382.41543 | I7: 393.16145 | J7: 404.20944 | K7: 415.56788 | L7: 427.2455 | M7: 439.25126 | N7: 451.59439 | O7: 464.28437 | P7: 477.33094 | Q7: 490.74412 | R7: 504.53422 | S7: 518.71182 | T7: 533.28783 | U7: 548.27342 | V7: 563.68011 | W7: 579.51974 | X7: 595.80447 | Y7: 612.54681 | Z7: 629.75961 | AA7: 647.45609 | AB7: 665.64986 | AC7: 684.35488 | AD7: 703.58551 | AE7: 723.35654 | AF7: 743.68313 | AG7: 764.58092 | AH7: 786.06593 | AI7: 808.15469 | AJ7: 830.86415 | AK7: 854.21175 | AL7: 878.21543 | AM7: 902.89362 | AN7: 928.26528
A8: Electric Car | B8: 0.32854726 | C8: 0.33777957 | D8: 0.3472713 | E8: 0.35702976 | F8: 0.36706244 | G8: 0.37737703 | H8: 0.38798147 | I8: 0.3988839 | J8: 0.41009269 | K8: 0.42161645 | L8: 0.43346404 | M8: 0.44564455 | N8: 0.45816733 | O8: 0.47104201 | P8: 0.48427847 | Q8: 0.49788688 | R8: 0.51187769 | S8: 0.52626165 | T8: 0.54104981 | U8: 0.55625352 | V8: 0.57188446 | W8: 0.58795463 | X8: 0.60447638 | Y8: 0.6214624 | Z8: 0.63892573 | AA8: 0.65687979 | AB8: 0.67533837 | AC8: 0.69431564 | AD8: 0.71382617 | AE8: 0.73388496 | AF8: 0.75450741 | AG8: 0.77570936 | AH8: 0.79750709 | AI8: 0.81991735 | AJ8: 0.84295734 | AK8: 0.86664477 | AL8: 0.89099782 | AM8: 0.9160352 | AN8: 0.94177615
A9: CNG Car | B9: 0.32433512 | C9: 0.33344906 | D9: 0.34281911 | E9: 0.35245246 | F9: 0.36235651 | G9: 0.37253886 | H9: 0.38300735 | I9: 0.39377 | J9: 0.40483509 | K9: 0.41621112 | L9: 0.42790681 | M9: 0.43993115 | N9: 0.45229339 | O9: 0.46500301 | P9: 0.47806977 | Q9: 0.49150372 | R9: 0.50531516 | S9: 0.51951471 | T9: 0.53411327 | U9: 0.54912206 | V9: 0.5645526 | W9: 0.58041675 | X9: 0.59672668 | Y9: 0.61349493 | Z9: 0.63073438 | AA9: 0.64845826 | AB9: 0.66668018 | AC9: 0.68541415 | AD9: 0.70467456 | AE9: 0.72447618 | AF9: 0.74483424 | AG9: 0.76576437 | AH9: 0.78728264 | AI9: 0.80940559 | AJ9: 0.8321502 | AK9: 0.85553394 | AL9: 0.87957477 | AM9: 0.90429116 | AN9: 0.92970209
A10: Diesel Car | B10: 5.3296954 | C10: 5.4794619 | D10: 5.6334369 | E10: 5.7917386 | F10: 5.9544887 | G10: 6.1218121 | H10: 6.2938374 | I10: 6.4706967 | J10: 6.6525258 | K10: 6.8394643 | L10: 7.0316559 | M10: 7.2292481 | N10: 7.4323928 | O10: 7.6412459 | P10: 7.8559678 | Q10: 8.0767235 | R10: 8.3036826 | S10: 8.5370193 | T10: 8.7769128 | U10: 9.0235474 | V10: 9.2771126 | W10: 9.537803 | X10: 9.805819 | Y10: 10.081366 | Z10: 10.364657 | AA10: 10.655907 | AB10: 10.955342 | AC10: 11.263192 | AD10: 11.579692 | AE10: 11.905086 | AF10: 12.239623 | AG10: 12.583561 | AH10: 12.937164 | AI10: 13.300703 | AJ10: 13.674458 | AK10: 14.058716 | AL10: 14.453771 | AM10: 14.859928 | AN10: 15.277497
A11: BioGasoil Car | B11: 91.397989 | C11: 93.966308 | D11: 96.606797 | E11: 99.321485 | F11: 102.11246 | G11: 104.98186 | H11: 107.93189 | I11: 110.96481 | J11: 114.08297 | K11: 117.28874 | L11: 120.5846 | M11: 123.97308 | N11: 127.45677 | O11: 131.03835 | P11: 134.72058 | Q11: 138.50628 | R11: 142.39836 | S11: 146.39981 | T11: 150.5137 | U11: 154.74319 | V11: 159.09154 | W11: 163.56207 | X11: 168.15823 | Y11: 172.88354 | Z11: 177.74163 | AA11: 182.73624 | AB11: 187.8712 | AC11: 193.15045 | AD11: 198.57805 | AE11: 204.15817 | AF11: 209.8951 | AG11: 215.79323 | AH11: 221.8571 | AI11: 228.09137 | AJ11: 234.50083 | AK11: 241.09039 | AL11: 247.86513 | AM11: 254.83023 | AN11: 261.99106
A14: Variable: Motorcycle: Total Activity (Billion Passenger-km)
A15: Scenario: Business as Usual
A16: Branch: Demand\Transportation\Passenger\Road Transport\Motorcycle\Gasoline Motorcycle
A17: Region: Indonesia
A18: Billion Passenger-km to Passenger*miles | B18: 621371000
A19: Branch | B19: 2022 | C19: 2023 | D19: 2024 | E19: 2025 | F19: 2026 | G19: 2027 | H19: 2028 | I19: 2029 | J19: 2030 | K19: 2031 | L19: 2032 | M19: 2033 | N19: 2034 | O19: 2035 | P19: 2036 | Q19: 2037 | R19: 2038 | S19: 2039 | T19: 2040 | U19: 2041 | V19: 2042 | W19: 2043 | X19: 2044 | Y19: 2045 | Z19: 2046 | AA19: 2047 | AB19: 2048 | AC19: 2049 | AD19: 2050 | AE19: 2051 | AF19: 2052 | AG19: 2053 | AH19: 2054 | AI19: 2055 | AJ19: 2056 | AK19: 2057 | AL19: 2058 | AM19: 2059 | AN19: 2060
A20: Gasoline Motorcycle | B20: 1351.126 | C20: 1389.0931 | D20: 1428.1272 | E20: 1468.2581 | F20: 1509.5167 | G20: 1551.9347 | H20: 1595.5447 | I20: 1640.3801 | J20: 1686.4754 | K20: 1733.866 | L20: 1782.5883 | M20: 1832.6798 | N20: 1884.1788 | O20: 1937.1249 | P20: 1991.5589 | Q20: 2047.5224 | R20: 2105.0586 | S20: 2164.2116 | T20: 2225.0268 | U20: 2287.5509 | V20: 2351.8319 | W20: 2417.9193 | X20: 2485.8638 | Y20: 2555.7175 | Z20: 2627.5341 | AA20: 2701.3689 | AB20: 2777.2784 | AC20: 2855.321 | AD20: 2935.5566 | AE20: 3018.0469 | AF20: 3102.8551 | AG20: 3190.0466 | AH20: 3279.6881 | AI20: 3371.8486 | AJ20: 3466.5988 | AK20: 3564.0116 | AL20: 3664.1617 | AM20: 3767.1261 | AN20: 3872.9838
A21: Electric Motorcycle | B21: 0.47306913 | C21: 0.48636255 | D21: 0.50002953 | E21: 0.51408055 | F21: 0.52852641 | G21: 0.54337821 | H21: 0.55864734 | I21: 0.57434555 | J21: 0.59048488 | K21: 0.60707773 | L21: 0.62413685 | M21: 0.64167534 | N21: 0.65970666 | O21: 0.67824467 | P21: 0.69730361 | Q21: 0.71689811 | R21: 0.73704322 | S21: 0.75775442 | T21: 0.77904761 | U21: 0.80093915 | V21: 0.82344585 | W21: 0.84658499 | X21: 0.87037436 | Y21: 0.89483221 | Z21: 0.91997734 | AA21: 0.94582906 | AB21: 0.97240722 | AC21: 0.99973224 | AD21: 1.0278251 | AE21: 1.0567074 | AF21: 1.0864013 | AG21: 1.1169296 | AH21: 1.1483157 | AI21: 1.1805838 | AJ21: 1.2137587 | AK21: 1.2478658 | AL21: 1.2829313 | AM21: 1.3189821 | AN21: 1.3560461
A22: CNG Motorcycle | B22: 0.027032522 | C22: 0.027792146 | D22: 0.028573116 | E22: 0.029376031 | F22: 0.030201509 | G22: 0.031050183 | H22: 0.031922705 | I22: 0.032819746 | J22: 0.033741993 | K22: 0.034690156 | L22: 0.035664963 | M22: 0.036667162 | N22: 0.037697524 | O22: 0.038756838 | P22: 0.039845921 | Q22: 0.040965606 | R22: 0.042116756 | S22: 0.043300253 | T22: 0.044517006 | U22: 0.045767951 | V22: 0.047054048 | W22: 0.048376285 | X22: 0.049735678 | Y22: 0.051133269 | Z22: 0.052570134 | AA22: 0.054047375 | AB22: 0.055566127 | AC22: 0.057127557 | AD22: 0.058732863 | AE22: 0.060383279 | AF22: 0.062080072 | AG22: 0.063824546 | AH22: 0.065618041 | AI22: 0.067461933 | AJ22: 0.069357639 | AK22: 0.071306616 | AL22: 0.073310359 | AM22: 0.075370408 | AN22: 0.077488346
A25: Variable: Bus: Total Activity (Billion Passenger-km)
A26: Scenario: Business as Usual
A27: Branch: Demand\Transportation\Passenger\Road Transport\Bus\Electric Bus
A28: Region: Indonesia
A29: Billion Passenger-km to Passenger*miles | B29: 621371000
A30: Branch | B30: 2022 | C30: 2023 | D30: 2024 | E30: 2025 | F30: 2026 | G30: 2027 | H30: 2028 | I30: 2029 | J30: 2030 | K30: 2031 | L30: 2032 | M30: 2033 | N30: 2034 | O30: 2035 | P30: 2036 | Q30: 2037 | R30: 2038 | S30: 2039 | T30: 2040 | U30: 2041 | V30: 2042 | W30: 2043 | X30: 2044 | Y30: 2045 | Z30: 2046 | AA30: 2047 | AB30: 2048 | AC30: 2049 | AD30: 2050 | AE30: 2051 | AF30: 2052 | AG30: 2053 | AH30: 2054 | AI30: 2055 | AJ30: 2056 | AK30: 2057 | AL30: 2058 | AM30: 2059 | AN30: 2060
A31: Electric Bus | B31: 0.20608822 | C31: 0.21187937 | D31: 0.21783327 | E31: 0.22395446 | F31: 0.23024767 | G31: 0.23671772 | H31: 0.24336958 | I31: 0.25020836 | J31: 0.25723931 | K31: 0.26446783 | L31: 0.27189948 | M31: 0.27953996 | N31: 0.28739514 | O31: 0.29547106 | P31: 0.30377391 | Q31: 0.31231007 | R31: 0.3210861 | S31: 0.33010875 | T31: 0.33938493 | U31: 0.34892178 | V31: 0.35872661 | W31: 0.36880697 | X31: 0.37917059 | Y31: 0.38982543 | Z31: 0.40077967 | AA31: 0.41204173 | AB31: 0.42362026 | AC31: 0.43552416 | AD31: 0.44776255 | AE31: 0.46034485 | AF31: 0.47328072 | AG31: 0.48658009 | AH31: 0.50025318 | AI31: 0.51431049 | AJ31: 0.52876281 | AK31: 0.54362125 | AL31: 0.55889722 | AM31: 0.57460244 | AN31: 0.59074899
A32: CNG Bus | B32: 0.37470585 | C32: 0.38523522 | D32: 0.39606048 | E32: 0.40718994 | F32: 0.41863213 | G32: 0.43039585 | H32: 0.44249014 | I32: 0.45492429 | J32: 0.46770783 | K32: 0.4808506 | L32: 0.49436269 | M32: 0.50825447 | N32: 0.52253662 | O32: 0.5372201 | P32: 0.55231619 | Q32: 0.56783649 | R32: 0.58379291 | S32: 0.60019772 | T32: 0.61706351 | U32: 0.63440323 | V32: 0.6522302 | W32: 0.67055812 | X32: 0.68940107 | Y32: 0.7087735 | Z32: 0.72869031 | AA32: 0.74916679 | AB32: 0.77021866 | AC32: 0.7918621 | AD32: 0.81411373 | AE32: 0.83699064 | AF32: 0.8605104 | AG32: 0.88469108 | AH32: 0.90955124 | AI32: 0.93510998 | AJ32: 0.96138693 | AK32: 0.98840227 | AL32: 1.0161768 | AM32: 1.0447317 | AN32: 1.0740891
A33: Diesel Bus | B33: 34.378485 | C33: 35.344534 | D33: 36.337729 | E33: 37.358833 | F33: 38.408631 | G33: 39.487928 | H33: 40.597554 | I33: 41.738361 | J33: 42.911225 | K33: 44.117047 | L33: 45.356753 | M33: 46.631295 | N33: 47.941652 | O33: 49.288831 | P33: 50.673866 | Q33: 52.097822 | R33: 53.56179 | S33: 55.066897 | T33: 56.614298 | U33: 58.205182 | V33: 59.84077 | W33: 61.522319 | X33: 63.25112 | Y33: 65.0285 | Z33: 66.855826 | AA33: 68.734501 | AB33: 70.665967 | AC33: 72.651708 | AD33: 74.693249 | AE33: 76.792158 | AF33: 78.950047 | AG33: 81.168574 | AH33: 83.449442 | AI33: 85.794403 | AJ33: 88.205259 | AK33: 90.683861 | AL33: 93.232112 | AM33: 95.85197 | AN33: 98.545448
A34: BioGasoil Bus | B34: 589.55046 | C34: 606.11706 | D34: 623.14918 | E34: 640.65991 | F34: 658.6627 | G34: 677.17138 | H34: 696.20016 | I34: 715.76365 | J34: 735.87688 | K34: 756.55531 | L34: 777.8148 | M34: 799.6717 | N34: 822.14278 | O34: 845.24531 | P34: 868.99703 | Q34: 893.41618 | R34: 918.52152 | S34: 944.33233 | T34: 970.86843 | U34: 998.15021 | V34: 1026.1986 | W34: 1055.0352 | X34: 1084.6821 | Y34: 1115.1621 | Z34: 1146.4986 | AA34: 1178.7156 | AB34: 1211.838 | AC34: 1245.8911 | AD34: 1280.9011 | AE34: 1316.8949 | AF34: 1353.9002 | AG34: 1391.9453 | AH34: 1431.0595 | AI34: 1471.2728 | AJ34: 1512.6161 | AK34: 1555.1212 | AL34: 1598.8207 | AM34: 1643.7482 | AN34: 1689.9382
A37: Variable: Railway: Total Activity (Billion Passenger-km)
A38: Scenario: Business as Usual
A39: Branch: Demand\Transportation\Passenger\Railway\Urban Train
A40: Region: Indonesia
A41: Billion Passenger-km to Passenger*miles | B41: 621371000
A42: Branch | B42: 2022 | C42: 2023 | D42: 2024 | E42: 2025 | F42: 2026 | G42: 2027 | H42: 2028 | I42: 2029 | J42: 2030 | K42: 2031 | L42: 2032 | M42: 2033 | N42: 2034 | O42: 2035 | P42: 2036 | Q42: 2037 | R42: 2038 | S42: 2039 | T42: 2040 | U42: 2041 | V42: 2042 | W42: 2043 | X42: 2044 | Y42: 2045 | Z42: 2046 | AA42: 2047 | AB42: 2048 | AC42: 2049 | AD42: 2050 | AE42: 2051 | AF42: 2052 | AG42: 2053 | AH42: 2054 | AI42: 2055 | AJ42: 2056 | AK42: 2057 | AL42: 2058 | AM42: 2059 | AN42: 2060
A43: Urban Train | B43: 5.5847886 | C43: 5.6038855 | D43: 5.6229824 | E43: 5.6420792 | F43: 5.6931631 | G43: 5.7442469 | H43: 5.7953307 | I43: 5.8464146 | J43: 5.8974984 | K43: 5.9404049 | L43: 5.9833114 | M43: 6.0262179 | N43: 6.0691244 | O43: 6.1120308 | P43: 6.1466654 | Q43: 6.1813 | R43: 6.2159346 | S43: 6.2505692 | T43: 6.2852038 | U43: 6.311748 | V43: 6.3382923 | W43: 6.3648365 | X43: 6.3913808 | Y43: 6.4179251 | Z43: 6.4367069 | AA43: 6.4554888 | AB43: 6.4742707 | AC43: 6.4930526 | AD43: 6.5118345 | AE43: 6.5118345 | AF43: 6.5118345 | AG43: 6.5118345 | AH43: 6.5118345 | AI43: 6.5118345 | AJ43: 6.5118345 | AK43: 6.5118345 | AL43: 6.5118345 | AM43: 6.5118345 | AN43: 6.5118345
A44: Diesel Train | B44: 0.74201688 | C44: 0.74455417 | D44: 0.74709145 | E44: 0.74962874 | F44: 0.75641594 | G44: 0.76320313 | H44: 0.76999033 | I44: 0.77677753 | J44: 0.78356473 | K44: 0.78926546 | L44: 0.79496618 | M44: 0.8006669 | N44: 0.80636762 | O44: 0.81206835 | P44: 0.81667003 | Q44: 0.82127172 | R44: 0.82587341 | S44: 0.83047509 | T44: 0.83507678 | U44: 0.83860355 | V44: 0.84213033 | W44: 0.8456571 | X44: 0.84918388 | Y44: 0.85271065 | Z44: 0.85520609 | AA44: 0.85770152 | AB44: 0.86019696 | AC44: 0.86269239 | AD44: 0.86518783 | AE44: 0.86518783 | AF44: 0.86518783 | AG44: 0.86518783 | AH44: 0.86518783 | AI44: 0.86518783 | AJ44: 0.86518783 | AK44: 0.86518783 | AL44: 0.86518783 | AM44: 0.86518783 | AN44: 0.86518783
A45: BioGasoil Train | B45: 12.720905 | C45: 12.764403 | D45: 12.807901 | E45: 12.8514 | F45: 12.967757 | G45: 13.084115 | H45: 13.200473 | I45: 13.31683 | J45: 13.433188 | K45: 13.530919 | L45: 13.628651 | M45: 13.726382 | N45: 13.824114 | O45: 13.921845 | P45: 14.000735 | Q45: 14.079625 | R45: 14.158515 | S45: 14.237404 | T45: 14.316294 | U45: 14.376756 | V45: 14.437218 | W45: 14.49768 | X45: 14.558142 | Y45: 14.618604 | Z45: 14.661385 | AA45: 14.704166 | AB45: 14.746947 | AC45: 14.789728 | AD45: 14.832509 | AE45: 14.832509 | AF45: 14.832509 | AG45: 14.832509 | AH45: 14.832509 | AI45: 14.832509 | AJ45: 14.832509 | AK45: 14.832509 | AL45: 14.832509 | AM45: 14.832509 | AN45: 14.832509
A48: Variable: Marine: Total Activity (Million Passenger-km)
...

Sheet Energy Consumption (EC) - psgr
A1: Variable: Car: Total Final Energy Consumption (Million Gigajoule)
A2: Scenario: Business as Usual
A3: Branch: Demand\Transportation\Passenger\Road Transport\Car\Gasoline Car
A4: Region: Indonesia
A5: Million Gigajoule to BTU | B5: 947817120000
A6: Branch | B6: 2022 | C6: 2023 | D6: 2024 | E6: 2025 | F6: 2026 | G6: 2027 | H6: 2028 | I6: 2029 | J6: 2030 | K6: 2031 | L6: 2032 | M6: 2033 | N6: 2034 | O6: 2035 | P6: 2036 | Q6: 2037 | R6: 2038 | S6: 2039 | T6: 2040 | U6: 2041 | V6: 2042 | W6: 2043 | X6: 2044 | Y6: 2045 | Z6: 2046 | AA6: 2047 | AB6: 2048 | AC6: 2049 | AD6: 2050 | AE6: 2051 | AF6: 2052 | AG6: 2053 | AH6: 2054 | AI6: 2055 | AJ6: 2056 | AK6: 2057 | AL6: 2058 | AM6: 2059 | AN6: 2060
A7: Gasoline Car | B7: 397.62002 | C7: 408.7933 | D7: 420.28055 | E7: 432.09059 | F7: 444.23251 | G7: 456.71561 | H7: 469.54949 | I7: 482.74402 | J7: 496.30931 | K7: 510.25579 | L7: 524.59418 | M7: 539.33547 | N7: 554.49101 | O7: 570.07242 | P7: 586.09167 | Q7: 602.56108 | R7: 619.49327 | S7: 636.90127 | T7: 654.79845 | U7: 673.19853 | V7: 692.11567 | W7: 711.56439 | X7: 731.55962 | Y7: 752.11673 | Z7: 773.2515 | AA7: 794.98016 | AB7: 817.31941 | AC7: 840.2864 | AD7: 863.89877 | AE7: 888.17466 | AF7: 913.13271 | AG7: 938.79209 | AH7: 965.17251 | AI7: 992.29423 | AJ7: 1020.1781 | AK7: 1048.8455 | AL7: 1078.3184 | AM7: 1108.6196 | AN7: 1139.7722
A8: Electric Car | B8: 0.055875385 | C8: 0.057445505 | D8: 0.059059746 | E8: 0.060719347 | F8: 0.062425584 | G8: 0.064179767 | H8: 0.065983244 | I8: 0.067837398 | J8: 0.069743655 | K8: 0.071703479 | L8: 0.073718374 | M8: 0.075789889 | N8: 0.077919614 | O8: 0.080109185 | P8: 0.082360284 | Q8: 0.08467464 | R8: 0.08705403 | S8: 0.089500281 | T8: 0.092015274 | U8: 0.094600938 | V8: 0.097259261 | W8: 0.099992284 | X8: 0.10280211 | Y8: 0.10569088 | Z8: 0.10866084 | AA8: 0.11171425 | AB8: 0.11485346 | AC8: 0.11808089 | AD8: 0.12139901 | AE8: 0.12481037 | AF8: 0.12831759 | AG8: 0.13192336 | AH8: 0.13563046 | AI8: 0.13944173 | AJ8: 0.14336009 | AK8: 0.14738857 | AL8: 0.15153024 | AM8: 0.1557883 | AN8: 0.16016601
A9: CNG Car | B9: 0.17696589 | C9: 0.1819387 | D9: 0.18705125 | E9: 0.19230746 | F9: 0.19771137 | G9: 0.20326714 | H9: 0.20897902 | I9: 0.21485141 | J9: 0.22088882 | K9: 0.22709588 | L9: 0.23347736 | M9: 0.24003817 | N9: 0.24678333 | O9: 0.25371804 | P9: 0.26084761 | Q9: 0.26817753 | R9: 0.27571343 | S9: 0.28346108 | T9: 0.29142644 | U9: 0.29961564 | V9: 0.30803495 | W9: 0.31669086 | X9: 0.32558999 | Y9: 0.33473919 | Z9: 0.34414549 | AA9: 0.35381612 | AB9: 0.36375848 | AC9: 0.37398024 | AD9: 0.38448923 | AE9: 0.39529352 | AF9: 0.40640142 | AG9: 0.41782146 | AH9: 0.4295624 | AI9: 0.44163327 | AJ9: 0.45404334 | AK9: 0.46680213 | AL9: 0.47991945 | AM9: 0.49340537 | AN9: 0.50727025
A10: Diesel Car | B10: 5.7240473 | C10: 5.8848952 | D10: 6.0502631 | E10: 6.2202778 | F10: 6.39507 | G10: 6.5747739 | H10: 6.7595276 | I10: 6.9494729 | J10: 7.1447558 | K10: 7.3455262 | L10: 7.5519383 | M10: 7.7641507 | N10: 7.9823263 | O10: 8.2066328 | P10: 8.4372423 | Q10: 8.6743321 | R10: 8.9180841 | S10: 9.1686857 | T10: 9.4263293 | U10: 9.6912128 | V10: 9.9635396 | W10: 10.243519 | X10: 10.531366 | Y10: 10.827301 | Z10: 11.131553 | AA10: 11.444353 | AB10: 11.765944 | AC10: 12.096572 | AD10: 12.43649 | AE10: 12.78596 | AF10: 13.145251 | AG10: 13.514637 | AH10: 13.894404 | AI10: 14.284842 | AJ10: 14.686251 | AK10: 15.098941 | AL10: 15.523227 | AM10: 15.959435 | AN10: 16.407902
A11: BioGasoil Car | B11: 93.536311 | C11: 96.164718 | D11: 98.866983 | E11: 101.64518 | F11: 104.50145 | G11: 107.43798 | H11: 110.45703 | I11: 113.56092 | J11: 116.75202 | K11: 120.0328 | L11: 123.40577 | M11: 126.87352 | N11: 130.43871 | O11: 134.10409 | P11: 137.87247 | Q11: 141.74674 | R11: 145.72987 | S11: 149.82494 | T11: 154.03508 | U11: 158.36352 | V11: 162.8136 | W11: 167.38872 | X11: 172.09241 | Y11: 176.92827 | Z11: 181.90003 | AA11: 187.01149 | AB11: 192.26658 | AC11: 197.66935 | AD11: 203.22393 | AE11: 208.9346 | AF11: 214.80575 | AG11: 220.84187 | AH11: 227.04761 | AI11: 233.42774 | AJ11: 239.98715 | AK11: 246.73088 | AL11: 253.66411 | AM11: 260.79217 | AN11: 268.12053
A14: Variable: Motorcycle: Total Final Energy Consumption (Million Gigajoule)
A15: Scenario: Business as Usual
A16: Branch: Demand\Transportation\Passenger\Road Transport\Motorcycle\Gasoline Motorcycle
A17: Region: Indonesia
A18: Million Gigajoule to BTU | B18: 947817120000
A19: Branch | B19: 2022 | C19: 2023 | D19: 2024 | E19: 2025 | F19: 2026 | G19: 2027 | H19: 2028 | I19: 2029 | J19: 2030 | K19: 2031 | L19: 2032 | M19: 2033 | N19: 2034 | O19: 2035 | P19: 2036 | Q19: 2037 | R19: 2038 | S19: 2039 | T19: 2040 | U19: 2041 | V19: 2042 | W19: 2043 | X19: 2044 | Y19: 2045 | Z19: 2046 | AA19: 2047 | AB19: 2048 | AC19: 2049 | AD19: 2050 | AE19: 2051 | AF19: 2052 | AG19: 2053 | AH19: 2054 | AI19: 2055 | AJ19: 2056 | AK19: 2057 | AL19: 2058 | AM19: 2059 | AN19: 2060
A20: Gasoline Motorcycle | B20: 783.08616 | C20: 805.09118 | D20: 827.71456 | E20: 850.97365 | F20: 874.88634 | G20: 899.47098 | H20: 924.74647 | I20: 950.7322 | J20: 977.44814 | K20: 1004.9148 | L20: 1033.1533 | M20: 1062.1853 | N20: 1092.0331 | O20: 1122.7197 | P20: 1154.2685 | Q20: 1186.7039 | R20: 1220.0508 | S20: 1254.3347 | T20: 1289.5819 | U20: 1325.8197 | V20: 1363.0757 | W20: 1401.3787 | X20: 1440.758 | Y20: 1481.2438 | Z20: 1522.8673 | AA20: 1565.6605 | AB20: 1609.6562 | AC20: 1654.8881 | AD20: 1701.3911 | AE20: 1749.2009 | AF20: 1798.3541 | AG20: 1848.8885 | AH20: 1900.843 | AI20: 1954.2574 | AJ20: 2009.1728 | AK20: 2065.6313 | AL20: 2123.6764 | AM20: 2183.3525 | AN20: 2244.7055
A21: Electric Motorcycle | B21: 0.031438387 | C21: 0.032321818 | D21: 0.033230073 | E21: 0.034163851 | F21: 0.035123868 | G21: 0.036110863 | H21: 0.037125592 | I21: 0.038168835 | J21: 0.039241394 | K21: 0.040344093 | L21: 0.041477777 | M21: 0.042643319 | N21: 0.043841612 | O21: 0.045073579 | P21: 0.046340163 | Q21: 0.04764234 | R21: 0.048981108 | S21: 0.050357496 | T21: 0.051772561 | U21: 0.05322739 | V21: 0.0547231 | W21: 0.05626084 | X21: 0.057841792 | Y21: 0.059467168 | Z21: 0.061138219 | AA21: 0.062856226 | AB21: 0.06462251 | AC21: 0.066438428 | AD21: 0.068305373 | AE21: 0.07022478 | AF21: 0.072198124 | AG21: 0.074226919 | AH21: 0.076312724 | AI21: 0.078457141 | AJ21: 0.080661817 | AK21: 0.082928445 | AL21: 0.085258766 | AM21: 0.08765457 | AN21: 0.090117697
A22: CNG Motorcycle | B22: 0.014699053 | C22: 0.015112102 | D22: 0.015536758 | E22: 0.015973347 | F22: 0.016422204 | G22: 0.016883674 | H22: 0.017358112 | I22: 0.017845882 | J22: 0.018347358 | K22: 0.018862926 | L22: 0.019392981 | M22: 0.019937931 | N22: 0.020498195 | O22: 0.021074202 | P22: 0.021666395 | Q22: 0.022275229 | R22: 0.022901172 | S22: 0.023544704 | T22: 0.024206319 | U22: 0.024886526 | V22: 0.025585847 | W22: 0.026304819 | X22: 0.027043994 | Y22: 0.027803941 | Z22: 0.028585242 | AA22: 0.029388499 | AB22: 0.030214327 | AC22: 0.031063361 | AD22: 0.031936254 | AE22: 0.032833675 | AF22: 0.033756314 | AG22: 0.034704879 | AH22: 0.035680099 | AI22: 0.036682724 | AJ22: 0.037713523 | AK22: 0.038773287 | AL22: 0.039862831 | AM22: 0.040982992 | AN22: 0.04213463
A25: Variable: Bus: Total Final Energy Consumption (Million Gigajoule)
A26: Scenario: Business as Usual
A27: Branch: Demand\Transportation\Passenger\Road Transport\Bus\Electric Bus
A28: Region: Indonesia
A29: Million Gigajoule to BTU | B29: 947817120000
A30: Branch | B30: 2022 | C30: 2023 | D30: 2024 | E30: 2025 | F30: 2026 | G30: 2027 | H30: 2028 | I30: 2029 | J30: 2030 | K30: 2031 | L30: 2032 | M30: 2033 | N30: 2034 | O30: 2035 | P30: 2036 | Q30: 2037 | R30: 2038 | S30: 2039 | T30: 2040 | U30: 2041 | V30: 2042 | W30: 2043 | X30: 2044 | Y30: 2045 | Z30: 2046 | AA30: 2047 | AB30: 2048 | AC30: 2049 | AD30: 2050 | AE30: 2051 | AF30: 2052 | AG30: 2053 | AH30: 2054 | AI30: 2055 | AJ30: 2056 | AK30: 2057 | AL30: 2058 | AM30: 2059 | AN30: 2060
A31: Electric Bus | B31: 0.022941174 | C31: 0.02358583 | D31: 0.024248601 | E31: 0.024929996 | F31: 0.025630539 | G31: 0.026350767 | H31: 0.027091233 | I31: 0.027852507 | J31: 0.028635173 | K31: 0.029439833 | L31: 0.030267104 | M31: 0.031117621 | N31: 0.031992038 | O31: 0.032891027 | P31: 0.033815277 | Q31: 0.034765499 | R31: 0.035742423 | S31: 0.036746799 | T31: 0.037779398 | U31: 0.038841014 | V31: 0.039932461 | W31: 0.041054579 | X31: 0.042208228 | Y31: 0.043394296 | Z31: 0.044613692 | AA31: 0.045867354 | AB31: 0.047156245 | AC31: 0.048481353 | AD31: 0.049843698 | AE31: 0.051244325 | AF31: 0.05268431 | AG31: 0.05416476 | AH31: 0.05568681 | AI31: 0.057251631 | AJ31: 0.058860424 | AK31: 0.060514425 | AL31: 0.062214903 | AM31: 0.063963166 | AN31: 0.065760556
A32: CNG Bus | B32: 0.19792659 | C32: 0.2034884 | D32: 0.2092065 | E32: 0.21508529 | F32: 0.22112927 | G32: 0.22734308 | H32: 0.23373151 | I32: 0.24029946 | J32: 0.24705197 | K32: 0.25399422 | L32: 0.26113156 | M32: 0.26846945 | N32: 0.27601355 | O32: 0.28376964 | P32: 0.29174367 | Q32: 0.29994178 | R32: 0.30837026 | S32: 0.31703558 | T32: 0.32594441 | U32: 0.33510357 | V32: 0.34452011 | W32: 0.35420126 | X32: 0.36415445 | Y32: 0.37438733 | Z32: 0.38490776 | AA32: 0.39572381 | AB32: 0.40684381 | AC32: 0.41827627 | AD32: 0.43003 | AE32: 0.44211401 | AF32: 0.45453758 | AG32: 0.46731026 | AH32: 0.48044186 | AI32: 0.49394246 | AJ32: 0.50782243 | AK32: 0.52209244 | AL32: 0.53676344 | AM32: 0.5518467 | AN32: 0.5673538
A33: Diesel Bus | B33: 20.57094 | C33: 21.148991 | D33: 21.743286 | E33: 22.35428 | F33: 22.982444 | G33: 23.62826 | H33: 24.292223 | I33: 24.974844 | J33: 25.676647 | K33: 26.39817 | L33: 27.139969 | M33: 27.902613 | N33: 28.686687 | O33: 29.492794 | P33: 30.321553 | Q33: 31.1736 | R33: 32.04959 | S33: 32.950196 | T33: 33.876109 | U33: 34.828041 | V33: 35.806722 | W33: 36.812905 | X33: 37.847362 | Y33: 38.910887 | Z33: 40.004298 | AA33: 41.128434 | AB33: 42.284159 | AC33: 43.47236 | AD33: 44.69395 | AE33: 45.949867 | AF33: 47.241076 | AG33: 48.568569 | AH33: 49.933364 | AI33: 51.336511 | AJ33: 52.779087 | AK33: 54.262199 | AL33: 55.786988 | AM33: 57.354624 | AN33: 58.966311
A34: BioGasoil Bus | B34: 336.14848 | C34: 345.59438 | D34: 355.30572 | E34: 365.28994 | F34: 375.55473 | G34: 386.10797 | H34: 396.95775 | I34: 408.11241 | J34: 419.58053 | K34: 431.3709 | L34: 443.49259 | M34: 455.95491 | N34: 468.76741 | O34: 481.93996 | P34: 495.48266 | Q34: 509.40591 | R34: 523.72041 | S34: 538.43716 | T34: 553.56745 | U34: 569.12291 | V34: 585.11548 | W34: 601.55745 | X34: 618.46145 | Y34: 635.84045 | Z34: 653.70781 | AA34: 672.07726 | AB34: 690.96289 | AC34: 710.37921 | AD34: 730.34114 | AE34: 750.86401 | AF34: 771.96357 | AG34: 793.65605 | AH34: 815.95809 | AI34: 838.88683 | AJ34: 862.45987 | AK34: 886.69532 | AL34: 911.6118 | AM34: 937.22845 | AN34: 963.56493
A37: Variable: Railway: Total Final Energy Consumption (Thousand Gigajoule)
A38: Scenario: Business as Usual
A39: Branch: Demand\Transportation\Passenger\Railway\Urban Train
A40: Region: Indonesia
A41: Thousand Gigajoule to BTU | B41: 947817120
A42: Branch | B42: 2022 | C42: 2023 | D42: 2024 | E42: 2025 | F42: 2026 | G42: 2027 | H42: 2028 | I42: 2029 | J42: 2030 | K42: 2031 | L42: 2032 | M42: 2033 | N42: 2034 | O42: 2035 | P42: 2036 | Q42: 2037 | R42: 2038 | S42: 2039 | T42: 2040 | U42: 2041 | V42: 2042 | W42: 2043 | X42: 2044 | Y42: 2045 | Z42: 2046 | AA42: 2047 | AB42: 2048 | AC42: 2049 | AD42: 2050 | AE42: 2051 | AF42: 2052 | AG42: 2053 | AH42: 2054 | AI42: 2055 | AJ42: 2056 | AK42: 2057 | AL42: 2058 | AM42: 2059 | AN42: 2060
A43: Urban Train | B43: 1128.8736 | C43: 1132.7337 | D43: 1136.5938 | E43: 1140.454 | F43: 1150.7797 | G43: 1161.1055 | H43: 1171.4313 | I43: 1181.757 | J43: 1192.0828 | K43: 1200.7556 | L43: 1209.4285 | M43: 1218.1013 | N43: 1226.7742 | O43: 1235.447 | P43: 1242.4478 | Q43: 1249.4486 | R43: 1256.4494 | S43: 1263.4503 | T43: 1270.4511 | U43: 1275.8166 | V43: 1281.182 | W43: 1286.5475 | X43: 1291.913 | Y43: 1297.2785 | Z43: 1301.075 | AA43: 1304.8714 | AB43: 1308.6679 | AC43: 1312.4643 | AD43: 1316.2608 | AE43: 1316.2608 | AF43: 1316.2608 | AG43: 1316.2608 | AH43: 1316.2608 | AI43: 1316.2608 | AJ43: 1316.2608 | AK43: 1316.2608 | AL43: 1316.2608 | AM43: 1316.2608 | AN43: 1316.2608
A44: Diesel Train | B44: 504.54337 | C44: 506.26863 | D44: 507.99389 | E44: 509.71915 | F44: 514.33418 | G44: 518.94922 | H44: 523.56426 | I44: 528.1793 | J44: 532.79434 | K44: 536.67061 | L44: 540.54689 | M44: 544.42316 | N44: 548.29944 | O44: 552.17572 | P44: 555.30469 | Q44: 558.43366 | R44: 561.56263 | S44: 564.69161 | T44: 567.82058 | U44: 570.21865 | V44: 572.61672 | W44: 575.0148 | X44: 577.41287 | Y44: 579.81094 | Z44: 581.50775 | AA44: 583.20455 | AB44: 584.90135 | AC44: 586.59815 | AD44: 588.29495 | AE44: 588.29495 | AF44: 588.29495 | AG44: 588.29495 | AH44: 588.29495 | AI44: 588.29495 | AJ44: 588.29495 | AK44: 588.29495 | AL44: 588.29495 | AM44: 588.29495 | AN44: 588.29495
A45: BioGasoil Train | B45: 826.03277 | C45: 828.85734 | D45: 831.68191 | E45: 834.50649 | F45: 842.06218 | G45: 849.61786 | H45: 857.17355 | I45: 864.72924 | J45: 872.28493 | K45: 878.63113 | L45: 884.97732 | M45: 891.32352 | N45: 897.66971 | O45: 904.01591 | P45: 909.13863 | Q45: 914.26135 | R45: 919.38407 | S45: 924.50678 | T45: 929.6295 | U45: 933.5556 | V45: 937.4817 | W45: 941.4078 | X45: 945.3339 | Y45: 949.25999 | Z45: 952.03798 | AA45: 954.81596 | AB45: 957.59395 | AC45: 960.37193 | AD45: 963.14992 | AE45: 963.14992 | AF45: 963.14992 | AG45: 963.14992 | AH45: 963.14992 | AI45: 963.14992 | AJ45: 963.14992 | AK45: 963.14992 | AL45: 963.14992 | AM45: 963.14992 | AN45: 963.14992
A48: Variable: Marine: Total Final Energy Consumption (Million Gigajoule)
...

Sheet Conversion - LA - psgr
A1: Variable: Car: Total Activity (Passenger*miles)
A2: Scenario: Business as Usual
A3: Branch: Demand\Transportation\Passenger\Road Transport\Car\Gasoline Car
A4: Region: Indonesia
A6: Branch | B6: 2022 | C6: 2023 | D6: 2024 | E6: 2025 | F6: 2026 | G6: 2027 | H6: 2028 | I6: 2029 | J6: 2030 | K6: 2031 | L6: 2032 | M6: 2033 | N6: 2034 | O6: 2035 | P6: 2036 | Q6: 2037 | R6: 2038 | S6: 2039 | T6: 2040 | U6: 2041 | V6: 2042 | W6: 2043 | X6: 2044 | Y6: 2045 | Z6: 2046 | AA6: 2047 | AB6: 2048 | AC6: 2049 | AD6: 2050 | AE6: 2051 | AF6: 2052 | AG6: 2053 | AH6: 2054 | AI6: 2055 | AJ6: 2056 | AK6: 2057 | AL6: 2058 | AM6: 2059 | AN6: 2060
A7: Gasoline Car | B7: ='Level of Activity (LA) - psgr'!B7*'Level of Activity (LA) - psgr'!$B$5 -> 2.0122098e+11 | C7: ='Level of Activity (LA) - psgr'!C7*'Level of Activity (LA) - psgr'!$B$5 -> 2.0687537e+11 | D7: ='Level of Activity (LA) - psgr'!D7*'Level of Activity (LA) - psgr'!$B$5 -> 2.1268864e+11 | E7: ='Level of Activity (LA) - psgr'!E7*'Level of Activity (LA) - psgr'!$B$5 -> 2.1866528e+11 | F7: ='Level of Activity (LA) - psgr'!F7*'Level of Activity (LA) - psgr'!$B$5 -> 2.2480985e+11 | G7: ='Level of Activity (LA) - psgr'!G7*'Level of Activity (LA) - psgr'!$B$5 -> 2.311271e+11 | H7: ='Level of Activity (LA) - psgr'!H7*'Level of Activity (LA) - psgr'!$B$5 -> 2.3762186e+11 | I7: ='Level of Activity (LA) - psgr'!I7*'Level of Activity (LA) - psgr'!$B$5 -> 2.4429912e+11 | ... AN7: ='Level of Activity (LA) - psgr'!AN7*'Level of Activity (LA) - psgr'!$B$5 -> 5.7679713e+11
A8: Electric Car | B8: ='Level of Activity (LA) - psgr'!B8*'Level of Activity (LA) - psgr'!$B$5 -> 2.0414974e+08 | C8: ='Level of Activity (LA) - psgr'!C8*'Level of Activity (LA) - psgr'!$B$5 -> 2.0988643e+08 | D8: ='Level of Activity (LA) - psgr'!D8*'Level of Activity (LA) - psgr'!$B$5 -> 2.1578432e+08 | E8: ='Level of Activity (LA) - psgr'!E8*'Level of Activity (LA) - psgr'!$B$5 -> 2.2184794e+08 | F8: ='Level of Activity (LA) - psgr'!F8*'Level of Activity (LA) - psgr'!$B$5 -> 2.2808195e+08 | G8: ='Level of Activity (LA) - psgr'!G8*'Level of Activity (LA) - psgr'!$B$5 -> 2.3449114e+08 | H8: ='Level of Activity (LA) - psgr'!H8*'Level of Activity (LA) - psgr'!$B$5 -> 2.4108044e+08 | I8: ='Level of Activity (LA) - psgr'!I8*'Level of Activity (LA) - psgr'!$B$5 -> 2.4785489e+08 | ... AN8: ='Level of Activity (LA) - psgr'!AN8*'Level of Activity (LA) - psgr'!$B$5 -> 5.8519239e+08
A9: CNG Car | B9: ='Level of Activity (LA) - psgr'!B9*'Level of Activity (LA) - psgr'!$B$5 -> 2.0153244e+08 | C9: ='Level of Activity (LA) - psgr'!C9*'Level of Activity (LA) - psgr'!$B$5 -> 2.0719558e+08 | D9: ='Level of Activity (LA) - psgr'!D9*'Level of Activity (LA) - psgr'!$B$5 -> 2.1301785e+08 | E9: ='Level of Activity (LA) - psgr'!E9*'Level of Activity (LA) - psgr'!$B$5 -> 2.1900374e+08 | F9: ='Level of Activity (LA) - psgr'!F9*'Level of Activity (LA) - psgr'!$B$5 -> 2.2515783e+08 | G9: ='Level of Activity (LA) - psgr'!G9*'Level of Activity (LA) - psgr'!$B$5 -> 2.3148485e+08 | H9: ='Level of Activity (LA) - psgr'!H9*'Level of Activity (LA) - psgr'!$B$5 -> 2.3798966e+08 | I9: ='Level of Activity (LA) - psgr'!I9*'Level of Activity (LA) - psgr'!$B$5 -> 2.4467726e+08 | ... AN9: ='Level of Activity (LA) - psgr'!AN9*'Level of Activity (LA) - psgr'!$B$5 -> 5.7768992e+08
A10: Diesel Car | B10: ='Level of Activity (LA) - psgr'!B10*'Level of Activity (LA) - psgr'!$B$5 -> 3.3117182e+09 | C10: ='Level of Activity (LA) - psgr'!C10*'Level of Activity (LA) - psgr'!$B$5 -> 3.4047787e+09 | D10: ='Level of Activity (LA) - psgr'!D10*'Level of Activity (LA) - psgr'!$B$5 -> 3.5004543e+09 | E10: ='Level of Activity (LA) - psgr'!E10*'Level of Activity (LA) - psgr'!$B$5 -> 3.5988184e+09 | F10: ='Level of Activity (LA) - psgr'!F10*'Level of Activity (LA) - psgr'!$B$5 -> 3.6999466e+09 | G10: ='Level of Activity (LA) - psgr'!G10*'Level of Activity (LA) - psgr'!$B$5 -> 3.8039165e+09 | H10: ='Level of Activity (LA) - psgr'!H10*'Level of Activity (LA) - psgr'!$B$5 -> 3.9108081e+09 | I10: ='Level of Activity (LA) - psgr'!I10*'Level of Activity (LA) - psgr'!$B$5 -> 4.0207033e+09 | ... AN10: ='Level of Activity (LA) - psgr'!AN10*'Level of Activity (LA) - psgr'!$B$5 -> 9.4929939e+09
A11: BioGasoil Car | B11: ='Level of Activity (LA) - psgr'!B11*'Level of Activity (LA) - psgr'!$B$5 -> 5.679206e+10 | C11: ='Level of Activity (LA) - psgr'!C11*'Level of Activity (LA) - psgr'!$B$5 -> 5.8387939e+10 | D11: ='Level of Activity (LA) - psgr'!D11*'Level of Activity (LA) - psgr'!$B$5 -> 6.0028662e+10 | E11: ='Level of Activity (LA) - psgr'!E11*'Level of Activity (LA) - psgr'!$B$5 -> 6.1715491e+10 | F11: ='Level of Activity (LA) - psgr'!F11*'Level of Activity (LA) - psgr'!$B$5 -> 6.344972e+10 | G11: ='Level of Activity (LA) - psgr'!G11*'Level of Activity (LA) - psgr'!$B$5 -> 6.5232681e+10 | H11: ='Level of Activity (LA) - psgr'!H11*'Level of Activity (LA) - psgr'!$B$5 -> 6.7065745e+10 | I11: ='Level of Activity (LA) - psgr'!I11*'Level of Activity (LA) - psgr'!$B$5 -> 6.8950318e+10 | ... AN11: ='Level of Activity (LA) - psgr'!AN11*'Level of Activity (LA) - psgr'!$B$5 -> 1.6279365e+11
A14: Variable: Motorcycle: Total Activity (Passenger*miles)
A15: Scenario: Business as Usual
A16: Branch: Demand\Transportation\Passenger\Road Transport\Motorcycle\Gasoline Motorcycle
A17: Region: Indonesia
A19: Branch | B19: 2022 | C19: 2023 | D19: 2024 | E19: 2025 | F19: 2026 | G19: 2027 | H19: 2028 | I19: 2029 | J19: 2030 | K19: 2031 | L19: 2032 | M19: 2033 | N19: 2034 | O19: 2035 | P19: 2036 | Q19: 2037 | R19: 2038 | S19: 2039 | T19: 2040 | U19: 2041 | V19: 2042 | W19: 2043 | X19: 2044 | Y19: 2045 | Z19: 2046 | AA19: 2047 | AB19: 2048 | AC19: 2049 | AD19: 2050 | AE19: 2051 | AF19: 2052 | AG19: 2053 | AH19: 2054 | AI19: 2055 | AJ19: 2056 | AK19: 2057 | AL19: 2058 | AM19: 2059 | AN19: 2060
A20: Gasoline Motorcycle | B20: ='Level of Activity (LA) - psgr'!B20*'Level of Activity (LA) - psgr'!$B$18 -> 8.395505e+11 | C20: ='Level of Activity (LA) - psgr'!C20*'Level of Activity (LA) - psgr'!$B$18 -> 8.6314219e+11 | D20: ='Level of Activity (LA) - psgr'!D20*'Level of Activity (LA) - psgr'!$B$18 -> 8.8739682e+11 | E20: ='Level of Activity (LA) - psgr'!E20*'Level of Activity (LA) - psgr'!$B$18 -> 9.1233301e+11 | F20: ='Level of Activity (LA) - psgr'!F20*'Level of Activity (LA) - psgr'!$B$18 -> 9.3796992e+11 | G20: ='Level of Activity (LA) - psgr'!G20*'Level of Activity (LA) - psgr'!$B$18 -> 9.6432724e+11 | H20: ='Level of Activity (LA) - psgr'!H20*'Level of Activity (LA) - psgr'!$B$18 -> 9.914252e+11 | I20: ='Level of Activity (LA) - psgr'!I20*'Level of Activity (LA) - psgr'!$B$18 -> 1.0192846e+12 | ... AN20: ='Level of Activity (LA) - psgr'!AN20*'Level of Activity (LA) - psgr'!$B$18 -> 2.4065598e+12
A21: Electric Motorcycle | B21: ='Level of Activity (LA) - psgr'!B21*'Level of Activity (LA) - psgr'!$B$18 -> 2.9395144e+08 | C21: ='Level of Activity (LA) - psgr'!C21*'Level of Activity (LA) - psgr'!$B$18 -> 3.0221159e+08 | D21: ='Level of Activity (LA) - psgr'!D21*'Level of Activity (LA) - psgr'!$B$18 -> 3.1070385e+08 | E21: ='Level of Activity (LA) - psgr'!E21*'Level of Activity (LA) - psgr'!$B$18 -> 3.1943475e+08 | F21: ='Level of Activity (LA) - psgr'!F21*'Level of Activity (LA) - psgr'!$B$18 -> 3.2841098e+08 | G21: ='Level of Activity (LA) - psgr'!G21*'Level of Activity (LA) - psgr'!$B$18 -> 3.3763946e+08 | H21: ='Level of Activity (LA) - psgr'!H21*'Level of Activity (LA) - psgr'!$B$18 -> 3.4712726e+08 | I21: ='Level of Activity (LA) - psgr'!I21*'Level of Activity (LA) - psgr'!$B$18 -> 3.5688167e+08 | ... AN21: ='Level of Activity (LA) - psgr'!AN21*'Level of Activity (LA) - psgr'!$B$18 -> 8.4260769e+08
A22: CNG Motorcycle | B22: ='Level of Activity (LA) - psgr'!B22*'Level of Activity (LA) - psgr'!$B$18 -> 16797225 | C22: ='Level of Activity (LA) - psgr'!C22*'Level of Activity (LA) - psgr'!$B$18 -> 17269233 | D22: ='Level of Activity (LA) - psgr'!D22*'Level of Activity (LA) - psgr'!$B$18 -> 17754506 | E22: ='Level of Activity (LA) - psgr'!E22*'Level of Activity (LA) - psgr'!$B$18 -> 18253414 | F22: ='Level of Activity (LA) - psgr'!F22*'Level of Activity (LA) - psgr'!$B$18 -> 18766342 | G22: ='Level of Activity (LA) - psgr'!G22*'Level of Activity (LA) - psgr'!$B$18 -> 19293683 | H22: ='Level of Activity (LA) - psgr'!H22*'Level of Activity (LA) - psgr'!$B$18 -> 19835843 | I22: ='Level of Activity (LA) - psgr'!I22*'Level of Activity (LA) - psgr'!$B$18 -> 20393238 | ... AN22: ='Level of Activity (LA) - psgr'!AN22*'Level of Activity (LA) - psgr'!$B$18 -> 48149011
A25: Variable: Bus: Total Activity (Passenger*miles)
A26: Scenario: Business as Usual
A27: Branch: Demand\Transportation\Passenger\Road Transport\Bus\Electric Bus
A28: Region: Indonesia
A30: Branch | B30: 2022 | C30: 2023 | D30: 2024 | E30: 2025 | F30: 2026 | G30: 2027 | H30: 2028 | I30: 2029 | J30: 2030 | K30: 2031 | L30: 2032 | M30: 2033 | N30: 2034 | O30: 2035 | P30: 2036 | Q30: 2037 | R30: 2038 | S30: 2039 | T30: 2040 | U30: 2041 | V30: 2042 | W30: 2043 | X30: 2044 | Y30: 2045 | Z30: 2046 | AA30: 2047 | AB30: 2048 | AC30: 2049 | AD30: 2050 | AE30: 2051 | AF30: 2052 | AG30: 2053 | AH30: 2054 | AI30: 2055 | AJ30: 2056 | AK30: 2057 | AL30: 2058 | AM30: 2059 | AN30: 2060
A31: Electric Bus | B31: ='Level of Activity (LA) - psgr'!B31*'Level of Activity (LA) - psgr'!$B$29 -> 1.2805724e+08 | C31: ='Level of Activity (LA) - psgr'!C31*'Level of Activity (LA) - psgr'!$B$29 -> 1.316557e+08 | D31: ='Level of Activity (LA) - psgr'!D31*'Level of Activity (LA) - psgr'!$B$29 -> 1.3535527e+08 | E31: ='Level of Activity (LA) - psgr'!E31*'Level of Activity (LA) - psgr'!$B$29 -> 1.3915881e+08 | F31: ='Level of Activity (LA) - psgr'!F31*'Level of Activity (LA) - psgr'!$B$29 -> 1.4306923e+08 | G31: ='Level of Activity (LA) - psgr'!G31*'Level of Activity (LA) - psgr'!$B$29 -> 1.4708953e+08 | H31: ='Level of Activity (LA) - psgr'!H31*'Level of Activity (LA) - psgr'!$B$29 -> 1.512228e+08 | I31: ='Level of Activity (LA) - psgr'!I31*'Level of Activity (LA) - psgr'!$B$29 -> 1.5547222e+08 | ... AN31: ='Level of Activity (LA) - psgr'!AN31*'Level of Activity (LA) - psgr'!$B$29 -> 3.6707429e+08
A32: CNG Bus | B32: ='Level of Activity (LA) - psgr'!B32*'Level of Activity (LA) - psgr'!$B$29 -> 2.3283135e+08 | C32: ='Level of Activity (LA) - psgr'!C32*'Level of Activity (LA) - psgr'!$B$29 -> 2.39374e+08 | D32: ='Level of Activity (LA) - psgr'!D32*'Level of Activity (LA) - psgr'!$B$29 -> 2.461005e+08 | E32: ='Level of Activity (LA) - psgr'!E32*'Level of Activity (LA) - psgr'!$B$29 -> 2.5301602e+08 | F32: ='Level of Activity (LA) - psgr'!F32*'Level of Activity (LA) - psgr'!$B$29 -> 2.6012586e+08 | G32: ='Level of Activity (LA) - psgr'!G32*'Level of Activity (LA) - psgr'!$B$29 -> 2.674355e+08 | H32: ='Level of Activity (LA) - psgr'!H32*'Level of Activity (LA) - psgr'!$B$29 -> 2.7495054e+08 | I32: ='Level of Activity (LA) - psgr'!I32*'Level of Activity (LA) - psgr'!$B$29 -> 2.8267676e+08 | ... AN32: ='Level of Activity (LA) - psgr'!AN32*'Level of Activity (LA) - psgr'!$B$29 -> 6.674078e+08
A33: Diesel Bus | B33: ='Level of Activity (LA) - psgr'!B33*'Level of Activity (LA) - psgr'!$B$29 -> 2.1361794e+10 | C33: ='Level of Activity (LA) - psgr'!C33*'Level of Activity (LA) - psgr'!$B$29 -> 2.1962068e+10 | D33: ='Level of Activity (LA) - psgr'!D33*'Level of Activity (LA) - psgr'!$B$29 -> 2.2579211e+10 | E33: ='Level of Activity (LA) - psgr'!E33*'Level of Activity (LA) - psgr'!$B$29 -> 2.3213695e+10 | F33: ='Level of Activity (LA) - psgr'!F33*'Level of Activity (LA) - psgr'!$B$29 -> 2.3866009e+10 | G33: ='Level of Activity (LA) - psgr'!G33*'Level of Activity (LA) - psgr'!$B$29 -> 2.4536653e+10 | H33: ='Level of Activity (LA) - psgr'!H33*'Level of Activity (LA) - psgr'!$B$29 -> 2.5226143e+10 | I33: ='Level of Activity (LA) - psgr'!I33*'Level of Activity (LA) - psgr'!$B$29 -> 2.5935007e+10 | ... AN33: ='Level of Activity (LA) - psgr'!AN33*'Level of Activity (LA) - psgr'!$B$29 -> 6.1233283e+10
A34: BioGasoil Bus | B34: ='Level of Activity (LA) - psgr'!B34*'Level of Activity (LA) - psgr'!$B$29 -> 3.6632956e+11 | C34: ='Level of Activity (LA) - psgr'!C34*'Level of Activity (LA) - psgr'!$B$29 -> 3.7662356e+11 | D34: ='Level of Activity (LA) - psgr'!D34*'Level of Activity (LA) - psgr'!$B$29 -> 3.8720683e+11 | E34: ='Level of Activity (LA) - psgr'!E34*'Level of Activity (LA) - psgr'!$B$29 -> 3.9808749e+11 | F34: ='Level of Activity (LA) - psgr'!F34*'Level of Activity (LA) - psgr'!$B$29 -> 4.092739e+11 | G34: ='Level of Activity (LA) - psgr'!G34*'Level of Activity (LA) - psgr'!$B$29 -> 4.2077466e+11 | H34: ='Level of Activity (LA) - psgr'!H34*'Level of Activity (LA) - psgr'!$B$29 -> 4.3259859e+11 | I34: ='Level of Activity (LA) - psgr'!I34*'Level of Activity (LA) - psgr'!$B$29 -> 4.4475477e+11 | ... AN34: ='Level of Activity (LA) - psgr'!AN34*'Level of Activity (LA) - psgr'!$B$29 -> 1.0500786e+12
A37: Variable: Railway: Total Activity (Passenger*miles)
A38: Scenario: Business as Usual
A39: Branch: Demand\Transportation\Passenger\Railway\Urban Train
A40: Region: Indonesia
A42: Branch | B42: 2022 | C42: 2023 | D42: 2024 | E42: 2025 | F42: 2026 | G42: 2027 | H42: 2028 | I42: 2029 | J42: 2030 | K42: 2031 | L42: 2032 | M42: 2033 | N42: 2034 | O42: 2035 | P42: 2036 | Q42: 2037 | R42: 2038 | S42: 2039 | T42: 2040 | U42: 2041 | V42: 2042 | W42: 2043 | X42: 2044 | Y42: 2045 | Z42: 2046 | AA42: 2047 | AB42: 2048 | AC42: 2049 | AD42: 2050 | AE42: 2051 | AF42: 2052 | AG42: 2053 | AH42: 2054 | AI42: 2055 | AJ42: 2056 | AK42: 2057 | AL42: 2058 | AM42: 2059 | AN42: 2060
A43: Urban Train | B43: ='Level of Activity (LA) - psgr'!B43*'Level of Activity (LA) - psgr'!$B$41 -> 3.4702257e+09 | C43: ='Level of Activity (LA) - psgr'!C43*'Level of Activity (LA) - psgr'!$B$41 -> 3.4820919e+09 | D43: ='Level of Activity (LA) - psgr'!D43*'Level of Activity (LA) - psgr'!$B$41 -> 3.4939582e+09 | E43: ='Level of Activity (LA) - psgr'!E43*'Level of Activity (LA) - psgr'!$B$41 -> 3.5058244e+09 | F43: ='Level of Activity (LA) - psgr'!F43*'Level of Activity (LA) - psgr'!$B$41 -> 3.5375664e+09 | G43: ='Level of Activity (LA) - psgr'!G43*'Level of Activity (LA) - psgr'!$B$41 -> 3.5693084e+09 | H43: ='Level of Activity (LA) - psgr'!H43*'Level of Activity (LA) - psgr'!$B$41 -> 3.6010505e+09 | I43: ='Level of Activity (LA) - psgr'!I43*'Level of Activity (LA) - psgr'!$B$41 -> 3.6327925e+09 | ... AN43: ='Level of Activity (LA) - psgr'!AN43*'Level of Activity (LA) - psgr'!$B$41 -> 4.0462651e+09
A44: Diesel Train | B44: ='Level of Activity (LA) - psgr'!B44*'Level of Activity (LA) - psgr'!$B$41 -> 4.6106777e+08 | C44: ='Level of Activity (LA) - psgr'!C44*'Level of Activity (LA) - psgr'!$B$41 -> 4.6264437e+08 | D44: ='Level of Activity (LA) - psgr'!D44*'Level of Activity (LA) - psgr'!$B$41 -> 4.6422096e+08 | E44: ='Level of Activity (LA) - psgr'!E44*'Level of Activity (LA) - psgr'!$B$41 -> 4.6579756e+08 | F44: ='Level of Activity (LA) - psgr'!F44*'Level of Activity (LA) - psgr'!$B$41 -> 4.7001493e+08 | G44: ='Level of Activity (LA) - psgr'!G44*'Level of Activity (LA) - psgr'!$B$41 -> 4.7423229e+08 | H44: ='Level of Activity (LA) - psgr'!H44*'Level of Activity (LA) - psgr'!$B$41 -> 4.7844966e+08 | I44: ='Level of Activity (LA) - psgr'!I44*'Level of Activity (LA) - psgr'!$B$41 -> 4.8266703e+08 | ... AN44: ='Level of Activity (LA) - psgr'!AN44*'Level of Activity (LA) - psgr'!$B$41 -> 5.3760263e+08
A45: BioGasoil Train | B45: ='Level of Activity (LA) - psgr'!B45*'Level of Activity (LA) - psgr'!$B$41 -> 7.9044013e+09 | C45: ='Level of Activity (LA) - psgr'!C45*'Level of Activity (LA) - psgr'!$B$41 -> 7.9314299e+09 | D45: ='Level of Activity (LA) - psgr'!D45*'Level of Activity (LA) - psgr'!$B$41 -> 7.9584585e+09 | E45: ='Level of Activity (LA) - psgr'!E45*'Level of Activity (LA) - psgr'!$B$41 -> 7.9854872e+09 | F45: ='Level of Activity (LA) - psgr'!F45*'Level of Activity (LA) - psgr'!$B$41 -> 8.0577884e+09 | G45: ='Level of Activity (LA) - psgr'!G45*'Level of Activity (LA) - psgr'!$B$41 -> 8.1300897e+09 | H45: ='Level of Activity (LA) - psgr'!H45*'Level of Activity (LA) - psgr'!$B$41 -> 8.2023909e+09 | I45: ='Level of Activity (LA) - psgr'!I45*'Level of Activity (LA) - psgr'!$B$41 -> 8.2746922e+09 | ... AN45: ='Level of Activity (LA) - psgr'!AN45*'Level of Activity (LA) - psgr'!$B$41 -> 9.2164908e+09
A48: Variable: Marine: Total Activity (Passenger*miles)
A49: Scenario: Business as Usual
A50: Branch: Demand\Transportation\Passenger\Marine\Gasoline Passenger Ship
A51: Region: Indonesia
A53: Branch | B53: 2022 | C53: 2023 | D53: 2024 | E53: 2025 | F53: 2026 | G53: 2027 | H53: 2028 | I53: 2029 | J53: 2030 | K53: 2031 | L53: 2032 | M53: 2033 | N53: 2034 | O53: 2035 | P53: 2036 | Q53: 2037 | R53: 2038 | S53: 2039 | T53: 2040 | U53: 2041 | V53: 2042 | W53: 2043 | X53: 2044 | Y53: 2045 | Z53: 2046 | AA53: 2047 | AB53: 2048 | AC53: 2049 | AD53: 2050 | AE53: 2051 | AF53: 2052 | AG53: 2053 | AH53: 2054 | AI53: 2055 | AJ53: 2056 | AK53: 2057 | AL53: 2058 | AM53: 2059 | AN53: 2060
...

Sheet Conversion - EC - psgr
A1: Variable: Car: Total Final Energy Consumption (BTU)
A2: Scenario: Business as Usual
A3: Branch: Demand\Transportation\Passenger\Road Transport\Car\Gasoline Car
A4: Region: Indonesia
A6: Branch | B6: 2022 | C6: 2023 | D6: 2024 | E6: 2025 | F6: 2026 | G6: 2027 | H6: 2028 | I6: 2029 | J6: 2030 | K6: 2031 | L6: 2032 | M6: 2033 | N6: 2034 | O6: 2035 | P6: 2036 | Q6: 2037 | R6: 2038 | S6: 2039 | T6: 2040 | U6: 2041 | V6: 2042 | W6: 2043 | X6: 2044 | Y6: 2045 | Z6: 2046 | AA6: 2047 | AB6: 2048 | AC6: 2049 | AD6: 2050 | AE6: 2051 | AF6: 2052 | AG6: 2053 | AH6: 2054 | AI6: 2055 | AJ6: 2056 | AK6: 2057 | AL6: 2058 | AM6: 2059 | AN6: 2060
A7: Gasoline Car | B7: ='Energy Consumption (EC) - psgr'!B7*'Energy Consumption (EC) - psgr'!$B$5 -> 3.7687106e+14 | C7: ='Energy Consumption (EC) - psgr'!C7*'Energy Consumption (EC) - psgr'!$B$5 -> 3.8746129e+14 | D7: ='Energy Consumption (EC) - psgr'!D7*'Energy Consumption (EC) - psgr'!$B$5 -> 3.983491e+14 | E7: ='Energy Consumption (EC) - psgr'!E7*'Energy Consumption (EC) - psgr'!$B$5 -> 4.0954286e+14 | F7: ='Energy Consumption (EC) - psgr'!F7*'Energy Consumption (EC) - psgr'!$B$5 -> 4.2105117e+14 | G7: ='Energy Consumption (EC) - psgr'!G7*'Energy Consumption (EC) - psgr'!$B$5 -> 4.3288287e+14 | H7: ='Energy Consumption (EC) - psgr'!H7*'Energy Consumption (EC) - psgr'!$B$5 -> 4.4504705e+14 | I7: ='Energy Consumption (EC) - psgr'!I7*'Energy Consumption (EC) - psgr'!$B$5 -> 4.5755304e+14 | ... AN7: ='Energy Consumption (EC) - psgr'!AN7*'Energy Consumption (EC) - psgr'!$B$5 -> 1.0802956e+15
A8: Electric Car | B8: ='Energy Consumption (EC) - psgr'!B8*'Energy Consumption (EC) - psgr'!$B$5 -> 5.2959647e+10 | C8: ='Energy Consumption (EC) - psgr'!C8*'Energy Consumption (EC) - psgr'!$B$5 -> 5.4447833e+10 | D8: ='Energy Consumption (EC) - psgr'!D8*'Energy Consumption (EC) - psgr'!$B$5 -> 5.5977838e+10 | E8: ='Energy Consumption (EC) - psgr'!E8*'Energy Consumption (EC) - psgr'!$B$5 -> 5.7550837e+10 | F8: ='Energy Consumption (EC) - psgr'!F8*'Energy Consumption (EC) - psgr'!$B$5 -> 5.9168038e+10 | G8: ='Energy Consumption (EC) - psgr'!G8*'Energy Consumption (EC) - psgr'!$B$5 -> 6.0830682e+10 | H8: ='Energy Consumption (EC) - psgr'!H8*'Energy Consumption (EC) - psgr'!$B$5 -> 6.2540048e+10 | I8: ='Energy Consumption (EC) - psgr'!I8*'Energy Consumption (EC) - psgr'!$B$5 -> 6.4297447e+10 | ... AN8: ='Energy Consumption (EC) - psgr'!AN8*'Energy Consumption (EC) - psgr'!$B$5 -> 1.5180809e+11
A9: CNG Car | B9: ='Energy Consumption (EC) - psgr'!B9*'Energy Consumption (EC) - psgr'!$B$5 -> 1.677313e+11 | C9: ='Energy Consumption (EC) - psgr'!C9*'Energy Consumption (EC) - psgr'!$B$5 -> 1.7244461e+11 | D9: ='Energy Consumption (EC) - psgr'!D9*'Energy Consumption (EC) - psgr'!$B$5 -> 1.7729037e+11 | E9: ='Energy Consumption (EC) - psgr'!E9*'Energy Consumption (EC) - psgr'!$B$5 -> 1.822723e+11 | F9: ='Energy Consumption (EC) - psgr'!F9*'Energy Consumption (EC) - psgr'!$B$5 -> 1.8739422e+11 | G9: ='Energy Consumption (EC) - psgr'!G9*'Energy Consumption (EC) - psgr'!$B$5 -> 1.9266007e+11 | H9: ='Energy Consumption (EC) - psgr'!H9*'Energy Consumption (EC) - psgr'!$B$5 -> 1.980739e+11 | I9: ='Energy Consumption (EC) - psgr'!I9*'Energy Consumption (EC) - psgr'!$B$5 -> 2.0363985e+11 | ... AN9: ='Energy Consumption (EC) - psgr'!AN9*'Energy Consumption (EC) - psgr'!$B$5 -> 4.8079943e+11
A10: Diesel Car | B10: ='Energy Consumption (EC) - psgr'!B10*'Energy Consumption (EC) - psgr'!$B$5 -> 5.42535e+12 | C10: ='Energy Consumption (EC) - psgr'!C10*'Energy Consumption (EC) - psgr'!$B$5 -> 5.5778045e+12 | D10: ='Energy Consumption (EC) - psgr'!D10*'Energy Consumption (EC) - psgr'!$B$5 -> 5.7345429e+12 | E10: ='Energy Consumption (EC) - psgr'!E10*'Energy Consumption (EC) - psgr'!$B$5 -> 5.8956858e+12 | F10: ='Energy Consumption (EC) - psgr'!F10*'Energy Consumption (EC) - psgr'!$B$5 -> 6.0613568e+12 | G10: ='Energy Consumption (EC) - psgr'!G10*'Energy Consumption (EC) - psgr'!$B$5 -> 6.2316833e+12 | H10: ='Energy Consumption (EC) - psgr'!H10*'Energy Consumption (EC) - psgr'!$B$5 -> 6.406796e+12 | I10: ='Energy Consumption (EC) - psgr'!I10*'Energy Consumption (EC) - psgr'!$B$5 -> 6.5868294e+12 | ... AN10: ='Energy Consumption (EC) - psgr'!AN10*'Energy Consumption (EC) - psgr'!$B$5 -> 1.555169e+13
A11: BioGasoil Car | B11: ='Energy Consumption (EC) - psgr'!B11*'Energy Consumption (EC) - psgr'!$B$5 -> 8.8655317e+13 | C11: ='Energy Consumption (EC) - psgr'!C11*'Energy Consumption (EC) - psgr'!$B$5 -> 9.1146566e+13 | D11: ='Energy Consumption (EC) - psgr'!D11*'Energy Consumption (EC) - psgr'!$B$5 -> 9.3707819e+13 | E11: ='Energy Consumption (EC) - psgr'!E11*'Energy Consumption (EC) - psgr'!$B$5 -> 9.6341045e+13 | F11: ='Energy Consumption (EC) - psgr'!F11*'Energy Consumption (EC) - psgr'!$B$5 -> 9.9048266e+13 | G11: ='Energy Consumption (EC) - psgr'!G11*'Energy Consumption (EC) - psgr'!$B$5 -> 1.0183156e+14 | H11: ='Energy Consumption (EC) - psgr'!H11*'Energy Consumption (EC) - psgr'!$B$5 -> 1.0469307e+14 | I11: ='Energy Consumption (EC) - psgr'!I11*'Energy Consumption (EC) - psgr'!$B$5 -> 1.0763498e+14 | ... AN11: ='Energy Consumption (EC) - psgr'!AN11*'Energy Consumption (EC) - psgr'!$B$5 -> 2.5412923e+14
A14: Variable: Motorcycle: Total Final Energy Consumption (BTU)
A15: Scenario: Business as Usual
A16: Branch: Demand\Transportation\Passenger\Road Transport\Motorcycle\Gasoline Motorcycle
A17: Region: Indonesia
A19: Branch | B19: 2022 | C19: 2023 | D19: 2024 | E19: 2025 | F19: 2026 | G19: 2027 | H19: 2028 | I19: 2029 | J19: 2030 | K19: 2031 | L19: 2032 | M19: 2033 | N19: 2034 | O19: 2035 | P19: 2036 | Q19: 2037 | R19: 2038 | S19: 2039 | T19: 2040 | U19: 2041 | V19: 2042 | W19: 2043 | X19: 2044 | Y19: 2045 | Z19: 2046 | AA19: 2047 | AB19: 2048 | AC19: 2049 | AD19: 2050 | AE19: 2051 | AF19: 2052 | AG19: 2053 | AH19: 2054 | AI19: 2055 | AJ19: 2056 | AK19: 2057 | AL19: 2058 | AM19: 2059 | AN19: 2060
A20: Gasoline Motorcycle | B20: ='Energy Consumption (EC) - psgr'!B20*'Energy Consumption (EC) - psgr'!$B$18 -> 7.4222247e+14 | C20: ='Energy Consumption (EC) - psgr'!C20*'Energy Consumption (EC) - psgr'!$B$18 -> 7.6307921e+14 | D20: ='Energy Consumption (EC) - psgr'!D20*'Energy Consumption (EC) - psgr'!$B$18 -> 7.8452203e+14 | E20: ='Energy Consumption (EC) - psgr'!E20*'Energy Consumption (EC) - psgr'!$B$18 -> 8.065674e+14 | F20: ='Energy Consumption (EC) - psgr'!F20*'Energy Consumption (EC) - psgr'!$B$18 -> 8.2923225e+14 | G20: ='Energy Consumption (EC) - psgr'!G20*'Energy Consumption (EC) - psgr'!$B$18 -> 8.52534e+14 | H20: ='Energy Consumption (EC) - psgr'!H20*'Energy Consumption (EC) - psgr'!$B$18 -> 8.7649053e+14 | I20: ='Energy Consumption (EC) - psgr'!I20*'Energy Consumption (EC) - psgr'!$B$18 -> 9.0112025e+14 | ... AN20: ='Energy Consumption (EC) - psgr'!AN20*'Energy Consumption (EC) - psgr'!$B$18 -> 2.1275703e+15
A21: Electric Motorcycle | B21: ='Energy Consumption (EC) - psgr'!B21*'Energy Consumption (EC) - psgr'!$B$18 -> 2.9797841e+10 | C21: ='Energy Consumption (EC) - psgr'!C21*'Energy Consumption (EC) - psgr'!$B$18 -> 3.0635172e+10 | D21: ='Energy Consumption (EC) - psgr'!D21*'Energy Consumption (EC) - psgr'!$B$18 -> 3.1496032e+10 | E21: ='Energy Consumption (EC) - psgr'!E21*'Energy Consumption (EC) - psgr'!$B$18 -> 3.2381083e+10 | F21: ='Energy Consumption (EC) - psgr'!F21*'Energy Consumption (EC) - psgr'!$B$18 -> 3.3291004e+10 | G21: ='Energy Consumption (EC) - psgr'!G21*'Energy Consumption (EC) - psgr'!$B$18 -> 3.4226494e+10 | H21: ='Energy Consumption (EC) - psgr'!H21*'Energy Consumption (EC) - psgr'!$B$18 -> 3.5188272e+10 | I21: ='Energy Consumption (EC) - psgr'!I21*'Energy Consumption (EC) - psgr'!$B$18 -> 3.6177076e+10 | ... AN21: ='Energy Consumption (EC) - psgr'!AN21*'Energy Consumption (EC) - psgr'!$B$18 -> 8.5415096e+10
A22: CNG Motorcycle | B22: ='Energy Consumption (EC) - psgr'!B22*'Energy Consumption (EC) - psgr'!$B$18 -> 1.3932014e+10 | C22: ='Energy Consumption (EC) - psgr'!C22*'Energy Consumption (EC) - psgr'!$B$18 -> 1.4323509e+10 | D22: ='Energy Consumption (EC) - psgr'!D22*'Energy Consumption (EC) - psgr'!$B$18 -> 1.4726005e+10 | E22: ='Energy Consumption (EC) - psgr'!E22*'Energy Consumption (EC) - psgr'!$B$18 -> 1.5139812e+10 | F22: ='Energy Consumption (EC) - psgr'!F22*'Energy Consumption (EC) - psgr'!$B$18 -> 1.5565246e+10 | G22: ='Energy Consumption (EC) - psgr'!G22*'Energy Consumption (EC) - psgr'!$B$18 -> 1.6002636e+10 | H22: ='Energy Consumption (EC) - psgr'!H22*'Energy Consumption (EC) - psgr'!$B$18 -> 1.6452316e+10 | I22: ='Energy Consumption (EC) - psgr'!I22*'Energy Consumption (EC) - psgr'!$B$18 -> 1.6914632e+10 | ... AN22: ='Energy Consumption (EC) - psgr'!AN22*'Energy Consumption (EC) - psgr'!$B$18 -> 3.9935924e+10
A25: Variable: Bus: Total Final Energy Consumption (BTU)
A26: Scenario: Business as Usual
A27: Branch: Demand\Transportation\Passenger\Road Transport\Bus\Electric Bus
A28: Region: Indonesia
A30: Branch | B30: 2022 | C30: 2023 | D30: 2024 | E30: 2025 | F30: 2026 | G30: 2027 | H30: 2028 | I30: 2029 | J30: 2030 | K30: 2031 | L30: 2032 | M30: 2033 | N30: 2034 | O30: 2035 | P30: 2036 | Q30: 2037 | R30: 2038 | S30: 2039 | T30: 2040 | U30: 2041 | V30: 2042 | W30: 2043 | X30: 2044 | Y30: 2045 | Z30: 2046 | AA30: 2047 | AB30: 2048 | AC30: 2049 | AD30: 2050 | AE30: 2051 | AF30: 2052 | AG30: 2053 | AH30: 2054 | AI30: 2055 | AJ30: 2056 | AK30: 2057 | AL30: 2058 | AM30: 2059 | AN30: 2060
A31: Electric Bus | B31: ='Energy Consumption (EC) - psgr'!B31*'Energy Consumption (EC) - psgr'!$B$29 -> 2.1744038e+10 | C31: ='Energy Consumption (EC) - psgr'!C31*'Energy Consumption (EC) - psgr'!$B$29 -> 2.2355054e+10 | D31: ='Energy Consumption (EC) - psgr'!D31*'Energy Consumption (EC) - psgr'!$B$29 -> 2.2983239e+10 | E31: ='Energy Consumption (EC) - psgr'!E31*'Energy Consumption (EC) - psgr'!$B$29 -> 2.3629077e+10 | F31: ='Energy Consumption (EC) - psgr'!F31*'Energy Consumption (EC) - psgr'!$B$29 -> 2.4293063e+10 | G31: ='Energy Consumption (EC) - psgr'!G31*'Energy Consumption (EC) - psgr'!$B$29 -> 2.4975708e+10 | H31: ='Energy Consumption (EC) - psgr'!H31*'Energy Consumption (EC) - psgr'!$B$29 -> 2.5677535e+10 | I31: ='Energy Consumption (EC) - psgr'!I31*'Energy Consumption (EC) - psgr'!$B$29 -> 2.6399083e+10 | ... AN31: ='Energy Consumption (EC) - psgr'!AN31*'Energy Consumption (EC) - psgr'!$B$29 -> 6.2328981e+10
A32: CNG Bus | B32: ='Energy Consumption (EC) - psgr'!B32*'Energy Consumption (EC) - psgr'!$B$29 -> 1.8759821e+11 | C32: ='Energy Consumption (EC) - psgr'!C32*'Energy Consumption (EC) - psgr'!$B$29 -> 1.9286979e+11 | D32: ='Energy Consumption (EC) - psgr'!D32*'Energy Consumption (EC) - psgr'!$B$29 -> 1.9828951e+11 | E32: ='Energy Consumption (EC) - psgr'!E32*'Energy Consumption (EC) - psgr'!$B$29 -> 2.0386152e+11 | F32: ='Energy Consumption (EC) - psgr'!F32*'Energy Consumption (EC) - psgr'!$B$29 -> 2.0959011e+11 | G32: ='Energy Consumption (EC) - psgr'!G32*'Energy Consumption (EC) - psgr'!$B$29 -> 2.1547967e+11 | H32: ='Energy Consumption (EC) - psgr'!H32*'Energy Consumption (EC) - psgr'!$B$29 -> 2.2153473e+11 | I32: ='Energy Consumption (EC) - psgr'!I32*'Energy Consumption (EC) - psgr'!$B$29 -> 2.2775994e+11 | ... AN32: ='Energy Consumption (EC) - psgr'!AN32*'Energy Consumption (EC) - psgr'!$B$29 -> 5.3774765e+11
A33: Diesel Bus | B33: ='Energy Consumption (EC) - psgr'!B33*'Energy Consumption (EC) - psgr'!$B$29 -> 1.9497489e+13 | C33: ='Energy Consumption (EC) - psgr'!C33*'Energy Consumption (EC) - psgr'!$B$29 -> 2.0045376e+13 | D33: ='Energy Consumption (EC) - psgr'!D33*'Energy Consumption (EC) - psgr'!$B$29 -> 2.0608658e+13 | E33: ='Energy Consumption (EC) - psgr'!E33*'Energy Consumption (EC) - psgr'!$B$29 -> 2.118777e+13 | F33: ='Energy Consumption (EC) - psgr'!F33*'Energy Consumption (EC) - psgr'!$B$29 -> 2.1783154e+13 | G33: ='Energy Consumption (EC) - psgr'!G33*'Energy Consumption (EC) - psgr'!$B$29 -> 2.2395269e+13 | H33: ='Energy Consumption (EC) - psgr'!H33*'Energy Consumption (EC) - psgr'!$B$29 -> 2.3024585e+13 | I33: ='Energy Consumption (EC) - psgr'!I33*'Energy Consumption (EC) - psgr'!$B$29 -> 2.3671585e+13 | ... AN33: ='Energy Consumption (EC) - psgr'!AN33*'Energy Consumption (EC) - psgr'!$B$29 -> 5.5889279e+13
A34: BioGasoil Bus | B34: ='Energy Consumption (EC) - psgr'!B34*'Energy Consumption (EC) - psgr'!$B$29 -> 3.1860728e+14 | C34: ='Energy Consumption (EC) - psgr'!C34*'Energy Consumption (EC) - psgr'!$B$29 -> 3.2756027e+14 | D34: ='Energy Consumption (EC) - psgr'!D34*'Energy Consumption (EC) - psgr'!$B$29 -> 3.3676484e+14 | E34: ='Energy Consumption (EC) - psgr'!E34*'Energy Consumption (EC) - psgr'!$B$29 -> 3.4622806e+14 | F34: ='Energy Consumption (EC) - psgr'!F34*'Energy Consumption (EC) - psgr'!$B$29 -> 3.5595721e+14 | G34: ='Energy Consumption (EC) - psgr'!G34*'Energy Consumption (EC) - psgr'!$B$29 -> 3.6595974e+14 | H34: ='Energy Consumption (EC) - psgr'!H34*'Energy Consumption (EC) - psgr'!$B$29 -> 3.7624335e+14 | I34: ='Energy Consumption (EC) - psgr'!I34*'Energy Consumption (EC) - psgr'!$B$29 -> 3.8681593e+14 | ... AN34: ='Energy Consumption (EC) - psgr'!AN34*'Energy Consumption (EC) - psgr'!$B$29 -> 9.1328333e+14
A37: Variable: Railway: Total Final Energy Consumption (BTU)
A38: Scenario: Business as Usual
A39: Branch: Demand\Transportation\Passenger\Railway\Urban Train
A40: Region: Indonesia
A42: Branch | B42: 2022 | C42: 2023 | D42: 2024 | E42: 2025 | F42: 2026 | G42: 2027 | H42: 2028 | I42: 2029 | J42: 2030 | K42: 2031 | L42: 2032 | M42: 2033 | N42: 2034 | O42: 2035 | P42: 2036 | Q42: 2037 | R42: 2038 | S42: 2039 | T42: 2040 | U42: 2041 | V42: 2042 | W42: 2043 | X42: 2044 | Y42: 2045 | Z42: 2046 | AA42: 2047 | AB42: 2048 | AC42: 2049 | AD42: 2050 | AE42: 2051 | AF42: 2052 | AG42: 2053 | AH42: 2054 | AI42: 2055 | AJ42: 2056 | AK42: 2057 | AL42: 2058 | AM42: 2059 | AN42: 2060
