Workbook

Sheet About 
A1: Direct Air Capture
A3: Sources: | B3: GDP growth
B4: OECD
B5: 2018
B6: Quarterly National Accounts
B7: https://data.oecd.org/gdp/gdp-long-term-forecast.htm
B8: Real GDP long-term forecast
B10: World Bank
B11: World Development Indicators, World Bank
B12: https://databank.worldbank.org/source/world-development-indicators
B14: Potential
B15: US Department of State
B16: 2021
B17: The Long-Term Strategy of the United States: Pathways to Net-Zero Greenhouse Gas Emissions by 2050
B18: https://www.whitehouse.gov/wp-content/uploads/2021/10/US-Long-Term-Strategy.pdf
B19: Figure 17
B21: Energy Intensity and CapEx Data
B22: Realmonte et al.
B23: 2019
B24: An inter-model assessment of the role of direct air capture in deep mitigation pathways
B25: https://www.nature.com/articles/s41467-019-10842-5
B26: Table 2
B27: https://static-content.springer.com/esm/art%3A10.1038%2Fs41467-019-10842-5/MediaObjects/41467_2019_10842_MOESM1_ESM.pdf
B28: Supplementary materials, Fig 3
A30: Note: | B30: DAC potential for Indonesia is adjusted based on the US DAC potential using the ratio of US GDP and Indonesia's GDP projections by 2050.

Sheet CDR potential
A1: pixels per 1.25 Gt | B1: 56
A2: pixels to upper range, 2030 | B2: 0
A3: pixels to upper range, 2040 | B3: 4
A4: pixels to upper range, 2050 | B4: 16
A6: 2040 potential (Gt) | B6: =B3/B1*1.25 -> 0.089285714
A7: 2050 potential (Gt) | B7: =B4/B1*1.25 -> 0.35714286
A9: *To be conservative, we choose to measure
A10: to the upper range of the CDR range. CDR
A11: in this report includes DAC as well as several
A12: other potential forms of geoengineering,
A13: meaning it is best to report the conservative
A14: potential.
B16: 2020 | C16: 2030 | D16: 2040 | E16: 2050
A17: potential | B17: 0 | C17: 0 | D17: =B6*10^9 -> 89285714 | E17: =B7*10^9 -> 3.5714286e+08

Sheet Data
A1: DAC Technologies Considered
A2: DAC1 = hydroxide sorbent-based technology, most mature technology, used for large-scale plants, requires high heat (>800C)
A3: DAC2 = amine-based technology, less mature, can be small modular units, can accept waste heat (temp 85-120C)
A5: According to the source paper, DAC1 heat is provided by natural gas, and DAC2 heat is provided by waste heat.
A6: However, the largest currently operating DAC facilities use solid sorbent systems and utilize non-fossil resources at low heat (80-120 C),
A7: see: https://www.wri.org/insights/direct-air-capture-resource-considerations-and-costs-carbon-removal, Status of the Leading DAC Companies.
A8: Therefore, we take the heat input specified for DAC1 plants and convert to the amount of electricity needed
A9: if supplied by a heat pump.
A11: Capital Cost per Ton CO2 Captured (amortized over lifetime of equipment)
A12: The paper indicates these costs include equipment, maintenance, and labor. Energy costs are not included.
A13: $/ton CO2 | B13: DAC1 | C13: DAC2
A14: High | B14: 300 | C14: 350
A15: Low | B15: 180 | C15: 200
A16: Floor | B16: 100 | C16: 50
A18: Electricity Required per Ton CO2 Captured
A19: GJ/ton CO2 | B19: DAC1 | C19: DAC2
A20: High | B20: 1.8 | C20: 1.1
A21: Low | B21: 1.3 | C21: 0.6
A22: Floor
A24: Heat Input Required per Ton CO2 Captured
A25: GJ/ton CO2 | B25: DAC1 | C25: DAC2
A26: High | B26: 8.1 | C26: 7.2
A27: Low | B27: 5.3 | C27: 4.4
A28: Floor
A30: Percent Reduction in Fuel Use with Heat Pump | B30: 0.67 | D30: Source: indst/PIFURfE
A32: Heat Input Required per Ton CO2 Captured, Converted to Electricity
A33: GJ/ton CO2 | B33: DAC1 | C33: DAC2
A34: High | B34: =B26*(1-$B$30) -> 2.673 | C34: =C26*(1-$B$30) -> 2.376
A35: Low | B35: =B27*(1-$B$30) -> 1.749 | C35: =C27*(1-$B$30) -> 1.452
A37: Technology Shares (Supplement Fig 3)
A38: Very little DAC of any sort is deployed before 2045-2050. DAC1 is dominant
A39: until after 2080. Therefore, for the EPS, which extends only to 2050, we
A40: assume the only relevant DAC technology is DAC1.
A62: Global DAC Potential
A63: We will use the 1.5-degree C pathway as our outer potential bound (100% lever setting),
A64: since it is the more aggressive of the two scenarios.
A65: We will measure deployment in specific years to the pixel, since the data are not
A66: provided in tabular form:
B68: 2045 | C68: 2050 | D68: 2060 | E68: 2070 | F68: 2080 | G68: 2090 | H68: 2100
A69: DAC1 (pixels, high zoom) | B69: 0 | C69: 5 | D69: 20 | E69: 122 | F69: 388 | G69: 384 | H69: 379
...

Sheet cal
A1: metric tons/yr | B1: 2019 | C1: 2020 | D1: 2021 | E1: 2022 | F1: 2023 | G1: 2024 | H1: 2025 | I1: 2026 | J1: 2027 | K1: 2028 | L1: 2029 | M1: 2030 | N1: 2031 | O1: 2032 | P1: 2033 | Q1: 2034 | R1: 2035 | S1: 2036 | T1: 2037 | U1: 2038 | V1: 2039 | W1: 2040 | X1: 2041 | Y1: 2042 | Z1: 2043 | AA1: 2044 | AB1: 2045 | AC1: 2046 | AD1: 2047 | AE1: 2048 | AF1: 2049 | AG1: 2050
A2: DAC Potential (US) | B2: {=TREND('CDR potential'!$B$17:$C$17,'CDR potential'!$B$16:$C$16,cal!B1)} -> 0 | C2: {=TREND('CDR potential'!$B$17:$C$17,'CDR potential'!$B$16:$C$16,cal!C1)} -> 0 | D2: {=TREND('CDR potential'!$B$17:$C$17,'CDR potential'!$B$16:$C$16,cal!D1)} -> 0 | E2: {=TREND('CDR potential'!$B$17:$C$17,'CDR potential'!$B$16:$C$16,cal!E1)} -> 0 | F2: {=TREND('CDR potential'!$B$17:$C$17,'CDR potential'!$B$16:$C$16,cal!F1)} -> 0 | G2: {=TREND('CDR potential'!$B$17:$C$17,'CDR potential'!$B$16:$C$16,cal!G1)} -> 0 | H2: {=TREND('CDR potential'!$B$17:$C$17,'CDR potential'!$B$16:$C$16,cal!H1)} -> 0 | I2: {=TREND('CDR potential'!$B$17:$C$17,'CDR potential'!$B$16:$C$16,cal!I1)} -> 0 | ... L2: {=TREND('CDR potential'!$B$17:$C$17,'CDR potential'!$B$16:$C$16,cal!L1)} -> 0 | M2: {=TREND('CDR potential'!$C$17:$D$17,'CDR potential'!$C$16:$D$16,cal!M1)} -> 0 | N2: {=TREND('CDR potential'!$C$17:$D$17,'CDR potential'!$C$16:$D$16,cal!N1)} -> 8928571.4 | O2: {=TREND('CDR potential'!$C$17:$D$17,'CDR potential'!$C$16:$D$16,cal!O1)} -> 17857143 | P2: {=TREND('CDR potential'!$C$17:$D$17,'CDR potential'!$C$16:$D$16,cal!P1)} -> 26785714 | Q2: {=TREND('CDR potential'!$C$17:$D$17,'CDR potential'!$C$16:$D$16,cal!Q1)} -> 35714286 | R2: {=TREND('CDR potential'!$C$17:$D$17,'CDR potential'!$C$16:$D$16,cal!R1)} -> 44642857 | S2: {=TREND('CDR potential'!$C$17:$D$17,'CDR potential'!$C$16:$D$16,cal!S1)} -> 53571429 | T2: {=TREND('CDR potential'!$C$17:$D$17,'CDR potential'!$C$16:$D$16,cal!T1)} -> 62500000 | ... V2: {=TREND('CDR potential'!$C$17:$D$17,'CDR potential'!$C$16:$D$16,cal!V1)} -> 80357143 | W2: {=TREND('CDR potential'!$D$17:$E$17,'CDR potential'!$D$16:$E$16,cal!W1)} -> 89285714 | X2: {=TREND('CDR potential'!$D$17:$E$17,'CDR potential'!$D$16:$E$16,cal!X1)} -> 1.1607143e+08 | Y2: {=TREND('CDR potential'!$D$17:$E$17,'CDR potential'!$D$16:$E$16,cal!Y1)} -> 1.4285714e+08 | Z2: {=TREND('CDR potential'!$D$17:$E$17,'CDR potential'!$D$16:$E$16,cal!Z1)} -> 1.6964286e+08 | AA2: {=TREND('CDR potential'!$D$17:$E$17,'CDR potential'!$D$16:$E$16,cal!AA1)} -> 1.9642857e+08 | AB2: {=TREND('CDR potential'!$D$17:$E$17,'CDR potential'!$D$16:$E$16,cal!AB1)} -> 2.2321429e+08 | AC2: {=TREND('CDR potential'!$D$17:$E$17,'CDR potential'!$D$16:$E$16,cal!AC1)} -> 250000000 | AD2: {=TREND('CDR potential'!$D$17:$E$17,'CDR potential'!$D$16:$E$16,cal!AD1)} -> 2.7678571e+08 | ... AG2: {=TREND('CDR potential'!$D$17:$E$17,'CDR potential'!$D$16:$E$16,cal!AG1)} -> 3.5714286e+08
A3: US GDP | B3: 19300000000000 | C3: 19600000000000 | D3: 19800000000000 | E3: 20100000000000 | F3: 20400000000000 | G3: 20800000000000 | H3: 21100000000000 | I3: 21500000000000 | J3: 21900000000000 | K3: 22300000000000 | L3: 22700000000000 | M3: 23100000000000 | N3: 23500000000000 | O3: 23900000000000 | P3: 24300000000000 | Q3: 24800000000000 | R3: 25200000000000 | S3: 25700000000000 | T3: 26200000000000 | U3: 26700000000000 | V3: 27200000000000 | W3: 27700000000000 | X3: 28200000000000 | Y3: 28800000000000 | Z3: 29300000000000 | AA3: 29900000000000 | AB3: 30500000000000 | AC3: 31100000000000 | AD3: 31700000000000 | AE3: 32400000000000 | AF3: 33000000000000 | AG3: 33700000000000
A4: Indonesia GDP | B4: 1.0164669e+12 | C4: 9.9547677e+11 | D4: 1.0322222e+12 | E4: 1.0853079e+12 | F4: 1.1654216e+12 | G4: 1.2454969e+12 | H4: 1.3201807e+12 | I4: 1.3902408e+12 | J4: 1.4576106e+12 | K4: 1.5238306e+12 | L4: 1.589702e+12 | M4: 1.6556504e+12 | N4: 1.7219029e+12 | O4: 1.7886075e+12 | P4: 1.8558273e+12 | Q4: 1.9235866e+12 | R4: 1.9918876e+12 | S4: 2.060695e+12 | T4: 2.1300001e+12 | U4: 2.1998326e+12 | V4: 2.2701583e+12 | W4: 2.3409419e+12 | X4: 2.4121733e+12 | Y4: 2.48384e+12 | Z4: 2.5559695e+12 | AA4: 2.6285637e+12 | AB4: 2.7015233e+12 | AC4: 2.7747492e+12 | AD4: 2.8482119e+12 | AE4: 2.9219436e+12 | AF4: 2.9959704e+12 | AG4: 3.0703009e+12
A5: Indonesia/US GDP | B5: =B4/B3 -> 0.052666677 | C5: =C4/C3 -> 0.050789631 | D5: =D4/D3 -> 0.052132435 | E5: =E4/E3 -> 0.053995417 | F5: =F4/F3 -> 0.057128508 | G5: =G4/G3 -> 0.059879658 | H5: =H4/H3 -> 0.062567806 | I5: =I4/I3 -> 0.064662362 | ... AG5: =AG4/AG3 -> 0.091106852
A6: DAC Potential (Indonesia) | B6: =B2*B5 -> 0 | C6: =C2*C5 -> 0 | D6: =D2*D5 -> 0 | E6: =E2*E5 -> 0 | F6: =F2*F5 -> 0 | G6: =G2*G5 -> 0 | H6: =H2*H5 -> 0 | I6: =I2*I5 -> 0 | ... AG6: =AG2*AG5 -> 32538161

Sheet DACD-potential
A1: metric tons/yr | B1: 2019 | C1: 2020 | D1: 2021 | E1: 2022 | F1: 2023 | G1: 2024 | H1: 2025 | I1: 2026 | J1: 2027 | K1: 2028 | L1: 2029 | M1: 2030 | N1: 2031 | O1: 2032 | P1: 2033 | Q1: 2034 | R1: 2035 | S1: 2036 | T1: 2037 | U1: 2038 | V1: 2039 | W1: 2040 | X1: 2041 | Y1: 2042 | Z1: 2043 | AA1: 2044 | AB1: 2045 | AC1: 2046 | AD1: 2047 | AE1: 2048 | AF1: 2049 | AG1: 2050 | AH1: 2051 | AI1: 2052 | AJ1: 2053 | AK1: 2054 | AL1: 2055 | AM1: 2056 | AN1: 2057 | AO1: 2058 | AP1: 2059 | AQ1: 2060 | AR1: 2061 | AS1: 2062 | AT1: 2063 | AU1: 2064 | AV1: 2065 | AW1: 2066 | AX1: 2067 | AY1: 2068 | AZ1: 2069 | BA1: 2070
A2: DAC Potential | B2: =cal!B6 -> 0 | C2: =cal!C6 -> 0 | D2: =cal!D6 -> 0 | E2: =cal!E6 -> 0 | F2: =cal!F6 -> 0 | G2: =cal!G6 -> 0 | H2: =cal!H6 -> 0 | I2: =cal!I6 -> 0 | ... AG2: =cal!AG6 -> 32538161 | AH2: =_xlfn.FORECAST.LINEAR(AH1,$B$2:$AG$2,$B$1:$AG$1) -> 23773752 | AI2: =_xlfn.FORECAST.LINEAR(AI1,$B$2:$AG$2,$B$1:$AG$1) -> 24739173 | AJ2: =_xlfn.FORECAST.LINEAR(AJ1,$B$2:$AG$2,$B$1:$AG$1) -> 25704594 | AK2: =_xlfn.FORECAST.LINEAR(AK1,$B$2:$AG$2,$B$1:$AG$1) -> 26670015 | AL2: =_xlfn.FORECAST.LINEAR(AL1,$B$2:$AG$2,$B$1:$AG$1) -> 27635436 | AM2: =_xlfn.FORECAST.LINEAR(AM1,$B$2:$AG$2,$B$1:$AG$1) -> 28600857 | AN2: =_xlfn.FORECAST.LINEAR(AN1,$B$2:$AG$2,$B$1:$AG$1) -> 29566278 | AO2: =_xlfn.FORECAST.LINEAR(AO1,$B$2:$AG$2,$B$1:$AG$1) -> 30531699 | ... BA2: =_xlfn.FORECAST.LINEAR(BA1,$B$2:$AG$2,$B$1:$AG$1) -> 42116750

Sheet DACD-energyintensity
A1: BTU/metric ton CO2 | B1: 2017 | C1: 2018 | D1: 2019 | E1: 2020 | F1: 2021 | G1: 2022 | H1: 2023 | I1: 2024 | J1: 2025 | K1: 2026 | L1: 2027 | M1: 2028 | N1: 2029 | O1: 2030 | P1: 2031 | Q1: 2032 | R1: 2033 | S1: 2034 | T1: 2035 | U1: 2036 | V1: 2037 | W1: 2038 | X1: 2039 | Y1: 2040 | Z1: 2041 | AA1: 2042 | AB1: 2043 | AC1: 2044 | AD1: 2045 | AE1: 2046 | AF1: 2047 | AG1: 2048 | AH1: 2049 | AI1: 2050 | AJ1: 2051 | AK1: 2052 | AL1: 2053 | AM1: 2054 | AN1: 2055 | AO1: 2056 | AP1: 2057 | AQ1: 2058 | AR1: 2059 | AS1: 2060 | AT1: 2061 | AU1: 2062 | AV1: 2063 | AW1: 2064 | AX1: 2065 | AY1: 2066 | AZ1: 2067 | BA1: 2068 | BB1: 2069 | BC1: 2070
A2: electricity | B2: =(Data!B20+Data!B34)*Data!B103 -> 4236315.7 | C2: =$B2 -> 4236315.7 | D2: =$B2 -> 4236315.7 | E2: =$B2 -> 4236315.7 | F2: =$B2 -> 4236315.7 | G2: =$B2 -> 4236315.7 | H2: =$B2 -> 4236315.7 | I2: =$B2 -> 4236315.7 | J2: =$B2 -> 4236315.7 | ... AI2: =$B2 -> 4236315.7 | AJ2: =_xlfn.FORECAST.LINEAR(AJ1,$B$2:$AG$2,$B$1:$AG$1) -> 4236315.7 | AK2: =_xlfn.FORECAST.LINEAR(AK1,$B$2:$AG$2,$B$1:$AG$1) -> 4236315.7 | AL2: =_xlfn.FORECAST.LINEAR(AL1,$B$2:$AG$2,$B$1:$AG$1) -> 4236315.7 | AM2: =_xlfn.FORECAST.LINEAR(AM1,$B$2:$AG$2,$B$1:$AG$1) -> 4236315.7 | AN2: =_xlfn.FORECAST.LINEAR(AN1,$B$2:$AG$2,$B$1:$AG$1) -> 4236315.7 | AO2: =_xlfn.FORECAST.LINEAR(AO1,$B$2:$AG$2,$B$1:$AG$1) -> 4236315.7 | AP2: =_xlfn.FORECAST.LINEAR(AP1,$B$2:$AG$2,$B$1:$AG$1) -> 4236315.7 | AQ2: =_xlfn.FORECAST.LINEAR(AQ1,$B$2:$AG$2,$B$1:$AG$1) -> 4236315.7 | ... BC2: =_xlfn.FORECAST.LINEAR(BC1,$B$2:$AG$2,$B$1:$AG$1) -> 4236315.7
A3: coal | B3: 0 | C3: =$B3 -> 0 | D3: =$B3 -> 0 | E3: =$B3 -> 0 | F3: =$B3 -> 0 | G3: =$B3 -> 0 | H3: =$B3 -> 0 | I3: =$B3 -> 0 | J3: =$B3 -> 0 | ... AI3: =$B3 -> 0 | AJ3: =AI3 -> 0 | AK3: =AJ3 -> 0 | AL3: =AK3 -> 0 | AM3: =AL3 -> 0 | AN3: =AM3 -> 0 | AO3: =AN3 -> 0 | AP3: =AO3 -> 0 | AQ3: =AP3 -> 0 | ... BC3: =BB3 -> 0
A4: natural gas | B4: 0 | C4: =$B4 -> 0 | D4: =$B4 -> 0 | E4: =$B4 -> 0 | F4: =$B4 -> 0 | G4: =$B4 -> 0 | H4: =$B4 -> 0 | I4: =$B4 -> 0 | J4: =$B4 -> 0 | ... AI4: =$B4 -> 0 | AJ4: =AI4 -> 0 | AK4: =AJ4 -> 0 | AL4: =AK4 -> 0 | AM4: =AL4 -> 0 | AN4: =AM4 -> 0 | AO4: =AN4 -> 0 | AP4: =AO4 -> 0 | AQ4: =AP4 -> 0 | ... BC4: =BB4 -> 0
A5: biomass | B5: 0 | C5: =$B5 -> 0 | D5: =$B5 -> 0 | E5: =$B5 -> 0 | F5: =$B5 -> 0 | G5: =$B5 -> 0 | H5: =$B5 -> 0 | I5: =$B5 -> 0 | J5: =$B5 -> 0 | ... AI5: =$B5 -> 0 | AJ5: =AI5 -> 0 | AK5: =AJ5 -> 0 | AL5: =AK5 -> 0 | AM5: =AL5 -> 0 | AN5: =AM5 -> 0 | AO5: =AN5 -> 0 | AP5: =AO5 -> 0 | AQ5: =AP5 -> 0 | ... BC5: =BB5 -> 0
A6: petroleum diesel | B6: 0 | C6: =$B6 -> 0 | D6: =$B6 -> 0 | E6: =$B6 -> 0 | F6: =$B6 -> 0 | G6: =$B6 -> 0 | H6: =$B6 -> 0 | I6: =$B6 -> 0 | J6: =$B6 -> 0 | ... AI6: =$B6 -> 0 | AJ6: =AI6 -> 0 | AK6: =AJ6 -> 0 | AL6: =AK6 -> 0 | AM6: =AL6 -> 0 | AN6: =AM6 -> 0 | AO6: =AN6 -> 0 | AP6: =AO6 -> 0 | AQ6: =AP6 -> 0 | ... BC6: =BB6 -> 0
A7: heat | B7: 0 | C7: =$B7 -> 0 | D7: =$B7 -> 0 | E7: =$B7 -> 0 | F7: =$B7 -> 0 | G7: =$B7 -> 0 | H7: =$B7 -> 0 | I7: =$B7 -> 0 | J7: =$B7 -> 0 | ... AI7: =$B7 -> 0 | AJ7: =AI7 -> 0 | AK7: =AJ7 -> 0 | AL7: =AK7 -> 0 | AM7: =AL7 -> 0 | AN7: =AM7 -> 0 | AO7: =AN7 -> 0 | AP7: =AO7 -> 0 | AQ7: =AP7 -> 0 | ... BC7: =BB7 -> 0
A8: crude oil | B8: 0 | C8: =$B8 -> 0 | D8: =$B8 -> 0 | E8: =$B8 -> 0 | F8: =$B8 -> 0 | G8: =$B8 -> 0 | H8: =$B8 -> 0 | I8: =$B8 -> 0 | J8: =$B8 -> 0 | ... AI8: =$B8 -> 0 | AJ8: =AI8 -> 0 | AK8: =AJ8 -> 0 | AL8: =AK8 -> 0 | AM8: =AL8 -> 0 | AN8: =AM8 -> 0 | AO8: =AN8 -> 0 | AP8: =AO8 -> 0 | AQ8: =AP8 -> 0 | ... BC8: =BB8 -> 0
A9: heavy or residual fuel oil | B9: 0 | C9: =$B9 -> 0 | D9: =$B9 -> 0 | E9: =$B9 -> 0 | F9: =$B9 -> 0 | G9: =$B9 -> 0 | H9: =$B9 -> 0 | I9: =$B9 -> 0 | J9: =$B9 -> 0 | ... AI9: =$B9 -> 0 | AJ9: =AI9 -> 0 | AK9: =AJ9 -> 0 | AL9: =AK9 -> 0 | AM9: =AL9 -> 0 | AN9: =AM9 -> 0 | AO9: =AN9 -> 0 | AP9: =AO9 -> 0 | AQ9: =AP9 -> 0 | ... BC9: =BB9 -> 0
A10: LPG propane or butane | B10: 0 | C10: =$B10 -> 0 | D10: =$B10 -> 0 | E10: =$B10 -> 0 | F10: =$B10 -> 0 | G10: =$B10 -> 0 | H10: =$B10 -> 0 | I10: =$B10 -> 0 | J10: =$B10 -> 0 | ... AI10: =$B10 -> 0 | AJ10: =AI10 -> 0 | AK10: =AJ10 -> 0 | AL10: =AK10 -> 0 | AM10: =AL10 -> 0 | AN10: =AM10 -> 0 | AO10: =AN10 -> 0 | AP10: =AO10 -> 0 | AQ10: =AP10 -> 0 | ... BC10: =BB10 -> 0
A11: hydrogen | B11: 0 | C11: =$B11 -> 0 | D11: =$B11 -> 0 | E11: =$B11 -> 0 | F11: =$B11 -> 0 | G11: =$B11 -> 0 | H11: =$B11 -> 0 | I11: =$B11 -> 0 | J11: =$B11 -> 0 | ... AI11: =$B11 -> 0 | AJ11: =AI11 -> 0 | AK11: =AJ11 -> 0 | AL11: =AK11 -> 0 | AM11: =AL11 -> 0 | AN11: =AM11 -> 0 | AO11: =AN11 -> 0 | AP11: =AO11 -> 0 | AQ11: =AP11 -> 0 | ... BC11: =BB11 -> 0

Sheet DACD-capex
A1: $/metric ton CO2 | B1: 2017 | C1: 2018 | D1: 2019 | E1: 2020 | F1: 2021 | G1: 2022 | H1: 2023 | I1: 2024 | J1: 2025 | K1: 2026 | L1: 2027 | M1: 2028 | N1: 2029 | O1: 2030 | P1: 2031 | Q1: 2032 | R1: 2033 | S1: 2034 | T1: 2035 | U1: 2036 | V1: 2037 | W1: 2038 | X1: 2039 | Y1: 2040 | Z1: 2041 | AA1: 2042 | AB1: 2043 | AC1: 2044 | AD1: 2045 | AE1: 2046 | AF1: 2047 | AG1: 2048 | AH1: 2049 | AI1: 2050 | AJ1: 2051 | AK1: 2052 | AL1: 2053 | AM1: 2054 | AN1: 2055 | AO1: 2056 | AP1: 2057 | AQ1: 2058 | AR1: 2059 | AS1: 2060 | AT1: 2061 | AU1: 2062 | AV1: 2063 | AW1: 2064 | AX1: 2065 | AY1: 2066 | AZ1: 2067 | BA1: 2068 | BB1: 2069 | BC1: 2070
A2: amortized CapEx | B2: =Data!B14 -> 300 | C2: =$B2 -> 300 | D2: =$B2 -> 300 | E2: =$B2 -> 300 | F2: =$B2 -> 300 | G2: =$B2 -> 300 | H2: =$B2 -> 300 | I2: =$B2 -> 300 | J2: =$B2 -> 300 | ... AI2: =$B2 -> 300 | AJ2: =AI2 -> 300 | AK2: =AJ2 -> 300 | AL2: =AK2 -> 300 | AM2: =AL2 -> 300 | AN2: =AM2 -> 300 | AO2: =AN2 -> 300 | AP2: =AO2 -> 300 | AQ2: =AP2 -> 300 | ... BC2: =BB2 -> 300
