Workbook

Sheet About
A1: BAU Expected Capacity Factors
A3: Source: | B3: Existing installed capacity & generation for all power plants
B4: ESDM
B5: 2022
B6: Handbook of Energy and Economic Statistics of Indonesia
B7: https://www.esdm.go.id/assets/media/content/content-handbook-of-energy-and-economic-statistics-of-indonesia-2022.pdf
B8: Table 6.4.1 & 6.4.2
B10: Ember
B11: 2024
B12: Indonesia’s expansion of clean power can spur growth and equality
B13: https://ember-energy.org/app/uploads/2024/10/EN-Report-Indonesias-expansion-of-clean-power-can-spur-growth-and-equality.pdf
B15: Climate Policy Initiative
B16: 2024
B17: Indonesia Power Sector Finance Dashboard
B18: https://www.climatepolicyinitiative.org/wp-content/uploads/2024/10/Indonesia-Power-Sector-Finance-Flows.pdf
B20: ERIA
B21: 2022
B22: Forecast of Biomass Demand Potential in Indonesia: Seeking a Business Model for Wood Pellets
B23: https://www.eria.org/uploads/media/Research-Project-Report/2022-01-Biomass-Demand-Potential-Indonesia/Forecast-of-Biomass-Demand-Potential-in-Indonesia.pdf
B25: IESR
B26: 2022
B27: Indonesia Energy Transition Outlook 2022
B28: https://iesr.or.id/wp-content/uploads/2022/01/Indonesia-Energy-Transition-Outlook-2022-IESR-Digital-Version-.pdf
B30: IRENA
B31: 2017
B32: RENEWABLE ENERGY PROSPECTS: INDONESIA
B33: https://www.irena.org/-/media/Files/IRENA/Agency/Publication/2017/Mar/IRENA_REmap_Indonesia_report_2017.pdf
B35: IAEA
B36: 2010
B37: PROVEN TECHNOLOGY PROVEN TECHNOLOGY PERSPECTIVE PERSPECTIVE FROM INDONESIA
B38: https://nucleus.iaea.org/sites/INPRO/df1/Session%202/19-Suprawoto.pdf
B40: Sidik Permana, Nuri Trianti, and Adi Rahmansyah
B41: 2020
B42: Nuclear energy contribution potential to secure electricity demand with low carbon emission and low risk of power plant in Indonesia
B43: https://iopscience.iop.org/article/10.1088/1755-1315/753/1/012048/pdf
A46: Notes
B47: We divide the quantity of power generated by the installed capacity to find the capacity factor for each technology. The value used for pre-retiring is based on the year 2022 (newest data available), and following the US EPS, we assume 10% improvement for newly builty power plants (exc. solar PV, wind PP). The value for nuclear and solar thermal is zero because they are not deployed in Indonesia. Some of the technology are classified as one type (ex: petroleum, crude oil, heavy oil or residual fuel). This can be seen further in the tab 'Generation' and 'Installed Capacity'. Co-firing in 'Generation' are all assumed to be fully coal since in Indonesia they usually still rely heavily on coal with lower mix of biomass. While hybrid PP in Indonesia uses solar and wind, thus we divide the value 50% for solar and 50% for wind.

Sheet Generation
A1: Power Generation | D1: (GWh)
A3: EPS Name | C3: HEESI Name | E3: table | G3: year | H3: hydro | I3: geothermal | J3: - petroleum - crude oil - heavy oil or residual fuel | K3: - natural gas peaker - natural gas non peaker | L3: - onshore wind - offshore wind | M3: - hard coal - lignite | N3: biomass | O3: Municipal Solid Waste | P3: solar PV | T3: Year | U3: 2011 | V3: 2012 | W3: 2013 | X3: 2014 | Y3: 2015 | Z3: 2016 | AA3: 2017 | AB3: 2018 | AC3: 2019 | AD3: 2020
A4: hydro | C4: Hydro PP | E4: 1,2,3 | G4: 2010 | H4: =B37+B56+B72+C72 -> 17456 | I4: =C37+C56 -> 9357 | J4: =E37+E56+G37 -> 19007 | K4: =H37+K37+L37+M37+G56+K56+J56+L56 -> 55389.6 | L4: =M56+E72+0.5*H72 -> 4 | M4: =F37+F56+I37 -> 68477 | N4: =N56+H56+O56+F72+G72 -> 95 | O4: =P56 -> 0 | P4: =D37+D56+D72+I72+J72+0.5*H72 -> 1 | T4: Hydro | U4: 12400 | V4: 12800 | W4: 16900 | X4: 15200 | Y4: 13700 | Z4: 19400 | AA4: 18600 | AB4: 16900 | AC4: 17200 | AD4: =_xlfn.FORECAST.LINEAR($AD$3,$U4:$AC4,$U$3:$AC$3) -> 19158.333
C5: Micro hydro PP | E5: 3 | G5: 2011 | H5: =B38+B57+B73+C73 -> 12419 | I5: =C38+C57 -> 9371 | J5: =E38+E57+G38 -> 22858 | K5: =H38+K38+L38+M38+G57+K57+J57+L57 -> 57459 | L5: =M57+E73+0.5*H73 -> 5 | M5: =F38+F57+I38 -> 81090 | N5: =N57+H57+O57+F73+G73 -> 186 | O5: =P57 -> 31 | P5: =D38+D57+D73+I73+J73+0.5*H73 -> 1 | T5: Geothermal | U5: 9370 | V5: 9420 | W5: 9410 | X5: 10000 | Y5: 10100 | Z5: 10700 | AA5: 12700 | AB5: 12600 | AC5: 14100 | AD5: =_xlfn.FORECAST.LINEAR($AD$3,$U5:$AC5,$U$3:$AC$3) -> 13911.667
A6: geothermal | C6: Geothermal PP | E6: 1,2 | G6: 2012 | H6: =B39+B58+B74+C74 -> 12799 | I6: =C39+C58 -> 9417 | J6: =E39+E58+G39 -> 21583 | K6: =H39+K39+L39+M39+G58+K58+J58+L58 -> 54077.1 | L6: =M58+E74+0.5*H74 -> 5 | M6: =F39+F58+I39 -> 102166 | N6: =N58+H58+O58+F74+G74 -> 238 | O6: =P58 -> 53 | P6: =D39+D58+D74+I74+J74+0.5*H74 -> 3 | T6: Biomass | U6: 0 | V6: 0 | W6: 0 | X6: 210 | Y6: 440 | Z6: 580 | AA6: 590 | AB6: 520 | AC6: 520 | AD6: =_xlfn.FORECAST.LINEAR($AD$3,$U6:$AC6,$U$3:$AC$3) -> 750.27778
A7: - petroleum - crude oil - heavy oil or residual fuel | C7: Diesel PP | E7: 1,2 | G7: 2013 | H7: =B40+B59+B75+C75 -> 16923 | I7: =C40+C59 -> 9414 | J7: =E40+E59+G40 -> 20362 | K7: =H40+K40+L40+M40+G59+K59+J59+L59 -> 58049.8 | L7: =M59+E75+0.5*H75 -> 0 | M7: =F40+F59+I40 -> 111252 | N7: =N59+H59+O59+F75+G75 -> 144 | O7: =P59 -> 41 | P7: =D40+D59+D75+I75+J75+0.5*H75 -> 5 | T7: Solar PV | U7: 0 | V7: 0 | W7: 0 | X7: 40 | Y7: 20 | Z7: 20 | AA7: 30 | AB7: 20 | AC7: 20 | AD7: =_xlfn.FORECAST.LINEAR($AD$3,$U7:$AC7,$U$3:$AC$3) -> 31.666667
C8: Steam PP - Oil | E8: 1 | G8: 2014 | H8: =B41+B60+B76+C76 -> 15162 | I8: =C41+C60 -> 10038 | J8: =E41+E60+G41 -> 23039 | K8: =H41+K41+L41+M41+G60+K60+J60+L60 -> 60537.1 | L8: =M60+E76+0.5*H76 -> 0 | M8: =F41+F60+I41 -> 119532 | N8: =N60+H60+O60+F76+G76 -> 205 | O8: =P60 -> 36 | P8: =D41+D60+D76+I76+J76+0.5*H76 -> 7 | T8: Wind | U8: 0 | V8: 0 | W8: 0 | X8: 0 | Y8: 0 | Z8: 10 | AA8: 0 | AB8: 170 | AC8: 170 | AD8: =_xlfn.FORECAST.LINEAR($AD$3,$U8:$AC8,$U$3:$AC$3) -> 138.88889
A9: - natural gas peaker - natural gas non peaker | C9: Steam PP - Gas | E9: 1, 2 | G9: 2015 | H9: =B42+B61+B77+C77 -> 13741 | I9: =C42+C61 -> 10048 | J9: =E42+E61+G42 -> 30911 | K9: =H42+K42+L42+M42+G61+K61+J61+L61 -> 54136.8 | L9: =M61+E77+0.5*H77 -> 4 | M9: =F42+F61+I42 -> 124657 | N9: =N61+H61+O61+F77+G77 -> 461 | O9: =P61 -> 19 | P9: =D42+D61+D77+I77+J77+0.5*H77 -> 5 | T9: Natural Gas | U9: 36600 | V9: 45300 | W9: 50300 | X9: 54500 | Y9: 57700 | Z9: 65300 | AA9: 59400 | AB9: 59400 | AC9: 59900 | AD9: =_xlfn.FORECAST.LINEAR($AD$3,$U9:$AC9,$U$3:$AC$3) -> 67975
C10: Combined Gas-Steam PP | E10: 1,2 | G10: 2016 | H10: =B43+B62+B78+C78 -> 18677 | I10: =C43+C62 -> 10656 | J10: =E43+E62+G43 -> 20800 | K10: =H43+K43+L43+M43+G62+K62+J62+L62 -> 61788.9 | L10: =M62+E78+0.5*H78 -> 6 | M10: =F43+F62+I43 -> 135381 | N10: =N62+H62+O62+F78+G78 -> 584 | O10: =P62 -> 6 | P10: =D43+D62+D78+I78+J78+0.5*H78 -> 21 | T10: Coal | U10: 77700 | V10: 101000 | W10: 110000 | X10: 120000 | Y10: 130000 | Z10: 134000 | AA10: 148000 | AB10: 161000 | AC10: 170000 | AD10: =_xlfn.FORECAST.LINEAR($AD$3,$U10:$AC10,$U$3:$AC$3) -> 181233.33
C11: Gas PP | E11: 1,2 | G11: 2017 | H11: =B44+B63+B79+C79 -> 18632 | I11: =C44+C63 -> 12764 | J11: =E44+E63+G44 -> 18848 | K11: =H44+K44+L44+M44+G63+K63+J63+L63 -> 55829.9 | L11: =M63+E79+0.5*H79 -> 0 | M11: =F44+F63+I44 -> 147964 | N11: =N63+H63+O63+F79+G79 -> 0 | O11: =P63 -> 590 | P11: =D44+D63+D79+I79+J79+0.5*H79 -> 29 | T11: Oil | U11: 42200 | V11: 29900 | W11: 26700 | X11: 25900 | Y11: 19200 | Z11: 16100 | AA11: 14300 | AB11: 15200 | AC11: 11300 | AD11: =_xlfn.FORECAST.LINEAR($AD$3,$U11:$AC11,$U$3:$AC$3) -> 5452.7778
C12: Gas Engine PP | E12: 1,2 | G12: 2018 | H12: =B45+B64+B80+C80 -> 21637 | I12: =C45+C64 -> 14019 | J12: =E45+E64+G45 -> 17946 | K12: =H45+K45+L45+M45+G64+K64+J64+L64 -> 57447.4 | L12: =M64+E80+0.5*H80 -> 192.5 | M12: =F45+F64+I45 -> 160013 | N12: =N64+H64+O64+F80+G80 -> 11803 | O12: =P64 -> 622 | P12: =D45+D64+D80+I80+J80+0.5*H80 -> 93.5
A13: - onshore wind - offshore wind | C13: Wind PP | E13: 2,3 | G13: 2019 | H13: =B46+B65+B81+C81 -> 21161 | I13: =C46+C65 -> 14100 | J13: =E46+E65+G46 -> 10582 | K13: =H46+K46+L46+M46+G65+K65+J65+L65 -> 62319.4 | L13: =M65+E81+0.5*H81 -> 486.5 | M13: =F46+F65+I46 -> 174493 | N13: =N65+H65+O65+F81+G81 -> 12166 | O13: =P65 -> 21 | P13: =D46+D65+D81+I81+J81+0.5*H81 -> 120.5 | T13: Year | U13: 2011 | V13: 2012 | W13: 2013 | X13: 2014 | Y13: 2015 | Z13: 2016 | AA13: 2017 | AB13: 2018 | AC13: 2019 | AD13: 2020
C14: Hybrid PP (1/2) | E14: 3 | G14: 2020 | H14: =B47+B66+B82+C82 -> 24428 | I14: =C47+C66 -> 15563 | J14: =E47+E66+G47 -> 6764 | K14: =H47+K47+L47+M47+G66+K66+J66+L66 -> 51275.9 | L14: =M66+E82+0.5*H82 -> 477.5 | M14: =F47+F66+I47 -> 180880 | N14: =N66+H66+O66+F82+G82 -> 12373 | O14: =P66 -> 17 | P14: =D47+D66+D82+I82+J82+0.5*H82 -> 173.5 | T14: Hydro | U14: 3920 | V14: 3940 | W14: 4090 | X14: 4160 | Y14: 4290 | Z14: 4400 | AA14: 4860 | AB14: 4940 | AC14: 4980 | AD14: =_xlfn.FORECAST.LINEAR($AD$13,$U14:$AC14,$U$13:$AC$13) -> 5149.4444
G15: 2021 | H15: =B48+B67+B83+C83 -> 24697 | I15: =C48+C67 -> 15868 | J15: =E48+E67+G48 -> 6648 | K15: =H48+K48+L48+M48+G67+K67+J67+L67 -> 55815 | L15: =M67+E83+0.5*H83 -> 439.5 | M15: =F48+F67+I48 -> 190232 | N15: =N67+H67+O67+F83+G83 -> 14965 | O15: =P67 -> 11 | P15: =D48+D67+D83+I83+J83+0.5*H83 -> 195.12 | T15: Geothermal | U15: 1150 | V15: 1220 | W15: 1260 | X15: 1320 | Y15: 1310 | Z15: 1370 | AA15: 2100 | AB15: 1720 | AC15: 2440 | AD15: =_xlfn.FORECAST.LINEAR($AD$13,$U15:$AC15,$U$13:$AC$13) -> 2242.5
G16: 2022 | H16: =B49+B68+B84+C84 -> 27295 | I16: =C49+C68 -> 16677 | J16: =E49+E68+G49 -> 6089 | K16: =H49+K49+L49+M49+G68+K68+J68+L68 -> 56126 | L16: =M68+E84+0.5*H84 -> 356 | M16: =F49+F68+I49 -> 205907 | N16: =N68+H68+O68+F84+G84 -> 20599 | O16: =P68 -> 44 | P16: =D49+D68+D84+I84+J84+0.5*H84 -> 443.73 | T16: Biomass | U16: 0 | V16: 0 | W16: 0 | X16: 30 | Y16: 40 | Z16: 40 | AA16: 150 | AB16: 170 | AC16: 170 | AD16: =_xlfn.FORECAST.LINEAR($AD$13,$U16:$AC16,$U$13:$AC$13) -> 191.66667
A17: - hard coal - lignite | C17: Coal | E17: 1,2 | T17: Solar PV | U17: 0 | V17: 10 | W17: 10 | X17: 10 | Y17: 10 | Z17: 10 | AA17: 20 | AB17: 30 | AC17: 60 | AD17: =_xlfn.FORECAST.LINEAR($AD$13,$U17:$AC17,$U$13:$AC$13) -> 44.444444
C18: Cofiring | E18: 1 | G18: fraction steam PP | T18: Wind | U18: 0 | V18: 0 | W18: 0 | X18: 0 | Y18: 0 | Z18: 0 | AA18: 0 | AB18: 70 | AC18: 130 | AD18: =_xlfn.FORECAST.LINEAR($AD$13,$U18:$AC18,$U$13:$AC$13) -> 83.055556
A19: biomass | C19: Biomass PP | E19: 2,3 | H19: coal | I19: oil | J19: gas | K19: co-firing | T19: Natural Gas | U19: 13000 | V19: 14500 | W19: 14700 | X19: 14800 | Y19: 15100 | Z19: 15800 | AA19: 14700 | AB19: 15200 | AC19: 17400 | AD19: =_xlfn.FORECAST.LINEAR($AD$13,$U19:$AC19,$U$13:$AC$13) -> 16747.222
C20: Biogas PP | E20: 2,3 | G20: 2010 | H20: =F37/SUM($F37:$I37) -> 0.85808551 | I20: =G37/SUM($F$37:$I$37) -> 0.12336875 | J20: =H37/SUM($F$37:$I$37) -> 0.018545749 | K20: =I37/SUM($F$37:$I$37) -> 0 | T20: Coal | U20: 14800 | V20: 17500 | W20: 18700 | X20: 20500 | Y20: 21100 | Z20: 23800 | AA20: 25700 | AB20: 26400 | AC20: 29400 | AD20: =_xlfn.FORECAST.LINEAR($AD$13,$U20:$AC20,$U$13:$AC$13) -> 30522.222
C21: Steam PP - biomass | E21: 2 | G21: 2011 | H21: =F38/SUM($F$38:$I$38) -> 0.88151309 | I21: =G38/SUM($F$38:$I$38) -> 0.10239669 | J21: =H38/SUM($F$38:$I$38) -> 0.016090221 | K21: =I38/SUM($F$38:$I$38) -> 0 | T21: Oil | U21: 6850 | V21: 7340 | W21: 7860 | X21: 7620 | Y21: 7220 | Z21: 7220 | AA21: 8160 | AB21: 7920 | AC21: 6500 | AD21: =_xlfn.FORECAST.LINEAR($AD$13,$U21:$AC21,$U$13:$AC$13) -> 7455
A22: Municipal Solid Waste | C22: Waste PP | E22: 2 | G22: 2012 | H22: =F39/SUM($F$39:$I$39) -> 0.90260488 | I22: =G39/SUM($F$39:$I$39) -> 0.03238828 | J22: =H39/SUM($F$39:$I$39) -> 0.065006841 | K22: =I39/SUM($F$39:$I$39) -> 0
A23: solar PV | C23: Solar PP | E23: 1,2 | G23: 2013 | H23: =F40/SUM($F$40:$I$40) -> 0.9186683 | I23: =G40/SUM($F$40:$I$40) -> 0.012889432 | J23: =H40/SUM($F$40:$I$40) -> 0.068442272 | K23: =I40/SUM($F$40:$I$40) -> 0
C24: Solar Public Street Lighting | E24: 3 | G24: 2014 | H24: =F41/SUM($F$41:$I$41) -> 0.9265098 | I24: =G41/SUM($F$41:$I$41) -> 0.008432209 | J24: =H41/SUM($F$41:$I$41) -> 0.065057992 | K24: =I41/SUM($F$41:$I$41) -> 0 | T24: Year | U24: 2011 | V24: 2012 | W24: 2013 | X24: 2014 | Y24: 2015 | Z24: 2016 | AA24: 2017 | AB24: 2018 | AC24: 2019 | AD24: 2020
C25: Solar Energy Saving Lamp | E25: 3 | G25: 2015 | H25: =F42/SUM($F$42:$I$42) -> 0.88047253 | I25: =G42/SUM($F$42:$I$42) -> 0.11801852 | J25: =H42/SUM($F$42:$I$42) -> 0.0015089503 | K25: =I42/SUM($F$42:$I$42) -> 0 | T25: Hydro
C26: Solar PP+PV | E26: 3 | G26: 2016 | H26: =F43/SUM($F$43:$I$43) -> 0.94321304 | I26: =G43/SUM($F$43:$I$43) -> 0.011113146 | J26: =H43/SUM($F$43:$I$43) -> 0.045673811 | K26: =I43/SUM($F$43:$I$43) -> 0 | T26: Geothermal
C27: Hybrid PP (1/2) | E27: 3 | G27: 2017 | H27: =F44/SUM($F$44:$I$44) -> 0.95798709 | I27: =G44/SUM($F$44:$I$44) -> 0.0026943475 | J27: =H44/SUM($F$44:$I$44) -> 0.039318566 | K27: =I44/SUM($F$44:$I$44) -> 0 | T27: Biomass
G28: 2018 | H28: =F45/SUM($F$45:$I$45) -> 0.96186122 | I28: =G45/SUM($F$45:$I$45) -> 0.0045193098 | J28: =H45/SUM($F$45:$I$45) -> 0.033619469 | K28: =I45/SUM($F$45:$I$45) -> 0 | T28: Solar PV
G29: 2019 | H29: =F46/SUM($F$46:$I$46) -> 0.96874595 | I29: =G46/SUM($F$46:$I$46) -> 0.0010212683 | J29: =H46/SUM($F$46:$I$46) -> 0.030232784 | K29: =I46/SUM($F$46:$I$46) -> 0 | T29: Wind
G30: 2020 | H30: =F47/SUM($F$47:$I$47) -> 0.98729888 | I30: =G47/SUM($F$47:$I$47) -> 0.00029618531 | J30: =H47/SUM($F$47:$I$47) -> 0.012309113 | K30: =I47/SUM($F$47:$I$47) -> 9.5824658e-05 | T30: Natural Gas
G31: 2021 | H31: =F48/SUM($F$46:$I$46) -> 0.92207561 | I31: =G48/SUM($F$46:$I$46) -> 0.0018236934 | J31: =H48/SUM($F$46:$I$46) -> 0.0077000389 | K31: =I48/SUM($F$46:$I$46) -> 0.0022208533 | T31: Coal
G32: 2022 | H32: =F49/SUM($F$47:$I$47) -> 0.99943376 | I32: =G49/SUM($F$47:$I$47) -> 7.8401993e-05 | J32: =H49/SUM($F$47:$I$47) -> 0.0025088638 | K32: =I49/SUM($F$47:$I$47) -> 0.0052180882 | T32: Oil
A34: Table 1. Power Plant Production | D34: (GWh)
F35: Steam PP
A36: Year | B36: Hydro PP | C36: Geothermal PP | D36: Solar PP | E36: Diesel PP | F36: Coal | G36: Oil | H36: Gas | I36: Cofiring | J36: Total | K36: Combined Gas-Steam PP | L36: Gas PP | M36: Gas Engine PP | N36: Wind PP | O36: Sub Total | U36: hard coal + lignite | V36: natural gas nonpeaker+peaker | W36: hydro | X36: wind onshore+offshore | Y36: solar PV | Z36: biomass | AA36: geothermal | AB36: petroleum, crude oil, heavy or residual oil | AC36: lignite | AD36: municipal solid waste
A37: 2010 | B37: 15827 | C37: 3398 | D37: 1 | E37: 11926 | F37: 46685 | G37: 6712 | H37: 1009 | I37: 0 | J37: 54407 | K37: 36812 | L37: 9266 | M37: 73.6 | N37: 0 | O37: 131710
A38: 2011 | B38: 10316 | C38: 3487 | D38: 1 | E38: 16125 | F38: 54950 | G38: 6383 | H38: 1003 | I38: 0 | J38: 62335 | K38: 40410 | L38: 10018 | M38: 48 | N38: 0 | O38: 142739
A39: 2012 | B39: 10525 | C39: 3558 | D39: 3 | E39: 18913 | F39: 66633 | G39: 2391 | H39: 4799 | I39: 0 | J39: 73823 | K39: 34569 | L39: 8310 | M39: 55.1 | N39: 0 | O39: 149755
A40: 2013 | B40: 13014 | C40: 4345 | D40: 5 | E40: 18919 | F40: 75193 | G40: 1055 | H40: 5602 | I40: 0 | J40: 81850 | K40: 36493 | L40: 8958 | M40: 381.8 | N40: 0 | O40: 163966
A41: 2014 | B41: 11164 | C41: 4285 | D41: 7 | E41: 21862 | F41: 83397 | G41: 759 | H41: 5856 | I41: 0 | J41: 90012 | K41: 38800 | L41: 9117 | M41: 51.1 | N41: 0 | O41: 175297
A42: 2015 | B42: 10005 | C42: 4392 | D42: 5 | E42: 18859 | F42: 85191 | G42: 11419 | H42: 146 | I42: 0 | J42: 96756 | K42: 39316 | L42: 5907 | M42: 1232.8 | N42: 0 | O42: 176472
...

Sheet Installed Capacity
A1: Installed Capacity | D1: (MW)
A3: EPS Name | C3: HEESI Name | E3: table | G3: year | H3: hydro | I3: geothermal | J3: - petroleum - crude oil - heavy oil or residual fuel | K3: - natural gas peaker - natural gas non peaker | L3: - onshore wind - offshore wind | M3: - hard coal - lignite | N3: biomass | O3: Municipal Solid Waste | P3: solar PV
A4: hydro | C4: Hydro PP | E4: 1,2 | G4: 2010 | H4: =B36+J36+K36 -> 3733.91 | I4: =F36 -> 1189 | J4: =C36*I20+G36+L36 -> 6171.5914 | K4: =J20*C36+D36+E36+H36 -> 11745.482 | L4: =I36 -> 0.34 | M4: =H20*C36+M36 -> 11139.237 | N4: =O36+P36 -> 0 | O4: =N36 -> 0 | P4: =L36 -> 0.19
C5: Micro hydro PP | E5: 1,2 | G5: 2011 | H5: =B37+J37+K37 -> 3944.42 | I5: =F37 -> 1226 | J5: =C37*I21+G37+L37 -> 7143.9992 | K5: =J21*C37+D37+E37+H37 -> 13149.09 | L5: =I37 -> 0.93 | M5: =H21*C37+M37 -> 14425.531 | N5: =O37+P37 -> 0 | O5: =N37 -> 26 | P5: =L37 -> 1.16
C6: Mini hydro PP | E6: 1 | G6: 2012 | H6: =B38+J38+K38 -> 4146.41 | I6: =F38 -> 1336 | J6: =C38*I22+G38+L38 -> 6616.1726 | K6: =J22*C38+D38+E38+H38 -> 15285.215 | L6: =I38 -> 0.93 | M6: =H22*C38+M38 -> 17834.953 | N6: =O38+P38 -> 0 | O6: =N38 -> 26 | P6: =L38 -> 4.09
A7: geothermal | C7: Geothermal PP | E7: 1 | G7: 2013 | H7: =B39+J39+K39 -> 5165.61 | I7: =F39 -> 1343.5 | J7: =C39*I23+G39+L39 -> 6250.95 | K7: =J23*C39+D39+E39+H39 -> 16319.194 | L7: =I39 -> 0.63 | M7: =H23*C39+M39 -> 21881.816 | N7: =O39+P39 -> 0 | O7: =N39 -> 26 | P7: =L39 -> 9.02
A8: - petroleum - crude oil - heavy oil or residual fuel | C8: Steam PP - fraction oil | E8: 1 | G8: 2014 | H8: =B40+J40+K40 -> 5229.39 | I8: =F40 -> 1403.5 | J8: =C40*I24+G40+L40 -> 6427.6941 | K8: =J24*C40+D40+E40+H40 -> 16700.581 | L8: =I40 -> 1.12 | M8: =H24*C40+M40 -> 23265.315 | N8: =O40+P40 -> 0 | O8: =N40 -> 36 | P8: =L40 -> 9.02
C9: Diesel PP | E9: 1 | G9: 2015 | H9: =B41+J41+K41 -> 5307.45 | I9: =F41 -> 1438.3 | J9: =C41*I25+G41+L41 -> 6982.3143 | K9: =J25*C41+D41+E41+H41 -> 15930.168 | L9: =I41 -> 1.46 | M9: =H25*C41+M41 -> 23286.368 | N9: =O41+P41 -> 1726.01 | O9: =N41 -> 15.65 | P9: =L41 -> 36.94
C10: Solar PP | E10: 1 | G10: 2016 | H10: =B42+J42+K42 -> 5650.86 | I10: =F42 -> 1533.3 | J10: =C42*I26+G42+L42 -> 4341.1796 | K10: =J26*C42+D42+E42+H42 -> 18364.643 | L10: =I42 -> 1.46 | M10: =H26*C42+M42 -> 26741.948 | N10: =O42+P42 -> 1767.45 | O10: =N42 -> 15.65 | P10: =L42 -> 46.7
A11: - natural gas peaker - natural gas non peaker | C11: Steam PP - fraction gas | E11: 1 | G11: 2017 | H11: =B43+J43+K43 -> 5687.9 | I11: =F43 -> 1808.3 | J11: =C43*I27+G43+L43 -> 4533.7299 | K11: =J27*C43+D43+E43+H43 -> 18869.316 | L11: =I43 -> 1.46 | M11: =H27*C43+M43 -> 29475.414 | N11: =O43+P43 -> 1841.16 | O11: =N43 -> 15.65 | P11: =L43 -> 54.48
C12: Gas PP | E12: 1 | G12: 2018 | H12: =B44+J44+K44+B55+C55 -> 5772.65 | I12: =F44 -> 1948.3 | J12: =C44*I28+G44+L44 -> 4798.0722 | K12: =J28*C44+D44+E44+H44 -> 19988.144 | L12: =I44+0.5*H55 -> 144.82 | M12: =H28*C44+M44 -> 30382.474 | N12: =O44+P44+G55+F55 -> 1867.15 | O12: =N44 -> 15.65 | P12: =L44+D55+I55+J55+0.5*H55 -> 67.26
C13: Combined Cycle PP | E13: 1 | G13: 2019 | H13: =B45+J45+K45+B56+C56 -> 5976.03 | I13: =F45 -> 2130.7 | J13: =C45*I29+G45+L45 -> 4920.186 | K13: =J29*C45+D45+E45+H45 -> 20910.211 | L13: =I45+0.5*H56 -> 155.62 | M13: =H29*C45+M45 -> 33651.493 | N13: =O45+P45+G56+F56 -> 1875.95 | O13: =N45 -> 15.65 | P13: =L45+D56+I56+J56+0.5*H56 -> 156.83
C14: Gas Engine PP | E14: 1 | G14: 2020 | H14: =B46+J46+K46+B57+C57 -> 6121.17 | I14: =F46 -> 2130.7 | J14: =C46*I30+G46+L46 -> 4998.2305 | K14: =J30*C46+D46+E46+H46 -> 21213.429 | L14: =I46+0.5*H57 -> 155.62 | M14: =H30*C46+M46 -> 36202.137 | N14: =O46+P46+G57+F57 -> 1884.86 | O14: =N46 -> 16.45 | P14: =L46+D57+I57+J57+0.5*H57 -> 187.12
G15: 2021 | H15: =B47+J47+K47+B58+C58 -> 6601.75 | I15: =F47 -> 2286.05 | J15: =C47*I31+G47+L47 -> 5125.9852 | K15: =J31*C47+D47+E47+H47 -> 20770.877 | L15: =I47+0.5*H58 -> 155.62 | M15: =H31*C47+M47 -> 37253.09 | N15: =O47+P47+G58+F58 -> 2255.95 | O15: =N47 -> 28.45 | P15: =L47+D58+I58+J58+0.5*H58 -> 226.83
G16: 2022 | H16: =B48+J48+K48+B59+C59 -> 6689.02 | I16: =F48 -> 2976.47 | J16: =C48*I32+G48+L48 -> 4489.0504 | K16: =J32*C48+D48+E48+H48 -> 17651.526 | L16: =I48+0.5*H59 -> 153.83 | M16: =H32*C48+M48 -> 47167.226 | N16: =O48+P48+G59+F59 -> 82913.54 | O16: =N48 -> 24.45 | P16: =L48+D59+I59+J59+0.5*H59 -> 312.88
A17: - onshore wind - offshore wind | C17: Wind PP | E17: 1,2
C18: Hybrid PP (1/2) | E18: 2 | G18: fraction steam PP from tab 'Generation'
A19: - hard coal - lignite | C19: Steam PP - coal | E19: 1 | H19: coal | I19: oil | J19: gas | K19: co-firing
C20: Coal gasification | E20: 1 | G20: 2010 | H20: 0.85808551 | I20: 0.12336875 | J20: 0.018545749 | K20: 0
A21: biomass | C21: Biogas PP | E21: 1,2 | G21: 2011 | H21: 0.88151309 | I21: 0.10239669 | J21: 0.016090221 | K21: 0
C22: Biomass PP | E22: 1,2 | G22: 2012 | H22: 0.90260488 | I22: 0.03238828 | J22: 0.065006841 | K22: 0
A23: Municipal Solid Waste | C23: Waste PP | E23: 1 | G23: 2013 | H23: 0.9186683 | I23: 0.012889432 | J23: 0.068442272 | K23: 0
A24: solar PV | C24: Solar PP | E24: 1 | G24: 2014 | H24: 0.9265098 | I24: 0.008432209 | J24: 0.065057992 | K24: 0
C25: Solar PP+PV | E25: 2 | G25: 2015 | H25: 0.88047253 | I25: 0.11801852 | J25: 0.0015089503 | K25: 0
C26: Solar Public Street Lighting | E26: 2 | G26: 2016 | H26: 0.94321304 | I26: 0.011113146 | J26: 0.045673811 | K26: 0
C27: Solar Energy Saving Lamp | E27: 2 | G27: 2017 | H27: 0.95798709 | I27: 0.0026943475 | J27: 0.039318566 | K27: 0
C28: Hybrid PP (1/2) | E28: 2 | G28: 2018 | H28: 0.96186122 | I28: 0.0045193098 | J28: 0.033619469 | K28: 0
G29: 2019 | H29: 0.96874595 | I29: 0.0010212683 | J29: 0.030232784 | K29: 0
G30: 2020 | H30: 0.98729888 | I30: 0.00029618531 | J30: 0.012309113 | K30: 9.5824658e-05
G31: 2021 | H31: 1.0058518 | I31: -0.0004288977 | J31: -0.0056145585 | K31: 0.00019164932
G32: 2022 | H32: 1.0244047 | I32: -0.0011539807 | J32: -0.02353823 | K32: 0.00028747397
A34: Table 1. On grid capacity | D34: (MW)
A35: Year | B35: Hydro PP | C35: Steam PP | D35: Gas PP | E35: Combined Cycle PP | F35: Geothermal PP | G35: Diesel PP | H35: Gas Engine PP | I35: Wind PP | J35: Micro Hydro PP | K35: Mini Hydro PP | L35: Solar PP | M35: Coal gasification | N35: Waste | O35: Biogas PP | P35: Biomas PP | Q35: Total
A36: 2010 | B36: 3719.69 | C36: 12981.5 | D36: 3821.57 | E36: 7590.32 | F36: 1189 | G36: 4569.89 | H36: 92.84 | I36: 0.34 | J36: 0.69 | K36: 13.53 | L36: 0.19 | M36: 0 | N36: 0 | O36: 0 | P36: 0 | Q36: 33979.56
A37: 2011 | B37: 3880.83 | C37: 16318 | D37: 4236.02 | E37: 8480.97 | F37: 1226 | G37: 5471.93 | H37: 169.54 | I37: 0.93 | J37: 5.93 | K37: 57.66 | L37: 1.16 | M37: 41 | N37: 26 | O37: 0 | P37: 0 | Q37: 39915.97
A38: 2012 | B38: 4078.24 | C38: 19714 | D38: 4343.82 | E38: 9461.11 | F38: 1336 | G38: 5973.58 | H38: 198.74 | I38: 0.93 | J38: 6.71 | K38: 61.46 | L38: 4.09 | M38: 41 | N38: 26 | O38: 0 | P38: 0 | Q38: 45245.67
A39: 2013 | B39: 5058.87 | C39: 23812.53 | D39: 4389.08 | E39: 9852.21 | F39: 1343.5 | G39: 5935 | H39: 448.12 | I39: 0.63 | J39: 29.69 | K39: 77.05 | L39: 9.02 | M39: 6 | N39: 26 | O39: 0 | P39: 0 | Q39: 50987.69
A40: 2014 | B40: 5059.06 | C40: 25104.23 | D40: 4310.5 | E40: 10146.11 | F40: 1403.5 | G40: 6206.99 | H40: 610.74 | I40: 1.12 | J40: 30.46 | K40: 139.87 | L40: 9.02 | M40: 6 | N40: 36 | O40: 0 | P40: 0 | Q40: 53063.6
A41: 2015 | B41: 5068.59 | C41: 26447.58 | D41: 4495.56 | E41: 10293.47 | F41: 1438.3 | G41: 3824.07 | H41: 1101.23 | I41: 1.46 | J41: 90.15 | K41: 148.71 | L41: 36.94 | M41: 0 | N41: 15.65 | O41: 54.72 | P41: 1671.29 | Q41: 54687.72
A42: 2016 | B42: 5343.59 | C42: 28351.97 | D42: 4969.24 | E42: 10293.47 | F42: 1533.3 | G42: 3979.4 | H42: 1806.99 | I42: 1.46 | J42: 95.87 | K42: 211.4 | L42: 46.7 | M42: 0 | N42: 15.65 | O42: 64.16 | P42: 1703.29 | Q42: 58416.48
...

Sheet Capacity Factor Calculation
A1: year | B1: hydro | C1: geothermal | D1: - petroleum - crude oil - heavy oil or residual fuel | E1: - natural gas peaker - natural gas non peaker | F1: - onshore wind - offshore wind | G1: - hard coal - lignite | H1: biomass | I1: Municipal Solid Waste | J1: solar PV | P1: Expected Capacity Factor (dimensionless) | Q1: 2020 | R1: 2021 | S1: 2022 | T1: 2023 | U1: 2024 | V1: 2025 | W1: 2026 | X1: 2027 | Y1: 2028 | Z1: 2029 | AA1: 2030 | AB1: 2031 | AC1: 2032 | AD1: 2033 | AE1: 2034 | AF1: 2035 | AG1: 2036 | AH1: 2037 | AI1: 2038 | AJ1: 2039 | AK1: 2040 | AL1: 2041 | AM1: 2042 | AN1: 2043 | AO1: 2044 | AP1: 2045 | AQ1: 2046 | AR1: 2047 | AS1: 2048 | AT1: 2049 | AU1: 2050
A2: 2010 | B2: =Generation!H4*1000/('Installed Capacity'!H4*24*365) -> 0.5336749 | C2: =Generation!I4*1000/('Installed Capacity'!I4*24*365) -> 0.89836054 | D2: =Generation!J4*1000/('Installed Capacity'!J4*24*365) -> 0.3515704 | E2: =Generation!K4*1000/('Installed Capacity'!K4*24*365) -> 0.53833584 | F2: =Generation!L4*1000/('Installed Capacity'!L4*24*365) -> 1.343003 | G2: =Generation!M4*1000/('Installed Capacity'!M4*24*365) -> 0.70175445 | H2: 0 | I2: 0 | J2: =Generation!P4*1000/('Installed Capacity'!P4*24*365) -> 0.60081711 | P2: hard coal | Q2: =M50 -> 0.67782537 | R2: =N50 -> 0.67966571 | S2: =O50 -> 0.68132094 | T2: =P50 -> 0.68281765 | U2: =Q50 -> 0.68417758 | V2: =R50 -> 0.68541866 | W2: =S50 -> 0.68655581 | X2: =T50 -> 0.68760156 | ... AU2: =AQ50 -> 0.69959863
A3: 2011 | B3: =Generation!H5*1000/('Installed Capacity'!H5*24*365) -> 0.35941762 | C3: =Generation!I5*1000/('Installed Capacity'!I5*24*365) -> 0.87255209 | D3: =Generation!J5*1000/('Installed Capacity'!J5*24*365) -> 0.3652521 | E3: =Generation!K5*1000/('Installed Capacity'!K5*24*365) -> 0.49883653 | F3: =Generation!L5*1000/('Installed Capacity'!L5*24*365) -> 0.61373791 | G3: =Generation!M5*1000/('Installed Capacity'!M5*24*365) -> 0.64169905 | H3: 0 | I3: =Generation!O5*1000/('Installed Capacity'!O5*24*365) -> 0.13610818 | J3: =Generation!P5*1000/('Installed Capacity'!P5*24*365) -> 0.098409699 | P3: natural gas nonpeaker | Q3: =M49 -> 0.4633427 | R3: =N49 -> 0.4723013 | S3: =O49 -> 0.48090541 | T3: =P49 -> 0.48917565 | U3: =Q49 -> 0.49713109 | V3: =R49 -> 0.50478937 | W3: =S49 -> 0.51216683 | X3: =T49 -> 0.51927864 | ... AU3: =AQ49 -> 0.63286829
A4: 2012 | B4: =Generation!H6*1000/('Installed Capacity'!H6*24*365) -> 0.35237062 | C4: =Generation!I6*1000/('Installed Capacity'!I6*24*365) -> 0.80464072 | D4: =Generation!J6*1000/('Installed Capacity'!J6*24*365) -> 0.37239246 | E4: =Generation!K6*1000/('Installed Capacity'!K6*24*365) -> 0.40386642 | F4: =Generation!L6*1000/('Installed Capacity'!L6*24*365) -> 0.61373791 | G4: =Generation!M6*1000/('Installed Capacity'!M6*24*365) -> 0.65392859 | H4: 0 | I4: =Generation!O6*1000/('Installed Capacity'!O6*24*365) -> 0.23270109 | J4: =Generation!P6*1000/('Installed Capacity'!P6*24*365) -> 0.083732458 | P4: nuclear | Q4: =Q3 -> 0.4633427 | R4: =R3 -> 0.4723013 | S4: =S3 -> 0.48090541 | T4: =T3 -> 0.48917565 | U4: =U3 -> 0.49713109 | V4: =V3 -> 0.50478937 | W4: =W3 -> 0.51216683 | X4: =X3 -> 0.51927864 | ... AU4: =AU3 -> 0.63286829
A5: 2013 | B5: =Generation!H7*1000/('Installed Capacity'!H7*24*365) -> 0.3739828 | C5: =Generation!I7*1000/('Installed Capacity'!I7*24*365) -> 0.79989396 | D5: =Generation!J7*1000/('Installed Capacity'!J7*24*365) -> 0.37185216 | E5: =Generation!K7*1000/('Installed Capacity'!K7*24*365) -> 0.40606721 | F5: =Generation!L7*1000/('Installed Capacity'!L7*24*365) -> 0 | G5: =Generation!M7*1000/('Installed Capacity'!M7*24*365) -> 0.58039058 | H5: 0 | I5: =Generation!O7*1000/('Installed Capacity'!O7*24*365) -> 0.18001405 | J5: =Generation!P7*1000/('Installed Capacity'!P7*24*365) -> 0.063278964 | P5: hydro | Q5: =M44 -> 0.42471074 | R5: =N44 -> 0.42670007 | S5: =O44 -> 0.42857965 | T5: =P44 -> 0.43035832 | U5: =Q44 -> 0.432044 | V5: =R44 -> 0.43364379 | W5: =S44 -> 0.4351641 | X5: =T44 -> 0.4366107 | ... AU5: =AQ44 -> 0.45745483
A6: 2014 | B6: =Generation!H8*1000/('Installed Capacity'!H8*24*365) -> 0.3309797 | C6: =Generation!I8*1000/('Installed Capacity'!I8*24*365) -> 0.81645202 | D6: =Generation!J8*1000/('Installed Capacity'!J8*24*365) -> 0.4091705 | E6: =Generation!K8*1000/('Installed Capacity'!K8*24*365) -> 0.41379566 | F6: =Generation!L8*1000/('Installed Capacity'!L8*24*365) -> 0 | G6: =Generation!M8*1000/('Installed Capacity'!M8*24*365) -> 0.58650422 | H6: 0 | I6: =Generation!O8*1000/('Installed Capacity'!O8*24*365) -> 0.11415525 | J6: =Generation!P8*1000/('Installed Capacity'!P8*24*365) -> 0.08859055 | P6: onshore wind | Q6: =M48 -> 0.19089507 | R6: =N48 -> 0.19048076 | S6: =O48 -> 0.19016033 | T6: =P48 -> 0.18990511 | U6: =Q48 -> 0.18969704 | V6: =R48 -> 0.18952416 | W6: =S48 -> 0.18937824 | X6: =T48 -> 0.18925342 | ... AU6: =AQ48 -> 0.18825354
A7: 2015 | B7: =Generation!H9*1000/('Installed Capacity'!H9*24*365) -> 0.2955482 | C7: =Generation!I9*1000/('Installed Capacity'!I9*24*365) -> 0.79749146 | D7: =Generation!J9*1000/('Installed Capacity'!J9*24*365) -> 0.50537012 | E7: =Generation!K9*1000/('Installed Capacity'!K9*24*365) -> 0.38794318 | F7: =Generation!L9*1000/('Installed Capacity'!L9*24*365) -> 0.31275411 | G7: =Generation!M9*1000/('Installed Capacity'!M9*24*365) -> 0.61109793 | H7: =Generation!N9*1000/('Installed Capacity'!N9*24*365) -> 0.030489725 | I7: =Generation!O9*1000/('Installed Capacity'!O9*24*365) -> 0.13859104 | J7: =Generation!P9*1000/('Installed Capacity'!P9*24*365) -> 0.015451442 | P7: solar PV | Q7: =M47 -> 0.081335616 | R7: =N47 -> 0.079500978 | S7: =O47 -> 0.078021432 | T7: =P47 -> 0.076802981 | U7: =Q47 -> 0.075782118 | V7: =R47 -> 0.074914384 | W7: =S47 -> 0.074167729 | X7: =T47 -> 0.073518463 | ... AU7: =AQ47 -> 0.067934783
A8: 2016 | B8: =Generation!H10*1000/('Installed Capacity'!H10*24*365) -> 0.37730144 | C8: =Generation!I10*1000/('Installed Capacity'!I10*24*365) -> 0.79334661 | D8: =Generation!J10*1000/('Installed Capacity'!J10*24*365) -> 0.54695485 | E8: =Generation!K10*1000/('Installed Capacity'!K10*24*365) -> 0.38408193 | F8: =Generation!L10*1000/('Installed Capacity'!L10*24*365) -> 0.46913117 | G8: =Generation!M10*1000/('Installed Capacity'!M10*24*365) -> 0.57791048 | H8: =Generation!N10*1000/('Installed Capacity'!N10*24*365) -> 0.037719125 | I8: =Generation!O10*1000/('Installed Capacity'!O10*24*365) -> 0.043765591 | J8: =Generation!P10*1000/('Installed Capacity'!P10*24*365) -> 0.051333196 | P8: solar thermal | Q8: =Q7 -> 0.081335616 | R8: =R7 -> 0.079500978 | S8: =S7 -> 0.078021432 | T8: =T7 -> 0.076802981 | U8: =U7 -> 0.075782118 | V8: =V7 -> 0.074914384 | W8: =W7 -> 0.074167729 | X8: =X7 -> 0.073518463 | ... AU8: =AU7 -> 0.067934783
A9: 2017 | B9: =Generation!H11*1000/('Installed Capacity'!H11*24*365) -> 0.37394129 | C9: =Generation!I11*1000/('Installed Capacity'!I11*24*365) -> 0.80577207 | D9: =Generation!J11*1000/('Installed Capacity'!J11*24*365) -> 0.47457573 | E9: =Generation!K11*1000/('Installed Capacity'!K11*24*365) -> 0.33775873 | F9: =Generation!L11*1000/('Installed Capacity'!L11*24*365) -> 0 | G9: =Generation!M11*1000/('Installed Capacity'!M11*24*365) -> 0.57304938 | H9: =Generation!N11*1000/('Installed Capacity'!N11*24*365) -> 0 | I9: =Generation!O11*1000/('Installed Capacity'!O11*24*365) -> 4.3036165 | J9: =Generation!P11*1000/('Installed Capacity'!P11*24*365) -> 0.06076546 | P9: biomass | Q9: =M46 -> 0.4468599 | R9: =N46 -> 0.44087343 | S9: =O46 -> 0.43612554 | T9: =P46 -> 0.43226788 | U9: =Q46 -> 0.42907154 | V9: =R46 -> 0.42637988 | W9: =S46 -> 0.42408212 | X9: =T46 -> 0.42209769 | ... AU9: =AQ46 -> 0.40553737
A10: 2018 | B10: =Generation!H12*1000/('Installed Capacity'!H12*24*365) -> 0.42787579 | C10: =Generation!I12*1000/('Installed Capacity'!I12*24*365) -> 0.82140454 | D10: =Generation!J12*1000/('Installed Capacity'!J12*24*365) -> 0.42696943 | E10: =Generation!K12*1000/('Installed Capacity'!K12*24*365) -> 0.32809061 | F10: =Generation!L12*1000/('Installed Capacity'!L12*24*365) -> 0.1517393 | G10: =Generation!M12*1000/('Installed Capacity'!M12*24*365) -> 0.60121254 | H10: =Generation!N12*1000/('Installed Capacity'!N12*24*365) -> 0.72162088 | I10: =Generation!O12*1000/('Installed Capacity'!O12*24*365) -> 4.537033 | J10: =Generation!P12*1000/('Installed Capacity'!P12*24*365) -> 0.1586904 | P10: geothermal | Q10: =M45 -> 0.70817828 | R10: =N45 -> 0.69515389 | S10: =O45 -> 0.68357368 | T10: =P45 -> 0.67321008 | U10: =Q45 -> 0.66388093 | V10: =R45 -> 0.65543871 | W10: =S45 -> 0.64776267 | X10: =T45 -> 0.64075305 | ... AU10: =AQ45 -> 0.56357967
A11: 2019 | B11: =Generation!H13*1000/('Installed Capacity'!H13*24*365) -> 0.40422141 | C11: =Generation!I13*1000/('Installed Capacity'!I13*24*365) -> 0.75542734 | D11: =Generation!J13*1000/('Installed Capacity'!J13*24*365) -> 0.24551732 | E11: =Generation!K13*1000/('Installed Capacity'!K13*24*365) -> 0.3402207 | F11: =Generation!L13*1000/('Installed Capacity'!L13*24*365) -> 0.3568727 | G11: =Generation!M13*1000/('Installed Capacity'!M13*24*365) -> 0.59192894 | H11: =Generation!N13*1000/('Installed Capacity'!N13*24*365) -> 0.74032505 | I11: =Generation!O13*1000/('Installed Capacity'!O13*24*365) -> 0.15317957 | J11: =Generation!P13*1000/('Installed Capacity'!P13*24*365) -> 0.087710947 | P11: petroleum | Q11: =M51 -> 0.083496072 | R11: =N51 -> 0.031828746 | S11: =O51 -> 0.031790414 | T11: =P51 -> 0.031752173 | U11: =Q51 -> 0.031714025 | V11: =R51 -> 0.031675968 | W11: =S51 -> 0.031638003 | X11: =T51 -> 0.031600128 | ... AU11: =AQ51 -> 0.030753367
A12: 2020 | B12: =Generation!H14*1000/('Installed Capacity'!H14*24*365) -> 0.45556396 | C12: =Generation!I14*1000/('Installed Capacity'!I14*24*365) -> 0.83380963 | D12: =Generation!J14*1000/('Installed Capacity'!J14*24*365) -> 0.1544839 | E12: =Generation!K14*1000/('Installed Capacity'!K14*24*365) -> 0.27592961 | F12: =Generation!L14*1000/('Installed Capacity'!L14*24*365) -> 0.35027074 | G12: =Generation!M14*1000/('Installed Capacity'!M14*24*365) -> 0.57036417 | H12: =Generation!N14*1000/('Installed Capacity'!N14*24*365) -> 0.74936225 | I12: =Generation!O14*1000/('Installed Capacity'!O14*24*365) -> 0.11797199 | J12: =Generation!P14*1000/('Installed Capacity'!P14*24*365) -> 0.10584617 | P12: natural gas peaker | Q12: =Q3 -> 0.4633427 | R12: =R3 -> 0.4723013 | S12: =S3 -> 0.48090541 | T12: =T3 -> 0.48917565 | U12: =U3 -> 0.49713109 | V12: =V3 -> 0.50478937 | W12: =W3 -> 0.51216683 | X12: =X3 -> 0.51927864 | ... AU12: =AU3 -> 0.63286829
A13: 2021 | B13: =Generation!H15*1000/('Installed Capacity'!H15*24*365) -> 0.42705226 | C13: =Generation!I15*1000/('Installed Capacity'!I15*24*365) -> 0.79237791 | D13: =Generation!J15*1000/('Installed Capacity'!J15*24*365) -> 0.14805039 | E13: =Generation!K15*1000/('Installed Capacity'!K15*24*365) -> 0.30675524 | F13: =Generation!L15*1000/('Installed Capacity'!L15*24*365) -> 0.32239579 | G13: =Generation!M15*1000/('Installed Capacity'!M15*24*365) -> 0.58293103 | H13: =Generation!N15*1000/('Installed Capacity'!N15*24*365) -> 0.75725674 | I13: =Generation!O15*1000/('Installed Capacity'!O15*24*365) -> 0.044137355 | J13: =Generation!P15*1000/('Installed Capacity'!P15*24*365) -> 0.098196767 | P13: lignite | Q13: =Q2 -> 0.67782537 | R13: =R2 -> 0.67966571 | S13: =S2 -> 0.68132094 | T13: =T2 -> 0.68281765 | U13: =U2 -> 0.68417758 | V13: =V2 -> 0.68541866 | W13: =W2 -> 0.68655581 | X13: =X2 -> 0.68760156 | ... AU13: =AU2 -> 0.69959863
A14: 2022 | B14: =Generation!H16*1000/('Installed Capacity'!H16*24*365) -> 0.46581825 | C14: =Generation!I16*1000/('Installed Capacity'!I16*24*365) -> 0.63960568 | D14: =Generation!J16*1000/('Installed Capacity'!J16*24*365) -> 0.1548415 | E14: =Generation!K16*1000/('Installed Capacity'!K16*24*365) -> 0.36297585 | F14: =Generation!L16*1000/('Installed Capacity'!L16*24*365) -> 0.26418299 | G14: =Generation!M16*1000/('Installed Capacity'!M16*24*365) -> 0.49834106 | H14: =Generation!N16*1000/('Installed Capacity'!N16*24*365) -> 0.028360676 | I14: =Generation!O16*1000/('Installed Capacity'!O16*24*365) -> 0.20543276 | J14: =Generation!P16*1000/('Installed Capacity'!P16*24*365) -> 0.16189628 | P14: offshore wind | Q14: =Q6 -> 0.19089507 | R14: =R6 -> 0.19048076 | S14: =S6 -> 0.19016033 | T14: =T6 -> 0.18990511 | U14: =U6 -> 0.18969704 | V14: =V6 -> 0.18952416 | W14: =W6 -> 0.18937824 | X14: =X6 -> 0.18925342 | ... AU14: =AU6 -> 0.18825354
P15: crude oil | Q15: =Q11 -> 0.083496072 | R15: =R11 -> 0.031828746 | S15: =S11 -> 0.031790414 | T15: =T11 -> 0.031752173 | U15: =U11 -> 0.031714025 | V15: =V11 -> 0.031675968 | W15: =W11 -> 0.031638003 | X15: =X11 -> 0.031600128 | ... AU15: =AU11 -> 0.030753367
P16: heavy or residual fuel oil | Q16: =Q15 -> 0.083496072 | R16: =R15 -> 0.031828746 | S16: =S15 -> 0.031790414 | T16: =T15 -> 0.031752173 | U16: =U15 -> 0.031714025 | V16: =V15 -> 0.031675968 | W16: =W15 -> 0.031638003 | X16: =X15 -> 0.031600128 | ... AU16: =AU15 -> 0.030753367
P17: municipal solid waste | Q17: =Q9 -> 0.4468599 | R17: =R9 -> 0.44087343 | S17: =S9 -> 0.43612554 | T17: =T9 -> 0.43226788 | U17: =U9 -> 0.42907154 | V17: =V9 -> 0.42637988 | W17: =W9 -> 0.42408212 | X17: =X9 -> 0.42209769 | ... AU17: =AU9 -> 0.40553737
A20: LEAP | C20: Year | D20: 2011 | E20: 2012 | F20: 2013 | G20: 2014 | H20: 2015 | I20: 2016 | J20: 2017 | K20: 2018 | L20: 2019 | M20: 2020 | N20: 2021 | O20: 2022 | P20: 2023 | Q20: 2024 | R20: 2025 | S20: 2026 | T20: 2027 | U20: 2028 | V20: 2029 | W20: 2030 | X20: 2031 | Y20: 2032 | Z20: 2033 | AA20: 2034 | AB20: 2035 | AC20: 2036 | AD20: 2037 | AE20: 2038 | AF20: 2039 | AG20: 2040 | AH20: 2041 | AI20: 2042 | AJ20: 2043 | AK20: 2044 | AL20: 2045 | AM20: 2046 | AN20: 2047 | AO20: 2048 | AP20: 2049 | AQ20: 2050
C21: Hydro | D21: 12400 | E21: 12800 | F21: 16900 | G21: 15200 | H21: 13700 | I21: 19400 | J21: 18600 | K21: 16900 | L21: 17200 | M21: =_xlfn.FORECAST.LINEAR(M$20,$D21:$L21,$D$20:$L$20) -> 19158.333 | N21: =_xlfn.FORECAST.LINEAR(N$20,$D21:$L21,$D$20:$L$20) -> 19810 | O21: =_xlfn.FORECAST.LINEAR(O$20,$D21:$L21,$D$20:$L$20) -> 20461.667 | P21: =_xlfn.FORECAST.LINEAR(P$20,$D21:$L21,$D$20:$L$20) -> 21113.333 | Q21: =_xlfn.FORECAST.LINEAR(Q$20,$D21:$L21,$D$20:$L$20) -> 21765 | R21: =_xlfn.FORECAST.LINEAR(R$20,$D21:$L21,$D$20:$L$20) -> 22416.667 | S21: =_xlfn.FORECAST.LINEAR(S$20,$D21:$L21,$D$20:$L$20) -> 23068.333 | T21: =_xlfn.FORECAST.LINEAR(T$20,$D21:$L21,$D$20:$L$20) -> 23720 | ... AQ21: =_xlfn.FORECAST.LINEAR(AQ$20,$D21:$L21,$D$20:$L$20) -> 38708.333
C22: Geothermal | D22: 9370 | E22: 9420 | F22: 9410 | G22: 10000 | H22: 10100 | I22: 10700 | J22: 12700 | K22: 12600 | L22: 14100 | M22: =_xlfn.FORECAST.LINEAR(M$20,$D22:$L22,$D$20:$L$20) -> 13911.667 | N22: =_xlfn.FORECAST.LINEAR(N$20,$D22:$L22,$D$20:$L$20) -> 14507.333 | O22: =_xlfn.FORECAST.LINEAR(O$20,$D22:$L22,$D$20:$L$20) -> 15103 | P22: =_xlfn.FORECAST.LINEAR(P$20,$D22:$L22,$D$20:$L$20) -> 15698.667 | Q22: =_xlfn.FORECAST.LINEAR(Q$20,$D22:$L22,$D$20:$L$20) -> 16294.333 | R22: =_xlfn.FORECAST.LINEAR(R$20,$D22:$L22,$D$20:$L$20) -> 16890 | S22: =_xlfn.FORECAST.LINEAR(S$20,$D22:$L22,$D$20:$L$20) -> 17485.667 | T22: =_xlfn.FORECAST.LINEAR(T$20,$D22:$L22,$D$20:$L$20) -> 18081.333 | ... AQ22: =_xlfn.FORECAST.LINEAR(AQ$20,$D22:$L22,$D$20:$L$20) -> 31781.667
C23: Biomass | D23: 0 | E23: 0 | F23: 0 | G23: 210 | H23: 440 | I23: 580 | J23: 590 | K23: 520 | L23: 520 | M23: =_xlfn.FORECAST.LINEAR(M$20,$D23:$L23,$D$20:$L$20) -> 750.27778 | N23: =_xlfn.FORECAST.LINEAR(N$20,$D23:$L23,$D$20:$L$20) -> 836.77778 | O23: =_xlfn.FORECAST.LINEAR(O$20,$D23:$L23,$D$20:$L$20) -> 923.27778 | P23: =_xlfn.FORECAST.LINEAR(P$20,$D23:$L23,$D$20:$L$20) -> 1009.7778 | Q23: =_xlfn.FORECAST.LINEAR(Q$20,$D23:$L23,$D$20:$L$20) -> 1096.2778 | R23: =_xlfn.FORECAST.LINEAR(R$20,$D23:$L23,$D$20:$L$20) -> 1182.7778 | S23: =_xlfn.FORECAST.LINEAR(S$20,$D23:$L23,$D$20:$L$20) -> 1269.2778 | T23: =_xlfn.FORECAST.LINEAR(T$20,$D23:$L23,$D$20:$L$20) -> 1355.7778 | ... AQ23: =_xlfn.FORECAST.LINEAR(AQ$20,$D23:$L23,$D$20:$L$20) -> 3345.2778
C24: Solar PV | D24: 0 | E24: 0 | F24: 0 | G24: 40 | H24: 20 | I24: 20 | J24: 30 | K24: 20 | L24: 20 | M24: =_xlfn.FORECAST.LINEAR(M$20,$D24:$L24,$D$20:$L$20) -> 31.666667 | N24: =_xlfn.FORECAST.LINEAR(N$20,$D24:$L24,$D$20:$L$20) -> 34.666667 | O24: =_xlfn.FORECAST.LINEAR(O$20,$D24:$L24,$D$20:$L$20) -> 37.666667 | P24: =_xlfn.FORECAST.LINEAR(P$20,$D24:$L24,$D$20:$L$20) -> 40.666667 | Q24: =_xlfn.FORECAST.LINEAR(Q$20,$D24:$L24,$D$20:$L$20) -> 43.666667 | R24: =_xlfn.FORECAST.LINEAR(R$20,$D24:$L24,$D$20:$L$20) -> 46.666667 | S24: =_xlfn.FORECAST.LINEAR(S$20,$D24:$L24,$D$20:$L$20) -> 49.666667 | T24: =_xlfn.FORECAST.LINEAR(T$20,$D24:$L24,$D$20:$L$20) -> 52.666667 | ... AQ24: =_xlfn.FORECAST.LINEAR(AQ$20,$D24:$L24,$D$20:$L$20) -> 121.66667
C25: Wind | D25: 0 | E25: 0 | F25: 0 | G25: 0 | H25: 0 | I25: 10 | J25: 0 | K25: 170 | L25: 170 | M25: =_xlfn.FORECAST.LINEAR(M$20,$D25:$L25,$D$20:$L$20) -> 138.88889 | N25: =_xlfn.FORECAST.LINEAR(N$20,$D25:$L25,$D$20:$L$20) -> 158.88889 | O25: =_xlfn.FORECAST.LINEAR(O$20,$D25:$L25,$D$20:$L$20) -> 178.88889 | P25: =_xlfn.FORECAST.LINEAR(P$20,$D25:$L25,$D$20:$L$20) -> 198.88889 | Q25: =_xlfn.FORECAST.LINEAR(Q$20,$D25:$L25,$D$20:$L$20) -> 218.88889 | R25: =_xlfn.FORECAST.LINEAR(R$20,$D25:$L25,$D$20:$L$20) -> 238.88889 | S25: =_xlfn.FORECAST.LINEAR(S$20,$D25:$L25,$D$20:$L$20) -> 258.88889 | T25: =_xlfn.FORECAST.LINEAR(T$20,$D25:$L25,$D$20:$L$20) -> 278.88889 | ... AQ25: =_xlfn.FORECAST.LINEAR(AQ$20,$D25:$L25,$D$20:$L$20) -> 738.88889
C26: Natural Gas | D26: 36600 | E26: 45300 | F26: 50300 | G26: 54500 | H26: 57700 | I26: 65300 | J26: 59400 | K26: 59400 | L26: 59900 | M26: =_xlfn.FORECAST.LINEAR(M$20,$D26:$L26,$D$20:$L$20) -> 67975 | N26: =_xlfn.FORECAST.LINEAR(N$20,$D26:$L26,$D$20:$L$20) -> 70716.667 | O26: =_xlfn.FORECAST.LINEAR(O$20,$D26:$L26,$D$20:$L$20) -> 73458.333 | P26: =_xlfn.FORECAST.LINEAR(P$20,$D26:$L26,$D$20:$L$20) -> 76200 | Q26: =_xlfn.FORECAST.LINEAR(Q$20,$D26:$L26,$D$20:$L$20) -> 78941.667 | R26: =_xlfn.FORECAST.LINEAR(R$20,$D26:$L26,$D$20:$L$20) -> 81683.333 | S26: =_xlfn.FORECAST.LINEAR(S$20,$D26:$L26,$D$20:$L$20) -> 84425 | T26: =_xlfn.FORECAST.LINEAR(T$20,$D26:$L26,$D$20:$L$20) -> 87166.667 | ... AQ26: =_xlfn.FORECAST.LINEAR(AQ$20,$D26:$L26,$D$20:$L$20) -> 150225
C27: Coal | D27: 77700 | E27: 101000 | F27: 110000 | G27: 120000 | H27: 130000 | I27: 134000 | J27: 148000 | K27: 161000 | L27: 170000 | M27: =_xlfn.FORECAST.LINEAR(M$20,$D27:$L27,$D$20:$L$20) -> 181233.33 | N27: =_xlfn.FORECAST.LINEAR(N$20,$D27:$L27,$D$20:$L$20) -> 191886.67 | O27: =_xlfn.FORECAST.LINEAR(O$20,$D27:$L27,$D$20:$L$20) -> 202540 | P27: =_xlfn.FORECAST.LINEAR(P$20,$D27:$L27,$D$20:$L$20) -> 213193.33 | Q27: =_xlfn.FORECAST.LINEAR(Q$20,$D27:$L27,$D$20:$L$20) -> 223846.67 | R27: =_xlfn.FORECAST.LINEAR(R$20,$D27:$L27,$D$20:$L$20) -> 234500 | S27: =_xlfn.FORECAST.LINEAR(S$20,$D27:$L27,$D$20:$L$20) -> 245153.33 | T27: =_xlfn.FORECAST.LINEAR(T$20,$D27:$L27,$D$20:$L$20) -> 255806.67 | ... AQ27: =_xlfn.FORECAST.LINEAR(AQ$20,$D27:$L27,$D$20:$L$20) -> 500833.33
C28: Oil | D28: 42200 | E28: 29900 | F28: 26700 | G28: 25900 | H28: 19200 | I28: 16100 | J28: 14300 | K28: 15200 | L28: 11300 | M28: =_xlfn.FORECAST.LINEAR(M$20,$D28:$L28,$D$20:$L$20) -> 5452.7778 | N28: =_xlfn.FORECAST.LINEAR(N$20,$D28:$L28,$D$20:$L$20) -> 2081.1111 | O28: =N28 -> 2081.1111 | P28: =O28 -> 2081.1111 | Q28: =P28 -> 2081.1111 | R28: =Q28 -> 2081.1111 | S28: =R28 -> 2081.1111 | T28: =S28 -> 2081.1111 | U28: =T28 -> 2081.1111 | V28: =U28 -> 2081.1111 | ... AQ28: =AP28 -> 2081.1111
A30: LEAP | C30: Year | D30: 2011 | E30: 2012 | F30: 2013 | G30: 2014 | H30: 2015 | I30: 2016 | J30: 2017 | K30: 2018 | L30: 2019 | M30: 2020 | N30: 2021 | O30: 2022 | P30: 2023 | Q30: 2024 | R30: 2025 | S30: 2026 | T30: 2027 | U30: 2028 | V30: 2029 | W30: 2030 | X30: 2031 | Y30: 2032 | Z30: 2033 | AA30: 2034 | AB30: 2035 | AC30: 2036 | AD30: 2037 | AE30: 2038 | AF30: 2039 | AG30: 2040 | AH30: 2041 | AI30: 2042 | AJ30: 2043 | AK30: 2044 | AL30: 2045 | AM30: 2046 | AN30: 2047 | AO30: 2048 | AP30: 2049 | AQ30: 2050
C31: Hydro | D31: 3920 | E31: 3940 | F31: 4090 | G31: 4160 | H31: 4290 | I31: 4400 | J31: 4860 | K31: 4940 | L31: 4980 | M31: =_xlfn.FORECAST.LINEAR(M$30,$D31:$L31,$D$30:$L$30) -> 5149.4444 | N31: =_xlfn.FORECAST.LINEAR(N$30,$D31:$L31,$D$30:$L$30) -> 5299.7778 | O31: =_xlfn.FORECAST.LINEAR(O$30,$D31:$L31,$D$30:$L$30) -> 5450.1111 | P31: =_xlfn.FORECAST.LINEAR(P$30,$D31:$L31,$D$30:$L$30) -> 5600.4444 | Q31: =_xlfn.FORECAST.LINEAR(Q$30,$D31:$L31,$D$30:$L$30) -> 5750.7778 | R31: =_xlfn.FORECAST.LINEAR(R$30,$D31:$L31,$D$30:$L$30) -> 5901.1111 | S31: =_xlfn.FORECAST.LINEAR(S$30,$D31:$L31,$D$30:$L$30) -> 6051.4444 | T31: =_xlfn.FORECAST.LINEAR(T$30,$D31:$L31,$D$30:$L$30) -> 6201.7778 | ... AQ31: =_xlfn.FORECAST.LINEAR(AQ$30,$D31:$L31,$D$30:$L$30) -> 9659.4444
C32: Geothermal | D32: 1150 | E32: 1220 | F32: 1260 | G32: 1320 | H32: 1310 | I32: 1370 | J32: 2100 | K32: 1720 | L32: 2440 | M32: =_xlfn.FORECAST.LINEAR(M$30,$D32:$L32,$D$30:$L$30) -> 2242.5 | N32: =_xlfn.FORECAST.LINEAR(N$30,$D32:$L32,$D$30:$L$30) -> 2382.3333 | O32: =_xlfn.FORECAST.LINEAR(O$30,$D32:$L32,$D$30:$L$30) -> 2522.1667 | P32: =_xlfn.FORECAST.LINEAR(P$30,$D32:$L32,$D$30:$L$30) -> 2662 | Q32: =_xlfn.FORECAST.LINEAR(Q$30,$D32:$L32,$D$30:$L$30) -> 2801.8333 | R32: =_xlfn.FORECAST.LINEAR(R$30,$D32:$L32,$D$30:$L$30) -> 2941.6667 | S32: =_xlfn.FORECAST.LINEAR(S$30,$D32:$L32,$D$30:$L$30) -> 3081.5 | T32: =_xlfn.FORECAST.LINEAR(T$30,$D32:$L32,$D$30:$L$30) -> 3221.3333 | ... AQ32: =_xlfn.FORECAST.LINEAR(AQ$30,$D32:$L32,$D$30:$L$30) -> 6437.5
C33: Biomass | D33: 0 | E33: 0 | F33: 0 | G33: 30 | H33: 40 | I33: 40 | J33: 150 | K33: 170 | L33: 170 | M33: =_xlfn.FORECAST.LINEAR(M$30,$D33:$L33,$D$30:$L$30) -> 191.66667 | N33: =_xlfn.FORECAST.LINEAR(N$30,$D33:$L33,$D$30:$L$30) -> 216.66667 | O33: =_xlfn.FORECAST.LINEAR(O$30,$D33:$L33,$D$30:$L$30) -> 241.66667 | P33: =_xlfn.FORECAST.LINEAR(P$30,$D33:$L33,$D$30:$L$30) -> 266.66667 | Q33: =_xlfn.FORECAST.LINEAR(Q$30,$D33:$L33,$D$30:$L$30) -> 291.66667 | R33: =_xlfn.FORECAST.LINEAR(R$30,$D33:$L33,$D$30:$L$30) -> 316.66667 | S33: =_xlfn.FORECAST.LINEAR(S$30,$D33:$L33,$D$30:$L$30) -> 341.66667 | T33: =_xlfn.FORECAST.LINEAR(T$30,$D33:$L33,$D$30:$L$30) -> 366.66667 | ... AQ33: =_xlfn.FORECAST.LINEAR(AQ$30,$D33:$L33,$D$30:$L$30) -> 941.66667
C34: Solar PV | D34: 0 | E34: 10 | F34: 10 | G34: 10 | H34: 10 | I34: 10 | J34: 20 | K34: 30 | L34: 60 | M34: =_xlfn.FORECAST.LINEAR(M$30,$D34:$L34,$D$30:$L$30) -> 44.444444 | N34: =_xlfn.FORECAST.LINEAR(N$30,$D34:$L34,$D$30:$L$30) -> 49.777778 | O34: =_xlfn.FORECAST.LINEAR(O$30,$D34:$L34,$D$30:$L$30) -> 55.111111 | P34: =_xlfn.FORECAST.LINEAR(P$30,$D34:$L34,$D$30:$L$30) -> 60.444444 | Q34: =_xlfn.FORECAST.LINEAR(Q$30,$D34:$L34,$D$30:$L$30) -> 65.777778 | R34: =_xlfn.FORECAST.LINEAR(R$30,$D34:$L34,$D$30:$L$30) -> 71.111111 | S34: =_xlfn.FORECAST.LINEAR(S$30,$D34:$L34,$D$30:$L$30) -> 76.444444 | T34: =_xlfn.FORECAST.LINEAR(T$30,$D34:$L34,$D$30:$L$30) -> 81.777778 | ... AQ34: =_xlfn.FORECAST.LINEAR(AQ$30,$D34:$L34,$D$30:$L$30) -> 204.44444
C35: Wind | D35: 0 | E35: 0 | F35: 0 | G35: 0 | H35: 0 | I35: 0 | J35: 0 | K35: 70 | L35: 130 | M35: =_xlfn.FORECAST.LINEAR(M$30,$D35:$L35,$D$30:$L$30) -> 83.055556 | N35: =_xlfn.FORECAST.LINEAR(N$30,$D35:$L35,$D$30:$L$30) -> 95.222222 | O35: =_xlfn.FORECAST.LINEAR(O$30,$D35:$L35,$D$30:$L$30) -> 107.38889 | P35: =_xlfn.FORECAST.LINEAR(P$30,$D35:$L35,$D$30:$L$30) -> 119.55556 | Q35: =_xlfn.FORECAST.LINEAR(Q$30,$D35:$L35,$D$30:$L$30) -> 131.72222 | R35: =_xlfn.FORECAST.LINEAR(R$30,$D35:$L35,$D$30:$L$30) -> 143.88889 | S35: =_xlfn.FORECAST.LINEAR(S$30,$D35:$L35,$D$30:$L$30) -> 156.05556 | T35: =_xlfn.FORECAST.LINEAR(T$30,$D35:$L35,$D$30:$L$30) -> 168.22222 | ... AQ35: =_xlfn.FORECAST.LINEAR(AQ$30,$D35:$L35,$D$30:$L$30) -> 448.05556
C36: Natural Gas | D36: 13000 | E36: 14500 | F36: 14700 | G36: 14800 | H36: 15100 | I36: 15800 | J36: 14700 | K36: 15200 | L36: 17400 | M36: =_xlfn.FORECAST.LINEAR(M$30,$D36:$L36,$D$30:$L$30) -> 16747.222 | N36: =_xlfn.FORECAST.LINEAR(N$30,$D36:$L36,$D$30:$L$30) -> 17092.222 | O36: =_xlfn.FORECAST.LINEAR(O$30,$D36:$L36,$D$30:$L$30) -> 17437.222 | P36: =_xlfn.FORECAST.LINEAR(P$30,$D36:$L36,$D$30:$L$30) -> 17782.222 | Q36: =_xlfn.FORECAST.LINEAR(Q$30,$D36:$L36,$D$30:$L$30) -> 18127.222 | R36: =_xlfn.FORECAST.LINEAR(R$30,$D36:$L36,$D$30:$L$30) -> 18472.222 | S36: =_xlfn.FORECAST.LINEAR(S$30,$D36:$L36,$D$30:$L$30) -> 18817.222 | T36: =_xlfn.FORECAST.LINEAR(T$30,$D36:$L36,$D$30:$L$30) -> 19162.222 | ... AQ36: =_xlfn.FORECAST.LINEAR(AQ$30,$D36:$L36,$D$30:$L$30) -> 27097.222
C37: Coal | D37: 14800 | E37: 17500 | F37: 18700 | G37: 20500 | H37: 21100 | I37: 23800 | J37: 25700 | K37: 26400 | L37: 29400 | M37: =_xlfn.FORECAST.LINEAR(M$30,$D37:$L37,$D$30:$L$30) -> 30522.222 | N37: =_xlfn.FORECAST.LINEAR(N$30,$D37:$L37,$D$30:$L$30) -> 32228.889 | O37: =_xlfn.FORECAST.LINEAR(O$30,$D37:$L37,$D$30:$L$30) -> 33935.556 | P37: =_xlfn.FORECAST.LINEAR(P$30,$D37:$L37,$D$30:$L$30) -> 35642.222 | Q37: =_xlfn.FORECAST.LINEAR(Q$30,$D37:$L37,$D$30:$L$30) -> 37348.889 | R37: =_xlfn.FORECAST.LINEAR(R$30,$D37:$L37,$D$30:$L$30) -> 39055.556 | S37: =_xlfn.FORECAST.LINEAR(S$30,$D37:$L37,$D$30:$L$30) -> 40762.222 | T37: =_xlfn.FORECAST.LINEAR(T$30,$D37:$L37,$D$30:$L$30) -> 42468.889 | ... AQ37: =_xlfn.FORECAST.LINEAR(AQ$30,$D37:$L37,$D$30:$L$30) -> 81722.222
C38: Oil | D38: 6850 | E38: 7340 | F38: 7860 | G38: 7620 | H38: 7220 | I38: 7220 | J38: 8160 | K38: 7920 | L38: 6500 | M38: =_xlfn.FORECAST.LINEAR(M$30,$D38:$L38,$D$30:$L$30) -> 7455 | N38: =_xlfn.FORECAST.LINEAR(N$30,$D38:$L38,$D$30:$L$30) -> 7464 | O38: =_xlfn.FORECAST.LINEAR(O$30,$D38:$L38,$D$30:$L$30) -> 7473 | P38: =_xlfn.FORECAST.LINEAR(P$30,$D38:$L38,$D$30:$L$30) -> 7482 | Q38: =_xlfn.FORECAST.LINEAR(Q$30,$D38:$L38,$D$30:$L$30) -> 7491 | R38: =_xlfn.FORECAST.LINEAR(R$30,$D38:$L38,$D$30:$L$30) -> 7500 | S38: =_xlfn.FORECAST.LINEAR(S$30,$D38:$L38,$D$30:$L$30) -> 7509 | T38: =_xlfn.FORECAST.LINEAR(T$30,$D38:$L38,$D$30:$L$30) -> 7518 | ... AQ38: =_xlfn.FORECAST.LINEAR(AQ$30,$D38:$L38,$D$30:$L$30) -> 7725
A40: Conversion per year of generation | C40: =24*365 -> 8760
A41: Conversion from GWh to MWh | C41: 1000
C43: Year | D43: 2011 | E43: 2012 | F43: 2013 | G43: 2014 | H43: 2015 | I43: 2016 | J43: 2017 | K43: 2018 | L43: 2019 | M43: 2020 | N43: 2021 | O43: 2022 | P43: 2023 | Q43: 2024 | R43: 2025 | S43: 2026 | T43: 2027 | U43: 2028 | V43: 2029 | W43: 2030 | X43: 2031 | Y43: 2032 | Z43: 2033 | AA43: 2034 | AB43: 2035 | AC43: 2036 | AD43: 2037 | AE43: 2038 | AF43: 2039 | AG43: 2040 | AH43: 2041 | AI43: 2042 | AJ43: 2043 | AK43: 2044 | AL43: 2045 | AM43: 2046 | AN43: 2047 | AO43: 2048 | AP43: 2049 | AQ43: 2050
C44: Hydro | D44: =(D21*$C$41)/(D31*$C$40) -> 0.36110335 | E44: =(E21*$C$41)/(E31*$C$40) -> 0.3708597 | F44: =(F21*$C$41)/(F31*$C$40) -> 0.47169285 | G44: =(G21*$C$41)/(G31*$C$40) -> 0.41710573 | H44: =(H21*$C$41)/(H31*$C$40) -> 0.36455173 | I44: =(I21*$C$41)/(I31*$C$40) -> 0.50332088 | J44: =(J21*$C$41)/(J31*$C$40) -> 0.43689047 | K44: =(K21*$C$41)/(K31*$C$40) -> 0.39053112 | ... AQ44: =(AQ21*$C$41)/(AQ31*$C$40) -> 0.45745483
C45: Geothermal | D45: =(D22*$C$41)/(D32*$C$40) -> 0.93011713 | E45: =(E22*$C$41)/(E32*$C$40) -> 0.88142825 | F45: =(F22*$C$41)/(F32*$C$40) -> 0.85254041 | G45: =(G22*$C$41)/(G32*$C$40) -> 0.86481251 | H45: =(H22*$C$41)/(H32*$C$40) -> 0.88012827 | I45: =(I22*$C$41)/(I32*$C$40) -> 0.89157751 | J45: =(J22*$C$41)/(J32*$C$40) -> 0.69036747 | K45: =(K22*$C$41)/(K32*$C$40) -> 0.83625358 | ... AQ45: =(AQ22*$C$41)/(AQ32*$C$40) -> 0.56357967
...

Sheet Solar Capacity Factor
A1: Country | B1: Solar thermal
A2: Indonesia | B2: 0.192
A5: Source: | B5: Rijanto, E., Aiman, S., & Santoso, A. (2013). Development of CSP plants in Wallacea region: Solar intensity resource assessment and CSP plant design specification. Energy Procedia, 32, 232-241.
B7: Concentrated Solar Power Plants Capacity Factors: A Review
B8: https://link.springer.com/chapter/10.1007/978-3-319-69480-1_2

Sheet Capacity Factor-Reports
A1: Type | B1: Capacity factor
A2: hard coal | B2: 0.65
A3: natural gas nonpeaker | B3: 0.29
A4: nuclear | B4: 0.45
A5: hydro | B5: 0.37
A6: onshore wind | B6: 0.35
A7: solar PV | B7: 0.18
A8: solar thermal | B8: =B7 -> 0.18
A9: biomass | B9: 0.5
A10: geothermal | B10: 0.82
A11: petroleum | B11: 0.7
A12: natural gas peaker | B12: 0.29
A13: lignite | B13: 0.65
A14: offshore wind | B14: 0.37
A15: crude oil | B15: 0.7
A16: heavy or residual fuel oil | B16: 0.7
A17: municipal solid waste | B17: 0.5

Sheet BECF-pre-ret
A1: Expected Capacity Factor (dimensionless) | B1: 2019 | C1: 2020 | D1: 2021 | E1: 2022 | F1: 2023 | G1: 2024 | H1: 2025 | I1: 2026 | J1: 2027 | K1: 2028 | L1: 2029 | M1: 2030 | N1: 2031 | O1: 2032 | P1: 2033 | Q1: 2034 | R1: 2035 | S1: 2036 | T1: 2037 | U1: 2038 | V1: 2039 | W1: 2040 | X1: 2041 | Y1: 2042 | Z1: 2043 | AA1: 2044 | AB1: 2045 | AC1: 2046 | AD1: 2047 | AE1: 2048 | AF1: 2049 | AG1: 2050 | AH1: 2051 | AI1: 2052 | AJ1: 2053 | AK1: 2054 | AL1: 2055 | AM1: 2056 | AN1: 2057 | AO1: 2058 | AP1: 2059 | AQ1: 2060 | AR1: 2061 | AS1: 2062 | AT1: 2063 | AU1: 2064 | AV1: 2065 | AW1: 2066 | AX1: 2067 | AY1: 2068 | AZ1: 2069 | BA1: 2070
A2: hard coal | B2: ='Capacity Factor-Reports'!B2 -> 0.65 | C2: =B2 -> 0.65 | D2: =C2 -> 0.65 | E2: =D2 -> 0.65 | F2: =E2 -> 0.65 | G2: =F2 -> 0.65 | H2: =G2 -> 0.65 | I2: =H2 -> 0.65 | J2: =I2 -> 0.65 | ... BA2: =AZ2 -> 0.65
A3: natural gas nonpeaker | B3: ='Capacity Factor-Reports'!B3 -> 0.29 | C3: =B3 -> 0.29 | D3: =C3 -> 0.29 | E3: =D3 -> 0.29 | F3: =E3 -> 0.29 | G3: =F3 -> 0.29 | H3: =G3 -> 0.29 | I3: =H3 -> 0.29 | J3: =I3 -> 0.29 | ... BA3: =AZ3 -> 0.29
A4: nuclear | B4: ='Capacity Factor-Reports'!B4 -> 0.45 | C4: =B4 -> 0.45 | D4: =C4 -> 0.45 | E4: =D4 -> 0.45 | F4: =E4 -> 0.45 | G4: =F4 -> 0.45 | H4: =G4 -> 0.45 | I4: =H4 -> 0.45 | J4: =I4 -> 0.45 | ... BA4: =AZ4 -> 0.45
A5: hydro | B5: ='Capacity Factor-Reports'!B5 -> 0.37 | C5: =B5 -> 0.37 | D5: =C5 -> 0.37 | E5: =D5 -> 0.37 | F5: =E5 -> 0.37 | G5: =F5 -> 0.37 | H5: =G5 -> 0.37 | I5: =H5 -> 0.37 | J5: =I5 -> 0.37 | ... BA5: =AZ5 -> 0.37
A6: onshore wind | B6: ='Capacity Factor-Reports'!B6 -> 0.35 | C6: =B6 -> 0.35 | D6: =C6 -> 0.35 | E6: =D6 -> 0.35 | F6: =E6 -> 0.35 | G6: =F6 -> 0.35 | H6: =G6 -> 0.35 | I6: =H6 -> 0.35 | J6: =I6 -> 0.35 | ... BA6: =AZ6 -> 0.35
A7: solar PV | B7: ='Capacity Factor-Reports'!B7 -> 0.18 | C7: =B7 -> 0.18 | D7: =C7 -> 0.18 | E7: =D7 -> 0.18 | F7: =E7 -> 0.18 | G7: =F7 -> 0.18 | H7: =G7 -> 0.18 | I7: =H7 -> 0.18 | J7: =I7 -> 0.18 | ... BA7: =AZ7 -> 0.18
A8: solar thermal | B8: ='Capacity Factor-Reports'!B8 -> 0.18 | C8: =B8 -> 0.18 | D8: =C8 -> 0.18 | E8: =D8 -> 0.18 | F8: =E8 -> 0.18 | G8: =F8 -> 0.18 | H8: =G8 -> 0.18 | I8: =H8 -> 0.18 | J8: =I8 -> 0.18 | ... BA8: =AZ8 -> 0.18
A9: biomass | B9: ='Capacity Factor-Reports'!B9 -> 0.5 | C9: =B9 -> 0.5 | D9: =C9 -> 0.5 | E9: =D9 -> 0.5 | F9: =E9 -> 0.5 | G9: =F9 -> 0.5 | H9: =G9 -> 0.5 | I9: =H9 -> 0.5 | J9: =I9 -> 0.5 | ... BA9: =AZ9 -> 0.5
A10: geothermal | B10: ='Capacity Factor-Reports'!B10 -> 0.82 | C10: =B10 -> 0.82 | D10: =C10 -> 0.82 | E10: =D10 -> 0.82 | F10: =E10 -> 0.82 | G10: =F10 -> 0.82 | H10: =G10 -> 0.82 | I10: =H10 -> 0.82 | J10: =I10 -> 0.82 | ... BA10: =AZ10 -> 0.82
A11: petroleum | B11: ='Capacity Factor-Reports'!B11 -> 0.7 | C11: =B11 -> 0.7 | D11: =C11 -> 0.7 | E11: =D11 -> 0.7 | F11: =E11 -> 0.7 | G11: =F11 -> 0.7 | H11: =G11 -> 0.7 | I11: =H11 -> 0.7 | J11: =I11 -> 0.7 | ... BA11: =AZ11 -> 0.7
A12: natural gas peaker | B12: ='Capacity Factor-Reports'!B12 -> 0.29 | C12: =B12 -> 0.29 | D12: =C12 -> 0.29 | E12: =D12 -> 0.29 | F12: =E12 -> 0.29 | G12: =F12 -> 0.29 | H12: =G12 -> 0.29 | I12: =H12 -> 0.29 | J12: =I12 -> 0.29 | ... BA12: =AZ12 -> 0.29
A13: lignite | B13: ='Capacity Factor-Reports'!B13 -> 0.65 | C13: =B13 -> 0.65 | D13: =C13 -> 0.65 | E13: =D13 -> 0.65 | F13: =E13 -> 0.65 | G13: =F13 -> 0.65 | H13: =G13 -> 0.65 | I13: =H13 -> 0.65 | J13: =I13 -> 0.65 | ... BA13: =AZ13 -> 0.65
... A17: municipal solid waste | B17: ='Capacity Factor-Reports'!B17 -> 0.5 | C17: =B17 -> 0.5 | D17: =C17 -> 0.5 | E17: =D17 -> 0.5 | F17: =E17 -> 0.5 | G17: =F17 -> 0.5 | H17: =G17 -> 0.5 | I17: =H17 -> 0.5 | J17: =I17 -> 0.5 | ... BA17: =AZ17 -> 0.5

Sheet BECF-pre-nonret
A1: Expected Capacity Factor (dimensionless) | B1: 2019 | C1: 2020 | D1: 2021 | E1: 2022 | F1: 2023 | G1: 2024 | H1: 2025 | I1: 2026 | J1: 2027 | K1: 2028 | L1: 2029 | M1: 2030 | N1: 2031 | O1: 2032 | P1: 2033 | Q1: 2034 | R1: 2035 | S1: 2036 | T1: 2037 | U1: 2038 | V1: 2039 | W1: 2040 | X1: 2041 | Y1: 2042 | Z1: 2043 | AA1: 2044 | AB1: 2045 | AC1: 2046 | AD1: 2047 | AE1: 2048 | AF1: 2049 | AG1: 2050 | AH1: 2051 | AI1: 2052 | AJ1: 2053 | AK1: 2054 | AL1: 2055 | AM1: 2056 | AN1: 2057 | AO1: 2058 | AP1: 2059 | AQ1: 2060 | AR1: 2061 | AS1: 2062 | AT1: 2063 | AU1: 2064 | AV1: 2065 | AW1: 2066 | AX1: 2067 | AY1: 2068 | AZ1: 2069 | BA1: 2070
A2: hard coal | B2: 0 | C2: =$B2 -> 0 | D2: =$B2 -> 0 | E2: =$B2 -> 0 | F2: =$B2 -> 0 | G2: =$B2 -> 0 | H2: =$B2 -> 0 | I2: =$B2 -> 0 | J2: =$B2 -> 0 | ... BA2: =$B2 -> 0
A3: natural gas nonpeaker | B3: 0 | C3: =$B3 -> 0 | D3: =$B3 -> 0 | E3: =$B3 -> 0 | F3: =$B3 -> 0 | G3: =$B3 -> 0 | H3: =$B3 -> 0 | I3: =$B3 -> 0 | J3: =$B3 -> 0 | ... BA3: =$B3 -> 0
A4: nuclear | B4: 0 | C4: =$B4 -> 0 | D4: =$B4 -> 0 | E4: =$B4 -> 0 | F4: =$B4 -> 0 | G4: =$B4 -> 0 | H4: =$B4 -> 0 | I4: =$B4 -> 0 | J4: =$B4 -> 0 | ... BA4: =$B4 -> 0
A5: hydro | B5: 0 | C5: =$B5 -> 0 | D5: =$B5 -> 0 | E5: =$B5 -> 0 | F5: =$B5 -> 0 | G5: =$B5 -> 0 | H5: =$B5 -> 0 | I5: =$B5 -> 0 | J5: =$B5 -> 0 | ... BA5: =$B5 -> 0
A6: onshore wind | B6: 0 | C6: =$B6 -> 0 | D6: =$B6 -> 0 | E6: =$B6 -> 0 | F6: =$B6 -> 0 | G6: =$B6 -> 0 | H6: =$B6 -> 0 | I6: =$B6 -> 0 | J6: =$B6 -> 0 | ... BA6: =$B6 -> 0
A7: solar PV | B7: 0 | C7: =$B7 -> 0 | D7: =$B7 -> 0 | E7: =$B7 -> 0 | F7: =$B7 -> 0 | G7: =$B7 -> 0 | H7: =$B7 -> 0 | I7: =$B7 -> 0 | J7: =$B7 -> 0 | ... BA7: =$B7 -> 0
A8: solar thermal | B8: 0 | C8: =$B8 -> 0 | D8: =$B8 -> 0 | E8: =$B8 -> 0 | F8: =$B8 -> 0 | G8: =$B8 -> 0 | H8: =$B8 -> 0 | I8: =$B8 -> 0 | J8: =$B8 -> 0 | ... BA8: =$B8 -> 0
A9: biomass | B9: 0 | C9: =$B9 -> 0 | D9: =$B9 -> 0 | E9: =$B9 -> 0 | F9: =$B9 -> 0 | G9: =$B9 -> 0 | H9: =$B9 -> 0 | I9: =$B9 -> 0 | J9: =$B9 -> 0 | ... BA9: =$B9 -> 0
A10: geothermal | B10: 0 | C10: =$B10 -> 0 | D10: =$B10 -> 0 | E10: =$B10 -> 0 | F10: =$B10 -> 0 | G10: =$B10 -> 0 | H10: =$B10 -> 0 | I10: =$B10 -> 0 | J10: =$B10 -> 0 | ... BA10: =$B10 -> 0
A11: petroleum | B11: 0 | C11: =$B11 -> 0 | D11: =$B11 -> 0 | E11: =$B11 -> 0 | F11: =$B11 -> 0 | G11: =$B11 -> 0 | H11: =$B11 -> 0 | I11: =$B11 -> 0 | J11: =$B11 -> 0 | ... BA11: =$B11 -> 0
A12: natural gas peaker | B12: 0 | C12: =$B12 -> 0 | D12: =$B12 -> 0 | E12: =$B12 -> 0 | F12: =$B12 -> 0 | G12: =$B12 -> 0 | H12: =$B12 -> 0 | I12: =$B12 -> 0 | J12: =$B12 -> 0 | ... BA12: =$B12 -> 0
A13: lignite | B13: 0 | C13: =$B13 -> 0 | D13: =$B13 -> 0 | E13: =$B13 -> 0 | F13: =$B13 -> 0 | G13: =$B13 -> 0 | H13: =$B13 -> 0 | I13: =$B13 -> 0 | J13: =$B13 -> 0 | ... BA13: =$B13 -> 0
... A17: municipal solid waste | B17: 0 | C17: =$B17 -> 0 | D17: =$B17 -> 0 | E17: =$B17 -> 0 | F17: =$B17 -> 0 | G17: =$B17 -> 0 | H17: =$B17 -> 0 | I17: =$B17 -> 0 | J17: =$B17 -> 0 | ... BA17: =$B17 -> 0

Sheet BECF-new
A1: Expected Capacity Factor (dimensionless) | B1: 2019 | C1: 2020 | D1: 2021 | E1: 2022 | F1: 2023 | G1: 2024 | H1: 2025 | I1: 2026 | J1: 2027 | K1: 2028 | L1: 2029 | M1: 2030 | N1: 2031 | O1: 2032 | P1: 2033 | Q1: 2034 | R1: 2035 | S1: 2036 | T1: 2037 | U1: 2038 | V1: 2039 | W1: 2040 | X1: 2041 | Y1: 2042 | Z1: 2043 | AA1: 2044 | AB1: 2045 | AC1: 2046 | AD1: 2047 | AE1: 2048 | AF1: 2049 | AG1: 2050 | AH1: 2051 | AI1: 2052 | AJ1: 2053 | AK1: 2054 | AL1: 2055 | AM1: 2056 | AN1: 2057 | AO1: 2058 | AP1: 2059 | AQ1: 2060 | AR1: 2061 | AS1: 2062 | AT1: 2063 | AU1: 2064 | AV1: 2065 | AW1: 2066 | AX1: 2067 | AY1: 2068 | AZ1: 2069 | BA1: 2070
A2: hard coal | B2: ='BECF-pre-ret'!B2 -> 0.65 | C2: =$B2 -> 0.65 | D2: =$B2 -> 0.65 | E2: =$B2 -> 0.65 | F2: =$B2 -> 0.65 | G2: =$B2 -> 0.65 | H2: =$B2 -> 0.65 | I2: =$B2 -> 0.65 | J2: =$B2 -> 0.65 | ... AG2: =$B2 -> 0.65 | AH2: =AG2 -> 0.65 | AI2: =AH2 -> 0.65 | AJ2: =AI2 -> 0.65 | AK2: =AJ2 -> 0.65 | AL2: =AK2 -> 0.65 | AM2: =AL2 -> 0.65 | AN2: =AM2 -> 0.65 | AO2: =AN2 -> 0.65 | ... BA2: =AZ2 -> 0.65
