Workbook
Name a: #REF!
Name Calculated_Relationship_HS12___HS07: #REF!
Name CAP_CT: #REF!
Name CAP_CT: #REF!
Name CAP_GFCF: #REF!
Name CAP_GFCF: #REF!
Name CAP_IT: #REF!
Name CAP_IT: #REF!
Name CAP_OCon: #REF!
Name CAP_OCon: #REF!
Name CAP_OMach: #REF!
Name CAP_OMach: #REF!
Name CAP_Other: #REF!
Name CAP_Other: #REF!
Name CAP_QI: #REF!
Name CAP_QI: #REF!
Name CAP_RStruc: #REF!
Name CAP_RStruc: #REF!
Name CAP_Soft: #REF!
Name CAP_Soft: #REF!
Name CAP_TraEq: #REF!
Name CAP_TraEq: #REF!
Name CAPIT: #REF!
Name CAPIT: #REF!
Name CAPIT_QI: #REF!
Name CAPIT_QI: #REF!
Name capit_qph: #REF!
Name capit_qph: #REF!
Name CAPNIT: #REF!
Name CAPNIT: #REF!
Name CAPNIT_QI: #REF!
Name CAPNIT_QI: #REF!
Name capnit_qph: #REF!
Name capnit_qph: #REF!
Name FLAPPIE: #REF!
Name FLAPPIE: #REF!
Name gal_per_barrel: #REF!
Name gal_per_barrel: About!$A$70
Name go_level_top1: OFFSET(#REF!,MATCH(#REF!,#REF!,0),2,1,8)
Name HS: #REF!
Name HS: #REF!
Name M1_stone: #REF!
Name M2_stone: #REF!
Name M3_stone: #REF!
Name Matrix1: #REF!
Name Matrix1: #REF!
Name preferences.energyunits: #REF!
Name Preferences.PowerUnits: #REF!
Name rca_trad_2010: #REF!
Name rca_trad_2011: #REF!
Name rca_trad_2012: #REF!
Name rca_trad_2013: #REF!
Name rca_trad_2014: #REF!
Name rca_trad_2015: #REF!
Name rca_trad_2016: #REF!
Name rca_trad_2017: #REF!
Name rca_vax_2010: #REF!
Name rca_vax_2011: #REF!
Name rca_vax_2012: #REF!
Name rca_vax_2013: #REF!

Sheet About
A1: BIFUbC BAU Industrial Fuel Use before CCS
A3: Sources: | B3: Energy consumption
B4: IEA
B5: World Energy Balances
B6: 44774
B7: https://www.iea.org/data-and-statistics/data-product/world-energy-balances
B10: Electricity consumption
B11: Statistik Industri Manufaktur Indonesia, 2020
B12: 2022
B13: Badan Pusat Statistik
B14: https://www.bps.go.id/publication/2022/09/30/206f24701aea1e4a26b6f1ff/statistik-industri-manufaktur-indonesia-2020.html
B16: Population
B17: World Bank
B18: https://data.worldbank.org/indicator/SP.POP.TOTL?locations=IN
A20: BIFUbC BAU Industrial Fuel Use before CCS
A22: Source | B22: IESR (2024)
B23: https://iesr.or.id/en/
A25: Comments | B25: These data come from the LEAP (Long-range Energy Alternatives Planning) Indonesia model and represent BAU (Business As Usual) scenarios projected for the country. The BAU scenarios assume no significant changes to current energy policies or interventions, providing a baseline for analyzing future energy consumption, emissions, and sectoral growth under existing conditions. This model helps evaluate long-term trends in Indonesia's energy use and environmental impacts, serving as a foundation for comparing potential outcomes from alternative policy scenarios aimed at sustainable development and climate goals.
A27: Note:
A28: IEA data processed and estimated by sector
A29: Forecasted using IO file change in output
A30: Electricity data from Stastik Industri Manufaktur Indonesia
A32: toe_to_btu | B32: 39680000
A36: Crude oil Consumption
A38: Source | B38: Source: Statistical Review of World Energy 2023
B39: https://www.indonesia-investments.com/business/commodities/crude-oil/item267?

Sheet Ind gov data
A33: ktoe | F33: fuel
B34: biomass | C34: coal | D34: briquette | E34: gas | F34: kerosene | G34: gasoil cn 48 | H34: biogasoil | I34: mdf | J34: fuel oil | K34: total fuel | L34: lpg | M34: electricity | N34: total
A35: 2018 | B35: 43176 | C35: 100506 | D35: 36 | E35: 93939 | F35: 203 | G35: 18517 | H35: 0 | I35: 394 | J35: 13174 | K35: 32288 | L35: 934 | M35: 57338 | N35: 328217
A36: 2019 | B36: 42862 | C36: 167412 | D36: 28 | E36: 92958 | F36: 192 | G36: 1099 | H36: 13323 | I36: 314 | J36: 9883 | K36: 24811 | L36: 959 | M36: 57794 | N36: 386825
A37: 2020 | B37: 52164 | C37: 113416 | D37: 188 | E37: 96400 | F37: 178 | G37: 2048 | H37: 12449 | I37: 234 | J37: 7669 | K37: 22578 | L37: 991 | M37: 54172 | N37: 339909
A38: 2021 | B38: 53461 | C38: 87820 | D38: 0 | E38: 88481 | F38: 177 | G38: 3706 | H38: 13473 | I38: 301 | J38: 8118 | K38: 25776 | L38: 1057 | M38: 60973 | N38: 317568
A41: btus
B42: biomass | C42: coal | D42: briquette | E42: gas | F42: kerosene | G42: gasoil cn 48 | H42: biogasoil | I42: mdf | J42: fuel oil | K42: total fuel | L42: lpg | M42: electricity | N42: total
A43: 2018 | B43: =B35*1000*About!$B$32 -> 1.7132237e+15 | C43: =C35*1000*About!$B$32 -> 3.9880781e+15 | D43: =D35*1000*About!$B$32 -> 1428480000000 | E43: =E35*1000*About!$B$32 -> 3.7274995e+15 | F43: =F35*1000*About!$B$32 -> 8055040000000 | G43: =G35*1000*About!$B$32 -> 734754560000000 | H43: =H35*1000*About!$B$32 -> 0 | I43: =I35*1000*About!$B$32 -> 15633920000000 | ... N43: =N35*1000*About!$B$32 -> 1.3023651e+16
A44: 2019 | B44: =B36*1000*About!$B$32 -> 1.7007642e+15 | C44: =C36*1000*About!$B$32 -> 6.6429082e+15 | D44: =D36*1000*About!$B$32 -> 1111040000000 | E44: =E36*1000*About!$B$32 -> 3.6885734e+15 | F44: =F36*1000*About!$B$32 -> 7618560000000 | G44: =G36*1000*About!$B$32 -> 43608320000000 | H44: =H36*1000*About!$B$32 -> 528656640000000 | I44: =I36*1000*About!$B$32 -> 12459520000000 | ... N44: =N36*1000*About!$B$32 -> 1.5349216e+16
A45: 2020 | B45: =B37*1000*About!$B$32 -> 2.0698675e+15 | C45: =C37*1000*About!$B$32 -> 4.5003469e+15 | D45: =D37*1000*About!$B$32 -> 7459840000000 | E45: =E37*1000*About!$B$32 -> 3.825152e+15 | F45: =F37*1000*About!$B$32 -> 7063040000000 | G45: =G37*1000*About!$B$32 -> 81264640000000 | H45: =H37*1000*About!$B$32 -> 493976320000000 | I45: =I37*1000*About!$B$32 -> 9285120000000 | ... N45: =N37*1000*About!$B$32 -> 1.3487589e+16
A46: 2021 | B46: =B38*1000*About!$B$32 -> 2.1213325e+15 | C46: =C38*1000*About!$B$32 -> 3.4846976e+15 | D46: =D38*1000*About!$B$32 -> 0 | E46: =E38*1000*About!$B$32 -> 3.5109261e+15 | F46: =F38*1000*About!$B$32 -> 7023360000000 | G46: =G38*1000*About!$B$32 -> 147054080000000 | H46: =H38*1000*About!$B$32 -> 534608640000000 | I46: =I38*1000*About!$B$32 -> 11943680000000 | ... N46: =N38*1000*About!$B$32 -> 1.2601098e+16
A49: COMPARE VALUES | B49: =SUM(calcs!D80:D104) -> 4.3800743e+13 | C49: =SUM(calcs!D30:D53) -> 7.8302527e+14 | E49: =SUM(calcs!D55:D79) -> 1.5994807e+15 | J49: =SUM(calcs!D180:D204) -> 2.2153246e+13 | L49: =SUM(calcs!D155:D179) -> 1.5644402e+13 | M49: =SUM(calcs!D5:D29) -> 4.7673728e+14

Sheet Electricity consumption
D1: generated (kwh) | E1: purchased (kwh) | F1: sold (kwh) | G1: Total | H1: percent of total
A2: food beverage and tobacco 1T12 | B2: 10 | C2: food industry | D2: 1446993803 | E2: 5289689785 | F2: 69495534 | G2: =SUM(D2:F2) -> 6806179122 | H2: =G2/SUM($G$2:$G$25) -> 0.11476603
A3: food beverage and tobacco 1T12 | B3: 11 | C3: beverages | D3: 10874632 | E3: 724494110 | G3: =SUM(D3:F3) -> 735368742 | H3: =G3/SUM($G$2:$G$25) -> 0.012399813
A4: food beverage and tobacco 1T12 | B4: 12 | C4: tobacco products | D4: 2484100 | E4: 181149874 | G4: =SUM(D4:F4) -> 183633974 | H4: =G4/SUM($G$2:$G$25) -> 0.0030964424
A5: textiles apparel and leather 13T15 | B5: 13 | C5: textiles | D5: 3746167 | E5: 3939696246 | G5: =SUM(D5:F5) -> 3943442413 | H5: =G5/SUM($G$2:$G$25) -> 0.066494462
A6: textiles apparel and leather 13T15 | B6: 14 | C6: wearing apparels | D6: 32717171 | E6: 2688662145 | F6: 26 | G6: =SUM(D6:F6) -> 2721379342 | H6: =G6/SUM($G$2:$G$25) -> 0.045887992
A7: textiles apparel and leather 13T15 | B7: 15 | C7: leather and related products and footwear | D7: 7197930 | E7: 745185904 | F7: 25 | G7: =SUM(D7:F7) -> 752383859 | H7: =G7/SUM($G$2:$G$25) -> 0.012686723
A8: wood products 16 | B8: 16 | C8: wood and wood products | D8: 90604474 | E8: 894994253 | F8: 620781 | G8: =SUM(D8:F8) -> 986219508 | H8: =G8/SUM($G$2:$G$25) -> 0.016629667
A9: pulp paper and printing 17T18 | B9: 17 | C9: paper and paper products | D9: 716317698 | E9: 2906539245 | F9: 314557786 | G9: =SUM(D9:F9) -> 3937414729 | H9: =G9/SUM($G$2:$G$25) -> 0.066392823
A10: pulp paper and printing 17T18 | B10: 18 | C10: printing and reproduction of recorded media | D10: 1345693 | E10: 204796190 | G10: =SUM(D10:F10) -> 206141883 | H10: =G10/SUM($G$2:$G$25) -> 0.0034759715
A11: refined petroleum and coke 19 | B11: 19 | C11: coke and refined petroleum products | D11: 1731917983 | E11: 1903553790 | G11: =SUM(D11:F11) -> 3635471773 | H11: =G11/SUM($G$2:$G$25) -> 0.06130145
A12: chemicals 2 | B12: 20 | C12: chemicals | D12: 1095954589 | E12: 4890031989 | F12: 651990 | G12: =SUM(D12:F12) -> 5986638568 | H12: =G12/SUM($G$2:$G$25) -> 0.10094691
A13: other manufacturing 31T33 and rubber and plastic products 22 | B13: 21 | C13: pharmaceuticals | D13: 70276995 | E13: 961022320 | G13: =SUM(D13:F13) -> 1031299315 | H13: =G13/SUM($G$2:$G$25) -> 0.017389805
A14: other manufacturing 31T33 and rubber and plastic products 22 | B14: 22 | C14: rubber and plastic products | D14: 46767718 | E14: 3210602634 | F14: 2550 | G14: =SUM(D14:F14) -> 3257372902 | H14: =G14/SUM($G$2:$G$25) -> 0.054925934
A15: cement and other nonmetallic minerals 239 & glass and glass products 231 | B15: 23 | C15: other non-metallic mineral products | D15: 1258964689 | E15: 7777749770 | F15: 66455455 | G15: =SUM(D15:F15) -> 9103169914 | H15: =G15/SUM($G$2:$G$25) -> 0.15349797
A16: iron and steel 241 | B16: 24 | C16: basic metals | D16: 5623272221 | E16: 5245970518 | F16: 44782959 | G16: =SUM(D16:F16) -> 10914025698 | H16: =G16/SUM($G$2:$G$25) -> 0.18403268
A17: metal products except machinery and vehicles 25, computers and electronics 26, appliances and electrical equipment 27, and other machinery 28 | B17: 25 | C17: fabricated metal products | D17: 2672759 | E17: 697453265 | G17: =SUM(D17:F17) -> 700126024 | H17: =G17/SUM($G$2:$G$25) -> 0.011805549
A18: metal products except machinery and vehicles 25, computers and electronics 26, appliances and electrical equipment 27, and other machinery 28 | B18: 26 | C18: computers, electronics | D18: 1142023 | E18: 586300435 | G18: =SUM(D18:F18) -> 587442458 | H18: =G18/SUM($G$2:$G$25) -> 0.009905475
A19: metal products except machinery and vehicles 25, computers and electronics 26, appliances and electrical equipment 27, and other machinery 28 | B19: 27 | C19: electrical equipment | D19: 5053647 | E19: 1176542830 | G19: =SUM(D19:F19) -> 1181596477 | H19: =G19/SUM($G$2:$G$25) -> 0.019924121
A20: metal products except machinery and vehicles 25, computers and electronics 26, appliances and electrical equipment 27, and other machinery 28 | B20: 28 | C20: machinery and equipment | D20: 6295645 | E20: 491681038 | G20: =SUM(D20:F20) -> 497976683 | H20: =G20/SUM($G$2:$G$25) -> 0.0083969
A21: road vehicles 29 and nonroad vehicles 3 | B21: 29 | C21: motor vehicles, trailers, and semi-trailers | D21: 1763488 | E21: 986190413 | G21: =SUM(D21:F21) -> 987953901 | H21: =G21/SUM($G$2:$G$25) -> 0.016658913
A22: road vehicles 29 and nonroad vehicles 3 | B22: 30 | C22: other transport equipment | D22: 1864277 | E22: 422697029 | G22: =SUM(D22:F22) -> 424561306 | H22: =G22/SUM($G$2:$G$25) -> 0.0071589674
A23: other manufacturing 31T33 and rubber and plastic products 22 | B23: 31 | C23: furntiture | D23: 7551270 | E23: 299696458 | F23: 200 | G23: =SUM(D23:F23) -> 307247928 | H23: =G23/SUM($G$2:$G$25) -> 0.0051808252
A24: other manufacturing 31T33 and rubber and plastic products 22 | B24: 32 | C24: other manufacturing | D24: 503898 | E24: 328090178 | G24: =SUM(D24:F24) -> 328594076 | H24: =G24/SUM($G$2:$G$25) -> 0.0055407646
A25: other manufacturing 31T33 and rubber and plastic products 22 | B25: 33 | C25: repair and installation of machinery and equipment | D25: 3581429 | E25: 85602679 | G25: =SUM(D25:F25) -> 89184108 | H25: =G25/SUM($G$2:$G$25) -> 0.0015038255
C27: TOTAL | D27: =SUM(D2:D25) -> 12169864299 | E27: =SUM(E2:E25) -> 46638393098 | F27: =SUM(F2:F25) -> 496567306 | H27: =SUM(H1:H25) -> 1
D29: =SUM(D27:F27) -> 59304824703
A47: road vehicles 29 and nonroad vehicles 3
A48: textiles apparel and leather 13T15

Sheet BIFUBC Output_energy
A1: EPS FUEL | B1: Assigned EPS Sector | C1: FUEL | D1: SECTOR | E1: 2018 | F1: 2019 | G1: 2020
A2: =C2 -> hard coal | B2: {=IFERROR(INDEX(crosswalk!C:C,MATCH(D2,crosswalk!B:B,0)),"")} -> agriculture and forestry 01T03 | C2: hard coal | D2: agriculture and forestry 1T3 | E2: 0 | F2: 0 | G2: 0
A3: =C3 -> hard coal | B3: {=IFERROR(INDEX(crosswalk!C:C,MATCH(D3,crosswalk!B:B,0)),"")} -> cement and other nonmetallic minerals 239 | C3: hard coal | D3: cement and other nonmetallic minerals 239 & glass and glass products 231 | E3: 3.3870673e+14 | F3: 4.0073899e+14 | G3: 115903236480000
A4: =C4 -> hard coal | B4: {=IFERROR(INDEX(crosswalk!C:C,MATCH(D4,crosswalk!B:B,0)),"")} -> chemicals 20 | C4: hard coal | D4: chemicals 2 | E4: 0 | F4: 0 | G4: 0
A5: =C5 -> hard coal | B5: {=IFERROR(INDEX(crosswalk!C:C,MATCH(D5,crosswalk!B:B,0)),"")} -> coal mining 05 | C5: hard coal | D5: coal mining 05 | E5: 0 | F5: 0 | G5: 0
A6: =C6 -> hard coal | B6: {=IFERROR(INDEX(crosswalk!C:C,MATCH(D6,crosswalk!B:B,0)),"")} -> construction 41T43 | C6: hard coal | D6: construction 41T43 | E6: 0 | F6: 0 | G6: 0
A7: =C7 -> hard coal | B7: {=IFERROR(INDEX(crosswalk!C:C,MATCH(D7,crosswalk!B:B,0)),"")} -> energy pipelines and gas processing 352T353 | C7: hard coal | D7: energy pipelines and gas processing 352T353 | E7: 0 | F7: 0 | G7: 0
A8: =C8 -> hard coal | B8: {=IFERROR(INDEX(crosswalk!C:C,MATCH(D8,crosswalk!B:B,0)),"")} -> food beverage and tobacco 10T12 | C8: hard coal | D8: food beverage and tobacco 1T12 | E8: 0 | F8: 0 | G8: 0
A9: =C9 -> hard coal | B9: {=IFERROR(INDEX(crosswalk!C:C,MATCH(D9,crosswalk!B:B,0)),"")} -> iron and steel 241 | C9: hard coal | D9: iron and steel 241 | E9: 84090153600000 | F9: 289971734272000 | G9: 368405579264000
A10: =C10 -> hard coal | B10: {=IFERROR(INDEX(crosswalk!C:C,MATCH(D10,crosswalk!B:B,0)),"")} | C10: hard coal | D10: many | E10: 0 | F10: 0 | G10: 0
A11: =C11 -> hard coal | B11: {=IFERROR(INDEX(crosswalk!C:C,MATCH(D11,crosswalk!B:B,0)),"")} -> metal products except machinery and vehicles 25 | C11: hard coal | D11: metal products except machinery and vehicles 25, computers and electronics 26, appliances and electrical equipment 27, and other machinery 28 | E11: 0 | F11: 0 | G11: 0
A12: =C12 -> hard coal | B12: {=IFERROR(INDEX(crosswalk!C:C,MATCH(D12,crosswalk!B:B,0)),"")} -> oil and gas extraction 06 | C12: hard coal | D12: oil and gas extraction 06 | E12: 0 | F12: 0 | G12: 0
A13: =C13 -> hard coal | B13: {=IFERROR(INDEX(crosswalk!C:C,MATCH(D13,crosswalk!B:B,0)),"")} -> other manufacturing 31T33 | C13: hard coal | D13: other manufacturing 31T33 and rubber and plastic products 22 | E13: 189547392000 | F13: 70901493760000 | G13: 95000368000000
... A20: =C20 -> hard coal | B20: {=IFERROR(INDEX(crosswalk!C:C,MATCH(D20,crosswalk!B:B,0)),"")} -> wood products 16 | C20: hard coal | D20: wood products 16 | E20: 0 | F20: 0 | G20: 0
A21: =C21 -> 0 | B21: {=IFERROR(INDEX(crosswalk!C:C,MATCH(D21,crosswalk!B:B,0)),"")}
A22: =C22 -> natural gas | B22: {=IFERROR(INDEX(crosswalk!C:C,MATCH(D22,crosswalk!B:B,0)),"")} -> agriculture and forestry 01T03 | C22: natural gas | D22: agriculture and forestry 1T3 | E22: 0 | F22: 0 | G22: 0
A23: =C23 -> natural gas | B23: {=IFERROR(INDEX(crosswalk!C:C,MATCH(D23,crosswalk!B:B,0)),"")} -> cement and other nonmetallic minerals 239 | C23: natural gas | D23: cement and other nonmetallic minerals 239 & glass and glass products 231 | E23: 0 | F23: 0 | G23: 0
A24: =C24 -> natural gas | B24: {=IFERROR(INDEX(crosswalk!C:C,MATCH(D24,crosswalk!B:B,0)),"")} -> chemicals 20 | C24: natural gas | D24: chemicals 2 | E24: 120052839936000 | F24: 118799134464000 | G24: 123197968000000
A25: =C25 -> natural gas | B25: {=IFERROR(INDEX(crosswalk!C:C,MATCH(D25,crosswalk!B:B,0)),"")} -> coal mining 05 | C25: natural gas | D25: coal mining 05 | E25: 0 | F25: 0 | G25: 0
A26: =C26 -> natural gas | B26: {=IFERROR(INDEX(crosswalk!C:C,MATCH(D26,crosswalk!B:B,0)),"")} -> construction 41T43 | C26: natural gas | D26: construction 41T43 | E26: 0 | F26: 0 | G26: 0
A27: =C27 -> natural gas | B27: {=IFERROR(INDEX(crosswalk!C:C,MATCH(D27,crosswalk!B:B,0)),"")} -> energy pipelines and gas processing 352T353 | C27: natural gas | D27: energy pipelines and gas processing 352T353 | E27: 36927664256000 | F27: 20041641856000 | G27: 55402438144000
A28: =C28 -> natural gas | B28: {=IFERROR(INDEX(crosswalk!C:C,MATCH(D28,crosswalk!B:B,0)),"")} -> food beverage and tobacco 10T12 | C28: natural gas | D28: food beverage and tobacco 1T12 | E28: 0 | F28: 0 | G28: 0
A29: =C29 -> natural gas | B29: {=IFERROR(INDEX(crosswalk!C:C,MATCH(D29,crosswalk!B:B,0)),"")} -> iron and steel 241 | C29: natural gas | D29: iron and steel 241 | E29: 4466027648000 | F29: 6186421504000 | G29: 9297111296000
A30: =C30 -> natural gas | B30: {=IFERROR(INDEX(crosswalk!C:C,MATCH(D30,crosswalk!B:B,0)),"")} | C30: natural gas | D30: many | E30: 0 | F30: 0 | G30: 0
A31: =C31 -> natural gas | B31: {=IFERROR(INDEX(crosswalk!C:C,MATCH(D31,crosswalk!B:B,0)),"")} -> metal products except machinery and vehicles 25 | C31: natural gas | D31: metal products except machinery and vehicles 25, computers and electronics 26, appliances and electrical equipment 27, and other machinery 28 | E31: 0 | F31: 0 | G31: 0
A32: =C32 -> natural gas | B32: {=IFERROR(INDEX(crosswalk!C:C,MATCH(D32,crosswalk!B:B,0)),"")} -> oil and gas extraction 06 | C32: natural gas | D32: oil and gas extraction 06 | E32: 192617798656000 | F32: 178811444224000 | G32: 157525151872000
A33: =C33 -> natural gas | B33: {=IFERROR(INDEX(crosswalk!C:C,MATCH(D33,crosswalk!B:B,0)),"")} -> other manufacturing 31T33 | C33: natural gas | D33: other manufacturing 31T33 and rubber and plastic products 22 | E33: 388392680960000 | F33: 382569688576000 | G33: 3.9385365e+14
... A40: =C40 -> natural gas | B40: {=IFERROR(INDEX(crosswalk!C:C,MATCH(D40,crosswalk!B:B,0)),"")} -> wood products 16 | C40: natural gas | D40: wood products 16 | E40: 0 | F40: 0 | G40: 0
A41: =C41 -> 0 | B41: {=IFERROR(INDEX(crosswalk!C:C,MATCH(D41,crosswalk!B:B,0)),"")}
A42: =C42 -> crude oil | B42: {=IFERROR(INDEX(crosswalk!C:C,MATCH(D42,crosswalk!B:B,0)),"")} -> agriculture and forestry 01T03 | C42: crude oil | D42: agriculture and forestry 1T3 | E42: 0 | F42: 0 | G42: 0
A43: =C43 -> crude oil | B43: {=IFERROR(INDEX(crosswalk!C:C,MATCH(D43,crosswalk!B:B,0)),"")} -> cement and other nonmetallic minerals 239 | C43: crude oil | D43: cement and other nonmetallic minerals 239 & glass and glass products 231 | E43: 0 | F43: 0 | G43: 0
A44: =C44 -> crude oil | B44: {=IFERROR(INDEX(crosswalk!C:C,MATCH(D44,crosswalk!B:B,0)),"")} -> chemicals 20 | C44: crude oil | D44: chemicals 2 | E44: 0 | F44: 0 | G44: 0
A45: =C45 -> crude oil | B45: {=IFERROR(INDEX(crosswalk!C:C,MATCH(D45,crosswalk!B:B,0)),"")} -> coal mining 05 | C45: crude oil | D45: coal mining 05 | E45: 0 | F45: 0 | G45: 0
A46: =C46 -> crude oil | B46: {=IFERROR(INDEX(crosswalk!C:C,MATCH(D46,crosswalk!B:B,0)),"")} -> construction 41T43 | C46: crude oil | D46: construction 41T43 | E46: 0 | F46: 0 | G46: 0
A47: =C47 -> crude oil | B47: {=IFERROR(INDEX(crosswalk!C:C,MATCH(D47,crosswalk!B:B,0)),"")} -> energy pipelines and gas processing 352T353 | C47: crude oil | D47: energy pipelines and gas processing 352T353 | E47: 0 | F47: 0 | G47: 0
A48: =C48 -> crude oil | B48: {=IFERROR(INDEX(crosswalk!C:C,MATCH(D48,crosswalk!B:B,0)),"")} -> food beverage and tobacco 10T12 | C48: crude oil | D48: food beverage and tobacco 1T12 | E48: 0 | F48: 0 | G48: 0
A49: =C49 -> crude oil | B49: {=IFERROR(INDEX(crosswalk!C:C,MATCH(D49,crosswalk!B:B,0)),"")} -> iron and steel 241 | C49: crude oil | D49: iron and steel 241 | E49: 0 | F49: 0 | G49: 0
A50: =C50 -> crude oil | B50: {=IFERROR(INDEX(crosswalk!C:C,MATCH(D50,crosswalk!B:B,0)),"")} | C50: crude oil | D50: many | E50: 0 | F50: 0 | G50: 0
A51: =C51 -> crude oil | B51: {=IFERROR(INDEX(crosswalk!C:C,MATCH(D51,crosswalk!B:B,0)),"")} -> metal products except machinery and vehicles 25 | C51: crude oil | D51: metal products except machinery and vehicles 25, computers and electronics 26, appliances and electrical equipment 27, and other machinery 28 | E51: 0 | F51: 0 | G51: 0
A52: =C52 -> crude oil | B52: {=IFERROR(INDEX(crosswalk!C:C,MATCH(D52,crosswalk!B:B,0)),"")} -> oil and gas extraction 06 | C52: crude oil | D52: oil and gas extraction 06 | E52: 0 | F52: 0 | G52: 0
...

Sheet BIFUBC Output_nonenergy
A1: EPS FUEL | B1: Assigned EPS Sector | C1: FUEL | D1: SECTOR | E1: 2020
A2: =C2 -> hard coal | B2: {=IFERROR(INDEX(crosswalk!C:C,MATCH(D2,crosswalk!B:B,0)),"")} -> agriculture and forestry 01T03 | C2: hard coal | D2: agriculture and forestry 1T3 | E2: 0
A3: =C3 -> hard coal | B3: {=IFERROR(INDEX(crosswalk!C:C,MATCH(D3,crosswalk!B:B,0)),"")} -> cement and other nonmetallic minerals 239 | C3: hard coal | D3: cement and other nonmetallic minerals 239 & glass and glass products 231 | E3: 0
A4: =C4 -> hard coal | B4: {=IFERROR(INDEX(crosswalk!C:C,MATCH(D4,crosswalk!B:B,0)),"")} -> chemicals 20 | C4: hard coal | D4: chemicals 2 | E4: 0
A5: =C5 -> hard coal | B5: {=IFERROR(INDEX(crosswalk!C:C,MATCH(D5,crosswalk!B:B,0)),"")} -> coal mining 05 | C5: hard coal | D5: coal mining 05 | E5: 0
A6: =C6 -> hard coal | B6: {=IFERROR(INDEX(crosswalk!C:C,MATCH(D6,crosswalk!B:B,0)),"")} -> construction 41T43 | C6: hard coal | D6: construction 41T43 | E6: 0
A7: =C7 -> hard coal | B7: {=IFERROR(INDEX(crosswalk!C:C,MATCH(D7,crosswalk!B:B,0)),"")} -> energy pipelines and gas processing 352T353 | C7: hard coal | D7: energy pipelines and gas processing 352T353 | E7: 0
A8: =C8 -> hard coal | B8: {=IFERROR(INDEX(crosswalk!C:C,MATCH(D8,crosswalk!B:B,0)),"")} -> food beverage and tobacco 10T12 | C8: hard coal | D8: food beverage and tobacco 1T12 | E8: 0
A9: =C9 -> hard coal | B9: {=IFERROR(INDEX(crosswalk!C:C,MATCH(D9,crosswalk!B:B,0)),"")} -> iron and steel 241 | C9: hard coal | D9: iron and steel 241 | E9: 0
A10: =C10 -> hard coal | B10: {=IFERROR(INDEX(crosswalk!C:C,MATCH(D10,crosswalk!B:B,0)),"")} -> metal products except machinery and vehicles 25 | C10: hard coal | D10: metal products except machinery and vehicles 25, computers and electronics 26, appliances and electrical equipment 27, and other machinery 28 | E10: 0
A11: =C11 -> hard coal | B11: {=IFERROR(INDEX(crosswalk!C:C,MATCH(D11,crosswalk!B:B,0)),"")} -> oil and gas extraction 06 | C11: hard coal | D11: oil and gas extraction 06 | E11: 0
A12: =C12 -> hard coal | B12: {=IFERROR(INDEX(crosswalk!C:C,MATCH(D12,crosswalk!B:B,0)),"")} -> other manufacturing 31T33 | C12: hard coal | D12: other manufacturing 31T33 and rubber and plastic products 22 | E12: 0
A13: =C13 -> hard coal | B13: {=IFERROR(INDEX(crosswalk!C:C,MATCH(D13,crosswalk!B:B,0)),"")} -> other metals 242 | C13: hard coal | D13: other metals 242 | E13: 0
... A19: =C19 -> hard coal | B19: {=IFERROR(INDEX(crosswalk!C:C,MATCH(D19,crosswalk!B:B,0)),"")} -> wood products 16 | C19: hard coal | D19: wood products 16 | E19: 0
A20: =C20 -> 0 | B20: {=IFERROR(INDEX(crosswalk!C:C,MATCH(D20,crosswalk!B:B,0)),"")}
A21: =C21 -> natural gas | B21: {=IFERROR(INDEX(crosswalk!C:C,MATCH(D21,crosswalk!B:B,0)),"")} -> agriculture and forestry 01T03 | C21: natural gas | D21: agriculture and forestry 1T3 | E21: 0
A22: =C22 -> natural gas | B22: {=IFERROR(INDEX(crosswalk!C:C,MATCH(D22,crosswalk!B:B,0)),"")} -> cement and other nonmetallic minerals 239 | C22: natural gas | D22: cement and other nonmetallic minerals 239 & glass and glass products 231 | E22: 0
A23: =C23 -> natural gas | B23: {=IFERROR(INDEX(crosswalk!C:C,MATCH(D23,crosswalk!B:B,0)),"")} -> chemicals 20 | C23: natural gas | D23: chemicals 2 | E23: 1.3440457e+14
A24: =C24 -> natural gas | B24: {=IFERROR(INDEX(crosswalk!C:C,MATCH(D24,crosswalk!B:B,0)),"")} -> coal mining 05 | C24: natural gas | D24: coal mining 05 | E24: 0
A25: =C25 -> natural gas | B25: {=IFERROR(INDEX(crosswalk!C:C,MATCH(D25,crosswalk!B:B,0)),"")} -> construction 41T43 | C25: natural gas | D25: construction 41T43 | E25: 0
A26: =C26 -> natural gas | B26: {=IFERROR(INDEX(crosswalk!C:C,MATCH(D26,crosswalk!B:B,0)),"")} -> energy pipelines and gas processing 352T353 | C26: natural gas | D26: energy pipelines and gas processing 352T353 | E26: 0
A27: =C27 -> natural gas | B27: {=IFERROR(INDEX(crosswalk!C:C,MATCH(D27,crosswalk!B:B,0)),"")} -> food beverage and tobacco 10T12 | C27: natural gas | D27: food beverage and tobacco 1T12 | E27: 0
A28: =C28 -> natural gas | B28: {=IFERROR(INDEX(crosswalk!C:C,MATCH(D28,crosswalk!B:B,0)),"")} -> iron and steel 241 | C28: natural gas | D28: iron and steel 241 | E28: 0
A29: =C29 -> natural gas | B29: {=IFERROR(INDEX(crosswalk!C:C,MATCH(D29,crosswalk!B:B,0)),"")} -> metal products except machinery and vehicles 25 | C29: natural gas | D29: metal products except machinery and vehicles 25, computers and electronics 26, appliances and electrical equipment 27, and other machinery 28 | E29: 0
A30: =C30 -> natural gas | B30: {=IFERROR(INDEX(crosswalk!C:C,MATCH(D30,crosswalk!B:B,0)),"")} -> oil and gas extraction 06 | C30: natural gas | D30: oil and gas extraction 06 | E30: 0
A31: =C31 -> natural gas | B31: {=IFERROR(INDEX(crosswalk!C:C,MATCH(D31,crosswalk!B:B,0)),"")} -> other manufacturing 31T33 | C31: natural gas | D31: other manufacturing 31T33 and rubber and plastic products 22 | E31: 0
A32: =C32 -> natural gas | B32: {=IFERROR(INDEX(crosswalk!C:C,MATCH(D32,crosswalk!B:B,0)),"")} -> other metals 242 | C32: natural gas | D32: other metals 242 | E32: 0
... A38: =C38 -> natural gas | B38: {=IFERROR(INDEX(crosswalk!C:C,MATCH(D38,crosswalk!B:B,0)),"")} -> wood products 16 | C38: natural gas | D38: wood products 16 | E38: 0
A39: =C39 -> 0 | B39: {=IFERROR(INDEX(crosswalk!C:C,MATCH(D39,crosswalk!B:B,0)),"")}
A40: =C40 -> crude oil | B40: {=IFERROR(INDEX(crosswalk!C:C,MATCH(D40,crosswalk!B:B,0)),"")} -> agriculture and forestry 01T03 | C40: crude oil | D40: agriculture and forestry 1T3 | E40: 0
A41: =C41 -> crude oil | B41: {=IFERROR(INDEX(crosswalk!C:C,MATCH(D41,crosswalk!B:B,0)),"")} -> cement and other nonmetallic minerals 239 | C41: crude oil | D41: cement and other nonmetallic minerals 239 & glass and glass products 231 | E41: 0
A42: =C42 -> crude oil | B42: {=IFERROR(INDEX(crosswalk!C:C,MATCH(D42,crosswalk!B:B,0)),"")} -> chemicals 20 | C42: crude oil | D42: chemicals 2 | E42: 86482790144000
A43: =C43 -> crude oil | B43: {=IFERROR(INDEX(crosswalk!C:C,MATCH(D43,crosswalk!B:B,0)),"")} -> coal mining 05 | C43: crude oil | D43: coal mining 05 | E43: 0
A44: =C44 -> crude oil | B44: {=IFERROR(INDEX(crosswalk!C:C,MATCH(D44,crosswalk!B:B,0)),"")} -> construction 41T43 | C44: crude oil | D44: construction 41T43 | E44: 0
A45: =C45 -> crude oil | B45: {=IFERROR(INDEX(crosswalk!C:C,MATCH(D45,crosswalk!B:B,0)),"")} -> energy pipelines and gas processing 352T353 | C45: crude oil | D45: energy pipelines and gas processing 352T353 | E45: 0
A46: =C46 -> crude oil | B46: {=IFERROR(INDEX(crosswalk!C:C,MATCH(D46,crosswalk!B:B,0)),"")} -> food beverage and tobacco 10T12 | C46: crude oil | D46: food beverage and tobacco 1T12 | E46: 0
A47: =C47 -> crude oil | B47: {=IFERROR(INDEX(crosswalk!C:C,MATCH(D47,crosswalk!B:B,0)),"")} -> iron and steel 241 | C47: crude oil | D47: iron and steel 241 | E47: 0
A48: =C48 -> crude oil | B48: {=IFERROR(INDEX(crosswalk!C:C,MATCH(D48,crosswalk!B:B,0)),"")} -> metal products except machinery and vehicles 25 | C48: crude oil | D48: metal products except machinery and vehicles 25, computers and electronics 26, appliances and electrical equipment 27, and other machinery 28 | E48: 0
A49: =C49 -> crude oil | B49: {=IFERROR(INDEX(crosswalk!C:C,MATCH(D49,crosswalk!B:B,0)),"")} -> oil and gas extraction 06 | C49: crude oil | D49: oil and gas extraction 06 | E49: 0
A50: =C50 -> crude oil | B50: {=IFERROR(INDEX(crosswalk!C:C,MATCH(D50,crosswalk!B:B,0)),"")} -> other manufacturing 31T33 | C50: crude oil | D50: other manufacturing 31T33 and rubber and plastic products 22 | E50: 0
...

Sheet China BFPIaE-production
A1: Fuel (BTU) | B1: 2017 | C1: 2018 | D1: 2019 | E1: 2020 | F1: 2021 | G1: 2022 | H1: 2023 | I1: 2024 | J1: 2025 | K1: 2026 | L1: 2027 | M1: 2028 | N1: 2029 | O1: 2030 | P1: 2031 | Q1: 2032 | R1: 2033 | S1: 2034 | T1: 2035 | U1: 2036 | V1: 2037 | W1: 2038 | X1: 2039 | Y1: 2040 | Z1: 2041 | AA1: 2042 | AB1: 2043 | AC1: 2044 | AD1: 2045 | AE1: 2046 | AF1: 2047 | AG1: 2048 | AH1: 2049 | AI1: 2050 | AJ1: 2051 | AK1: 2052 | AL1: 2053 | AM1: 2054 | AN1: 2055 | AO1: 2056 | AP1: 2057 | AQ1: 2058 | AR1: 2059 | AS1: 2060
A2: electricity (not used in this variable) | B2: 0 | C2: 0 | D2: 0 | E2: 0 | F2: 0 | G2: 0 | H2: 0 | I2: 0 | J2: 0 | K2: 0 | L2: 0 | M2: 0 | N2: 0 | O2: 0 | P2: 0 | Q2: 0 | R2: 0 | S2: 0 | T2: 0 | U2: 0 | V2: 0 | W2: 0 | X2: 0 | Y2: 0 | Z2: 0 | AA2: 0 | AB2: 0 | AC2: 0 | AD2: 0 | AE2: 0 | AF2: 0 | AG2: 0 | AH2: 0 | AI2: 0 | AJ2: {=TREND(AE2:AI2,AE$1:AI$1,AJ$1)} -> 0 | AK2: {=TREND(AF2:AJ2,AF$1:AJ$1,AK$1)} -> 0 | AL2: {=TREND(AG2:AK2,AG$1:AK$1,AL$1)} -> 0 | AM2: {=TREND(AH2:AL2,AH$1:AL$1,AM$1)} -> 0 | AN2: {=TREND(AI2:AM2,AI$1:AM$1,AN$1)} -> 0 | AO2: {=TREND(AJ2:AN2,AJ$1:AN$1,AO$1)} -> 0 | AP2: {=TREND(AK2:AO2,AK$1:AO$1,AP$1)} -> 0 | AQ2: {=TREND(AL2:AP2,AL$1:AP$1,AQ$1)} -> 0 | ... AS2: {=TREND(AN2:AR2,AN$1:AR$1,AS$1)} -> 0
A3: hard coal | B3: 6.9332359e+16 | C3: 6.9662954e+16 | D3: 6.9993549e+16 | E3: 7.0324145e+16 | F3: 7.065474e+16 | G3: 7.0985335e+16 | H3: 7.131593e+16 | I3: 7.1646526e+16 | J3: 7.1977121e+16 | K3: 7.1882458e+16 | L3: 7.1787919e+16 | M3: 7.1693505e+16 | N3: 7.1599215e+16 | O3: 7.1505049e+16 | P3: 7.1106307e+16 | Q3: 7.0709789e+16 | R3: 7.0315483e+16 | S3: 6.9923375e+16 | T3: 6.9533453e+16 | U3: 6.8755364e+16 | V3: 6.7985982e+16 | W3: 6.7225209e+16 | X3: 6.6472949e+16 | Y3: 6.5729107e+16 | Z3: 6.4993589e+16 | AA3: 6.4266301e+16 | AB3: 6.3547152e+16 | AC3: 6.283605e+16 | AD3: 6.2132906e+16 | AE3: 6.143763e+16 | AF3: 6.0750134e+16 | AG3: 6.0070331e+16 | AH3: 5.9398135e+16 | AI3: 5.8733462e+16 | AJ3: {=TREND(AE3:AI3,AE$1:AI$1,AJ$1)} -> 5.8049838e+16 | AK3: {=TREND(AF3:AJ3,AF$1:AJ$1,AK$1)} -> 5.7379142e+16 | AL3: {=TREND(AG3:AK3,AG$1:AK$1,AL$1)} -> 5.6706979e+16 | AM3: {=TREND(AH3:AL3,AH$1:AL$1,AM$1)} -> 5.6032521e+16 | AN3: {=TREND(AI3:AM3,AI$1:AM$1,AN$1)} -> 5.5356966e+16 | AO3: {=TREND(AJ3:AN3,AJ$1:AN$1,AO$1)} -> 5.468538e+16 | AP3: {=TREND(AK3:AO3,AK$1:AO$1,AP$1)} -> 5.4010937e+16 | AQ3: {=TREND(AL3:AP3,AL$1:AP$1,AQ$1)} -> 5.3336789e+16 | ... AS3: {=TREND(AN3:AR3,AN$1:AR$1,AS$1)} -> 5.1989874e+16
A4: natural gas | B4: 5.9027487e+15 | C4: 6.10117e+15 | D4: 6.2995913e+15 | E4: 6.4980126e+15 | F4: 6.6964339e+15 | G4: 6.8948552e+15 | H4: 7.0932765e+15 | I4: 7.2916978e+15 | J4: 7.4901192e+15 | K4: 7.7365303e+15 | L4: 7.991048e+15 | M4: 8.2539388e+15 | N4: 8.5254783e+15 | O4: 8.8059509e+15 | P4: 9.0425602e+15 | Q4: 9.2855271e+15 | R4: 9.5350223e+15 | S4: 9.7912213e+15 | T4: 1.0054304e+16 | U4: 1.0298563e+16 | V4: 1.0548755e+16 | W4: 1.0805026e+16 | X4: 1.1067523e+16 | Y4: 1.1336397e+16 | Z4: 1.1611802e+16 | AA4: 1.1893899e+16 | AB4: 1.2182848e+16 | AC4: 1.2478818e+16 | AD4: 1.2781977e+16 | AE4: 1.3092502e+16 | AF4: 1.341057e+16 | AG4: 1.3736366e+16 | AH4: 1.4070076e+16 | AI4: 1.4411894e+16 | AJ4: {=TREND(AE4:AI4,AE$1:AI$1,AJ$1)} -> 1.4733769e+16 | AK4: {=TREND(AF4:AJ4,AF$1:AJ$1,AK$1)} -> 1.5069112e+16 | AL4: {=TREND(AG4:AK4,AG$1:AK$1,AL$1)} -> 1.5402999e+16 | AM4: {=TREND(AH4:AL4,AH$1:AL$1,AM$1)} -> 1.5734489e+16 | AN4: {=TREND(AI4:AM4,AI$1:AM$1,AN$1)} -> 1.6064779e+16 | AO4: {=TREND(AJ4:AN4,AJ$1:AN$1,AO$1)} -> 1.6399249e+16 | AP4: {=TREND(AK4:AO4,AK$1:AO$1,AP$1)} -> 1.6730742e+16 | AQ4: {=TREND(AL4:AP4,AL$1:AP$1,AQ$1)} -> 1.7062525e+16 | ... AS4: {=TREND(AN4:AR4,AN$1:AR$1,AS$1)} -> 1.7727548e+16
A5: nuclear | B5: 1.0211464e+15 | C5: 1.2689735e+15 | D5: 1.4192524e+15 | E5: 1.5873282e+15 | F5: 1.6148422e+15 | G5: 1.6428331e+15 | H5: 1.6713092e+15 | I5: 1.7002789e+15 | J5: 1.7297508e+15 | K5: 1.7597335e+15 | L5: 1.7902359e+15 | M5: 1.821267e+15 | N5: 1.852836e+15 | O5: 1.8849522e+15 | P5: 2.8764377e+15 | Q5: 2.9262965e+15 | R5: 2.9770196e+15 | S5: 3.0286219e+15 | T5: 3.0811186e+15 | U5: 3.1345253e+15 | V5: 3.1888577e+15 | W5: 3.2441319e+15 | X5: 3.3003642e+15 | Y5: 3.3575711e+15 | Z5: 4.4767615e+15 | AA5: 4.4767615e+15 | AB5: 4.4767615e+15 | AC5: 4.4767615e+15 | AD5: 4.4767615e+15 | AE5: 4.4767615e+15 | AF5: 4.4767615e+15 | AG5: 4.4767615e+15 | AH5: 4.4767615e+15 | AI5: 4.4767615e+15 | AJ5: {=TREND(AE5:AI5,AE$1:AI$1,AJ$1)} -> 4.4767615e+15 | AK5: {=TREND(AF5:AJ5,AF$1:AJ$1,AK$1)} -> 4.4767615e+15 | AL5: {=TREND(AG5:AK5,AG$1:AK$1,AL$1)} -> 4.4767615e+15 | AM5: {=TREND(AH5:AL5,AH$1:AL$1,AM$1)} -> 4.4767615e+15 | AN5: {=TREND(AI5:AM5,AI$1:AM$1,AN$1)} -> 4.4767615e+15 | AO5: {=TREND(AJ5:AN5,AJ$1:AN$1,AO$1)} -> 4.4767615e+15 | AP5: {=TREND(AK5:AO5,AK$1:AO$1,AP$1)} -> 4.4767615e+15 | AQ5: {=TREND(AL5:AP5,AL$1:AP$1,AQ$1)} -> 4.4767615e+15 | ... AS5: {=TREND(AN5:AR5,AN$1:AR$1,AS$1)} -> 4.4767615e+15
A6: hydro (is not a fuel) | B6: 0 | C6: 0 | D6: 0 | E6: 0 | F6: 0 | G6: 0 | H6: 0 | I6: 0 | J6: 0 | K6: 0 | L6: 0 | M6: 0 | N6: 0 | O6: 0 | P6: 0 | Q6: 0 | R6: 0 | S6: 0 | T6: 0 | U6: 0 | V6: 0 | W6: 0 | X6: 0 | Y6: 0 | Z6: 0 | AA6: 0 | AB6: 0 | AC6: 0 | AD6: 0 | AE6: 0 | AF6: 0 | AG6: 0 | AH6: 0 | AI6: 0 | AJ6: {=TREND(AE6:AI6,AE$1:AI$1,AJ$1)} -> 0 | AK6: {=TREND(AF6:AJ6,AF$1:AJ$1,AK$1)} -> 0 | AL6: {=TREND(AG6:AK6,AG$1:AK$1,AL$1)} -> 0 | AM6: {=TREND(AH6:AL6,AH$1:AL$1,AM$1)} -> 0 | AN6: {=TREND(AI6:AM6,AI$1:AM$1,AN$1)} -> 0 | AO6: {=TREND(AJ6:AN6,AJ$1:AN$1,AO$1)} -> 0 | AP6: {=TREND(AK6:AO6,AK$1:AO$1,AP$1)} -> 0 | AQ6: {=TREND(AL6:AP6,AL$1:AP$1,AQ$1)} -> 0 | ... AS6: {=TREND(AN6:AR6,AN$1:AR$1,AS$1)} -> 0
A7: wind (is not a fuel) | B7: 0 | C7: 0 | D7: 0 | E7: 0 | F7: 0 | G7: 0 | H7: 0 | I7: 0 | J7: 0 | K7: 0 | L7: 0 | M7: 0 | N7: 0 | O7: 0 | P7: 0 | Q7: 0 | R7: 0 | S7: 0 | T7: 0 | U7: 0 | V7: 0 | W7: 0 | X7: 0 | Y7: 0 | Z7: 0 | AA7: 0 | AB7: 0 | AC7: 0 | AD7: 0 | AE7: 0 | AF7: 0 | AG7: 0 | AH7: 0 | AI7: 0 | AJ7: {=TREND(AE7:AI7,AE$1:AI$1,AJ$1)} -> 0 | AK7: {=TREND(AF7:AJ7,AF$1:AJ$1,AK$1)} -> 0 | AL7: {=TREND(AG7:AK7,AG$1:AK$1,AL$1)} -> 0 | AM7: {=TREND(AH7:AL7,AH$1:AL$1,AM$1)} -> 0 | AN7: {=TREND(AI7:AM7,AI$1:AM$1,AN$1)} -> 0 | AO7: {=TREND(AJ7:AN7,AJ$1:AN$1,AO$1)} -> 0 | AP7: {=TREND(AK7:AO7,AK$1:AO$1,AP$1)} -> 0 | AQ7: {=TREND(AL7:AP7,AL$1:AP$1,AQ$1)} -> 0 | ... AS7: {=TREND(AN7:AR7,AN$1:AR$1,AS$1)} -> 0
A8: solar (is not a fuel) | B8: 0 | C8: 0 | D8: 0 | E8: 0 | F8: 0 | G8: 0 | H8: 0 | I8: 0 | J8: 0 | K8: 0 | L8: 0 | M8: 0 | N8: 0 | O8: 0 | P8: 0 | Q8: 0 | R8: 0 | S8: 0 | T8: 0 | U8: 0 | V8: 0 | W8: 0 | X8: 0 | Y8: 0 | Z8: 0 | AA8: 0 | AB8: 0 | AC8: 0 | AD8: 0 | AE8: 0 | AF8: 0 | AG8: 0 | AH8: 0 | AI8: 0 | AJ8: {=TREND(AE8:AI8,AE$1:AI$1,AJ$1)} -> 0 | AK8: {=TREND(AF8:AJ8,AF$1:AJ$1,AK$1)} -> 0 | AL8: {=TREND(AG8:AK8,AG$1:AK$1,AL$1)} -> 0 | AM8: {=TREND(AH8:AL8,AH$1:AL$1,AM$1)} -> 0 | AN8: {=TREND(AI8:AM8,AI$1:AM$1,AN$1)} -> 0 | AO8: {=TREND(AJ8:AN8,AJ$1:AN$1,AO$1)} -> 0 | AP8: {=TREND(AK8:AO8,AK$1:AO$1,AP$1)} -> 0 | AQ8: {=TREND(AL8:AP8,AL$1:AP$1,AQ$1)} -> 0 | ... AS8: {=TREND(AN8:AR8,AN$1:AR$1,AS$1)} -> 0
A9: biomass | B9: 0 | C9: =$B$9 -> 0 | D9: =$B$9 -> 0 | E9: =$B$9 -> 0 | F9: =$B$9 -> 0 | G9: =$B$9 -> 0 | H9: =$B$9 -> 0 | I9: =$B$9 -> 0 | J9: =$B$9 -> 0 | ... AI9: =$B$9 -> 0 | AJ9: {=TREND(AE9:AI9,AE$1:AI$1,AJ$1)} -> 0 | AK9: {=TREND(AF9:AJ9,AF$1:AJ$1,AK$1)} -> 0 | AL9: {=TREND(AG9:AK9,AG$1:AK$1,AL$1)} -> 0 | AM9: {=TREND(AH9:AL9,AH$1:AL$1,AM$1)} -> 0 | AN9: {=TREND(AI9:AM9,AI$1:AM$1,AN$1)} -> 0 | AO9: {=TREND(AJ9:AN9,AJ$1:AN$1,AO$1)} -> 0 | AP9: {=TREND(AK9:AO9,AK$1:AO$1,AP$1)} -> 0 | AQ9: {=TREND(AL9:AP9,AL$1:AP$1,AQ$1)} -> 0 | ... AS9: {=TREND(AN9:AR9,AN$1:AR$1,AS$1)} -> 0
A10: petroleum gasoline | B10: 7.0098085e+16 | C10: 7.0330255e+16 | D10: 7.0563194e+16 | E10: 7.0796905e+16 | F10: 7.103139e+16 | G10: 7.1266651e+16 | H10: 7.1502692e+16 | I10: 7.1739514e+16 | J10: 7.1977121e+16 | K10: 7.1882458e+16 | L10: 7.1787919e+16 | M10: 7.1693505e+16 | N10: 7.1599215e+16 | O10: 7.1505049e+16 | P10: 7.1106307e+16 | Q10: 7.0709789e+16 | R10: 7.0315483e+16 | S10: 6.9923375e+16 | T10: 6.9533453e+16 | U10: 6.8755364e+16 | V10: 6.7985982e+16 | W10: 6.7225209e+16 | X10: 6.6472949e+16 | Y10: 6.5729107e+16 | Z10: 6.4993589e+16 | AA10: 6.4266301e+16 | AB10: 6.3547152e+16 | AC10: 6.283605e+16 | AD10: 6.2132906e+16 | AE10: 6.143763e+16 | AF10: 6.0750134e+16 | AG10: 6.0070331e+16 | AH10: 5.9398135e+16 | AI10: 5.8733462e+16 | AJ10: {=TREND(AE10:AI10,AE$1:AI$1,AJ$1)} -> 5.8049838e+16 | AK10: {=TREND(AF10:AJ10,AF$1:AJ$1,AK$1)} -> 5.7379142e+16 | AL10: {=TREND(AG10:AK10,AG$1:AK$1,AL$1)} -> 5.6706979e+16 | AM10: {=TREND(AH10:AL10,AH$1:AL$1,AM$1)} -> 5.6032521e+16 | AN10: {=TREND(AI10:AM10,AI$1:AM$1,AN$1)} -> 5.5356966e+16 | AO10: {=TREND(AJ10:AN10,AJ$1:AN$1,AO$1)} -> 5.468538e+16 | AP10: {=TREND(AK10:AO10,AK$1:AO$1,AP$1)} -> 5.4010937e+16 | AQ10: {=TREND(AL10:AP10,AL$1:AP$1,AQ$1)} -> 5.3336789e+16 | ... AS10: {=TREND(AN10:AR10,AN$1:AR$1,AS$1)} -> 5.1989874e+16
A11: petroleum diesel | B11: 8.3432892e+15 | C11: 8.2204151e+15 | D11: 8.0993506e+15 | E11: 7.9800691e+15 | F11: 7.8625442e+15 | G11: 7.7467502e+15 | H11: 7.6326615e+15 | I11: 7.520253e+15 | J11: 7.4095e+15 | K11: 7.3228153e+15 | L11: 7.2371448e+15 | M11: 7.1524765e+15 | N11: 7.0687988e+15 | O11: 6.9861e+15 | P11: 6.9432373e+15 | Q11: 6.9006375e+15 | R11: 6.8582991e+15 | S11: 6.8162205e+15 | T11: 6.7744e+15 | U11: 6.7315206e+15 | V11: 6.6889126e+15 | W11: 6.6465743e+15 | X11: 6.604504e+15 | Y11: 6.5627e+15 | Z11: 6.5211606e+15 | AA11: 6.4798841e+15 | AB11: 6.4388689e+15 | AC11: 6.3981133e+15 | AD11: 6.3576156e+15 | AE11: 6.3173743e+15 | AF11: 6.2773877e+15 | AG11: 6.2376542e+15 | AH11: 6.1981722e+15 | AI11: 6.1589401e+15 | AJ11: {=TREND(AE11:AI11,AE$1:AI$1,AJ$1)} -> 6.1190806e+15 | AK11: {=TREND(AF11:AJ11,AF$1:AJ$1,AK$1)} -> 6.0796485e+15 | AL11: {=TREND(AG11:AK11,AG$1:AK$1,AL$1)} -> 6.0401682e+15 | AM11: {=TREND(AH11:AL11,AH$1:AL$1,AM$1)} -> 6.000612e+15 | AN11: {=TREND(AI11:AM11,AI$1:AM$1,AN$1)} -> 5.9610192e+15 | AO11: {=TREND(AJ11:AN11,AJ$1:AN$1,AO$1)} -> 5.9215579e+15 | AP11: {=TREND(AK11:AO11,AK$1:AO$1,AP$1)} -> 5.8820022e+15 | AQ11: {=TREND(AL11:AP11,AL$1:AP$1,AQ$1)} -> 5.8424561e+15 | ... AS11: {=TREND(AN11:AR11,AN$1:AR$1,AS$1)} -> 5.7634096e+15
A12: biofuel gasoline | B12: 0 | C12: =$B$12 -> 0 | D12: =$B$12 -> 0 | E12: =$B$12 -> 0 | F12: =$B$12 -> 0 | G12: =$B$12 -> 0 | H12: =$B$12 -> 0 | I12: =$B$12 -> 0 | J12: =$B$12 -> 0 | ... AI12: =$B$12 -> 0 | AJ12: {=TREND(AE12:AI12,AE$1:AI$1,AJ$1)} -> 0 | AK12: {=TREND(AF12:AJ12,AF$1:AJ$1,AK$1)} -> 0 | AL12: {=TREND(AG12:AK12,AG$1:AK$1,AL$1)} -> 0 | AM12: {=TREND(AH12:AL12,AH$1:AL$1,AM$1)} -> 0 | AN12: {=TREND(AI12:AM12,AI$1:AM$1,AN$1)} -> 0 | AO12: {=TREND(AJ12:AN12,AJ$1:AN$1,AO$1)} -> 0 | AP12: {=TREND(AK12:AO12,AK$1:AO$1,AP$1)} -> 0 | AQ12: {=TREND(AL12:AP12,AL$1:AP$1,AQ$1)} -> 0 | ... AS12: {=TREND(AN12:AR12,AN$1:AR$1,AS$1)} -> 0
A13: biofuel diesel | B13: =$B$12 -> 0 | C13: =$B$12 -> 0 | D13: =$B$12 -> 0 | E13: =$B$12 -> 0 | F13: =$B$12 -> 0 | G13: =$B$12 -> 0 | H13: =$B$12 -> 0 | I13: =$B$12 -> 0 | ... AI13: =$B$12 -> 0 | AJ13: {=TREND(AE13:AI13,AE$1:AI$1,AJ$1)} -> 0 | AK13: {=TREND(AF13:AJ13,AF$1:AJ$1,AK$1)} -> 0 | AL13: {=TREND(AG13:AK13,AG$1:AK$1,AL$1)} -> 0 | AM13: {=TREND(AH13:AL13,AH$1:AL$1,AM$1)} -> 0 | AN13: {=TREND(AI13:AM13,AI$1:AM$1,AN$1)} -> 0 | AO13: {=TREND(AJ13:AN13,AJ$1:AN$1,AO$1)} -> 0 | AP13: {=TREND(AK13:AO13,AK$1:AO$1,AP$1)} -> 0 | AQ13: {=TREND(AL13:AP13,AL$1:AP$1,AQ$1)} -> 0 | ... AS13: {=TREND(AN13:AR13,AN$1:AR$1,AS$1)} -> 0
A14: jet fuel or kerosene | B14: 4.8769557e+15 | C14: 5.1456625e+15 | D14: 5.4291743e+15 | E14: 5.7283069e+15 | F14: 6.0439208e+15 | G14: 6.3769242e+15 | H14: 6.7282752e+15 | I14: 7.0989846e+15 | J14: 7.4901192e+15 | K14: 7.7365303e+15 | L14: 7.991048e+15 | M14: 8.2539388e+15 | N14: 8.5254783e+15 | O14: 8.8059509e+15 | P14: 9.0425602e+15 | Q14: 9.2855271e+15 | R14: 9.5350223e+15 | S14: 9.7912213e+15 | T14: 1.0054304e+16 | U14: 1.0298563e+16 | V14: 1.0548755e+16 | W14: 1.0805026e+16 | X14: 1.1067523e+16 | Y14: 1.1336397e+16 | Z14: 1.1611802e+16 | AA14: 1.1893899e+16 | AB14: 1.2182848e+16 | AC14: 1.2478818e+16 | AD14: 1.2781977e+16 | AE14: 1.3092502e+16 | AF14: 1.341057e+16 | AG14: 1.3736366e+16 | AH14: 1.4070076e+16 | AI14: 1.4411894e+16 | AJ14: {=TREND(AE14:AI14,AE$1:AI$1,AJ$1)} -> 1.4733769e+16 | AK14: {=TREND(AF14:AJ14,AF$1:AJ$1,AK$1)} -> 1.5069112e+16 | AL14: {=TREND(AG14:AK14,AG$1:AK$1,AL$1)} -> 1.5402999e+16 | AM14: {=TREND(AH14:AL14,AH$1:AL$1,AM$1)} -> 1.5734489e+16 | AN14: {=TREND(AI14:AM14,AI$1:AM$1,AN$1)} -> 1.6064779e+16 | AO14: {=TREND(AJ14:AN14,AJ$1:AN$1,AO$1)} -> 1.6399249e+16 | AP14: {=TREND(AK14:AO14,AK$1:AO$1,AP$1)} -> 1.6730742e+16 | AQ14: {=TREND(AL14:AP14,AL$1:AP$1,AQ$1)} -> 1.7062525e+16 | ... AS14: {=TREND(AN14:AR14,AN$1:AR$1,AS$1)} -> 1.7727548e+16
A15: heat (not used in this variable) | B15: 0 | C15: 0 | D15: 0 | E15: 0 | F15: 0 | G15: 0 | H15: 0 | I15: 0 | J15: 0 | K15: 0 | L15: 0 | M15: 0 | N15: 0 | O15: 0 | P15: 0 | Q15: 0 | R15: 0 | S15: 0 | T15: 0 | U15: 0 | V15: 0 | W15: 0 | X15: 0 | Y15: 0 | Z15: 0 | AA15: 0 | AB15: 0 | AC15: 0 | AD15: 0 | AE15: 0 | AF15: 0 | AG15: 0 | AH15: 0 | AI15: 0 | AJ15: {=TREND(AE15:AI15,AE$1:AI$1,AJ$1)} -> 0 | AK15: {=TREND(AF15:AJ15,AF$1:AJ$1,AK$1)} -> 0 | AL15: {=TREND(AG15:AK15,AG$1:AK$1,AL$1)} -> 0 | AM15: {=TREND(AH15:AL15,AH$1:AL$1,AM$1)} -> 0 | AN15: {=TREND(AI15:AM15,AI$1:AM$1,AN$1)} -> 0 | AO15: {=TREND(AJ15:AN15,AJ$1:AN$1,AO$1)} -> 0 | AP15: {=TREND(AK15:AO15,AK$1:AO$1,AP$1)} -> 0 | AQ15: {=TREND(AL15:AP15,AL$1:AP$1,AQ$1)} -> 0 | ... AS15: {=TREND(AN15:AR15,AN$1:AR$1,AS$1)} -> 0
A16: geothermal (is not a fuel) | B16: 0 | C16: 0 | D16: 0 | E16: 0 | F16: 0 | G16: 0 | H16: 0 | I16: 0 | J16: 0 | K16: 0 | L16: 0 | M16: 0 | N16: 0 | O16: 0 | P16: 0 | Q16: 0 | R16: 0 | S16: 0 | T16: 0 | U16: 0 | V16: 0 | W16: 0 | X16: 0 | Y16: 0 | Z16: 0 | AA16: 0 | AB16: 0 | AC16: 0 | AD16: 0 | AE16: 0 | AF16: 0 | AG16: 0 | AH16: 0 | AI16: 0 | AJ16: {=TREND(AE16:AI16,AE$1:AI$1,AJ$1)} -> 0 | AK16: {=TREND(AF16:AJ16,AF$1:AJ$1,AK$1)} -> 0 | AL16: {=TREND(AG16:AK16,AG$1:AK$1,AL$1)} -> 0 | AM16: {=TREND(AH16:AL16,AH$1:AL$1,AM$1)} -> 0 | AN16: {=TREND(AI16:AM16,AI$1:AM$1,AN$1)} -> 0 | AO16: {=TREND(AJ16:AN16,AJ$1:AN$1,AO$1)} -> 0 | AP16: {=TREND(AK16:AO16,AK$1:AO$1,AP$1)} -> 0 | AQ16: {=TREND(AL16:AP16,AL$1:AP$1,AQ$1)} -> 0 | ... AS16: {=TREND(AN16:AR16,AN$1:AR$1,AS$1)} -> 0
A17: lignite | B17: 0 | C17: 0 | D17: 0 | E17: 0 | F17: 0 | G17: 0 | H17: 0 | I17: 0 | J17: 0 | K17: 0 | L17: 0 | M17: 0 | N17: 0 | O17: 0 | P17: 0 | Q17: 0 | R17: 0 | S17: 0 | T17: 0 | U17: 0 | V17: 0 | W17: 0 | X17: 0 | Y17: 0 | Z17: 0 | AA17: 0 | AB17: 0 | AC17: 0 | AD17: 0 | AE17: 0 | AF17: 0 | AG17: 0 | AH17: 0 | AI17: 0 | AJ17: {=TREND(AE17:AI17,AE$1:AI$1,AJ$1)} -> 0 | AK17: {=TREND(AF17:AJ17,AF$1:AJ$1,AK$1)} -> 0 | AL17: {=TREND(AG17:AK17,AG$1:AK$1,AL$1)} -> 0 | AM17: {=TREND(AH17:AL17,AH$1:AL$1,AM$1)} -> 0 | AN17: {=TREND(AI17:AM17,AI$1:AM$1,AN$1)} -> 0 | AO17: {=TREND(AJ17:AN17,AJ$1:AN$1,AO$1)} -> 0 | AP17: {=TREND(AK17:AO17,AK$1:AO$1,AP$1)} -> 0 | AQ17: {=TREND(AL17:AP17,AL$1:AP$1,AQ$1)} -> 0 | ... AS17: {=TREND(AN17:AR17,AN$1:AR$1,AS$1)} -> 0
A18: crude oil | B18: 7.5971851e+15 | C18: 7.5737245e+15 | D18: 7.5502638e+15 | E18: 7.5268032e+15 | F18: 7.5033426e+15 | G18: 7.4798819e+15 | H18: 7.4564213e+15 | I18: 7.4329606e+15 | J18: 7.4095e+15 | K18: 7.3228153e+15 | L18: 7.2371448e+15 | M18: 7.1524765e+15 | N18: 7.0687988e+15 | O18: 6.9861e+15 | P18: 6.9432373e+15 | Q18: 6.9006375e+15 | R18: 6.8582991e+15 | S18: 6.8162205e+15 | T18: 6.7744e+15 | U18: 6.7315206e+15 | V18: 6.6889126e+15 | W18: 6.6465743e+15 | X18: 6.604504e+15 | Y18: 6.5627e+15 | Z18: 6.5211606e+15 | AA18: 6.4798841e+15 | AB18: 6.4388689e+15 | AC18: 6.3981133e+15 | AD18: 6.3576156e+15 | AE18: 6.3173743e+15 | AF18: 6.2773877e+15 | AG18: 6.2376542e+15 | AH18: 6.1981722e+15 | AI18: 6.1589401e+15 | AJ18: {=TREND(AE18:AI18,AE$1:AI$1,AJ$1)} -> 6.1190806e+15 | AK18: {=TREND(AF18:AJ18,AF$1:AJ$1,AK$1)} -> 6.0796485e+15 | AL18: {=TREND(AG18:AK18,AG$1:AK$1,AL$1)} -> 6.0401682e+15 | AM18: {=TREND(AH18:AL18,AH$1:AL$1,AM$1)} -> 6.000612e+15 | AN18: {=TREND(AI18:AM18,AI$1:AM$1,AN$1)} -> 5.9610192e+15 | AO18: {=TREND(AJ18:AN18,AJ$1:AN$1,AO$1)} -> 5.9215579e+15 | AP18: {=TREND(AK18:AO18,AK$1:AO$1,AP$1)} -> 5.8820022e+15 | AQ18: {=TREND(AL18:AP18,AL$1:AP$1,AQ$1)} -> 5.8424561e+15 | ... AS18: {=TREND(AN18:AR18,AN$1:AR$1,AS$1)} -> 5.7634096e+15
A19: heavy fuel oil | B19: 1.2423759e+16 | C19: =$B$19 -> 1.2423759e+16 | D19: =$B$19 -> 1.2423759e+16 | E19: =$B$19 -> 1.2423759e+16 | F19: =$B$19 -> 1.2423759e+16 | G19: =$B$19 -> 1.2423759e+16 | H19: =$B$19 -> 1.2423759e+16 | I19: =$B$19 -> 1.2423759e+16 | J19: =$B$19 -> 1.2423759e+16 | ... AI19: =$B$19 -> 1.2423759e+16 | AJ19: {=TREND(AE19:AI19,AE$1:AI$1,AJ$1)} -> 1.2423759e+16 | AK19: {=TREND(AF19:AJ19,AF$1:AJ$1,AK$1)} -> 1.2423759e+16 | AL19: {=TREND(AG19:AK19,AG$1:AK$1,AL$1)} -> 1.2423759e+16 | AM19: {=TREND(AH19:AL19,AH$1:AL$1,AM$1)} -> 1.2423759e+16 | AN19: {=TREND(AI19:AM19,AI$1:AM$1,AN$1)} -> 1.2423759e+16 | AO19: {=TREND(AJ19:AN19,AJ$1:AN$1,AO$1)} -> 1.2423759e+16 | AP19: {=TREND(AK19:AO19,AK$1:AO$1,AP$1)} -> 1.2423759e+16 | AQ19: {=TREND(AL19:AP19,AL$1:AP$1,AQ$1)} -> 1.2423759e+16 | ... AS19: {=TREND(AN19:AR19,AN$1:AR$1,AS$1)} -> 1.2423759e+16
A20: LPG propane or butane | B20: 1.7435125e+15 | C20: =$B$20 -> 1.7435125e+15 | D20: =$B$20 -> 1.7435125e+15 | E20: =$B$20 -> 1.7435125e+15 | F20: =$B$20 -> 1.7435125e+15 | G20: =$B$20 -> 1.7435125e+15 | H20: =$B$20 -> 1.7435125e+15 | I20: =$B$20 -> 1.7435125e+15 | J20: =$B$20 -> 1.7435125e+15 | ... AI20: =$B$20 -> 1.7435125e+15 | AJ20: {=TREND(AE20:AI20,AE$1:AI$1,AJ$1)} -> 1.7435125e+15 | AK20: {=TREND(AF20:AJ20,AF$1:AJ$1,AK$1)} -> 1.7435125e+15 | AL20: {=TREND(AG20:AK20,AG$1:AK$1,AL$1)} -> 1.7435125e+15 | AM20: {=TREND(AH20:AL20,AH$1:AL$1,AM$1)} -> 1.7435125e+15 | AN20: {=TREND(AI20:AM20,AI$1:AM$1,AN$1)} -> 1.7435125e+15 | AO20: {=TREND(AJ20:AN20,AJ$1:AN$1,AO$1)} -> 1.7435125e+15 | AP20: {=TREND(AK20:AO20,AK$1:AO$1,AP$1)} -> 1.7435125e+15 | AQ20: {=TREND(AL20:AP20,AL$1:AP$1,AQ$1)} -> 1.7435125e+15 | ... AS20: {=TREND(AN20:AR20,AN$1:AR$1,AS$1)} -> 1.7435125e+15
A21: municipal solid waste | B21: 0 | C21: =$B$21 -> 0 | D21: =$B$21 -> 0 | E21: =$B$21 -> 0 | F21: =$B$21 -> 0 | G21: =$B$21 -> 0 | H21: =$B$21 -> 0 | I21: =$B$21 -> 0 | J21: =$B$21 -> 0 | ... AI21: =$B$21 -> 0 | AJ21: {=TREND(AE21:AI21,AE$1:AI$1,AJ$1)} -> 0 | AK21: {=TREND(AF21:AJ21,AF$1:AJ$1,AK$1)} -> 0 | AL21: {=TREND(AG21:AK21,AG$1:AK$1,AL$1)} -> 0 | AM21: {=TREND(AH21:AL21,AH$1:AL$1,AM$1)} -> 0 | AN21: {=TREND(AI21:AM21,AI$1:AM$1,AN$1)} -> 0 | AO21: {=TREND(AJ21:AN21,AJ$1:AN$1,AO$1)} -> 0 | AP21: {=TREND(AK21:AO21,AK$1:AO$1,AP$1)} -> 0 | AQ21: {=TREND(AL21:AP21,AL$1:AP$1,AQ$1)} -> 0 | ... AS21: {=TREND(AN21:AR21,AN$1:AR$1,AS$1)} -> 0
A22: hydrogen | B22: 2.181951e+15 | C22: 2.39274e+15 | D22: 2.8485e+15 | E22: 2.9369773e+15 | F22: 3.0282028e+15 | G22: 3.1222619e+15 | H22: 3.2192425e+15 | I22: 3.3192354e+15 | J22: 3.4223343e+15 | K22: 3.5286354e+15 | L22: 3.6382384e+15 | M22: 3.7512458e+15 | N22: 3.8677633e+15 | O22: 3.9879e+15 | P22: 4.0968345e+15 | Q22: 4.2087447e+15 | R22: 4.3237118e+15 | S22: 4.4418194e+15 | T22: 4.5631533e+15 | U22: 4.6878016e+15 | V22: 4.8158548e+15 | W22: 4.9474059e+15 | X22: 5.0825505e+15 | Y22: 5.2213867e+15 | Z22: 5.3640155e+15 | AA22: 5.5105403e+15 | AB22: 5.6610676e+15 | AC22: 5.8157068e+15 | AD22: 5.9745701e+15 | AE22: 6.137773e+15 | AF22: 6.305434e+15 | AG22: 6.4776749e+15 | AH22: 6.6546207e+15 | AI22: 6.8364e+15 | AJ22: {=TREND(AE22:AI22,AE$1:AI$1,AJ$1)} -> 7.0063127e+15 | AK22: {=TREND(AF22:AJ22,AF$1:AJ$1,AK$1)} -> 7.1842332e+15 | AL22: {=TREND(AG22:AK22,AG$1:AK$1,AL$1)} -> 7.3612909e+15 | AM22: {=TREND(AH22:AL22,AH$1:AL$1,AM$1)} -> 7.5369236e+15 | AN22: {=TREND(AI22:AM22,AI$1:AM$1,AN$1)} -> 7.7118397e+15 | AO22: {=TREND(AJ22:AN22,AJ$1:AN$1,AO$1)} -> 7.8892433e+15 | AP22: {=TREND(AK22:AO22,AK$1:AO$1,AP$1)} -> 8.0648769e+15 | AQ22: {=TREND(AL22:AP22,AL$1:AP$1,AQ$1)} -> 8.2406824e+15 | ... AS22: {=TREND(AN22:AR22,AN$1:AR$1,AS$1)} -> 8.59316e+15

Sheet Indonesia BFPIaE-production
A1: Fuel (BTU) | B1: 2019 | C1: 2020 | D1: 2021 | E1: 2022 | F1: 2023 | G1: 2024 | H1: 2025 | I1: 2026 | J1: 2027 | K1: 2028 | L1: 2029 | M1: 2030 | N1: 2031 | O1: 2032 | P1: 2033 | Q1: 2034 | R1: 2035 | S1: 2036 | T1: 2037 | U1: 2038 | V1: 2039 | W1: 2040 | X1: 2041 | Y1: 2042 | Z1: 2043 | AA1: 2044 | AB1: 2045 | AC1: 2046 | AD1: 2047 | AE1: 2048 | AF1: 2049 | AG1: 2050
A2: electricity (not used in this variable) | B2: 0 | C2: 0 | D2: 0 | E2: 0 | F2: 0 | G2: 0 | H2: 0 | I2: 0 | J2: 0 | K2: 0 | L2: 0 | M2: 0 | N2: 0 | O2: 0 | P2: 0 | Q2: 0 | R2: 0 | S2: 0 | T2: 0 | U2: 0 | V2: 0 | W2: 0 | X2: 0 | Y2: 0 | Z2: 0 | AA2: 0 | AB2: 0 | AC2: 0 | AD2: 0 | AE2: 0 | AF2: 0 | AG2: 0
A3: hard coal | B3: 1.1273549e+16 | C3: 1.0047045e+16 | D3: 1.1171222e+16 | E3: 1.1659831e+16 | F3: 1.2148441e+16 | G3: 1.263705e+16 | H3: 1.312566e+16 | I3: 1.361427e+16 | J3: 1.4102879e+16 | K3: 1.4591489e+16 | L3: 1.5080098e+16 | M3: 1.5568708e+16 | N3: 1.6057317e+16 | O3: 1.6545927e+16 | P3: 1.7034537e+16 | Q3: 1.7523146e+16 | R3: 1.8011756e+16 | S3: 1.8500365e+16 | T3: 1.8988975e+16 | U3: 1.9477584e+16 | V3: 1.9966194e+16 | W3: 2.0454803e+16 | X3: 2.0943413e+16 | Y3: 2.1432023e+16 | Z3: 2.1920632e+16 | AA3: 2.2409242e+16 | AB3: 2.2897851e+16 | AC3: 2.3386461e+16 | AD3: 2.387507e+16 | AE3: 2.436368e+16 | AF3: 2.485229e+16 | AG3: 2.5340899e+16
A4: natural gas | B4: 1.6183561e+11 | C4: 1.5198573e+11 | D4: 1.5198573e+11 | E4: 1.5198573e+11 | F4: 1.5198573e+11 | G4: 1.5198573e+11 | H4: 1.5198573e+11 | I4: 1.5198573e+11 | J4: 1.5198573e+11 | K4: 1.5198573e+11 | L4: 1.5198573e+11 | M4: 1.5198573e+11 | N4: 1.5198573e+11 | O4: 1.5198573e+11 | P4: 1.5198573e+11 | Q4: 1.5198573e+11 | R4: 1.5198573e+11 | S4: 1.5198573e+11 | T4: 1.5198573e+11 | U4: 1.5198573e+11 | V4: 1.5198573e+11 | W4: 1.5198573e+11 | X4: 1.5198573e+11 | Y4: 1.5198573e+11 | Z4: 1.5198573e+11 | AA4: 1.5198573e+11 | AB4: 1.5198573e+11 | AC4: 1.5198573e+11 | AD4: 1.5198573e+11 | AE4: 1.5198573e+11 | AF4: 1.5198573e+11 | AG4: 1.5198573e+11
A5: nuclear | B5: 0 | C5: 0 | D5: 0 | E5: 0 | F5: 0 | G5: 0 | H5: 0 | I5: 0 | J5: 0 | K5: 0 | L5: 0 | M5: 0 | N5: 0 | O5: 0 | P5: 0 | Q5: 0 | R5: 0 | S5: 0 | T5: 0 | U5: 0 | V5: 0 | W5: 0 | X5: 0 | Y5: 0 | Z5: 0 | AA5: 0 | AB5: 0 | AC5: 0 | AD5: 0 | AE5: 0 | AF5: 0 | AG5: 0
A6: hydro (is not a fuel) | B6: 0 | C6: 0 | D6: 0 | E6: 0 | F6: 0 | G6: 0 | H6: 0 | I6: 0 | J6: 0 | K6: 0 | L6: 0 | M6: 0 | N6: 0 | O6: 0 | P6: 0 | Q6: 0 | R6: 0 | S6: 0 | T6: 0 | U6: 0 | V6: 0 | W6: 0 | X6: 0 | Y6: 0 | Z6: 0 | AA6: 0 | AB6: 0 | AC6: 0 | AD6: 0 | AE6: 0 | AF6: 0 | AG6: 0
A7: wind (is not a fuel) | B7: 0 | C7: 0 | D7: 0 | E7: 0 | F7: 0 | G7: 0 | H7: 0 | I7: 0 | J7: 0 | K7: 0 | L7: 0 | M7: 0 | N7: 0 | O7: 0 | P7: 0 | Q7: 0 | R7: 0 | S7: 0 | T7: 0 | U7: 0 | V7: 0 | W7: 0 | X7: 0 | Y7: 0 | Z7: 0 | AA7: 0 | AB7: 0 | AC7: 0 | AD7: 0 | AE7: 0 | AF7: 0 | AG7: 0
A8: solar (is not a fuel) | B8: 0 | C8: 0 | D8: 0 | E8: 0 | F8: 0 | G8: 0 | H8: 0 | I8: 0 | J8: 0 | K8: 0 | L8: 0 | M8: 0 | N8: 0 | O8: 0 | P8: 0 | Q8: 0 | R8: 0 | S8: 0 | T8: 0 | U8: 0 | V8: 0 | W8: 0 | X8: 0 | Y8: 0 | Z8: 0 | AA8: 0 | AB8: 0 | AC8: 0 | AD8: 0 | AE8: 0 | AF8: 0 | AG8: 0
A9: biomass | B9: 0 | C9: 0 | D9: 0 | E9: 0 | F9: 0 | G9: 0 | H9: 0 | I9: 0 | J9: 0 | K9: 0 | L9: 0 | M9: 0 | N9: 0 | O9: 0 | P9: 0 | Q9: 0 | R9: 0 | S9: 0 | T9: 0 | U9: 0 | V9: 0 | W9: 0 | X9: 0 | Y9: 0 | Z9: 0 | AA9: 0 | AB9: 0 | AC9: 0 | AD9: 0 | AE9: 0 | AF9: 0 | AG9: 0
A10: petroleum gasoline | B10: 0 | C10: 0 | D10: 2.5157914e+08 | E10: 2.5557361e+08 | F10: 2.5956808e+08 | G10: 2.6356255e+08 | H10: 2.6755701e+08 | I10: 2.7155148e+08 | J10: 2.7554595e+08 | K10: 2.7954042e+08 | L10: 2.8353488e+08 | M10: 2.8752935e+08 | N10: 2.9152382e+08 | O10: 2.9551829e+08 | P10: 2.9951275e+08 | Q10: 3.0350722e+08 | R10: 3.0750169e+08 | S10: 3.1149616e+08 | T10: 3.1549062e+08 | U10: 3.1948509e+08 | V10: 3.2347956e+08 | W10: 3.2747403e+08 | X10: 3.3146849e+08 | Y10: 3.3546296e+08 | Z10: 3.3945743e+08 | AA10: 3.434519e+08 | AB10: 3.4744636e+08 | AC10: 3.5144083e+08 | AD10: 3.554353e+08 | AE10: 3.5942977e+08 | AF10: 3.6342423e+08 | AG10: 3.674187e+08
A11: petroleum diesel | B11: 0 | C11: 4042600000 | D11: 1.731579e+09 | E11: 1.7287144e+09 | F11: 1.7258498e+09 | G11: 1.7229852e+09 | H11: 1.7201206e+09 | I11: 1.717256e+09 | J11: 1.7143914e+09 | K11: 1.7115268e+09 | L11: 1.7086622e+09 | M11: 1.7057976e+09 | N11: 1.702933e+09 | O11: 1.7000684e+09 | P11: 1.6972038e+09 | Q11: 1.6943392e+09 | R11: 1.6914746e+09 | S11: 1.68861e+09 | T11: 1.6857454e+09 | U11: 1.6828808e+09 | V11: 1.6800162e+09 | W11: 1.6771516e+09 | X11: 1.674287e+09 | Y11: 1.6714224e+09 | Z11: 1.6685578e+09 | AA11: 1.6656932e+09 | AB11: 1.6628286e+09 | AC11: 1.659964e+09 | AD11: 1.6570994e+09 | AE11: 1.6542348e+09 | AF11: 1.6513702e+09 | AG11: 1.6485056e+09
A12: biofuel gasoline | B12: 0 | C12: 1 | D12: 2 | E12: 3 | F12: 4 | G12: 5 | H12: 6 | I12: 7 | J12: 8 | K12: 9 | L12: 10 | M12: 11 | N12: 12 | O12: 13 | P12: 14 | Q12: 15 | R12: 16 | S12: 17 | T12: 18 | U12: 19 | V12: 20 | W12: 21 | X12: 22 | Y12: 23 | Z12: 24 | AA12: 25 | AB12: 26 | AC12: 27 | AD12: 28 | AE12: 29 | AF12: 30 | AG12: 31
... A22: hydrogen | B22: 0 | C22: 0 | D22: 0 | E22: 0 | F22: 0 | G22: 0 | H22: 0 | I22: 0 | J22: 0 | K22: 0 | L22: 0 | M22: 0 | N22: 0 | O22: 0 | P22: 0 | Q22: 0 | R22: 0 | S22: 0 | T22: 0 | U22: 0 | V22: 0 | W22: 0 | X22: 0 | Y22: 0 | Z22: 0 | AA22: 0 | AB22: 0 | AC22: 0 | AD22: 0 | AE22: 0 | AF22: 0 | AG22: 0

Sheet China BIFUbC
B1: BTU/yr | C1: 2020 | D1: 2021 | E1: 2022 | F1: 2023 | G1: 2024 | H1: 2025 | I1: 2026 | J1: 2027 | K1: 2028 | L1: 2029 | M1: 2030 | N1: 2031 | O1: 2032 | P1: 2033 | Q1: 2034 | R1: 2035 | S1: 2036 | T1: 2037 | U1: 2038 | V1: 2039 | W1: 2040 | X1: 2041 | Y1: 2042 | Z1: 2043 | AA1: 2044 | AB1: 2045 | AC1: 2046 | AD1: 2047 | AE1: 2048 | AF1: 2049 | AG1: 2050
A2: electricity | B2: agriculture and forestry 01T03 | C2: 449642493570200 | D2: 4.7662104e+14 | E2: 5.0521831e+14 | F2: 5.355314e+14 | G2: 5.6766329e+14 | H2: 6.0172309e+14 | I2: 6.3782647e+14 | J2: 6.7609606e+14 | K2: 716661822604110 | L2: 7.5966153e+14 | M2: 7.9954376e+14 | N2: 8.4151981e+14 | O2: 8.856996e+14 | P2: 9.3219883e+14 | Q2: 9.8113927e+14 | R2: 1.0326491e+15 | S2: 1.0868632e+15 | T2: 1.1439235e+15 | U2: 1.2039795e+15 | V2: 1.2671884e+15 | W2: 1.3204103e+15 | X2: 1.3758675e+15 | Y2: 1.433654e+15 | Z2: 1.4938674e+15 | AA2: 1.5566099e+15 | AB2: 1.6219875e+15 | AC2: 1.6901109e+15 | AD2: 1.7610956e+15 | AE2: 1.8350616e+15 | AF2: 1.9121342e+15 | AG2: 1.9733225e+15 | AH2: 2.0364688e+15 | AI2: 2.1103187e+15 | AJ2: 2.1759158e+15 | AK2: 2.2409999e+15 | AL2: 2.3098457e+15 | AM2: 2.3779402e+15 | AN2: 2.4437559e+15 | AO2: 2.5114777e+15 | AP2: 2.5792636e+15 | AQ2: 2.6461686e+15 | AR2: 2.7133106e+15
A3: electricity | B3: coal mining 05 | C3: 1.48422e+15 | D3: 3.5038592e+14 | E3: 3.7206459e+14 | F3: 3.9260107e+14 | G3: 4.1292319e+14 | H3: 4.3637532e+14 | I3: 4.5788083e+14 | J3: 4.819483e+14 | K3: 5.0423628e+14 | L3: 5.3000956e+14 | M3: 5.5436206e+14 | N3: 5.8436784e+14 | O3: 5.971666e+14 | P3: 6.1096719e+14 | Q3: 6.2313192e+14 | R3: 6.3684838e+14 | S3: 6.4984639e+14 | T3: 6.6140742e+14 | U3: 6.749041e+14 | V3: 6.8968927e+14 | W3: 7.0483569e+14 | X3: 7.1789864e+14 | Y3: 7.3213729e+14 | Z3: 7.4327996e+14 | AA3: 756211890068079 | AB3: 771740711950645 | AC3: 7.8833725e+14 | AD3: 8.0692015e+14 | AE3: 8.2325705e+14 | AF3: 8.4400239e+14 | AG3: 8.6576399e+14 | AH3: 8.8936918e+14 | AI3: 908084047310000 | AJ3: 930601562978608 | AK3: 952219752845336 | AL3: 973450880313456 | AM3: 994434818252584 | AN3: 1.0164235e+15 | AO3: 1.0375838e+15 | AP3: 1.0589327e+15 | AQ3: 1.0803989e+15 | AR3: 1.101886e+15
A4: electricity | B4: oil and gas extraction 06 | C4: 1.5186205e+14 | D4: 1.6134973e+14 | E4: 1.7133257e+14 | F4: 1.8078944e+14 | G4: 1.901476e+14 | H4: 2.0094711e+14 | I4: 2.1085022e+14 | J4: 2.2193308e+14 | K4: 2.3219651e+14 | L4: 2.4406488e+14 | M4: 2.55279e+14 | N4: 2.690964e+14 | O4: 2.7499012e+14 | P4: 2.8134518e+14 | Q4: 2.8694693e+14 | R4: 2.9326324e+14 | S4: 2.9924872e+14 | T4: 3.0457247e+14 | U4: 3.1078758e+14 | V4: 3.1759602e+14 | W4: 3.2457082e+14 | X4: 3.305862e+14 | Y4: 3.3714297e+14 | Z4: 3.4227408e+14 | AA4: 3.4822912e+14 | AB4: 3.5538001e+14 | AC4: 363022574738842 | AD4: 3.7157984e+14 | AE4: 3.7910285e+14 | AF4: 3.886559e+14 | AG4: 3.9867693e+14 | AH4: 4.0954692e+14 | AI4: 418164954404520 | AJ4: 428534078210580 | AK4: 438489070159516 | AL4: 448265823176992 | AM4: 457928747525828 | AN4: 468054334058200 | AO4: 477798467344688 | AP4: 487629480028508 | AQ4: 497514480483412 | AR4: 507409085453772
A5: electricity | B5: other mining and quarrying 07T08 | C5: 4.5611021e+14 | D5: 4.8460599e+14 | E5: 5.1458897e+14 | F5: 5.4299222e+14 | G5: 5.71099e+14 | H5: 6.0353479e+14 | I5: 6.3327828e+14 | J5: 6.6656513e+14 | K5: 6.9739082e+14 | L5: 7.3303689e+14 | M5: 7.6671796e+14 | N5: 808217851131625 | O5: 8.2591935e+14 | P5: 8.4500644e+14 | Q5: 8.6183104e+14 | R5: 880801767857354 | S5: 8.9877885e+14 | T5: 9.1476849e+14 | U5: 9.3343525e+14 | V5: 9.5388409e+14 | W5: 9.7483254e+14 | X5: 9.9289944e+14 | Y5: 1.0125924e+15 | Z5: 1.0280034e+15 | AA5: 1.0458891e+15 | AB5: 1.0673664e+15 | AC5: 1.0903205e+15 | AD5: 1.1160218e+15 | AE5: 1.1386168e+15 | AF5: 1.1673089e+15 | AG5: 1.1974066e+15 | AH5: 1.2300541e+15 | AI5: 1.2559379e+15 | AJ5: 1.2870811e+15 | AK5: 1.3169804e+15 | AL5: 1.3463444e+15 | AM5: 1.3753665e+15 | AN5: 1.4057782e+15 | AO5: 1.4350443e+15 | AP5: 1.4645712e+15 | AQ5: 1.4942603e+15 | AR5: 1.5239783e+15
A6: electricity | B6: food beverage and tobacco 10T12 | C6: 4.4861784e+14 | D6: 4.6524269e+14 | E6: 4.9131914e+14 | F6: 5.1587424e+14 | G6: 5.4012181e+14 | H6: 5.6839901e+14 | I6: 5.9404825e+14 | J6: 6.2290518e+14 | K6: 6.493207e+14 | L6: 6.8005336e+14 | M6: 7.087602e+14 | N6: 7.4444954e+14 | O6: 7.5245078e+14 | P6: 7.60641e+14 | Q6: 7.6563595e+14 | R6: 7.7128595e+14 | S6: 774708409784248 | T6: 7.7501318e+14 | U6: 7.7608633e+14 | V6: 7.7698656e+14 | W6: 7.7651451e+14 | X6: 7.719296e+14 | Y6: 7.6833688e+14 | Z6: 7.5973253e+14 | AA6: 7.5116617e+14 | AB6: 7.431975e+14 | AC6: 734092414109407 | AD6: 7.2449594e+14 | AE6: 7.1047076e+14 | AF6: 6.976771e+14 | AG6: 6.8286314e+14 | AH6: 6.6643327e+14 | AI6: 653268154730324 | AJ6: 638447773930804 | AK6: 623321798445676 | AL6: 608746372946516 | AM6: 594447427440716 | AN6: 579443448829756 | AO6: 564816457956572 | AP6: 550261019595356 | AQ6: 535562442497844 | AR6: 520820439528004
A7: electricity | B7: textiles apparel and leather 13T15 | C7: 759697535189126 | D7: 787850350761658 | E7: 8.3200869e+14 | F7: 873590734446982 | G7: 9.1465201e+14 | H7: 9.6253712e+14 | I7: 1.005972e+15 | J7: 1.0548388e+15 | K7: 1.0995714e+15 | L7: 1.1516146e+15 | M7: 1.2002273e+15 | N7: 1.2606643e+15 | O7: 1.2742137e+15 | P7: 1.2880832e+15 | Q7: 1.2965417e+15 | R7: 1.3061095e+15 | S7: 1.3119052e+15 | T7: 1.3124213e+15 | U7: 1.3142386e+15 | V7: 1.315763e+15 | W7: 1.3149637e+15 | X7: 1.3071995e+15 | Y7: 1.3011155e+15 | Z7: 1.2865448e+15 | AA7: 1.2720383e+15 | AB7: 1.258544e+15 | AC7: 1.2431253e+15 | AD7: 1.2268745e+15 | AE7: 1.203124e+15 | AF7: 1.181459e+15 | AG7: 1.1563727e+15 | AH7: 1.1285501e+15 | AI7: 1.1062561e+15 | AJ7: 1.081159e+15 | AK7: 1.0555444e+15 | AL7: 1.0308621e+15 | AM7: 1.006648e+15 | AN7: 981239972104784 | AO7: 956470362326008 | AP7: 931821920859664 | AQ7: 906931085679336 | AR7: 881966712344704
