Workbook
Name dollars_2019_2012: About!$A$70
Name dollars_2020_2012: About!$A$105
Name dollars_2021_2012: About!$A$104
Name dollars_2022_2012: About!$A$103
Name lignite_multiplier: '[1]Hard Coal and Lig Multipliers'!$N$15
Name lignite_multiplier: '[1]Hard Coal and Lig Multipliers'!$N$15
Name lignite_multiplier: '[1]Hard Coal and Lig Multipliers'!$N$15
Name lignite_multiplier: #REF!
Name nonlignite_multiplier: '[1]Hard Coal and Lig Multipliers'!$N$16
Name nonlignite_multiplier: '[1]Hard Coal and Lig Multipliers'!$N$16
Name nonlignite_multiplier: '[1]Hard Coal and Lig Multipliers'!$N$16
Name nonlignite_multiplier: #REF!

Sheet About
A1: BFPaT BAU Pretax Fuel Price by Sector
A2: BFPaT BAU Fuel Tax by Sector
A4: Sources: | B4: All Fuel Prices
B5: Handbook of Energy Economics and Statistics
B6: 2020
B7: https://www.esdm.go.id/assets/media/content/content-handbook-of-energy-and-economic-statistics-of-indonesia-2020.pdf
B9: Hydrogen values are from the US version, but used the Indonesia tax percentages
B11: IESR
B12: 2019
B13: https://www.climate-transparency.org/wp-content/uploads/2019/04/SPM-english-lowres.pdf
A16: Notes
A18: Pre-Tax Prices
A19: This variable contains PRE-TAX fuel prices per unit energy, disaggregated by sector.
A21: BAU Fuel Taxes
A22: Separately, it also specifies the amount of BAU fuel tax per unit energy that is levied on each fuel.
A23: BAU fuel taxes include sales taxes, value-added taxes (VAT), and excise taxes, not carbon taxes.
A24: If there is a BAU Carbon Tax in the modeled region, its effect on fuel prices must not be included here.
A25: (A BAU carbon tax is specified separately in fuels/BCTR BAU Carbon Tax Rate.)
A27: BAU Fuel Subsidies
A28: All pre-tax fuel prices in this variable should incorporate the contribution of any BAU subsidies.
A29: This is because BAU subsidies are often applied far upstream of retail sales, such as subsidies for oil
A30: and gas drilling companies. Similarly, subsidies paid for electricity generation
... A69: We adjust dollars of the following years to 2012 dollars using the following conversion factors:
A70: 0.89805482 | B70: 2019 to 2012
A71: 0.914 | B71: 2018 to 2012; used for EIA AEO 2018 and DOE Clean Cities report
A72: 0.96868157 | B72: 2015 to 2012; used for CEC/CARB hydrogen report
A73: 1.022 | B73: 2011 to 2012; used for Euroheat and Power statistics
A74: See "cpi.xlsx" in the InputData folder for source information.
A77: Crude Oil Heat Content
A78: 5.719 | B78: million BTU / barrel (U.S.-produced crude)
A79: 6.063 | B79: million BTU / barrel (imported crude)
A80: Source: EIA AEO 2019, Appendix G, Conversion Factors
A82: For the United States EPS, we use West Texas Intermediate as our crude benchmark, as this is typical in the U.S.
A83: When adapting the EPS to other countries, using Brent crude (also available in AEO table 12) is advised, and
A84: the heat content used should be switched to the value for "imported" crude above.
A86: Municipal Solid Waste Prices
A87: Rather than costing money, companies usually pay a "tipping fee" to the processor for accepting their
A88: municipal solid waste. This would imply a negative fuel price. However, there may be extra expenses
A89: associated with sorting the waste so that only suitable MSW is combusted, while other items (such as
A90: electronics and batteries, which should not have been part of the MSW stream) don't get combusted.
...

Sheet Fuel Prices - ID
B2: Units (US$/BOE) | C2: 2010 | D2: 2011 | E2: 2012 | F2: 2013 | G2: 2014 | H2: 2015 | I2: 2016 | J2: 2017 | K2: 2018 | L2: 2019 | M2: 2020 | N2: 2021 | O2: 2022 | P2: 2023 | Q2: 2024 | R2: 2025 | S2: 2026 | T2: 2027 | U2: 2028 | V2: 2029 | W2: 2030 | X2: 2031 | Y2: 2032 | Z2: 2033 | AA2: 2034 | AB2: 2035 | AC2: 2036 | AD2: 2037 | AE2: 2038 | AF2: 2039 | AG2: 2040 | AH2: 2041 | AI2: 2042 | AJ2: 2043 | AK2: 2044 | AL2: 2045 | AM2: 2046 | AN2: 2047 | AO2: 2048 | AP2: 2049 | AQ2: 2050
B3: Electricity - Household | C3: 112 | D3: 111 | E3: 107 | F3: 93 | G3: 99 | H3: 99 | I3: 102 | J3: 127 | K3: 128 | L3: 129 | M3: 115 | N3: =TREND($C$3:$M$3,$C$2:$M$2,N2) -> 123.14545 | O3: =TREND($C$3:$M$3,$C$2:$M$2,O2) -> 125.15455 | P3: =TREND($C$3:$M$3,$C$2:$M$2,P2) -> 127.16364 | Q3: =TREND($C$3:$M$3,$C$2:$M$2,Q2) -> 129.17273 | R3: =TREND($C$3:$M$3,$C$2:$M$2,R2) -> 131.18182 | S3: =TREND($C$3:$M$3,$C$2:$M$2,S2) -> 133.19091 | T3: =TREND($C$3:$M$3,$C$2:$M$2,T2) -> 135.2 | U3: =TREND($C$3:$M$3,$C$2:$M$2,U2) -> 137.20909 | ... AQ3: =TREND($C$3:$M$3,$C$2:$M$2,AQ2) -> 181.40909
B4: Electricity - Industry | C4: 120 | D4: 125 | E4: 120 | F4: 107 | G4: 128 | H4: 135 | I4: 128 | J4: 131 | K4: 126 | L4: 129 | M4: 126 | N4: =TREND($C$4:$M$4,$C$2:$M$2,N2) -> 131.10909 | O4: =TREND($C$4:$M$4,$C$2:$M$2,O2) -> 132.12727 | P4: =TREND($C$4:$M$4,$C$2:$M$2,P2) -> 133.14545 | Q4: =TREND($C$4:$M$4,$C$2:$M$2,Q2) -> 134.16364 | R4: =TREND($C$4:$M$4,$C$2:$M$2,R2) -> 135.18182 | S4: =TREND($C$4:$M$4,$C$2:$M$2,S2) -> 136.2 | T4: =TREND($C$4:$M$4,$C$2:$M$2,T2) -> 137.21818 | U4: =TREND($C$4:$M$4,$C$2:$M$2,U2) -> 138.23636 | ... AQ4: =TREND($C$4:$M$4,$C$2:$M$2,AQ2) -> 160.63636
B5: Electricity - Commercial | C5: 170 | D5: 171 | E5: 163 | F5: 149 | G5: 166 | H5: 152 | I5: 146 | J5: 150 | K5: 145 | L5: 148 | M5: 143 | N5: =AVERAGE(C5:M5) -> 154.81818 | O5: =AVERAGE(D5:N5) -> 153.43802 | P5: =AVERAGE(E5:O5) -> 151.84147 | Q5: =AVERAGE(F5:P5) -> 150.82706 | R5: =AVERAGE(G5:Q5) -> 150.99316 | S5: =AVERAGE(H5:R5) -> 149.6289 | T5: =AVERAGE(I5:S5) -> 149.41334 | U5: =AVERAGE(J5:T5) -> 149.72365 | ... AQ5: =AVERAGE(AF5:AP5) -> 150.29277
B6: Coal - Indonesia | C6: 17 | D6: 18 | E6: 18 | F6: 18 | G6: 19 | H6: 11 | I6: 11 | J6: 14 | K6: 13 | L6: 13 | M6: 15 | N6: =TREND($C$6:$M$6,$C$7:$M$7,N7) -> 14.679145 | O6: =TREND($C$6:$M$6,$C$7:$M$7,O7) -> 15.210973 | P6: =TREND($C$6:$M$6,$C$7:$M$7,P7) -> 15.461245 | Q6: =TREND($C$6:$M$6,$C$7:$M$7,Q7) -> 15.461245 | R6: =TREND($C$6:$M$6,$C$7:$M$7,R7) -> 15.461245 | S6: =TREND($C$6:$M$6,$C$7:$M$7,S7) -> 15.429961 | T6: =TREND($C$6:$M$6,$C$7:$M$7,T7) -> 15.336109 | U6: =TREND($C$6:$M$6,$C$7:$M$7,U7) -> 15.273541 | ... AQ6: =TREND($C$6:$M$6,$C$7:$M$7,AQ7) -> 12.77082
B7: Coal - US | C7: =TREND($L$7:$AQ$7,$L$2:$AQ$2,C2) -> 3.0998662 | D7: =TREND($L$7:$AQ$7,$L$2:$AQ$2,D2) -> 3.1208028 | E7: =TREND($L$7:$AQ$7,$L$2:$AQ$2,E2) -> 3.1417394 | F7: =TREND($L$7:$AQ$7,$L$2:$AQ$2,F2) -> 3.162676 | G7: =TREND($L$7:$AQ$7,$L$2:$AQ$2,G2) -> 3.1836125 | H7: =TREND($L$7:$AQ$7,$L$2:$AQ$2,H2) -> 3.2045491 | I7: =TREND($L$7:$AQ$7,$L$2:$AQ$2,I2) -> 3.2254857 | J7: =TREND($L$7:$AQ$7,$L$2:$AQ$2,J2) -> 3.2464223 | K7: =TREND($L$7:$AQ$7,$L$2:$AQ$2,K2) -> 3.2673589 | L7: 4.14 | M7: 3.72 | N7: 3.48 | O7: 3.31 | P7: 3.23 | Q7: 3.23 | R7: 3.23 | S7: 3.24 | T7: 3.27 | U7: 3.29 | V7: 3.33 | W7: 3.37 | X7: 3.41 | Y7: 3.44 | Z7: 3.48 | AA7: 3.51 | AB7: 3.55 | AC7: 3.58 | AD7: 3.61 | AE7: 3.64 | AF7: 3.68 | AG7: 3.71 | AH7: 3.75 | AI7: 3.78 | AJ7: 3.82 | AK7: 3.86 | AL7: 3.9 | AM7: 3.93 | AN7: 3.97 | AO7: 4.01 | AP7: 4.05 | AQ7: 4.09
B8: Natural Gas | C8: 6 | D8: 4.01 | E8: 2.76 | F8: 3.71 | G8: 4.35 | H8: 2.6 | I8: 2.46 | J8: 2.96 | K8: 3.13 | L8: 2.53 | M8: =C56 -> 2.99 | N8: =AVERAGE(C8:M8) -> 3.4090909 | O8: =AVERAGE(D8:N8) -> 3.1735537 | P8: =AVERAGE(E8:O8) -> 3.0975131 | Q8: =AVERAGE(F8:P8) -> 3.1281962 | R8: =AVERAGE(G8:Q8) -> 3.0753049 | S8: =AVERAGE(H8:R8) -> 2.9594235 | T8: =AVERAGE(I8:S8) -> 2.9920984 | U8: =AVERAGE(J8:T8) -> 3.040471 | ... AQ8: =AVERAGE(AF8:AP8) -> 3.0575131
B9: Gasoline | C9: 82 | D9: 85 | E9: 80 | F9: 78 | G9: 93 | H9: 90 | I9: 4 | J9: 82 | K9: 79 | L9: 80 | M9: 79 | N9: =TREND($C$9:$M$9,$C$2:$M$2,N2) -> 69.145455 | O9: =TREND($C$9:$M$9,$C$2:$M$2,O2) -> 68.063636 | P9: =TREND($C$9:$M$9,$C$2:$M$2,P2) -> 66.981818 | Q9: =TREND($C$9:$M$9,$C$2:$M$2,Q2) -> 65.9 | R9: =TREND($C$9:$M$9,$C$2:$M$2,R2) -> 64.818182 | S9: =TREND($C$9:$M$9,$C$2:$M$2,S2) -> 63.736364 | T9: =TREND($C$9:$M$9,$C$2:$M$2,T2) -> 62.654545 | U9: =TREND($C$9:$M$9,$C$2:$M$2,U2) -> 61.572727 | ... AQ9: =TREND($C$9:$M$9,$C$2:$M$2,AQ2) -> 37.772727
B10: Gasoil CN 48 - Indonesia | C10: 77 | D10: 76 | E10: 72 | F10: 64 | G10: 71 | H10: 76 | I10: 61 | J10: 59 | K10: 57 | L10: 57 | M10: 56 | N10: =AVERAGE(C10:M10) -> 66 | O10: =AVERAGE(D10:N10) -> 65 | P10: =AVERAGE(E10:O10) -> 64 | Q10: =AVERAGE(F10:P10) -> 63.272727 | R10: =AVERAGE(G10:Q10) -> 63.206612 | S10: =AVERAGE(H10:R10) -> 62.498122 | T10: =AVERAGE(I10:S10) -> 61.270678 | U10: =AVERAGE(J10:T10) -> 61.295285 | ... AQ10: =AVERAGE(AF10:AP10) -> 62.273702
B11: Avtur (Jet Fuel) | C11: 125 | D11: 161 | E11: 165 | F11: 139 | G11: 123 | H11: 113 | I11: 91 | J11: 105 | K11: 122 | L11: 120 | M11: 118 | N11: =AVERAGE(C11:M11) -> 125.63636 | O11: =AVERAGE(D11:N11) -> 125.69421 | P11: =AVERAGE(E11:O11) -> 122.4846 | Q11: =AVERAGE(F11:P11) -> 118.61956 | R11: =AVERAGE(G11:Q11) -> 116.76679 | S11: =AVERAGE(H11:R11) -> 116.20014 | T11: =AVERAGE(I11:S11) -> 116.49106 | U11: =AVERAGE(J11:T11) -> 118.80843 | ... AQ11: =AVERAGE(AF11:AP11) -> 119.1895
B12: Kerosene | C12: 47 | D12: 47 | E12: 35 | F12: 35 | G12: 34 | H12: 31 | I12: 31 | J12: 31 | K12: 30 | L12: 30 | M12: 30 | N12: =AVERAGE(C12:M12) -> 34.636364 | O12: =AVERAGE(D12:N12) -> 33.512397 | P12: =AVERAGE(E12:O12) -> 32.286251 | Q12: =AVERAGE(F12:P12) -> 32.039546 | R12: =AVERAGE(G12:Q12) -> 31.770414 | S12: =AVERAGE(H12:R12) -> 31.567725 | T12: =AVERAGE(I12:S12) -> 31.619336 | U12: =AVERAGE(J12:T12) -> 31.675639 | ... AQ12: =AVERAGE(AF12:AP12) -> 31.928142
B13: LPG 3 kg | C13: 55 | D13: 55 | E13: 52 | F13: 41 | G13: 40 | H13: 36 | I13: 37 | J13: 37 | K13: 36 | L13: 36 | M13: 35
B14: LPG 12 kg | C14: 76 | D14: 76 | E14: 71 | F14: 61 | G14: 97 | H14: 104 | I14: 101 | J14: 104 | K14: 104 | L14: 105 | M14: 103
B15: LPG 50 kg | C15: 96 | D15: 95 | E15: 136 | F15: 129 | G15: 124 | H15: 104 | I15: 93 | J15: 108 | K15: 115 | L15: 116 | M15: 114
B16: Average LPG | C16: =AVERAGE(C13:C15) -> 75.666667 | D16: =AVERAGE(D13:D15) -> 75.333333 | E16: =AVERAGE(E13:E15) -> 86.333333 | F16: =AVERAGE(F13:F15) -> 77 | G16: =AVERAGE(G13:G15) -> 87 | H16: =AVERAGE(H13:H15) -> 81.333333 | I16: =AVERAGE(I13:I15) -> 77 | J16: =AVERAGE(J13:J15) -> 83 | ... M16: =AVERAGE(M13:M15) -> 84 | N16: =TREND($C$16:$M$16,$C$2:$M$2,N2) -> 85.993939 | O16: =TREND($C$16:$M$16,$C$2:$M$2,O2) -> 86.730303 | P16: =TREND($C$16:$M$16,$C$2:$M$2,P2) -> 87.466667 | Q16: =TREND($C$16:$M$16,$C$2:$M$2,Q2) -> 88.20303 | R16: =TREND($C$16:$M$16,$C$2:$M$2,R2) -> 88.939394 | S16: =TREND($C$16:$M$16,$C$2:$M$2,S2) -> 89.675758 | T16: =TREND($C$16:$M$16,$C$2:$M$2,T2) -> 90.412121 | U16: =TREND($C$16:$M$16,$C$2:$M$2,U2) -> 91.148485 | ... AQ16: =TREND($C$16:$M$16,$C$2:$M$2,AQ2) -> 107.34848
B17: Crude Oil | C17: 79.4 | D17: 111.55 | E17: 112.73 | F17: 105.85 | G17: 96.51 | H17: 49.21 | I17: 40.13 | J17: 51.19 | K17: 67.47 | L17: 62.37 | M17: 40.39 | N17: =AVERAGE(C17:M17) -> 74.254545 | O17: =AVERAGE(D17:N17) -> 73.786777 | P17: =AVERAGE(E17:O17) -> 70.353757 | Q17: =AVERAGE(F17:P17) -> 66.501371 | R17: =AVERAGE(G17:Q17) -> 62.924223 | S17: =AVERAGE(H17:R17) -> 59.87097 | T17: =AVERAGE(I17:S17) -> 60.840149 | U17: =AVERAGE(J17:T17) -> 62.72289 | ... AQ17: =AVERAGE(AF17:AP17) -> 63.779943
L19: Conversion Rate | Q19: Conversion Rate
B20: Assumption: | L20: 5799000 | M20: BOE | N20: BTU | Q20: 1000000 | R20: MMBTU | S20: BTU
B21: transportation = commercial sector
B22: industry = dist. heating and geoengineering sector
B55: 2019 | C55: 2020 | D55: 2021
A56: Natural Gas | B56: 2.53 | C56: =(B56+D56)/2 -> 2.99 | D56: 3.45

Sheet Tax Percentages
A1: Average Sales Tax Rate | B1: 0.1
A2: Used when no more specific data are available for a fuel type.
B4: 2019 | C4: 2020 | D4: 2021 | E4: 2022 | F4: 2023 | G4: 2024 | H4: 2025 | I4: 2026 | J4: 2027 | K4: 2028 | L4: 2029 | M4: 2030 | N4: 2031 | O4: 2032 | P4: 2033 | Q4: 2034 | R4: 2035 | S4: 2036 | T4: 2037 | U4: 2038 | V4: 2039 | W4: 2040 | X4: 2041 | Y4: 2042 | Z4: 2043 | AA4: 2044 | AB4: 2045 | AC4: 2046 | AD4: 2047 | AE4: 2048 | AF4: 2049 | AG4: 2050
A5: electricity | B5: =$B$1 -> 0.1 | C5: =$B$1 -> 0.1 | D5: =$B$1 -> 0.1 | E5: =$B$1 -> 0.1 | F5: =$B$1 -> 0.1 | G5: =$B$1 -> 0.1 | H5: =$B$1 -> 0.1 | I5: =$B$1 -> 0.1 | ... AG5: =$B$1 -> 0.1
A6: hard coal | B6: =$B$1 -> 0.1 | C6: =$B$1 -> 0.1 | D6: =$B$1 -> 0.1 | E6: =$B$1 -> 0.1 | F6: =$B$1 -> 0.1 | G6: =$B$1 -> 0.1 | H6: =$B$1 -> 0.1 | I6: =$B$1 -> 0.1 | ... AG6: =$B$1 -> 0.1
A7: natural gas | B7: =$B$1 -> 0.1 | C7: =$B$1 -> 0.1 | D7: =$B$1 -> 0.1 | E7: =$B$1 -> 0.1 | F7: =$B$1 -> 0.1 | G7: =$B$1 -> 0.1 | H7: =$B$1 -> 0.1 | I7: =$B$1 -> 0.1 | ... AG7: =$B$1 -> 0.1
A8: nuclear | B8: =$B$1 -> 0.1 | C8: =$B$1 -> 0.1 | D8: =$B$1 -> 0.1 | E8: =$B$1 -> 0.1 | F8: =$B$1 -> 0.1 | G8: =$B$1 -> 0.1 | H8: =$B$1 -> 0.1 | I8: =$B$1 -> 0.1 | ... AG8: =$B$1 -> 0.1
A9: hydro (does not use fuel) | B9: 0 | C9: 0 | D9: 0 | E9: 0 | F9: 0 | G9: 0 | H9: 0 | I9: 0 | J9: 0 | K9: 0 | L9: 0 | M9: 0 | N9: 0 | O9: 0 | P9: 0 | Q9: 0 | R9: 0 | S9: 0 | T9: 0 | U9: 0 | V9: 0 | W9: 0 | X9: 0 | Y9: 0 | Z9: 0 | AA9: 0 | AB9: 0 | AC9: 0 | AD9: 0 | AE9: 0 | AF9: 0 | AG9: 0
A10: wind (does not use fuel) | B10: 0 | C10: 0 | D10: 0 | E10: 0 | F10: 0 | G10: 0 | H10: 0 | I10: 0 | J10: 0 | K10: 0 | L10: 0 | M10: 0 | N10: 0 | O10: 0 | P10: 0 | Q10: 0 | R10: 0 | S10: 0 | T10: 0 | U10: 0 | V10: 0 | W10: 0 | X10: 0 | Y10: 0 | Z10: 0 | AA10: 0 | AB10: 0 | AC10: 0 | AD10: 0 | AE10: 0 | AF10: 0 | AG10: 0
A11: solar (does not use fuel) | B11: 0 | C11: 0 | D11: 0 | E11: 0 | F11: 0 | G11: 0 | H11: 0 | I11: 0 | J11: 0 | K11: 0 | L11: 0 | M11: 0 | N11: 0 | O11: 0 | P11: 0 | Q11: 0 | R11: 0 | S11: 0 | T11: 0 | U11: 0 | V11: 0 | W11: 0 | X11: 0 | Y11: 0 | Z11: 0 | AA11: 0 | AB11: 0 | AC11: 0 | AD11: 0 | AE11: 0 | AF11: 0 | AG11: 0
A12: biomass | B12: =$B$1 -> 0.1 | C12: =$B$1 -> 0.1 | D12: =$B$1 -> 0.1 | E12: =$B$1 -> 0.1 | F12: =$B$1 -> 0.1 | G12: =$B$1 -> 0.1 | H12: =$B$1 -> 0.1 | I12: =$B$1 -> 0.1 | ... AG12: =$B$1 -> 0.1
A13: petroleum gasoline | B13: 0.1 | C13: 0.1 | D13: 0.1 | E13: 0.1 | F13: 0.1 | G13: 0.1 | H13: 0.1 | I13: 0.1 | J13: 0.1 | K13: 0.1 | L13: 0.1 | M13: 0.1 | N13: 0.1 | O13: 0.1 | P13: 0.1 | Q13: 0.1 | R13: 0.1 | S13: 0.1 | T13: 0.1 | U13: 0.1 | V13: 0.1 | W13: 0.1 | X13: 0.1 | Y13: 0.1 | Z13: 0.1 | AA13: 0.1 | AB13: 0.1 | AC13: 0.1 | AD13: 0.1 | AE13: 0.1 | AF13: 0.1 | AG13: 0.1
A14: petroleum diesel | B14: 0.1 | C14: 0.1 | D14: 0.1 | E14: 0.1 | F14: 0.1 | G14: 0.1 | H14: 0.1 | I14: 0.1 | J14: 0.1 | K14: 0.1 | L14: 0.1 | M14: 0.1 | N14: 0.1 | O14: 0.1 | P14: 0.1 | Q14: 0.1 | R14: 0.1 | S14: 0.1 | T14: 0.1 | U14: 0.1 | V14: 0.1 | W14: 0.1 | X14: 0.1 | Y14: 0.1 | Z14: 0.1 | AA14: 0.1 | AB14: 0.1 | AC14: 0.1 | AD14: 0.1 | AE14: 0.1 | AF14: 0.1 | AG14: 0.1
A15: biofuel gasoline | B15: =B13 -> 0.1 | C15: =C13 -> 0.1 | D15: =D13 -> 0.1 | E15: =E13 -> 0.1 | F15: =F13 -> 0.1 | G15: =G13 -> 0.1 | H15: =H13 -> 0.1 | I15: =I13 -> 0.1 | ... AG15: =AG13 -> 0.1
A16: biofuel diesel | B16: =B14 -> 0.1 | C16: =C14 -> 0.1 | D16: =D14 -> 0.1 | E16: =E14 -> 0.1 | F16: =F14 -> 0.1 | G16: =G14 -> 0.1 | H16: =H14 -> 0.1 | I16: =I14 -> 0.1 | ... AG16: =AG14 -> 0.1
A17: jet fuel | B17: =$B$1 -> 0.1 | C17: =$B$1 -> 0.1 | D17: =$B$1 -> 0.1 | E17: =$B$1 -> 0.1 | F17: =$B$1 -> 0.1 | G17: =$B$1 -> 0.1 | H17: =$B$1 -> 0.1 | I17: =$B$1 -> 0.1 | ... AG17: =$B$1 -> 0.1
A18: heat | B18: =$B$1 -> 0.1 | C18: =$B$1 -> 0.1 | D18: =$B$1 -> 0.1 | E18: =$B$1 -> 0.1 | F18: =$B$1 -> 0.1 | G18: =$B$1 -> 0.1 | H18: =$B$1 -> 0.1 | I18: =$B$1 -> 0.1 | ... AG18: =$B$1 -> 0.1
A19: geothermal (does not use fuel) | B19: 0 | C19: 0 | D19: 0 | E19: 0 | F19: 0 | G19: 0 | H19: 0 | I19: 0 | J19: 0 | K19: 0 | L19: 0 | M19: 0 | N19: 0 | O19: 0 | P19: 0 | Q19: 0 | R19: 0 | S19: 0 | T19: 0 | U19: 0 | V19: 0 | W19: 0 | X19: 0 | Y19: 0 | Z19: 0 | AA19: 0 | AB19: 0 | AC19: 0 | AD19: 0 | AE19: 0 | AF19: 0 | AG19: 0
A20: lignite | B20: =$B$1 -> 0.1 | C20: =$B$1 -> 0.1 | D20: =$B$1 -> 0.1 | E20: =$B$1 -> 0.1 | F20: =$B$1 -> 0.1 | G20: =$B$1 -> 0.1 | H20: =$B$1 -> 0.1 | I20: =$B$1 -> 0.1 | ... AG20: =$B$1 -> 0.1
A21: crude oil | B21: 0 | C21: 0 | D21: 0 | E21: 0 | F21: 0 | G21: 0 | H21: 0 | I21: 0 | J21: 0 | K21: 0 | L21: 0 | M21: 0 | N21: 0 | O21: 0 | P21: 0 | Q21: 0 | R21: 0 | S21: 0 | T21: 0 | U21: 0 | V21: 0 | W21: 0 | X21: 0 | Y21: 0 | Z21: 0 | AA21: 0 | AB21: 0 | AC21: 0 | AD21: 0 | AE21: 0 | AF21: 0 | AG21: 0
A22: heavy fuel oil | B22: 0 | C22: 0 | D22: 0 | E22: 0 | F22: 0 | G22: 0 | H22: 0 | I22: 0 | J22: 0 | K22: 0 | L22: 0 | M22: 0 | N22: 0 | O22: 0 | P22: 0 | Q22: 0 | R22: 0 | S22: 0 | T22: 0 | U22: 0 | V22: 0 | W22: 0 | X22: 0 | Y22: 0 | Z22: 0 | AA22: 0 | AB22: 0 | AC22: 0 | AD22: 0 | AE22: 0 | AF22: 0 | AG22: 0
A23: LPG propane or butane | B23: =$B$1 -> 0.1 | C23: =$B$1 -> 0.1 | D23: =$B$1 -> 0.1 | E23: =$B$1 -> 0.1 | F23: =$B$1 -> 0.1 | G23: =$B$1 -> 0.1 | H23: =$B$1 -> 0.1 | I23: =$B$1 -> 0.1 | ... AG23: =$B$1 -> 0.1
A24: municipal solid waste (no fuel cost) | B24: 0 | C24: 0 | D24: 0 | E24: 0 | F24: 0 | G24: 0 | H24: 0 | I24: 0 | J24: 0 | K24: 0 | L24: 0 | M24: 0 | N24: 0 | O24: 0 | P24: 0 | Q24: 0 | R24: 0 | S24: 0 | T24: 0 | U24: 0 | V24: 0 | W24: 0 | X24: 0 | Y24: 0 | Z24: 0 | AA24: 0 | AB24: 0 | AC24: 0 | AD24: 0 | AE24: 0 | AF24: 0 | AG24: 0
A25: hydrogen | B25: =$B$1 -> 0.1 | C25: =$B$1 -> 0.1 | D25: =$B$1 -> 0.1 | E25: =$B$1 -> 0.1 | F25: =$B$1 -> 0.1 | G25: =$B$1 -> 0.1 | H25: =$B$1 -> 0.1 | I25: =$B$1 -> 0.1 | ... AG25: =$B$1 -> 0.1

Sheet US_BFPaT-pretax-lignite
A1: Fuel Price ($/BTU) | B1: 2019 | C1: 2020 | D1: 2021 | E1: 2022 | F1: 2023 | G1: 2024 | H1: 2025 | I1: 2026 | J1: 2027 | K1: 2028 | L1: 2029 | M1: 2030 | N1: 2031 | O1: 2032 | P1: 2033 | Q1: 2034 | R1: 2035 | S1: 2036 | T1: 2037 | U1: 2038 | V1: 2039 | W1: 2040 | X1: 2041 | Y1: 2042 | Z1: 2043 | AA1: 2044 | AB1: 2045 | AC1: 2046 | AD1: 2047 | AE1: 2048 | AF1: 2049 | AG1: 2050
A2: Transportation Sector | B2: =D2 -> 0 | C2: =D2 -> 0 | D2: 0 | E2: 0 | F2: 0 | G2: 0 | H2: 0 | I2: 0 | J2: 0 | K2: 0 | L2: 0 | M2: 0 | N2: 0 | O2: 0 | P2: 0 | Q2: 0 | R2: 0 | S2: 0 | T2: 0 | U2: 0 | V2: 0 | W2: 0 | X2: 0 | Y2: 0 | Z2: 0 | AA2: 0 | AB2: 0 | AC2: 0 | AD2: 0 | AE2: 0 | AF2: 0 | AG2: 0
A3: Electricity Sector | B3: =D3 -> 1.4394778e-06 | C3: =D3 -> 1.4394778e-06 | D3: 1.4394778e-06 | E3: 1.5963145e-06 | F3: 1.7242891e-06 | G3: 1.3833783e-06 | H3: 1.3721105e-06 | I3: 1.3525997e-06 | J3: 1.3394924e-06 | K3: 1.3229763e-06 | L3: 1.3152749e-06 | M3: 1.3161896e-06 | N3: 1.3115401e-06 | O3: 1.2915801e-06 | P3: 1.283835e-06 | Q3: 1.2828684e-06 | R3: 1.2782862e-06 | S3: 1.2740287e-06 | T3: 1.2725294e-06 | U3: 1.2896551e-06 | V3: 1.2867171e-06 | W3: 1.2881288e-06 | X3: 1.2872249e-06 | Y3: 1.2860853e-06 | Z3: 1.2858239e-06 | AA3: 1.2823006e-06 | AB3: 1.2796003e-06 | AC3: 1.2800819e-06 | AD3: 1.2766239e-06 | AE3: 1.2708071e-06 | AF3: 1.2731558e-06 | AG3: 1.2711783e-06
A4: Residential Buildings Sector | B4: =D4 -> 0 | C4: =D4 -> 0 | D4: 0 | E4: 0 | F4: 0 | G4: 0 | H4: 0 | I4: 0 | J4: 0 | K4: 0 | L4: 0 | M4: 0 | N4: 0 | O4: 0 | P4: 0 | Q4: 0 | R4: 0 | S4: 0 | T4: 0 | U4: 0 | V4: 0 | W4: 0 | X4: 0 | Y4: 0 | Z4: 0 | AA4: 0 | AB4: 0 | AC4: 0 | AD4: 0 | AE4: 0 | AF4: 0 | AG4: 0
A5: Commercial Buildings Sector | B5: =D5 -> 0 | C5: =D5 -> 0 | D5: 0 | E5: 0 | F5: 0 | G5: 0 | H5: 0 | I5: 0 | J5: 0 | K5: 0 | L5: 0 | M5: 0 | N5: 0 | O5: 0 | P5: 0 | Q5: 0 | R5: 0 | S5: 0 | T5: 0 | U5: 0 | V5: 0 | W5: 0 | X5: 0 | Y5: 0 | Z5: 0 | AA5: 0 | AB5: 0 | AC5: 0 | AD5: 0 | AE5: 0 | AF5: 0 | AG5: 0
A6: Industry Sector | B6: =D6 -> 0 | C6: =D6 -> 0 | D6: 0 | E6: 0 | F6: 0 | G6: 0 | H6: 0 | I6: 0 | J6: 0 | K6: 0 | L6: 0 | M6: 0 | N6: 0 | O6: 0 | P6: 0 | Q6: 0 | R6: 0 | S6: 0 | T6: 0 | U6: 0 | V6: 0 | W6: 0 | X6: 0 | Y6: 0 | Z6: 0 | AA6: 0 | AB6: 0 | AC6: 0 | AD6: 0 | AE6: 0 | AF6: 0 | AG6: 0
A7: District Heating Sector | B7: =D7 -> 0 | C7: =D7 -> 0 | D7: 0 | E7: 0 | F7: 0 | G7: 0 | H7: 0 | I7: 0 | J7: 0 | K7: 0 | L7: 0 | M7: 0 | N7: 0 | O7: 0 | P7: 0 | Q7: 0 | R7: 0 | S7: 0 | T7: 0 | U7: 0 | V7: 0 | W7: 0 | X7: 0 | Y7: 0 | Z7: 0 | AA7: 0 | AB7: 0 | AC7: 0 | AD7: 0 | AE7: 0 | AF7: 0 | AG7: 0
A8: LULUCF Sector | B8: =D8 -> 0 | C8: =D8 -> 0 | D8: 0 | E8: 0 | F8: 0 | G8: 0 | H8: 0 | I8: 0 | J8: 0 | K8: 0 | L8: 0 | M8: 0 | N8: 0 | O8: 0 | P8: 0 | Q8: 0 | R8: 0 | S8: 0 | T8: 0 | U8: 0 | V8: 0 | W8: 0 | X8: 0 | Y8: 0 | Z8: 0 | AA8: 0 | AB8: 0 | AC8: 0 | AD8: 0 | AE8: 0 | AF8: 0 | AG8: 0
A9: Geoengineering Sector | B9: =D9 -> 0 | C9: =D9 -> 0 | D9: =D6 -> 0 | E9: =E6 -> 0 | F9: =F6 -> 0 | G9: =G6 -> 0 | H9: =H6 -> 0 | I9: =I6 -> 0 | J9: =J6 -> 0 | K9: =K6 -> 0 | ... AA9: =AA6 -> 0 | AB9: 0 | AC9: 0 | AD9: 0 | AE9: 0 | AF9: 0 | AG9: 0

Sheet Hydrogen
A1: Table 12: New Vehicle Fuel Economies, Fuel Economy Ratios, Gasoline Fuel Prices, and GasolineEquivalent Hydrogen Prices
A2: Vehicle Fuel Economies
B3: 2015 | C3: 2016 | D3: 2017 | E3: 2018 | F3: 2019 | G3: 2020 | H3: 2021 | I3: 2022 | J3: 2023 | K3: 2024 | L3: 2025
A4: New Fuel Cell Electric Vehicle (FCEV) | B4: 72 | C4: 74.1 | D4: 77.6 | E4: 79.3 | F4: 81.4 | G4: 83 | H4: 85.3 | I4: 87.3 | J4: 88.9 | K4: 90.8 | L4: 93.3
A5: New Conventional Gasoline Vehicle (CGV) | B5: 28.6 | C5: 29.8 | D5: 31.6 | E5: 32.7 | F5: 33.9 | G5: 35.1 | H5: 36.5 | I5: 37.8 | J5: 39.1 | K5: 40.4 | L5: 42.1
A6: Fuel Economy Ratio (FCEV/CGV) | B6: 2.52 | C6: 2.49 | D6: 2.46 | E6: 2.43 | F6: 2.4 | G6: 2.36 | H6: 2.34 | I6: 2.31 | J6: 2.27 | K6: 2.25 | L6: 2.22
A7: Fuel Prices
B8: 2015 | C8: 2016 | D8: 2017 | E8: 2018 | F8: 2019 | G8: 2020 | H8: 2021 | I8: 2022 | J8: 2023 | K8: 2024 | L8: 2025
A9: Gasoline Price ($/gal) | B9: 2.89 | C9: 3.35 | D9: 3.54 | E9: 3.63 | F9: 3.75 | G9: 4.01 | H9: 4.15 | I9: 4.32 | J9: 4.48 | K9: 4.64 | L9: 4.81
A10: Gasoline-Equivalent Hydrogen Price ($/kg) | B10: 7.28 | C10: 8.33 | D10: 8.7 | E10: 8.8 | F10: 9 | G10: 9.48 | H10: 9.71 | I10: 9.97 | J10: 10.19 | K10: 10.43 | L10: 10.66
A11: Hydrogen Price used in Scenario Analyses ($/kg) | B11: 14 | C11: 13.71 | D11: 13.42 | E11: 13.13 | F11: 12.85 | G11: 12.56 | H11: 12.27 | I11: 11.98 | J11: 11.69 | K11: 11.4 | L11: 11.11
A14: Hydrogen Energy Content (using Higher Heating Values)
A15: 61013 | B15: BTU/lb
A16: Source: U.S. DOE, Alternative Fuels Data Center, https://afdc.energy.gov/fuels/fuel_comparison_chart.pdf
A18: Conversion factor
A19: 2.20462 | B19: lb/kg
A22: Hydrogen Prices in $/BTU and Extrapolated to 2050
B23: 2015 | C23: 2016 | D23: 2017 | E23: 2018 | F23: 2019 | G23: 2020 | H23: 2021 | I23: 2022 | J23: 2023 | K23: 2024 | L23: 2025
A24: Hydrogen Prices ($/BTU) | B24: =B11/$A$19/$A$15 -> 0.00010408111 | C24: =C11/$A$19/$A$15 -> 0.00010192514 | D24: =D11/$A$19/$A$15 -> 9.9769178e-05 | E24: =E11/$A$19/$A$15 -> 9.7613212e-05 | F24: =F11/$A$19/$A$15 -> 9.553159e-05 | G24: =G11/$A$19/$A$15 -> 9.3375624e-05 | H24: =H11/$A$19/$A$15 -> 9.1219658e-05 | I24: =I11/$A$19/$A$15 -> 8.9063692e-05 | ... L24: =L11/$A$19/$A$15 -> 8.2595795e-05
A26: These data points form a linear cost decline. Projecting it out to 2050 results in a cost decline of 70% relative to 2018.
A27: However, the IEA source (The Future of Hydrogen) only projects a 50% cost cecline in hydrogen supplier CapEx and OpEx
A28: over that time period, and only for electrolysis, not for natural gas reforming or coal gasification.
A30: To have the drop in prices charged by hydrogen suppliers better match the price drops in their CapEx and OpEx costs,
A31: we use IEA data to project percentage declines in hydrogen cost, though we continue to rely on
A32: California Energy Commission / California Air Resources Board data for prices in the start year.
A33: We only use electrolysis costs here, because they are the only costs that decline, and they may drive the market
A34: price of hydrogen fuel. (In any case, these declines are already more conservative than extrapolating CEC/CARB values.)
A36: BNEF Year | D36: 2017 | E36: 2030 | F36: 2050
A37: Hydrogen Price ($/BTU) | D37: =D24 -> 9.9769178e-05 | E37: =1.97*(7.4)/1000000 -> 1.4578e-05 | F37: =1.01*(7.4)/1000000 -> 7.474e-06
A39: Hydrogen Prices using CEC/CARB Start Year Price and IEA Rate of Price Decline
B40: 2017 | C40: 2018 | D40: 2019 | E40: 2020 | F40: 2021 | G40: 2022 | H40: 2023 | I40: 2024 | J40: 2025 | K40: 2026 | L40: 2027 | M40: 2028 | N40: 2029 | O40: 2030 | P40: 2031 | Q40: 2032 | R40: 2033 | S40: 2034 | T40: 2035 | U40: 2036 | V40: 2037 | W40: 2038 | X40: 2039 | Y40: 2040 | Z40: 2041 | AA40: 2042 | AB40: 2043 | AC40: 2044 | AD40: 2045 | AE40: 2046 | AF40: 2047 | AG40: 2048 | AH40: 2049 | AI40: 2050
A41: Hydrogen Prices ($/BTU) | B41: =TREND($D37:$E37,$D$36:$E$36,B$40) -> 9.9769178e-05 | C41: =TREND($D37:$E37,$D$36:$E$36,C$40) -> 9.321601e-05 | D41: =TREND($D37:$E37,$D$36:$E$36,D$40) -> 8.6662843e-05 | E41: =TREND($D37:$E37,$D$36:$E$36,E$40) -> 8.0109675e-05 | F41: =TREND($D37:$E37,$D$36:$E$36,F$40) -> 7.3556508e-05 | G41: =TREND($D37:$E37,$D$36:$E$36,G$40) -> 6.700334e-05 | H41: =TREND($D37:$E37,$D$36:$E$36,H$40) -> 6.0450173e-05 | I41: =TREND($D37:$E37,$D$36:$E$36,I$40) -> 5.3897005e-05 | ... O41: =TREND($D37:$E37,$D$36:$E$36,O$40) -> 1.4578e-05 | P41: =TREND($E37:$F37,$E$36:$F$36,P$40) -> 1.42228e-05 | Q41: =TREND($E37:$F37,$E$36:$F$36,Q$40) -> 1.38676e-05 | R41: =TREND($E37:$F37,$E$36:$F$36,R$40) -> 1.35124e-05 | S41: =TREND($E37:$F37,$E$36:$F$36,S$40) -> 1.31572e-05 | T41: =TREND($E37:$F37,$E$36:$F$36,T$40) -> 1.2802e-05 | U41: =TREND($E37:$F37,$E$36:$F$36,U$40) -> 1.24468e-05 | V41: =TREND($E37:$F37,$E$36:$F$36,V$40) -> 1.20916e-05 | W41: =TREND($E37:$F37,$E$36:$F$36,W$40) -> 1.17364e-05 | ... AI41: =TREND($E37:$F37,$E$36:$F$36,AI$40) -> 7.474e-06
A43: Transportation Sector Hydrogen Prices
B44: 2021 | C44: 2022 | D44: 2023 | E44: 2024 | F44: 2025 | G44: 2026 | H44: 2027 | I44: 2028 | J44: 2029 | K44: 2030 | L44: 2031 | M44: 2032 | N44: 2033 | O44: 2034 | P44: 2035 | Q44: 2036 | R44: 2037 | S44: 2038 | T44: 2039 | U44: 2040 | V44: 2041 | W44: 2042 | X44: 2043 | Y44: 2044 | Z44: 2045 | AA44: 2046 | AB44: 2047 | AC44: 2048 | AD44: 2049 | AE44: 2050
A45: $/kg (2020 USD) | B45: #REF! | C45: #REF! | D45: #REF! | E45: #REF! | F45: #REF! | G45: #REF! | H45: #REF! | I45: #REF! | J45: #REF! | K45: #REF! | L45: #REF! | M45: #REF! | N45: #REF! | O45: #REF! | P45: #REF! | Q45: =$P$45 -> #REF! | R45: =$P$45 -> #REF! | S45: =$P$45 -> #REF! | T45: =$P$45 -> #REF! | U45: =$P$45 -> #REF! | V45: =$P$45 -> #REF! | W45: =$P$45 -> #REF! | X45: =$P$45 -> #REF! | ... AE45: =$P$45 -> #REF!
A46: $/BTU (2012 USD) | B46: =B45/$A$19/$A$15*dollars_2020_2012 -> #VALUE! | C46: =C45/$A$19/$A$15*dollars_2020_2012 -> #VALUE! | D46: =D45/$A$19/$A$15*dollars_2020_2012 -> #VALUE! | E46: =E45/$A$19/$A$15*dollars_2020_2012 -> #VALUE! | F46: =F45/$A$19/$A$15*dollars_2020_2012 -> #VALUE! | G46: =G45/$A$19/$A$15*dollars_2020_2012 -> #VALUE! | H46: =H45/$A$19/$A$15*dollars_2020_2012 -> #VALUE! | I46: =I45/$A$19/$A$15*dollars_2020_2012 -> #VALUE! | ... AE46: =AE45/$A$19/$A$15*dollars_2020_2012 -> #VALUE!

Sheet Pretax >

Sheet BFPaT-pretax-electricity
A1: Fuel Price ($/BTU) | B1: 2019 | C1: 2020 | D1: 2021 | E1: 2022 | F1: 2023 | G1: 2024 | H1: 2025 | I1: 2026 | J1: 2027 | K1: 2028 | L1: 2029 | M1: 2030 | N1: 2031 | O1: 2032 | P1: 2033 | Q1: 2034 | R1: 2035 | S1: 2036 | T1: 2037 | U1: 2038 | V1: 2039 | W1: 2040 | X1: 2041 | Y1: 2042 | Z1: 2043 | AA1: 2044 | AB1: 2045 | AC1: 2046 | AD1: 2047 | AE1: 2048 | AF1: 2049 | AG1: 2050
A2: Transportation Sector | B2: =B5 -> 2.2969477e-05 | C2: =C5 -> 2.2193482e-05 | D2: =D5 -> 2.4027654e-05 | E2: =E5 -> 2.3813453e-05 | F2: =F5 -> 2.3565671e-05 | G2: =G5 -> 2.3408235e-05 | H2: =H5 -> 2.3434013e-05 | I2: =I5 -> 2.3222281e-05 | ... AG2: =AG5 -> 2.3325313e-05
A3: Electricity Sector | B3: 0 | C3: 0 | D3: 0 | E3: 0 | F3: 0 | G3: 0 | H3: 0 | I3: 0 | J3: 0 | K3: 0 | L3: 0 | M3: 0 | N3: 0 | O3: 0 | P3: 0 | Q3: 0 | R3: 0 | S3: 0 | T3: 0 | U3: 0 | V3: 0 | W3: 0 | X3: 0 | Y3: 0 | Z3: 0 | AA3: 0 | AB3: 0 | AC3: 0 | AD3: 0 | AE3: 0 | AF3: 0 | AG3: 0
A4: Residential Buildings Sector | B4: =('Fuel Prices - ID'!L3/'Fuel Prices - ID'!$L$20)*(1-'Tax Percentages'!B5) -> 2.0020693e-05 | C4: =('Fuel Prices - ID'!M3/'Fuel Prices - ID'!$L$20)*(1-'Tax Percentages'!C5) -> 1.7847905e-05 | D4: =('Fuel Prices - ID'!N3/'Fuel Prices - ID'!$L$20)*(1-'Tax Percentages'!D5) -> 1.9112073e-05 | E4: =('Fuel Prices - ID'!O3/'Fuel Prices - ID'!$L$20)*(1-'Tax Percentages'!E5) -> 1.9423882e-05 | F4: =('Fuel Prices - ID'!P3/'Fuel Prices - ID'!$L$20)*(1-'Tax Percentages'!F5) -> 1.9735691e-05 | G4: =('Fuel Prices - ID'!Q3/'Fuel Prices - ID'!$L$20)*(1-'Tax Percentages'!G5) -> 2.00475e-05 | H4: =('Fuel Prices - ID'!R3/'Fuel Prices - ID'!$L$20)*(1-'Tax Percentages'!H5) -> 2.035931e-05 | I4: =('Fuel Prices - ID'!S3/'Fuel Prices - ID'!$L$20)*(1-'Tax Percentages'!I5) -> 2.0671119e-05 | ... AG4: =('Fuel Prices - ID'!AQ3/'Fuel Prices - ID'!$L$20)*(1-'Tax Percentages'!AG5) -> 2.8154541e-05
A5: Commercial Buildings Sector | B5: =('Fuel Prices - ID'!L5/'Fuel Prices - ID'!$L$20)*(1-'Tax Percentages'!B5) -> 2.2969477e-05 | C5: =('Fuel Prices - ID'!M5/'Fuel Prices - ID'!$L$20)*(1-'Tax Percentages'!C5) -> 2.2193482e-05 | D5: =('Fuel Prices - ID'!N5/'Fuel Prices - ID'!$L$20)*(1-'Tax Percentages'!D5) -> 2.4027654e-05 | E5: =('Fuel Prices - ID'!O5/'Fuel Prices - ID'!$L$20)*(1-'Tax Percentages'!E5) -> 2.3813453e-05 | F5: =('Fuel Prices - ID'!P5/'Fuel Prices - ID'!$L$20)*(1-'Tax Percentages'!F5) -> 2.3565671e-05 | G5: =('Fuel Prices - ID'!Q5/'Fuel Prices - ID'!$L$20)*(1-'Tax Percentages'!G5) -> 2.3408235e-05 | H5: =('Fuel Prices - ID'!R5/'Fuel Prices - ID'!$L$20)*(1-'Tax Percentages'!H5) -> 2.3434013e-05 | I5: =('Fuel Prices - ID'!S5/'Fuel Prices - ID'!$L$20)*(1-'Tax Percentages'!I5) -> 2.3222281e-05 | ... AG5: =('Fuel Prices - ID'!AQ5/'Fuel Prices - ID'!$L$20)*(1-'Tax Percentages'!AG5) -> 2.3325313e-05
A6: Industry Sector | B6: =('Fuel Prices - ID'!L4/'Fuel Prices - ID'!$L$20)*(1-'Tax Percentages'!B5) -> 2.0020693e-05 | C6: =('Fuel Prices - ID'!M4/'Fuel Prices - ID'!$L$20)*(1-'Tax Percentages'!C5) -> 1.9555096e-05 | D6: =('Fuel Prices - ID'!N4/'Fuel Prices - ID'!$L$20)*(1-'Tax Percentages'!D5) -> 2.0348022e-05 | E6: =('Fuel Prices - ID'!O4/'Fuel Prices - ID'!$L$20)*(1-'Tax Percentages'!E5) -> 2.0506043e-05 | F6: =('Fuel Prices - ID'!P4/'Fuel Prices - ID'!$L$20)*(1-'Tax Percentages'!F5) -> 2.0664064e-05 | G6: =('Fuel Prices - ID'!Q4/'Fuel Prices - ID'!$L$20)*(1-'Tax Percentages'!G5) -> 2.0822085e-05 | H6: =('Fuel Prices - ID'!R4/'Fuel Prices - ID'!$L$20)*(1-'Tax Percentages'!H5) -> 2.0980106e-05 | I6: =('Fuel Prices - ID'!S4/'Fuel Prices - ID'!$L$20)*(1-'Tax Percentages'!I5) -> 2.1138127e-05 | ... AG6: =('Fuel Prices - ID'!AQ4/'Fuel Prices - ID'!$L$20)*(1-'Tax Percentages'!AG5) -> 2.4930631e-05
A7: District Heating Sector | B7: =B6 -> 2.0020693e-05 | C7: =C6 -> 1.9555096e-05 | D7: =D6 -> 2.0348022e-05 | E7: =E6 -> 2.0506043e-05 | F7: =F6 -> 2.0664064e-05 | G7: =G6 -> 2.0822085e-05 | H7: =H6 -> 2.0980106e-05 | I7: =I6 -> 2.1138127e-05 | ... AG7: =AG6 -> 2.4930631e-05
A8: LULUCF Sector | B8: 0 | C8: 0 | D8: 0 | E8: 0 | F8: 0 | G8: 0 | H8: 0 | I8: 0 | J8: 0 | K8: 0 | L8: 0 | M8: 0 | N8: 0 | O8: 0 | P8: 0 | Q8: 0 | R8: 0 | S8: 0 | T8: 0 | U8: 0 | V8: 0 | W8: 0 | X8: 0 | Y8: 0 | Z8: 0 | AA8: 0 | AB8: 0 | AC8: 0 | AD8: 0 | AE8: 0 | AF8: 0 | AG8: 0
A9: Geoengineering Sector | B9: =B6 -> 2.0020693e-05 | C9: =C6 -> 1.9555096e-05 | D9: =D6 -> 2.0348022e-05 | E9: =E6 -> 2.0506043e-05 | F9: =F6 -> 2.0664064e-05 | G9: =G6 -> 2.0822085e-05 | H9: =H6 -> 2.0980106e-05 | I9: =I6 -> 2.1138127e-05 | ... AG9: =AG6 -> 2.4930631e-05

Sheet BFPaT-pretax-coal
A1: Fuel Price ($/BTU) | B1: 2019 | C1: 2020 | D1: 2021 | E1: 2022 | F1: 2023 | G1: 2024 | H1: 2025 | I1: 2026 | J1: 2027 | K1: 2028 | L1: 2029 | M1: 2030 | N1: 2031 | O1: 2032 | P1: 2033 | Q1: 2034 | R1: 2035 | S1: 2036 | T1: 2037 | U1: 2038 | V1: 2039 | W1: 2040 | X1: 2041 | Y1: 2042 | Z1: 2043 | AA1: 2044 | AB1: 2045 | AC1: 2046 | AD1: 2047 | AE1: 2048 | AF1: 2049 | AG1: 2050
A2: Transportation Sector | B2: 0 | C2: 0 | D2: 0 | E2: 0 | F2: 0 | G2: 0 | H2: 0 | I2: 0 | J2: 0 | K2: 0 | L2: 0 | M2: 0 | N2: 0 | O2: 0 | P2: 0 | Q2: 0 | R2: 0 | S2: 0 | T2: 0 | U2: 0 | V2: 0 | W2: 0 | X2: 0 | Y2: 0 | Z2: 0 | AA2: 0 | AB2: 0 | AC2: 0 | AD2: 0 | AE2: 0 | AF2: 0 | AG2: 0
A3: Electricity Sector | B3: =('Fuel Prices - ID'!L6/'Fuel Prices - ID'!$L$20)*(1-'Tax Percentages'!B6) -> 2.0175892e-06 | C3: =('Fuel Prices - ID'!M6/'Fuel Prices - ID'!$L$20)*(1-'Tax Percentages'!C6) -> 2.3279876e-06 | D3: =('Fuel Prices - ID'!N6/'Fuel Prices - ID'!$L$20)*(1-'Tax Percentages'!D6) -> 2.2781911e-06 | E3: =('Fuel Prices - ID'!O6/'Fuel Prices - ID'!$L$20)*(1-'Tax Percentages'!E6) -> 2.3607304e-06 | F3: =('Fuel Prices - ID'!P6/'Fuel Prices - ID'!$L$20)*(1-'Tax Percentages'!F6) -> 2.3995724e-06 | G3: =('Fuel Prices - ID'!Q6/'Fuel Prices - ID'!$L$20)*(1-'Tax Percentages'!G6) -> 2.3995724e-06 | H3: =('Fuel Prices - ID'!R6/'Fuel Prices - ID'!$L$20)*(1-'Tax Percentages'!H6) -> 2.3995724e-06 | I3: =('Fuel Prices - ID'!S6/'Fuel Prices - ID'!$L$20)*(1-'Tax Percentages'!I6) -> 2.3947172e-06 | ... AG3: =('Fuel Prices - ID'!AQ6/'Fuel Prices - ID'!$L$20)*(1-'Tax Percentages'!AG6) -> 1.9820207e-06
A4: Residential Buildings Sector | B4: 0 | C4: 0 | D4: 0 | E4: 0 | F4: 0 | G4: 0 | H4: 0 | I4: 0 | J4: 0 | K4: 0 | L4: 0 | M4: 0 | N4: 0 | O4: 0 | P4: 0 | Q4: 0 | R4: 0 | S4: 0 | T4: 0 | U4: 0 | V4: 0 | W4: 0 | X4: 0 | Y4: 0 | Z4: 0 | AA4: 0 | AB4: 0 | AC4: 0 | AD4: 0 | AE4: 0 | AF4: 0 | AG4: 0
A5: Commercial Buildings Sector | B5: 0 | C5: 0 | D5: 0 | E5: 0 | F5: 0 | G5: 0 | H5: 0 | I5: 0 | J5: 0 | K5: 0 | L5: 0 | M5: 0 | N5: 0 | O5: 0 | P5: 0 | Q5: 0 | R5: 0 | S5: 0 | T5: 0 | U5: 0 | V5: 0 | W5: 0 | X5: 0 | Y5: 0 | Z5: 0 | AA5: 0 | AB5: 0 | AC5: 0 | AD5: 0 | AE5: 0 | AF5: 0 | AG5: 0
A6: Industry Sector | B6: =B3 -> 2.0175892e-06 | C6: =C3 -> 2.3279876e-06 | D6: =D3 -> 2.2781911e-06 | E6: =E3 -> 2.3607304e-06 | F6: =F3 -> 2.3995724e-06 | G6: =G3 -> 2.3995724e-06 | H6: =H3 -> 2.3995724e-06 | I6: =I3 -> 2.3947172e-06 | ... AG6: =AG3 -> 1.9820207e-06
A7: District Heating Sector | B7: =B3 -> 2.0175892e-06 | C7: =C3 -> 2.3279876e-06 | D7: =D3 -> 2.2781911e-06 | E7: =E3 -> 2.3607304e-06 | F7: =F3 -> 2.3995724e-06 | G7: =G3 -> 2.3995724e-06 | H7: =H3 -> 2.3995724e-06 | I7: =I3 -> 2.3947172e-06 | ... AG7: =AG3 -> 1.9820207e-06
A8: LULUCF Sector | B8: 0 | C8: 0 | D8: 0 | E8: 0 | F8: 0 | G8: 0 | H8: 0 | I8: 0 | J8: 0 | K8: 0 | L8: 0 | M8: 0 | N8: 0 | O8: 0 | P8: 0 | Q8: 0 | R8: 0 | S8: 0 | T8: 0 | U8: 0 | V8: 0 | W8: 0 | X8: 0 | Y8: 0 | Z8: 0 | AA8: 0 | AB8: 0 | AC8: 0 | AD8: 0 | AE8: 0 | AF8: 0 | AG8: 0
A9: Geoengineering Sector | B9: =B6 -> 2.0175892e-06 | C9: =C6 -> 2.3279876e-06 | D9: =D6 -> 2.2781911e-06 | E9: =E6 -> 2.3607304e-06 | F9: =F6 -> 2.3995724e-06 | G9: =G6 -> 2.3995724e-06 | H9: =H6 -> 2.3995724e-06 | I9: =I6 -> 2.3947172e-06 | ... AG9: =AG6 -> 1.9820207e-06

Sheet BFPaT-pretax-natgas
A1: Fuel Price ($/BTU) | B1: 2019 | C1: 2020 | D1: 2021 | E1: 2022 | F1: 2023 | G1: 2024 | H1: 2025 | I1: 2026 | J1: 2027 | K1: 2028 | L1: 2029 | M1: 2030 | N1: 2031 | O1: 2032 | P1: 2033 | Q1: 2034 | R1: 2035 | S1: 2036 | T1: 2037 | U1: 2038 | V1: 2039 | W1: 2040 | X1: 2041 | Y1: 2042 | Z1: 2043 | AA1: 2044 | AB1: 2045 | AC1: 2046 | AD1: 2047 | AE1: 2048 | AF1: 2049 | AG1: 2050
A2: Transportation Sector | B2: =('Fuel Prices - ID'!L8/'Fuel Prices - ID'!$L$20)*(1-'Tax Percentages'!B7) -> 3.9265391e-07 | C2: =('Fuel Prices - ID'!M8/10^6)*(1-'Tax Percentages'!C7) -> 2.691e-06 | D2: =('Fuel Prices - ID'!N8/10^6)*(1-'Tax Percentages'!D7) -> 3.0681818e-06 | E2: =('Fuel Prices - ID'!O8/10^6)*(1-'Tax Percentages'!E7) -> 2.8561983e-06 | F2: =('Fuel Prices - ID'!P8/10^6)*(1-'Tax Percentages'!F7) -> 2.7877618e-06 | G2: =('Fuel Prices - ID'!Q8/10^6)*(1-'Tax Percentages'!G7) -> 2.8153765e-06 | H2: =('Fuel Prices - ID'!R8/10^6)*(1-'Tax Percentages'!H7) -> 2.7677744e-06 | I2: =('Fuel Prices - ID'!S8/10^6)*(1-'Tax Percentages'!I7) -> 2.6634812e-06 | J2: =('Fuel Prices - ID'!T8/10^6)*(1-'Tax Percentages'!J7) -> 2.6928886e-06 | ... AG2: =('Fuel Prices - ID'!AQ8/10^6)*(1-'Tax Percentages'!AG7) -> 2.7517618e-06
A3: Electricity Sector | B3: =B2 -> 3.9265391e-07 | C3: =C2 -> 2.691e-06 | D3: =D2 -> 3.0681818e-06 | E3: =E2 -> 2.8561983e-06 | F3: =F2 -> 2.7877618e-06 | G3: =G2 -> 2.8153765e-06 | H3: =H2 -> 2.7677744e-06 | I3: =I2 -> 2.6634812e-06 | ... AG3: =AG2 -> 2.7517618e-06
A4: Residential Buildings Sector | B4: =B2 -> 3.9265391e-07 | C4: =C2 -> 2.691e-06 | D4: =D2 -> 3.0681818e-06 | E4: =E2 -> 2.8561983e-06 | F4: =F2 -> 2.7877618e-06 | G4: =G2 -> 2.8153765e-06 | H4: =H2 -> 2.7677744e-06 | I4: =I2 -> 2.6634812e-06 | ... AG4: =AG2 -> 2.7517618e-06
A5: Commercial Buildings Sector | B5: =B2 -> 3.9265391e-07 | C5: =C2 -> 2.691e-06 | D5: =D2 -> 3.0681818e-06 | E5: =E2 -> 2.8561983e-06 | F5: =F2 -> 2.7877618e-06 | G5: =G2 -> 2.8153765e-06 | H5: =H2 -> 2.7677744e-06 | I5: =I2 -> 2.6634812e-06 | ... AG5: =AG2 -> 2.7517618e-06
A6: Industry Sector | B6: =B2 -> 3.9265391e-07 | C6: =C2 -> 2.691e-06 | D6: =D2 -> 3.0681818e-06 | E6: =E2 -> 2.8561983e-06 | F6: =F2 -> 2.7877618e-06 | G6: =G2 -> 2.8153765e-06 | H6: =H2 -> 2.7677744e-06 | I6: =I2 -> 2.6634812e-06 | ... AG6: =AG2 -> 2.7517618e-06
A7: District Heating Sector | B7: =B3 -> 3.9265391e-07 | C7: =C3 -> 2.691e-06 | D7: =D3 -> 3.0681818e-06 | E7: =E3 -> 2.8561983e-06 | F7: =F3 -> 2.7877618e-06 | G7: =G3 -> 2.8153765e-06 | H7: =H3 -> 2.7677744e-06 | I7: =I3 -> 2.6634812e-06 | ... AG7: =AG3 -> 2.7517618e-06
A8: LULUCF Sector | B8: 0 | C8: 0 | D8: 0 | E8: 0 | F8: 0 | G8: 0 | H8: 0 | I8: 0 | J8: 0 | K8: 0 | L8: 0 | M8: 0 | N8: 0 | O8: 0 | P8: 0 | Q8: 0 | R8: 0 | S8: 0 | T8: 0 | U8: 0 | V8: 0 | W8: 0 | X8: 0 | Y8: 0 | Z8: 0 | AA8: 0 | AB8: 0 | AC8: 0 | AD8: 0 | AE8: 0 | AF8: 0 | AG8: 0
A9: Geoengineering Sector | B9: =B6 -> 3.9265391e-07 | C9: =C6 -> 2.691e-06 | D9: =D6 -> 3.0681818e-06 | E9: =E6 -> 2.8561983e-06 | F9: =F6 -> 2.7877618e-06 | G9: =G6 -> 2.8153765e-06 | H9: =H6 -> 2.7677744e-06 | I9: =I6 -> 2.6634812e-06 | ... AG9: =AG6 -> 2.7517618e-06

Sheet BFPaT-pretax-nuclear
A1: Fuel Price ($/BTU) | B1: 2019 | C1: 2020 | D1: 2021 | E1: 2022 | F1: 2023 | G1: 2024 | H1: 2025 | I1: 2026 | J1: 2027 | K1: 2028 | L1: 2029 | M1: 2030 | N1: 2031 | O1: 2032 | P1: 2033 | Q1: 2034 | R1: 2035 | S1: 2036 | T1: 2037 | U1: 2038 | V1: 2039 | W1: 2040 | X1: 2041 | Y1: 2042 | Z1: 2043 | AA1: 2044 | AB1: 2045 | AC1: 2046 | AD1: 2047 | AE1: 2048 | AF1: 2049 | AG1: 2050
A2: Transportation Sector | B2: 0 | C2: 0 | D2: 0 | E2: 0 | F2: 0 | G2: 0 | H2: 0 | I2: 0 | J2: 0 | K2: 0 | L2: 0 | M2: 0 | N2: 0 | O2: 0 | P2: 0 | Q2: 0 | R2: 0 | S2: 0 | T2: 0 | U2: 0 | V2: 0 | W2: 0 | X2: 0 | Y2: 0 | Z2: 0 | AA2: 0 | AB2: 0 | AC2: 0 | AD2: 0 | AE2: 0 | AF2: 0 | AG2: 0
A3: Electricity Sector | B3: 0 | C3: 0 | D3: 0 | E3: 0 | F3: 0 | G3: 0 | H3: 0 | I3: 0 | J3: 0 | K3: 0 | L3: 0 | M3: 0 | N3: 0 | O3: 0 | P3: 0 | Q3: 0 | R3: 0 | S3: 0 | T3: 0 | U3: 0 | V3: 0 | W3: 0 | X3: 0 | Y3: 0 | Z3: 0 | AA3: 0 | AB3: 0 | AC3: 0 | AD3: 0 | AE3: 0 | AF3: 0 | AG3: 0
A4: Residential Buildings Sector | B4: 0 | C4: 0 | D4: 0 | E4: 0 | F4: 0 | G4: 0 | H4: 0 | I4: 0 | J4: 0 | K4: 0 | L4: 0 | M4: 0 | N4: 0 | O4: 0 | P4: 0 | Q4: 0 | R4: 0 | S4: 0 | T4: 0 | U4: 0 | V4: 0 | W4: 0 | X4: 0 | Y4: 0 | Z4: 0 | AA4: 0 | AB4: 0 | AC4: 0 | AD4: 0 | AE4: 0 | AF4: 0 | AG4: 0
A5: Commercial Buildings Sector | B5: 0 | C5: 0 | D5: 0 | E5: 0 | F5: 0 | G5: 0 | H5: 0 | I5: 0 | J5: 0 | K5: 0 | L5: 0 | M5: 0 | N5: 0 | O5: 0 | P5: 0 | Q5: 0 | R5: 0 | S5: 0 | T5: 0 | U5: 0 | V5: 0 | W5: 0 | X5: 0 | Y5: 0 | Z5: 0 | AA5: 0 | AB5: 0 | AC5: 0 | AD5: 0 | AE5: 0 | AF5: 0 | AG5: 0
A6: Industry Sector | B6: 0 | C6: 0 | D6: 0 | E6: 0 | F6: 0 | G6: 0 | H6: 0 | I6: 0 | J6: 0 | K6: 0 | L6: 0 | M6: 0 | N6: 0 | O6: 0 | P6: 0 | Q6: 0 | R6: 0 | S6: 0 | T6: 0 | U6: 0 | V6: 0 | W6: 0 | X6: 0 | Y6: 0 | Z6: 0 | AA6: 0 | AB6: 0 | AC6: 0 | AD6: 0 | AE6: 0 | AF6: 0 | AG6: 0
A7: District Heating Sector | B7: 0 | C7: 0 | D7: 0 | E7: 0 | F7: 0 | G7: 0 | H7: 0 | I7: 0 | J7: 0 | K7: 0 | L7: 0 | M7: 0 | N7: 0 | O7: 0 | P7: 0 | Q7: 0 | R7: 0 | S7: 0 | T7: 0 | U7: 0 | V7: 0 | W7: 0 | X7: 0 | Y7: 0 | Z7: 0 | AA7: 0 | AB7: 0 | AC7: 0 | AD7: 0 | AE7: 0 | AF7: 0 | AG7: 0
A8: LULUCF Sector | B8: 0 | C8: 0 | D8: 0 | E8: 0 | F8: 0 | G8: 0 | H8: 0 | I8: 0 | J8: 0 | K8: 0 | L8: 0 | M8: 0 | N8: 0 | O8: 0 | P8: 0 | Q8: 0 | R8: 0 | S8: 0 | T8: 0 | U8: 0 | V8: 0 | W8: 0 | X8: 0 | Y8: 0 | Z8: 0 | AA8: 0 | AB8: 0 | AC8: 0 | AD8: 0 | AE8: 0 | AF8: 0 | AG8: 0
A9: Geoengineering Sector | B9: =B6 -> 0 | C9: =C6 -> 0 | D9: =D6 -> 0 | E9: =E6 -> 0 | F9: =F6 -> 0 | G9: =G6 -> 0 | H9: =H6 -> 0 | I9: =I6 -> 0 | ... AG9: =AG6 -> 0

Sheet BFPaT-pretax-hydro
A1: Fuel Price ($/BTU) | B1: 2019 | C1: 2020 | D1: 2021 | E1: 2022 | F1: 2023 | G1: 2024 | H1: 2025 | I1: 2026 | J1: 2027 | K1: 2028 | L1: 2029 | M1: 2030 | N1: 2031 | O1: 2032 | P1: 2033 | Q1: 2034 | R1: 2035 | S1: 2036 | T1: 2037 | U1: 2038 | V1: 2039 | W1: 2040 | X1: 2041 | Y1: 2042 | Z1: 2043 | AA1: 2044 | AB1: 2045 | AC1: 2046 | AD1: 2047 | AE1: 2048 | AF1: 2049 | AG1: 2050
A2: Transportation Sector | B2: 0 | C2: 0 | D2: 0 | E2: 0 | F2: 0 | G2: 0 | H2: 0 | I2: 0 | J2: 0 | K2: 0 | L2: 0 | M2: 0 | N2: 0 | O2: 0 | P2: 0 | Q2: 0 | R2: 0 | S2: 0 | T2: 0 | U2: 0 | V2: 0 | W2: 0 | X2: 0 | Y2: 0 | Z2: 0 | AA2: 0 | AB2: 0 | AC2: 0 | AD2: 0 | AE2: 0 | AF2: 0 | AG2: 0
A3: Electricity Sector | B3: 0 | C3: 0 | D3: 0 | E3: 0 | F3: 0 | G3: 0 | H3: 0 | I3: 0 | J3: 0 | K3: 0 | L3: 0 | M3: 0 | N3: 0 | O3: 0 | P3: 0 | Q3: 0 | R3: 0 | S3: 0 | T3: 0 | U3: 0 | V3: 0 | W3: 0 | X3: 0 | Y3: 0 | Z3: 0 | AA3: 0 | AB3: 0 | AC3: 0 | AD3: 0 | AE3: 0 | AF3: 0 | AG3: 0
A4: Residential Buildings Sector | B4: 0 | C4: 0 | D4: 0 | E4: 0 | F4: 0 | G4: 0 | H4: 0 | I4: 0 | J4: 0 | K4: 0 | L4: 0 | M4: 0 | N4: 0 | O4: 0 | P4: 0 | Q4: 0 | R4: 0 | S4: 0 | T4: 0 | U4: 0 | V4: 0 | W4: 0 | X4: 0 | Y4: 0 | Z4: 0 | AA4: 0 | AB4: 0 | AC4: 0 | AD4: 0 | AE4: 0 | AF4: 0 | AG4: 0
A5: Commercial Buildings Sector | B5: 0 | C5: 0 | D5: 0 | E5: 0 | F5: 0 | G5: 0 | H5: 0 | I5: 0 | J5: 0 | K5: 0 | L5: 0 | M5: 0 | N5: 0 | O5: 0 | P5: 0 | Q5: 0 | R5: 0 | S5: 0 | T5: 0 | U5: 0 | V5: 0 | W5: 0 | X5: 0 | Y5: 0 | Z5: 0 | AA5: 0 | AB5: 0 | AC5: 0 | AD5: 0 | AE5: 0 | AF5: 0 | AG5: 0
A6: Industry Sector | B6: 0 | C6: 0 | D6: 0 | E6: 0 | F6: 0 | G6: 0 | H6: 0 | I6: 0 | J6: 0 | K6: 0 | L6: 0 | M6: 0 | N6: 0 | O6: 0 | P6: 0 | Q6: 0 | R6: 0 | S6: 0 | T6: 0 | U6: 0 | V6: 0 | W6: 0 | X6: 0 | Y6: 0 | Z6: 0 | AA6: 0 | AB6: 0 | AC6: 0 | AD6: 0 | AE6: 0 | AF6: 0 | AG6: 0
A7: District Heating Sector | B7: 0 | C7: 0 | D7: 0 | E7: 0 | F7: 0 | G7: 0 | H7: 0 | I7: 0 | J7: 0 | K7: 0 | L7: 0 | M7: 0 | N7: 0 | O7: 0 | P7: 0 | Q7: 0 | R7: 0 | S7: 0 | T7: 0 | U7: 0 | V7: 0 | W7: 0 | X7: 0 | Y7: 0 | Z7: 0 | AA7: 0 | AB7: 0 | AC7: 0 | AD7: 0 | AE7: 0 | AF7: 0 | AG7: 0
A8: LULUCF Sector | B8: 0 | C8: 0 | D8: 0 | E8: 0 | F8: 0 | G8: 0 | H8: 0 | I8: 0 | J8: 0 | K8: 0 | L8: 0 | M8: 0 | N8: 0 | O8: 0 | P8: 0 | Q8: 0 | R8: 0 | S8: 0 | T8: 0 | U8: 0 | V8: 0 | W8: 0 | X8: 0 | Y8: 0 | Z8: 0 | AA8: 0 | AB8: 0 | AC8: 0 | AD8: 0 | AE8: 0 | AF8: 0 | AG8: 0
A9: Geoengineering Sector | B9: =B6 -> 0 | C9: =C6 -> 0 | D9: =D6 -> 0 | E9: =E6 -> 0 | F9: =F6 -> 0 | G9: =G6 -> 0 | H9: =H6 -> 0 | I9: =I6 -> 0 | ... Y9: =Y6 -> 0 | Z9: 0 | AA9: 0 | AB9: 0 | AC9: 0 | AD9: 0 | AE9: 0 | AF9: 0 | AG9: 0

Sheet BFPaT-pretax-wind
A1: Fuel Price ($/BTU) | B1: 2019 | C1: 2020 | D1: 2021 | E1: 2022 | F1: 2023 | G1: 2024 | H1: 2025 | I1: 2026 | J1: 2027 | K1: 2028 | L1: 2029 | M1: 2030 | N1: 2031 | O1: 2032 | P1: 2033 | Q1: 2034 | R1: 2035 | S1: 2036 | T1: 2037 | U1: 2038 | V1: 2039 | W1: 2040 | X1: 2041 | Y1: 2042 | Z1: 2043 | AA1: 2044 | AB1: 2045 | AC1: 2046 | AD1: 2047 | AE1: 2048 | AF1: 2049 | AG1: 2050
A2: Transportation Sector | B2: 0 | C2: 0 | D2: 0 | E2: 0 | F2: 0 | G2: 0 | H2: 0 | I2: 0 | J2: 0 | K2: 0 | L2: 0 | M2: 0 | N2: 0 | O2: 0 | P2: 0 | Q2: 0 | R2: 0 | S2: 0 | T2: 0 | U2: 0 | V2: 0 | W2: 0 | X2: 0 | Y2: 0 | Z2: 0 | AA2: 0 | AB2: 0 | AC2: 0 | AD2: 0 | AE2: 0 | AF2: 0 | AG2: 0
A3: Electricity Sector | B3: 0 | C3: 0 | D3: 0 | E3: 0 | F3: 0 | G3: 0 | H3: 0 | I3: 0 | J3: 0 | K3: 0 | L3: 0 | M3: 0 | N3: 0 | O3: 0 | P3: 0 | Q3: 0 | R3: 0 | S3: 0 | T3: 0 | U3: 0 | V3: 0 | W3: 0 | X3: 0 | Y3: 0 | Z3: 0 | AA3: 0 | AB3: 0 | AC3: 0 | AD3: 0 | AE3: 0 | AF3: 0 | AG3: 0
A4: Residential Buildings Sector | B4: 0 | C4: 0 | D4: 0 | E4: 0 | F4: 0 | G4: 0 | H4: 0 | I4: 0 | J4: 0 | K4: 0 | L4: 0 | M4: 0 | N4: 0 | O4: 0 | P4: 0 | Q4: 0 | R4: 0 | S4: 0 | T4: 0 | U4: 0 | V4: 0 | W4: 0 | X4: 0 | Y4: 0 | Z4: 0 | AA4: 0 | AB4: 0 | AC4: 0 | AD4: 0 | AE4: 0 | AF4: 0 | AG4: 0
A5: Commercial Buildings Sector | B5: 0 | C5: 0 | D5: 0 | E5: 0 | F5: 0 | G5: 0 | H5: 0 | I5: 0 | J5: 0 | K5: 0 | L5: 0 | M5: 0 | N5: 0 | O5: 0 | P5: 0 | Q5: 0 | R5: 0 | S5: 0 | T5: 0 | U5: 0 | V5: 0 | W5: 0 | X5: 0 | Y5: 0 | Z5: 0 | AA5: 0 | AB5: 0 | AC5: 0 | AD5: 0 | AE5: 0 | AF5: 0 | AG5: 0
A6: Industry Sector | B6: 0 | C6: 0 | D6: 0 | E6: 0 | F6: 0 | G6: 0 | H6: 0 | I6: 0 | J6: 0 | K6: 0 | L6: 0 | M6: 0 | N6: 0 | O6: 0 | P6: 0 | Q6: 0 | R6: 0 | S6: 0 | T6: 0 | U6: 0 | V6: 0 | W6: 0 | X6: 0 | Y6: 0 | Z6: 0 | AA6: 0 | AB6: 0 | AC6: 0 | AD6: 0 | AE6: 0 | AF6: 0 | AG6: 0
A7: District Heating Sector | B7: 0 | C7: 0 | D7: 0 | E7: 0 | F7: 0 | G7: 0 | H7: 0 | I7: 0 | J7: 0 | K7: 0 | L7: 0 | M7: 0 | N7: 0 | O7: 0 | P7: 0 | Q7: 0 | R7: 0 | S7: 0 | T7: 0 | U7: 0 | V7: 0 | W7: 0 | X7: 0 | Y7: 0 | Z7: 0 | AA7: 0 | AB7: 0 | AC7: 0 | AD7: 0 | AE7: 0 | AF7: 0 | AG7: 0
A8: LULUCF Sector | B8: 0 | C8: 0 | D8: 0 | E8: 0 | F8: 0 | G8: 0 | H8: 0 | I8: 0 | J8: 0 | K8: 0 | L8: 0 | M8: 0 | N8: 0 | O8: 0 | P8: 0 | Q8: 0 | R8: 0 | S8: 0 | T8: 0 | U8: 0 | V8: 0 | W8: 0 | X8: 0 | Y8: 0 | Z8: 0 | AA8: 0 | AB8: 0 | AC8: 0 | AD8: 0 | AE8: 0 | AF8: 0 | AG8: 0
A9: Geoengineering Sector | B9: =B6 -> 0 | C9: =C6 -> 0 | D9: =D6 -> 0 | E9: =E6 -> 0 | F9: =F6 -> 0 | G9: =G6 -> 0 | H9: =H6 -> 0 | I9: =I6 -> 0 | ... Y9: =Y6 -> 0 | Z9: 0 | AA9: 0 | AB9: 0 | AC9: 0 | AD9: 0 | AE9: 0 | AF9: 0 | AG9: 0

Sheet BFPaT-pretax-solar
A1: Fuel Price ($/BTU) | B1: 2019 | C1: 2020 | D1: 2021 | E1: 2022 | F1: 2023 | G1: 2024 | H1: 2025 | I1: 2026 | J1: 2027 | K1: 2028 | L1: 2029 | M1: 2030 | N1: 2031 | O1: 2032 | P1: 2033 | Q1: 2034 | R1: 2035 | S1: 2036 | T1: 2037 | U1: 2038 | V1: 2039 | W1: 2040 | X1: 2041 | Y1: 2042 | Z1: 2043 | AA1: 2044 | AB1: 2045 | AC1: 2046 | AD1: 2047 | AE1: 2048 | AF1: 2049 | AG1: 2050
A2: Transportation Sector | B2: 0 | C2: 0 | D2: 0 | E2: 0 | F2: 0 | G2: 0 | H2: 0 | I2: 0 | J2: 0 | K2: 0 | L2: 0 | M2: 0 | N2: 0 | O2: 0 | P2: 0 | Q2: 0 | R2: 0 | S2: 0 | T2: 0 | U2: 0 | V2: 0 | W2: 0 | X2: 0 | Y2: 0 | Z2: 0 | AA2: 0 | AB2: 0 | AC2: 0 | AD2: 0 | AE2: 0 | AF2: 0 | AG2: 0
A3: Electricity Sector | B3: 0 | C3: 0 | D3: 0 | E3: 0 | F3: 0 | G3: 0 | H3: 0 | I3: 0 | J3: 0 | K3: 0 | L3: 0 | M3: 0 | N3: 0 | O3: 0 | P3: 0 | Q3: 0 | R3: 0 | S3: 0 | T3: 0 | U3: 0 | V3: 0 | W3: 0 | X3: 0 | Y3: 0 | Z3: 0 | AA3: 0 | AB3: 0 | AC3: 0 | AD3: 0 | AE3: 0 | AF3: 0 | AG3: 0
A4: Residential Buildings Sector | B4: 0 | C4: 0 | D4: 0 | E4: 0 | F4: 0 | G4: 0 | H4: 0 | I4: 0 | J4: 0 | K4: 0 | L4: 0 | M4: 0 | N4: 0 | O4: 0 | P4: 0 | Q4: 0 | R4: 0 | S4: 0 | T4: 0 | U4: 0 | V4: 0 | W4: 0 | X4: 0 | Y4: 0 | Z4: 0 | AA4: 0 | AB4: 0 | AC4: 0 | AD4: 0 | AE4: 0 | AF4: 0 | AG4: 0
A5: Commercial Buildings Sector | B5: 0 | C5: 0 | D5: 0 | E5: 0 | F5: 0 | G5: 0 | H5: 0 | I5: 0 | J5: 0 | K5: 0 | L5: 0 | M5: 0 | N5: 0 | O5: 0 | P5: 0 | Q5: 0 | R5: 0 | S5: 0 | T5: 0 | U5: 0 | V5: 0 | W5: 0 | X5: 0 | Y5: 0 | Z5: 0 | AA5: 0 | AB5: 0 | AC5: 0 | AD5: 0 | AE5: 0 | AF5: 0 | AG5: 0
A6: Industry Sector | B6: 0 | C6: 0 | D6: 0 | E6: 0 | F6: 0 | G6: 0 | H6: 0 | I6: 0 | J6: 0 | K6: 0 | L6: 0 | M6: 0 | N6: 0 | O6: 0 | P6: 0 | Q6: 0 | R6: 0 | S6: 0 | T6: 0 | U6: 0 | V6: 0 | W6: 0 | X6: 0 | Y6: 0 | Z6: 0 | AA6: 0 | AB6: 0 | AC6: 0 | AD6: 0 | AE6: 0 | AF6: 0 | AG6: 0
A7: District Heating Sector | B7: 0 | C7: 0 | D7: 0 | E7: 0 | F7: 0 | G7: 0 | H7: 0 | I7: 0 | J7: 0 | K7: 0 | L7: 0 | M7: 0 | N7: 0 | O7: 0 | P7: 0 | Q7: 0 | R7: 0 | S7: 0 | T7: 0 | U7: 0 | V7: 0 | W7: 0 | X7: 0 | Y7: 0 | Z7: 0 | AA7: 0 | AB7: 0 | AC7: 0 | AD7: 0 | AE7: 0 | AF7: 0 | AG7: 0
A8: LULUCF Sector | B8: 0 | C8: 0 | D8: 0 | E8: 0 | F8: 0 | G8: 0 | H8: 0 | I8: 0 | J8: 0 | K8: 0 | L8: 0 | M8: 0 | N8: 0 | O8: 0 | P8: 0 | Q8: 0 | R8: 0 | S8: 0 | T8: 0 | U8: 0 | V8: 0 | W8: 0 | X8: 0 | Y8: 0 | Z8: 0 | AA8: 0 | AB8: 0 | AC8: 0 | AD8: 0 | AE8: 0 | AF8: 0 | AG8: 0
A9: Geoengineering Sector | B9: =B6 -> 0 | C9: =C6 -> 0 | D9: =D6 -> 0 | E9: =E6 -> 0 | F9: =F6 -> 0 | G9: =G6 -> 0 | H9: =H6 -> 0 | I9: =I6 -> 0 | ... Y9: =Y6 -> 0 | Z9: 0 | AA9: 0 | AB9: 0 | AC9: 0 | AD9: 0 | AE9: 0 | AF9: 0 | AG9: 0

Sheet BFPaT-pretax-biomass
A1: Fuel Price ($/BTU) | B1: 2019 | C1: 2020 | D1: 2021 | E1: 2022 | F1: 2023 | G1: 2024 | H1: 2025 | I1: 2026 | J1: 2027 | K1: 2028 | L1: 2029 | M1: 2030 | N1: 2031 | O1: 2032 | P1: 2033 | Q1: 2034 | R1: 2035 | S1: 2036 | T1: 2037 | U1: 2038 | V1: 2039 | W1: 2040 | X1: 2041 | Y1: 2042 | Z1: 2043 | AA1: 2044 | AB1: 2045 | AC1: 2046 | AD1: 2047 | AE1: 2048 | AF1: 2049 | AG1: 2050
A2: Transportation Sector | B2: 0 | C2: 0 | D2: 0 | E2: 0 | F2: 0 | G2: 0 | H2: 0 | I2: 0 | J2: 0 | K2: 0 | L2: 0 | M2: 0 | N2: 0 | O2: 0 | P2: 0 | Q2: 0 | R2: 0 | S2: 0 | T2: 0 | U2: 0 | V2: 0 | W2: 0 | X2: 0 | Y2: 0 | Z2: 0 | AA2: 0 | AB2: 0 | AC2: 0 | AD2: 0 | AE2: 0 | AF2: 0 | AG2: 0
A3: Electricity Sector | B3: 0 | C3: 0 | D3: 0 | E3: 0 | F3: 0 | G3: 0 | H3: 0 | I3: 0 | J3: 0 | K3: 0 | L3: 0 | M3: 0 | N3: 0 | O3: 0 | P3: 0 | Q3: 0 | R3: 0 | S3: 0 | T3: 0 | U3: 0 | V3: 0 | W3: 0 | X3: 0 | Y3: 0 | Z3: 0 | AA3: 0 | AB3: 0 | AC3: 0 | AD3: 0 | AE3: 0 | AF3: 0 | AG3: 0
A4: Residential Buildings Sector | B4: 0 | C4: 0 | D4: 0 | E4: 0 | F4: 0 | G4: 0 | H4: 0 | I4: 0 | J4: 0 | K4: 0 | L4: 0 | M4: 0 | N4: 0 | O4: 0 | P4: 0 | Q4: 0 | R4: 0 | S4: 0 | T4: 0 | U4: 0 | V4: 0 | W4: 0 | X4: 0 | Y4: 0 | Z4: 0 | AA4: 0 | AB4: 0 | AC4: 0 | AD4: 0 | AE4: 0 | AF4: 0 | AG4: 0
A5: Commercial Buildings Sector | B5: 0 | C5: 0 | D5: 0 | E5: 0 | F5: 0 | G5: 0 | H5: 0 | I5: 0 | J5: 0 | K5: 0 | L5: 0 | M5: 0 | N5: 0 | O5: 0 | P5: 0 | Q5: 0 | R5: 0 | S5: 0 | T5: 0 | U5: 0 | V5: 0 | W5: 0 | X5: 0 | Y5: 0 | Z5: 0 | AA5: 0 | AB5: 0 | AC5: 0 | AD5: 0 | AE5: 0 | AF5: 0 | AG5: 0
A6: Industry Sector | B6: 0 | C6: 0 | D6: 0 | E6: 0 | F6: 0 | G6: 0 | H6: 0 | I6: 0 | J6: 0 | K6: 0 | L6: 0 | M6: 0 | N6: 0 | O6: 0 | P6: 0 | Q6: 0 | R6: 0 | S6: 0 | T6: 0 | U6: 0 | V6: 0 | W6: 0 | X6: 0 | Y6: 0 | Z6: 0 | AA6: 0 | AB6: 0 | AC6: 0 | AD6: 0 | AE6: 0 | AF6: 0 | AG6: 0
A7: District Heating Sector | B7: =B3 -> 0 | C7: =C3 -> 0 | D7: =D3 -> 0 | E7: =E3 -> 0 | F7: =F3 -> 0 | G7: =G3 -> 0 | H7: =H3 -> 0 | I7: =I3 -> 0 | ... AG7: =AG3 -> 0
A8: LULUCF Sector | B8: 0 | C8: 0 | D8: 0 | E8: 0 | F8: 0 | G8: 0 | H8: 0 | I8: 0 | J8: 0 | K8: 0 | L8: 0 | M8: 0 | N8: 0 | O8: 0 | P8: 0 | Q8: 0 | R8: 0 | S8: 0 | T8: 0 | U8: 0 | V8: 0 | W8: 0 | X8: 0 | Y8: 0 | Z8: 0 | AA8: 0 | AB8: 0 | AC8: 0 | AD8: 0 | AE8: 0 | AF8: 0 | AG8: 0
A9: Geoengineering Sector | B9: =B6 -> 0 | C9: =C6 -> 0 | D9: =D6 -> 0 | E9: =E6 -> 0 | F9: =F6 -> 0 | G9: =G6 -> 0 | H9: =H6 -> 0 | I9: =I6 -> 0 | ... AG9: =AG6 -> 0

Sheet BFPaT-pretax-petgas
A1: Fuel Price ($/BTU) | B1: 2019 | C1: 2020 | D1: 2021 | E1: 2022 | F1: 2023 | G1: 2024 | H1: 2025 | I1: 2026 | J1: 2027 | K1: 2028 | L1: 2029 | M1: 2030 | N1: 2031 | O1: 2032 | P1: 2033 | Q1: 2034 | R1: 2035 | S1: 2036 | T1: 2037 | U1: 2038 | V1: 2039 | W1: 2040 | X1: 2041 | Y1: 2042 | Z1: 2043 | AA1: 2044 | AB1: 2045 | AC1: 2046 | AD1: 2047 | AE1: 2048 | AF1: 2049 | AG1: 2050
A2: Transportation Sector | B2: =('Fuel Prices - ID'!L9/'Fuel Prices - ID'!$L$20)*(1-'Tax Percentages'!B13) -> 1.2415934e-05 | C2: =('Fuel Prices - ID'!M9/'Fuel Prices - ID'!$L$20)*(1-'Tax Percentages'!C13) -> 1.2260735e-05 | D2: =('Fuel Prices - ID'!N9/'Fuel Prices - ID'!$L$20)*(1-'Tax Percentages'!D13) -> 1.0731317e-05 | E2: =('Fuel Prices - ID'!O9/'Fuel Prices - ID'!$L$20)*(1-'Tax Percentages'!E13) -> 1.056342e-05 | F2: =('Fuel Prices - ID'!P9/'Fuel Prices - ID'!$L$20)*(1-'Tax Percentages'!F13) -> 1.0395523e-05 | G2: =('Fuel Prices - ID'!Q9/'Fuel Prices - ID'!$L$20)*(1-'Tax Percentages'!G13) -> 1.0227625e-05 | H2: =('Fuel Prices - ID'!R9/'Fuel Prices - ID'!$L$20)*(1-'Tax Percentages'!H13) -> 1.0059728e-05 | I2: =('Fuel Prices - ID'!S9/'Fuel Prices - ID'!$L$20)*(1-'Tax Percentages'!I13) -> 9.8918309e-06 | ... AG2: =('Fuel Prices - ID'!AQ9/'Fuel Prices - ID'!$L$20)*(1-'Tax Percentages'!AG13) -> 5.862296e-06
A3: Electricity Sector | B3: 0 | C3: 0 | D3: 0 | E3: 0 | F3: 0 | G3: 0 | H3: 0 | I3: 0 | J3: 0 | K3: 0 | L3: 0 | M3: 0 | N3: 0 | O3: 0 | P3: 0 | Q3: 0 | R3: 0 | S3: 0 | T3: 0 | U3: 0 | V3: 0 | W3: 0 | X3: 0 | Y3: 0 | Z3: 0 | AA3: 0 | AB3: 0 | AC3: 0 | AD3: 0 | AE3: 0 | AF3: 0 | AG3: 0
A4: Residential Buildings Sector | B4: 0 | C4: 0 | D4: 0 | E4: 0 | F4: 0 | G4: 0 | H4: 0 | I4: 0 | J4: 0 | K4: 0 | L4: 0 | M4: 0 | N4: 0 | O4: 0 | P4: 0 | Q4: 0 | R4: 0 | S4: 0 | T4: 0 | U4: 0 | V4: 0 | W4: 0 | X4: 0 | Y4: 0 | Z4: 0 | AA4: 0 | AB4: 0 | AC4: 0 | AD4: 0 | AE4: 0 | AF4: 0 | AG4: 0
A5: Commercial Buildings Sector | B5: 0 | C5: 0 | D5: 0 | E5: 0 | F5: 0 | G5: 0 | H5: 0 | I5: 0 | J5: 0 | K5: 0 | L5: 0 | M5: 0 | N5: 0 | O5: 0 | P5: 0 | Q5: 0 | R5: 0 | S5: 0 | T5: 0 | U5: 0 | V5: 0 | W5: 0 | X5: 0 | Y5: 0 | Z5: 0 | AA5: 0 | AB5: 0 | AC5: 0 | AD5: 0 | AE5: 0 | AF5: 0 | AG5: 0
A6: Industry Sector | B6: 0 | C6: 0 | D6: 0 | E6: 0 | F6: 0 | G6: 0 | H6: 0 | I6: 0 | J6: 0 | K6: 0 | L6: 0 | M6: 0 | N6: 0 | O6: 0 | P6: 0 | Q6: 0 | R6: 0 | S6: 0 | T6: 0 | U6: 0 | V6: 0 | W6: 0 | X6: 0 | Y6: 0 | Z6: 0 | AA6: 0 | AB6: 0 | AC6: 0 | AD6: 0 | AE6: 0 | AF6: 0 | AG6: 0
A7: District Heating Sector | B7: =B3 -> 0 | C7: =C3 -> 0 | D7: =D3 -> 0 | E7: =E3 -> 0 | F7: =F3 -> 0 | G7: =G3 -> 0 | H7: =H3 -> 0 | I7: =I3 -> 0 | ... Y7: =Y3 -> 0 | Z7: 0 | AA7: 0 | AB7: 0 | AC7: 0 | AD7: 0 | AE7: 0 | AF7: 0 | AG7: 0
A8: LULUCF Sector | B8: 0 | C8: 0 | D8: 0 | E8: 0 | F8: 0 | G8: 0 | H8: 0 | I8: 0 | J8: 0 | K8: 0 | L8: 0 | M8: 0 | N8: 0 | O8: 0 | P8: 0 | Q8: 0 | R8: 0 | S8: 0 | T8: 0 | U8: 0 | V8: 0 | W8: 0 | X8: 0 | Y8: 0 | Z8: 0 | AA8: 0 | AB8: 0 | AC8: 0 | AD8: 0 | AE8: 0 | AF8: 0 | AG8: 0
A9: Geoengineering Sector | B9: =B6 -> 0 | C9: =C6 -> 0 | D9: =D6 -> 0 | E9: =E6 -> 0 | F9: =F6 -> 0 | G9: =G6 -> 0 | H9: =H6 -> 0 | I9: =I6 -> 0 | ... Y9: =Y6 -> 0 | Z9: 0 | AA9: 0 | AB9: 0 | AC9: 0 | AD9: 0 | AE9: 0 | AF9: 0 | AG9: 0

Sheet BFPaT-pretax-petdies
A1: Fuel Price ($/BTU) | B1: 2019 | C1: 2020 | D1: 2021 | E1: 2022 | F1: 2023 | G1: 2024 | H1: 2025 | I1: 2026 | J1: 2027 | K1: 2028 | L1: 2029 | M1: 2030 | N1: 2031 | O1: 2032 | P1: 2033 | Q1: 2034 | R1: 2035 | S1: 2036 | T1: 2037 | U1: 2038 | V1: 2039 | W1: 2040 | X1: 2041 | Y1: 2042 | Z1: 2043 | AA1: 2044 | AB1: 2045 | AC1: 2046 | AD1: 2047 | AE1: 2048 | AF1: 2049 | AG1: 2050
A2: Transportation Sector | B2: =('Fuel Prices - ID'!L$10/'Fuel Prices - ID'!$L$20)*(1-'Tax Percentages'!B$14) -> 8.8463528e-06 | C2: =('Fuel Prices - ID'!M$10/'Fuel Prices - ID'!$L$20)*(1-'Tax Percentages'!C$14) -> 8.6911536e-06 | D2: =('Fuel Prices - ID'!N$10/'Fuel Prices - ID'!$L$20)*(1-'Tax Percentages'!D$14) -> 1.0243145e-05 | E2: =('Fuel Prices - ID'!O$10/'Fuel Prices - ID'!$L$20)*(1-'Tax Percentages'!E$14) -> 1.0087946e-05 | F2: =('Fuel Prices - ID'!P$10/'Fuel Prices - ID'!$L$20)*(1-'Tax Percentages'!F$14) -> 9.932747e-06 | G2: =('Fuel Prices - ID'!Q$10/'Fuel Prices - ID'!$L$20)*(1-'Tax Percentages'!G$14) -> 9.8198749e-06 | H2: =('Fuel Prices - ID'!R$10/'Fuel Prices - ID'!$L$20)*(1-'Tax Percentages'!H$14) -> 9.8096138e-06 | I2: =('Fuel Prices - ID'!S$10/'Fuel Prices - ID'!$L$20)*(1-'Tax Percentages'!I$14) -> 9.6996568e-06 | ... AG2: =('Fuel Prices - ID'!AQ$10/'Fuel Prices - ID'!$L$20)*(1-'Tax Percentages'!AG$14) -> 9.6648271e-06
A3: Electricity Sector | B3: =('Fuel Prices - ID'!L$10/'Fuel Prices - ID'!$L$20)*(1-'Tax Percentages'!B$14) -> 8.8463528e-06 | C3: =('Fuel Prices - ID'!M$10/'Fuel Prices - ID'!$L$20)*(1-'Tax Percentages'!C$14) -> 8.6911536e-06 | D3: =('Fuel Prices - ID'!N$10/'Fuel Prices - ID'!$L$20)*(1-'Tax Percentages'!D$14) -> 1.0243145e-05 | E3: =('Fuel Prices - ID'!O$10/'Fuel Prices - ID'!$L$20)*(1-'Tax Percentages'!E$14) -> 1.0087946e-05 | F3: =('Fuel Prices - ID'!P$10/'Fuel Prices - ID'!$L$20)*(1-'Tax Percentages'!F$14) -> 9.932747e-06 | G3: =('Fuel Prices - ID'!Q$10/'Fuel Prices - ID'!$L$20)*(1-'Tax Percentages'!G$14) -> 9.8198749e-06 | H3: =('Fuel Prices - ID'!R$10/'Fuel Prices - ID'!$L$20)*(1-'Tax Percentages'!H$14) -> 9.8096138e-06 | I3: =('Fuel Prices - ID'!S$10/'Fuel Prices - ID'!$L$20)*(1-'Tax Percentages'!I$14) -> 9.6996568e-06 | ... AG3: =('Fuel Prices - ID'!AQ$10/'Fuel Prices - ID'!$L$20)*(1-'Tax Percentages'!AG$14) -> 9.6648271e-06
A4: Residential Buildings Sector | B4: =('Fuel Prices - ID'!L$10/'Fuel Prices - ID'!$L$20)*(1-'Tax Percentages'!B$14) -> 8.8463528e-06 | C4: =('Fuel Prices - ID'!M$10/'Fuel Prices - ID'!$L$20)*(1-'Tax Percentages'!C$14) -> 8.6911536e-06 | D4: =('Fuel Prices - ID'!N$10/'Fuel Prices - ID'!$L$20)*(1-'Tax Percentages'!D$14) -> 1.0243145e-05 | E4: =('Fuel Prices - ID'!O$10/'Fuel Prices - ID'!$L$20)*(1-'Tax Percentages'!E$14) -> 1.0087946e-05 | F4: =('Fuel Prices - ID'!P$10/'Fuel Prices - ID'!$L$20)*(1-'Tax Percentages'!F$14) -> 9.932747e-06 | G4: =('Fuel Prices - ID'!Q$10/'Fuel Prices - ID'!$L$20)*(1-'Tax Percentages'!G$14) -> 9.8198749e-06 | H4: =('Fuel Prices - ID'!R$10/'Fuel Prices - ID'!$L$20)*(1-'Tax Percentages'!H$14) -> 9.8096138e-06 | I4: =('Fuel Prices - ID'!S$10/'Fuel Prices - ID'!$L$20)*(1-'Tax Percentages'!I$14) -> 9.6996568e-06 | ... AG4: =('Fuel Prices - ID'!AQ$10/'Fuel Prices - ID'!$L$20)*(1-'Tax Percentages'!AG$14) -> 9.6648271e-06
A5: Commercial Buildings Sector | B5: =('Fuel Prices - ID'!L$10/'Fuel Prices - ID'!$L$20)*(1-'Tax Percentages'!B$14) -> 8.8463528e-06 | C5: =('Fuel Prices - ID'!M$10/'Fuel Prices - ID'!$L$20)*(1-'Tax Percentages'!C$14) -> 8.6911536e-06 | D5: =('Fuel Prices - ID'!N$10/'Fuel Prices - ID'!$L$20)*(1-'Tax Percentages'!D$14) -> 1.0243145e-05 | E5: =('Fuel Prices - ID'!O$10/'Fuel Prices - ID'!$L$20)*(1-'Tax Percentages'!E$14) -> 1.0087946e-05 | F5: =('Fuel Prices - ID'!P$10/'Fuel Prices - ID'!$L$20)*(1-'Tax Percentages'!F$14) -> 9.932747e-06 | G5: =('Fuel Prices - ID'!Q$10/'Fuel Prices - ID'!$L$20)*(1-'Tax Percentages'!G$14) -> 9.8198749e-06 | H5: =('Fuel Prices - ID'!R$10/'Fuel Prices - ID'!$L$20)*(1-'Tax Percentages'!H$14) -> 9.8096138e-06 | I5: =('Fuel Prices - ID'!S$10/'Fuel Prices - ID'!$L$20)*(1-'Tax Percentages'!I$14) -> 9.6996568e-06 | ... AG5: =('Fuel Prices - ID'!AQ$10/'Fuel Prices - ID'!$L$20)*(1-'Tax Percentages'!AG$14) -> 9.6648271e-06
A6: Industry Sector | B6: =('Fuel Prices - ID'!L$10/'Fuel Prices - ID'!$L$20)*(1-'Tax Percentages'!B$14) -> 8.8463528e-06 | C6: =('Fuel Prices - ID'!M$10/'Fuel Prices - ID'!$L$20)*(1-'Tax Percentages'!C$14) -> 8.6911536e-06 | D6: =('Fuel Prices - ID'!N$10/'Fuel Prices - ID'!$L$20)*(1-'Tax Percentages'!D$14) -> 1.0243145e-05 | E6: =('Fuel Prices - ID'!O$10/'Fuel Prices - ID'!$L$20)*(1-'Tax Percentages'!E$14) -> 1.0087946e-05 | F6: =('Fuel Prices - ID'!P$10/'Fuel Prices - ID'!$L$20)*(1-'Tax Percentages'!F$14) -> 9.932747e-06 | G6: =('Fuel Prices - ID'!Q$10/'Fuel Prices - ID'!$L$20)*(1-'Tax Percentages'!G$14) -> 9.8198749e-06 | H6: =('Fuel Prices - ID'!R$10/'Fuel Prices - ID'!$L$20)*(1-'Tax Percentages'!H$14) -> 9.8096138e-06 | I6: =('Fuel Prices - ID'!S$10/'Fuel Prices - ID'!$L$20)*(1-'Tax Percentages'!I$14) -> 9.6996568e-06 | ... AG6: =('Fuel Prices - ID'!AQ$10/'Fuel Prices - ID'!$L$20)*(1-'Tax Percentages'!AG$14) -> 9.6648271e-06
A7: District Heating Sector | B7: =B3 -> 8.8463528e-06 | C7: =C3 -> 8.6911536e-06 | D7: =D3 -> 1.0243145e-05 | E7: =E3 -> 1.0087946e-05 | F7: =F3 -> 9.932747e-06 | G7: =G3 -> 9.8198749e-06 | H7: =H3 -> 9.8096138e-06 | I7: =I3 -> 9.6996568e-06 | ... AG7: =AG3 -> 9.6648271e-06
A8: LULUCF Sector | B8: 0 | C8: 0 | D8: 0 | E8: 0 | F8: 0 | G8: 0 | H8: 0 | I8: 0 | J8: 0 | K8: 0 | L8: 0 | M8: 0 | N8: 0 | O8: 0 | P8: 0 | Q8: 0 | R8: 0 | S8: 0 | T8: 0 | U8: 0 | V8: 0 | W8: 0 | X8: 0 | Y8: 0 | Z8: 0 | AA8: 0 | AB8: 0 | AC8: 0 | AD8: 0 | AE8: 0 | AF8: 0 | AG8: 0
