Workbook

Sheet About 
A1: BCEU BAU Components Energy Use
A3: Source | B3: IESR (2024)
B4: https://iesr.or.id/en/
A10: Comments | B10: These data come from the LEAP (Long-range Energy Alternatives Planning) Indonesia model and represent BAU (Business As Usual) scenarios projected for the country. The BAU scenarios assume no significant changes to current energy policies or interventions, providing a baseline for analyzing future energy consumption, emissions, and sectoral growth under existing conditions. This model helps evaluate long-term trends in Indonesia's energy use and environmental impacts, serving as a foundation for comparing potential outcomes from alternative policy scenarios aimed at sustainable development and climate goals.

Sheet Commercial
A1: Variable: Non Electricity Consumption: Total Final Energy Consumption (Thousand Gigajoule)
A2: Scenario: Business as Usual
A3: Branch: Demand\Commercial\Office\Conventional Office\Non Electricity Consumption\Gasoil Generator
A4: Region: Indonesia
A5: Thousand Gigajoule to Gigajoule | B5: 1000
A6: Branch | B6: 2022 | C6: 2023 | D6: 2024 | E6: 2025 | F6: 2026 | G6: 2027 | H6: 2028 | I6: 2029 | J6: 2030 | K6: 2031 | L6: 2032 | M6: 2033 | N6: 2034 | O6: 2035 | P6: 2036 | Q6: 2037 | R6: 2038 | S6: 2039 | T6: 2040 | U6: 2041 | V6: 2042 | W6: 2043 | X6: 2044 | Y6: 2045 | Z6: 2046 | AA6: 2047 | AB6: 2048 | AC6: 2049 | AD6: 2050 | AE6: 2051 | AF6: 2052 | AG6: 2053 | AH6: 2054 | AI6: 2055 | AJ6: 2056 | AK6: 2057 | AL6: 2058 | AM6: 2059 | AN6: 2060 | AO6: =AN6+1 -> 2061 | AP6: =AO6+1 -> 2062 | AQ6: =AP6+1 -> 2063 | AR6: =AQ6+1 -> 2064 | AS6: =AR6+1 -> 2065 | AT6: =AS6+1 -> 2066 | AU6: =AT6+1 -> 2067 | AV6: =AU6+1 -> 2068 | ... AX6: =AW6+1 -> 2070
A7: Gasoil Generator | B7: 328.18775 | C7: 344.62501 | D7: 347.9738 | E7: 351.33736 | F7: 356.71991 | G7: 362.14197 | H7: 367.60354 | I7: 373.10462 | J7: 378.64521 | K7: 383.69711 | L7: 388.7822 | M7: 393.90048 | N7: 399.05194 | O7: 404.23658 | P7: 408.90412 | Q7: 413.59844 | R7: 418.31956 | S7: 423.06746 | T7: 427.84214 | U7: 432.08976 | V7: 436.35792 | W7: 440.6466 | X7: 444.95581 | Y7: 449.28555 | Z7: 453.08941 | AA7: 456.9078 | AB7: 460.74072 | AC7: 464.58816 | AD7: 468.45012 | AE7: 470.96822 | AF7: 473.48631 | AG7: 476.0044 | AH7: 478.52249 | AI7: 481.04059 | AJ7: 483.55868 | AK7: 486.07677 | AL7: 488.59486 | AM7: 491.11296 | AN7: 493.63105 | AO7: =(AN7+AN7*$AN$10) -> 496.16205 | AP7: =(AO7+AO7*$AN$10) -> 498.70603 | AQ7: =(AP7+AP7*$AN$10) -> 501.26306 | AR7: =(AQ7+AQ7*$AN$10) -> 503.83319 | AS7: =(AR7+AR7*$AN$10) -> 506.41651 | AT7: =(AS7+AS7*$AN$10) -> 509.01307 | AU7: =(AT7+AT7*$AN$10) -> 511.62294 | AV7: =(AU7+AU7*$AN$10) -> 514.24619 | ... AX7: =(AW7+AW7*$AN$10) -> 519.53312
A8: Biogasoil Generator | B8: 3364.4751 | C8: 3532.9846 | D8: 3567.3153 | E8: 3601.7974 | F8: 3656.9776 | G8: 3712.5629 | H8: 3768.5531 | I8: 3824.9484 | J8: 3881.7487 | K8: 3933.5392 | L8: 3985.6699 | M8: 4038.1408 | N8: 4090.9519 | O8: 4144.1032 | P8: 4191.9533 | Q8: 4240.078 | R8: 4288.4773 | S8: 4337.1513 | T8: 4386.0998 | U8: 4429.6451 | V8: 4473.4008 | W8: 4517.367 | X8: 4561.5436 | Y8: 4605.9307 | Z8: 4644.9267 | AA8: 4684.0716 | AB8: 4723.3654 | AC8: 4762.8081 | AD8: 4802.3997 | AE8: 4828.2144 | AF8: 4854.0291 | AG8: 4879.8438 | AH8: 4905.6584 | AI8: 4931.4731 | AJ8: 4957.2878 | AK8: 4983.1025 | AL8: 5008.9171 | AM8: 5034.7318 | AN8: 5060.5465 | AO8: =(AN8+AN8*$AN$11) -> 5086.4935 | AP8: =(AO8+AO8*$AN$11) -> 5112.5736 | AQ8: =(AP8+AP8*$AN$11) -> 5138.7874 | AR8: =(AQ8+AQ8*$AN$11) -> 5165.1356 | AS8: =(AR8+AR8*$AN$11) -> 5191.6189 | AT8: =(AS8+AS8*$AN$11) -> 5218.238 | AU8: =(AT8+AT8*$AN$11) -> 5244.9936 | AV8: =(AU8+AU8*$AN$11) -> 5271.8863 | ... AX8: =(AW8+AW8*$AN$11) -> 5326.0862
A9: MDF Generator | B9: 2.9221903 | C9: 3.068548 | D9: 3.0983657 | E9: 3.1283148 | F9: 3.1762412 | G9: 3.2245193 | H9: 3.2731493 | I9: 3.322131 | J9: 3.3714644 | K9: 3.4164467 | L9: 3.4617245 | M9: 3.5072977 | N9: 3.5531664 | O9: 3.5993305 | P9: 3.6408904 | Q9: 3.6826888 | R9: 3.7247257 | S9: 3.767001 | T9: 3.8095149 | U9: 3.8473359 | V9: 3.8853396 | W9: 3.9235261 | X9: 3.9618954 | Y9: 4.0004475 | Z9: 4.0343171 | AA9: 4.0683162 | AB9: 4.1024445 | AC9: 4.1367022 | AD9: 4.1710892 | AE9: 4.1935104 | AF9: 4.2159315 | AG9: 4.2383527 | AH9: 4.2607738 | AI9: 4.283195 | AJ9: 4.3056161 | AK9: 4.3280372 | AL9: 4.3504584 | AM9: 4.3728795 | AN9: 4.3953007 | AO9: =(AN9+AN9*$AN$12) -> 4.4178368 | AP9: =(AO9+AO9*$AN$12) -> 4.4404885 | AQ9: =(AP9+AP9*$AN$12) -> 4.4632563 | AR9: =(AQ9+AQ9*$AN$12) -> 4.4861408 | AS9: =(AR9+AR9*$AN$12) -> 4.5091427 | AT9: =(AS9+AS9*$AN$12) -> 4.5322625 | AU9: =(AT9+AT9*$AN$12) -> 4.5555008 | AV9: =(AU9+AU9*$AN$12) -> 4.5788583 | ... AX9: =(AW9+AW9*$AN$12) -> 4.6259332
AM10: Growth rate | AN10: =(AN7-AM7)/AM7 -> 0.0051273188
A11: Variable: Non Electricity Consumption: Total Final Energy Consumption (Thousand Gigajoule) | AM11: Growth rate | AN11: =(AN8-AM8)/AM8 -> 0.0051273188
A12: Scenario: Business as Usual | AM12: Growth rate | AN12: =(AN9-AM9)/AM9 -> 0.0051273188
A13: Branch: Demand\Commercial\Hotel\Five Star\Non Electricity Consumption\Biomass Heat
A14: Region: Indonesia
A16: Branch | B16: 2022 | C16: 2023 | D16: 2024 | E16: 2025 | F16: 2026 | G16: 2027 | H16: 2028 | I16: 2029 | J16: 2030 | K16: 2031 | L16: 2032 | M16: 2033 | N16: 2034 | O16: 2035 | P16: 2036 | Q16: 2037 | R16: 2038 | S16: 2039 | T16: 2040 | U16: 2041 | V16: 2042 | W16: 2043 | X16: 2044 | Y16: 2045 | Z16: 2046 | AA16: 2047 | AB16: 2048 | AC16: 2049 | AD16: 2050 | AE16: 2051 | AF16: 2052 | AG16: 2053 | AH16: 2054 | AI16: 2055 | AJ16: 2056 | AK16: 2057 | AL16: 2058 | AM16: 2059 | AN16: 2060 | AO16: =AN16+1 -> 2061 | AP16: =AO16+1 -> 2062 | AQ16: =AP16+1 -> 2063 | AR16: =AQ16+1 -> 2064 | AS16: =AR16+1 -> 2065 | AT16: =AS16+1 -> 2066 | AU16: =AT16+1 -> 2067 | AV16: =AU16+1 -> 2068 | ... AX16: =AW16+1 -> 2070
A17: Biomass Heat | B17: 660.23083 | C17: 703.32055 | D17: 749.2225 | E17: 798.12023 | F17: 850.20925 | G17: 905.69784 | H17: 964.80787 | I17: 1027.7757 | J17: 1094.8531 | K17: 1166.3083 | L17: 1242.4269 | M17: 1323.5135 | N17: 1409.8921 | O17: 1501.9082 | P17: 1599.9297 | Q17: 1704.3485 | R17: 1815.5821 | S17: 1934.0754 | T17: 2060.3021 | U17: 2194.767 | V17: 2338.0076 | W17: 2490.5968 | X17: 2653.1447 | Y17: 2826.3012 | Z17: 3010.7587 | AA17: 3207.2547 | AB17: 3416.575 | AC17: 3639.5565 | AD17: 3877.0908 | AE17: 4130.1277 | AF17: 4399.6789 | AG17: 4686.8223 | AH17: 4992.7061 | AI17: 5318.5532 | AJ17: 5665.6665 | AK17: 6035.4342 | AL17: 6429.3345 | AM17: 6848.9426 | AN17: 7295.9363 | AO17: =(AN17+AN17*$AN$25) -> 7772.1029 | AP17: =(AO17+AO17*$AN$25) -> 8279.3463 | AQ17: =(AP17+AP17*$AN$25) -> 8819.6947 | AR17: =(AQ17+AQ17*$AN$25) -> 9395.3088 | AS17: =(AR17+AR17*$AN$25) -> 10008.49 | AT17: =(AS17+AS17*$AN$25) -> 10661.691 | AU17: =(AT17+AT17*$AN$25) -> 11357.522 | AV17: =(AU17+AU17*$AN$25) -> 12098.766 | ... AX17: =(AW17+AW17*$AN$25) -> 13729.543
A18: Solar Heat | B18: 403.3108 | C18: 429.63273 | D18: 457.67255 | E18: 487.54238 | F18: 519.36165 | G18: 553.2576 | H18: 589.36575 | I18: 627.83049 | J18: 668.80561 | K18: 712.45496 | L18: 758.95306 | M18: 808.48585 | N18: 861.25138 | O18: 917.46063 | P18: 977.33836 | Q18: 1041.124 | R18: 1109.0725 | S18: 1181.4558 | T18: 1258.563 | U18: 1340.7027 | V18: 1428.2031 | W18: 1521.4143 | X18: 1620.7088 | Y18: 1726.4838 | Z18: 1839.1621 | AA18: 1959.1943 | AB18: 2087.0604 | AC18: 2223.2716 | AD18: 2368.3726 | AE18: 2522.9436 | AF18: 2687.6025 | AG18: 2863.0079 | AH18: 3049.8611 | AI18: 3248.9091 | AJ18: 3460.9479 | AK18: 3686.8254 | AL18: 3927.4447 | AM18: 4183.7679 | AN18: 4456.82 | AO18: =(AN18+AN18*$AN$25) -> 4747.6927 | AP18: =(AO18+AO18*$AN$25) -> 5057.549 | AQ18: =(AP18+AP18*$AN$25) -> 5387.6281 | AR18: =(AQ18+AQ18*$AN$25) -> 5739.2496 | AS18: =(AR18+AR18*$AN$25) -> 6113.8196 | AT18: =(AS18+AS18*$AN$25) -> 6512.8358 | AU18: =(AT18+AT18*$AN$25) -> 6937.8936 | AV18: =(AU18+AU18*$AN$25) -> 7390.6926 | ... AX18: =(AW18+AW18*$AN$25) -> 8386.8746
A19: Gas Heat | B19: 313.17283 | C19: 333.61193 | D19: 355.38499 | E19: 378.57906 | F19: 403.28688 | G19: 429.60725 | H19: 457.64541 | I19: 487.51346 | J19: 519.33085 | K19: 553.22478 | L19: 589.33079 | M19: 627.79325 | N19: 668.76594 | O19: 712.4127 | P19: 758.90805 | Q19: 808.4379 | R19: 861.2003 | S19: 917.40621 | T19: 977.28039 | U19: 1041.0622 | V19: 1109.0068 | W19: 1181.3857 | X19: 1258.4884 | Y19: 1340.6231 | Z19: 1428.1184 | AA19: 1521.324 | AB19: 1620.6127 | AC19: 1726.3814 | AD19: 1839.053 | AE19: 1959.0781 | AF19: 2086.9366 | AG19: 2223.1397 | AH19: 2368.2321 | AI19: 2522.7939 | AJ19: 2687.4431 | AK19: 2862.8381 | AL19: 3049.6802 | AM19: 3248.7164 | AN19: 3460.7427 | AO19: =(AN19+AN19*$AN$25) -> 3686.6067 | AP19: =(AO19+AO19*$AN$25) -> 3927.2117 | AQ19: =(AP19+AP19*$AN$25) -> 4183.5198 | AR19: =(AQ19+AQ19*$AN$25) -> 4456.5556 | AS19: =(AR19+AR19*$AN$25) -> 4747.411 | AT19: =(AS19+AS19*$AN$25) -> 5057.2491 | AU19: =(AT19+AT19*$AN$25) -> 5387.3085 | AV19: =(AU19+AU19*$AN$25) -> 5738.9092 | ... AX19: =(AW19+AW19*$AN$25) -> 6512.4495
A20: Kerosene Heat | B20: 21.96271 | C20: 23.396098 | D20: 24.923036 | E20: 26.549628 | F20: 28.28238 | G20: 30.128219 | H20: 32.094526 | I20: 34.189163 | J20: 36.420506 | K20: 38.797477 | L20: 41.329579 | M20: 44.026939 | N20: 46.900341 | O20: 49.961274 | P20: 53.221978 | Q20: 56.69549 | R20: 60.395701 | S20: 64.337403 | T20: 68.53636 | U20: 73.00936 | V20: 77.774289 | W20: 82.850199 | X20: 88.257386 | Y20: 94.017471 | Z20: 100.15349 | AA20: 106.68997 | AB20: 113.65305 | AC20: 121.07057 | AD20: 128.9722 | AE20: 137.38952 | AF20: 146.35619 | AG20: 155.90808 | AH20: 166.08336 | AI20: 176.92273 | AJ20: 188.46952 | AK20: 200.76992 | AL20: 213.87309 | AM20: 227.83144 | AN20: 242.70077 | AO20: =(AN20+AN20*$AN$25) -> 258.54055 | AP20: =(AO20+AO20*$AN$25) -> 275.4141 | AQ20: =(AP20+AP20*$AN$25) -> 293.3889 | AR20: =(AQ20+AQ20*$AN$25) -> 312.53682 | AS20: =(AR20+AR20*$AN$25) -> 332.93441 | AT20: =(AS20+AS20*$AN$25) -> 354.66325 | AU20: =(AT20+AT20*$AN$25) -> 377.81022 | AV20: =(AU20+AU20*$AN$25) -> 402.46786 | ... AX20: =(AW20+AW20*$AN$25) -> 456.71599
A21: Gasoil Generator | B21: 16.796903 | C21: 17.893147 | D21: 19.060936 | E21: 20.304941 | F21: 21.630136 | G21: 23.041818 | H21: 24.545634 | I21: 26.147596 | J21: 27.854109 | K21: 29.671997 | L21: 31.608529 | M21: 33.671448 | N21: 35.869002 | O21: 38.209979 | P21: 40.703739 | Q21: 43.360253 | R21: 46.190144 | S21: 49.204727 | T21: 52.416055 | U21: 55.836969 | V21: 59.481148 | W21: 63.363163 | X21: 67.498536 | Y21: 71.903803 | Z21: 76.596578 | AA21: 81.595625 | AB21: 86.920933 | AC21: 92.593795 | AD21: 98.636895 | AE21: 105.0744 | AF21: 111.93204 | AG21: 119.23724 | AH21: 127.01921 | AI21: 135.30907 | AJ21: 144.13997 | AK21: 153.54721 | AL21: 163.56841 | AM21: 174.24364 | AN21: 185.61559 | AO21: =(AN21+AN21*$AN$25) -> 197.72972 | AP21: =(AO21+AO21*$AN$25) -> 210.63448 | AQ21: =(AP21+AP21*$AN$25) -> 224.38146 | AR21: =(AQ21+AQ21*$AN$25) -> 239.02563 | AS21: =(AR21+AR21*$AN$25) -> 254.62555 | AT21: =(AS21+AS21*$AN$25) -> 271.24359 | AU21: =(AT21+AT21*$AN$25) -> 288.94621 | AV21: =(AU21+AU21*$AN$25) -> 307.80417 | ... AX21: =(AW21+AW21*$AN$25) -> 349.2927
A22: Biogasoil Generator | B22: 172.19644 | C22: 183.43478 | D22: 195.40658 | E22: 208.15972 | F22: 221.74518 | G22: 236.2173 | H22: 251.63393 | I22: 268.05673 | J22: 285.55135 | K22: 304.18775 | L22: 324.04045 | M22: 345.18883 | N22: 367.71745 | O22: 391.7164 | P22: 417.28162 | Q22: 444.51535 | R22: 473.52648 | S22: 504.43101 | T22: 537.35251 | U22: 572.42262 | V22: 609.78157 | W22: 649.57874 | X22: 691.97325 | Y22: 737.13462 | Z22: 785.24344 | AA22: 836.49206 | AB22: 891.0854 | AC22: 949.24176 | AD22: 1011.1937 | AE22: 1077.1888 | AF22: 1147.4912 | AG22: 1222.3818 | AH22: 1302.16 | AI22: 1387.145 | AJ22: 1477.6765 | AK22: 1574.1166 | AL22: 1676.8507 | AM22: 1786.2897 | AN22: 1902.8712 | AO22: =(AN22+AN22*$AN$25) -> 2027.0614 | AP22: =(AO22+AO22*$AN$25) -> 2159.3568 | AQ22: =(AP22+AP22*$AN$25) -> 2300.2865 | AR22: =(AQ22+AQ22*$AN$25) -> 2450.4138 | AS22: =(AR22+AR22*$AN$25) -> 2610.3391 | AT22: =(AS22+AS22*$AN$25) -> 2780.7019 | AU22: =(AT22+AT22*$AN$25) -> 2962.1834 | AV22: =(AU22+AU22*$AN$25) -> 3155.5092 | ... AX22: =(AW22+AW22*$AN$25) -> 3580.8363
A23: MDF Generator | B23: 0.14955996 | C23: 0.15932094 | D23: 0.16971896 | E23: 0.1807956 | F23: 0.19259516 | G23: 0.20516481 | H23: 0.21855481 | I23: 0.23281871 | J23: 0.24801354 | K23: 0.26420005 | L23: 0.28144297 | M23: 0.29981124 | N23: 0.31937831 | O23: 0.34022241 | P23: 0.3624269 | Q23: 0.38608056 | R23: 0.41127796 | S23: 0.43811987 | T23: 0.4667136 | U23: 0.49717348 | V23: 0.52962133 | W23: 0.56418687 | X23: 0.60100831 | Y23: 0.64023289 | Z23: 0.68201745 | AA23: 0.72652907 | AB23: 0.77394572 | AC23: 0.824457 | AD23: 0.87826488 | AE23: 0.9355845 | AF23: 0.99664508 | AG23: 1.0616907 | AH23: 1.1309816 | AI23: 1.2047947 | AJ23: 1.2834252 | AK23: 1.3671874 | AL23: 1.4564164 | AM23: 1.5514689 | AN23: 1.6527249 | AO23: =(AN23+AN23*$AN$25) -> 1.7605894 | AP23: =(AO23+AO23*$AN$25) -> 1.8754936 | AQ23: =(AP23+AP23*$AN$25) -> 1.997897 | AR23: =(AQ23+AQ23*$AN$25) -> 2.128289 | AS23: =(AR23+AR23*$AN$25) -> 2.267191 | AT23: =(AS23+AS23*$AN$25) -> 2.4151584 | AU23: =(AT23+AT23*$AN$25) -> 2.5727828 | AV23: =(AU23+AU23*$AN$25) -> 2.7406945 | ... AX23: =(AW23+AW23*$AN$25) -> 3.1101092
A24: LPG Heat | B24: 273.08574 | C24: 290.90858 | D24: 309.89462 | E24: 330.11978 | F24: 351.66492 | G24: 374.6162 | H24: 399.06539 | I24: 425.11024 | J24: 452.8549 | K24: 482.41031 | L24: 513.89464 | M24: 547.43378 | N24: 583.16184 | O24: 621.22168 | P24: 661.76549 | Q24: 704.95536 | R24: 750.96401 | S24: 799.9754 | T24: 852.18549 | U24: 907.80306 | V24: 967.05049 | W24: 1030.1647 | X24: 1097.398 | Y24: 1169.0193 | Z24: 1245.3149 | AA24: 1326.5899 | AB24: 1413.1693 | AC24: 1505.3992 | AD24: 1603.6486 | AE24: 1708.3101 | AF24: 1819.8023 | AG24: 1938.571 | AH24: 2065.0911 | AI24: 2199.8685 | AJ24: 2343.4421 | AK24: 2496.386 | AL24: 2659.3117 | AM24: 2832.8707 | AN24: 3017.757 | AO24: =(AN24+AN24*$AN$25) -> 3214.7097 | AP24: =(AO24+AO24*$AN$25) -> 3424.5166 | AQ24: =(AP24+AP24*$AN$25) -> 3648.0164 | AR24: =(AQ24+AQ24*$AN$25) -> 3886.1028 | AS24: =(AR24+AR24*$AN$25) -> 4139.7278 | AT24: =(AS24+AS24*$AN$25) -> 4409.9056 | AU24: =(AT24+AT24*$AN$25) -> 4697.7165 | AV24: =(AU24+AU24*$AN$25) -> 5004.3112 | ... AX24: =(AW24+AW24*$AN$25) -> 5678.8359
AM25: Growth rate | AN25: =(AN17-AM17)/AM17 -> 0.065264627
A26: Variable: Non Electricity Consumption: Total Final Energy Consumption (Million Gigajoule) | AM26: Growth rate | AN26: =(AN18-AM18)/AM18 -> 0.065264627
A27: Scenario: Business as Usual | AM27: Growth rate | AN27: =(AN19-AM19)/AM19 -> 0.065264627
AM28: Growth rate | AN28: =(AN20-AM20)/AM20 -> 0.065264627
AM29: Growth rate | AN29: =(AN21-AM21)/AM21 -> 0.065264627
AM30: Growth rate | AN30: =(AN22-AM22)/AM22 -> 0.065264627
AM31: Growth rate | AN31: =(AN23-AM23)/AM23 -> 0.065264627
AM32: Growth rate | AN32: =(AN24-AM24)/AM24 -> 0.065264627
A33: Branch: Demand\Commercial\Hotel\Four Star\Non Electricity Consumption\Biomass Heat
A34: Region: Indonesia
A35: Million Gigajoule to Gigajoule | B35: 1000000
A36: Branch | B36: 2022 | C36: 2023 | D36: 2024 | E36: 2025 | F36: 2026 | G36: 2027 | H36: 2028 | I36: 2029 | J36: 2030 | K36: 2031 | L36: 2032 | M36: 2033 | N36: 2034 | O36: 2035 | P36: 2036 | Q36: 2037 | R36: 2038 | S36: 2039 | T36: 2040 | U36: 2041 | V36: 2042 | W36: 2043 | X36: 2044 | Y36: 2045 | Z36: 2046 | AA36: 2047 | AB36: 2048 | AC36: 2049 | AD36: 2050 | AE36: 2051 | AF36: 2052 | AG36: 2053 | AH36: 2054 | AI36: 2055 | AJ36: 2056 | AK36: 2057 | AL36: 2058 | AM36: 2059 | AN36: 2060 | AO36: =AN36+1 -> 2061 | AP36: =AO36+1 -> 2062 | AQ36: =AP36+1 -> 2063 | AR36: =AQ36+1 -> 2064 | AS36: =AR36+1 -> 2065 | AT36: =AS36+1 -> 2066 | AU36: =AT36+1 -> 2067 | AV36: =AU36+1 -> 2068 | ... AX36: =AW36+1 -> 2070
A37: Biomass Heat | B37: 1.4471193 | C37: 1.5415649 | D37: 1.6421746 | E37: 1.7493505 | F37: 1.8635212 | G37: 1.9851433 | H37: 2.1147029 | I37: 2.2527182 | J37: 2.399741 | K37: 2.5563592 | L37: 2.723199 | M37: 2.9009276 | N37: 3.0902555 | O37: 3.2919399 | P37: 3.5067872 | Q37: 3.7356563 | R37: 3.9794625 | S37: 4.2391807 | T37: 4.5158492 | U37: 4.8105744 | V37: 5.1245348 | W37: 5.4589856 | X37: 5.8152643 | Y37: 6.1947953 | Z37: 6.5990963 | AA37: 7.0297839 | AB37: 7.4885801 | AC37: 7.9773195 | AD37: 8.4979563 | AE37: 9.0525722 | AF37: 9.643385 | AG37: 10.272757 | AH37: 10.943205 | AI37: 11.657409 | AJ37: 12.418225 | AK37: 13.228696 | AL37: 14.092062 | AM37: 15.011775 | AN37: 15.991513 | AO37: =(AN37+AN37*$AN$45) -> 17.035193 | AP37: =(AO37+AO37*$AN$45) -> 18.146989 | AQ37: =(AP37+AP37*$AN$45) -> 19.331345 | AR37: =(AQ37+AQ37*$AN$45) -> 20.592998 | AS37: =(AR37+AR37*$AN$45) -> 21.936992 | AT37: =(AS37+AS37*$AN$45) -> 23.368702 | AU37: =(AT37+AT37*$AN$45) -> 24.893852 | AV37: =(AU37+AU37*$AN$45) -> 26.51854 | ... AX37: =(AW37+AW37*$AN$45) -> 30.09294
A38: Solar Heat | B38: 0.88399209 | C38: 0.9416855 | D38: 1.0031443 | E38: 1.0686141 | F38: 1.1383568 | G38: 1.2126512 | H38: 1.2917944 | I38: 1.3761029 | J38: 1.4659138 | K38: 1.5615861 | L38: 1.6635024 | M38: 1.7720703 | N38: 1.8877238 | O38: 2.0109254 | P38: 2.1421677 | Q38: 2.2819755 | R38: 2.4309077 | S38: 2.58956 | T38: 2.7585667 | U38: 2.9386035 | V38: 3.1303904 | W38: 3.3346941 | X38: 3.5523317 | Y38: 3.7841733 | Z38: 4.031146 | AA38: 4.2942372 | AB38: 4.574499 | AC38: 4.873052 | AD38: 5.1910899 | AE38: 5.5298844 | AF38: 5.8907903 | AG38: 6.2752505 | AH38: 6.6848024 | AI38: 7.1210835 | AJ38: 7.5858384 | AK38: 8.0809253 | AL38: 8.6083239 | AM38: 9.1701429 | AN38: 9.7686289 | AO38: =(AN38+AN38*$AN$45) -> 10.406175 | AP38: =(AO38+AO38*$AN$45) -> 11.08533 | AQ38: =(AP38+AP38*$AN$45) -> 11.80881 | AR38: =(AQ38+AQ38*$AN$45) -> 12.579507 | AS38: =(AR38+AR38*$AN$45) -> 13.400504 | AT38: =(AS38+AS38*$AN$45) -> 14.275083 | AU38: =(AT38+AT38*$AN$45) -> 15.206741 | AV38: =(AU38+AU38*$AN$45) -> 16.199203 | ... AX38: =(AW38+AW38*$AN$45) -> 18.382673
A39: Gas Heat | B39: 0.68642421 | C39: 0.73122343 | D39: 0.77894645 | E39: 0.8297841 | F39: 0.88393965 | G39: 0.94162964 | H39: 1.0030848 | I39: 1.0685507 | J39: 1.1382893 | K39: 1.2125793 | L39: 1.2917178 | M39: 1.3760213 | N39: 1.4658268 | O39: 1.5614935 | P39: 1.6634038 | Q39: 1.7719652 | R39: 1.8876118 | S39: 2.0108061 | T39: 2.1420406 | U39: 2.2818401 | V39: 2.4307635 | W39: 2.5894064 | X39: 2.7584031 | Y39: 2.9384292 | Z39: 3.1302047 | AA39: 3.3344963 | AB39: 3.552121 | AC39: 3.7839489 | AD39: 4.0309069 | AE39: 4.2939825 | AF39: 4.5742277 | AG39: 4.8727629 | AH39: 5.190782 | AI39: 5.5295564 | AJ39: 5.8904409 | AK39: 6.2748783 | AL39: 6.6844059 | AM39: 7.1206611 | AN39: 7.5853884 | AO39: =(AN39+AN39*$AN$45) -> 8.080446 | AP39: =(AO39+AO39*$AN$45) -> 8.6078133 | AQ39: =(AP39+AP39*$AN$45) -> 9.169599 | AR39: =(AQ39+AQ39*$AN$45) -> 9.7680495 | AS39: =(AR39+AR39*$AN$45) -> 10.405558 | AT39: =(AS39+AS39*$AN$45) -> 11.084672 | AU39: =(AT39+AT39*$AN$45) -> 11.808109 | AV39: =(AU39+AU39*$AN$45) -> 12.578761 | ... AX39: =(AW39+AW39*$AN$45) -> 14.274236
A40: Kerosene Heat | B40: 0.04813871 | C40: 0.051280464 | D40: 0.054627265 | E40: 0.058192493 | F40: 0.061990404 | G40: 0.066036185 | H40: 0.070346012 | I40: 0.074937118 | J40: 0.079827861 | K40: 0.085037797 | L40: 0.090587757 | M40: 0.096499933 | N40: 0.10279797 | O40: 0.10950704 | P40: 0.11665397 | Q40: 0.12426735 | R40: 0.13237761 | S40: 0.14101719 | T40: 0.15022062 | U40: 0.16002471 | V40: 0.17046867 | W40: 0.18159424 | X40: 0.19344592 | Y40: 0.2060711 | Z40: 0.21952025 | AA40: 0.23384716 | AB40: 0.24910911 | AC40: 0.26536712 | AD40: 0.28268621 | AE40: 0.30113562 | AF40: 0.32078912 | AG40: 0.3417253 | AH40: 0.36402788 | AI40: 0.38778602 | AJ40: 0.41309473 | AK40: 0.4400552 | AL40: 0.46877524 | AM40: 0.49936968 | AN40: 0.53196086 | AO40: =(AN40+AN40*$AN$45) -> 0.56667909 | AP40: =(AO40+AO40*$AN$45) -> 0.60366318 | AQ40: =(AP40+AP40*$AN$45) -> 0.64306104 | AR40: =(AQ40+AQ40*$AN$45) -> 0.68503018 | AS40: =(AR40+AR40*$AN$45) -> 0.72973841 | AT40: =(AS40+AS40*$AN$45) -> 0.77736452 | AU40: =(AT40+AT40*$AN$45) -> 0.82809893 | AV40: =(AU40+AU40*$AN$45) -> 0.88214449 | ... AX40: =(AW40+AW40*$AN$45) -> 1.0010476
A41: Gasoil Generator | B41: 0.036816096 | C41: 0.039218885 | D41: 0.041778491 | E41: 0.044505149 | F41: 0.047409761 | G41: 0.050503941 | H41: 0.053800062 | I41: 0.057311303 | J41: 0.061051704 | K41: 0.06503622 | L41: 0.069280785 | M41: 0.07380237 | N41: 0.078619054 | O41: 0.083750097 | P41: 0.089216016 | Q41: 0.095038666 | R41: 0.10124133 | S41: 0.10784881 | T41: 0.11488752 | U41: 0.12238561 | V41: 0.13037306 | W41: 0.13888181 | X41: 0.14794588 | Y41: 0.15760151 | Z41: 0.16788732 | AA41: 0.17884442 | AB41: 0.19051663 | AC41: 0.20295063 | AD41: 0.21619613 | AE41: 0.23030609 | AF41: 0.24533693 | AG41: 0.26134875 | AH41: 0.27840558 | AI41: 0.29657562 | AJ41: 0.31593151 | AK41: 0.33655067 | AL41: 0.35851552 | AM41: 0.3819139 | AN41: 0.40683937 | AO41: =(AN41+AN41*$AN$45) -> 0.43339159 | AP41: =(AO41+AO41*$AN$45) -> 0.46167673 | AQ41: =(AP41+AP41*$AN$45) -> 0.49180789 | AR41: =(AQ41+AQ41*$AN$45) -> 0.52390555 | AS41: =(AR41+AR41*$AN$45) -> 0.55809805 | AT41: =(AS41+AS41*$AN$45) -> 0.59452211 | AU41: =(AT41+AT41*$AN$45) -> 0.63332337 | AV41: =(AU41+AU41*$AN$45) -> 0.67465699 | ... AX41: =(AW41+AW41*$AN$45) -> 0.76559314
...

Sheet Commercial-Conversion
A1: Variable: Non Electricity Consumption: Total Final Energy Consumption (Gigajoule)
A2: Scenario: Business as Usual
A3: Branch: Demand\Commercial\Office\Conventional Office\Non Electricity Consumption\Gasoil Generator
A4: Region: Indonesia
A6: Branch | B6: 2022 | C6: 2023 | D6: 2024 | E6: 2025 | F6: 2026 | G6: 2027 | H6: 2028 | I6: 2029 | J6: 2030 | K6: 2031 | L6: 2032 | M6: 2033 | N6: 2034 | O6: 2035 | P6: 2036 | Q6: 2037 | R6: 2038 | S6: 2039 | T6: 2040 | U6: 2041 | V6: 2042 | W6: 2043 | X6: 2044 | Y6: 2045 | Z6: 2046 | AA6: 2047 | AB6: 2048 | AC6: 2049 | AD6: 2050 | AE6: 2051 | AF6: 2052 | AG6: 2053 | AH6: 2054 | AI6: 2055 | AJ6: 2056 | AK6: 2057 | AL6: 2058 | AM6: 2059 | AN6: 2060 | AO6: =AN6+1 -> 2061 | AP6: =AO6+1 -> 2062 | AQ6: =AP6+1 -> 2063 | AR6: =AQ6+1 -> 2064 | AS6: =AR6+1 -> 2065 | AT6: =AS6+1 -> 2066 | AU6: =AT6+1 -> 2067 | AV6: =AU6+1 -> 2068 | ... AX6: =AW6+1 -> 2070
A7: Gasoil Generator | B7: =Commercial!B7*Commercial!$B$5 -> 328187.75 | C7: =Commercial!C7*Commercial!$B$5 -> 344625.01 | D7: =Commercial!D7*Commercial!$B$5 -> 347973.8 | E7: =Commercial!E7*Commercial!$B$5 -> 351337.36 | F7: =Commercial!F7*Commercial!$B$5 -> 356719.91 | G7: =Commercial!G7*Commercial!$B$5 -> 362141.97 | H7: =Commercial!H7*Commercial!$B$5 -> 367603.54 | I7: =Commercial!I7*Commercial!$B$5 -> 373104.62 | ... AX7: =Commercial!AX7*Commercial!$B$5 -> 519533.12
A8: Biogasoil Generator | B8: =Commercial!B8*Commercial!$B$5 -> 3364475.1 | C8: =Commercial!C8*Commercial!$B$5 -> 3532984.6 | D8: =Commercial!D8*Commercial!$B$5 -> 3567315.3 | E8: =Commercial!E8*Commercial!$B$5 -> 3601797.4 | F8: =Commercial!F8*Commercial!$B$5 -> 3656977.6 | G8: =Commercial!G8*Commercial!$B$5 -> 3712562.9 | H8: =Commercial!H8*Commercial!$B$5 -> 3768553.1 | I8: =Commercial!I8*Commercial!$B$5 -> 3824948.4 | ... AX8: =Commercial!AX8*Commercial!$B$5 -> 5326086.2
A9: MDF Generator | B9: =Commercial!B9*Commercial!$B$5 -> 2922.1903 | C9: =Commercial!C9*Commercial!$B$5 -> 3068.548 | D9: =Commercial!D9*Commercial!$B$5 -> 3098.3657 | E9: =Commercial!E9*Commercial!$B$5 -> 3128.3148 | F9: =Commercial!F9*Commercial!$B$5 -> 3176.2412 | G9: =Commercial!G9*Commercial!$B$5 -> 3224.5193 | H9: =Commercial!H9*Commercial!$B$5 -> 3273.1493 | I9: =Commercial!I9*Commercial!$B$5 -> 3322.131 | ... AX9: =Commercial!AX9*Commercial!$B$5 -> 4625.9332
A11: Variable: Non Electricity Consumption: Total Final Energy Consumption (Gigajoule)
A12: Scenario: Business as Usual
A13: Branch: Demand\Commercial\Hotel\Five Star\Non Electricity Consumption\Biomass Heat
A14: Region: Indonesia
A16: Branch | B16: 2022 | C16: 2023 | D16: 2024 | E16: 2025 | F16: 2026 | G16: 2027 | H16: 2028 | I16: 2029 | J16: 2030 | K16: 2031 | L16: 2032 | M16: 2033 | N16: 2034 | O16: 2035 | P16: 2036 | Q16: 2037 | R16: 2038 | S16: 2039 | T16: 2040 | U16: 2041 | V16: 2042 | W16: 2043 | X16: 2044 | Y16: 2045 | Z16: 2046 | AA16: 2047 | AB16: 2048 | AC16: 2049 | AD16: 2050 | AE16: 2051 | AF16: 2052 | AG16: 2053 | AH16: 2054 | AI16: 2055 | AJ16: 2056 | AK16: 2057 | AL16: 2058 | AM16: 2059 | AN16: 2060 | AO16: =AN16+1 -> 2061 | AP16: =AO16+1 -> 2062 | AQ16: =AP16+1 -> 2063 | AR16: =AQ16+1 -> 2064 | AS16: =AR16+1 -> 2065 | AT16: =AS16+1 -> 2066 | AU16: =AT16+1 -> 2067 | AV16: =AU16+1 -> 2068 | ... AX16: =AW16+1 -> 2070
A17: Biomass Heat | B17: =Commercial!B17*Commercial!$B$5 -> 660230.83 | C17: =Commercial!C17*Commercial!$B$5 -> 703320.55 | D17: =Commercial!D17*Commercial!$B$5 -> 749222.5 | E17: =Commercial!E17*Commercial!$B$5 -> 798120.23 | F17: =Commercial!F17*Commercial!$B$5 -> 850209.25 | G17: =Commercial!G17*Commercial!$B$5 -> 905697.84 | H17: =Commercial!H17*Commercial!$B$5 -> 964807.87 | I17: =Commercial!I17*Commercial!$B$5 -> 1027775.7 | ... AX17: =Commercial!AX17*Commercial!$B$5 -> 13729543
A18: Solar Heat | B18: =Commercial!B18*Commercial!$B$5 -> 403310.8 | C18: =Commercial!C18*Commercial!$B$5 -> 429632.73 | D18: =Commercial!D18*Commercial!$B$5 -> 457672.55 | E18: =Commercial!E18*Commercial!$B$5 -> 487542.38 | F18: =Commercial!F18*Commercial!$B$5 -> 519361.65 | G18: =Commercial!G18*Commercial!$B$5 -> 553257.6 | H18: =Commercial!H18*Commercial!$B$5 -> 589365.75 | I18: =Commercial!I18*Commercial!$B$5 -> 627830.49 | ... AX18: =Commercial!AX18*Commercial!$B$5 -> 8386874.6
A19: Gas Heat | B19: =Commercial!B19*Commercial!$B$5 -> 313172.83 | C19: =Commercial!C19*Commercial!$B$5 -> 333611.93 | D19: =Commercial!D19*Commercial!$B$5 -> 355384.99 | E19: =Commercial!E19*Commercial!$B$5 -> 378579.06 | F19: =Commercial!F19*Commercial!$B$5 -> 403286.88 | G19: =Commercial!G19*Commercial!$B$5 -> 429607.25 | H19: =Commercial!H19*Commercial!$B$5 -> 457645.41 | I19: =Commercial!I19*Commercial!$B$5 -> 487513.46 | ... AX19: =Commercial!AX19*Commercial!$B$5 -> 6512449.5
A20: Kerosene Heat | B20: =Commercial!B20*Commercial!$B$5 -> 21962.71 | C20: =Commercial!C20*Commercial!$B$5 -> 23396.098 | D20: =Commercial!D20*Commercial!$B$5 -> 24923.036 | E20: =Commercial!E20*Commercial!$B$5 -> 26549.628 | F20: =Commercial!F20*Commercial!$B$5 -> 28282.38 | G20: =Commercial!G20*Commercial!$B$5 -> 30128.219 | H20: =Commercial!H20*Commercial!$B$5 -> 32094.526 | I20: =Commercial!I20*Commercial!$B$5 -> 34189.163 | ... AX20: =Commercial!AX20*Commercial!$B$5 -> 456715.99
A21: Gasoil Generator | B21: =Commercial!B21*Commercial!$B$5 -> 16796.903 | C21: =Commercial!C21*Commercial!$B$5 -> 17893.147 | D21: =Commercial!D21*Commercial!$B$5 -> 19060.936 | E21: =Commercial!E21*Commercial!$B$5 -> 20304.941 | F21: =Commercial!F21*Commercial!$B$5 -> 21630.136 | G21: =Commercial!G21*Commercial!$B$5 -> 23041.818 | H21: =Commercial!H21*Commercial!$B$5 -> 24545.634 | I21: =Commercial!I21*Commercial!$B$5 -> 26147.596 | ... AX21: =Commercial!AX21*Commercial!$B$5 -> 349292.7
A22: Biogasoil Generator | B22: =Commercial!B22*Commercial!$B$5 -> 172196.44 | C22: =Commercial!C22*Commercial!$B$5 -> 183434.78 | D22: =Commercial!D22*Commercial!$B$5 -> 195406.58 | E22: =Commercial!E22*Commercial!$B$5 -> 208159.72 | F22: =Commercial!F22*Commercial!$B$5 -> 221745.18 | G22: =Commercial!G22*Commercial!$B$5 -> 236217.3 | H22: =Commercial!H22*Commercial!$B$5 -> 251633.93 | I22: =Commercial!I22*Commercial!$B$5 -> 268056.73 | ... AX22: =Commercial!AX22*Commercial!$B$5 -> 3580836.3
A23: MDF Generator | B23: =Commercial!B23*Commercial!$B$5 -> 149.55996 | C23: =Commercial!C23*Commercial!$B$5 -> 159.32094 | D23: =Commercial!D23*Commercial!$B$5 -> 169.71896 | E23: =Commercial!E23*Commercial!$B$5 -> 180.7956 | F23: =Commercial!F23*Commercial!$B$5 -> 192.59516 | G23: =Commercial!G23*Commercial!$B$5 -> 205.16481 | H23: =Commercial!H23*Commercial!$B$5 -> 218.55481 | I23: =Commercial!I23*Commercial!$B$5 -> 232.81871 | ... AX23: =Commercial!AX23*Commercial!$B$5 -> 3110.1092
A24: LPG Heat | B24: =Commercial!B24*Commercial!$B$5 -> 273085.74 | C24: =Commercial!C24*Commercial!$B$5 -> 290908.58 | D24: =Commercial!D24*Commercial!$B$5 -> 309894.62 | E24: =Commercial!E24*Commercial!$B$5 -> 330119.78 | F24: =Commercial!F24*Commercial!$B$5 -> 351664.92 | G24: =Commercial!G24*Commercial!$B$5 -> 374616.2 | H24: =Commercial!H24*Commercial!$B$5 -> 399065.39 | I24: =Commercial!I24*Commercial!$B$5 -> 425110.24 | ... AX24: =Commercial!AX24*Commercial!$B$5 -> 5678835.9
A26: Variable: Non Electricity Consumption: Total Final Energy Consumption (Gigajoule)
A27: Scenario: Business as Usual
A28: Branch: Demand\Commercial\Hotel\Four Star\Non Electricity Consumption\Biomass Heat
A29: Region: Indonesia
A31: Branch | B31: 2022 | C31: 2023 | D31: 2024 | E31: 2025 | F31: 2026 | G31: 2027 | H31: 2028 | I31: 2029 | J31: 2030 | K31: 2031 | L31: 2032 | M31: 2033 | N31: 2034 | O31: 2035 | P31: 2036 | Q31: 2037 | R31: 2038 | S31: 2039 | T31: 2040 | U31: 2041 | V31: 2042 | W31: 2043 | X31: 2044 | Y31: 2045 | Z31: 2046 | AA31: 2047 | AB31: 2048 | AC31: 2049 | AD31: 2050 | AE31: 2051 | AF31: 2052 | AG31: 2053 | AH31: 2054 | AI31: 2055 | AJ31: 2056 | AK31: 2057 | AL31: 2058 | AM31: 2059 | AN31: 2060 | AO31: =AN31+1 -> 2061 | AP31: =AO31+1 -> 2062 | AQ31: =AP31+1 -> 2063 | AR31: =AQ31+1 -> 2064 | AS31: =AR31+1 -> 2065 | AT31: =AS31+1 -> 2066 | AU31: =AT31+1 -> 2067 | AV31: =AU31+1 -> 2068 | ... AX31: =AW31+1 -> 2070
A32: Biomass Heat | B32: =Commercial!B37*Commercial!$B$35 -> 1447119.3 | C32: =Commercial!C37*Commercial!$B$35 -> 1541564.9 | D32: =Commercial!D37*Commercial!$B$35 -> 1642174.6 | E32: =Commercial!E37*Commercial!$B$35 -> 1749350.5 | F32: =Commercial!F37*Commercial!$B$35 -> 1863521.2 | G32: =Commercial!G37*Commercial!$B$35 -> 1985143.3 | H32: =Commercial!H37*Commercial!$B$35 -> 2114702.9 | I32: =Commercial!I37*Commercial!$B$35 -> 2252718.2 | ... AX32: =Commercial!AX37*Commercial!$B$35 -> 30092940
A33: Solar Heat | B33: =Commercial!B38*Commercial!$B$35 -> 883992.09 | C33: =Commercial!C38*Commercial!$B$35 -> 941685.5 | D33: =Commercial!D38*Commercial!$B$35 -> 1003144.3 | E33: =Commercial!E38*Commercial!$B$35 -> 1068614.1 | F33: =Commercial!F38*Commercial!$B$35 -> 1138356.8 | G33: =Commercial!G38*Commercial!$B$35 -> 1212651.2 | H33: =Commercial!H38*Commercial!$B$35 -> 1291794.4 | I33: =Commercial!I38*Commercial!$B$35 -> 1376102.9 | ... AX33: =Commercial!AX38*Commercial!$B$35 -> 18382673
A34: Gas Heat | B34: =Commercial!B39*Commercial!$B$35 -> 686424.21 | C34: =Commercial!C39*Commercial!$B$35 -> 731223.43 | D34: =Commercial!D39*Commercial!$B$35 -> 778946.45 | E34: =Commercial!E39*Commercial!$B$35 -> 829784.1 | F34: =Commercial!F39*Commercial!$B$35 -> 883939.65 | G34: =Commercial!G39*Commercial!$B$35 -> 941629.64 | H34: =Commercial!H39*Commercial!$B$35 -> 1003084.8 | I34: =Commercial!I39*Commercial!$B$35 -> 1068550.7 | ... AX34: =Commercial!AX39*Commercial!$B$35 -> 14274236
A35: Kerosene Heat | B35: =Commercial!B40*Commercial!$B$35 -> 48138.71 | C35: =Commercial!C40*Commercial!$B$35 -> 51280.464 | D35: =Commercial!D40*Commercial!$B$35 -> 54627.265 | E35: =Commercial!E40*Commercial!$B$35 -> 58192.493 | F35: =Commercial!F40*Commercial!$B$35 -> 61990.404 | G35: =Commercial!G40*Commercial!$B$35 -> 66036.185 | H35: =Commercial!H40*Commercial!$B$35 -> 70346.012 | I35: =Commercial!I40*Commercial!$B$35 -> 74937.118 | ... AX35: =Commercial!AX40*Commercial!$B$35 -> 1001047.6
A36: Gasoil Generator | B36: =Commercial!B41*Commercial!$B$35 -> 36816.096 | C36: =Commercial!C41*Commercial!$B$35 -> 39218.885 | D36: =Commercial!D41*Commercial!$B$35 -> 41778.491 | E36: =Commercial!E41*Commercial!$B$35 -> 44505.149 | F36: =Commercial!F41*Commercial!$B$35 -> 47409.761 | G36: =Commercial!G41*Commercial!$B$35 -> 50503.941 | H36: =Commercial!H41*Commercial!$B$35 -> 53800.062 | I36: =Commercial!I41*Commercial!$B$35 -> 57311.303 | ... AX36: =Commercial!AX41*Commercial!$B$35 -> 765593.14
A37: Biogasoil Generator | B37: =Commercial!B42*Commercial!$B$35 -> 377426.76 | C37: =Commercial!C42*Commercial!$B$35 -> 402059.38 | D37: =Commercial!D42*Commercial!$B$35 -> 428299.63 | E37: =Commercial!E42*Commercial!$B$35 -> 456252.45 | F37: =Commercial!F42*Commercial!$B$35 -> 486029.59 | G37: =Commercial!G42*Commercial!$B$35 -> 517750.13 | H37: =Commercial!H42*Commercial!$B$35 -> 551540.9 | I37: =Commercial!I42*Commercial!$B$35 -> 587537.02 | ... AX37: =Commercial!AX42*Commercial!$B$35 -> 7848614.3
A38: MDF Generator | B38: =Commercial!B43*Commercial!$B$35 -> 327.81126 | C38: =Commercial!C43*Commercial!$B$35 -> 349.20574 | D38: =Commercial!D43*Commercial!$B$35 -> 371.99652 | E38: =Commercial!E43*Commercial!$B$35 -> 396.27473 | F38: =Commercial!F43*Commercial!$B$35 -> 422.13745 | G38: =Commercial!G43*Commercial!$B$35 -> 449.6881 | H38: =Commercial!H43*Commercial!$B$35 -> 479.03682 | I38: =Commercial!I43*Commercial!$B$35 -> 510.30098 | ... AX38: =Commercial!AX43*Commercial!$B$35 -> 6816.8566
A39: LPG Heat | B39: =Commercial!B44*Commercial!$B$35 -> 598559.8 | C39: =Commercial!C44*Commercial!$B$35 -> 637624.58 | D39: =Commercial!D44*Commercial!$B$35 -> 679238.91 | E39: =Commercial!E44*Commercial!$B$35 -> 723569.19 | F39: =Commercial!F44*Commercial!$B$35 -> 770792.66 | G39: =Commercial!G44*Commercial!$B$35 -> 821098.16 | H39: =Commercial!H44*Commercial!$B$35 -> 874686.82 | I39: =Commercial!I44*Commercial!$B$35 -> 931772.93 | ... AX39: =Commercial!AX44*Commercial!$B$35 -> 12447090
A41: Variable: Non Electricity Consumption: Total Final Energy Consumption (Gigajoule)
A42: Scenario: Business as Usual
A43: Branch: Demand\Commercial\Hotel\Three Star\Non Electricity Consumption\Biomass Heat
A44: Region: Indonesia
A46: Branch | B46: 2022 | C46: 2023 | D46: 2024 | E46: 2025 | F46: 2026 | G46: 2027 | H46: 2028 | I46: 2029 | J46: 2030 | K46: 2031 | L46: 2032 | M46: 2033 | N46: 2034 | O46: 2035 | P46: 2036 | Q46: 2037 | R46: 2038 | S46: 2039 | T46: 2040 | U46: 2041 | V46: 2042 | W46: 2043 | X46: 2044 | Y46: 2045 | Z46: 2046 | AA46: 2047 | AB46: 2048 | AC46: 2049 | AD46: 2050 | AE46: 2051 | AF46: 2052 | AG46: 2053 | AH46: 2054 | AI46: 2055 | AJ46: 2056 | AK46: 2057 | AL46: 2058 | AM46: 2059 | AN46: 2060 | AO46: =AN46+1 -> 2061 | AP46: =AO46+1 -> 2062 | AQ46: =AP46+1 -> 2063 | AR46: =AQ46+1 -> 2064 | AS46: =AR46+1 -> 2065 | AT46: =AS46+1 -> 2066 | AU46: =AT46+1 -> 2067 | AV46: =AU46+1 -> 2068 | ... AX46: =AW46+1 -> 2070
A47: Biomass Heat | B47: =Commercial!B52*Commercial!$B$35 -> 1086472.7 | C47: =Commercial!C52*Commercial!$B$35 -> 1157381 | D47: =Commercial!D52*Commercial!$B$35 -> 1232917 | E47: =Commercial!E52*Commercial!$B$35 -> 1313382.9 | F47: =Commercial!F52*Commercial!$B$35 -> 1399100.3 | G47: =Commercial!G52*Commercial!$B$35 -> 1490412.1 | H47: =Commercial!H52*Commercial!$B$35 -> 1587683.3 | I47: =Commercial!I52*Commercial!$B$35 -> 1691302.8 | ... AX47: =Commercial!AX52*Commercial!$B$35 -> 22593272
...

Sheet Electricity
A1: Variable: Electric Appliances: Total Final Energy Consumption (Million Gigajoule)
A2: Scenario: Business as Usual
A3: Branch: Demand\Commercial\Office\Conventional Office\Electric Appliances\Air Conditioner
A4: Region: Indonesia
A5: Million Gigajoule to Gigajoule | B5: 1000000
A6: Branch | B6: 2022 | C6: 2023 | D6: 2024 | E6: 2025 | F6: 2026 | G6: 2027 | H6: 2028 | I6: 2029 | J6: 2030 | K6: 2031 | L6: 2032 | M6: 2033 | N6: 2034 | O6: 2035 | P6: 2036 | Q6: 2037 | R6: 2038 | S6: 2039 | T6: 2040 | U6: 2041 | V6: 2042 | W6: 2043 | X6: 2044 | Y6: 2045 | Z6: 2046 | AA6: 2047 | AB6: 2048 | AC6: 2049 | AD6: 2050 | AE6: 2051 | AF6: 2052 | AG6: 2053 | AH6: 2054 | AI6: 2055 | AJ6: 2056 | AK6: 2057 | AL6: 2058 | AM6: 2059 | AN6: 2060 | AO6: =AN6+1 -> 2061 | AP6: =AO6+1 -> 2062 | AQ6: =AP6+1 -> 2063 | AR6: =AQ6+1 -> 2064 | AS6: =AR6+1 -> 2065 | AT6: =AS6+1 -> 2066 | AU6: =AT6+1 -> 2067 | AV6: =AU6+1 -> 2068 | ... AX6: =AW6+1 -> 2070
A7: Air Conditioner | B7: 45.305693 | C7: 47.574826 | D7: 48.03712 | E7: 48.501453 | F7: 49.244504 | G7: 49.993009 | H7: 50.746968 | I7: 51.506382 | J7: 52.271249 | K7: 52.968655 | L7: 53.670642 | M7: 54.37721 | N7: 55.088359 | O7: 55.804089 | P7: 56.448434 | Q7: 57.096477 | R7: 57.748217 | S7: 58.403656 | T7: 59.062792 | U7: 59.649168 | V7: 60.238379 | W7: 60.830423 | X7: 61.425301 | Y7: 62.023013 | Z7: 62.548129 | AA7: 63.075251 | AB7: 63.604377 | AC7: 64.135509 | AD7: 64.668646 | AE7: 65.016264 | AF7: 65.363882 | AG7: 65.7115 | AH7: 66.059118 | AI7: 66.406736 | AJ7: 66.754354 | AK7: 67.101972 | AL7: 67.44959 | AM7: 67.797207 | AN7: 68.144825 | AO7: =(AN7+AN7*$AN$11) -> 68.494226 | AP7: =(AO7+AO7*$AN$11) -> 68.845417 | AQ7: =(AP7+AP7*$AN$11) -> 69.19841 | AR7: =(AQ7+AQ7*$AN$11) -> 69.553212 | AS7: =(AR7+AR7*$AN$11) -> 69.909834 | AT7: =(AS7+AS7*$AN$11) -> 70.268284 | AU7: =(AT7+AT7*$AN$11) -> 70.628571 | AV7: =(AU7+AU7*$AN$11) -> 70.990707 | ... AX7: =(AW7+AW7*$AN$11) -> 71.720557
A8: Lighting and Electronics | B8: 17.669927 | C8: 18.554924 | D8: 18.735226 | E8: 18.916323 | F8: 19.206125 | G8: 19.498054 | H8: 19.792109 | I8: 20.088292 | J8: 20.386602 | K8: 20.658602 | L8: 20.932388 | M8: 21.20796 | N8: 21.485319 | O8: 21.764465 | P8: 22.01577 | Q8: 22.268517 | R8: 22.522706 | S8: 22.778337 | T8: 23.03541 | U8: 23.264106 | V8: 23.493907 | W8: 23.724814 | X8: 23.956826 | Y8: 24.189943 | Z8: 24.394746 | AA8: 24.600332 | AB8: 24.806699 | AC8: 25.013849 | AD8: 25.221781 | AE8: 25.357357 | AF8: 25.492934 | AG8: 25.62851 | AH8: 25.764087 | AI8: 25.899663 | AJ8: 26.035239 | AK8: 26.170816 | AL8: 26.306392 | AM8: 26.441969 | AN8: 26.577545 | AO8: =(AN8+AN8*$AN$11) -> 26.713817 | AP8: =(AO8+AO8*$AN$11) -> 26.850787 | AQ8: =(AP8+AP8*$AN$11) -> 26.988459 | AR8: =(AQ8+AQ8*$AN$11) -> 27.126838 | AS8: =(AR8+AR8*$AN$11) -> 27.265926 | AT8: =(AS8+AS8*$AN$11) -> 27.405727 | AU8: =(AT8+AT8*$AN$11) -> 27.546245 | AV8: =(AU8+AU8*$AN$11) -> 27.687483 | ... AX8: =(AW8+AW8*$AN$11) -> 27.972136
A9: Elevator or Escalator | B9: 4.8062202 | C9: 5.0469395 | D9: 5.0959815 | E9: 5.1452399 | F9: 5.2240659 | G9: 5.3034706 | H9: 5.3834537 | I9: 5.4640155 | J9: 5.5451559 | K9: 5.6191397 | L9: 5.6936095 | M9: 5.7685652 | N9: 5.8440069 | O9: 5.9199345 | P9: 5.9882894 | Q9: 6.0570365 | R9: 6.126176 | S9: 6.1957076 | T9: 6.2656316 | U9: 6.3278369 | V9: 6.3903428 | W9: 6.4531494 | X9: 6.5162566 | Y9: 6.5796644 | Z9: 6.635371 | AA9: 6.6912903 | AB9: 6.7474223 | AC9: 6.803767 | AD9: 6.8603244 | AE9: 6.8972012 | AF9: 6.934078 | AG9: 6.9709548 | AH9: 7.0078315 | AI9: 7.0447083 | AJ9: 7.0815851 | AK9: 7.1184619 | AL9: 7.1553387 | AM9: 7.1922155 | AN9: 7.2290922 | AO9: =(AN9+AN9*$AN$11) -> 7.2661581 | AP9: =(AO9+AO9*$AN$11) -> 7.303414 | AQ9: =(AP9+AP9*$AN$11) -> 7.3408609 | AR9: =(AQ9+AQ9*$AN$11) -> 7.3784999 | AS9: =(AR9+AR9*$AN$11) -> 7.4163318 | AT9: =(AS9+AS9*$AN$11) -> 7.4543577 | AU9: =(AT9+AT9*$AN$11) -> 7.4925786 | AV9: =(AU9+AU9*$AN$11) -> 7.5309954 | ... AX9: =(AW9+AW9*$AN$11) -> 7.608421
A10: Other Electricity Use | B10: 2.8978681 | C10: 3.0430076 | D10: 3.0725771 | E10: 3.102277 | F10: 3.1498045 | G10: 3.1976808 | H10: 3.2459059 | I10: 3.2944799 | J10: 3.3434028 | K10: 3.3880107 | L10: 3.4329116 | M10: 3.4781055 | N10: 3.5235924 | O10: 3.5693723 | P10: 3.6105863 | Q10: 3.6520367 | R10: 3.6937237 | S10: 3.7356472 | T10: 3.7778073 | U10: 3.8153134 | V10: 3.8530008 | W10: 3.8908695 | X10: 3.9289194 | Y10: 3.9671506 | Z10: 4.0007384 | AA10: 4.0344544 | AB10: 4.0682987 | AC10: 4.1022713 | AD10: 4.1363721 | AE10: 4.1586066 | AF10: 4.1808411 | AG10: 4.2030757 | AH10: 4.2253102 | AI10: 4.2475447 | AJ10: 4.2697793 | AK10: 4.2920138 | AL10: 4.3142483 | AM10: 4.3364828 | AN10: 4.3587174 | AO10: =(AN10+AN10*$AN$11) -> 4.3810659 | AP10: =(AO10+AO10*$AN$11) -> 4.403529 | AQ10: =(AP10+AP10*$AN$11) -> 4.4261073 | AR10: =(AQ10+AQ10*$AN$11) -> 4.4488014 | AS10: =(AR10+AR10*$AN$11) -> 4.4716118 | AT10: =(AS10+AS10*$AN$11) -> 4.4945392 | AU10: =(AT10+AT10*$AN$11) -> 4.5175841 | AV10: =(AU10+AU10*$AN$11) -> 4.5407472 | ... AX10: =(AW10+AW10*$AN$11) -> 4.5874303
AM11: Growth rate | AN11: =(AN7-AM7)/AM7 -> 0.0051273188
A12: Variable: Electric Appliances: Total Final Energy Consumption (Million Gigajoule) | AM12: Growth rate | AN12: =(AN8-AM8)/AM8 -> 0.0051273188
A13: Scenario: Business as Usual | AM13: Growth rate | AN13: =(AN9-AM9)/AM9 -> 0.0051273188
A14: Branch: Demand\Commercial\Hotel\Five Star\Electric Appliances\Air Conditioner | AM14: Growth rate | AN14: =(AN10-AM10)/AM10 -> 0.0051273188
A15: Region: Indonesia
A16: Million Gigajoule to Gigajoule | B16: 1000000
A17: Branch | B17: 2022 | C17: 2023 | D17: 2024 | E17: 2025 | F17: 2026 | G17: 2027 | H17: 2028 | I17: 2029 | J17: 2030 | K17: 2031 | L17: 2032 | M17: 2033 | N17: 2034 | O17: 2035 | P17: 2036 | Q17: 2037 | R17: 2038 | S17: 2039 | T17: 2040 | U17: 2041 | V17: 2042 | W17: 2043 | X17: 2044 | Y17: 2045 | Z17: 2046 | AA17: 2047 | AB17: 2048 | AC17: 2049 | AD17: 2050 | AE17: 2051 | AF17: 2052 | AG17: 2053 | AH17: 2054 | AI17: 2055 | AJ17: 2056 | AK17: 2057 | AL17: 2058 | AM17: 2059 | AN17: 2060 | AO17: =AN17+1 -> 2061 | AP17: =AO17+1 -> 2062 | AQ17: =AP17+1 -> 2063 | AR17: =AQ17+1 -> 2064 | AS17: =AR17+1 -> 2065 | AT17: =AS17+1 -> 2066 | AU17: =AT17+1 -> 2067 | AV17: =AU17+1 -> 2068 | ... AX17: =AW17+1 -> 2070
A18: Air Conditioner | B18: 2.3983642 | C18: 2.5548925 | D18: 2.7216367 | E18: 2.8992633 | F18: 3.0884826 | G18: 3.2900512 | H18: 3.5047752 | I18: 3.7335131 | J18: 3.9771794 | K18: 4.2367485 | L18: 4.5132583 | M18: 4.8078145 | N18: 5.1215947 | O18: 5.4558537 | P18: 5.8119279 | Q18: 6.1912412 | R18: 6.5953103 | S18: 7.0257507 | T18: 7.4842837 | U18: 7.9727427 | V18: 8.4930808 | W18: 9.0473785 | X18: 9.6378523 | Y18: 10.266863 | Z18: 10.936926 | AA18: 11.650721 | AB18: 12.4111 | AC18: 13.221106 | AD18: 14.083977 | AE18: 15.003162 | AF18: 15.982338 | AG18: 17.02542 | AH18: 18.136577 | AI18: 19.320254 | AJ18: 20.581183 | AK18: 21.924407 | AL18: 23.355295 | AM18: 24.879569 | AN18: 26.503325 | AO18: =(AN18+AN18*$AN$22) -> 28.233055 | AP18: =(AO18+AO18*$AN$22) -> 30.075675 | AQ18: =(AP18+AP18*$AN$22) -> 32.038552 | AR18: =(AQ18+AQ18*$AN$22) -> 34.129537 | AS18: =(AR18+AR18*$AN$22) -> 36.356988 | AT18: =(AS18+AS18*$AN$22) -> 38.729813 | AU18: =(AT18+AT18*$AN$22) -> 41.2575 | AV18: =(AU18+AU18*$AN$22) -> 43.950155 | ... AX18: =(AW18+AW18*$AN$22) -> 49.874141
A19: Lighting and Electronics | B19: 0.74881054 | C19: 0.79768138 | D19: 0.84974176 | E19: 0.90519984 | F19: 0.96427737 | G19: 1.0272106 | H19: 1.0942511 | I19: 1.165667 | J19: 1.2417438 | K19: 1.3227857 | L19: 1.4091169 | M19: 1.5010823 | N19: 1.5990499 | O19: 1.7034113 | P19: 1.8145838 | Q19: 1.933012 | R19: 2.0591693 | S19: 2.1935602 | T19: 2.3367221 | U19: 2.4892274 | V19: 2.6516859 | W19: 2.8247471 | X19: 3.0091032 | Y19: 3.2054912 | Z19: 3.4146964 | AA19: 3.6375553 | AB19: 3.874959 | AC19: 4.1278567 | AD19: 4.3972598 | AE19: 4.6842453 | AF19: 4.9899608 | AG19: 5.3156287 | AH19: 5.6625513 | AI19: 6.0321156 | AJ19: 6.4257993 | AK19: 6.8451767 | AL19: 7.2919246 | AM19: 7.7678294 | AN19: 8.2747939 | AO19: =(AN19+AN19*$AN$22) -> 8.8148452 | AP19: =(AO19+AO19*$AN$22) -> 9.3901428 | AQ19: =(AP19+AP19*$AN$22) -> 10.002987 | AR19: =(AQ19+AQ19*$AN$22) -> 10.655828 | AS19: =(AR19+AR19*$AN$22) -> 11.351277 | AT19: =(AS19+AS19*$AN$22) -> 12.092114 | AU19: =(AT19+AT19*$AN$22) -> 12.881301 | AV19: =(AU19+AU19*$AN$22) -> 13.721994 | ... AX19: =(AW19+AW19*$AN$22) -> 15.571564
A20: Elevator or Escalator | B20: 0.22428142 | C20: 0.23891906 | D20: 0.25451202 | E20: 0.27112266 | F20: 0.28881738 | G20: 0.30766693 | H20: 0.3277467 | I20: 0.34913697 | J20: 0.37192326 | K20: 0.3961967 | L20: 0.42205432 | M20: 0.44959954 | N20: 0.47894249 | O20: 0.51020049 | P20: 0.54349854 | Q20: 0.57896977 | R20: 0.61675601 | S20: 0.65700836 | T20: 0.69988777 | U20: 0.74556568 | V20: 0.79422475 | W20: 0.84605953 | X20: 0.90127729 | Y20: 0.96009882 | Z20: 1.0227593 | AA20: 1.0895093 | AB20: 1.1606157 | AC20: 1.2363629 | AD20: 1.3170536 | AE20: 1.4030107 | AF20: 1.4945776 | AG20: 1.5921207 | AH20: 1.6960298 | AI20: 1.8067206 | AJ20: 1.9246355 | AK20: 2.0502462 | AL20: 2.1840547 | AM20: 2.3265962 | AN20: 2.4784407 | AO20: =(AN20+AN20*$AN$22) -> 2.6401952 | AP20: =(AO20+AO20*$AN$22) -> 2.8125065 | AQ20: =(AP20+AP20*$AN$22) -> 2.9960637 | AR20: =(AQ20+AQ20*$AN$22) -> 3.1916007 | AS20: =(AR20+AR20*$AN$22) -> 3.3998993 | AT20: =(AS20+AS20*$AN$22) -> 3.6217925 | AU20: =(AT20+AT20*$AN$22) -> 3.8581674 | AV20: =(AU20+AU20*$AN$22) -> 4.1099693 | ... AX20: =(AW20+AW20*$AN$22) -> 4.6639468
A21: Other Electricity Use | B21: 0.24598607 | C21: 0.26204026 | D21: 0.27914222 | E21: 0.29736033 | F21: 0.31676744 | G21: 0.33744115 | H21: 0.35946412 | I21: 0.38292442 | J21: 0.40791584 | K21: 0.43453831 | L21: 0.46289829 | M21: 0.49310918 | N21: 0.52529176 | O21: 0.55957473 | P21: 0.59609517 | Q21: 0.6349991 | R21: 0.67644208 | S21: 0.72058982 | T21: 0.76761884 | U21: 0.8177172 | V21: 0.87108521 | W21: 0.92793626 | X21: 0.98849767 | Y21: 1.0530116 | Z21: 1.121736 | AA21: 1.1949457 | AB21: 1.2729334 | AC21: 1.3560109 | AD21: 1.4445105 | AE21: 1.5387859 | AF21: 1.6392142 | AG21: 1.7461969 | AH21: 1.8601618 | AI21: 1.9815645 | AJ21: 2.1108906 | AK21: 2.2486571 | AL21: 2.3954149 | AM21: 2.5517507 | AN21: 2.7182898 | AO21: =(AN21+AN21*$AN$22) -> 2.8956979 | AP21: =(AO21+AO21*$AN$22) -> 3.0846846 | AQ21: =(AP21+AP21*$AN$22) -> 3.2860054 | AR21: =(AQ21+AQ21*$AN$22) -> 3.5004653 | AS21: =(AR21+AR21*$AN$22) -> 3.7289218 | AT21: =(AS21+AS21*$AN$22) -> 3.9722885 | AU21: =(AT21+AT21*$AN$22) -> 4.2315385 | AV21: =(AU21+AU21*$AN$22) -> 4.5077082 | ... AX21: =(AW21+AW21*$AN$22) -> 5.1152965
AM22: Growth rate | AN22: =(AN18-AM18)/AM18 -> 0.065264627
A23: Variable: Electric Appliances: Total Final Energy Consumption (Million Gigajoule) | AM23: Growth rate | AN23: =(AN19-AM19)/AM19 -> 0.065264627
A24: Scenario: Business as Usual | AM24: Growth rate | AN24: =(AN20-AM20)/AM20 -> 0.065264627
A25: Branch: Demand\Commercial\Hotel\Four Star\Electric Appliances\Air Conditioner | AM25: Growth rate | AN25: =(AN21-AM21)/AM21 -> 0.065264627
A26: Region: Indonesia
A27: Million Gigajoule to Gigajoule | B27: 1000000
A28: Branch | B28: 2022 | C28: 2023 | D28: 2024 | E28: 2025 | F28: 2026 | G28: 2027 | H28: 2028 | I28: 2029 | J28: 2030 | K28: 2031 | L28: 2032 | M28: 2033 | N28: 2034 | O28: 2035 | P28: 2036 | Q28: 2037 | R28: 2038 | S28: 2039 | T28: 2040 | U28: 2041 | V28: 2042 | W28: 2043 | X28: 2044 | Y28: 2045 | Z28: 2046 | AA28: 2047 | AB28: 2048 | AC28: 2049 | AD28: 2050 | AE28: 2051 | AF28: 2052 | AG28: 2053 | AH28: 2054 | AI28: 2055 | AJ28: 2056 | AK28: 2057 | AL28: 2058 | AM28: 2059 | AN28: 2060 | AO28: =AN28+1 -> 2061 | AP28: =AO28+1 -> 2062 | AQ28: =AP28+1 -> 2063 | AR28: =AQ28+1 -> 2064 | AS28: =AR28+1 -> 2065 | AT28: =AS28+1 -> 2066 | AU28: =AT28+1 -> 2067 | AV28: =AU28+1 -> 2068 | ... AX28: =AW28+1 -> 2070
A29: Air Conditioner | B29: 5.2568266 | C29: 5.5999114 | D29: 5.9653876 | E29: 6.3547164 | F29: 6.7694545 | G29: 7.2112605 | H29: 7.6819007 | I29: 8.1832571 | J29: 8.7173343 | K29: 9.2862679 | L29: 9.8923327 | M29: 10.537952 | N29: 11.225708 | O29: 11.958349 | P29: 12.738806 | Q29: 13.5702 | R29: 14.455854 | S29: 15.39931 | T29: 16.40434 | U29: 17.474963 | V29: 18.61546 | W29: 19.830391 | X29: 21.124614 | Y29: 22.503304 | Z29: 23.971974 | AA29: 25.536496 | AB29: 27.203126 | AC29: 28.978528 | AD29: 30.869801 | AE29: 32.884507 | AF29: 35.030702 | AG29: 37.316967 | AH29: 39.752445 | AI29: 42.346874 | AJ29: 45.110627 | AK29: 48.054755 | AL29: 51.191031 | AM29: 54.531994 | AN29: 58.091004 | AO29: =(AN29+AN29*$AN$33) -> 61.882292 | AP29: =(AO29+AO29*$AN$33) -> 65.921017 | AQ29: =(AP29+AP29*$AN$33) -> 70.223327 | AR29: =(AQ29+AQ29*$AN$33) -> 74.806427 | AS29: =(AR29+AR29*$AN$33) -> 79.68864 | AT29: =(AS29+AS29*$AN$33) -> 84.88949 | AU29: =(AT29+AT29*$AN$33) -> 90.429771 | AV29: =(AU29+AU29*$AN$33) -> 96.331636 | ... AX29: =(AW29+AW29*$AN$33) -> 109.31605
A30: Lighting and Electronics | B30: 1.6412717 | C30: 1.7483886 | D30: 1.8624966 | E30: 1.9840517 | F30: 2.1135401 | G30: 2.2514795 | H30: 2.3984215 | I30: 2.5549536 | J30: 2.7217017 | K30: 2.8993325 | L30: 3.0885564 | M30: 3.2901298 | N30: 3.5048589 | O30: 3.7336022 | P30: 3.9772744 | Q30: 4.2368497 | R30: 4.5133662 | S30: 4.8079293 | T30: 5.121717 | U30: 5.455984 | V30: 5.8120667 | W30: 6.1913891 | X30: 6.5954678 | Y30: 7.0259185 | Z30: 7.4844625 | AA30: 7.9729332 | AB30: 8.4932837 | AC30: 9.0475946 | AD30: 9.6380825 | AE30: 10.267108 | AF30: 10.937187 | AG30: 11.650999 | AH30: 12.411397 | AI30: 13.221422 | AJ30: 14.084313 | AK30: 15.003521 | AL30: 15.98272 | AM30: 17.025826 | AN30: 18.13701 | AO30: =(AN30+AN30*$AN$33) -> 19.320716 | AP30: =(AO30+AO30*$AN$33) -> 20.581675 | AQ30: =(AP30+AP30*$AN$33) -> 21.92493 | AR30: =(AQ30+AQ30*$AN$33) -> 23.355853 | AS30: =(AR30+AR30*$AN$33) -> 24.880164 | AT30: =(AS30+AS30*$AN$33) -> 26.503958 | AU30: =(AT30+AT30*$AN$33) -> 28.233729 | AV30: =(AU30+AU30*$AN$33) -> 30.076393 | ... AX30: =(AW30+AW30*$AN$33) -> 34.130352
A31: Elevator or Escalator | B31: 0.49158861 | C31: 0.52367196 | D31: 0.55784921 | E31: 0.59425703 | F31: 0.633041 | G31: 0.67435618 | H31: 0.71836779 | I31: 0.76525179 | J31: 0.81519567 | K31: 0.86839911 | L31: 0.92507485 | M31: 0.98544952 | N31: 1.0497645 | O31: 1.118277 | P31: 1.1912609 | Q31: 1.2690081 | R31: 1.3518295 | S31: 1.4400561 | T31: 1.5340408 | U31: 1.6341595 | V31: 1.7408123 | W31: 1.8544257 | X31: 1.9754541 | Y31: 2.1043814 | Z31: 2.2417231 | AA31: 2.3880283 | AB31: 2.5438821 | AC31: 2.7099076 | AD31: 2.8867687 | AE31: 3.0751726 | AF31: 3.2758726 | AG31: 3.4896712 | AH31: 3.7174232 | AI31: 3.9600395 | AJ31: 4.21849 | AK31: 4.4938082 | AL31: 4.7870949 | AM31: 5.0995228 | AN31: 5.4323413 | AO31: =(AN31+AN31*$AN$33) -> 5.786881 | AP31: =(AO31+AO31*$AN$33) -> 6.1645596 | AQ31: =(AP31+AP31*$AN$33) -> 6.5668873 | AR31: =(AQ31+AQ31*$AN$33) -> 6.9954728 | AS31: =(AR31+AR31*$AN$33) -> 7.4520297 | AT31: =(AS31+AS31*$AN$33) -> 7.9383836 | AU31: =(AT31+AT31*$AN$33) -> 8.4564793 | AV31: =(AU31+AU31*$AN$33) -> 9.0083883 | ... AX31: =(AW31+AW31*$AN$33) -> 10.222617
A32: Other Electricity Use | B32: 0.5391617 | C32: 0.57434989 | D32: 0.61183462 | E32: 0.65176578 | F32: 0.69430303 | G32: 0.73961646 | H32: 0.78788725 | I32: 0.83930842 | J32: 0.89408557 | K32: 0.95243773 | L32: 1.0145982 | M32: 1.0808156 | N32: 1.1513546 | O32: 1.2264974 | P32: 1.3065442 | Q32: 1.3918154 | R32: 1.4826517 | S32: 1.5794164 | T32: 1.6824964 | U32: 1.7923039 | V32: 1.909278 | W32: 2.0338863 | X32: 2.1666271 | Y32: 2.3080312 | Z32: 2.458664 | AA32: 2.6191278 | AB32: 2.7900642 | AC32: 2.9721567 | AD32: 3.1661334 | AE32: 3.3727699 | AF32: 3.5928925 | AG32: 3.8273813 | AH32: 4.0771739 | AI32: 4.3432691 | AJ32: 4.6267309 | AK32: 4.9286928 | AL32: 5.2503621 | AM32: 5.593025 | AN32: 5.9580517 | AO32: =(AN32+AN32*$AN$33) -> 6.3469018 | AP32: =(AO32+AO32*$AN$33) -> 6.7611299 | AQ32: =(AP32+AP32*$AN$33) -> 7.2023926 | AR32: =(AQ32+AQ32*$AN$33) -> 7.672454 | AS32: =(AR32+AR32*$AN$33) -> 8.1731939 | AT32: =(AS32+AS32*$AN$33) -> 8.7066143 | AU32: =(AT32+AT32*$AN$33) -> 9.2748483 | AV32: =(AU32+AU32*$AN$33) -> 9.8801678 | ... AX32: =(AW32+AW32*$AN$33) -> 11.211903
AM33: Growth rate | AN33: =(AN29-AM29)/AM29 -> 0.065264627
A34: Variable: Electric Appliances: Total Final Energy Consumption (Million Gigajoule) | AM34: Growth rate | AN34: =(AN30-AM30)/AM30 -> 0.065264627
A35: Scenario: Business as Usual | AM35: Growth rate | AN35: =(AN31-AM31)/AM31 -> 0.065264627
A36: Branch: Demand\Commercial\Hotel\Three Star\Electric Appliances\Air Conditioner | AM36: Growth rate | AN36: =(AN32-AM32)/AM32 -> 0.065264627
A37: Region: Indonesia
A38: Million Gigajoule to Gigajoule | B38: 1000000
A39: Branch | B39: 2022 | C39: 2023 | D39: 2024 | E39: 2025 | F39: 2026 | G39: 2027 | H39: 2028 | I39: 2029 | J39: 2030 | K39: 2031 | L39: 2032 | M39: 2033 | N39: 2034 | O39: 2035 | P39: 2036 | Q39: 2037 | R39: 2038 | S39: 2039 | T39: 2040 | U39: 2041 | V39: 2042 | W39: 2043 | X39: 2044 | Y39: 2045 | Z39: 2046 | AA39: 2047 | AB39: 2048 | AC39: 2049 | AD39: 2050 | AE39: 2051 | AF39: 2052 | AG39: 2053 | AH39: 2054 | AI39: 2055 | AJ39: 2056 | AK39: 2057 | AL39: 2058 | AM39: 2059 | AN39: 2060 | AO39: =AN39+1 -> 2061 | AP39: =AO39+1 -> 2062 | AQ39: =AP39+1 -> 2063 | AR39: =AQ39+1 -> 2064 | AS39: =AR39+1 -> 2065 | AT39: =AS39+1 -> 2066 | AU39: =AT39+1 -> 2067 | AV39: =AU39+1 -> 2068 | ... AX39: =AW39+1 -> 2070
A40: Air Conditioner | B40: 3.9467368 | C40: 4.2043191 | D40: 4.4787124 | E40: 4.7710139 | F40: 5.0823923 | G40: 5.4140928 | H40: 5.7674415 | I40: 6.1438514 | J40: 6.5448276 | K40: 6.9719733 | L40: 7.4269966 | M40: 7.9117167 | N40: 8.428072 | O40: 8.9781269 | P40: 9.564081 | Q40: 10.188277 | R40: 10.853211 | S40: 11.561542 | T40: 12.316102 | U40: 13.119908 | V40: 13.976174 | W40: 14.888323 | X40: 15.860004 | Y40: 16.895101 | Z40: 17.997754 | AA40: 19.172371 | AB40: 20.423648 | AC40: 21.75659 | AD40: 23.176526 | AE40: 24.689133 | AF40: 26.30046 | AG40: 28.01695 | AH40: 29.845466 | AI40: 31.793319 | AJ40: 33.868298 | AK40: 36.0787 | AL40: 38.433363 | AM40: 40.941702 | AN40: 43.613746 | AO40: =(AN40+AN40*$AN$44) -> 46.460181 | AP40: =(AO40+AO40*$AN$44) -> 49.492388 | AQ40: =(AP40+AP40*$AN$44) -> 52.72249 | AR40: =(AQ40+AQ40*$AN$44) -> 56.163404 | AS40: =(AR40+AR40*$AN$44) -> 59.828887 | AT40: =(AS40+AS40*$AN$44) -> 63.733597 | AU40: =(AT40+AT40*$AN$44) -> 67.893147 | AV40: =(AU40+AU40*$AN$44) -> 72.324168 | ... AX40: =(AW40+AW40*$AN$44) -> 82.07265
...

Sheet Electricity-Conversion
A1: Variable: Electric Appliances: Total Final Energy Consumption (Gigajoule)
A2: Scenario: Business as Usual
A3: Branch: Demand\Commercial\Office\Conventional Office\Electric Appliances\Air Conditioner
A4: Region: Indonesia
A6: Branch | B6: 2022 | C6: 2023 | D6: 2024 | E6: 2025 | F6: 2026 | G6: 2027 | H6: 2028 | I6: 2029 | J6: 2030 | K6: 2031 | L6: 2032 | M6: 2033 | N6: 2034 | O6: 2035 | P6: 2036 | Q6: 2037 | R6: 2038 | S6: 2039 | T6: 2040 | U6: 2041 | V6: 2042 | W6: 2043 | X6: 2044 | Y6: 2045 | Z6: 2046 | AA6: 2047 | AB6: 2048 | AC6: 2049 | AD6: 2050 | AE6: 2051 | AF6: 2052 | AG6: 2053 | AH6: 2054 | AI6: 2055 | AJ6: 2056 | AK6: 2057 | AL6: 2058 | AM6: 2059 | AN6: 2060 | AO6: =AN6+1 -> 2061 | AP6: =AO6+1 -> 2062 | AQ6: =AP6+1 -> 2063 | AR6: =AQ6+1 -> 2064 | AS6: =AR6+1 -> 2065 | AT6: =AS6+1 -> 2066 | AU6: =AT6+1 -> 2067 | AV6: =AU6+1 -> 2068 | ... AX6: =AW6+1 -> 2070
A7: Air Conditioner | B7: =Electricity!B7*Electricity!$B$5 -> 45305693 | C7: =Electricity!C7*Electricity!$B$5 -> 47574826 | D7: =Electricity!D7*Electricity!$B$5 -> 48037120 | E7: =Electricity!E7*Electricity!$B$5 -> 48501453 | F7: =Electricity!F7*Electricity!$B$5 -> 49244504 | G7: =Electricity!G7*Electricity!$B$5 -> 49993009 | H7: =Electricity!H7*Electricity!$B$5 -> 50746968 | I7: =Electricity!I7*Electricity!$B$5 -> 51506382 | ... AX7: =Electricity!AX7*Electricity!$B$5 -> 71720557
A8: Lighting and Electronics | B8: =Electricity!B8*Electricity!$B$5 -> 17669927 | C8: =Electricity!C8*Electricity!$B$5 -> 18554924 | D8: =Electricity!D8*Electricity!$B$5 -> 18735226 | E8: =Electricity!E8*Electricity!$B$5 -> 18916323 | F8: =Electricity!F8*Electricity!$B$5 -> 19206125 | G8: =Electricity!G8*Electricity!$B$5 -> 19498054 | H8: =Electricity!H8*Electricity!$B$5 -> 19792109 | I8: =Electricity!I8*Electricity!$B$5 -> 20088292 | ... AX8: =Electricity!AX8*Electricity!$B$5 -> 27972136
A9: Elevator or Escalator | B9: =Electricity!B9*Electricity!$B$5 -> 4806220.2 | C9: =Electricity!C9*Electricity!$B$5 -> 5046939.5 | D9: =Electricity!D9*Electricity!$B$5 -> 5095981.5 | E9: =Electricity!E9*Electricity!$B$5 -> 5145239.9 | F9: =Electricity!F9*Electricity!$B$5 -> 5224065.9 | G9: =Electricity!G9*Electricity!$B$5 -> 5303470.6 | H9: =Electricity!H9*Electricity!$B$5 -> 5383453.7 | I9: =Electricity!I9*Electricity!$B$5 -> 5464015.5 | ... AX9: =Electricity!AX9*Electricity!$B$5 -> 7608421
A10: Other Electricity Use | B10: =Electricity!B10*Electricity!$B$5 -> 2897868.1 | C10: =Electricity!C10*Electricity!$B$5 -> 3043007.6 | D10: =Electricity!D10*Electricity!$B$5 -> 3072577.1 | E10: =Electricity!E10*Electricity!$B$5 -> 3102277 | F10: =Electricity!F10*Electricity!$B$5 -> 3149804.5 | G10: =Electricity!G10*Electricity!$B$5 -> 3197680.8 | H10: =Electricity!H10*Electricity!$B$5 -> 3245905.9 | I10: =Electricity!I10*Electricity!$B$5 -> 3294479.9 | ... AX10: =Electricity!AX10*Electricity!$B$5 -> 4587430.3
A12: Variable: Electric Appliances: Total Final Energy Consumption (Gigajoule)
A13: Scenario: Business as Usual
A14: Branch: Demand\Commercial\Hotel\Five Star\Electric Appliances\Air Conditioner
A15: Region: Indonesia
A17: Branch | B17: 2022 | C17: 2023 | D17: 2024 | E17: 2025 | F17: 2026 | G17: 2027 | H17: 2028 | I17: 2029 | J17: 2030 | K17: 2031 | L17: 2032 | M17: 2033 | N17: 2034 | O17: 2035 | P17: 2036 | Q17: 2037 | R17: 2038 | S17: 2039 | T17: 2040 | U17: 2041 | V17: 2042 | W17: 2043 | X17: 2044 | Y17: 2045 | Z17: 2046 | AA17: 2047 | AB17: 2048 | AC17: 2049 | AD17: 2050 | AE17: 2051 | AF17: 2052 | AG17: 2053 | AH17: 2054 | AI17: 2055 | AJ17: 2056 | AK17: 2057 | AL17: 2058 | AM17: 2059 | AN17: 2060 | AO17: =AN17+1 -> 2061 | AP17: =AO17+1 -> 2062 | AQ17: =AP17+1 -> 2063 | AR17: =AQ17+1 -> 2064 | AS17: =AR17+1 -> 2065 | AT17: =AS17+1 -> 2066 | AU17: =AT17+1 -> 2067 | AV17: =AU17+1 -> 2068 | ... AX17: =AW17+1 -> 2070
A18: Air Conditioner | B18: =Electricity!B18*Electricity!$B$16 -> 2398364.2 | C18: =Electricity!C18*Electricity!$B$16 -> 2554892.5 | D18: =Electricity!D18*Electricity!$B$16 -> 2721636.7 | E18: =Electricity!E18*Electricity!$B$16 -> 2899263.3 | F18: =Electricity!F18*Electricity!$B$16 -> 3088482.6 | G18: =Electricity!G18*Electricity!$B$16 -> 3290051.2 | H18: =Electricity!H18*Electricity!$B$16 -> 3504775.2 | I18: =Electricity!I18*Electricity!$B$16 -> 3733513.1 | ... AX18: =Electricity!AX18*Electricity!$B$16 -> 49874141
A19: Lighting and Electronics | B19: =Electricity!B19*Electricity!$B$16 -> 748810.54 | C19: =Electricity!C19*Electricity!$B$16 -> 797681.38 | D19: =Electricity!D19*Electricity!$B$16 -> 849741.76 | E19: =Electricity!E19*Electricity!$B$16 -> 905199.84 | F19: =Electricity!F19*Electricity!$B$16 -> 964277.37 | G19: =Electricity!G19*Electricity!$B$16 -> 1027210.6 | H19: =Electricity!H19*Electricity!$B$16 -> 1094251.1 | I19: =Electricity!I19*Electricity!$B$16 -> 1165667 | ... AX19: =Electricity!AX19*Electricity!$B$16 -> 15571564
A20: Elevator or Escalator | B20: =Electricity!B20*Electricity!$B$16 -> 224281.42 | C20: =Electricity!C20*Electricity!$B$16 -> 238919.06 | D20: =Electricity!D20*Electricity!$B$16 -> 254512.02 | E20: =Electricity!E20*Electricity!$B$16 -> 271122.66 | F20: =Electricity!F20*Electricity!$B$16 -> 288817.38 | G20: =Electricity!G20*Electricity!$B$16 -> 307666.93 | H20: =Electricity!H20*Electricity!$B$16 -> 327746.7 | I20: =Electricity!I20*Electricity!$B$16 -> 349136.97 | ... AX20: =Electricity!AX20*Electricity!$B$16 -> 4663946.8
A21: Other Electricity Use | B21: =Electricity!B21*Electricity!$B$16 -> 245986.07 | C21: =Electricity!C21*Electricity!$B$16 -> 262040.26 | D21: =Electricity!D21*Electricity!$B$16 -> 279142.22 | E21: =Electricity!E21*Electricity!$B$16 -> 297360.33 | F21: =Electricity!F21*Electricity!$B$16 -> 316767.44 | G21: =Electricity!G21*Electricity!$B$16 -> 337441.15 | H21: =Electricity!H21*Electricity!$B$16 -> 359464.12 | I21: =Electricity!I21*Electricity!$B$16 -> 382924.42 | ... AX21: =Electricity!AX21*Electricity!$B$16 -> 5115296.5
A23: Variable: Electric Appliances: Total Final Energy Consumption (Gigajoule)
A24: Scenario: Business as Usual
A25: Branch: Demand\Commercial\Hotel\Four Star\Electric Appliances\Air Conditioner
A26: Region: Indonesia
