Workbook
Name a: [1]ISICrev3.1!$E:$F
Name Calculated_Relationship_HS12___HS07: '[2]Correlation HS2012-HS2007'!#REF!
Name CAP_CT: #REF!
Name CAP_GFCF: #REF!
Name CAP_IT: #REF!
Name CAP_OCon: #REF!
Name CAP_OMach: #REF!
Name CAP_Other: #REF!
Name CAP_QI: #REF!
Name CAP_RStruc: #REF!
Name CAP_Soft: #REF!
Name CAP_TraEq: #REF!
Name CAPIT: #REF!
Name CAPIT_QI: #REF!
Name capit_qph: #REF!
Name CAPNIT: #REF!
Name CAPNIT_QI: #REF!
Name capnit_qph: #REF!
Name FLAPPIE: #REF!
Name go_level_top1: OFFSET('[3]35-sector'!$E$36,MATCH(#REF!,'[3]35-sector'!$E$37:$E$71,0),2,1,8)
Name HS: '[4]HS02_CPC1.1_SITC3_ISIC3.1 (2)'!#REF!
Name M1_stone: '[3]2000'!$E$1382:$BV$1451
Name M2_stone: '[3]2000'!$E$1524:$BV$1593
Name M3_stone: '[3]2000'!$E$1737:$BV$1806
Name Matrix1: #REF!
Name rca_trad_2010: '[5]13-sector VAX_G_2010'!$C$141:$P$203
Name rca_trad_2011: '[5]13-sector VAX_G_2011'!$C$141:$P$203
Name rca_trad_2012: '[5]13-sector VAX_G_2012'!$C$141:$P$203
Name rca_trad_2013: '[5]13-sector VAX_G_2013'!$C$141:$P$203
Name rca_trad_2014: '[5]13-sector VAX_G_2014'!$C$141:$P$203
Name rca_trad_2015: '[5]13-sector VAX_G_2015'!$C$141:$P$203
Name rca_trad_2016: '[5]13-sector VAX_G_2016'!$C$141:$P$203
Name rca_trad_2017: '[5]13-sector VAX_G_2017'!$C$141:$P$203
Name rca_vax_2010: '[5]13-sector VAX_G_2010'!$C$209:$P$271
Name rca_vax_2011: '[5]13-sector VAX_G_2011'!$C$209:$P$271
Name rca_vax_2012: '[5]13-sector VAX_G_2012'!$C$209:$P$271
Name rca_vax_2013: '[5]13-sector VAX_G_2013'!$C$209:$P$271
Name rca_vax_2014: '[5]13-sector VAX_G_2014'!$C$209:$P$271
Name rca_vax_2015: '[5]13-sector VAX_G_2015'!$C$209:$P$271
Name rca_vax_2016: '[5]13-sector VAX_G_2016'!$C$209:$P$271
Name rca_vax_2017: '[5]13-sector VAX_G_2017'!$C$209:$P$271
Name sector_list: #REF!
Name Sectors: #REF!
Name SUNBURST: '[5]35-sector'!#REF!
Name VAConL: #REF!
Name vax_g_2010: '[5]13-sector VAX_G_2010'!$T$5:$AI$67
Name vax_g_2011: '[5]13-sector VAX_G_2011'!$T$5:$AI$67
Name vax_g_2012: '[5]13-sector VAX_G_2012'!$T$5:$AI$67
Name vax_g_2013: '[5]13-sector VAX_G_2013'!$T$5:$AI$67
Name vax_g_2014: '[5]13-sector VAX_G_2014'!$T$5:$AI$67
Name vax_g_2015: '[5]13-sector VAX_G_2015'!$T$5:$AI$67
Name vax_g_2016: '[5]13-sector VAX_G_2016'!$T$5:$AI$67
Name vax_g_2017: '[5]13-sector VAX_G_2017'!$T$5:$AI$67
Name x_2010: '[5]13-sector VAX_G_2010'!$C$5:$R$67
Name x_2011: '[5]13-sector VAX_G_2011'!$C$5:$R$67
Name x_2012: '[5]13-sector VAX_G_2012'!$C$5:$R$67
Name x_2013: '[5]13-sector VAX_G_2013'!$C$5:$R$67
Name x_2014: '[5]13-sector VAX_G_2014'!$C$5:$R$67
Name x_2015: '[5]13-sector VAX_G_2015'!$C$5:$R$67
Name x_2016: '[5]13-sector VAX_G_2016'!$C$5:$R$67

Sheet About
A1: BPCiObIC BAU Percent Change in Output by ISIC Code
A3: Source: | B3: Most Industries
B4: OECD
B5: 2021
B6: Input-Output Tables 2021 Edition (ISIC Rev. 4)
B7: https://stats.oecd.org/Index.aspx?DataSetCode=IOTS_2021
B8: Variable: TTL
B11: BPS- Statistics Indonesia
B12: Growth Rate of GDP by Industry (2010=100) (Percent), 2026
B13: 2019-2025
B14: https://www.bps.go.id/en/statistics-table/2/MTA0IzI=/growth-rate-of-gdp-by-industry--2010-100---percent-.html
B17: Electricity consumption
B18: Statistik Industri Manufaktur Indonesia, 2020
B19: 2019-2024
B20: Badan Pusat Statistik
B21: https://www.bps.go.id/en/statistics-table/2/MTA0IzI=/growth-rate-of-gdp-by-industry--2010-100---percent-.html
A24: Notes: | B24: We examine each industry to determin the appropriate trend, then carry that forward.
B25: From there, we estimate the annual percentage growth.
B27: Note that this is not linked to BIFUbC nor fuel production.

Sheet OECD 2018
B1: =DotStatQuery(C1) -> #NAME? | C1: Sorry, the query is too large to fit into the Excel cell. You will not be able to update your table with the .Stat Populator.
B2: Dataset: Input-Output Tables (IOTs) 2021 ed.
B3: Variable | D3: TTL: Total | M3: 1 | N3: 2 | O3: 3 | P3: 4 | Q3: 5 | R3: 6 | S3: 7 | T3: 8 | U3: 9 | V3: 10 | W3: 11 | X3: 12 | Y3: 13 | Z3: 14 | AA3: 15
B4: Country | D4: IDN: Indonesia
B5: From industry / sector | D5: OUTPUT: Output at basic prices
B6: Unit | D6: US Dollar, Millions
D7: 1995 | E7: 1996 | F7: 1997 | G7: 1998 | H7: 1999 | I7: 2000 | J7: 2001 | K7: 2002 | L7: 2003 | M7: 2004 | N7: 2005 | O7: 2006 | P7: 2007 | Q7: 2008 | R7: 2009 | S7: 2010 | T7: 2011 | U7: 2012 | V7: 2013 | W7: 2014 | X7: 2015 | Y7: 2016 | Z7: 2017 | AA7: 2018 | AB7: SPARK | AC7: Intercept | AD7: Slope | AE7: R2
A9: ISIC 01T03 | B9: D01T02: Agriculture, hunting, forestry | D9: 34317.2 | E9: 38860.9 | F9: 37050.6 | G9: 16258.4 | H9: 24351.3 | I9: 26274.1 | J9: 25280.6 | K9: 30755.7 | L9: 36838.9 | M9: 40118.3 | N9: 44253.6 | O9: 56841.2 | P9: 67541.6 | Q9: 79095.1 | R9: 86180.8 | S9: 110613.9 | T9: 128256.9 | U9: 132003.4 | V9: 129858.8 | W9: 126113.1 | X9: 120681.1 | Y9: 128515.9 | Z9: 139310.1 | AA9: 142726.1 | AC9: =INTERCEPT(M9:AA9,$M$7:$AA$7) -> -15047330 | AD9: =SLOPE(M9:AA9,$M$7:$AA$7) -> 7533.3021 | AE9: =RSQ(M9:AA9,$M$7:$AA$7) -> 0.86881943
B10: D03: Fishing and aquaculture | D10: 5520.9 | E10: 6287.4 | F10: 6045.8 | G10: 2681.1 | H10: 4021.7 | I10: 4353.5 | J10: 4228 | K10: 5167.5 | L10: 6212.5 | M10: 6774.5 | N10: 7533.3 | O10: 9578.6 | P10: 11357.8 | Q10: 13401.8 | R10: 14114.8 | S10: 18553.9 | T10: 21833.2 | U10: 22470.9 | V10: 22371.7 | W10: 22986.5 | X10: 23974.1 | Y10: 26461.3 | Z10: 28943.2 | AA10: 30116.1 | AC10: =INTERCEPT(M10:AA10,$M$7:$AA$7) -> -3399385.7 | AD10: =SLOPE(M10:AA10,$M$7:$AA$7) -> 1699.6936 | AE10: =RSQ(M10:AA10,$M$7:$AA$7) -> 0.97185619
A11: ISIC 05 | B11: D05T06: Mining and quarrying, energy producing products | D11: 22832.6 | E11: 26011.3 | F11: 25010.7 | G11: 11090.8 | H11: 16637.1 | I11: 18013.5 | J11: 17480.3 | K11: 21363.1 | L11: 25680.6 | M11: 28006 | N11: 31143.8 | O11: 39627.2 | P11: 46987.6 | Q11: 55453.4 | R11: 58389.6 | S11: 76742.9 | T11: 94749.2 | U11: 92616.4 | V11: 92534.8 | W11: 88476.9 | X11: 84666.1 | Y11: 90166.4 | Z11: 97743.9 | AA11: 100140.2 | AC11: =INTERCEPT(M11:AA11,$M$7:$AA$7) -> -10638070 | AD11: =SLOPE(M11:AA11,$M$7:$AA$7) -> 5325.6586 | AE11: =RSQ(M11:AA11,$M$7:$AA$7) -> 0.85025292
A12: ISIC 07T08 | B12: D07T08: Mining and quarrying, non-energy producing products | D12: 9601 | E12: 10869 | F12: 10420.2 | G12: 4557 | H12: 6788 | I12: 7545.8 | J12: 6936.4 | K12: 7835.3 | L12: 9418.8 | M12: 10271.7 | N12: 12560.1 | O12: 15919 | P12: 18625.3 | Q12: 21877.2 | R12: 22792.9 | S12: 30658.7 | T12: 35808.1 | U12: 36632.7 | V12: 36625.7 | W12: 35752 | X12: 32544.4 | Y12: 34801 | Z12: 37808.5 | AA12: 38835.3 | AC12: =INTERCEPT(M12:AA12,$M$7:$AA$7) -> -4114458.6 | AD12: =SLOPE(M12:AA12,$M$7:$AA$7) -> 2059.95 | AE12: =RSQ(M12:AA12,$M$7:$AA$7) -> 0.84353377
A13: ISIC 09 | B13: D09: Mining support service activities | D13: 1352.5 | E13: 1528.2 | F13: 1470.8 | G13: 653.1 | H13: 978.7 | I13: 1054.6 | J13: 1042.9 | K13: 1276.5 | L13: 1538.5 | M13: 1674.4 | N13: 1860.9 | O13: 2328.3 | P13: 2761.2 | Q13: 3244.8 | R13: 3436.6 | S13: 4531 | T13: 5763.8 | U13: 5936.4 | V13: 5844.9 | W13: 5680.7 | X13: 5435.9 | Y13: 5783.8 | Z13: 6263.7 | AA13: 6417.9 | AC13: =INTERCEPT(M13:AA13,$M$7:$AA$7) -> -721846.43 | AD13: =SLOPE(M13:AA13,$M$7:$AA$7) -> 361.16893 | AE13: =RSQ(M13:AA13,$M$7:$AA$7) -> 0.87897435
A14: ISIC 10T12 | B14: D10T12: Food products, beverages and tobacco | D14: 36432.7 | E14: 40567.5 | F14: 39051.5 | G14: 17318.7 | H14: 25977.6 | I14: 27973.8 | J14: 26860.4 | K14: 32906.2 | L14: 39722.4 | M14: 43227.5 | N14: 47972.5 | O14: 63456.6 | P14: 75364.5 | Q14: 88685.6 | R14: 94414.7 | S14: 124268.1 | T14: 143982.2 | U14: 148772.6 | V14: 146988.7 | W14: 143476.8 | X14: 137297.2 | Y14: 144220.8 | Z14: 156370.9 | AA14: 160201.6 | AC14: =INTERCEPT(M14:AA14,$M$7:$AA$7) -> -17228765 | AD14: =SLOPE(M14:AA14,$M$7:$AA$7) -> 8624.2393 | AE14: =RSQ(M14:AA14,$M$7:$AA$7) -> 0.86803975
A15: ISIC 13T15 | B15: D13T15: Textiles, textile products, leather and footwear | D15: 11991.1 | E15: 14775.2 | F15: 14199.3 | G15: 7277.8 | H15: 9561.6 | I15: 10900.8 | J15: 10994.6 | K15: 12443.6 | L15: 14588 | M15: 15901.2 | N15: 17604.8 | O15: 21337.4 | P15: 24544.7 | Q15: 28529.1 | R15: 30423.5 | S15: 39542.2 | T15: 45611.3 | U15: 46754.9 | V15: 46294 | W15: 45475.9 | X15: 44187.9 | Y15: 47086 | Z15: 50976 | AA15: 52239.5 | AC15: =INTERCEPT(M15:AA15,$M$7:$AA$7) -> -5361753.6 | AD15: =SLOPE(M15:AA15,$M$7:$AA$7) -> 2684.6614 | AE15: =RSQ(M15:AA15,$M$7:$AA$7) -> 0.89628504
A16: ISIC 16 | B16: D16: Wood and products of wood and cork | D16: 3625.6 | E16: 4038.1 | F16: 3887.1 | G16: 1723.8 | H16: 2585.7 | I16: 2784.7 | J16: 2676.9 | K16: 3279.4 | L16: 3958.6 | M16: 4308.1 | N16: 4780.9 | O16: 6273 | P16: 7450.3 | Q16: 8767.6 | R16: 9334 | S16: 12284.4 | T16: 14287.7 | U16: 14762 | V16: 14583.7 | W16: 14233.7 | X16: 13620.7 | Y16: 14311.9 | Z16: 15517.3 | AA16: 15897.5 | AC16: =INTERCEPT(M16:AA16,$M$7:$AA$7) -> -1710885.4 | AD16: =SLOPE(M16:AA16,$M$7:$AA$7) -> 856.41286 | AE16: =RSQ(M16:AA16,$M$7:$AA$7) -> 0.86890222
A17: ISIC 17T18 | B17: D17T18: Paper products and printing | D17: 5743 | E17: 6391.9 | F17: 6153 | G17: 2728.6 | H17: 4093 | I17: 4407.6 | J17: 4240.3 | K17: 5194.7 | L17: 6270.9 | M17: 6824.1 | N17: 7573.2 | O17: 9926.6 | P17: 11789.3 | Q17: 13872.7 | R17: 14768.8 | S17: 19439.5 | T17: 23023.6 | U17: 23789.1 | V17: 23503.4 | W17: 22940.6 | X17: 21952.5 | Y17: 23065.1 | Z17: 25005.9 | AA17: 25618.8 | AC17: =INTERCEPT(M17:AA17,$M$7:$AA$7) -> -2793795.9 | AD17: =SLOPE(M17:AA17,$M$7:$AA$7) -> 1398.3104 | AE17: =RSQ(M17:AA17,$M$7:$AA$7) -> 0.87159065
A18: ISIC 19 | B18: D19: Coke and refined petroleum products | D18: 19822.4 | E18: 21651.6 | F18: 20664.1 | G18: 9161.2 | H18: 13744.6 | I18: 15410.8 | J18: 15573.4 | K18: 18758.4 | L18: 21974.4 | M18: 24293.1 | N18: 27343.6 | O18: 36111.7 | P18: 42434.4 | Q18: 50934.7 | R18: 50299.7 | S18: 65477.8 | T18: 82684 | U18: 83146.5 | V18: 79675.9 | W18: 74951.4 | X18: 71722.4 | Y18: 82949.1 | Z18: 89846.8 | AA18: 92056.9 | AC18: =INTERCEPT(M18:AA18,$M$7:$AA$7) -> -9626379.6 | AD18: =SLOPE(M18:AA18,$M$7:$AA$7) -> 4818.4857 | AE18: =RSQ(M18:AA18,$M$7:$AA$7) -> 0.86951253
A19: ISIC 20 | B19: D20: Chemical and chemical products | D19: 9080.7 | E19: 10113.8 | F19: 9735.6 | G19: 4317.4 | H19: 6476.2 | I19: 6974.7 | J19: 6704.7 | K19: 8213.7 | L19: 9914.9 | M19: 10790.1 | N19: 11974.4 | O19: 15711.5 | P19: 18660.2 | Q19: 21959.5 | R19: 23378.3 | S19: 30768 | T19: 35785.3 | U19: 36973.2 | V19: 36526.9 | W19: 35650.1 | X19: 34114.7 | Y19: 35846.1 | Z19: 38865 | AA19: 39817.2 | AC19: =INTERCEPT(M19:AA19,$M$7:$AA$7) -> -4285129.5 | AD19: =SLOPE(M19:AA19,$M$7:$AA$7) -> 2144.9946 | AE19: =RSQ(M19:AA19,$M$7:$AA$7) -> 0.86890142
A20: ISIC 21 | B20: D21: Pharmaceuticals, medicinal chemical and botanical products | D20: 1445.2 | E20: 1530.7 | F20: 1474.9 | G20: 655 | H20: 981.5 | I20: 1052 | J20: 788.6 | K20: 966.5 | L20: 1169.4 | M20: 1270 | N20: 1409.1 | O20: 2454.1 | P20: 2913.3 | Q20: 3423.4 | R20: 3643.7 | S20: 4806.8 | T20: 4107.6 | U20: 4247.1 | V20: 4199.6 | W20: 4102 | X20: 3925.3 | Y20: 4120.8 | Z20: 4463.4 | AA20: 4573.2 | AC20: =INTERCEPT(M20:AA20,$M$7:$AA$7) -> -401621.97 | AD20: =SLOPE(M20:AA20,$M$7:$AA$7) -> 201.49143 | AE20: =RSQ(M20:AA20,$M$7:$AA$7) -> 0.67452398
A21: ISIC 22 | B21: D22: Rubber and plastics products | D21: 6713.8 | E21: 7477.7 | F21: 7198 | G21: 3192.1 | H21: 4788.2 | I21: 5156.8 | J21: 4957.1 | K21: 6072.8 | L21: 7330.5 | M21: 7977.6 | N21: 8853.2 | O21: 11616.3 | P21: 13796.4 | Q21: 16235.7 | R21: 17284.7 | S21: 22748.3 | T21: 26457.8 | U21: 27336.1 | V21: 27006.1 | W21: 26357.9 | X21: 25222.7 | Y21: 26502.8 | Z21: 28734.8 | AA21: 29438.8 | AC21: =INTERCEPT(M21:AA21,$M$7:$AA$7) -> -3168213.4 | AD21: =SLOPE(M21:AA21,$M$7:$AA$7) -> 1585.9032 | AE21: =RSQ(M21:AA21,$M$7:$AA$7) -> 0.86890196
A22: ISIC 23 | B22: D23: Other non-metallic mineral products | D22: 3746.5 | E22: 4172.7 | F22: 4016.7 | G22: 1781.3 | H22: 2671.9 | I22: 2877.6 | J22: 2766.2 | K22: 3388.8 | L22: 4090.6 | M22: 4451.7 | N22: 4940.3 | O22: 6482.2 | P22: 7698.7 | Q22: 9060 | R22: 9645.3 | S22: 12694.2 | T22: 14764.2 | U22: 15254.3 | V22: 15070.1 | W22: 14708.4 | X22: 14074.9 | Y22: 14789.3 | Z22: 16034.8 | AA22: 16427.7 | AC22: =INTERCEPT(M22:AA22,$M$7:$AA$7) -> -1767953.6 | AD22: =SLOPE(M22:AA22,$M$7:$AA$7) -> 884.97929 | AE22: =RSQ(M22:AA22,$M$7:$AA$7) -> 0.86890126
... A34: ISIC 45T47 | B34: D45T47: Wholesale and retail trade; repair of motor vehicles | D34: 44544 | E34: 50728.1 | F34: 48778.7 | G34: 21631.8 | H34: 32448 | I34: 35125.5 | J34: 34112.6 | K34: 41692.4 | L34: 50124 | M34: 54658 | N34: 60780.4 | O34: 77282.5 | P34: 91637.8 | Q34: 108129.2 | R34: 113881.9 | S34: 149697.2 | T34: 176155.5 | U34: 181301.1 | V34: 178355.6 | W34: 173211 | X34: 165750.4 | Y34: 176511.2 | Z34: 191336.5 | AA34: 196028.3 | AC34: =INTERCEPT(M34:AA34,$M$7:$AA$7) -> -20841685 | AD34: =SLOPE(M34:AA34,$M$7:$AA$7) -> 10433.283 | AE34: =RSQ(M34:AA34,$M$7:$AA$7) -> 0.87134133
A35: ISIC 49T53 | B35: COMBINED: 4953 | D35: =SUM(D36:D40) -> 18014 | E35: =SUM(E36:E40) -> 20515 | F35: =SUM(F36:F40) -> 19726.5 | G35: =SUM(G36:G40) -> 8748.1 | H35: =SUM(H36:H40) -> 13122.2 | I35: =SUM(I36:I40) -> 14205 | J35: =SUM(J36:J40) -> 13795.5 | K35: =SUM(K36:K40) -> 16860.9 | ... AA35: =SUM(AA36:AA40) -> 93728.7 | AC35: =INTERCEPT(M35:AA35,$M$7:$AA$7) -> -10294557 | AD35: =SLOPE(M35:AA35,$M$7:$AA$7) -> 5148.7082 | AE35: =RSQ(M35:AA35,$M$7:$AA$7) -> 0.95071072
B36: D49: Land transport and transport via pipelines | D36: 8988.8 | E36: 10239.8 | F36: 9846.2 | G36: 4366.5 | H36: 6549.7 | I36: 7090.5 | J36: 6883.8 | K36: 8413.3 | L36: 10114.6 | M36: 11029.8 | N36: 12265.2 | O36: 15597 | P36: 18494.1 | Q36: 21824.5 | R36: 22982.6 | S36: 30208.3 | T36: 35291.5 | U36: 36321.6 | V36: 35730.5 | W36: 34699.1 | X36: 33204.5 | Y36: 35361.1 | Z36: 38332.3 | AA36: 39272.1 | AC36: =INTERCEPT(M36:AA36,$M$7:$AA$7) -> -4151920.9 | AD36: =SLOPE(M36:AA36,$M$7:$AA$7) -> 2078.5489 | AE36: =RSQ(M36:AA36,$M$7:$AA$7) -> 0.87024344
B37: D50: Water transport | D37: 2751 | E37: 3133.8 | F37: 3013.4 | G37: 1336.3 | H37: 2004.5 | I37: 2170 | J37: 2106.8 | K37: 2574.9 | L37: 3095.5 | M37: 3375.6 | N37: 3753.7 | O37: 4773.4 | P37: 5660 | Q37: 6679.3 | R37: 7033.7 | S37: 9245.1 | T37: 10800.8 | U37: 11116 | V37: 10935.2 | W37: 10619.5 | X37: 10162.1 | Y37: 10822.1 | Z37: 11731.4 | AA37: 12019 | AC37: =INTERCEPT(M37:AA37,$M$7:$AA$7) -> -1270675.6 | AD37: =SLOPE(M37:AA37,$M$7:$AA$7) -> 636.13 | AE37: =RSQ(M37:AA37,$M$7:$AA$7) -> 0.87024326
B38: D51: Air transport | D38: 3689.2 | E38: 4202.6 | F38: 4041 | G38: 1792.1 | H38: 2688.1 | I38: 2910.1 | J38: 2825.2 | K38: 3453 | L38: 4151.2 | M38: 4526.8 | N38: 5033.8 | O38: 6401.3 | P38: 7590.3 | Q38: 8957.2 | R38: 9432.5 | S38: 12398.1 | T38: 14484.3 | U38: 14907 | V38: 14664.5 | W38: 16120.7 | X38: 19118.3 | Y38: 23951.6 | Z38: 29776.2 | AA38: 30571.1 | AC38: =INTERCEPT(M38:AA38,$M$7:$AA$7) -> -3570016.8 | AD38: =SLOPE(M38:AA38,$M$7:$AA$7) -> 1782.4693 | AE38: =RSQ(M38:AA38,$M$7:$AA$7) -> 0.91870327
B39: D52: Warehousing and support activities for transportation | D39: 2176.8 | E39: 2479.8 | F39: 2384.4 | G39: 1057.4 | H39: 1586.2 | I39: 1717.1 | J39: 1667.1 | K39: 2037.5 | L39: 2449.4 | M39: 2671.1 | N39: 2970.3 | O39: 3777.1 | P39: 4478.7 | Q39: 5285.2 | R39: 5565.7 | S39: 7315.6 | T39: 8546.5 | U39: 8796 | V39: 8652.9 | W39: 8403.1 | X39: 8041.1 | Y39: 8563.4 | Z39: 9282.9 | AA39: 9510.5 | AC39: =INTERCEPT(M39:AA39,$M$7:$AA$7) -> -1005467.7 | AD39: =SLOPE(M39:AA39,$M$7:$AA$7) -> 503.36071 | AE39: =RSQ(M39:AA39,$M$7:$AA$7) -> 0.87024147
B40: D53: Postal and courier activities | D40: 408.2 | E40: 459 | F40: 441.5 | G40: 195.8 | H40: 293.7 | I40: 317.3 | J40: 312.6 | K40: 382.2 | L40: 459.9 | M40: 500.9 | N40: 557.2 | O40: 704.9 | P40: 836 | Q40: 982.3 | R40: 1040.5 | S40: 1371.9 | T40: 2115.9 | U40: 2179.2 | V40: 2145.7 | W40: 2085.4 | X40: 1995.6 | Y40: 2123.2 | Z40: 2299.4 | AA40: 2356 | AC40: =INTERCEPT(M40:AA40,$M$7:$AA$7) -> -296475.82 | AD40: =SLOPE(M40:AA40,$M$7:$AA$7) -> 148.19929 | AE40: =RSQ(M40:AA40,$M$7:$AA$7) -> 0.87605351
A41: ISIC 55T56 | B41: D55T56: Accommodation and food service activities | D41: 14355.2 | E41: 16348.2 | F41: 15719.9 | G41: 6971.3 | H41: 10457 | I41: 11319.9 | J41: 10993.5 | K41: 13436.2 | L41: 16153.5 | M41: 17614.7 | N41: 19587.7 | O41: 24905.8 | P41: 29532.1 | Q41: 34846.8 | R41: 36700.8 | S41: 48242.9 | T41: 56769.7 | U41: 58427.9 | V41: 57478.7 | W41: 55820.8 | X41: 53416.4 | Y41: 56884.3 | Z41: 61662.1 | AA41: 63174.1 | AC41: =INTERCEPT(M41:AA41,$M$7:$AA$7) -> -6716657.8 | AD41: =SLOPE(M41:AA41,$M$7:$AA$7) -> 3362.3382 | AE41: =RSQ(M41:AA41,$M$7:$AA$7) -> 0.87134171
A42: ISIC 58T60 | B42: D58T60: Publishing, audiovisual and broadcasting activities | D42: 3756 | E42: 4461.6 | F42: 4288.5 | G42: 1901.6 | H42: 2852.6 | I42: 3093.6 | J42: 2719.5 | K42: 3320.1 | L42: 3983.8 | M42: 4247 | N42: 4840.1 | O42: 5778.5 | P42: 6854.2 | Q42: 8096.6 | R42: 8528.9 | S42: 11191.4 | T42: 12738.5 | U42: 13089.1 | V42: 12855.8 | W42: 12477.4 | X42: 11940.1 | Y42: 12772.5 | Z42: 13839.9 | AA42: 14179.9 | AC42: =INTERCEPT(M42:AA42,$M$7:$AA$7) -> -1444418.1 | AD42: =SLOPE(M42:AA42,$M$7:$AA$7) -> 723.345 | AE42: =RSQ(M42:AA42,$M$7:$AA$7) -> 0.8675895
A43: ISIC 61 | B43: D61: Telecommunications | D43: 7189.8 | E43: 8429.5 | F43: 8106 | G43: 3676 | H43: 5391.9 | I43: 5835.9 | J43: 6074.6 | K43: 7928.7 | L43: 9142.6 | M43: 11030.7 | N43: 11236.1 | O43: 14687.7 | P43: 17414 | Q43: 20540.4 | R43: 21631.9 | S43: 28451.7 | T43: 32086.2 | U43: 33052.3 | V43: 32541.7 | W43: 31609.1 | X43: 30247.5 | Y43: 32125.7 | Z43: 34841 | AA43: 35693.6 | AC43: =INTERCEPT(M43:AA43,$M$7:$AA$7) -> -3654461 | AD43: =SLOPE(M43:AA43,$M$7:$AA$7) -> 1830.0714 | AE43: =RSQ(M43:AA43,$M$7:$AA$7) -> 0.86283708
A44: ISIC 62T63 | B44: D62T63: IT and other information services | D44: 2384.3 | E44: 2289.6 | F44: 2202.8 | G44: 978.2 | H44: 1465.8 | I44: 1582 | J44: 1414.3 | K44: 1729.3 | L44: 2080.4 | M44: 2213.3 | N44: 2521 | O44: 2661 | P44: 3155 | Q44: 3721.4 | R44: 3919.1 | S44: 5154.7 | T44: 7890.9 | U44: 8114.1 | V44: 7976.6 | W44: 7748 | X44: 7414.2 | Y44: 7923.9 | Z44: 8577.7 | AA44: 8789.2 | AC44: =INTERCEPT(M44:AA44,$M$7:$AA$7) -> -1063403.9 | AD44: =SLOPE(M44:AA44,$M$7:$AA$7) -> 531.70357 | AE44: =RSQ(M44:AA44,$M$7:$AA$7) -> 0.8724947
A45: ISIC 64T66 | B45: D64T66: Financial and insurance activities | D45: 10787.7 | E45: 12285.3 | F45: 11813.2 | G45: 5238.8 | H45: 7858.3 | I45: 8506.7 | J45: 8261.4 | K45: 10097.1 | L45: 12139 | M45: 13237.1 | N45: 14719.8 | O45: 18716.3 | P45: 22192.9 | Q45: 26186.8 | R45: 27580 | S45: 36253.7 | T45: 42661.4 | U45: 43907.5 | V45: 43194.2 | W45: 41948.3 | X45: 40141.5 | Y45: 44824.9 | Z45: 48982.1 | AA45: 48486.4 | AC45: =INTERCEPT(M45:AA45,$M$7:$AA$7) -> -5286494.4 | AD45: =SLOPE(M45:AA45,$M$7:$AA$7) -> 2645.7964 | AE45: =RSQ(M45:AA45,$M$7:$AA$7) -> 0.8939242
A46: ISIC 68 | B46: D68: Real estate activities | D46: 8410.1 | E46: 9798.9 | F46: 9271.8 | G46: 4062.8 | H46: 5995.1 | I46: 6425.3 | J46: 6238.4 | K46: 8040.8 | L46: 9343.8 | M46: 9987.7 | N46: 10950.2 | O46: 13745 | P46: 16082.2 | Q46: 18976.4 | R46: 19986 | S46: 26271.5 | T46: 30914.9 | U46: 31817.9 | V46: 31301 | W46: 30398.1 | X46: 29088.8 | Y46: 30977.3 | Z46: 33579.1 | AA46: 34402.5 | AC46: =INTERCEPT(M46:AA46,$M$7:$AA$7) -> -3618981.8 | AD46: =SLOPE(M46:AA46,$M$7:$AA$7) -> 1811.8086 | AE46: =RSQ(M46:AA46,$M$7:$AA$7) -> 0.87210105
A47: ISIC 69T82 | B47: COMBINED: 69T82 | D47: =SUM(D48:D49) -> 5443.1 | E47: =SUM(E48:E49) -> 6195 | F47: =SUM(F48:F49) -> 5957 | G47: =SUM(G48:G49) -> 2641.8 | H47: =SUM(H48:H49) -> 3962.7 | I47: =SUM(I48:I49) -> 4289.6 | J47: =SUM(J48:J49) -> 4166 | K47: =SUM(K48:K49) -> 5091.6 | ... AA47: =SUM(AA48:AA49) -> 24467.5 | AC47: =INTERCEPT(M47:AA47,$M$7:$AA$7) -> -2615636.8 | AD47: =SLOPE(M47:AA47,$M$7:$AA$7) -> 1309.2471 | AE47: =RSQ(M47:AA47,$M$7:$AA$7) -> 0.87109964
B48: D69T75: Professional, scientific and technical activities | D48: 983 | E48: 1781.7 | F48: 1713.3 | G48: 759.8 | H48: 1139.7 | I48: 1233.7 | J48: 1193.9 | K48: 1459.4 | L48: 1755 | M48: 1913.5 | N48: 2127.5 | O48: 2169.1 | P48: 2574.2 | Q48: 3090.3 | R48: 3307.8 | S48: 4256.9 | T48: 4180.4 | U48: 4571.7 | V48: 4302.5 | W48: 4015.2 | X48: 3808.2 | Y48: 4053.5 | Z48: 4342 | AA48: 4483.7 | AC48: =INTERCEPT(M48:AA48,$M$7:$AA$7) -> -360698.1 | AD48: =SLOPE(M48:AA48,$M$7:$AA$7) -> 181.12607 | AE48: =RSQ(M48:AA48,$M$7:$AA$7) -> 0.74238842
B49: D77T82: Administrative and support services | D49: 4460.1 | E49: 4413.3 | F49: 4243.7 | G49: 1882 | H49: 2823 | I49: 3055.9 | J49: 2972.1 | K49: 3632.2 | L49: 4367.6 | M49: 4761.5 | N49: 5295.2 | O49: 7268.9 | P49: 8619.1 | Q49: 10170.3 | R49: 10711.3 | S49: 14080 | T49: 17625.3 | U49: 18140.1 | V49: 17845.4 | W49: 17330.7 | X49: 16618 | Y49: 17824.8 | Z49: 19417.4 | AA49: 19983.8 | AC49: =INTERCEPT(M49:AA49,$M$7:$AA$7) -> -2254938.7 | AD49: =SLOPE(M49:AA49,$M$7:$AA$7) -> 1128.1211 | AE49: =RSQ(M49:AA49,$M$7:$AA$7) -> 0.88546445
A50: ISIC 84 | B50: D84: Public administration and defence; compulsory social security | D50: 13646.2 | E50: 15540.7 | F50: 14943.5 | G50: 6626.9 | H50: 9940.5 | I50: 10760.8 | J50: 10450.5 | K50: 12772.6 | L50: 15355.6 | M50: 16744.6 | N50: 18620.2 | O50: 23675.7 | P50: 28073.5 | Q50: 33125.6 | R50: 34888 | S50: 45860.1 | T50: 53965.6 | U50: 55542 | V50: 54639.6 | W50: 53063.6 | X50: 50778 | Y50: 54074.6 | Z50: 58616.4 | AA50: 60053.7 | AC50: =INTERCEPT(M50:AA50,$M$7:$AA$7) -> -6384895.3 | AD50: =SLOPE(M50:AA50,$M$7:$AA$7) -> 3196.2589 | AE50: =RSQ(M50:AA50,$M$7:$AA$7) -> 0.87134158
A51: ISIC 85 | B51: D85: Education | D51: 10147.7 | E51: 11556.5 | F51: 11112.4 | G51: 4928 | H51: 7392.1 | I51: 8002 | J51: 7771.3 | K51: 9498.1 | L51: 11418.9 | M51: 12451.8 | N51: 13846.6 | O51: 17605.9 | P51: 20876.3 | Q51: 24633.2 | R51: 25943.8 | S51: 34102.9 | T51: 40130.5 | U51: 41302.7 | V51: 40631.7 | W51: 39459.7 | X51: 37760.1 | Y51: 40211.5 | Z51: 43588.9 | AA51: 44657.8 | AC51: =INTERCEPT(M51:AA51,$M$7:$AA$7) -> -4748003.8 | AD51: =SLOPE(M51:AA51,$M$7:$AA$7) -> 2376.8361 | AE51: =RSQ(M51:AA51,$M$7:$AA$7) -> 0.87134184
A52: ISIC 86T88 | B52: D86T88: Human health and social work activities | D52: 4864.7 | E52: 5540.1 | F52: 5327.2 | G52: 2362.4 | H52: 3543.7 | I52: 3836.1 | J52: 3725.5 | K52: 4553.3 | L52: 5474.1 | M52: 5969.3 | N52: 6637.9 | O52: 8440.1 | P52: 10007.9 | Q52: 11808.9 | R52: 12437.2 | S52: 16348.6 | T52: 19238.1 | U52: 19800.1 | V52: 19478.4 | W52: 18916.5 | X52: 18101.8 | Y52: 19277 | Z52: 20896 | AA52: 21408.4 | AC52: =INTERCEPT(M52:AA52,$M$7:$AA$7) -> -2276133.3 | AD52: =SLOPE(M52:AA52,$M$7:$AA$7) -> 1139.4254 | AE52: =RSQ(M52:AA52,$M$7:$AA$7) -> 0.87134075
...

Sheet isic groups
A1: ISIC used | B1: ISIC Group | E1: bifubc sector used | F1: bifubc sector grouped
A2: ISIC 01T03 | E2: agriculture and forestry 01T03
A3: ISIC 239 | B3: ISIC 231 | E3: cement and other nonmetallic minerals 239 | F3: glass and glass products 231
A4: ISIC 20 | E4: chemicals 20
A5: ISIC 05 | E5: coal mining 05
A6: ISIC 41T43 | E6: construction 41T43
A7: ISIC 352T353 | E7: energy pipelines and gas processing 352T353
A8: ISIC 10T12 | E8: food beverage and tobacco 10T12
A9: ISIC 241 | E9: iron and steel 241
A10: ISIC 25 | B10: ISIC 26 | C10: ISIC 27 | D10: ISIC 28 | E10: metal products except machinery and vehicles 25 | F10: computers and electronics 26 | G10: appliances and electrical equipment 27 | H10: other machinery 28
A11: ISIC 06 | E11: oil and gas extraction 06
A12: ISIC 31T33 | B12: ISIC 22 | E12: other manufacturing 31T33 | F12: rubber and plastic products 22
A13: ISIC 242 | E13: other metals 242
A14: ISIC 07T08 | E14: other mining and quarrying 07T08
A15: ISIC 17T18 | E15: pulp paper and printing 17T18
A16: ISIC 19 | E16: refined petroleum and coke 19
A17: ISIC 29 | B17: ISIC 30 | E17: road vehicles 29 | F17: nonroad vehicles 30
A18: ISIC 13T15 | E18: textiles apparel and leather 13T15
A19: ISIC 16 | E19: wood products 16

Sheet calcs
A1: Preconsolidation
A2: original | B2: consolidated | C2: Intercept | D2: Slope | E2: 2018 | F2: 2020 | G2: 2021 | H2: 2022 | I2: 2023 | J2: 2024 | K2: 2025 | L2: 2026 | M2: 2027 | N2: 2028 | O2: 2029 | P2: 2030 | Q2: 2031 | R2: 2032 | S2: 2033 | T2: 2034 | U2: 2035 | V2: 2036 | W2: 2037 | X2: 2038 | Y2: 2039 | Z2: 2040 | AA2: 2041 | AB2: 2042 | AC2: 2043 | AD2: 2044 | AE2: 2045 | AF2: 2046 | AG2: 2047 | AH2: 2048 | AI2: 2049 | AJ2: 2050 | AL2: TOTAL
A3: ISIC 01T03 | B3: ISIC 01T03 | C3: {=INDEX('OECD 2018'!AC:AC,MATCH($A3,'OECD 2018'!$A:$A,0))} -> -15047330 | D3: {=INDEX('OECD 2018'!AD:AD,MATCH($A3,'OECD 2018'!$A:$A,0))} -> 7533.3021 | E3: =SUMIFS('OECD 2018'!$AA$9:$AA$65,'OECD 2018'!$A$9:$A$65,calcs!A3) -> 142726.1 | F3: =F$2*$D3+$C3 -> 169940.38 | G3: =G$2*$D3+$C3 -> 177473.68 | H3: =H$2*$D3+$C3 -> 185006.98 | I3: =I$2*$D3+$C3 -> 192540.29 | J3: =J$2*$D3+$C3 -> 200073.59 | K3: =K$2*$D3+$C3 -> 207606.89 | L3: =L$2*$D3+$C3 -> 215140.19 | M3: =M$2*$D3+$C3 -> 222673.49 | ... AJ3: =AJ$2*$D3+$C3 -> 395939.44 | AL3: =(AJ3-E3)/E3 -> 1.7741208
A4: ISIC 05 | B4: ISIC 05 | C4: {=INDEX('OECD 2018'!AC:AC,MATCH($A4,'OECD 2018'!$A:$A,0))} -> -10638070 | D4: {=INDEX('OECD 2018'!AD:AD,MATCH($A4,'OECD 2018'!$A:$A,0))} -> 5325.6586 | E4: =SUMIFS('OECD 2018'!$AA$9:$AA$65,'OECD 2018'!$A$9:$A$65,calcs!A4) -> 100140.2 | F4: =F$2*$D4+$C4 -> 119760.55 | G4: =G$2*$D4+$C4 -> 125086.21 | H4: =H$2*$D4+$C4 -> 130411.87 | I4: =I$2*$D4+$C4 -> 135737.53 | J4: =J$2*$D4+$C4 -> 141063.19 | K4: =K$2*$D4+$C4 -> 146388.85 | L4: =L$2*$D4+$C4 -> 151714.51 | M4: =M$2*$D4+$C4 -> 157040.16 | ... AJ4: =AJ$2*$D4+$C4 -> 279530.31 | AL4: =(AJ4-E4)/E4 -> 1.7913896
A5: ISIC 07T08 | B5: ISIC 07T08 | C5: {=INDEX('OECD 2018'!AC:AC,MATCH($A5,'OECD 2018'!$A:$A,0))} -> -4114458.6 | D5: {=INDEX('OECD 2018'!AD:AD,MATCH($A5,'OECD 2018'!$A:$A,0))} -> 2059.95 | E5: =SUMIFS('OECD 2018'!$AA$9:$AA$65,'OECD 2018'!$A$9:$A$65,calcs!A5) -> 38835.3 | F5: =F$2*$D5+$C5 -> 46640.39 | G5: =G$2*$D5+$C5 -> 48700.34 | H5: =H$2*$D5+$C5 -> 50760.29 | I5: =I$2*$D5+$C5 -> 52820.24 | J5: =J$2*$D5+$C5 -> 54880.19 | K5: =K$2*$D5+$C5 -> 56940.14 | L5: =L$2*$D5+$C5 -> 59000.09 | M5: =M$2*$D5+$C5 -> 61060.04 | ... AJ5: =AJ$2*$D5+$C5 -> 108438.89 | AL5: =(AJ5-E5)/E5 -> 1.7922764
A6: ISIC 09 | B6: ISIC 09 | C6: {=INDEX('OECD 2018'!AC:AC,MATCH($A6,'OECD 2018'!$A:$A,0))} -> -721846.43 | D6: {=INDEX('OECD 2018'!AD:AD,MATCH($A6,'OECD 2018'!$A:$A,0))} -> 361.16893 | E6: =SUMIFS('OECD 2018'!$AA$9:$AA$65,'OECD 2018'!$A$9:$A$65,calcs!A6) -> 6417.9 | F6: =F$2*$D6+$C6 -> 7714.807 | G6: =G$2*$D6+$C6 -> 8075.976 | H6: =H$2*$D6+$C6 -> 8437.1449 | I6: =I$2*$D6+$C6 -> 8798.3138 | J6: =J$2*$D6+$C6 -> 9159.4827 | K6: =K$2*$D6+$C6 -> 9520.6517 | L6: =L$2*$D6+$C6 -> 9881.8206 | M6: =M$2*$D6+$C6 -> 10242.99 | ... AJ6: =AJ$2*$D6+$C6 -> 18549.875 | AL6: =(AJ6-E6)/E6 -> 1.890334
A7: ISIC 10T12 | B7: ISIC 10T12 | C7: {=INDEX('OECD 2018'!AC:AC,MATCH($A7,'OECD 2018'!$A:$A,0))} -> -17228765 | D7: {=INDEX('OECD 2018'!AD:AD,MATCH($A7,'OECD 2018'!$A:$A,0))} -> 8624.2393 | E7: =SUMIFS('OECD 2018'!$AA$9:$AA$65,'OECD 2018'!$A$9:$A$65,calcs!A7) -> 160201.6 | F7: =F$2*$D7+$C7 -> 192198.17 | G7: =G$2*$D7+$C7 -> 200822.41 | H7: =H$2*$D7+$C7 -> 209446.65 | I7: =I$2*$D7+$C7 -> 218070.89 | J7: =J$2*$D7+$C7 -> 226695.13 | K7: =K$2*$D7+$C7 -> 235319.37 | L7: =L$2*$D7+$C7 -> 243943.61 | M7: =M$2*$D7+$C7 -> 252567.85 | ... AJ7: =AJ$2*$D7+$C7 -> 450925.35 | AL7: =(AJ7-E7)/E7 -> 1.8147369
A8: ISIC 13T15 | B8: ISIC 13T15 | C8: {=INDEX('OECD 2018'!AC:AC,MATCH($A8,'OECD 2018'!$A:$A,0))} -> -5361753.6 | D8: {=INDEX('OECD 2018'!AD:AD,MATCH($A8,'OECD 2018'!$A:$A,0))} -> 2684.6614 | E8: =SUMIFS('OECD 2018'!$AA$9:$AA$65,'OECD 2018'!$A$9:$A$65,calcs!A8) -> 52239.5 | F8: =F$2*$D8+$C8 -> 61262.513 | G8: =G$2*$D8+$C8 -> 63947.174 | H8: =H$2*$D8+$C8 -> 66631.836 | I8: =I$2*$D8+$C8 -> 69316.497 | J8: =J$2*$D8+$C8 -> 72001.159 | K8: =K$2*$D8+$C8 -> 74685.82 | L8: =L$2*$D8+$C8 -> 77370.481 | M8: =M$2*$D8+$C8 -> 80055.143 | ... AJ8: =AJ$2*$D8+$C8 -> 141802.36 | AL8: =(AJ8-E8)/E8 -> 1.7144662
A9: ISIC 16 | B9: ISIC 16 | C9: {=INDEX('OECD 2018'!AC:AC,MATCH($A9,'OECD 2018'!$A:$A,0))} -> -1710885.4 | D9: {=INDEX('OECD 2018'!AD:AD,MATCH($A9,'OECD 2018'!$A:$A,0))} -> 856.41286 | E9: =SUMIFS('OECD 2018'!$AA$9:$AA$65,'OECD 2018'!$A$9:$A$65,calcs!A9) -> 15897.5 | F9: =F$2*$D9+$C9 -> 19068.569 | G9: =G$2*$D9+$C9 -> 19924.982 | H9: =H$2*$D9+$C9 -> 20781.395 | I9: =I$2*$D9+$C9 -> 21637.808 | J9: =J$2*$D9+$C9 -> 22494.22 | K9: =K$2*$D9+$C9 -> 23350.633 | L9: =L$2*$D9+$C9 -> 24207.046 | M9: =M$2*$D9+$C9 -> 25063.459 | ... AJ9: =AJ$2*$D9+$C9 -> 44760.955 | AL9: =(AJ9-E9)/E9 -> 1.8155971
A10: ISIC 17T18 | B10: ISIC 17T18 | C10: {=INDEX('OECD 2018'!AC:AC,MATCH($A10,'OECD 2018'!$A:$A,0))} -> -2793795.9 | D10: {=INDEX('OECD 2018'!AD:AD,MATCH($A10,'OECD 2018'!$A:$A,0))} -> 1398.3104 | E10: =SUMIFS('OECD 2018'!$AA$9:$AA$65,'OECD 2018'!$A$9:$A$65,calcs!A10) -> 25618.8 | F10: =F$2*$D10+$C10 -> 30791.007 | G10: =G$2*$D10+$C10 -> 32189.317 | H10: =H$2*$D10+$C10 -> 33587.627 | I10: =I$2*$D10+$C10 -> 34985.938 | J10: =J$2*$D10+$C10 -> 36384.248 | K10: =K$2*$D10+$C10 -> 37782.558 | L10: =L$2*$D10+$C10 -> 39180.869 | M10: =M$2*$D10+$C10 -> 40579.179 | ... AJ10: =AJ$2*$D10+$C10 -> 72740.317 | AL10: =(AJ10-E10)/E10 -> 1.8393335
A11: ISIC 19 | B11: ISIC 19 | C11: {=INDEX('OECD 2018'!AC:AC,MATCH($A11,'OECD 2018'!$A:$A,0))} -> -9626379.6 | D11: {=INDEX('OECD 2018'!AD:AD,MATCH($A11,'OECD 2018'!$A:$A,0))} -> 4818.4857 | E11: =SUMIFS('OECD 2018'!$AA$9:$AA$65,'OECD 2018'!$A$9:$A$65,calcs!A11) -> 92056.9 | F11: =F$2*$D11+$C11 -> 106961.57 | G11: =G$2*$D11+$C11 -> 111780.06 | H11: =H$2*$D11+$C11 -> 116598.54 | I11: =I$2*$D11+$C11 -> 121417.03 | J11: =J$2*$D11+$C11 -> 126235.51 | K11: =K$2*$D11+$C11 -> 131054 | L11: =L$2*$D11+$C11 -> 135872.49 | M11: =M$2*$D11+$C11 -> 140690.97 | ... AJ11: =AJ$2*$D11+$C11 -> 251516.14 | AL11: =(AJ11-E11)/E11 -> 1.7321813
A12: ISIC 20 | B12: ISIC 20 | C12: {=INDEX('OECD 2018'!AC:AC,MATCH($A12,'OECD 2018'!$A:$A,0))} -> -4285129.5 | D12: {=INDEX('OECD 2018'!AD:AD,MATCH($A12,'OECD 2018'!$A:$A,0))} -> 2144.9946 | E12: =SUMIFS('OECD 2018'!$AA$9:$AA$65,'OECD 2018'!$A$9:$A$65,calcs!A12) -> 39817.2 | F12: =F$2*$D12+$C12 -> 47759.652 | G12: =G$2*$D12+$C12 -> 49904.646 | H12: =H$2*$D12+$C12 -> 52049.641 | I12: =I$2*$D12+$C12 -> 54194.636 | J12: =J$2*$D12+$C12 -> 56339.63 | K12: =K$2*$D12+$C12 -> 58484.625 | L12: =L$2*$D12+$C12 -> 60629.62 | M12: =M$2*$D12+$C12 -> 62774.614 | ... AJ12: =AJ$2*$D12+$C12 -> 112109.49 | AL12: =(AJ12-E12)/E12 -> 1.8156046
A13: ISIC 21 | B13: ISIC 21 | C13: {=INDEX('OECD 2018'!AC:AC,MATCH($A13,'OECD 2018'!$A:$A,0))} -> -401621.97 | D13: {=INDEX('OECD 2018'!AD:AD,MATCH($A13,'OECD 2018'!$A:$A,0))} -> 201.49143 | E13: =SUMIFS('OECD 2018'!$AA$9:$AA$65,'OECD 2018'!$A$9:$A$65,calcs!A13) -> 4573.2 | F13: =F$2*$D13+$C13 -> 5390.7162 | G13: =G$2*$D13+$C13 -> 5592.2076 | H13: =H$2*$D13+$C13 -> 5793.699 | I13: =I$2*$D13+$C13 -> 5995.1905 | J13: =J$2*$D13+$C13 -> 6196.6819 | K13: =K$2*$D13+$C13 -> 6398.1733 | L13: =L$2*$D13+$C13 -> 6599.6648 | M13: =M$2*$D13+$C13 -> 6801.1562 | ... AJ13: =AJ$2*$D13+$C13 -> 11435.459 | AL13: =(AJ13-E13)/E13 -> 1.5005377
A14: ISIC 22 | B14: ISIC 31T33 | C14: {=INDEX('OECD 2018'!AC:AC,MATCH($A14,'OECD 2018'!$A:$A,0))} -> -3168213.4 | D14: {=INDEX('OECD 2018'!AD:AD,MATCH($A14,'OECD 2018'!$A:$A,0))} -> 1585.9032 | E14: =SUMIFS('OECD 2018'!$AA$9:$AA$65,'OECD 2018'!$A$9:$A$65,calcs!A14) -> 29438.8 | F14: =F$2*$D14+$C14 -> 35311.076 | G14: =G$2*$D14+$C14 -> 36896.979 | H14: =H$2*$D14+$C14 -> 38482.882 | I14: =I$2*$D14+$C14 -> 40068.785 | J14: =J$2*$D14+$C14 -> 41654.688 | K14: =K$2*$D14+$C14 -> 43240.592 | L14: =L$2*$D14+$C14 -> 44826.495 | M14: =M$2*$D14+$C14 -> 46412.398 | ... AJ14: =AJ$2*$D14+$C14 -> 82888.172 | AL14: =(AJ14-E14)/E14 -> 1.8156097
... A40: ISIC 97T98 | B40: ISIC 97T98 | C40: {=INDEX('OECD 2018'!AC:AC,MATCH($A40,'OECD 2018'!$A:$A,0))} -> -342234.34 | D40: {=INDEX('OECD 2018'!AD:AD,MATCH($A40,'OECD 2018'!$A:$A,0))} -> 171.40143 | E40: =SUMIFS('OECD 2018'!$AA$9:$AA$65,'OECD 2018'!$A$9:$A$65,calcs!A40) -> 3763.2 | F40: =F$2*$D40+$C40 -> 3996.5462 | G40: =G$2*$D40+$C40 -> 4167.9476 | H40: =H$2*$D40+$C40 -> 4339.349 | I40: =I$2*$D40+$C40 -> 4510.7505 | J40: =J$2*$D40+$C40 -> 4682.1519 | K40: =K$2*$D40+$C40 -> 4853.5533 | L40: =L$2*$D40+$C40 -> 5024.9548 | M40: =M$2*$D40+$C40 -> 5196.3562 | ... AJ40: =AJ$2*$D40+$C40 -> 9138.589 | AL40: =(AJ40-E40)/E40 -> 1.4284091
A42: consolidation
A43: =SUM(F44:AJ81)=SUM(F3:AJ40) -> TRUE | F43: 2020 | G43: 2021 | H43: 2022 | I43: 2023 | J43: 2024 | K43: 2025 | L43: 2026 | M43: 2027 | N43: 2028 | O43: 2029 | P43: 2030 | Q43: 2031 | R43: 2032 | S43: 2033 | T43: 2034 | U43: 2035 | V43: 2036 | W43: 2037 | X43: 2038 | Y43: 2039 | Z43: 2040 | AA43: 2041 | AB43: 2042 | AC43: 2043 | AD43: 2044 | AE43: 2045 | AF43: 2046 | AG43: 2047 | AH43: 2048 | AI43: 2049 | AJ43: 2050 | AL43: TOTAL
A44: ISIC 01T03 | F44: =SUMIFS(F$3:F$40,$B$3:$B$40,$A44) -> 169940.38 | G44: =SUMIFS(G$3:G$40,$B$3:$B$40,$A44) -> 177473.68 | H44: =SUMIFS(H$3:H$40,$B$3:$B$40,$A44) -> 185006.98 | I44: =SUMIFS(I$3:I$40,$B$3:$B$40,$A44) -> 192540.29 | J44: =SUMIFS(J$3:J$40,$B$3:$B$40,$A44) -> 200073.59 | K44: =SUMIFS(K$3:K$40,$B$3:$B$40,$A44) -> 207606.89 | L44: =SUMIFS(L$3:L$40,$B$3:$B$40,$A44) -> 215140.19 | M44: =SUMIFS(M$3:M$40,$B$3:$B$40,$A44) -> 222673.49 | ... AJ44: =SUMIFS(AJ$3:AJ$40,$B$3:$B$40,$A44) -> 395939.44 | AL44: =(AJ44-E44)/E44 -> #DIV/0!
A45: ISIC 05 | F45: =SUMIFS(F$3:F$40,$B$3:$B$40,$A45) -> 119760.55 | G45: =SUMIFS(G$3:G$40,$B$3:$B$40,$A45) -> 125086.21 | H45: =SUMIFS(H$3:H$40,$B$3:$B$40,$A45) -> 130411.87 | I45: =SUMIFS(I$3:I$40,$B$3:$B$40,$A45) -> 135737.53 | J45: =SUMIFS(J$3:J$40,$B$3:$B$40,$A45) -> 141063.19 | K45: =SUMIFS(K$3:K$40,$B$3:$B$40,$A45) -> 146388.85 | L45: =SUMIFS(L$3:L$40,$B$3:$B$40,$A45) -> 151714.51 | M45: =SUMIFS(M$3:M$40,$B$3:$B$40,$A45) -> 157040.16 | ... AJ45: =SUMIFS(AJ$3:AJ$40,$B$3:$B$40,$A45) -> 279530.31 | AL45: =(AJ45-E45)/E45 -> #DIV/0!
A46: ISIC 07T08 | F46: =SUMIFS(F$3:F$40,$B$3:$B$40,$A46) -> 46640.39 | G46: =SUMIFS(G$3:G$40,$B$3:$B$40,$A46) -> 48700.34 | H46: =SUMIFS(H$3:H$40,$B$3:$B$40,$A46) -> 50760.29 | I46: =SUMIFS(I$3:I$40,$B$3:$B$40,$A46) -> 52820.24 | J46: =SUMIFS(J$3:J$40,$B$3:$B$40,$A46) -> 54880.19 | K46: =SUMIFS(K$3:K$40,$B$3:$B$40,$A46) -> 56940.14 | L46: =SUMIFS(L$3:L$40,$B$3:$B$40,$A46) -> 59000.09 | M46: =SUMIFS(M$3:M$40,$B$3:$B$40,$A46) -> 61060.04 | ... AJ46: =SUMIFS(AJ$3:AJ$40,$B$3:$B$40,$A46) -> 108438.89 | AL46: =(AJ46-E46)/E46 -> #DIV/0!
A47: ISIC 09 | F47: =SUMIFS(F$3:F$40,$B$3:$B$40,$A47) -> 7714.807 | G47: =SUMIFS(G$3:G$40,$B$3:$B$40,$A47) -> 8075.976 | H47: =SUMIFS(H$3:H$40,$B$3:$B$40,$A47) -> 8437.1449 | I47: =SUMIFS(I$3:I$40,$B$3:$B$40,$A47) -> 8798.3138 | J47: =SUMIFS(J$3:J$40,$B$3:$B$40,$A47) -> 9159.4827 | K47: =SUMIFS(K$3:K$40,$B$3:$B$40,$A47) -> 9520.6517 | L47: =SUMIFS(L$3:L$40,$B$3:$B$40,$A47) -> 9881.8206 | M47: =SUMIFS(M$3:M$40,$B$3:$B$40,$A47) -> 10242.99 | ... AJ47: =SUMIFS(AJ$3:AJ$40,$B$3:$B$40,$A47) -> 18549.875 | AL47: =(AJ47-E47)/E47 -> #DIV/0!
A48: ISIC 10T12 | F48: =SUMIFS(F$3:F$40,$B$3:$B$40,$A48) -> 192198.17 | G48: =SUMIFS(G$3:G$40,$B$3:$B$40,$A48) -> 200822.41 | H48: =SUMIFS(H$3:H$40,$B$3:$B$40,$A48) -> 209446.65 | I48: =SUMIFS(I$3:I$40,$B$3:$B$40,$A48) -> 218070.89 | J48: =SUMIFS(J$3:J$40,$B$3:$B$40,$A48) -> 226695.13 | K48: =SUMIFS(K$3:K$40,$B$3:$B$40,$A48) -> 235319.37 | L48: =SUMIFS(L$3:L$40,$B$3:$B$40,$A48) -> 243943.61 | M48: =SUMIFS(M$3:M$40,$B$3:$B$40,$A48) -> 252567.85 | ... AJ48: =SUMIFS(AJ$3:AJ$40,$B$3:$B$40,$A48) -> 450925.35 | AL48: =(AJ48-E48)/E48 -> #DIV/0!
A49: ISIC 13T15 | F49: =SUMIFS(F$3:F$40,$B$3:$B$40,$A49) -> 61262.513 | G49: =SUMIFS(G$3:G$40,$B$3:$B$40,$A49) -> 63947.174 | H49: =SUMIFS(H$3:H$40,$B$3:$B$40,$A49) -> 66631.836 | I49: =SUMIFS(I$3:I$40,$B$3:$B$40,$A49) -> 69316.497 | J49: =SUMIFS(J$3:J$40,$B$3:$B$40,$A49) -> 72001.159 | K49: =SUMIFS(K$3:K$40,$B$3:$B$40,$A49) -> 74685.82 | L49: =SUMIFS(L$3:L$40,$B$3:$B$40,$A49) -> 77370.481 | M49: =SUMIFS(M$3:M$40,$B$3:$B$40,$A49) -> 80055.143 | ... AJ49: =SUMIFS(AJ$3:AJ$40,$B$3:$B$40,$A49) -> 141802.36 | AL49: =(AJ49-E49)/E49 -> #DIV/0!
A50: ISIC 16 | F50: =SUMIFS(F$3:F$40,$B$3:$B$40,$A50) -> 19068.569 | G50: =SUMIFS(G$3:G$40,$B$3:$B$40,$A50) -> 19924.982 | H50: =SUMIFS(H$3:H$40,$B$3:$B$40,$A50) -> 20781.395 | I50: =SUMIFS(I$3:I$40,$B$3:$B$40,$A50) -> 21637.808 | J50: =SUMIFS(J$3:J$40,$B$3:$B$40,$A50) -> 22494.22 | K50: =SUMIFS(K$3:K$40,$B$3:$B$40,$A50) -> 23350.633 | L50: =SUMIFS(L$3:L$40,$B$3:$B$40,$A50) -> 24207.046 | M50: =SUMIFS(M$3:M$40,$B$3:$B$40,$A50) -> 25063.459 | ... AJ50: =SUMIFS(AJ$3:AJ$40,$B$3:$B$40,$A50) -> 44760.955 | AL50: =(AJ50-E50)/E50 -> #DIV/0!
A51: ISIC 17T18 | F51: =SUMIFS(F$3:F$40,$B$3:$B$40,$A51) -> 30791.007 | G51: =SUMIFS(G$3:G$40,$B$3:$B$40,$A51) -> 32189.317 | H51: =SUMIFS(H$3:H$40,$B$3:$B$40,$A51) -> 33587.627 | I51: =SUMIFS(I$3:I$40,$B$3:$B$40,$A51) -> 34985.938 | J51: =SUMIFS(J$3:J$40,$B$3:$B$40,$A51) -> 36384.248 | K51: =SUMIFS(K$3:K$40,$B$3:$B$40,$A51) -> 37782.558 | L51: =SUMIFS(L$3:L$40,$B$3:$B$40,$A51) -> 39180.869 | M51: =SUMIFS(M$3:M$40,$B$3:$B$40,$A51) -> 40579.179 | ... AJ51: =SUMIFS(AJ$3:AJ$40,$B$3:$B$40,$A51) -> 72740.317 | AL51: =(AJ51-E51)/E51 -> #DIV/0!
A52: ISIC 19 | F52: =SUMIFS(F$3:F$40,$B$3:$B$40,$A52) -> 106961.57 | G52: =SUMIFS(G$3:G$40,$B$3:$B$40,$A52) -> 111780.06 | H52: =SUMIFS(H$3:H$40,$B$3:$B$40,$A52) -> 116598.54 | I52: =SUMIFS(I$3:I$40,$B$3:$B$40,$A52) -> 121417.03 | J52: =SUMIFS(J$3:J$40,$B$3:$B$40,$A52) -> 126235.51 | K52: =SUMIFS(K$3:K$40,$B$3:$B$40,$A52) -> 131054 | L52: =SUMIFS(L$3:L$40,$B$3:$B$40,$A52) -> 135872.49 | M52: =SUMIFS(M$3:M$40,$B$3:$B$40,$A52) -> 140690.97 | ... AJ52: =SUMIFS(AJ$3:AJ$40,$B$3:$B$40,$A52) -> 251516.14 | AL52: =(AJ52-E52)/E52 -> #DIV/0!
A53: ISIC 20 | F53: =SUMIFS(F$3:F$40,$B$3:$B$40,$A53) -> 47759.652 | G53: =SUMIFS(G$3:G$40,$B$3:$B$40,$A53) -> 49904.646 | H53: =SUMIFS(H$3:H$40,$B$3:$B$40,$A53) -> 52049.641 | I53: =SUMIFS(I$3:I$40,$B$3:$B$40,$A53) -> 54194.636 | J53: =SUMIFS(J$3:J$40,$B$3:$B$40,$A53) -> 56339.63 | K53: =SUMIFS(K$3:K$40,$B$3:$B$40,$A53) -> 58484.625 | L53: =SUMIFS(L$3:L$40,$B$3:$B$40,$A53) -> 60629.62 | M53: =SUMIFS(M$3:M$40,$B$3:$B$40,$A53) -> 62774.614 | ... AJ53: =SUMIFS(AJ$3:AJ$40,$B$3:$B$40,$A53) -> 112109.49 | AL53: =(AJ53-E53)/E53 -> #DIV/0!
A54: ISIC 21 | F54: =SUMIFS(F$3:F$40,$B$3:$B$40,$A54) -> 5390.7162 | G54: =SUMIFS(G$3:G$40,$B$3:$B$40,$A54) -> 5592.2076 | H54: =SUMIFS(H$3:H$40,$B$3:$B$40,$A54) -> 5793.699 | I54: =SUMIFS(I$3:I$40,$B$3:$B$40,$A54) -> 5995.1905 | J54: =SUMIFS(J$3:J$40,$B$3:$B$40,$A54) -> 6196.6819 | K54: =SUMIFS(K$3:K$40,$B$3:$B$40,$A54) -> 6398.1733 | L54: =SUMIFS(L$3:L$40,$B$3:$B$40,$A54) -> 6599.6648 | M54: =SUMIFS(M$3:M$40,$B$3:$B$40,$A54) -> 6801.1562 | ... AJ54: =SUMIFS(AJ$3:AJ$40,$B$3:$B$40,$A54) -> 11435.459 | AL54: =(AJ54-E54)/E54 -> #DIV/0!
A55: ISIC 22 | F55: =SUMIFS(F$3:F$40,$B$3:$B$40,$A55) -> 0 | G55: =SUMIFS(G$3:G$40,$B$3:$B$40,$A55) -> 0 | H55: =SUMIFS(H$3:H$40,$B$3:$B$40,$A55) -> 0 | I55: =SUMIFS(I$3:I$40,$B$3:$B$40,$A55) -> 0 | J55: =SUMIFS(J$3:J$40,$B$3:$B$40,$A55) -> 0 | K55: =SUMIFS(K$3:K$40,$B$3:$B$40,$A55) -> 0 | L55: =SUMIFS(L$3:L$40,$B$3:$B$40,$A55) -> 0 | M55: =SUMIFS(M$3:M$40,$B$3:$B$40,$A55) -> 0 | ... AJ55: =SUMIFS(AJ$3:AJ$40,$B$3:$B$40,$A55) -> 0 | AL55: =(AJ55-E55)/E55 -> #DIV/0!
... A81: ISIC 97T98 | F81: =SUMIFS(F$3:F$40,$B$3:$B$40,$A81) -> 3996.5462 | G81: =SUMIFS(G$3:G$40,$B$3:$B$40,$A81) -> 4167.9476 | H81: =SUMIFS(H$3:H$40,$B$3:$B$40,$A81) -> 4339.349 | I81: =SUMIFS(I$3:I$40,$B$3:$B$40,$A81) -> 4510.7505 | J81: =SUMIFS(J$3:J$40,$B$3:$B$40,$A81) -> 4682.1519 | K81: =SUMIFS(K$3:K$40,$B$3:$B$40,$A81) -> 4853.5533 | L81: =SUMIFS(L$3:L$40,$B$3:$B$40,$A81) -> 5024.9548 | M81: =SUMIFS(M$3:M$40,$B$3:$B$40,$A81) -> 5196.3562 | ... AJ81: =SUMIFS(AJ$3:AJ$40,$B$3:$B$40,$A81) -> 9138.589 | AL81: =(AJ81-E81)/E81 -> #DIV/0!
D84: ISIC CODE | F84: 2020 | G84: 2021 | H84: 2022 | I84: 2023 | J84: 2024 | K84: 2025 | L84: 2026 | M84: 2027 | N84: 2028 | O84: 2029 | P84: 2030 | Q84: 2031 | R84: 2032 | S84: 2033 | T84: 2034 | U84: 2035 | V84: 2036 | W84: 2037 | X84: 2038 | Y84: 2039 | Z84: 2040 | AA84: 2041 | AB84: 2042 | AC84: 2043 | AD84: 2044 | AE84: 2045 | AF84: 2046 | AG84: 2047 | AH84: 2048 | AI84: 2049 | AJ84: 2050
D85: ISIC 01T03 | F85: 0 | G85: =IFERROR((SUMIFS(G$44:G$81,$A$44:$A$81,$D85)-SUMIFS(F$44:F$81,$A$44:$A$81,$D85))/SUMIFS(F$44:F$81,$A$44:$A$81,$D85),0) -> 0.044329089 | H85: =IFERROR((SUMIFS(H$44:H$81,$A$44:$A$81,$D85)-SUMIFS(G$44:G$81,$A$44:$A$81,$D85))/SUMIFS(G$44:G$81,$A$44:$A$81,$D85),0) -> 0.042447433 | I85: =IFERROR((SUMIFS(I$44:I$81,$A$44:$A$81,$D85)-SUMIFS(H$44:H$81,$A$44:$A$81,$D85))/SUMIFS(H$44:H$81,$A$44:$A$81,$D85),0) -> 0.040719015 | J85: =IFERROR((SUMIFS(J$44:J$81,$A$44:$A$81,$D85)-SUMIFS(I$44:I$81,$A$44:$A$81,$D85))/SUMIFS(I$44:I$81,$A$44:$A$81,$D85),0) -> 0.039125849 | K85: =IFERROR((SUMIFS(K$44:K$81,$A$44:$A$81,$D85)-SUMIFS(J$44:J$81,$A$44:$A$81,$D85))/SUMIFS(J$44:J$81,$A$44:$A$81,$D85),0) -> 0.037652657 | L85: =IFERROR((SUMIFS(L$44:L$81,$A$44:$A$81,$D85)-SUMIFS(K$44:K$81,$A$44:$A$81,$D85))/SUMIFS(K$44:K$81,$A$44:$A$81,$D85),0) -> 0.036286378 | M85: =IFERROR((SUMIFS(M$44:M$81,$A$44:$A$81,$D85)-SUMIFS(L$44:L$81,$A$44:$A$81,$D85))/SUMIFS(L$44:L$81,$A$44:$A$81,$D85),0) -> 0.035015782 | N85: =IFERROR((SUMIFS(N$44:N$81,$A$44:$A$81,$D85)-SUMIFS(M$44:M$81,$A$44:$A$81,$D85))/SUMIFS(M$44:M$81,$A$44:$A$81,$D85),0) -> 0.033831158 | ... AJ85: =IFERROR((SUMIFS(AJ$44:AJ$81,$A$44:$A$81,$D85)-SUMIFS(AI$44:AI$81,$A$44:$A$81,$D85))/SUMIFS(AI$44:AI$81,$A$44:$A$81,$D85),0) -> 0.019395425
D86: ISIC 05 | F86: 0 | G86: =IFERROR((SUMIFS(G$44:G$81,$A$44:$A$81,$D86)-SUMIFS(F$44:F$81,$A$44:$A$81,$D86))/SUMIFS(F$44:F$81,$A$44:$A$81,$D86),0) -> 0.044469221 | H86: =IFERROR((SUMIFS(H$44:H$81,$A$44:$A$81,$D86)-SUMIFS(G$44:G$81,$A$44:$A$81,$D86))/SUMIFS(G$44:G$81,$A$44:$A$81,$D86),0) -> 0.042575904 | I86: =IFERROR((SUMIFS(I$44:I$81,$A$44:$A$81,$D86)-SUMIFS(H$44:H$81,$A$44:$A$81,$D86))/SUMIFS(H$44:H$81,$A$44:$A$81,$D86),0) -> 0.040837222 | J86: =IFERROR((SUMIFS(J$44:J$81,$A$44:$A$81,$D86)-SUMIFS(I$44:I$81,$A$44:$A$81,$D86))/SUMIFS(I$44:I$81,$A$44:$A$81,$D86),0) -> 0.039234975 | K86: =IFERROR((SUMIFS(K$44:K$81,$A$44:$A$81,$D86)-SUMIFS(J$44:J$81,$A$44:$A$81,$D86))/SUMIFS(J$44:J$81,$A$44:$A$81,$D86),0) -> 0.037753709 | L86: =IFERROR((SUMIFS(L$44:L$81,$A$44:$A$81,$D86)-SUMIFS(K$44:K$81,$A$44:$A$81,$D86))/SUMIFS(K$44:K$81,$A$44:$A$81,$D86),0) -> 0.036380221 | M86: =IFERROR((SUMIFS(M$44:M$81,$A$44:$A$81,$D86)-SUMIFS(L$44:L$81,$A$44:$A$81,$D86))/SUMIFS(L$44:L$81,$A$44:$A$81,$D86),0) -> 0.03510316 | N86: =IFERROR((SUMIFS(N$44:N$81,$A$44:$A$81,$D86)-SUMIFS(M$44:M$81,$A$44:$A$81,$D86))/SUMIFS(M$44:M$81,$A$44:$A$81,$D86),0) -> 0.033912717 | ... AJ86: =IFERROR((SUMIFS(AJ$44:AJ$81,$A$44:$A$81,$D86)-SUMIFS(AI$44:AI$81,$A$44:$A$81,$D86))/SUMIFS(AI$44:AI$81,$A$44:$A$81,$D86),0) -> 0.019422204
D87: ISIC 06 | F87: =F86 -> 0 | G87: =IFERROR((SUMIFS(G$44:G$81,$A$44:$A$81,$D87)-SUMIFS(F$44:F$81,$A$44:$A$81,$D87))/SUMIFS(F$44:F$81,$A$44:$A$81,$D87),0) -> 0 | H87: =IFERROR((SUMIFS(H$44:H$81,$A$44:$A$81,$D87)-SUMIFS(G$44:G$81,$A$44:$A$81,$D87))/SUMIFS(G$44:G$81,$A$44:$A$81,$D87),0) -> 0 | I87: =IFERROR((SUMIFS(I$44:I$81,$A$44:$A$81,$D87)-SUMIFS(H$44:H$81,$A$44:$A$81,$D87))/SUMIFS(H$44:H$81,$A$44:$A$81,$D87),0) -> 0 | J87: =IFERROR((SUMIFS(J$44:J$81,$A$44:$A$81,$D87)-SUMIFS(I$44:I$81,$A$44:$A$81,$D87))/SUMIFS(I$44:I$81,$A$44:$A$81,$D87),0) -> 0 | K87: =IFERROR((SUMIFS(K$44:K$81,$A$44:$A$81,$D87)-SUMIFS(J$44:J$81,$A$44:$A$81,$D87))/SUMIFS(J$44:J$81,$A$44:$A$81,$D87),0) -> 0 | L87: =IFERROR((SUMIFS(L$44:L$81,$A$44:$A$81,$D87)-SUMIFS(K$44:K$81,$A$44:$A$81,$D87))/SUMIFS(K$44:K$81,$A$44:$A$81,$D87),0) -> 0 | M87: =IFERROR((SUMIFS(M$44:M$81,$A$44:$A$81,$D87)-SUMIFS(L$44:L$81,$A$44:$A$81,$D87))/SUMIFS(L$44:L$81,$A$44:$A$81,$D87),0) -> 0 | N87: =IFERROR((SUMIFS(N$44:N$81,$A$44:$A$81,$D87)-SUMIFS(M$44:M$81,$A$44:$A$81,$D87))/SUMIFS(M$44:M$81,$A$44:$A$81,$D87),0) -> 0 | ... AJ87: =IFERROR((SUMIFS(AJ$44:AJ$81,$A$44:$A$81,$D87)-SUMIFS(AI$44:AI$81,$A$44:$A$81,$D87))/SUMIFS(AI$44:AI$81,$A$44:$A$81,$D87),0) -> 0
D88: ISIC 07T08 | F88: 0 | G88: =IFERROR((SUMIFS(G$44:G$81,$A$44:$A$81,$D88)-SUMIFS(F$44:F$81,$A$44:$A$81,$D88))/SUMIFS(F$44:F$81,$A$44:$A$81,$D88),0) -> 0.044166655 | H88: =IFERROR((SUMIFS(H$44:H$81,$A$44:$A$81,$D88)-SUMIFS(G$44:G$81,$A$44:$A$81,$D88))/SUMIFS(G$44:G$81,$A$44:$A$81,$D88),0) -> 0.042298473 | I88: =IFERROR((SUMIFS(I$44:I$81,$A$44:$A$81,$D88)-SUMIFS(H$44:H$81,$A$44:$A$81,$D88))/SUMIFS(H$44:H$81,$A$44:$A$81,$D88),0) -> 0.040581919 | J88: =IFERROR((SUMIFS(J$44:J$81,$A$44:$A$81,$D88)-SUMIFS(I$44:I$81,$A$44:$A$81,$D88))/SUMIFS(I$44:I$81,$A$44:$A$81,$D88),0) -> 0.038999255 | K88: =IFERROR((SUMIFS(K$44:K$81,$A$44:$A$81,$D88)-SUMIFS(J$44:J$81,$A$44:$A$81,$D88))/SUMIFS(J$44:J$81,$A$44:$A$81,$D88),0) -> 0.037535402 | L88: =IFERROR((SUMIFS(L$44:L$81,$A$44:$A$81,$D88)-SUMIFS(K$44:K$81,$A$44:$A$81,$D88))/SUMIFS(K$44:K$81,$A$44:$A$81,$D88),0) -> 0.036177466 | M88: =IFERROR((SUMIFS(M$44:M$81,$A$44:$A$81,$D88)-SUMIFS(L$44:L$81,$A$44:$A$81,$D88))/SUMIFS(L$44:L$81,$A$44:$A$81,$D88),0) -> 0.034914354 | N88: =IFERROR((SUMIFS(N$44:N$81,$A$44:$A$81,$D88)-SUMIFS(M$44:M$81,$A$44:$A$81,$D88))/SUMIFS(M$44:M$81,$A$44:$A$81,$D88),0) -> 0.033736467 | ... AJ88: =IFERROR((SUMIFS(AJ$44:AJ$81,$A$44:$A$81,$D88)-SUMIFS(AI$44:AI$81,$A$44:$A$81,$D88))/SUMIFS(AI$44:AI$81,$A$44:$A$81,$D88),0) -> 0.019364265
D89: ISIC 09 | F89: 0 | G89: =IFERROR((SUMIFS(G$44:G$81,$A$44:$A$81,$D89)-SUMIFS(F$44:F$81,$A$44:$A$81,$D89))/SUMIFS(F$44:F$81,$A$44:$A$81,$D89),0) -> 0.046815031 | H89: =IFERROR((SUMIFS(H$44:H$81,$A$44:$A$81,$D89)-SUMIFS(G$44:G$81,$A$44:$A$81,$D89))/SUMIFS(G$44:G$81,$A$44:$A$81,$D89),0) -> 0.044721397 | I89: =IFERROR((SUMIFS(I$44:I$81,$A$44:$A$81,$D89)-SUMIFS(H$44:H$81,$A$44:$A$81,$D89))/SUMIFS(H$44:H$81,$A$44:$A$81,$D89),0) -> 0.042807008 | J89: =IFERROR((SUMIFS(J$44:J$81,$A$44:$A$81,$D89)-SUMIFS(I$44:I$81,$A$44:$A$81,$D89))/SUMIFS(I$44:I$81,$A$44:$A$81,$D89),0) -> 0.041049789 | K89: =IFERROR((SUMIFS(K$44:K$81,$A$44:$A$81,$D89)-SUMIFS(J$44:J$81,$A$44:$A$81,$D89))/SUMIFS(J$44:J$81,$A$44:$A$81,$D89),0) -> 0.039431149 | L89: =IFERROR((SUMIFS(L$44:L$81,$A$44:$A$81,$D89)-SUMIFS(K$44:K$81,$A$44:$A$81,$D89))/SUMIFS(K$44:K$81,$A$44:$A$81,$D89),0) -> 0.037935316 | M89: =IFERROR((SUMIFS(M$44:M$81,$A$44:$A$81,$D89)-SUMIFS(L$44:L$81,$A$44:$A$81,$D89))/SUMIFS(L$44:L$81,$A$44:$A$81,$D89),0) -> 0.036548825 | N89: =IFERROR((SUMIFS(N$44:N$81,$A$44:$A$81,$D89)-SUMIFS(M$44:M$81,$A$44:$A$81,$D89))/SUMIFS(M$44:M$81,$A$44:$A$81,$D89),0) -> 0.035260109 | ... AJ89: =IFERROR((SUMIFS(AJ$44:AJ$81,$A$44:$A$81,$D89)-SUMIFS(AI$44:AI$81,$A$44:$A$81,$D89))/SUMIFS(AI$44:AI$81,$A$44:$A$81,$D89),0) -> 0.019856769
D90: ISIC 10T12 | F90: 0 | G90: =IFERROR((SUMIFS(G$44:G$81,$A$44:$A$81,$D90)-SUMIFS(F$44:F$81,$A$44:$A$81,$D90))/SUMIFS(F$44:F$81,$A$44:$A$81,$D90),0) -> 0.044871599 | H90: =IFERROR((SUMIFS(H$44:H$81,$A$44:$A$81,$D90)-SUMIFS(G$44:G$81,$A$44:$A$81,$D90))/SUMIFS(G$44:G$81,$A$44:$A$81,$D90),0) -> 0.042944605 | I90: =IFERROR((SUMIFS(I$44:I$81,$A$44:$A$81,$D90)-SUMIFS(H$44:H$81,$A$44:$A$81,$D90))/SUMIFS(H$44:H$81,$A$44:$A$81,$D90),0) -> 0.041176305 | J90: =IFERROR((SUMIFS(J$44:J$81,$A$44:$A$81,$D90)-SUMIFS(I$44:I$81,$A$44:$A$81,$D90))/SUMIFS(I$44:I$81,$A$44:$A$81,$D90),0) -> 0.03954787 | K90: =IFERROR((SUMIFS(K$44:K$81,$A$44:$A$81,$D90)-SUMIFS(J$44:J$81,$A$44:$A$81,$D90))/SUMIFS(J$44:J$81,$A$44:$A$81,$D90),0) -> 0.038043337 | L90: =IFERROR((SUMIFS(L$44:L$81,$A$44:$A$81,$D90)-SUMIFS(K$44:K$81,$A$44:$A$81,$D90))/SUMIFS(K$44:K$81,$A$44:$A$81,$D90),0) -> 0.036649084 | M90: =IFERROR((SUMIFS(M$44:M$81,$A$44:$A$81,$D90)-SUMIFS(L$44:L$81,$A$44:$A$81,$D90))/SUMIFS(L$44:L$81,$A$44:$A$81,$D90),0) -> 0.035353413 | N90: =IFERROR((SUMIFS(N$44:N$81,$A$44:$A$81,$D90)-SUMIFS(M$44:M$81,$A$44:$A$81,$D90))/SUMIFS(M$44:M$81,$A$44:$A$81,$D90),0) -> 0.034146228 | ... AJ90: =IFERROR((SUMIFS(AJ$44:AJ$81,$A$44:$A$81,$D90)-SUMIFS(AI$44:AI$81,$A$44:$A$81,$D90))/SUMIFS(AI$44:AI$81,$A$44:$A$81,$D90),0) -> 0.01949857
D91: ISIC 13T15 | F91: 0 | G91: =IFERROR((SUMIFS(G$44:G$81,$A$44:$A$81,$D91)-SUMIFS(F$44:F$81,$A$44:$A$81,$D91))/SUMIFS(F$44:F$81,$A$44:$A$81,$D91),0) -> 0.043822254 | H91: =IFERROR((SUMIFS(H$44:H$81,$A$44:$A$81,$D91)-SUMIFS(G$44:G$81,$A$44:$A$81,$D91))/SUMIFS(G$44:G$81,$A$44:$A$81,$D91),0) -> 0.041982487 | I91: =IFERROR((SUMIFS(I$44:I$81,$A$44:$A$81,$D91)-SUMIFS(H$44:H$81,$A$44:$A$81,$D91))/SUMIFS(H$44:H$81,$A$44:$A$81,$D91),0) -> 0.040290972 | J91: =IFERROR((SUMIFS(J$44:J$81,$A$44:$A$81,$D91)-SUMIFS(I$44:I$81,$A$44:$A$81,$D91))/SUMIFS(I$44:I$81,$A$44:$A$81,$D91),0) -> 0.038730483 | K91: =IFERROR((SUMIFS(K$44:K$81,$A$44:$A$81,$D91)-SUMIFS(J$44:J$81,$A$44:$A$81,$D91))/SUMIFS(J$44:J$81,$A$44:$A$81,$D91),0) -> 0.037286364 | L91: =IFERROR((SUMIFS(L$44:L$81,$A$44:$A$81,$D91)-SUMIFS(K$44:K$81,$A$44:$A$81,$D91))/SUMIFS(K$44:K$81,$A$44:$A$81,$D91),0) -> 0.035946066 | M91: =IFERROR((SUMIFS(M$44:M$81,$A$44:$A$81,$D91)-SUMIFS(L$44:L$81,$A$44:$A$81,$D91))/SUMIFS(L$44:L$81,$A$44:$A$81,$D91),0) -> 0.034698781 | N91: =IFERROR((SUMIFS(N$44:N$81,$A$44:$A$81,$D91)-SUMIFS(M$44:M$81,$A$44:$A$81,$D91))/SUMIFS(M$44:M$81,$A$44:$A$81,$D91),0) -> 0.033535153 | ... AJ91: =IFERROR((SUMIFS(AJ$44:AJ$81,$A$44:$A$81,$D91)-SUMIFS(AI$44:AI$81,$A$44:$A$81,$D91))/SUMIFS(AI$44:AI$81,$A$44:$A$81,$D91),0) -> 0.019297771
D92: ISIC 16 | F92: 0 | G92: =IFERROR((SUMIFS(G$44:G$81,$A$44:$A$81,$D92)-SUMIFS(F$44:F$81,$A$44:$A$81,$D92))/SUMIFS(F$44:F$81,$A$44:$A$81,$D92),0) -> 0.044912277 | H92: =IFERROR((SUMIFS(H$44:H$81,$A$44:$A$81,$D92)-SUMIFS(G$44:G$81,$A$44:$A$81,$D92))/SUMIFS(G$44:G$81,$A$44:$A$81,$D92),0) -> 0.042981864 | I92: =IFERROR((SUMIFS(I$44:I$81,$A$44:$A$81,$D92)-SUMIFS(H$44:H$81,$A$44:$A$81,$D92))/SUMIFS(H$44:H$81,$A$44:$A$81,$D92),0) -> 0.041210557 | J92: =IFERROR((SUMIFS(J$44:J$81,$A$44:$A$81,$D92)-SUMIFS(I$44:I$81,$A$44:$A$81,$D92))/SUMIFS(I$44:I$81,$A$44:$A$81,$D92),0) -> 0.039579465 | K92: =IFERROR((SUMIFS(K$44:K$81,$A$44:$A$81,$D92)-SUMIFS(J$44:J$81,$A$44:$A$81,$D92))/SUMIFS(J$44:J$81,$A$44:$A$81,$D92),0) -> 0.038072573 | L92: =IFERROR((SUMIFS(L$44:L$81,$A$44:$A$81,$D92)-SUMIFS(K$44:K$81,$A$44:$A$81,$D92))/SUMIFS(K$44:K$81,$A$44:$A$81,$D92),0) -> 0.036676215 | M92: =IFERROR((SUMIFS(M$44:M$81,$A$44:$A$81,$D92)-SUMIFS(L$44:L$81,$A$44:$A$81,$D92))/SUMIFS(L$44:L$81,$A$44:$A$81,$D92),0) -> 0.03537866 | N92: =IFERROR((SUMIFS(N$44:N$81,$A$44:$A$81,$D92)-SUMIFS(M$44:M$81,$A$44:$A$81,$D92))/SUMIFS(M$44:M$81,$A$44:$A$81,$D92),0) -> 0.034169779 | ... AJ92: =IFERROR((SUMIFS(AJ$44:AJ$81,$A$44:$A$81,$D92)-SUMIFS(AI$44:AI$81,$A$44:$A$81,$D92))/SUMIFS(AI$44:AI$81,$A$44:$A$81,$D92),0) -> 0.019506247
D93: ISIC 17T18 | F93: 0 | G93: =IFERROR((SUMIFS(G$44:G$81,$A$44:$A$81,$D93)-SUMIFS(F$44:F$81,$A$44:$A$81,$D93))/SUMIFS(F$44:F$81,$A$44:$A$81,$D93),0) -> 0.045412947 | H93: =IFERROR((SUMIFS(H$44:H$81,$A$44:$A$81,$D93)-SUMIFS(G$44:G$81,$A$44:$A$81,$D93))/SUMIFS(G$44:G$81,$A$44:$A$81,$D93),0) -> 0.0434402 | I93: =IFERROR((SUMIFS(I$44:I$81,$A$44:$A$81,$D93)-SUMIFS(H$44:H$81,$A$44:$A$81,$D93))/SUMIFS(H$44:H$81,$A$44:$A$81,$D93),0) -> 0.04163171 | J93: =IFERROR((SUMIFS(J$44:J$81,$A$44:$A$81,$D93)-SUMIFS(I$44:I$81,$A$44:$A$81,$D93))/SUMIFS(I$44:I$81,$A$44:$A$81,$D93),0) -> 0.039967783 | K93: =IFERROR((SUMIFS(K$44:K$81,$A$44:$A$81,$D93)-SUMIFS(J$44:J$81,$A$44:$A$81,$D93))/SUMIFS(J$44:J$81,$A$44:$A$81,$D93),0) -> 0.038431751 | L93: =IFERROR((SUMIFS(L$44:L$81,$A$44:$A$81,$D93)-SUMIFS(K$44:K$81,$A$44:$A$81,$D93))/SUMIFS(K$44:K$81,$A$44:$A$81,$D93),0) -> 0.037009414 | M93: =IFERROR((SUMIFS(M$44:M$81,$A$44:$A$81,$D93)-SUMIFS(L$44:L$81,$A$44:$A$81,$D93))/SUMIFS(L$44:L$81,$A$44:$A$81,$D93),0) -> 0.0356886 | N93: =IFERROR((SUMIFS(N$44:N$81,$A$44:$A$81,$D93)-SUMIFS(M$44:M$81,$A$44:$A$81,$D93))/SUMIFS(M$44:M$81,$A$44:$A$81,$D93),0) -> 0.034458813 | ... AJ93: =IFERROR((SUMIFS(AJ$44:AJ$81,$A$44:$A$81,$D93)-SUMIFS(AI$44:AI$81,$A$44:$A$81,$D93))/SUMIFS(AI$44:AI$81,$A$44:$A$81,$D93),0) -> 0.019600098
...

Sheet GDP growth by Industry
A1: Unit: dimensionless (% change) | B1: 2019 | C1: 2020 | D1: 2021 | E1: 2022 | F1: 2023 | G1: 2024 | H1: 2025 | I1: 2026 | J1: 2027 | K1: 2028 | L1: 2029 | M1: 2030 | N1: 2031 | O1: 2032 | P1: 2033 | Q1: 2034 | R1: 2035 | S1: 2036 | T1: 2037 | U1: 2038 | V1: 2039 | W1: 2040 | X1: 2041 | Y1: 2042 | Z1: 2043 | AA1: 2044 | AB1: 2045 | AC1: 2046 | AD1: 2047 | AE1: 2048 | AF1: 2049 | AG1: 2050 | AH1: 2051 | AI1: 2052 | AJ1: 2053 | AK1: 2054 | AL1: 2055 | AM1: 2056 | AN1: 2057 | AO1: 2058 | AP1: 2059 | AQ1: 2060 | AR1: 2061 | AS1: 2062 | AT1: 2063 | AU1: 2064 | AV1: 2065 | AW1: 2066 | AX1: 2067 | AY1: 2068 | AZ1: 2069 | BA1: 2070
A2: ISIC 01T03 | B2: =B47 -> 0.0285 | C2: =C47 -> 0.0437 | D2: =D47 -> 0.0321 | E2: =E47 -> 0.0463 | F2: =F47 -> 0.0418 | G2: =G47 -> 0.0825 | H2: =H47 -> 0.073666667 | I2: =I47 -> 0.08162381 | ... BA2: =BA47 -> 0.4317381
A3: ISIC 05 | B3: =B48 -> 0.0251 | C3: =C48 -> 0.1247 | D3: =D48 -> 0.2718 | E3: =E48 -> 0.3371 | F3: =F48 -> 0.0329 | G3: =G48 -> 0.0177 | H3: =H48 -> 0.0177 | I3: =I48 -> 0.22316571 | ... BA3: =BA48 -> 0.84469714
A4: ISIC 06 | B4: =B48 -> 0.0251 | C4: =C48 -> 0.1247 | D4: =D48 -> 0.2718 | E4: =E48 -> 0.3371 | F4: =F48 -> 0.0329 | G4: =G48 -> 0.0177 | H4: =H48 -> 0.0177 | I4: =I48 -> 0.22316571 | ... BA4: =BA48 -> 0.84469714
A5: ISIC 07T08 | B5: =B4 -> 0.0251 | C5: =C4 -> 0.1247 | D5: =D4 -> 0.2718 | E5: =E4 -> 0.3371 | F5: =F4 -> 0.0329 | G5: =G4 -> 0.0177 | H5: =H4 -> 0.0177 | I5: =I4 -> 0.22316571 | ... BA5: =BA4 -> 0.84469714
A6: ISIC 09 | B6: =B5 -> 0.0251 | C6: =C5 -> 0.1247 | D6: =D5 -> 0.2718 | E6: =E5 -> 0.3371 | F6: =F5 -> 0.0329 | G6: =G5 -> 0.0177 | H6: =H5 -> 0.0177 | I6: =I5 -> 0.22316571 | ... BA6: =BA5 -> 0.84469714
A7: ISIC 10T12 | B7: =B49 -> 0.0357 | C7: =C49 -> 0.0124 | D7: =D49 -> 0.0129 | E7: =E49 -> 0.0129 | F7: =F49 -> 0.0211 | G7: =G49 -> 0.0076 | H7: =H49 -> 0.00566 | I7: =I49 -> 0.0023914286 | ... BA7: =BA49 -> 0.0023914286
A8: ISIC 13T15 | B8: =B7 -> 0.0357 | C8: =C7 -> 0.0124 | D8: =D7 -> 0.0129 | E8: =E7 -> 0.0129 | F8: =F7 -> 0.0211 | G8: =G7 -> 0.0076 | H8: =H7 -> 0.00566 | I8: =I7 -> 0.0023914286 | ... BA8: =BA7 -> 0.0023914286
A9: ISIC 16 | B9: =B49 -> 0.0357 | C9: =C49 -> 0.0124 | D9: =D49 -> 0.0129 | E9: =E49 -> 0.0129 | F9: =F49 -> 0.0211 | G9: =G49 -> 0.0076 | H9: =H49 -> 0.00566 | I9: =I49 -> 0.0023914286 | ... BA9: =BA49 -> 0.0023914286
A10: ISIC 17T18 | B10: =B9 -> 0.0357 | C10: =C9 -> 0.0124 | D10: =D9 -> 0.0129 | E10: =E9 -> 0.0129 | F10: =F9 -> 0.0211 | G10: =G9 -> 0.0076 | H10: =H9 -> 0.00566 | I10: =I9 -> 0.0023914286 | ... BA10: =BA9 -> 0.0023914286
A11: ISIC 19 | B11: =B9 -> 0.0357 | C11: =C9 -> 0.0124 | D11: =D9 -> 0.0129 | E11: =E9 -> 0.0129 | F11: =F9 -> 0.0211 | G11: =G9 -> 0.0076 | H11: =H9 -> 0.00566 | I11: =I9 -> 0.0023914286 | ... BA11: =BA9 -> 0.0023914286
A12: ISIC 20 | B12: =B9 -> 0.0357 | C12: =C9 -> 0.0124 | D12: =D9 -> 0.0129 | E12: =E9 -> 0.0129 | F12: =F9 -> 0.0211 | G12: =G9 -> 0.0076 | H12: =H9 -> 0.00566 | I12: =I9 -> 0.0023914286 | ... BA12: =BA9 -> 0.0023914286
A13: ISIC 21 | B13: =B9 -> 0.0357 | C13: =C9 -> 0.0124 | D13: =D9 -> 0.0129 | E13: =E9 -> 0.0129 | F13: =F9 -> 0.0211 | G13: =G9 -> 0.0076 | H13: =H9 -> 0.00566 | I13: =I9 -> 0.0023914286 | ... BA13: =BA9 -> 0.0023914286
A14: ISIC 22 | B14: =B9 -> 0.0357 | C14: =C9 -> 0.0124 | D14: =D9 -> 0.0129 | E14: =E9 -> 0.0129 | F14: =F9 -> 0.0211 | G14: =G9 -> 0.0076 | H14: =H9 -> 0.00566 | I14: =I9 -> 0.0023914286 | ... BA14: =BA9 -> 0.0023914286
A15: ISIC 231 | B15: =B9 -> 0.0357 | C15: =C9 -> 0.0124 | D15: =D9 -> 0.0129 | E15: =E9 -> 0.0129 | F15: =F9 -> 0.0211 | G15: =G9 -> 0.0076 | H15: =H9 -> 0.00566 | I15: =I9 -> 0.0023914286 | ... BA15: =BA9 -> 0.0023914286
A16: ISIC 239 | B16: =B9 -> 0.0357 | C16: =C9 -> 0.0124 | D16: =D9 -> 0.0129 | E16: =E9 -> 0.0129 | F16: =F9 -> 0.0211 | G16: =G9 -> 0.0076 | H16: =H9 -> 0.00566 | I16: =I9 -> 0.0023914286 | ... BA16: =BA9 -> 0.0023914286
A17: ISIC 241 | B17: =B9 -> 0.0357 | C17: =C9 -> 0.0124 | D17: =D9 -> 0.0129 | E17: =E9 -> 0.0129 | F17: =F9 -> 0.0211 | G17: =G9 -> 0.0076 | H17: =H9 -> 0.00566 | I17: =I9 -> 0.0023914286 | ... BA17: =BA9 -> 0.0023914286
A18: ISIC 242 | B18: =B9 -> 0.0357 | C18: =C9 -> 0.0124 | D18: =D9 -> 0.0129 | E18: =E9 -> 0.0129 | F18: =F9 -> 0.0211 | G18: =G9 -> 0.0076 | H18: =H9 -> 0.00566 | I18: =I9 -> 0.0023914286 | ... BA18: =BA9 -> 0.0023914286
A19: ISIC 25 | B19: =B9 -> 0.0357 | C19: =C9 -> 0.0124 | D19: =D9 -> 0.0129 | E19: =E9 -> 0.0129 | F19: =F9 -> 0.0211 | G19: =G9 -> 0.0076 | H19: =H9 -> 0.00566 | I19: =I9 -> 0.0023914286 | ... BA19: =BA9 -> 0.0023914286
A20: ISIC 26 | B20: =B9 -> 0.0357 | C20: =C9 -> 0.0124 | D20: =D9 -> 0.0129 | E20: =E9 -> 0.0129 | F20: =F9 -> 0.0211 | G20: =G9 -> 0.0076 | H20: =H9 -> 0.00566 | I20: =I9 -> 0.0023914286 | ... BA20: =BA9 -> 0.0023914286
A21: ISIC 27 | B21: =B9 -> 0.0357 | C21: =C9 -> 0.0124 | D21: =D9 -> 0.0129 | E21: =E9 -> 0.0129 | F21: =F9 -> 0.0211 | G21: =G9 -> 0.0076 | H21: =H9 -> 0.00566 | I21: =I9 -> 0.0023914286 | ... BA21: =BA9 -> 0.0023914286
A22: ISIC 28 | B22: =B9 -> 0.0357 | C22: =C9 -> 0.0124 | D22: =D9 -> 0.0129 | E22: =E9 -> 0.0129 | F22: =F9 -> 0.0211 | G22: =G9 -> 0.0076 | H22: =H9 -> 0.00566 | I22: =I9 -> 0.0023914286 | ... BA22: =BA9 -> 0.0023914286
A23: ISIC 29 | B23: =B9 -> 0.0357 | C23: =C9 -> 0.0124 | D23: =D9 -> 0.0129 | E23: =E9 -> 0.0129 | F23: =F9 -> 0.0211 | G23: =G9 -> 0.0076 | H23: =H9 -> 0.00566 | I23: =I9 -> 0.0023914286 | ... BA23: =BA9 -> 0.0023914286
A24: ISIC 30 | B24: =B9 -> 0.0357 | C24: =C9 -> 0.0124 | D24: =D9 -> 0.0129 | E24: =E9 -> 0.0129 | F24: =F9 -> 0.0211 | G24: =G9 -> 0.0076 | H24: =H9 -> 0.00566 | I24: =I9 -> 0.0023914286 | ... BA24: =BA9 -> 0.0023914286
A25: ISIC 31T33 | B25: =B9 -> 0.0357 | C25: =C9 -> 0.0124 | D25: =D9 -> 0.0129 | E25: =E9 -> 0.0129 | F25: =F9 -> 0.0211 | G25: =G9 -> 0.0076 | H25: =H9 -> 0.00566 | I25: =I9 -> 0.0023914286 | ... BA25: =BA9 -> 0.0023914286
A26: ISIC 351 | B26: =B50 -> 0.0058 | C26: =C50 -> 0.0006 | D26: =D50 -> 0.0096 | E26: =E50 -> 0.0154 | F26: =F50 -> 0.0076 | G26: =G50 -> 0.003 | H26: =H50 -> 0.00828 | I26: =I50 -> 0.0086457143 | ... BA26: =BA50 -> 0.024737143
A27: ISIC 352T353 | B27: =B50 -> 0.0058 | C27: =C50 -> 0.0006 | D27: =D50 -> 0.0096 | E27: =E50 -> 0.0154 | F27: =F50 -> 0.0076 | G27: =G50 -> 0.003 | H27: =H50 -> 0.00828 | I27: =I50 -> 0.0086457143 | ... BA27: =BA50 -> 0.024737143
A28: ISIC 41T43 | B28: =B52 -> 0.03 | C28: =C52 -> 0.0038 | D28: =D52 -> 0.0427 | E28: =E52 -> 0.0584 | F28: =F52 -> 0.0326 | G28: =G52 -> 0.0071 | H28: =H52 -> 0.02786 | I28: =I52 -> 0.027505714 | ... BA28: =BA52 -> 0.011917143
A29: ISIC 49T53 | B29: =B54 -> 0.0576 | C29: =C54 -> 0.0434 | D29: =D54 -> 0.0238 | E29: =E54 -> 0.0484 | F29: =F54 -> 0.0409 | G29: =G54 -> 0.0106 | H29: =H54 -> 0.01566 | I29: =I54 -> 0.0094342857 | ... BA29: =BA54 -> 0.0032085714
A30: ISIC 55T56 | B30: =B55 -> 0.0091 | C30: =C55 -> 0.006 | D30: =D55 -> 0.0073 | E30: =E55 -> 0.018 | F30: =F55 -> 0.012 | G30: =G55 -> 0.0227 | H30: =H55 -> 0.022186667 | I30: =I55 -> 0.024949524 | ... BA30: =BA55 -> 0.14651524
A31: ISIC 58T60 | B31: =B56 -> 0.0244 | C31: =C56 -> 0.0043 | D31: =D56 -> 0.0073 | E31: =E56 -> 0.0075 | F31: =F56 -> 0.0105 | G31: =G56 -> 0.01 | H31: =H56 -> 0.0053466667 | I31: =I56 -> 0.0038266667 | ... BA31: =BA56 -> 0.00078666667
A32: ISIC 61 | B32: =B56 -> 0.0244 | C32: =C56 -> 0.0043 | D32: =D56 -> 0.0073 | E32: =E56 -> 0.0075 | F32: =F56 -> 0.0105 | G32: =G56 -> 0.01 | H32: =H56 -> 0.0053466667 | I32: =I56 -> 0.0038266667 | ... BA32: =BA56 -> 0.00078666667
A33: ISIC 62T63 | B33: =B56 -> 0.0244 | C33: =C56 -> 0.0043 | D33: =D56 -> 0.0073 | E33: =E56 -> 0.0075 | F33: =F56 -> 0.0105 | G33: =G56 -> 0.01 | H33: =H56 -> 0.0053466667 | I33: =I56 -> 0.0038266667 | ... BA33: =BA56 -> 0.00078666667
A34: ISIC 64T66 | B34: =B57 -> 0.0257 | C34: =C57 -> 0.0041 | D34: =D57 -> 0.0414 | E34: =E57 -> 0.0422 | F34: =F57 -> 0.0368 | G34: =G57 -> 0.0217 | H34: =H57 -> 0.03654 | I34: =I57 -> 0.038794286 | ... BA34: =BA57 -> 0.13798286
A35: ISIC 68 | B35: =B58 -> 0.0234 | C35: =C58 -> 0.0092 | D35: =D58 -> 0.0039 | E35: =E58 -> 0.0253 | F35: =F58 -> 0.0205 | G35: =G58 -> 0.0051 | H35: =H58 -> 0.010946667 | I35: =I58 -> 0.009912381 | ... BA35: =BA58 -> 0.00060380952
